Workbook

Sheet INPUT
B3: INPUT — Raw Data
B4: All figures in USD thousands unless stated
B5: METRIC | C5: UNIT | E5: 2022 | F5: 2023 | G5: 2024 | H5: 2025 (LTM)
B7: INPUT
B9: Revenue | C9: ($000) | E9: 17568.8 | F9: 18428.4 | G9: 20576.6 | H9: 22136.4
B10: Cost of Goods Sold (COGS) | C10: ($000) | E10: -13113.4 | F10: -13662 | G10: -15202.7 | H10: -16283.2
B11: Gross Profit | C11: ($000) | D11: =D9+D10 | E11: =E9+E10 | F11: =F9+F10 | G11: =G9+G10 | H11: =H9+H10
D13: =SUM(D14:D16) | E13: =SUM(E14:E16) | F13: =SUM(F14:F16) | G13: =SUM(G14:G16) | H13: =SUM(H14:H16)
B14: Operating Expenses (SG&A) | C14: ($000) | E14: -1948.9 | F14: -2005 | G14: -2283.2 | H14: -2306.7
B15: Research & Development | C15: ($000) | E15: -1063.6 | F15: -1107.7 | G15: -1273.7 | H15: -1327.8
B16: Depreciation & Amortization | C16: ($000) | E16: -1058.8 | F16: -1045.1 | G16: -1155.4 | H16: -1087.3
B17: EBIT (Operating Profit) | C17: ($000) | D17: =D11+D13 | E17: =E11+E13 | F17: =F11+F13 | G17: =G11+G13 | H17: =H11+H13
D19: =D17+D20+D21 | E19: =E17+E20+E21 | F19: =F17+F20+F21 | G19: =G17+G20+G21 | H19: =H17+H20+H21
B20: Interest Expense | C20: ($000) | E20: -104.4 | F20: -230.4 | G20: -319.3 | H20: -285.1
B21: Interest Income | C21: ($000) | E21: 25.8 | F21: 161.4 | G21: 123.5 | H21: 116.8
B22: Earnings Before Tax (EBT) | C22: ($000) | D22: =D19 | E22: =E19 | F22: =F19 | G22: =G19 | H22: =H19
D24: =-ROUND(D22*0.21,0) | E24: =-ROUND(E22*E104,0) | F24: =-ROUND(F22*F104,0) | G24: =-ROUND(G22*G104,0) | H24: =-ROUND(H22*H104,0)
B25: Income Tax Expense | C25: ($000) | E25: -225.1 | F25: -252.2 | G25: -247.3 | H25: -396.5
B26: Net Income | C26: ($000) | D26: =D22+D24 | E26: =E22+E24 | F26: =F22+F24 | G26: =G22+G24 | H26: =H22+H24
B29: Common Dividends | C29: ($000) | E29: -350.7 | F29: -491 | G29: -275.4 | H29: -45.2
B30: EBITDA | C30: ($000) | D30: =D17-D16 | E30: =E17-E16 | F30: =F17-F16 | G30: =G17-G16 | H30: =H17-H16
B32: BALANCE SHEET
B34: Cash & Cash Equivalents | C34: ($000) | E34: 5099.6 | F34: 3979.9 | G34: 4767.1 | H34: 4446.5
B35: Accounts Receivable | C35: ($000) | E35: 3634.8 | F35: 3858.2 | G35: 4418.4 | H35: 3969
B36: Inventories | C36: ($000) | E36: 3672.3 | F36: 4250.8 | G36: 4935.5 | H36: 4964.2
B37: Other Current Assets | C37: ($000) | E37: 2941 | F37: 3388 | G37: 5362 | H37: -0.1
B38: Total Current Assets | C38: ($000) | D38: =SUM(D34:D37) | E38: =SUM(E34:E37) | F38: =SUM(F34:F37) | G38: =SUM(G34:G37) | H38: =SUM(H34:H37)
B41: PP&E (Net) | C41: ($000) | E41: 3478.9 | F41: 3596.1 | G41: 3715.5 | H41: 3899.2
B42: Intangible Assets | C42: ($000) | E42: 7035.8 | F42: 10227.7 | G42: 11431.9 | H42: 10526.6
B43: Other Long-Term Assets | C43: ($000) | E43: 3865 | F43: 4531 | G43: -0.01 | H43: 4664
B44: Total Assets | C44: ($000) | D44: =D38+SUM(D41:D43) | E44: =E38+SUM(E41:E43) | F44: =F38+SUM(F41:F43) | G44: =G38+SUM(G41:G43) | H44: =H38+SUM(H41:H43)
B47: Accounts Payable | C47: ($000) | E47: 2507.6 | F47: 2741.1 | G47: 3008.4 | H47: 2952.7
B48: Short-Term Debt | C48: ($000) | E48: 1480.3 | F48: 2713.3 | G48: 3272.5 | H48: 2130.1
B49: Income Tax Payable | C49: ($000) | E49: 1576.3 | F49: 1882.6 | G49: 1980.5 | H49: 2143
B50: Other Current Liabilities | C50: ($000) | E50: 749.2 | F50: 768.5 | G50: 876.6 | H50: 1932
B51: Total Current Liabilities | C51: ($000) | D51: =SUM(D47:D50) | E51: =SUM(E47:E50) | F51: =SUM(F47:F50) | G51: =SUM(G47:G50) | H51: =SUM(H47:H50)
B54: Long-Term Debt | C54: ($000) | E54: 3991.1 | F54: 5720.3 | G54: 4550.9 | H54: 3999.4
B55: Total Liabilities | C55: ($000) | D55: =D51+D54 | E55: =E51+E54 | F55: =F51+F54 | G55: =G51+G54 | H55: =H51+H54
B58: Common Equity (Paid-In Capital) | C58: ($000) | E58: 4716.8 | F58: 4336.2 | G58: 3750.4 | H58: 3750.4
B59: Retained Earnings | C59: ($000) | E59: 3222.3 | F59: 3372.3 | G59: 4079.3 | H59: 5001.1
...

Sheet RATIOS
B1: FinSight | F1: RATIOS — Financial Ratio Analysis
B3: RATIOS
B5: Year | E5: =IF(INPUT!E5="","",INPUT!E5) | F5: =IF(INPUT!F5="","",INPUT!F5) | G5: =IF(INPUT!G5="","",INPUT!G5) | H5: =IF(INPUT!H5="","",INPUT!H5)
B7: VALUATION RATIOS
B9: Price / Earnings (P/E) | D9: =IFERROR(INPUT!D95/( INPUT!D26/INPUT!D96),"–") | E9: =IFERROR(INPUT!E95/(INPUT!E26/INPUT!E96),"–") | F9: =IFERROR(INPUT!F95/(INPUT!F26/INPUT!F96),"–") | G9: =IFERROR(INPUT!G95/(INPUT!G26/INPUT!G96),"–") | H9: =IFERROR(INPUT!H95/(INPUT!H26/INPUT!H96),"–")
B10: EV / EBITDA | D10: =IFERROR(INPUT!D98/INPUT!D30,"–") | E10: =IFERROR(INPUT!E98/INPUT!E30,"–") | F10: =IFERROR(INPUT!F98/INPUT!F30,"–") | G10: =IFERROR(INPUT!G98/INPUT!G30,"–") | H10: =IFERROR(INPUT!H98/INPUT!H30,"–")
B11: EV / Revenue | D11: =IFERROR(INPUT!D98/INPUT!D9,"–") | E11: =IFERROR(INPUT!E98/INPUT!E9,"–") | F11: =IFERROR(INPUT!F98/INPUT!F9,"–") | G11: =IFERROR(INPUT!G98/INPUT!G9,"–") | H11: =IFERROR(INPUT!H98/INPUT!H9,"–")
B12: EV / EBIT | D12: =IFERROR(INPUT!D98/INPUT!D17,"–") | E12: =IFERROR(INPUT!E98/INPUT!E17,"–") | F12: =IFERROR(INPUT!F98/INPUT!F17,"–") | G12: =IFERROR(INPUT!G98/INPUT!G17,"–") | H12: =IFERROR(INPUT!H98/INPUT!H17,"–")
B13: Price / Book (P/B) | D13: =IFERROR(INPUT!D97/INPUT!D60,"–") | E13: =IFERROR(INPUT!E97/INPUT!E60,"–") | F13: =IFERROR(INPUT!F97/INPUT!F60,"–") | G13: =IFERROR(INPUT!G97/INPUT!G60,"–") | H13: =IFERROR(INPUT!H97/INPUT!H60,"–")
B14: Price / Sales (P/S) | D14: =IFERROR(INPUT!D97/INPUT!D9,"–") | E14: =IFERROR(INPUT!E97/INPUT!E9,"–") | F14: =IFERROR(INPUT!F97/INPUT!F9,"–") | G14: =IFERROR(INPUT!G97/INPUT!G9,"–") | H14: =IFERROR(INPUT!H97/INPUT!H9,"–")
B15: Earnings Per Share (EPS) | D15: =IFERROR(INPUT!D26/INPUT!D96,"–") | E15: =IFERROR(INPUT!E26/INPUT!E96,"–") | F15: =IFERROR(INPUT!F26/INPUT!F96,"–") | G15: =IFERROR(INPUT!G26/INPUT!G96,"–") | H15: =IFERROR(INPUT!H26/INPUT!H96,"–")
B17: PROFITABILITY RATIOS
B19: Gross Profit Margin | D19: =IFERROR(INPUT!D11/INPUT!D9,"–") | E19: =IFERROR(INPUT!E11/INPUT!E9,"–") | F19: =IFERROR(INPUT!F11/INPUT!F9,"–") | G19: =IFERROR(INPUT!G11/INPUT!G9,"–") | H19: =IFERROR(INPUT!H11/INPUT!H9,"–")
B20: EBITDA Margin | D20: =IFERROR(INPUT!D30/INPUT!D9,"–") | E20: =IFERROR(INPUT!E30/INPUT!E9,"–") | F20: =IFERROR(INPUT!F30/INPUT!F9,"–") | G20: =IFERROR(INPUT!G30/INPUT!G9,"–") | H20: =IFERROR(INPUT!H30/INPUT!H9,"–")
B21: EBIT (Operating) Margin | D21: =IFERROR(INPUT!D17/INPUT!D9,"–") | E21: =IFERROR(INPUT!E17/INPUT!E9,"–") | F21: =IFERROR(INPUT!F17/INPUT!F9,"–") | G21: =IFERROR(INPUT!G17/INPUT!G9,"–") | H21: =IFERROR(INPUT!H17/INPUT!H9,"–")
B22: Net Profit Margin | D22: =IFERROR(INPUT!D26/INPUT!D9,"–") | E22: =IFERROR(INPUT!E26/INPUT!E9,"–") | F22: =IFERROR(INPUT!F26/INPUT!F9,"–") | G22: =IFERROR(INPUT!G26/INPUT!G9,"–") | H22: =IFERROR(INPUT!H26/INPUT!H9,"–")
B23: Return on Equity (ROE) | D23: =IFERROR(INPUT!D26/INPUT!D60,"–") | E23: =IFERROR(INPUT!E26/INPUT!E60,"–") | F23: =IFERROR(INPUT!F26/INPUT!F60,"–") | G23: =IFERROR(INPUT!G26/INPUT!G60,"–") | H23: =IFERROR(INPUT!H26/INPUT!H60,"–")
B24: Return on Assets (ROA) | D24: =IFERROR(INPUT!D26/INPUT!D44,"–") | E24: =IFERROR(INPUT!E26/INPUT!E44,"–") | F24: =IFERROR(INPUT!F26/INPUT!F44,"–") | G24: =IFERROR(INPUT!G26/INPUT!G44,"–") | H24: =IFERROR(INPUT!H26/INPUT!H44,"–")
B25: Return on Invested Capital (ROIC) | D25: =IFERROR(INPUT!D17*(1-INPUT!D104)/(INPUT!D58+INPUT!D59),"–") | E25: =IFERROR(INPUT!E17*(1-INPUT!E104)/(INPUT!E58+INPUT!E59),"–") | F25: =IFERROR(INPUT!F17*(1-INPUT!F104)/(INPUT!F58+INPUT!F59),"–") | G25: =IFERROR(INPUT!G17*(1-INPUT!G104)/(INPUT!G58+INPUT!G59),"–") | H25: =IFERROR(INPUT!H17*(1-INPUT!H104)/(INPUT!H58+INPUT!H59),"–")
B27: LIQUIDITY & SOLVENCY RATIOS
B29: Current Ratio | D29: =IFERROR(INPUT!D38/INPUT!D51,"–") | E29: =IFERROR(INPUT!E38/INPUT!E51,"–") | F29: =IFERROR(INPUT!F38/INPUT!F51,"–") | G29: =IFERROR(INPUT!G38/INPUT!G51,"–") | H29: =IFERROR(INPUT!H38/INPUT!H51,"–")
B30: Quick Ratio | D30: =IFERROR((INPUT!D38-INPUT!D36)/INPUT!D51,"–") | E30: =IFERROR((INPUT!E38-INPUT!E36)/INPUT!E51,"–") | F30: =IFERROR((INPUT!F38-INPUT!F36)/INPUT!F51,"–") | G30: =IFERROR((INPUT!G38-INPUT!G36)/INPUT!G51,"–") | H30: =IFERROR((INPUT!H38-INPUT!H36)/INPUT!H51,"–")
B31: Cash Ratio | D31: =IFERROR(INPUT!D34/INPUT!D51,"–") | E31: =IFERROR(INPUT!E34/INPUT!E51,"–") | F31: =IFERROR(INPUT!F34/INPUT!F51,"–") | G31: =IFERROR(INPUT!G34/INPUT!G51,"–") | H31: =IFERROR(INPUT!H34/INPUT!H51,"–")
B32: Debt / Equity Ratio | D32: =IFERROR((INPUT!D49+INPUT!D55)/INPUT!D60,"–") | E32: =IFERROR((INPUT!E49+INPUT!E55)/INPUT!E60,"–") | F32: =IFERROR((INPUT!F49+INPUT!F55)/INPUT!F60,"–") | G32: =IFERROR((INPUT!G49+INPUT!G55)/INPUT!G60,"–") | H32: =IFERROR((INPUT!H49+INPUT!H55)/INPUT!H60,"–")
B33: Net Debt / EBITDA | D33: =IFERROR((INPUT!D49+INPUT!D55-INPUT!D34)/INPUT!D30,"–") | E33: =IFERROR((INPUT!E49+INPUT!E55-INPUT!E34)/INPUT!E30,"–") | F33: =IFERROR((INPUT!F49+INPUT!F55-INPUT!F34)/INPUT!F30,"–") | G33: =IFERROR((INPUT!G49+INPUT!G55-INPUT!G34)/INPUT!G30,"–") | H33: =IFERROR((INPUT!H49+INPUT!H55-INPUT!H34)/INPUT!H30,"–")
B34: Interest Coverage (EBIT/Interest) | D34: =IFERROR(INPUT!D17/ABS(INPUT!D20),"–") | E34: =IFERROR(INPUT!E17/ABS(INPUT!E20),"–") | F34: =IFERROR(INPUT!F17/ABS(INPUT!F20),"–") | G34: =IFERROR(INPUT!G17/ABS(INPUT!G20),"–") | H34: =IFERROR(INPUT!H17/ABS(INPUT!H20),"–")
B35: Debt / Total Assets | D35: =IFERROR((INPUT!D49+INPUT!D55)/INPUT!D44,"–") | E35: =IFERROR((INPUT!E49+INPUT!E55)/INPUT!E44,"–") | F35: =IFERROR((INPUT!F49+INPUT!F55)/INPUT!F44,"–") | G35: =IFERROR((INPUT!G49+INPUT!G55)/INPUT!G44,"–") | H35: =IFERROR((INPUT!H49+INPUT!H55)/INPUT!H44,"–")
B36: Equity Ratio | D36: =IFERROR(INPUT!D60/INPUT!D44,"–") | E36: =IFERROR(INPUT!E60/INPUT!E44,"–") | F36: =IFERROR(INPUT!F60/INPUT!F44,"–") | G36: =IFERROR(INPUT!G60/INPUT!G44,"–") | H36: =IFERROR(INPUT!H60/INPUT!H44,"–")
B38: OPERATIONAL EFFICIENCY RATIOS
B40: Asset Turnover | D40: =IFERROR(INPUT!D9/INPUT!D44,"–") | E40: =IFERROR(INPUT!E9/INPUT!E44,"–") | F40: =IFERROR(INPUT!F9/INPUT!F44,"–") | G40: =IFERROR(INPUT!G9/INPUT!G44,"–") | H40: =IFERROR(INPUT!H9/INPUT!H44,"–")
B41: Inventory Turnover | D41: =IFERROR(ABS(INPUT!D10)/INPUT!D36,"–") | E41: =IFERROR(ABS(INPUT!E10)/INPUT!E36,"–") | F41: =IFERROR(ABS(INPUT!F10)/INPUT!F36,"–") | G41: =IFERROR(ABS(INPUT!G10)/INPUT!G36,"–") | H41: =IFERROR(ABS(INPUT!H10)/INPUT!H36,"–")
B42: Days Inventory Outstanding (DIO) | D42: =IFERROR(INPUT!D36/ABS(INPUT!D10)*INPUT!D110,"–") | E42: =IFERROR(INPUT!E36/ABS(INPUT!E10)*INPUT!E110,"–") | F42: =IFERROR(INPUT!F36/ABS(INPUT!F10)*INPUT!F110,"–") | G42: =IFERROR(INPUT!G36/ABS(INPUT!G10)*INPUT!G110,"–") | H42: =IFERROR(INPUT!H36/ABS(INPUT!H10)*INPUT!H110,"–")
B43: Receivables Turnover | D43: =IFERROR(INPUT!D9/INPUT!D35,"–") | E43: =IFERROR(INPUT!E9/INPUT!E35,"–") | F43: =IFERROR(INPUT!F9/INPUT!F35,"–") | G43: =IFERROR(INPUT!G9/INPUT!G35,"–") | H43: =IFERROR(INPUT!H9/INPUT!H35,"–")
B44: Days Sales Outstanding (DSO) | D44: =IFERROR(INPUT!D35/INPUT!D9*INPUT!D110,"–") | E44: =IFERROR(INPUT!E35/INPUT!E9*INPUT!E110,"–") | F44: =IFERROR(INPUT!F35/INPUT!F9*INPUT!F110,"–") | G44: =IFERROR(INPUT!G35/INPUT!G9*INPUT!G110,"–") | H44: =IFERROR(INPUT!H35/INPUT!H9*INPUT!H110,"–")
B45: Days Payable Outstanding (DPO) | D45: =IFERROR(INPUT!D48/ABS(INPUT!D10)*INPUT!D110,"–") | E45: =IFERROR(INPUT!E48/ABS(INPUT!E10)*INPUT!E110,"–") | F45: =IFERROR(INPUT!F48/ABS(INPUT!F10)*INPUT!F110,"–") | G45: =IFERROR(INPUT!G48/ABS(INPUT!G10)*INPUT!G110,"–") | H45: =IFERROR(INPUT!H48/ABS(INPUT!H10)*INPUT!H110,"–")
B46: Cash Conversion Cycle (CCC) | D46: =IFERROR(D42+D44-D45,"–") | E46: =IFERROR(E42+E44-E45,"–") | F46: =IFERROR(F42+F44-F45,"–") | G46: =IFERROR(G42+G44-G45,"–") | H46: =IFERROR(H42+H44-H45,"–")
B47: Fixed Asset Turnover | D47: =IFERROR(INPUT!D9/INPUT!D41,"–") | E47: =IFERROR(INPUT!E9/INPUT!E41,"–") | F47: =IFERROR(INPUT!F9/INPUT!F41,"–") | G47: =IFERROR(INPUT!G9/INPUT!G41,"–") | H47: =IFERROR(INPUT!H9/INPUT!H41,"–")
B49: GROWTH RATIOS
B51: Revenue Growth (YoY) | D51: – | E51: =IFERROR(INPUT!E9/INPUT!D9-1,"–") | F51: =IFERROR(INPUT!F9/INPUT!E9-1,"–") | G51: =IFERROR(INPUT!G9/INPUT!F9-1,"–") | H51: =IFERROR(INPUT!H9/INPUT!G9-1,"–")
B52: Gross Profit Growth (YoY) | D52: – | E52: =IFERROR(INPUT!E11/INPUT!D11-1,"–") | F52: =IFERROR(INPUT!F11/INPUT!E11-1,"–") | G52: =IFERROR(INPUT!G11/INPUT!F11-1,"–") | H52: =IFERROR(INPUT!H11/INPUT!G11-1,"–")
...

Sheet ALTMAN Z-SCORE
B1: FinSight | F1: ALTMAN Z-SCORE — Bankruptcy Risk
B3: ALTMAN Z-SCORE
B5: COMPONENT | E5: =IF(INPUT!E5="","",INPUT!E5) | F5: =IF(INPUT!F5="","",INPUT!F5) | G5: =IF(INPUT!G5="","",INPUT!G5) | H5: =IF(INPUT!H5="","",INPUT!H5)
B7: INTERMEDIATE CALCULATIONS
B8: Working Capital | D8: =IFERROR(INPUT!D38-INPUT!D51,"–") | E8: =IFERROR(INPUT!E38-INPUT!E51,"–") | F8: =IFERROR(INPUT!F38-INPUT!F51,"–") | G8: =IFERROR(INPUT!G38-INPUT!G51,"–") | H8: =IFERROR(INPUT!H38-INPUT!H51,"–")
B9: Total Assets | D9: =INPUT!D44 | E9: =INPUT!E44 | F9: =INPUT!F44 | G9: =INPUT!G44 | H9: =INPUT!H44
B10: Retained Earnings | D10: =INPUT!D59 | E10: =INPUT!E59 | F10: =INPUT!F59 | G10: =INPUT!G59 | H10: =INPUT!H59
B11: EBIT | D11: =INPUT!D17 | E11: =INPUT!E17 | F11: =INPUT!F17 | G11: =INPUT!G17 | H11: =INPUT!H17
B12: Market Cap (Book Value of Equity) | D12: =INPUT!D60 | E12: =INPUT!E60 | F12: =INPUT!F60 | G12: =INPUT!G60 | H12: =INPUT!H60
B13: Total Liabilities | D13: =INPUT!D55 | E13: =INPUT!E55 | F13: =INPUT!F55 | G13: =INPUT!G55 | H13: =INPUT!H55
B14: Revenue | D14: =INPUT!D9 | E14: =INPUT!E9 | F14: =INPUT!F9 | G14: =INPUT!G9 | H14: =INPUT!H9
B16: 5 ALTMAN Z-SCORE COMPONENTS
B17: X1 = Working Capital / Total Assets | D17: =IFERROR(D8/D9,"–") | E17: =IFERROR(E8/E9,"–") | F17: =IFERROR(F8/F9,"–") | G17: =IFERROR(G8/G9,"–") | H17: =IFERROR(H8/H9,"–")
B18: X2 = Retained Earnings / Total Assets | D18: =IFERROR(D10/D9,"–") | E18: =IFERROR(E10/E9,"–") | F18: =IFERROR(F10/F9,"–") | G18: =IFERROR(G10/G9,"–") | H18: =IFERROR(H10/H9,"–")
B19: X3 = EBIT / Total Assets | D19: =IFERROR(D11/D9,"–") | E19: =IFERROR(E11/E9,"–") | F19: =IFERROR(F11/F9,"–") | G19: =IFERROR(G11/G9,"–") | H19: =IFERROR(H11/H9,"–")
B20: X4 = Equity / Total Liabilities | D20: =IFERROR(D12/D13,"–") | E20: =IFERROR(E12/E13,"–") | F20: =IFERROR(F12/F13,"–") | G20: =IFERROR(G12/G13,"–") | H20: =IFERROR(H12/H13,"–")
B21: X5 = Revenue / Total Assets | D21: =IFERROR(D14/D9,"–") | E21: =IFERROR(E14/E9,"–") | F21: =IFERROR(F14/F9,"–") | G21: =IFERROR(G14/G9,"–") | H21: =IFERROR(H14/H9,"–")
B23: ALTMAN Z-SCORE CALCULATION
B24: 1.2 × X1 | D24: =IFERROR(1.2*D17,"–") | E24: =IFERROR(1.2*E17,"–") | F24: =IFERROR(1.2*F17,"–") | G24: =IFERROR(1.2*G17,"–") | H24: =IFERROR(1.2*H17,"–")
B25: 1.4 × X2 | D25: =IFERROR(1.4*D18,"–") | E25: =IFERROR(1.4*E18,"–") | F25: =IFERROR(1.4*F18,"–") | G25: =IFERROR(1.4*G18,"–") | H25: =IFERROR(1.4*H18,"–")
B26: 3.3 × X3 | D26: =IFERROR(3.3*D19,"–") | E26: =IFERROR(3.3*E19,"–") | F26: =IFERROR(3.3*F19,"–") | G26: =IFERROR(3.3*G19,"–") | H26: =IFERROR(3.3*H19,"–")
B27: 0.6 × X4 | D27: =IFERROR(0.6*D20,"–") | E27: =IFERROR(0.6*E20,"–") | F27: =IFERROR(0.6*F20,"–") | G27: =IFERROR(0.6*G20,"–") | H27: =IFERROR(0.6*H20,"–")
B28: 1.0 × X5 | D28: =IFERROR(1*D21,"–") | E28: =IFERROR(1*E21,"–") | F28: =IFERROR(1*F21,"–") | G28: =IFERROR(1*G21,"–") | H28: =IFERROR(1*H21,"–")
B30: Z-SCORE (FINAL) | D30: =IFERROR(D24+D25+D26+D27+D28,"–") | E30: =IFERROR(E24+E25+E26+E27+E28,"–") | F30: =IFERROR(F24+F25+F26+F27+F28,"–") | G30: =IFERROR(G24+G25+G26+G27+G28,"–") | H30: =IFERROR(H24+H25+H26+H27+H28,"–")
B32: ZONE INTERPRETATION
B33: ZONE | D33: =IFERROR(IF(D30>2.99,"SAFE",IF(D30>=1.81,"GREY","DISTRESS")),"–") | E33: =IFERROR(IF(E30>2.99,"SAFE",IF(E30>=1.81,"GREY","DISTRESS")),"–") | F33: =IFERROR(IF(F30>2.99,"SAFE",IF(F30>=1.81,"GREY","DISTRESS")),"–") | G33: =IFERROR(IF(G30>2.99,"SAFE",IF(G30>=1.81,"GREY","DISTRESS")),"–") | H33: =IFERROR(IF(H30>2.99,"SAFE",IF(H30>=1.81,"GREY","DISTRESS")),"–")
B35: SAFE ZONE | D35: Low probability of bankruptcy
B36: GREY ZONE | D36: Some risk — monitor closely
B37: DISTRESS ZONE | D37: High probability of bankruptcy
B39: NOTE: Altman Z-Score was developed by Edward Altman (1968) for publicly traded manufacturing companies.
B40: Modified versions exist for private companies (Z') and non-manufacturing firms (Z'').

Sheet BENEISH M-SCORE
B1: FinSight | F1: BENEISH M-SCORE — Earnings Manipulation
B3: BENEISH M-SCORE
B5: INDEX / COMPONENT | E5: =IF(INPUT!H5="","",INPUT!H5) | F5: Year t (Current)
B7: BASE FINANCIAL DATA (from INPUT)
B9: Net Sales (Revenue) | E9: =INPUT!E9 | F9: =INPUT!F9
B10: Cost of Goods Sold | E10: =ABS(INPUT!E10) | F10: =ABS(INPUT!F10)
B11: Gross Profit | E11: =INPUT!E11 | F11: =INPUT!F11
B12: Total Current Assets | E12: =INPUT!E38 | F12: =INPUT!F38
B13: PP&E (Net) | E13: =INPUT!E41 | F13: =INPUT!F41
B14: Total Assets | E14: =INPUT!E44 | F14: =INPUT!F44
B15: Total Current Liabilities | E15: =INPUT!E51 | F15: =INPUT!F51
B16: Long-Term Debt | E16: =INPUT!E54 | F16: =INPUT!F54
B17: Net Income | E17: =INPUT!E26 | F17: =INPUT!F26
B18: Cash from Operations (CFO) | E18: =INPUT!E75 | F18: =INPUT!F75
B19: Depreciation & Amortization | E19: =INPUT!E16 | F19: =INPUT!F16
B20: SG&A Expense | E20: =ABS(INPUT!E14) | F20: =ABS(INPUT!F14)
B22: 8 BENEISH INDICES
B24: DSRI — Days Sales Receivable Index | F24: =IFERROR((INPUT!F35/INPUT!F9)/(INPUT!E35/INPUT!E9),"–")
B25: GMI — Gross Margin Index | F25: =IFERROR((E11/E9)/(F11/F9),"–")
B26: AQI — Asset Quality Index | F26: =IFERROR((1-(F12+F13)/F14)/(1-(E12+E13)/E14),"–")
B27: SGI — Sales Growth Index | F27: =IFERROR(F9/E9,"–")
B28: DEPI — Depreciation Index | F28: =IFERROR((E19/(E19+E13))/(F19/(F19+F13)),"–")
B29: SGAI — SG&A Expense Index | F29: =IFERROR((F20/F9)/(E20/E9),"–")
B30: TATA — Total Accruals to Total Assets | F30: =IFERROR((F17-F18)/F14,"–")
B31: LVGI — Leverage Index | F31: =IFERROR(((F16+F15)/F14)/((E16+E15)/E14),"–")
B33: M-SCORE WEIGHTED CALCULATION
B35: Constant | F35: =-4.84
B36: 0.920 × DSRI | F36: =IFERROR(0.92*F24,"–")
B37: 0.528 × GMI | F37: =IFERROR(0.528*F25,"–")
B38: 0.404 × AQI | F38: =IFERROR(0.404*F26,"–")
B39: 0.892 × SGI | F39: =IFERROR(0.892*F27,"–")
B40: 0.115 × DEPI | F40: =IFERROR(0.115*F28,"–")
B41: -0.172 × SGAI | F41: =IFERROR(-0.172*F29,"–")
B42: 4.679 × TATA | F42: =IFERROR(4.679*F30,"–")
B43: -0.327 × LVGI | F43: =IFERROR(-0.327*F31,"–")
B45: M-SCORE (FINAL) | F45: =IFERROR(F35+F36+F37+F38+F39+F40+F41+F42+F43,"–")
B47: INTERPRETATION
B48: RESULT | F48: =IF(ISNUMBER(F45),IF(F45>-2.22,"⚠ POSSIBLE MANIPULATOR (M > -2.22)","✓ NOT LIKELY MANIPULATOR (M ≤ -2.22)"),"–")
B50: NOT LIKELY MANIPULATOR
B51: POSSIBLE MANIPULATOR
...

Sheet DCF
B1: FinSight | K1: DCF — Discounted Cash Flow Valuation
B3: DCF
B4: All figures in USD thousands unless stated
B5: METRIC | C5: (Units) | D5: =IF(INPUT!D5="","",INPUT!D5) | E5: =IF(INPUT!E5="","",INPUT!E5) | F5: =IF(INPUT!F5="","",INPUT!F5) | G5: =IF(INPUT!G5="","",INPUT!G5) | H5: =IF(INPUT!H5="","",INPUT!H5) | I5: =TEXT(INPUT!D117+1,"0")&"F" | J5: =TEXT(INPUT!D117+2,"0")&"F" | K5: =TEXT(INPUT!D117+3,"0")&"F" | L5: =TEXT(INPUT!D117+4,"0")&"F" | M5: =TEXT(INPUT!D117+5,"0")&"F" | N5: Terminal
B7: INCOME STATEMENT
B9: Revenue | D9: =INPUT!D9 | E9: =INPUT!E9 | F9: =INPUT!F9 | G9: =INPUT!G9 | H9: =IF(INPUT!H9<>"",INPUT!H9,INPUT!G9) | I9: =H9*(1+$I$29) | J9: =I9*(1+$I$29) | K9: =J9*(1+$I$29) | L9: =K9*(1+$I$29) | M9: =L9*(1+$I$29)
B10: Cost of Goods Sold | D10: =INPUT!D10 | E10: =INPUT!E10 | F10: =INPUT!F10 | G10: =INPUT!G10 | H10: =IF(INPUT!H10<>"",INPUT!H10,INPUT!G10) | I10: =-I9*(1-$I$30) | J10: =-J9*(1-$I$30) | K10: =-K9*(1-$I$30) | L10: =-L9*(1-$I$30) | M10: =-M9*(1-$I$30)
B11: Gross Profit | D11: =SUM(D9:D10) | E11: =SUM(E9:E10) | F11: =SUM(F9:F10) | G11: =SUM(G9:G10) | H11: =SUM(H9:H10) | I11: =SUM(I9:I10) | J11: =SUM(J9:J10) | K11: =SUM(K9:K10) | ... M11: =SUM(M9:M10)
B13: SG&A Expenses | D13: =INPUT!D14 | E13: =INPUT!E14 | F13: =INPUT!F14 | G13: =INPUT!G14 | H13: =IF(INPUT!H14<>"",INPUT!H14,INPUT!G14) | I13: =-I9*$I$31 | J13: =-J9*$I$31 | K13: =-K9*$I$31 | L13: =-L9*$I$31 | M13: =-M9*$I$31
B14: Research & Development | D14: =INPUT!D15 | E14: =INPUT!E15 | F14: =INPUT!F15 | G14: =INPUT!G15 | H14: =IF(INPUT!H15<>"",INPUT!H15,INPUT!G15) | I14: =-I9*$I$32 | J14: =-J9*$I$32 | K14: =-K9*$I$32 | L14: =-L9*$I$32 | M14: =-M9*$I$32
B15: EBITDA | D15: =INPUT!D30 | E15: =INPUT!E30 | F15: =INPUT!F30 | G15: =INPUT!G30 | H15: =IF(INPUT!H30<>"",INPUT!H30,INPUT!G30) | I15: =I11+I13+I14 | J15: =J11+J13+J14 | K15: =K11+K13+K14 | L15: =L11+L13+L14 | M15: =M11+M13+M14
B17: Depreciation & Amortization | D17: =INPUT!D16 | E17: =INPUT!E16 | F17: =INPUT!F16 | G17: =INPUT!G16 | H17: =IF(INPUT!H16<>"",INPUT!H16,INPUT!G16) | I17: =-I9*$I$33 | J17: =-J9*$I$33 | K17: =-K9*$I$33 | L17: =-L9*$I$33 | M17: =-M9*$I$33
B18: EBIT (Operating Profit) | D18: =D15+D17 | E18: =E15+E17 | F18: =F15+F17 | G18: =G15+G17 | H18: =H15+H17 | I18: =I15+I17 | J18: =J15+J17 | K18: =K15+K17 | ... M18: =M15+M17
B20: Interest Expense | D20: =INPUT!D20 | E20: =INPUT!E20 | F20: =INPUT!F20 | G20: =INPUT!G20 | H20: =IF(INPUT!H20<>"",INPUT!H20,INPUT!G20) | I20: =-I18*(INPUT!H103)/(1-$I$34) | J20: =-J18*(INPUT!H103)/(1-$I$34) | K20: =-K18*(INPUT!H103)/(1-$I$34) | L20: =-L18*(INPUT!H103)/(1-$I$34) | M20: =-M18*(INPUT!H103)/(1-$I$34)
B21: Earnings Before Tax (EBT) | D21: =D18+D20 | E21: =E18+E20 | F21: =F18+F20 | G21: =G18+G20 | H21: =H18+H20 | I21: =I18+I20 | J21: =J18+J20 | K21: =K18+K20 | ... M21: =M18+M20
B23: Income Taxes | D23: =INPUT!D24 | E23: =INPUT!E24 | F23: =INPUT!F24 | G23: =INPUT!G24 | H23: =IF(INPUT!H24<>"",INPUT!H24,INPUT!G24) | I23: =-I21*$I$34 | J23: =-J21*$I$34 | K23: =-K21*$I$34 | L23: =-L21*$I$34 | M23: =-M21*$I$34
B24: Net Income | D24: =D21+D23 | E24: =E21+E23 | F24: =F21+F23 | G24: =G21+G23 | H24: =H21+H23 | I24: =I21+I23 | J24: =J21+J23 | K24: =K21+K23 | ... M24: =M21+M23
B26: ASSUMPTIONS & DRIVERS
B27: All figures in USD thousands unless stated
B28: INCOME STATEMENT DRIVERS | I28: =TEXT(INPUT!D117+1,"0")&"F" | J28: =TEXT(INPUT!D117+2,"0")&"F" | K28: =TEXT(INPUT!D117+3,"0")&"F" | L28: =TEXT(INPUT!D117+4,"0")&"F" | M28: =TEXT(INPUT!D117+5,"0")&"F"
B29: Revenue Growth Rate (YoY) | D29: =IFERROR(IF(NOT(ISBLANK(INPUT!H9)),INPUT!H9/INPUT!G9-1,IF(NOT(ISBLANK(INPUT!G9)),INPUT!G9/INPUT!F9-1,IF(NOT(ISBLANK(INPUT!F9)),INPUT!F9/INPUT!E9-1,IF(NOT(ISBLANK(INPUT!E9)),INPUT!E9/INPUT!D9-1,0.05)))),0.05) | E29: =I29 | F29: =I29 | I29: =IFERROR(AVERAGE(IF(ISNUMBER(RATIOS!F51),RATIOS!F51,0),IF(ISNUMBER(RATIOS!G51),RATIOS!G51,0),IF(ISNUMBER(RATIOS!H51),RATIOS!H51,0)),0.05) | J29: =I29 | K29: =I29 | L29: =I29 | M29: =I29
B30: Gross Margin | D30: =IFERROR(INPUT!H11/INPUT!H9,0.4) | E30: =I30 | F30: =I30 | I30: =IFERROR(AVERAGE(IF(INPUT!E9<>0,INPUT!E11/INPUT!E9),IF(INPUT!F9<>0,INPUT!F11/INPUT!F9),IF(INPUT!G9<>0,INPUT!G11/INPUT!G9),IF(INPUT!H9<>0,INPUT!H11/INPUT!H9)),0.4) | J30: =I30 | K30: =I30 | L30: =I30 | M30: =I30
B31: SG&A (% of Revenue) | D31: =IFERROR(ABS(INPUT!H14)/INPUT!H9,0.15) | E31: =I31 | F31: =I31 | I31: =IFERROR(AVERAGE(IF(INPUT!E9<>0,ABS(INPUT!E14)/INPUT!E9),IF(INPUT!F9<>0,ABS(INPUT!F14)/INPUT!F9),IF(INPUT!G9<>0,ABS(INPUT!G14)/INPUT!G9),IF(INPUT!H9<>0,ABS(INPUT!H14)/INPUT!H9)),0.15) | J31: =I31 | K31: =I31 | L31: =I31 | M31: =I31
B32: R&D (% of Revenue) | D32: =IFERROR(ABS(INPUT!H15)/INPUT!H9,0.05) | E32: =I32 | F32: =I32 | I32: =IFERROR(AVERAGE(IF(INPUT!E9<>0,ABS(INPUT!E15)/INPUT!E9),IF(INPUT!F9<>0,ABS(INPUT!F15)/INPUT!F9),IF(INPUT!G9<>0,ABS(INPUT!G15)/INPUT!G9),IF(INPUT!H9<>0,ABS(INPUT!H15)/INPUT!H9)),0.05) | J32: =I32 | K32: =I32 | L32: =I32 | M32: =I32
B33: D&A (% of Revenue) | D33: =IFERROR(ABS(INPUT!H16)/INPUT!H9,0.04) | E33: =I33 | F33: =I33 | I33: =IFERROR(AVERAGE(IF(INPUT!E9<>0,ABS(INPUT!E16)/INPUT!E9),IF(INPUT!F9<>0,ABS(INPUT!F16)/INPUT!F9),IF(INPUT!G9<>0,ABS(INPUT!G16)/INPUT!G9),IF(INPUT!H9<>0,ABS(INPUT!H16)/INPUT!H9)),0.04) | J33: =I33 | K33: =I33 | L33: =I33 | M33: =I33
B34: Effective Tax Rate | D34: =IFERROR(INPUT!H104,0.21) | E34: =I34 | F34: =I34 | I34: =IFERROR(AVERAGEIF(INPUT!E104:H104,"<>0"),0.21) | J34: =I34 | K34: =I34 | L34: =I34 | M34: =I34
B36: BALANCE SHEET / CASH FLOW DRIVERS
B37: CapEx (% of Revenue) | D37: =IFERROR(ABS(INPUT!H78)/INPUT!H9,0.05) | E37: =I37 | F37: =I37 | I37: =IFERROR(AVERAGE(IF(INPUT!E9<>0,ABS(INPUT!E78)/INPUT!E9),IF(INPUT!F9<>0,ABS(INPUT!F78)/INPUT!F9),IF(INPUT!G9<>0,ABS(INPUT!G78)/INPUT!G9),IF(INPUT!H9<>0,ABS(INPUT!H78)/INPUT!H9)),0.05) | J37: =I37 | K37: =I37 | L37: =I37 | M37: =I37
B38: Change in NWC (% of Revenue Change) | D38: =IFERROR(ABS((INPUT!H71+INPUT!H72+INPUT!H73)/INPUT!H9),0.1) | E38: =I38 | F38: =I38 | I38: =IFERROR(AVERAGE(IF(INPUT!E9<>0,ABS((INPUT!E71+INPUT!E72+INPUT!E73)/INPUT!E9)),IF(INPUT!F9<>0,ABS((INPUT!F71+INPUT!F72+INPUT!F73)/INPUT!F9)),IF(INPUT!G9<>0,ABS((INPUT!G71+INPUT!G72+INPUT!G73)/INPUT!G9)),IF(INPUT!H9<>0,ABS((INPUT!H71+INPUT!H72+INPUT!H73)/INPUT!H9))),0.1) | J38: =I38 | K38: =I38 | L38: =I38 | M38: =I38
B40: FREE CASH FLOW CALCULATION
B42: EBIT | D42: =D18 | E42: =E18 | F42: =F18 | G42: =G18 | H42: =H18 | I42: =I18 | J42: =J18 | K42: =K18 | ... M42: =M18
B43: (-) Taxes on EBIT (Unlevered) | D43: =D18*(-INPUT!D104) | E43: =E18*(-INPUT!E104) | F43: =F18*(-INPUT!F104) | G43: =G18*(-INPUT!G104) | H43: =H18*(-INPUT!H104) | I43: =I18*(-$I$34) | J43: =J18*(-$I$34) | K43: =K18*(-$I$34) | L43: =L18*(-$I$34) | M43: =M18*(-$I$34)
B44: NOPAT (Net Operating Profit After Tax) | D44: =D42+D43 | E44: =E42+E43 | F44: =F42+F43 | G44: =G42+G43 | H44: =H42+H43 | I44: =I42+I43 | J44: =J42+J43 | K44: =K42+K43 | ... M44: =M42+M43
B46: (+) Depreciation & Amortization | D46: =ABS(D17) | E46: =ABS(E17) | F46: =ABS(F17) | G46: =ABS(G17) | H46: =ABS(H17) | I46: =ABS(I17) | J46: =ABS(J17) | K46: =ABS(K17) | ... M46: =ABS(M17)
B47: (-) Capital Expenditures (CapEx) | D47: =INPUT!D78 | E47: =INPUT!E78 | F47: =INPUT!F78 | G47: =INPUT!G78 | H47: =IF(INPUT!H78<>"",INPUT!H78,INPUT!G78) | I47: =-I9*$I$37 | J47: =-J9*$I$37 | K47: =-K9*$I$37 | L47: =-L9*$I$37 | M47: =-M9*$I$37
B48: (-) Change in Working Capital | D48: =INPUT!D70+INPUT!D71+INPUT!D72+INPUT!D73 | E48: =INPUT!E70+INPUT!E71+INPUT!E72+INPUT!E73 | F48: =INPUT!F70+INPUT!F71+INPUT!F72+INPUT!F73 | G48: =INPUT!G70+INPUT!G71+INPUT!G72+INPUT!G73 | H48: =IF(INPUT!H70<>"",INPUT!H70,INPUT!G70)+IF(INPUT!H71<>"",INPUT!H71,INPUT!G71)+IF(INPUT!H72<>"",INPUT!H72,INPUT!G72)+IF(INPUT!H73<>"",INPUT!H73,INPUT!G73) | I48: =-(I9-H9)*$I$38 | J48: =-(J9-I9)*$I$38 | K48: =-(K9-J9)*$I$38 | L48: =-(L9-K9)*$I$38 | M48: =-(M9-L9)*$I$38
B49: Unlevered Free Cash Flow (UFCF) | D49: =D44+D46+D47+D48 | E49: =E44+E46+E47+E48 | F49: =F44+F46+F47+F48 | G49: =G44+G46+G47+G48 | H49: =H44+H46+H47+H48 | I49: =I44+I46+I47+I48 | J49: =J44+J46+J47+J48 | K49: =K44+K46+K47+K48 | ... M49: =M44+M46+M47+M48
B51: WACC CALCULATION (Capital Asset Pricing Model)
B53: Risk-Free Rate (Rf) | D53: =INPUT!H100 | N53: =D53
B54: Beta (Levered) | D54: =INPUT!H99 | N54: =D54
...

Sheet COMPARABLES
B1: FinSight | K1: COMPARABLES — Trading Comparables
B3: COMPARABLES
B4: All figures in USD millions unless stated
B6: COMPARABLE TRADING ANALYSIS
D7: Share Price | E7: Enterprise Value | F7: Revenue (LTM) | G7: EBITDA (LTM) | H7: EV / EBITDA | I7: EV / Revenue | J7: EPS (LTM) | K7: P / E (LTM)
B8: PEER COMPANIES | C8: TICKER | D8: (USD/sh) | E8: ($M) | F8: ($M) | G8: ($M) | H8: (x) | I8: (x) | J8: (USD/sh) | K8: (x)
B9: THALES.PA | C9: THALES.PA | D9: 75.33 | E9: 173303.61 | F9: 185019.01 | G9: 17629 | H9: =IFERROR(E9/G9,"–") | I9: =IFERROR(E9/F9,"–") | J9: 15.98 | K9: =IFERROR(D9/J9,"–")
B10: 24558 | C10: BAE.L | D10: 11.62 | E10: 183371.55 | F10: 187267.01 | G10: 5393 | H10: =IFERROR(E10/G10,"–") | I10: =IFERROR(E10/F10,"–") | J10: 10.81 | K10: =IFERROR(D10/J10,"–")
B11: Lockheed Martin Corporation | C11: LMT | D11: 628.5 | E11: 163255.44 | F11: 75048 | G11: 8285 | H11: =IFERROR(E11/G11,"–") | I11: =IFERROR(E11/F11,"–") | J11: 23.5 | K11: =IFERROR(D11/J11,"–")
B12: General Dynamics Corporation | C12: GD | D12: 350.02 | E12: 144410 | F12: 133453 | G12: 15742 | H12: =IFERROR(E12/G12,"–") | I12: =IFERROR(E12/F12,"–") | J12: 1.3 | K12: =IFERROR(D12/J12,"–")
B13: RTX Corporation | C13: RTX | D13: 203.48 | E13: 258704.92 | F13: 321913 | G13: 24292 | H13: =IFERROR(E13/G13,"–") | I13: =IFERROR(E13/F13,"–") | K13: =IFERROR(D13/J13,"–")
B15: Mean | D15: =IFERROR(AVERAGE(D9:D13),"–") | E15: =IFERROR(AVERAGE(E9:E13),"–") | F15: =IFERROR(AVERAGE(F9:F13),"–") | G15: =IFERROR(AVERAGE(G9:G13),"–") | H15: =IFERROR(AVERAGE(H9:H13),"–") | I15: =IFERROR(AVERAGE(I9:I13),"–") | J15: =IFERROR(AVERAGE(J9:J13),"–") | K15: =IFERROR(AVERAGE(K9:K13),"–")
B16: Median | D16: =IFERROR(MEDIAN(D9:D13),"–") | E16: =IFERROR(MEDIAN(E9:E13),"–") | F16: =IFERROR(MEDIAN(F9:F13),"–") | G16: =IFERROR(MEDIAN(G9:G13),"–") | H16: =IFERROR(MEDIAN(H9:H13),"–") | I16: =IFERROR(MEDIAN(I9:I13),"–") | J16: =IFERROR(MEDIAN(J9:J13),"–") | K16: =IFERROR(MEDIAN(K9:K13),"–")
B17: Maximum | D17: =IFERROR(MAX(D9:D13),"–") | E17: =IFERROR(MAX(E9:E13),"–") | F17: =IFERROR(MAX(F9:F13),"–") | G17: =IFERROR(MAX(G9:G13),"–") | H17: =IFERROR(MAX(H9:H13),"–") | I17: =IFERROR(MAX(I9:I13),"–") | J17: =IFERROR(MAX(J9:J13),"–") | K17: =IFERROR(MAX(K9:K13),"–")
B18: Minimum | D18: =IFERROR(MIN(D9:D13),"–") | E18: =IFERROR(MIN(E9:E13),"–") | F18: =IFERROR(MIN(F9:F13),"–") | G18: =IFERROR(MIN(G9:G13),"–") | H18: =IFERROR(MIN(H9:H13),"–") | I18: =IFERROR(MIN(I9:I13),"–") | J18: =IFERROR(MIN(J9:J13),"–") | K18: =IFERROR(MIN(K9:K13),"–")
B20: TARGET COMPANY VALUATION (Based on Peer Multiples)
B21: TARGET COMPANY METRICS (from INPUT) | D21: =INPUT!H5
B22: Target: Revenue (LTM) | C22: ($M) | D22: =INPUT!H9/1000
B23: Target: EBITDA (LTM) | C23: ($M) | D23: =INPUT!H30/1000
B24: Target: EPS (LTM) | C24: ($) | D24: =IFERROR(INPUT!F26/INPUT!F96,"–")
B25: Target: Net Debt | C25: ($M) | D25: =IFERROR((INPUT!H54+INPUT!H55-INPUT!H34)/1000,"–")
B26: Target: Shares Outstanding | C26: (M) | D26: =INPUT!H96/1000
B28: IMPLIED VALUATION
B29: EV / EBITDA — Implied EV ($M) | D29: =IFERROR(D23*H18,"–") | E29: =IFERROR(D23*H15,"–") | F29: =IFERROR(D23*H16,"–") | G29: =IFERROR(D23*H17,"–")
B30: EV / Revenue — Implied EV ($M) | D30: =IFERROR(D22*I18,"–") | E30: =IFERROR(D22*I15,"–") | F30: =IFERROR(D22*I16,"–") | G30: =IFERROR(D22*I17,"–")
B31: P/E — Implied Equity Value ($M) | D31: =IFERROR(D24*K18*D26,"–") | E31: =IFERROR(D24*K15*D26,"–") | F31: =IFERROR(D24*K16*D26,"–") | G31: =IFERROR(D24*K17*D26,"–")
B33: Implied Enterprise Value (Average of 3 Methods) | C33: ($M) | D33: =IFERROR(AVERAGE(D29,D30),"–") | E33: =IFERROR(AVERAGE(E29,E30),"–") | F33: =IFERROR(AVERAGE(F29,F30),"–") | G33: =IFERROR(AVERAGE(G29,G30),"–")
B34: (-) Net Debt | C34: ($M) | D34: =D25 | E34: =D25 | F34: =D25 | G34: =D25
B35: Implied Equity Value ($M) | C35: ($M) | D35: =IFERROR(D33-D34,"–") | E35: =IFERROR(E33-E34,"–") | F35: =IFERROR(F33-F34,"–") | G35: =IFERROR(G33-G34,"–")
B36: Implied Share Price ($) | C36: ($) | D36: =IFERROR(D35/D26,"–") | E36: =IFERROR(E35/D26,"–") | F36: =IFERROR(F35/D26,"–") | G36: =IFERROR(G35/D26,"–")
B37: Current Share Price ($) | C37: ($) | D37: =INPUT!H95 | E37: =INPUT!H95 | F37: =INPUT!H95 | G37: =INPUT!H95
B38: Implied Upside / (Downside) | C38: (%) | D38: =IFERROR(D36/D37-1,"–") | E38: =IFERROR(E36/D37-1,"–") | F38: =IFERROR(F36/D37-1,"–") | G38: =IFERROR(G36/D37-1,"–")
B41: (1) Target company EV based on LTM EV/EBITDA and EV/Revenue multiples relative to comparable peer set.
B43: © 2015 to 2024 FinSight
B44: This Excel model is for educational purposes only.
B45: https://finsight.com/
B47: Company | C47: EV/EBITDA (x) | D47: EV/Revenue (x) | E47: P/E (x)
B48: =B9 | C48: =IFERROR(H9*1,0) | D48: =IFERROR(I9*1,0) | E48: =IFERROR(K9*1,0)
B49: =B10 | C49: =IFERROR(H10*1,0) | D49: =IFERROR(I10*1,0) | E49: =IFERROR(K10*1,0)
B50: =B11 | C50: =IFERROR(H11*1,0) | D50: =IFERROR(I11*1,0) | E50: =IFERROR(K11*1,0)
...

Sheet SCENARIOS
B1: FinSight | H1: SCENARIOS — Scenario Analysis
B3: SCENARIOS
B4: All figures in USD thousands unless stated | 3 scenarios: Pessimistic / Realistic (Base) / Optimistic
B5: METRIC | C5: (Units) | E5: =TEXT(INPUT!D117-3,"0") | F5: =TEXT(INPUT!D117-2,"0") | G5: =TEXT(INPUT!D117-1,"0") | H5: =INPUT!D117&" (LTM)" | I5: =TEXT(INPUT!D117+1,"0")&"F" | J5: =TEXT(INPUT!D117+2,"0")&"F" | K5: =TEXT(INPUT!D117+3,"0")&"F" | L5: =TEXT(INPUT!D117+4,"0")&"F" | M5: =TEXT(INPUT!D117+5,"0")&"F"
B6: ▶ SELECT SCENARIO | D6: Realistic
B7: SCENARIO ASSUMPTIONS
B8: DRIVER | C8: (Units) | D8: Pessimistic | E8: Realistic | F8: Optimistic
B9: Revenue Growth Rate (Y1-Y5) | C9: (%) | D9: {=IFERROR(INDEX(SECTOR_REF!$C$2:$E$61,MATCH(1,(SECTOR_REF!$A$2:$A$61=INPUT!$D$116)*(SECTOR_REF!$B$2:$B$61="Revenue Growth Rate (Y1-Y5)"),0),MATCH("Pessimiste",{"Pessimiste","Realiste","Optimiste"},0)),IFERROR(INPUT!H9/INPUT!G9-1,0.02))} | E9: {=IFERROR(INDEX(SECTOR_REF!$C$2:$E$61,MATCH(1,(SECTOR_REF!$A$2:$A$61=INPUT!$D$116)*(SECTOR_REF!$B$2:$B$61="Revenue Growth Rate (Y1-Y5)"),0),MATCH("Realiste",{"Pessimiste","Realiste","Optimiste"},0)),IFERROR(INPUT!H9/INPUT!G9-1,0.05))} | F9: {=IFERROR(INDEX(SECTOR_REF!$C$2:$E$61,MATCH(1,(SECTOR_REF!$A$2:$A$61=INPUT!$D$116)*(SECTOR_REF!$B$2:$B$61="Revenue Growth Rate (Y1-Y5)"),0),MATCH("Optimiste",{"Pessimiste","Realiste","Optimiste"},0)),IFERROR(INPUT!H9/INPUT!G9-1,0.09))}
B10: Gross Margin | C10: (%) | D10: {=IFERROR(INDEX(SECTOR_REF!$C$2:$E$61,MATCH(1,(SECTOR_REF!$A$2:$A$61=INPUT!$D$116)*(SECTOR_REF!$B$2:$B$61="Gross Margin"),0),MATCH("Pessimiste",{"Pessimiste","Realiste","Optimiste"},0)),IFERROR(INPUT!H11/INPUT!H9,0.4)-0.03)} | E10: {=IFERROR(INDEX(SECTOR_REF!$C$2:$E$61,MATCH(1,(SECTOR_REF!$A$2:$A$61=INPUT!$D$116)*(SECTOR_REF!$B$2:$B$61="Gross Margin"),0),MATCH("Realiste",{"Pessimiste","Realiste","Optimiste"},0)),IFERROR(INPUT!H11/INPUT!H9,0.4))} | F10: {=IFERROR(INDEX(SECTOR_REF!$C$2:$E$61,MATCH(1,(SECTOR_REF!$A$2:$A$61=INPUT!$D$116)*(SECTOR_REF!$B$2:$B$61="Gross Margin"),0),MATCH("Optimiste",{"Pessimiste","Realiste","Optimiste"},0)),IFERROR(INPUT!H11/INPUT!H9,0.4)+0.03)}
B11: EBITDA Margin | C11: (%) | D11: {=IFERROR(INDEX(SECTOR_REF!$C$2:$E$61,MATCH(1,(SECTOR_REF!$A$2:$A$61=INPUT!$D$116)*(SECTOR_REF!$B$2:$B$61="EBITDA Margin"),0),MATCH("Pessimiste",{"Pessimiste","Realiste","Optimiste"},0)),IFERROR(INPUT!H30/INPUT!H9,0.15)-0.03)} | E11: {=IFERROR(INDEX(SECTOR_REF!$C$2:$E$61,MATCH(1,(SECTOR_REF!$A$2:$A$61=INPUT!$D$116)*(SECTOR_REF!$B$2:$B$61="EBITDA Margin"),0),MATCH("Realiste",{"Pessimiste","Realiste","Optimiste"},0)),IFERROR(INPUT!H30/INPUT!H9,0.15))} | F11: {=IFERROR(INDEX(SECTOR_REF!$C$2:$E$61,MATCH(1,(SECTOR_REF!$A$2:$A$61=INPUT!$D$116)*(SECTOR_REF!$B$2:$B$61="EBITDA Margin"),0),MATCH("Optimiste",{"Pessimiste","Realiste","Optimiste"},0)),IFERROR(INPUT!H30/INPUT!H9,0.15)+0.03)}
B12: Terminal Growth Rate | C12: (%) | D12: {=IFERROR(INDEX(SECTOR_REF!$C$2:$E$61,MATCH(1,(SECTOR_REF!$A$2:$A$61=INPUT!$D$116)*(SECTOR_REF!$B$2:$B$61="Terminal Growth Rate"),0),MATCH("Pessimiste",{"Pessimiste","Realiste","Optimiste"},0)),DCF!D67-0.01)} | E12: {=IFERROR(INDEX(SECTOR_REF!$C$2:$E$61,MATCH(1,(SECTOR_REF!$A$2:$A$61=INPUT!$D$116)*(SECTOR_REF!$B$2:$B$61="Terminal Growth Rate"),0),MATCH("Realiste",{"Pessimiste","Realiste","Optimiste"},0)),DCF!D67)} | F12: {=IFERROR(INDEX(SECTOR_REF!$C$2:$E$61,MATCH(1,(SECTOR_REF!$A$2:$A$61=INPUT!$D$116)*(SECTOR_REF!$B$2:$B$61="Terminal Growth Rate"),0),MATCH("Optimiste",{"Pessimiste","Realiste","Optimiste"},0)),DCF!D67+0.01)}
B13: WACC | C13: (%) | D13: {=IFERROR(INDEX(SECTOR_REF!$C$2:$E$61,MATCH(1,(SECTOR_REF!$A$2:$A$61=INPUT!$D$116)*(SECTOR_REF!$B$2:$B$61="WACC"),0),MATCH("Pessimiste",{"Pessimiste","Realiste","Optimiste"},0)),DCF!D63+0.015)} | E13: {=IFERROR(INDEX(SECTOR_REF!$C$2:$E$61,MATCH(1,(SECTOR_REF!$A$2:$A$61=INPUT!$D$116)*(SECTOR_REF!$B$2:$B$61="WACC"),0),MATCH("Realiste",{"Pessimiste","Realiste","Optimiste"},0)),DCF!D63)} | F13: {=IFERROR(INDEX(SECTOR_REF!$C$2:$E$61,MATCH(1,(SECTOR_REF!$A$2:$A$61=INPUT!$D$116)*(SECTOR_REF!$B$2:$B$61="WACC"),0),MATCH("Optimiste",{"Pessimiste","Realiste","Optimiste"},0)),DCF!D63-0.015)}
B14: ▶ Secteur actif : | D14: =IF(INPUT!$D$116="","— Aucun secteur sélectionné (INPUT!D116) —",INPUT!$D$116)
B15: SCENARIO RESULTS — DYNAMIC VIEW
B16: METRIC | C16: (Units) | D16: =TEXT(INPUT!D117-3,"0") | E16: =TEXT(INPUT!D117-2,"0") | F16: =TEXT(INPUT!D117-1,"0") | G16: =INPUT!D117&" (LTM)" | H16: =TEXT(INPUT!D117+1,"0")&"F" | I16: =TEXT(INPUT!D117+2,"0")&"F" | J16: =TEXT(INPUT!D117+3,"0")&"F" | K16: =TEXT(INPUT!D117+4,"0")&"F" | L16: =TEXT(INPUT!D117+5,"0")&"F"
B17: Revenue | C17: 0 | D17: =INPUT!E9 | E17: =INPUT!F9 | F17: =INPUT!G9 | G17: =INPUT!H9 | H17: =INPUT!H9*(1+IF($D$6="Pessimistic",$D$9,IF($D$6="Realistic",$E$9,$F$9))) | I17: =H17*(1+IF($D$6="Pessimistic",$D$9,IF($D$6="Realistic",$E$9,$F$9))) | J17: =I17*(1+IF($D$6="Pessimistic",$D$9,IF($D$6="Realistic",$E$9,$F$9))) | K17: =J17*(1+IF($D$6="Pessimistic",$D$9,IF($D$6="Realistic",$E$9,$F$9))) | L17: =K17*(1+IF($D$6="Pessimistic",$D$9,IF($D$6="Realistic",$E$9,$F$9)))
B18: Gross Profit | C18: 0 | D18: =INPUT!E11 | E18: =INPUT!F11 | F18: =INPUT!G11 | G18: =INPUT!H11 | H18: =H17*IF($D$6="Pessimistic",$D$10,IF($D$6="Realistic",$E$10,$F$10)) | I18: =I17*IF($D$6="Pessimistic",$D$10,IF($D$6="Realistic",$E$10,$F$10)) | J18: =J17*IF($D$6="Pessimistic",$D$10,IF($D$6="Realistic",$E$10,$F$10)) | K18: =K17*IF($D$6="Pessimistic",$D$10,IF($D$6="Realistic",$E$10,$F$10)) | L18: =L17*IF($D$6="Pessimistic",$D$10,IF($D$6="Realistic",$E$10,$F$10))
B19: EBITDA | C19: 0 | D19: =INPUT!E30 | E19: =INPUT!F30 | F19: =INPUT!G30 | G19: =INPUT!H30 | H19: =H17*IF($D$6="Pessimistic",$D$11,IF($D$6="Realistic",$E$11,$F$11)) | I19: =I17*IF($D$6="Pessimistic",$D$11,IF($D$6="Realistic",$E$11,$F$11)) | J19: =J17*IF($D$6="Pessimistic",$D$11,IF($D$6="Realistic",$E$11,$F$11)) | K19: =K17*IF($D$6="Pessimistic",$D$11,IF($D$6="Realistic",$E$11,$F$11)) | L19: =L17*IF($D$6="Pessimistic",$D$11,IF($D$6="Realistic",$E$11,$F$11))
B20: Net Income | C20: 0 | D20: =INPUT!E26 | E20: =INPUT!F26 | F20: =INPUT!G26 | G20: =INPUT!H26 | H20: =H19*0.6 | I20: =I19*0.6 | J20: =J19*0.6 | K20: =K19*0.6 | L20: =L19*0.6
B21: Free Cash Flow (Est.) | C21: 0 | D21: =IFERROR(INPUT!E75+INPUT!E78,"–") | E21: =IFERROR(INPUT!F75+INPUT!F78,"–") | F21: =IFERROR(INPUT!G75+INPUT!G78,"–") | G21: =IFERROR(INPUT!H75+INPUT!H78,"–") | H21: =H19*0.5 | I21: =I19*0.5 | J21: =J19*0.5 | K21: =K19*0.5 | L21: =L19*0.5
B22: EBITDA Margin | C22: (%) | D22: =IFERROR(INPUT!E30/INPUT!E9,"–") | E22: =IFERROR(INPUT!F30/INPUT!F9,"–") | F22: =IFERROR(INPUT!G30/INPUT!G9,"–") | G22: =IFERROR(INPUT!H30/INPUT!H9,"–") | H22: =IFERROR(H19/H17,"–") | I22: =IFERROR(I19/I17,"–") | J22: =IFERROR(J19/J17,"–") | K22: =IFERROR(K19/K17,"–") | L22: =IFERROR(L19/L17,"–")
B23: Implied Share Price | C23: ($) | M23: =IFERROR("$"&TEXT(IF($D$6="Pessimistic",DCF!D91*(1+$D$9+$D$11-$E$9-$E$11)*0.8,IF($D$6="Realistic",DCF!D91,DCF!D91*(1+$F$9+$F$11-$E$9-$E$11)*1.2)),"#,##0.00"),"–")
B25: SCENARIO SUMMARY COMPARISON
B26: METRIC (Year 5) | D26: Pessimistic | E26: Realistic | F26: Optimistic
B27: Revenue (Year 5) | C27: 0 | D27: =INPUT!H9*(1+$D$9)^5 | E27: =INPUT!H9*(1+$E$9)^5 | F27: =INPUT!H9*(1+$F$9)^5
B28: EBITDA (Year 5) | C28: 0 | D28: =D27*$D$11 | E28: =E27*$E$11 | F28: =F27*$F$11
B29: Net Income (Year 5) | C29: 0 | D29: =D28*0.6 | E29: =E28*0.6 | F29: =F28*0.6
B30: FCF (Year 5) | C30: 0 | D30: =D28*0.5 | E30: =E28*0.5 | F30: =F28*0.5
B31: EBITDA Margin (Year 5) | C31: (%) | D31: =$D$11 | E31: =$E$11 | F31: =$F$11
B32: Implied Share Price | C32: ($) | D32: =IFERROR("$"&TEXT(DCF!D91*(1+$D$9+$D$11-$E$9-$E$11)*0.8,"#,##0.00"),"–") | E32: =IFERROR("$"&TEXT(DCF!D91,"#,##0.00"),"–") | F32: =IFERROR("$"&TEXT(DCF!D91*(1+$F$9+$F$11-$E$9-$E$11)*1.2,"#,##0.00"),"–")
B33: Delta (Opt. vs Pess.) | D33: ="—" | E33: ="—" | F33: =IFERROR(F27/D27-1,"–")
B34: Revenue
B35: ="▶ SCÉNARIO SÉLECTIONNÉ : "&$D$6
B37: CHART DATA: Revenue by Scenario
B38: Year | D38: =TEXT(INPUT!D117+1,"0")&"F" | E38: =TEXT(INPUT!D117+2,"0")&"F" | F38: =TEXT(INPUT!D117+3,"0")&"F" | G38: =TEXT(INPUT!D117+4,"0")&"F" | H38: =TEXT(INPUT!D117+5,"0")&"F"
B39: Pessimistic | D39: =IF(INPUT!H9="",NA(),INPUT!H9*(1+$D$9)) | E39: =IF(INPUT!H9="",NA(),D39*(1+$D$9)) | F39: =IF(INPUT!H9="",NA(),E39*(1+$D$9)) | G39: =IF(INPUT!H9="",NA(),F39*(1+$D$9)) | H39: =IF(INPUT!H9="",NA(),G39*(1+$D$9))
B40: Realistic | D40: =IF(INPUT!H9="",NA(),INPUT!H9*(1+$E$9)) | E40: =IF(INPUT!H9="",NA(),D40*(1+$E$9)) | F40: =IF(INPUT!H9="",NA(),E40*(1+$E$9)) | G40: =IF(INPUT!H9="",NA(),F40*(1+$E$9)) | H40: =IF(INPUT!H9="",NA(),G40*(1+$E$9))
B41: Optimistic | D41: =IF(INPUT!H9="",NA(),INPUT!H9*(1+$F$9)) | E41: =IF(INPUT!H9="",NA(),D41*(1+$F$9)) | F41: =IF(INPUT!H9="",NA(),E41*(1+$F$9)) | G41: =IF(INPUT!H9="",NA(),F41*(1+$F$9)) | H41: =IF(INPUT!H9="",NA(),G41*(1+$F$9))
B42: SCENARIO SUMMARY COMPARISON
B43: CHART DATA: EBITDA by Scenario
...

Sheet DASHBOARD
B1: FinSight | Q1: Année | R1: 2022 | S1: 2023 | T1: 2024
Q2: Année | R2: Cumul Revenue | S2: =RATIOS!F78 | T2: =RATIOS!G78
B3: Financial Performance | Q3: 2022 | R3: =RATIOS!E78
Q4: 2023 | R4: =RATIOS!F78
M5: ="All figures in "&INPUT!D118&" "&INPUT!D119&" unless stated" | Q5: 2024 | R5: =RATIOS!G78
Q7: Year | R7: Revenue | S7: Net Income | T7: Net Margin
B8: Revenue & Profitability | H8: Profit Margins | Q8: 2022 | R8: =RATIOS!E75 | S8: =RATIOS!E77 | T8: =RATIOS!E82
Q9: 2023 | R9: =RATIOS!F75 | S9: =RATIOS!F77 | T9: =RATIOS!F82
Q10: 2024 | R10: =RATIOS!G75 | S10: =RATIOS!G77 | T10: =RATIOS!G82
Q11: 2025 (LTM) | R11: =RATIOS!H75 | S11: =RATIOS!H77 | T11: =RATIOS!H82
B25: Cumulative revenue | H25: Expense Breakdown
B42: Performance Summary (Five-Year) | H42: Income Statement (LTM)
C44: 5-Yr Avg | D44: Trend | I44: Actual | J44: Prev Year | K44: Variance | L44: Var %
B45: Revenue | C45: =AVERAGE(INPUT!D9:H9) | H45: Revenue | I45: =INPUT!H9 | J45: =INPUT!G9 | K45: =I45-J45 | L45: =IF(J45=0,NA(),K45/ABS(J45))
B47: COGS | C47: =ABS(AVERAGE(INPUT!D10:H10)) | H47: COGS | I47: =ABS(INPUT!H10) | J47: =ABS(INPUT!G10) | K47: =I47-J47 | L47: =IF(J47=0,NA(),K47/ABS(J47))
B49: Expenses | C49: =ABS(AVERAGE(INPUT!D13:H13)) | H49: Expenses | I49: =ABS(INPUT!H13) | J49: =ABS(INPUT!G13) | K49: =I49-J49 | L49: =IF(J49=0,NA(),K49/ABS(J49))
B51: Net Income | C51: =AVERAGE(INPUT!D26:H26) | H51: Net Income | I51: =INPUT!H26 | J51: =INPUT!G26 | K51: =I51-J51 | L51: =IF(J51=0,NA(),K51/ABS(J51))
B53: Net Margin (%) | C53: =AVERAGE(INPUT!D26:H26)/AVERAGE(INPUT!D9:H9) | H53: Net Margin (%) | I53: =INPUT!H26/INPUT!H9 | J53: =INPUT!G26/INPUT!G9 | K53: =I53-J53 | L53: =IF(J53=0,NA(),K53/ABS(J53))
B58: P&L Summary (LTM) | C58: P&L Summary (LTM) | D58: P&L Summary (LTM) | E58: P&L Summary (LTM) | H58: Balance Sheet Summary (LTM)
B60: Revenue | D60: =INPUT!H9 | E60: =INPUT!H9 | H60: Assets
B61: COGS | D61: =INPUT!H10 | E61: =ABS(INPUT!H10) | H61: Current Assets | J61: =INPUT!H38 | K61: =INPUT!H38
H62: Non-current Assets | J62: =SUM(INPUT!H41:H43) | K62: =SUM(INPUT!H41:H43)
B63: Expenses | D63: =ABS(INPUT!H14)
B64: SG&A | D64: =ABS(INPUT!H15) | E64: =ABS(INPUT!H15) | H64: Total Assets | J64: =INPUT!H44 | K64: =INPUT!H44
B65: R&D | D65: =ABS(INPUT!H16) | E65: =ABS(INPUT!H16)
B66: D&A | D66: =ABS(INPUT!H20) | E66: =ABS(INPUT!H20) | H66: Liabilities | J66: =INPUT!H51
B67: Interest | D67: =SUM(D64:D66) | E67: =SUM(E64:E66) | H67: Current Liabilities | J67: =INPUT!H54 | K67: =INPUT!H51
B68: Total Expenses | D68: =SUM(D64:D67) | E68: =SUM(E64:E67) | H68: Long-term Liabilities | J68: =INPUT!H60 | K68: =INPUT!H54
H69: Shareholders' Equity | J69: =INPUT!F60 | K69: =INPUT!H60
D70: =D60+D61-D68 | J70: =INPUT!H63
B71: Net Operating Profit | D71: =D60+D61-D68 | E71: =E60-E61-E68 | H71: Liabilities & Shareholders' Equity | J71: =INPUT!F63 | K71: =INPUT!H63
C81: =IF(INPUT!D5="",NA(),INPUT!D5) | D81: =INPUT!E5 | E81: =INPUT!F5 | F81: =INPUT!G5 | G81: =INPUT!H5 | I81: =IF(INPUT!D5="",NA(),INPUT!D5) | J81: =INPUT!E5 | K81: =INPUT!F5 | L81: =INPUT!G5 | M81: =INPUT!H5
B82: Revenue | C82: =IF(INPUT!D9="",NA(),INPUT!D9) | D82: =IF(INPUT!E9="",NA(),INPUT!E9) | E82: =IF(INPUT!F9="",NA(),INPUT!F9) | F82: =IF(INPUT!G9="",NA(),INPUT!G9) | G82: =IF(INPUT!H9="",NA(),INPUT!H9)
C83: EBITDA | D83: =IF(INPUT!D30="",NA(),INPUT!D30) | E83: =IF(INPUT!E30="",NA(),INPUT!E30) | F83: =IF(INPUT!F30="",NA(),INPUT!F30) | G83: =IF(INPUT!G30="",NA(),INPUT!G30) | H83: =IF(INPUT!H30="",NA(),INPUT!H30)
C84: Net Income | D84: =IF(INPUT!D26="",NA(),INPUT!D26) | E84: =IF(INPUT!E26="",NA(),INPUT!E26) | F84: =IF(INPUT!F26="",NA(),INPUT!F26) | G84: =IF(INPUT!G26="",NA(),INPUT!G26) | H84: =IF(INPUT!H26="",NA(),INPUT!H26)
J85: =IF(INPUT!D5="",NA(),INPUT!D5) | K85: =INPUT!E5 | L85: =INPUT!F5 | M85: =INPUT!G5 | N85: =INPUT!H5
I86: Gross Margin | J86: =IF(INPUT!D9="",NA(),INPUT!D11/INPUT!D9) | K86: =IF(INPUT!E9="",NA(),INPUT!E11/INPUT!E9) | L86: =IF(INPUT!F9="",NA(),INPUT!F11/INPUT!F9) | M86: =IF(INPUT!G9="",NA(),INPUT!G11/INPUT!G9) | N86: =IF(INPUT!H9="",NA(),INPUT!H11/INPUT!H9)
I87: EBITDA Margin | J87: =IF(INPUT!D9="",NA(),INPUT!D30/INPUT!D9) | K87: =IF(INPUT!E9="",NA(),INPUT!E30/INPUT!E9) | L87: =IF(INPUT!F9="",NA(),INPUT!F30/INPUT!F9) | M87: =IF(INPUT!G9="",NA(),INPUT!G30/INPUT!G9) | N87: =IF(INPUT!H9="",NA(),INPUT!H30/INPUT!H9)
D88: =IF(INPUT!D5="",NA(),INPUT!D5) | E88: =INPUT!E5 | F88: =INPUT!F5 | G88: =INPUT!G5 | H88: =INPUT!H5 | I88: Net Margin | J88: =IF(INPUT!D9="",NA(),INPUT!D26/INPUT!D9) | K88: =IF(INPUT!E9="",NA(),INPUT!E26/INPUT!E9) | L88: =IF(INPUT!F9="",NA(),INPUT!F26/INPUT!F9) | M88: =IF(INPUT!G9="",NA(),INPUT!G26/INPUT!G9) | N88: =IF(INPUT!H9="",NA(),INPUT!H26/INPUT!H9)
C89: Revenue | D89: =IF(INPUT!D9="",NA(),INPUT!D9) | E89: =IF(INPUT!E9="",NA(),INPUT!E9) | F89: =IF(INPUT!F9="",NA(),INPUT!F9) | G89: =IF(INPUT!G9="",NA(),INPUT!G9) | H89: =IF(INPUT!H9="",NA(),INPUT!H9)
...

Sheet DASHBOARD 2
B1: FinSight | R1: =INPUT!D114&" ("&INPUT!D115&") — "&INPUT!D116
B3: Projected Business Performance | Q3: Football Field Chart — Valuation Inputs
B5: All figures in USD Thousands unless stated | T5: Low ($) | U5: Delta ($) | V5: High ($)
B6: Company Information | Q6: 52-Week Trading Range | T6: =INPUT!H95*0.75 | U6: =V6-T6 | V6: =INPUT!H95*1.45
C7: Company Name | D7: =INPUT!D114 | Q7: Consensus Research | T7: =INPUT!H95*1.1 | U7: =V7-T7 | V7: =INPUT!H95*1.6
C8: Ticker Symbol | D8: =INPUT!D115 | Q8: Precedent Transactions | T8: =INPUT!H95*1.2 | U8: =V8-T8 | V8: =INPUT!H95*1.75
C9: Sector | D9: =INPUT!D116 | Q9: Sum-of-the-Parts | T9: =INPUT!H95*1.3 | U9: =V9-T9 | V9: =INPUT!H95*1.85
C10: Base Year (LTM) | D10: =INPUT!D117 | Q10: Discounted Cash Flow | T10: =INPUT!H95*1.15 | U10: =V10-T10 | V10: =INPUT!H95*1.7
C11: Currency | D11: =INPUT!D118 | Q11: Current Share Price | T11: =INPUT!H95
C12: Analysis Date | D12: =INPUT!D120
Q15: Financial Data — Multi-Year
Q17: All figures in USD Thousands unless stated | T17: =INPUT!E5 | U17: =INPUT!E5 | V17: =INPUT!F5 | W17: =INPUT!G5 | X17: =INPUT!H5
B19: Stock Chart: Trailing 52-Weeks | I19: Valuation Summary: Football Field Chart | Q19: Revenue Growth (%) | T19: ="" | U19: =IF(INPUT!D9=0,"",INPUT!E9/INPUT!D9-1) | V19: =IF(INPUT!E9=0,"",INPUT!F9/INPUT!E9-1) | W19: =IF(INPUT!F9=0,"",INPUT!G9/INPUT!F9-1) | X19: =IF(INPUT!G9=0,"",INPUT!H9/INPUT!G9-1)
Q20: EBITDA Growth (%) | T20: ="" | U20: ="" | V20: =IF(INPUT!D30=0,"",INPUT!F30/INPUT!E30-1) | W20: =IF(INPUT!E30=0,"",INPUT!G30/INPUT!F30-1) | X20: =IF(INPUT!F30=0,"",INPUT!H30/INPUT!G30-1)
Q22: Revenue
Q23: Revenue — Products | T23: =INPUT!E9 | U23: =INPUT!E9 | V23: =INPUT!F9 | W23: =INPUT!G9 | X23: =INPUT!H9
Q24: Cost of Revenue (COGS) | T24: =ABS(INPUT!E10) | U24: =ABS(INPUT!E10) | V24: =ABS(INPUT!F10) | W24: =ABS(INPUT!G10) | X24: =ABS(INPUT!H10)
Q25: Gross Profit | T25: =INPUT!E11 | U25: =INPUT!E11 | V25: =INPUT!F11 | W25: =INPUT!G11 | X25: =INPUT!H11
Q26: SG&A | T26: =ABS(INPUT!E14) | U26: =ABS(INPUT!E14) | V26: =ABS(INPUT!F14) | W26: =ABS(INPUT!G14) | X26: =ABS(INPUT!H14)
Q27: Total Revenue | T27: =INPUT!E9 | U27: =INPUT!E9 | V27: =INPUT!F9 | W27: =INPUT!G9 | X27: =INPUT!H9
Q29: EBITDA | T29: =INPUT!E30 | U29: =INPUT!E30 | V29: =INPUT!F30 | W29: =INPUT!G30 | X29: =INPUT!H30
Q30: Cash from Ops (CFO) | T30: =INPUT!E75 | U30: =INPUT!E75 | V30: =INPUT!F75 | W30: =INPUT!G75 | X30: =INPUT!H75
Q31: Net Income | T31: =INPUT!E26 | U31: =INPUT!E26 | V31: =INPUT!F26 | W31: =INPUT!G26 | X31: =INPUT!H26
R34: ly
B39: Total Revenue ($000) | I39: Other Financial Metrics ($ Millier)
V84: Low | W84: Delta | X84: High
S85: 52-Week Trading Range | V85: =T6 | W85: =U6 | X85: =V6
S86: Consensus Research | V86: =T7 | W86: =U7 | X86: =V7
S87: Precedent Trans. | V87: =T8 | W87: =U8 | X87: =V8
S88: Sum-of-the-Parts | V88: =T9 | W88: =U9 | X88: =V9
S89: Discounted Cash Flow | V89: =T10 | W89: =U10 | X89: =V10
Q92: =K103 | R92: =L103 | S92: =M103 | T92: =N103
Q93: =IF(INPUT!E9="",NA(),INPUT!E30/1000) | R93: =IF(INPUT!F9="",NA(),INPUT!F30/1000) | S93: =IF(INPUT!G9="",NA(),INPUT!G30/1000) | T93: =IF(INPUT!H9="",NA(),INPUT!H30/1000)
Q94: =IF(INPUT!E9="",NA(),INPUT!E75/1000) | R94: =IF(INPUT!F9="",NA(),INPUT!F75/1000) | S94: =IF(INPUT!G9="",NA(),INPUT!G75/1000) | T94: =IF(INPUT!H9="",NA(),INPUT!H75/1000)
Q95: =IF(INPUT!E9="",NA(),INPUT!E26/1000) | S95: 2022 | T95: 2023 | U95: 2024 | V95: 2025 (LTM)
R96: EBITDA | S96: =U29 | T96: =V29 | U96: =W29 | V96: =X29
R97: CFO | S97: =U30 | T97: =V30 | U97: =W30 | V97: =X30
R98: Net Income | S98: =U31 | T98: =V31 | U98: =W31 | V98: =X31
B103: Year | C103: =IF(INPUT!D9="","",INPUT!D5) | D103: =IF(INPUT!E9="",NA(),'DASHBOARD 2'!U17) | E103: =IF(INPUT!F9="",NA(),'DASHBOARD 2'!V17) | F103: =IF(INPUT!G9="",NA(),'DASHBOARD 2'!W17) | G103: =IF(INPUT!H9="",NA(),'DASHBOARD 2'!X17) | I103: Year | J103: =IF(INPUT!D9="","",INPUT!D5) | K103: =IF(INPUT!E9="",NA(),'DASHBOARD 2'!U17) | L103: =IF(INPUT!F9="",NA(),'DASHBOARD 2'!V17) | M103: =IF(INPUT!G9="",NA(),'DASHBOARD 2'!W17) | N103: =IF(INPUT!H9="",NA(),'DASHBOARD 2'!X17) | P103: =J103
B104: Revenue Growth (%) | C104: ="" | D104: =IF(INPUT!E9="",NA(),'DASHBOARD 2'!U19) | E104: =IF(INPUT!F9="",NA(),'DASHBOARD 2'!V19) | F104: =IF(INPUT!G9="",NA(),'DASHBOARD 2'!W19) | G104: =IF(INPUT!H9="",NA(),'DASHBOARD 2'!X19) | I104: EBITDA ($000) | J104: =IF(INPUT!D9="","",INPUT!D30) | K104: =IF(INPUT!E9="",NA(),INPUT!E30) | L104: =IF(INPUT!F9="",NA(),INPUT!F30) | M104: =IF(INPUT!G9="",NA(),INPUT!G30) | N104: =IF(INPUT!H9="",NA(),INPUT!H30) | P104: =IF(INPUT!D9="",NA(),INPUT!D30/1000)
...

Sheet STOCK_DATA
A1: STOCK_DATA — Apple Inc. (AAPL) — Trailing 52 Weeks
A2: # | B2: Month | C2: Close Price ($)
A3: 1 | B3: May-25 | C3: 263.24
A4: 2 | B4: Jun-25 | C4: 248.52
A5: 3 | B5: Jul-25 | C5: 234.78
A6: 4 | B6: Aug-25 | C6: 224.23
A7: 5 | B7: Sep-25 | C7: 265.45
A8: 6 | B8: Oct-25 | C8: 245.83
A9: 7 | B9: Nov-25 | C9: 224.42
A10: 8 | B10: Dec-25 | C10: 228.81
A11: 9 | B11: Jan-26 | C11: 256
A12: 10 | B12: Feb-26 | C12: 254.9
A13: 11 | B13: Mar-26 | C13: 252.1
A14: 12 | B14: Apr-26 | C14: 267.3
A15: 13
A17: ⚠️ Données simulées. Remplacer par données réelles (Bloomberg/FactSet) en colonne B (Mois) et C (Prix).

Sheet SECTOR_REF
A1: Secteur | B1: Driver | C1: Pessimiste | D1: Realiste | E1: Optimiste
A2: Technologie / SaaS | B2: Revenue Growth Rate (Y1-Y5) | C2: 0.05 | D2: 0.12 | E2: 0.22
A3: Technologie / SaaS | B3: Gross Margin | C3: 0.55 | D3: 0.68 | E3: 0.78
A4: Technologie / SaaS | B4: EBITDA Margin | C4: 0.08 | D4: 0.18 | E4: 0.28
A5: Technologie / SaaS | B5: SG&A (% Revenue) | C5: 0.3 | D5: 0.22 | E5: 0.15
A6: Technologie / SaaS | B6: R&D (% Revenue) | C6: 0.18 | D6: 0.12 | E6: 0.08
A7: Technologie / SaaS | B7: CapEx (% Revenue) | C7: 0.08 | D7: 0.05 | E7: 0.03
A8: Technologie / SaaS | B8: Change in NWC (% Rev Change) | C8: 0.05 | D8: 0.03 | E8: 0.02
A9: Technologie / SaaS | B9: Terminal Growth Rate | C9: 0.02 | D9: 0.03 | E9: 0.04
A10: Technologie / SaaS | B10: WACC | C10: 0.11 | D10: 0.09 | E10: 0.07
A11: Technologie / SaaS | B11: EV/EBITDA Exit Multiple | C11: 12 | D11: 16 | E11: 22
A12: Industrie / Manufacturing | B12: Revenue Growth Rate (Y1-Y5) | C12: 0.01 | D12: 0.04 | E12: 0.07
A13: Industrie / Manufacturing | B13: Gross Margin | C13: 0.18 | D13: 0.25 | E13: 0.32
... A61: Sante / Pharma | B61: EV/EBITDA Exit Multiple | C61: 8 | D61: 12 | E61: 18
