Workbook
Name LBO_ELIGIBLE: 'LBO MODEL'!$C$62
Name LBO_EQUITY_ENTRY: 'LBO MODEL'!$C$69
Name LBO_EQUITY_EXIT: 'LBO MODEL'!$C$70
Name LBO_IRR_BASE: 'LBO MODEL'!$C$64
Name LBO_IRR_BEAR: 'LBO MODEL'!$C$67
Name LBO_IRR_BULL: 'LBO MODEL'!$C$66
Name LBO_LEVERAGE_EXIT: 'LBO MODEL'!$C$68
Name LBO_MEGA_FLAG: 'LBO MODEL'!$C$63
Name LBO_MOIC_BASE: 'LBO MODEL'!$C$65

Sheet INPUT
B3: INPUT — Raw Data
B4: All figures in USD millions unless stated
B5: METRIC | C5: UNIT | E5: 2022 | F5: 2023 | G5: 2024 | H5: 2025 (LTM)
B7: INPUT
B9: Revenue | C9: ($M) | E9: 394328 | F9: 383285 | G9: 391035 | H9: 416161
B10: Cost of Goods Sold (COGS) | C10: ($M) | E10: -223546 | F10: -214137 | G10: -210352 | H10: -220960
B11: Gross Profit | C11: ($M) | D11: =D9+D10 -> 0 | E11: =E9+E10 -> 170782 | F11: =F9+F10 -> 169148 | G11: =G9+G10 -> 180683 | H11: =H9+H10 -> 195201
D13: =SUM(D14:D16) -> 0 | E13: =SUM(E14:E16) -> -62449 | F13: =SUM(F14:F16) -> -66366 | G13: =SUM(G14:G16) -> -68912 | H13: =SUM(H14:H16) -> -73849
B14: Operating Expenses (SG&A) | C14: ($M) | E14: -25094 | F14: -24932 | G14: -26097 | H14: -27601
B15: Research & Development | C15: ($M) | E15: -26251 | F15: -29915 | G15: -31370 | H15: -34550
B16: Depreciation & Amortization | C16: ($M) | E16: -11104 | F16: -11519 | G16: -11445 | H16: -11698
B17: EBIT (Operating Profit) | C17: ($M) | D17: =D11+D13 -> 0 | E17: =E11+E13 -> 108333 | F17: =F11+F13 -> 102782 | G17: =G11+G13 -> 111771 | H17: =H11+H13 -> 121352
D19: =D17+D20+D21 -> 0 | E19: =E17+E20+E21 -> 108227 | F19: =F17+F20+F21 -> 102599 | G19: =G17+G20+G21 -> 111771 | H19: =H17+H20+H21 -> 121352
B20: Interest Expense | C20: ($M) | E20: -2931 | F20: -3933 | G20: 0 | H20: 0
B21: Interest Income | C21: ($M) | E21: 2825 | F21: 3750 | G21: 0 | H21: 0
B22: Earnings Before Tax (EBT) | C22: ($M) | D22: =D19 -> 0 | E22: =E19 -> 108227 | F22: =F19 -> 102599 | G22: =G19 -> 111771 | H22: =H19 -> 121352
D24: =-ROUND(D22*0.21,0) -> 0 | E24: =-ROUND(E22*E104,0) -> -17533 | F24: =-ROUND(F22*F104,0) -> -15103 | G24: =-ROUND(G22*G104,0) -> -26926 | H24: =-ROUND(H22*H104,0) -> -18895
B25: Income Tax Expense | C25: ($M) | E25: -19300 | F25: -16741 | G25: -29749 | H25: -20719
B26: Net Income | C26: ($M) | D26: =D22+D24 -> 0 | E26: =E22+E24 -> 90694 | F26: =F22+F24 -> 87496 | G26: =G22+G24 -> 84845 | H26: =H22+H24 -> 102457
B29: Common Dividends | C29: ($M) | E29: -89402 | F29: -77550 | G29: -94949 | H29: -90711
B30: EBITDA | C30: ($M) | D30: =D17-D16 -> 0 | E30: =E17-E16 -> 119437 | F30: =F17-F16 -> 114301 | G30: =G17-G16 -> 123216 | H30: =H17-H16 -> 133050
B32: BALANCE SHEET
B34: Cash & Cash Equivalents | C34: ($M) | E34: 23646 | F34: 29965 | G34: 29943 | H34: 35934
B35: Accounts Receivable | C35: ($M) | E35: 28184 | F35: 29508 | G35: 33410 | H35: 39777
B36: Inventories | C36: ($M) | E36: 4946 | F36: 6331 | G36: 7286 | H36: 5718
B37: Other Current Assets | C37: ($M) | E37: 21223 | F37: 14695 | G37: 14287 | H37: 14585
B38: Total Current Assets | C38: ($M) | D38: =SUM(D34:D37) -> 0 | E38: =SUM(E34:E37) -> 77999 | F38: =SUM(F34:F37) -> 80499 | G38: =SUM(G34:G37) -> 84926 | H38: =SUM(H34:H37) -> 96014
B41: PP&E (Net) | C41: ($M) | E41: 42117 | F41: 43715 | G41: 45680 | H41: 49834
B42: Intangible Assets | C42: ($M) | E42: 593 | F42: 615 | G42: 1470 | H42: 1389
B43: Other Long-Term Assets | C43: ($M) | E43: 39053 | F43: 46906 | G43: 55335 | H43: 62950
B44: Total Assets | C44: ($M) | D44: =D38+SUM(D41:D43) -> 0 | E44: =E38+SUM(E41:E43) -> 159762 | F44: =F38+SUM(F41:F43) -> 171735 | G44: =G38+SUM(G41:G43) -> 187411 | H44: =H38+SUM(H41:H43) -> 210187
B47: Accounts Payable | C47: ($M) | E47: 64115 | F47: 62611 | G47: 68960 | H47: 69860
B48: Short-Term Debt | C48: ($M) | E48: 21110 | F48: 15807 | G48: 20879 | H48: 20329
B49: Income Tax Payable | C49: ($M) | E49: 6552 | F49: 8819 | G49: 26601 | H49: 13016
B50: Other Current Liabilities | C50: ($M) | E50: 52630 | F50: 50010 | G50: 44024 | H50: 44452
B51: Total Current Liabilities | C51: ($M) | D51: =SUM(D47:D50) -> 0 | E51: =SUM(E47:E50) -> 144407 | F51: =SUM(F47:F50) -> 137247 | G51: =SUM(G47:G50) -> 160464 | H51: =SUM(H47:H50) -> 147657
B54: Long-Term Debt | C54: ($M) | E54: 98959 | F54: 95281 | G54: 85750 | H54: 78328
B55: Total Liabilities | C55: ($M) | D55: =D51+D54 -> 0 | E55: =E51+E54 -> 243366 | F55: =F51+F54 -> 232528 | G55: =G51+G54 -> 246214 | H55: =H51+H54 -> 225985
B58: Common Equity (Paid-In Capital) | C58: ($M) | E58: 64849 | F58: 73812 | G58: 83276 | H58: 93568
B59: Retained Earnings | C59: ($M) | E59: -3068 | F59: -214 | G59: -19154 | H59: -14264
...

Sheet RATIOS
B1: FinSight | F1: RATIOS — Financial Ratio Analysis
B3: RATIOS
B5: Year | E5: =IF(INPUT!E5="","",INPUT!E5) -> 2022 | F5: =IF(INPUT!F5="","",INPUT!F5) -> 2023 | G5: =IF(INPUT!G5="","",INPUT!G5) -> 2024 | H5: =IF(INPUT!H5="","",INPUT!H5) -> 2025 (LTM)
B7: VALUATION RATIOS
B9: Price / Earnings (P/E) | D9: =IFERROR(INPUT!D95/( INPUT!D26/INPUT!D96),"–") -> – | E9: =IFERROR(INPUT!E95/(INPUT!E26/INPUT!E96),"–") -> 23.242442 | F9: =IFERROR(INPUT!F95/(INPUT!F26/INPUT!F96),"–") -> 31.627446 | G9: =IFERROR(INPUT!G95/(INPUT!G26/INPUT!G96),"–") -> 41.041994 | H9: =IFERROR(INPUT!H95/(INPUT!H26/INPUT!H96),"–") -> 37.441872
B10: EV / EBITDA | D10: =IFERROR(INPUT!D98/INPUT!D30,"–") -> – | E10: =IFERROR(INPUT!E98/INPUT!E30,"–") -> 18.456366 | F10: =IFERROR(INPUT!F98/INPUT!F30,"–") -> 24.920149 | G10: =IFERROR(INPUT!G98/INPUT!G30,"–") -> 28.883376 | H10: =IFERROR(INPUT!H98/INPUT!H30,"–") -> 29.304058
B11: EV / Revenue | D11: =IFERROR(INPUT!D98/INPUT!D9,"–") -> – | E11: =IFERROR(INPUT!E98/INPUT!E9,"–") -> 5.5902016 | F11: =IFERROR(INPUT!F98/INPUT!F9,"–") -> 7.4315405 | G11: =IFERROR(INPUT!G98/INPUT!G9,"–") -> 9.101216 | H11: =IFERROR(INPUT!H98/INPUT!H9,"–") -> 9.3687416
B12: EV / EBIT | D12: =IFERROR(INPUT!D98/INPUT!D17,"–") -> – | E12: =IFERROR(INPUT!E98/INPUT!E17,"–") -> 20.348121 | F12: =IFERROR(INPUT!F98/INPUT!F17,"–") -> 27.713004 | G12: =IFERROR(INPUT!G98/INPUT!G17,"–") -> 31.840943 | H12: =IFERROR(INPUT!H98/INPUT!H17,"–") -> 32.128889
B13: Price / Book (P/B) | D13: =IFERROR(INPUT!D97/INPUT!D60,"–") -> – | E13: =IFERROR(INPUT!E97/INPUT!E60,"–") -> 34.119713 | F13: =IFERROR(INPUT!F97/INPUT!F60,"–") -> 37.599867 | G13: =IFERROR(INPUT!G97/INPUT!G60,"–") -> 54.305979 | H13: =IFERROR(INPUT!H97/INPUT!H60,"–") -> 48.37312
B14: Price / Sales (P/S) | D14: =IFERROR(INPUT!D97/INPUT!D9,"–") -> – | E14: =IFERROR(INPUT!E97/INPUT!E9,"–") -> 5.3456767 | F14: =IFERROR(INPUT!F97/INPUT!F9,"–") -> 7.2198886 | G14: =IFERROR(INPUT!G97/INPUT!G9,"–") -> 8.9051057 | H14: =IFERROR(INPUT!H97/INPUT!H9,"–") -> 9.2180235
B15: Earnings Per Share (EPS) | D15: =IFERROR(INPUT!D26/INPUT!D96,"–") -> – | E15: =IFERROR(INPUT!E26/INPUT!E96,"–") -> 5.5932162 | F15: =IFERROR(INPUT!F26/INPUT!F96,"–") -> 5.5331689 | G15: =IFERROR(INPUT!G26/INPUT!G96,"–") -> 5.506555 | H15: =IFERROR(INPUT!H26/INPUT!H96,"–") -> 6.9788177
B17: PROFITABILITY RATIOS
B19: Gross Profit Margin | D19: =IFERROR(INPUT!D11/INPUT!D9,"–") -> – | E19: =IFERROR(INPUT!E11/INPUT!E9,"–") -> 0.43309631 | F19: =IFERROR(INPUT!F11/INPUT!F9,"–") -> 0.4413113 | G19: =IFERROR(INPUT!G11/INPUT!G9,"–") -> 0.4620635 | H19: =IFERROR(INPUT!H11/INPUT!H9,"–") -> 0.46905164
B20: EBITDA Margin | D20: =IFERROR(INPUT!D30/INPUT!D9,"–") -> – | E20: =IFERROR(INPUT!E30/INPUT!E9,"–") -> 0.30288744 | F20: =IFERROR(INPUT!F30/INPUT!F9,"–") -> 0.29821412 | G20: =IFERROR(INPUT!G30/INPUT!G9,"–") -> 0.31510223 | H20: =IFERROR(INPUT!H30/INPUT!H9,"–") -> 0.319708
B21: EBIT (Operating) Margin | D21: =IFERROR(INPUT!D17/INPUT!D9,"–") -> – | E21: =IFERROR(INPUT!E17/INPUT!E9,"–") -> 0.27472815 | F21: =IFERROR(INPUT!F17/INPUT!F9,"–") -> 0.26816077 | G21: =IFERROR(INPUT!G17/INPUT!G9,"–") -> 0.28583375 | H21: =IFERROR(INPUT!H17/INPUT!H9,"–") -> 0.29159868
B22: Net Profit Margin | D22: =IFERROR(INPUT!D26/INPUT!D9,"–") -> – | E22: =IFERROR(INPUT!E26/INPUT!E9,"–") -> 0.22999635 | F22: =IFERROR(INPUT!F26/INPUT!F9,"–") -> 0.22827922 | G22: =IFERROR(INPUT!G26/INPUT!G9,"–") -> 0.21697546 | H22: =IFERROR(INPUT!H26/INPUT!H9,"–") -> 0.24619558
B23: Return on Equity (ROE) | D23: =IFERROR(INPUT!D26/INPUT!D60,"–") -> – | E23: =IFERROR(INPUT!E26/INPUT!E60,"–") -> 1.4679918 | F23: =IFERROR(INPUT!F26/INPUT!F60,"–") -> 1.1888367 | G23: =IFERROR(INPUT!G26/INPUT!G60,"–") -> 1.3231808 | H23: =IFERROR(INPUT!H26/INPUT!H60,"–") -> 1.2919525
B24: Return on Assets (ROA) | D24: =IFERROR(INPUT!D26/INPUT!D44,"–") -> – | E24: =IFERROR(INPUT!E26/INPUT!E44,"–") -> 0.56768193 | F24: =IFERROR(INPUT!F26/INPUT!F44,"–") -> 0.50948263 | G24: =IFERROR(INPUT!G26/INPUT!G44,"–") -> 0.45272156 | H24: =IFERROR(INPUT!H26/INPUT!H44,"–") -> 0.48745641
B25: Return on Invested Capital (ROIC) | D25: =IFERROR(INPUT!D17*(1-INPUT!D104)/(INPUT!D58+INPUT!D59),"–") -> – | E25: =IFERROR(INPUT!E17*(1-INPUT!E104)/(INPUT!E58+INPUT!E59),"–") -> 1.4694332 | F25: =IFERROR(INPUT!F17*(1-INPUT!F104)/(INPUT!F58+INPUT!F59),"–") -> 1.1909629 | G25: =IFERROR(INPUT!G17*(1-INPUT!G104)/(INPUT!G58+INPUT!G59),"–") -> 1.3231865 | H25: =IFERROR(INPUT!H17*(1-INPUT!H104)/(INPUT!H58+INPUT!H59),"–") -> 1.2919587
B27: LIQUIDITY & SOLVENCY RATIOS
B29: Current Ratio | D29: =IFERROR(INPUT!D38/INPUT!D51,"–") -> – | E29: =IFERROR(INPUT!E38/INPUT!E51,"–") -> 0.5401331 | F29: =IFERROR(INPUT!F38/INPUT!F51,"–") -> 0.58652648 | G29: =IFERROR(INPUT!G38/INPUT!G51,"–") -> 0.52925267 | H29: =IFERROR(INPUT!H38/INPUT!H51,"–") -> 0.65025024
B30: Quick Ratio | D30: =IFERROR((INPUT!D38-INPUT!D36)/INPUT!D51,"–") -> – | E30: =IFERROR((INPUT!E38-INPUT!E36)/INPUT!E51,"–") -> 0.50588268 | F30: =IFERROR((INPUT!F38-INPUT!F36)/INPUT!F51,"–") -> 0.54039797 | G30: =IFERROR((INPUT!G38-INPUT!G36)/INPUT!G51,"–") -> 0.48384684 | H30: =IFERROR((INPUT!H38-INPUT!H36)/INPUT!H51,"–") -> 0.61152536
B31: Cash Ratio | D31: =IFERROR(INPUT!D34/INPUT!D51,"–") -> – | E31: =IFERROR(INPUT!E34/INPUT!E51,"–") -> 0.16374552 | F31: =IFERROR(INPUT!F34/INPUT!F51,"–") -> 0.218329 | G31: =IFERROR(INPUT!G34/INPUT!G51,"–") -> 0.1866026 | H31: =IFERROR(INPUT!H34/INPUT!H51,"–") -> 0.2433613
B32: Debt / Equity Ratio | D32: =IFERROR((INPUT!D49+INPUT!D55)/INPUT!D60,"–") -> – | E32: =IFERROR((INPUT!E49+INPUT!E55)/INPUT!E60,"–") -> 4.0452243 | F32: =IFERROR((INPUT!F49+INPUT!F55)/INPUT!F60,"–") -> 3.2792603 | G32: =IFERROR((INPUT!G49+INPUT!G55)/INPUT!G60,"–") -> 4.254624 | H32: =IFERROR((INPUT!H49+INPUT!H55)/INPUT!H60,"–") -> 3.013732
B33: Net Debt / EBITDA | D33: =IFERROR((INPUT!D49+INPUT!D55-INPUT!D34)/INPUT!D30,"–") -> – | E33: =IFERROR((INPUT!E49+INPUT!E55-INPUT!E34)/INPUT!E30,"–") -> 1.8944883 | F33: =IFERROR((INPUT!F49+INPUT!F55-INPUT!F34)/INPUT!F30,"–") -> 1.8493452 | G33: =IFERROR((INPUT!G49+INPUT!G55-INPUT!G34)/INPUT!G30,"–") -> 1.9711076 | H33: =IFERROR((INPUT!H49+INPUT!H55-INPUT!H34)/INPUT!H30,"–") -> 1.5262458
B34: Interest Coverage (EBIT/Interest) | D34: =IFERROR(INPUT!D17/ABS(INPUT!D20),"–") -> – | E34: =IFERROR(INPUT!E17/ABS(INPUT!E20),"–") -> 36.961105 | F34: =IFERROR(INPUT!F17/ABS(INPUT!F20),"–") -> 26.133232 | G34: =IFERROR(INPUT!G17/ABS(INPUT!G20),"–") -> – | H34: =IFERROR(INPUT!H17/ABS(INPUT!H20),"–") -> –
B35: Debt / Total Assets | D35: =IFERROR((INPUT!D49+INPUT!D55)/INPUT!D44,"–") -> – | E35: =IFERROR((INPUT!E49+INPUT!E55)/INPUT!E44,"–") -> 1.5643144 | F35: =IFERROR((INPUT!F49+INPUT!F55)/INPUT!F44,"–") -> 1.4053454 | G35: =IFERROR((INPUT!G49+INPUT!G55)/INPUT!G44,"–") -> 1.4557043 | H35: =IFERROR((INPUT!H49+INPUT!H55)/INPUT!H44,"–") -> 1.1370875
B36: Equity Ratio | D36: =IFERROR(INPUT!D60/INPUT!D44,"–") -> – | E36: =IFERROR(INPUT!E60/INPUT!E44,"–") -> 0.38670648 | F36: =IFERROR(INPUT!F60/INPUT!F44,"–") -> 0.42855562 | G36: =IFERROR(INPUT!G60/INPUT!G44,"–") -> 0.34214641 | H36: =IFERROR(INPUT!H60/INPUT!H44,"–") -> 0.37730212
B38: OPERATIONAL EFFICIENCY RATIOS
B40: Asset Turnover | D40: =IFERROR(INPUT!D9/INPUT!D44,"–") -> – | E40: =IFERROR(INPUT!E9/INPUT!E44,"–") -> 2.4682215 | F40: =IFERROR(INPUT!F9/INPUT!F44,"–") -> 2.2318398 | G40: =IFERROR(INPUT!G9/INPUT!G44,"–") -> 2.0865104 | H40: =IFERROR(INPUT!H9/INPUT!H44,"–") -> 1.9799559
B41: Inventory Turnover | D41: =IFERROR(ABS(INPUT!D10)/INPUT!D36,"–") -> – | E41: =IFERROR(ABS(INPUT!E10)/INPUT!E36,"–") -> 45.197331 | F41: =IFERROR(ABS(INPUT!F10)/INPUT!F36,"–") -> 33.823567 | G41: =IFERROR(ABS(INPUT!G10)/INPUT!G36,"–") -> 28.870711 | H41: =IFERROR(ABS(INPUT!H10)/INPUT!H36,"–") -> 38.642882
B42: Days Inventory Outstanding (DIO) | D42: =IFERROR(INPUT!D36/ABS(INPUT!D10)*INPUT!D110,"–") -> – | E42: =IFERROR(INPUT!E36/ABS(INPUT!E10)*INPUT!E110,"–") -> 0 | F42: =IFERROR(INPUT!F36/ABS(INPUT!F10)*INPUT!F110,"–") -> 0 | G42: =IFERROR(INPUT!G36/ABS(INPUT!G10)*INPUT!G110,"–") -> 0 | H42: =IFERROR(INPUT!H36/ABS(INPUT!H10)*INPUT!H110,"–") -> 9.4454652
B43: Receivables Turnover | D43: =IFERROR(INPUT!D9/INPUT!D35,"–") -> – | E43: =IFERROR(INPUT!E9/INPUT!E35,"–") -> 13.991201 | F43: =IFERROR(INPUT!F9/INPUT!F35,"–") -> 12.989189 | G43: =IFERROR(INPUT!G9/INPUT!G35,"–") -> 11.70413 | H43: =IFERROR(INPUT!H9/INPUT!H35,"–") -> 10.462353
B44: Days Sales Outstanding (DSO) | D44: =IFERROR(INPUT!D35/INPUT!D9*INPUT!D110,"–") -> – | E44: =IFERROR(INPUT!E35/INPUT!E9*INPUT!E110,"–") -> 0 | F44: =IFERROR(INPUT!F35/INPUT!F9*INPUT!F110,"–") -> 0 | G44: =IFERROR(INPUT!G35/INPUT!G9*INPUT!G110,"–") -> 0 | H44: =IFERROR(INPUT!H35/INPUT!H9*INPUT!H110,"–") -> 34.886991
B45: Days Payable Outstanding (DPO) | D45: =IFERROR(INPUT!D48/ABS(INPUT!D10)*INPUT!D110,"–") -> – | E45: =IFERROR(INPUT!E48/ABS(INPUT!E10)*INPUT!E110,"–") -> 0 | F45: =IFERROR(INPUT!F48/ABS(INPUT!F10)*INPUT!F110,"–") -> 0 | G45: =IFERROR(INPUT!G48/ABS(INPUT!G10)*INPUT!G110,"–") -> 0 | H45: =IFERROR(INPUT!H48/ABS(INPUT!H10)*INPUT!H110,"–") -> 33.581123
B46: Cash Conversion Cycle (CCC) | D46: =IFERROR(D42+D44-D45,"–") -> – | E46: =IFERROR(E42+E44-E45,"–") -> 0 | F46: =IFERROR(F42+F44-F45,"–") -> 0 | G46: =IFERROR(G42+G44-G45,"–") -> 0 | H46: =IFERROR(H42+H44-H45,"–") -> 10.751333
B47: Fixed Asset Turnover | D47: =IFERROR(INPUT!D9/INPUT!D41,"–") -> – | E47: =IFERROR(INPUT!E9/INPUT!E41,"–") -> 9.3626802 | F47: =IFERROR(INPUT!F9/INPUT!F41,"–") -> 8.7678143 | G47: =IFERROR(INPUT!G9/INPUT!G41,"–") -> 8.5603109 | H47: =IFERROR(INPUT!H9/INPUT!H41,"–") -> 8.3509451
B49: GROWTH RATIOS
B51: Revenue Growth (YoY) | D51: – | E51: =IFERROR(INPUT!E9/INPUT!D9-1,"–") -> – | F51: =IFERROR(INPUT!F9/INPUT!E9-1,"–") -> -0.028004605 | G51: =IFERROR(INPUT!G9/INPUT!F9-1,"–") -> 0.020219941 | H51: =IFERROR(INPUT!H9/INPUT!G9-1,"–") -> 0.064255118
B52: Gross Profit Growth (YoY) | D52: – | E52: =IFERROR(INPUT!E11/INPUT!D11-1,"–") -> – | F52: =IFERROR(INPUT!F11/INPUT!E11-1,"–") -> -0.009567753 | G52: =IFERROR(INPUT!G11/INPUT!F11-1,"–") -> 0.068194717 | H52: =IFERROR(INPUT!H11/INPUT!G11-1,"–") -> 0.080350669
...

Sheet ALTMAN Z-SCORE
B1: FinSight | F1: ALTMAN Z-SCORE — Bankruptcy Risk
B3: ALTMAN Z-SCORE
B5: COMPONENT | E5: =IF(INPUT!E5="","",INPUT!E5) -> 2022 | F5: =IF(INPUT!F5="","",INPUT!F5) -> 2023 | G5: =IF(INPUT!G5="","",INPUT!G5) -> 2024 | H5: =IF(INPUT!H5="","",INPUT!H5) -> 2025 (LTM)
B7: INTERMEDIATE CALCULATIONS
B8: Working Capital | D8: =IFERROR(INPUT!D38-INPUT!D51,"–") -> 0 | E8: =IFERROR(INPUT!E38-INPUT!E51,"–") -> -66408 | F8: =IFERROR(INPUT!F38-INPUT!F51,"–") -> -56748 | G8: =IFERROR(INPUT!G38-INPUT!G51,"–") -> -75538 | H8: =IFERROR(INPUT!H38-INPUT!H51,"–") -> -51643
B9: Total Assets | D9: =INPUT!D44 -> 0 | E9: =INPUT!E44 -> 159762 | F9: =INPUT!F44 -> 171735 | G9: =INPUT!G44 -> 187411 | H9: =INPUT!H44 -> 210187
B10: Retained Earnings | D10: =INPUT!D59 -> 0 | E10: =INPUT!E59 -> -3068 | F10: =INPUT!F59 -> -214 | G10: =INPUT!G59 -> -19154 | H10: =INPUT!H59 -> -14264
B11: EBIT | D11: =INPUT!D17 -> 0 | E11: =INPUT!E17 -> 108333 | F11: =INPUT!F17 -> 102782 | G11: =INPUT!G17 -> 111771 | H11: =INPUT!H17 -> 121352
B12: Market Cap (Book Value of Equity) | D12: =INPUT!D60 -> 0 | E12: =INPUT!E60 -> 61781 | F12: =INPUT!F60 -> 73598 | G12: =INPUT!G60 -> 64122 | H12: =INPUT!H60 -> 79304
B13: Total Liabilities | D13: =INPUT!D55 -> 0 | E13: =INPUT!E55 -> 243366 | F13: =INPUT!F55 -> 232528 | G13: =INPUT!G55 -> 246214 | H13: =INPUT!H55 -> 225985
B14: Revenue | D14: =INPUT!D9 -> 0 | E14: =INPUT!E9 -> 394328 | F14: =INPUT!F9 -> 383285 | G14: =INPUT!G9 -> 391035 | H14: =INPUT!H9 -> 416161
B16: 5 ALTMAN Z-SCORE COMPONENTS
B17: X1 = Working Capital / Total Assets | D17: =IFERROR(D8/D9,"–") -> – | E17: =IFERROR(E8/E9,"–") -> -0.41566831 | F17: =IFERROR(F8/F9,"–") -> -0.33043934 | G17: =IFERROR(G8/G9,"–") -> -0.40306065 | H17: =IFERROR(H8/H9,"–") -> -0.24570026
B18: X2 = Retained Earnings / Total Assets | D18: =IFERROR(D10/D9,"–") -> – | E18: =IFERROR(E10/E9,"–") -> -0.019203565 | F18: =IFERROR(F10/F9,"–") -> -0.0012461059 | G18: =IFERROR(G10/G9,"–") -> -0.10220318 | H18: =IFERROR(H10/H9,"–") -> -0.067863379
B19: X3 = EBIT / Total Assets | D19: =IFERROR(D11/D9,"–") -> – | E19: =IFERROR(E11/E9,"–") -> 0.67808991 | F19: =IFERROR(F11/F9,"–") -> 0.59849186 | G19: =IFERROR(G11/G9,"–") -> 0.59639509 | H19: =IFERROR(H11/H9,"–") -> 0.57735255
B20: X4 = Equity / Total Liabilities | D20: =IFERROR(D12/D13,"–") -> – | E20: =IFERROR(E12/E13,"–") -> 0.25386044 | F20: =IFERROR(F12/F13,"–") -> 0.31651242 | G20: =IFERROR(G12/G13,"–") -> 0.26043198 | H20: =IFERROR(H12/H13,"–") -> 0.35092595
B21: X5 = Revenue / Total Assets | D21: =IFERROR(D14/D9,"–") -> – | E21: =IFERROR(E14/E9,"–") -> 2.4682215 | F21: =IFERROR(F14/F9,"–") -> 2.2318398 | G21: =IFERROR(G14/G9,"–") -> 2.0865104 | H21: =IFERROR(H14/H9,"–") -> 1.9799559
B23: ALTMAN Z-SCORE CALCULATION
B24: 1.2 × X1 | D24: =IFERROR(1.2*D17,"–") -> – | E24: =IFERROR(1.2*E17,"–") -> -0.49880197 | F24: =IFERROR(1.2*F17,"–") -> -0.39652721 | G24: =IFERROR(1.2*G17,"–") -> -0.48367278 | H24: =IFERROR(1.2*H17,"–") -> -0.29484031
B25: 1.4 × X2 | D25: =IFERROR(1.4*D18,"–") -> – | E25: =IFERROR(1.4*E18,"–") -> -0.026884991 | F25: =IFERROR(1.4*F18,"–") -> -0.0017445483 | G25: =IFERROR(1.4*G18,"–") -> -0.14308445 | H25: =IFERROR(1.4*H18,"–") -> -0.09500873
B26: 3.3 × X3 | D26: =IFERROR(3.3*D19,"–") -> – | E26: =IFERROR(3.3*E19,"–") -> 2.2376967 | F26: =IFERROR(3.3*F19,"–") -> 1.9750231 | G26: =IFERROR(3.3*G19,"–") -> 1.9681038 | H26: =IFERROR(3.3*H19,"–") -> 1.9052634
B27: 0.6 × X4 | D27: =IFERROR(0.6*D20,"–") -> – | E27: =IFERROR(0.6*E20,"–") -> 0.15231626 | F27: =IFERROR(0.6*F20,"–") -> 0.18990745 | G27: =IFERROR(0.6*G20,"–") -> 0.15625919 | H27: =IFERROR(0.6*H20,"–") -> 0.21055557
B28: 1.0 × X5 | D28: =IFERROR(1*D21,"–") -> – | E28: =IFERROR(1*E21,"–") -> 2.4682215 | F28: =IFERROR(1*F21,"–") -> 2.2318398 | G28: =IFERROR(1*G21,"–") -> 2.0865104 | H28: =IFERROR(1*H21,"–") -> 1.9799559
B30: Z-SCORE (FINAL) | D30: =IFERROR(D24+D25+D26+D27+D28,"–") -> – | E30: =IFERROR(E24+E25+E26+E27+E28,"–") -> 4.3325475 | F30: =IFERROR(F24+F25+F26+F27+F28,"–") -> 3.9984986 | G30: =IFERROR(G24+G25+G26+G27+G28,"–") -> 3.5841161 | H30: =IFERROR(H24+H25+H26+H27+H28,"–") -> 3.7059259
B32: ZONE INTERPRETATION
B33: ZONE | D33: =IFERROR(IF(D30>2.99,"SAFE",IF(D30>=1.81,"GREY","DISTRESS")),"–") -> SAFE | E33: =IFERROR(IF(E30>2.99,"SAFE",IF(E30>=1.81,"GREY","DISTRESS")),"–") -> SAFE | F33: =IFERROR(IF(F30>2.99,"SAFE",IF(F30>=1.81,"GREY","DISTRESS")),"–") -> SAFE | G33: =IFERROR(IF(G30>2.99,"SAFE",IF(G30>=1.81,"GREY","DISTRESS")),"–") -> SAFE | H33: =IFERROR(IF(H30>2.99,"SAFE",IF(H30>=1.81,"GREY","DISTRESS")),"–") -> SAFE
B35: SAFE ZONE | D35: Low probability of bankruptcy
B36: GREY ZONE | D36: Some risk — monitor closely
B37: DISTRESS ZONE | D37: High probability of bankruptcy
B39: NOTE: Altman Z-Score was developed by Edward Altman (1968) for publicly traded manufacturing companies.
B40: Modified versions exist for private companies (Z') and non-manufacturing firms (Z'').

Sheet BENEISH M-SCORE
B1: FinSight | F1: BENEISH M-SCORE — Earnings Manipulation
B3: BENEISH M-SCORE
B5: INDEX / COMPONENT | E5: =IF(INPUT!H5="","",INPUT!H5) -> 2025 (LTM) | F5: Year t (Current)
B7: BASE FINANCIAL DATA (from INPUT)
B9: Net Sales (Revenue) | E9: =INPUT!E9 -> 394328 | F9: =INPUT!F9 -> 383285
B10: Cost of Goods Sold | E10: =ABS(INPUT!E10) -> 223546 | F10: =ABS(INPUT!F10) -> 214137
B11: Gross Profit | E11: =INPUT!E11 -> 170782 | F11: =INPUT!F11 -> 169148
B12: Total Current Assets | E12: =INPUT!E38 -> 77999 | F12: =INPUT!F38 -> 80499
B13: PP&E (Net) | E13: =INPUT!E41 -> 42117 | F13: =INPUT!F41 -> 43715
B14: Total Assets | E14: =INPUT!E44 -> 159762 | F14: =INPUT!F44 -> 171735
B15: Total Current Liabilities | E15: =INPUT!E51 -> 144407 | F15: =INPUT!F51 -> 137247
B16: Long-Term Debt | E16: =INPUT!E54 -> 98959 | F16: =INPUT!F54 -> 95281
B17: Net Income | E17: =INPUT!E26 -> 90694 | F17: =INPUT!F26 -> 87496
B18: Cash from Operations (CFO) | E18: =INPUT!E75 -> 104393 | F18: =INPUT!F75 -> 92864
B19: Depreciation & Amortization | E19: =INPUT!E16 -> -11104 | F19: =INPUT!F16 -> -11519
B20: SG&A Expense | E20: =ABS(INPUT!E14) -> 25094 | F20: =ABS(INPUT!F14) -> 24932
B22: 8 BENEISH INDICES
B24: DSRI — Days Sales Receivable Index | F24: =IFERROR((INPUT!F35/INPUT!F9)/(INPUT!E35/INPUT!E9),"–") -> 1.0771419
B25: GMI — Gross Margin Index | F25: =IFERROR((E11/E9)/(F11/F9),"–") -> 0.98138504
B26: AQI — Asset Quality Index | F26: =IFERROR((1-(F12+F13)/F14)/(1-(E12+E13)/E14),"–") -> 1.1150668
B27: SGI — Sales Growth Index | F27: =IFERROR(F9/E9,"–") -> 0.97199539
B28: DEPI — Depreciation Index | F28: =IFERROR((E19/(E19+E13))/(F19/(F19+F13)),"–") -> 1.0007436
B29: SGAI — SG&A Expense Index | F29: =IFERROR((F20/F9)/(E20/E9),"–") -> 1.0221697
B30: TATA — Total Accruals to Total Assets | F30: =IFERROR((F17-F18)/F14,"–") -> -0.031257461
B31: LVGI — Leverage Index | F31: =IFERROR(((F16+F15)/F14)/((E16+E15)/E14),"–") -> 0.88885317
B33: M-SCORE WEIGHTED CALCULATION
B35: Constant | F35: =-4.84 -> -4.84
B36: 0.920 × DSRI | F36: =IFERROR(0.92*F24,"–") -> 0.99097059
B37: 0.528 × GMI | F37: =IFERROR(0.528*F25,"–") -> 0.5181713
B38: 0.404 × AQI | F38: =IFERROR(0.404*F26,"–") -> 0.45048697
B39: 0.892 × SGI | F39: =IFERROR(0.892*F27,"–") -> 0.86701989
B40: 0.115 × DEPI | F40: =IFERROR(0.115*F28,"–") -> 0.11508551
B41: -0.172 × SGAI | F41: =IFERROR(-0.172*F29,"–") -> -0.17581319
B42: 4.679 × TATA | F42: =IFERROR(4.679*F30,"–") -> -0.14625366
B43: -0.327 × LVGI | F43: =IFERROR(-0.327*F31,"–") -> -0.29065499
B45: M-SCORE (FINAL) | F45: =IFERROR(F35+F36+F37+F38+F39+F40+F41+F42+F43,"–") -> -2.5109876
B47: INTERPRETATION
B48: RESULT | F48: =IF(ISNUMBER(F45),IF(F45>-2.22,"⚠ POSSIBLE MANIPULATOR (M > -2.22)","✓ NOT LIKELY MANIPULATOR (M ≤ -2.22)"),"–") -> ✓ NOT LIKELY MANIPULATOR (M ≤ -2.22)
B50: NOT LIKELY MANIPULATOR
B51: POSSIBLE MANIPULATOR
...

Sheet DCF
B1: FinSight | K1: DCF — Discounted Cash Flow Valuation
B3: DCF
B4: All figures in USD millions unless stated
B5: METRIC | C5: (Units) | D5: =IF(INPUT!D5="","",INPUT!D5) | E5: =IF(INPUT!E5="","",INPUT!E5) -> 2022 | F5: =IF(INPUT!F5="","",INPUT!F5) -> 2023 | G5: =IF(INPUT!G5="","",INPUT!G5) -> 2024 | H5: =IF(INPUT!H5="","",INPUT!H5) -> 2025 (LTM) | I5: =TEXT(INPUT!D117+1,"0")&"F" -> 2026F | J5: =TEXT(INPUT!D117+2,"0")&"F" -> 2027F | K5: =TEXT(INPUT!D117+3,"0")&"F" -> 2028F | L5: =TEXT(INPUT!D117+4,"0")&"F" -> 2029F | M5: =TEXT(INPUT!D117+5,"0")&"F" -> 2030F | N5: Terminal
B7: INCOME STATEMENT
B9: Revenue | D9: =INPUT!D9 -> 0 | E9: =INPUT!E9 -> 394328 | F9: =INPUT!F9 -> 383285 | G9: =INPUT!G9 -> 391035 | H9: =IF(INPUT!H9<>"",INPUT!H9,INPUT!G9) -> 416161 | I9: =H9*(1+$I$29) -> 423994.6 | J9: =I9*(1+$I$29) -> 431975.66 | K9: =J9*(1+$I$29) -> 440106.94 | L9: =K9*(1+$I$29) -> 448391.29 | M9: =L9*(1+$I$29) -> 456831.58
B10: Cost of Goods Sold | D10: =INPUT!D10 -> 0 | E10: =INPUT!E10 -> -223546 | F10: =INPUT!F10 -> -214137 | G10: =INPUT!G10 -> -210352 | H10: =IF(INPUT!H10<>"",INPUT!H10,INPUT!G10) -> -220960 | I10: =-I9*(1-$I$30) -> -232611.63 | J10: =-J9*(1-$I$30) -> -236990.19 | K10: =-K9*(1-$I$30) -> -241451.17 | L10: =-L9*(1-$I$30) -> -245996.12 | M10: =-M9*(1-$I$30) -> -250626.63
B11: Gross Profit | D11: =SUM(D9:D10) -> 0 | E11: =SUM(E9:E10) -> 170782 | F11: =SUM(F9:F10) -> 169148 | G11: =SUM(G9:G10) -> 180683 | H11: =SUM(H9:H10) -> 195201 | I11: =SUM(I9:I10) -> 191382.97 | J11: =SUM(J9:J10) -> 194985.47 | K11: =SUM(K9:K10) -> 198655.77 | ... M11: =SUM(M9:M10) -> 206204.95
B13: SG&A Expenses | D13: =INPUT!D14 -> 0 | E13: =INPUT!E14 -> -25094 | F13: =INPUT!F14 -> -24932 | G13: =INPUT!G14 -> -26097 | H13: =IF(INPUT!H14<>"",INPUT!H14,INPUT!G14) -> -27601 | I13: =-I9*$I$31 -> -27744.801 | J13: =-J9*$I$31 -> -28267.055 | K13: =-K9*$I$31 -> -28799.139 | L13: =-L9*$I$31 -> -29341.24 | M13: =-M9*$I$31 -> -29893.544
B14: Research & Development | D14: =INPUT!D15 -> 0 | E14: =INPUT!E15 -> -26251 | F14: =INPUT!F15 -> -29915 | G14: =INPUT!G15 -> -31370 | H14: =IF(INPUT!H15<>"",INPUT!H15,INPUT!G15) -> -34550 | I14: =-I9*$I$32 -> -32633.19 | J14: =-J9*$I$32 -> -33247.461 | K14: =-K9*$I$32 -> -33873.294 | L14: =-L9*$I$32 -> -34510.907 | M14: =-M9*$I$32 -> -35160.523
B15: EBITDA | D15: =INPUT!D30 -> 0 | E15: =INPUT!E30 -> 119437 | F15: =INPUT!F30 -> 114301 | G15: =INPUT!G30 -> 123216 | H15: =IF(INPUT!H30<>"",INPUT!H30,INPUT!G30) -> 133050 | I15: =I11+I13+I14 -> 131004.98 | J15: =J11+J13+J14 -> 133470.95 | K15: =K11+K13+K14 -> 135983.34 | L15: =L11+L13+L14 -> 138543.02 | M15: =M11+M13+M14 -> 141150.88
B17: Depreciation & Amortization | D17: =INPUT!D16 -> 0 | E17: =INPUT!E16 -> -11104 | F17: =INPUT!F16 -> -11519 | G17: =INPUT!G16 -> -11445 | H17: =IF(INPUT!H16<>"",INPUT!H16,INPUT!G16) -> -11698 | I17: =-I9*$I$33 -> -12252.431 | J17: =-J9*$I$33 -> -12483.065 | K17: =-K9*$I$33 -> -12718.04 | L17: =-L9*$I$33 -> -12957.437 | M17: =-M9*$I$33 -> -13201.341
B18: EBIT (Operating Profit) | D18: =D15+D17 -> 0 | E18: =E15+E17 -> 108333 | F18: =F15+F17 -> 102782 | G18: =G15+G17 -> 111771 | H18: =H15+H17 -> 121352 | I18: =I15+I17 -> 118752.55 | J18: =J15+J17 -> 120987.89 | K18: =K15+K17 -> 123265.3 | ... M18: =M15+M17 -> 127949.54
B20: Interest Expense | D20: =INPUT!D20 -> 0 | E20: =INPUT!E20 -> -2931 | F20: =INPUT!F20 -> -3933 | G20: =INPUT!G20 -> 0 | H20: =IF(INPUT!H20<>"",INPUT!H20,INPUT!G20) -> 0 | I20: =-I18*(INPUT!H103)/(1-$I$34) -> -8363.3634 | J20: =-J18*(INPUT!H103)/(1-$I$34) -> -8520.791 | K20: =-K18*(INPUT!H103)/(1-$I$34) -> -8681.182 | L20: =-L18*(INPUT!H103)/(1-$I$34) -> -8844.5921 | M20: =-M18*(INPUT!H103)/(1-$I$34) -> -9011.0781
B21: Earnings Before Tax (EBT) | D21: =D18+D20 -> 0 | E21: =E18+E20 -> 105402 | F21: =F18+F20 -> 98849 | G21: =G18+G20 -> 111771 | H21: =H18+H20 -> 121352 | I21: =I18+I20 -> 110389.19 | J21: =J18+J20 -> 112467.1 | K21: =K18+K20 -> 114584.12 | ... M21: =M18+M20 -> 118938.46
B23: Income Taxes | D23: =INPUT!D24 -> 0 | E23: =INPUT!E24 -> -17533 | F23: =INPUT!F24 -> -15103 | G23: =INPUT!G24 -> -26926 | H23: =IF(INPUT!H24<>"",INPUT!H24,INPUT!G24) -> -18895 | I23: =-I21*$I$34 -> -19478.172 | J23: =-J21*$I$34 -> -19844.819 | K23: =-K21*$I$34 -> -20218.368 | L23: =-L21*$I$34 -> -20598.948 | M23: =-M21*$I$34 -> -20986.692
B24: Net Income | D24: =D21+D23 -> 0 | E24: =E21+E23 -> 87869 | F24: =F21+F23 -> 83746 | G24: =G21+G23 -> 84845 | H24: =H21+H23 -> 102457 | I24: =I21+I23 -> 90911.015 | J24: =J21+J23 -> 92622.277 | K24: =K21+K23 -> 94365.751 | ... M24: =M21+M23 -> 97951.771
B26: ASSUMPTIONS & DRIVERS
B27: All figures in USD millions unless stated
B28: INCOME STATEMENT DRIVERS | I28: =TEXT(INPUT!D117+1,"0")&"F" -> 2026F | J28: =TEXT(INPUT!D117+2,"0")&"F" -> 2027F | K28: =TEXT(INPUT!D117+3,"0")&"F" -> 2028F | L28: =TEXT(INPUT!D117+4,"0")&"F" -> 2029F | M28: =TEXT(INPUT!D117+5,"0")&"F" -> 2030F
B29: Revenue Growth Rate (YoY) | D29: =IFERROR(IF(NOT(ISBLANK(INPUT!H9)),INPUT!H9/INPUT!G9-1,IF(NOT(ISBLANK(INPUT!G9)),INPUT!G9/INPUT!F9-1,IF(NOT(ISBLANK(INPUT!F9)),INPUT!F9/INPUT!E9-1,IF(NOT(ISBLANK(INPUT!E9)),INPUT!E9/INPUT!D9-1,0.05)))),0.05) -> 0.064255118 | E29: =I29 -> 0.018823484 | F29: =I29 -> 0.018823484 | I29: =IFERROR(AVERAGE(IF(ISNUMBER(RATIOS!F51),RATIOS!F51,0),IF(ISNUMBER(RATIOS!G51),RATIOS!G51,0),IF(ISNUMBER(RATIOS!H51),RATIOS!H51,0)),0.05) -> 0.018823484 | J29: =I29 -> 0.018823484 | K29: =I29 -> 0.018823484 | L29: =I29 -> 0.018823484 | M29: =I29 -> 0.018823484
B30: Gross Margin | D30: =IFERROR(INPUT!H11/INPUT!H9,0.4) -> 0.46905164 | E30: =I30 -> 0.45138069 | F30: =I30 -> 0.45138069 | I30: =IFERROR(AVERAGE(IF(INPUT!E9<>0,INPUT!E11/INPUT!E9),IF(INPUT!F9<>0,INPUT!F11/INPUT!F9),IF(INPUT!G9<>0,INPUT!G11/INPUT!G9),IF(INPUT!H9<>0,INPUT!H11/INPUT!H9)),0.4) -> 0.45138069 | J30: =I30 -> 0.45138069 | K30: =I30 -> 0.45138069 | L30: =I30 -> 0.45138069 | M30: =I30 -> 0.45138069
B31: SG&A (% of Revenue) | D31: =IFERROR(ABS(INPUT!H14)/INPUT!H9,0.15) -> 0.066322889 | E31: =I31 -> 0.065436685 | F31: =I31 -> 0.065436685 | I31: =IFERROR(AVERAGE(IF(INPUT!E9<>0,ABS(INPUT!E14)/INPUT!E9),IF(INPUT!F9<>0,ABS(INPUT!F14)/INPUT!F9),IF(INPUT!G9<>0,ABS(INPUT!G14)/INPUT!G9),IF(INPUT!H9<>0,ABS(INPUT!H14)/INPUT!H9)),0.15) -> 0.065436685 | J31: =I31 -> 0.065436685 | K31: =I31 -> 0.065436685 | L31: =I31 -> 0.065436685 | M31: =I31 -> 0.065436685
B32: R&D (% of Revenue) | D32: =IFERROR(ABS(INPUT!H15)/INPUT!H9,0.05) -> 0.083020754 | E32: =I32 -> 0.076966052 | F32: =I32 -> 0.076966052 | I32: =IFERROR(AVERAGE(IF(INPUT!E9<>0,ABS(INPUT!E15)/INPUT!E9),IF(INPUT!F9<>0,ABS(INPUT!F15)/INPUT!F9),IF(INPUT!G9<>0,ABS(INPUT!G15)/INPUT!G9),IF(INPUT!H9<>0,ABS(INPUT!H15)/INPUT!H9)),0.05) -> 0.076966052 | J32: =I32 -> 0.076966052 | K32: =I32 -> 0.076966052 | L32: =I32 -> 0.076966052 | M32: =I32 -> 0.076966052
B33: D&A (% of Revenue) | D33: =IFERROR(ABS(INPUT!H16)/INPUT!H9,0.04) -> 0.028109313 | E33: =I33 -> 0.028897612 | F33: =I33 -> 0.028897612 | I33: =IFERROR(AVERAGE(IF(INPUT!E9<>0,ABS(INPUT!E16)/INPUT!E9),IF(INPUT!F9<>0,ABS(INPUT!F16)/INPUT!F9),IF(INPUT!G9<>0,ABS(INPUT!G16)/INPUT!G9),IF(INPUT!H9<>0,ABS(INPUT!H16)/INPUT!H9)),0.04) -> 0.028897612 | J33: =I33 -> 0.028897612 | K33: =I33 -> 0.028897612 | L33: =I33 -> 0.028897612 | M33: =I33 -> 0.028897612
B34: Effective Tax Rate | D34: =IFERROR(INPUT!H104,0.21) -> 0.1557 | E34: =I34 -> 0.17645 | F34: =I34 -> 0.17645 | I34: =IFERROR(AVERAGEIF(INPUT!E104:H104,"<>0"),0.21) -> 0.17645 | J34: =I34 -> 0.17645 | K34: =I34 -> 0.17645 | L34: =I34 -> 0.17645 | M34: =I34 -> 0.17645
B36: BALANCE SHEET / CASH FLOW DRIVERS
B37: CapEx (% of Revenue) | D37: =IFERROR(ABS(INPUT!H78)/INPUT!H9,0.05) -> 0.030553079 | E37: =I37 -> 0.02761485 | F37: =I37 -> 0.02761485 | I37: =IFERROR(AVERAGE(IF(INPUT!E9<>0,ABS(INPUT!E78)/INPUT!E9),IF(INPUT!F9<>0,ABS(INPUT!F78)/INPUT!F9),IF(INPUT!G9<>0,ABS(INPUT!G78)/INPUT!G9),IF(INPUT!H9<>0,ABS(INPUT!H78)/INPUT!H9)),0.05) -> 0.02761485 | J37: =I37 -> 0.02761485 | K37: =I37 -> 0.02761485 | L37: =I37 -> 0.02761485 | M37: =I37 -> 0.02761485
B38: Change in NWC (% of Revenue Change) | D38: =IFERROR(ABS((INPUT!H71+INPUT!H72+INPUT!H73)/INPUT!H9),0.1) -> 0.011358585 | E38: =I38 -> 0.0065151953 | F38: =I38 -> 0.0065151953 | I38: =IFERROR(AVERAGE(IF(INPUT!E9<>0,ABS((INPUT!E71+INPUT!E72+INPUT!E73)/INPUT!E9)),IF(INPUT!F9<>0,ABS((INPUT!F71+INPUT!F72+INPUT!F73)/INPUT!F9)),IF(INPUT!G9<>0,ABS((INPUT!G71+INPUT!G72+INPUT!G73)/INPUT!G9)),IF(INPUT!H9<>0,ABS((INPUT!H71+INPUT!H72+INPUT!H73)/INPUT!H9))),0.1) -> 0.0065151953 | J38: =I38 -> 0.0065151953 | K38: =I38 -> 0.0065151953 | L38: =I38 -> 0.0065151953 | M38: =I38 -> 0.0065151953
B40: FREE CASH FLOW CALCULATION
B42: EBIT | D42: =D18 -> 0 | E42: =E18 -> 108333 | F42: =F18 -> 102782 | G42: =G18 -> 111771 | H42: =H18 -> 121352 | I42: =I18 -> 118752.55 | J42: =J18 -> 120987.89 | K42: =K18 -> 123265.3 | ... M42: =M18 -> 127949.54
B43: (-) Taxes on EBIT (Unlevered) | D43: =D18*(-INPUT!D104) -> 0 | E43: =E18*(-INPUT!E104) -> -17549.946 | F43: =F18*(-INPUT!F104) -> -15129.51 | G43: =G18*(-INPUT!G104) -> -26925.634 | H43: =H18*(-INPUT!H104) -> -18894.506 | I43: =I18*(-$I$34) -> -20953.888 | J43: =J18*(-$I$34) -> -21348.313 | K43: =K18*(-$I$34) -> -21750.162 | L43: =L18*(-$I$34) -> -22159.576 | M43: =M18*(-$I$34) -> -22576.697
B44: NOPAT (Net Operating Profit After Tax) | D44: =D42+D43 -> 0 | E44: =E42+E43 -> 90783.054 | F44: =F42+F43 -> 87652.49 | G44: =G42+G43 -> 84845.366 | H44: =H42+H43 -> 102457.49 | I44: =I42+I43 -> 97798.663 | J44: =J42+J43 -> 99639.574 | K44: =K42+K43 -> 101515.14 | ... M44: =M42+M43 -> 105372.84
B46: (+) Depreciation & Amortization | D46: =ABS(D17) -> 0 | E46: =ABS(E17) -> 11104 | F46: =ABS(F17) -> 11519 | G46: =ABS(G17) -> 11445 | H46: =ABS(H17) -> 11698 | I46: =ABS(I17) -> 12252.431 | J46: =ABS(J17) -> 12483.065 | K46: =ABS(K17) -> 12718.04 | ... M46: =ABS(M17) -> 13201.341
B47: (-) Capital Expenditures (CapEx) | D47: =INPUT!D78 -> 0 | E47: =INPUT!E78 -> -10708 | F47: =INPUT!F78 -> -10959 | G47: =INPUT!G78 -> -9447 | H47: =IF(INPUT!H78<>"",INPUT!H78,INPUT!G78) -> -12715 | I47: =-I9*$I$37 -> -11708.547 | J47: =-J9*$I$37 -> -11928.943 | K47: =-K9*$I$37 -> -12153.487 | L47: =-L9*$I$37 -> -12382.258 | M47: =-M9*$I$37 -> -12615.336
B48: (-) Change in Working Capital | D48: =INPUT!D70+INPUT!D71+INPUT!D72+INPUT!D73 -> 0 | E48: =INPUT!E70+INPUT!E71+INPUT!E72+INPUT!E73 -> 12693 | F48: =INPUT!F70+INPUT!F71+INPUT!F72+INPUT!F73 -> 7595 | G48: =INPUT!G70+INPUT!G71+INPUT!G72+INPUT!G73 -> 11275 | H48: =IF(INPUT!H70<>"",INPUT!H70,INPUT!G70)+IF(INPUT!H71<>"",INPUT!H71,INPUT!G71)+IF(INPUT!H72<>"",INPUT!H72,INPUT!G72)+IF(INPUT!H73<>"",INPUT!H73,INPUT!G73) -> 6971 | I48: =-(I9-H9)*$I$38 -> -51.037435 | J48: =-(J9-I9)*$I$38 -> -51.998137 | K48: =-(K9-J9)*$I$38 -> -52.976923 | L48: =-(L9-K9)*$I$38 -> -53.974134 | M48: =-(M9-L9)*$I$38 -> -54.990115
B49: Unlevered Free Cash Flow (UFCF) | D49: =D44+D46+D47+D48 -> 0 | E49: =E44+E46+E47+E48 -> 103872.05 | F49: =F44+F46+F47+F48 -> 95807.49 | G49: =G44+G46+G47+G48 -> 98118.366 | H49: =H44+H46+H47+H48 -> 108411.49 | I49: =I44+I46+I47+I48 -> 98291.509 | J49: =J44+J46+J47+J48 -> 100141.7 | K49: =K44+K46+K47+K48 -> 102026.71 | ... M49: =M44+M46+M47+M48 -> 105903.86
B51: WACC CALCULATION (Capital Asset Pricing Model)
B53: Risk-Free Rate (Rf) | D53: =INPUT!H100 -> 0.043 | N53: =D53 -> 0.043
B54: Beta (Levered) | D54: =INPUT!H99 -> 1.109 | N54: =D54 -> 1.109
...

Sheet COMPARABLES
B1: FinSight | K1: COMPARABLES — Trading Comparables
B3: COMPARABLES
B4: All figures in USD millions unless stated
B6: COMPARABLE TRADING ANALYSIS
D7: Share Price | E7: Enterprise Value | F7: Revenue (LTM) | G7: EBITDA (LTM) | H7: EV / EBITDA | I7: EV / Revenue | J7: EPS (LTM) | K7: P / E (LTM)
B8: PEER COMPANIES | C8: TICKER | D8: (USD/sh) | E8: ($M) | F8: ($M) | G8: ($M) | H8: (x) | I8: (x) | J8: (USD/sh) | K8: (x)
B9: Microsoft Corporation | C9: MSFT | D9: 370.79 | E9: 2804095.4 | F9: 305453.01 | G9: 175258.99 | H9: =IFERROR(E9/G9,"–") -> 15.999724 | I9: =IFERROR(E9/F9,"–") -> 9.1801203 | J9: 15.98 | K9: =IFERROR(D9/J9,"–") -> 23.203379
B10: Alphabet Inc. | C10: GOOG | D10: 316.08 | E10: 3767280.9 | F10: 402836 | G10: 150175.01 | H10: =IFERROR(E10/G10,"–") -> 25.085937 | I10: =IFERROR(E10/F10,"–") -> 9.3518972 | J10: 10.81 | K10: =IFERROR(D10/J10,"–") -> 29.239593
B11: Meta Platforms, Inc. | C11: META | D11: 627 | E11: 1593036.4 | F11: 200966 | G11: 101892 | H11: =IFERROR(E11/G11,"–") -> 15.634558 | I11: =IFERROR(E11/F11,"–") -> 7.9268949 | J11: 23.5 | K11: =IFERROR(D11/J11,"–") -> 26.680851
B12: Sony Group Corporation | C12: SONY | D12: 20.99 | E12: 54186.15 | F12: 13170288 | G12: 2036071 | H12: =IFERROR(E12/G12,"–") -> 0.026613094 | I12: =IFERROR(E12/F12,"–") -> 0.0041142723 | J12: 1.3 | K12: =IFERROR(D12/J12,"–") -> 16.146154
B13: SMSNG.KS | C13: SMSNG.KS | D13: 87.8 | E13: 258704.92 | F13: 321913 | G13: 24292 | H13: =IFERROR(E13/G13,"–") -> 10.649799 | I13: =IFERROR(E13/F13,"–") -> 0.80364856 | K13: =IFERROR(D13/J13,"–") -> –
B15: Mean | D15: =IFERROR(AVERAGE(D9:D13),"–") -> 284.532 | E15: =IFERROR(AVERAGE(E9:E13),"–") -> 1695460.7 | F15: =IFERROR(AVERAGE(F9:F13),"–") -> 2880291.1 | G15: =IFERROR(AVERAGE(G9:G13),"–") -> 497537.8 | H15: =IFERROR(AVERAGE(H9:H13),"–") -> 13.479326 | I15: =IFERROR(AVERAGE(I9:I13),"–") -> 5.4533351 | J15: =IFERROR(AVERAGE(J9:J13),"–") -> 12.8975 | K15: =IFERROR(AVERAGE(K9:K13),"–") -> 23.817494
B16: Median | D16: =IFERROR(MEDIAN(D9:D13),"–") -> 316.08 | E16: =IFERROR(MEDIAN(E9:E13),"–") -> 1593036.4 | F16: =IFERROR(MEDIAN(F9:F13),"–") -> 321913 | G16: =IFERROR(MEDIAN(G9:G13),"–") -> 150175.01 | H16: =IFERROR(MEDIAN(H9:H13),"–") -> 15.634558 | I16: =IFERROR(MEDIAN(I9:I13),"–") -> 7.9268949 | J16: =IFERROR(MEDIAN(J9:J13),"–") -> 13.395 | K16: =IFERROR(MEDIAN(K9:K13),"–") -> 24.942115
B17: Maximum | D17: =IFERROR(MAX(D9:D13),"–") -> 627 | E17: =IFERROR(MAX(E9:E13),"–") -> 3767280.9 | F17: =IFERROR(MAX(F9:F13),"–") -> 13170288 | G17: =IFERROR(MAX(G9:G13),"–") -> 2036071 | H17: =IFERROR(MAX(H9:H13),"–") -> 25.085937 | I17: =IFERROR(MAX(I9:I13),"–") -> 9.3518972 | J17: =IFERROR(MAX(J9:J13),"–") -> 23.5 | K17: =IFERROR(MAX(K9:K13),"–") -> 29.239593
B18: Minimum | D18: =IFERROR(MIN(D9:D13),"–") -> 20.99 | E18: =IFERROR(MIN(E9:E13),"–") -> 54186.15 | F18: =IFERROR(MIN(F9:F13),"–") -> 200966 | G18: =IFERROR(MIN(G9:G13),"–") -> 24292 | H18: =IFERROR(MIN(H9:H13),"–") -> 0.026613094 | I18: =IFERROR(MIN(I9:I13),"–") -> 0.0041142723 | J18: =IFERROR(MIN(J9:J13),"–") -> 1.3 | K18: =IFERROR(MIN(K9:K13),"–") -> 16.146154
B20: TARGET COMPANY VALUATION (Based on Peer Multiples)
B21: TARGET COMPANY METRICS (from INPUT) | D21: =INPUT!H5 -> 2025 (LTM)
B22: Target: Revenue (LTM) | C22: ($M) | D22: =INPUT!H9/1000 -> 416.161
B23: Target: EBITDA (LTM) | C23: ($M) | D23: =INPUT!H30/1000 -> 133.05
B24: Target: EPS (LTM) | C24: ($) | D24: =IFERROR(INPUT!F26/INPUT!F96,"–") -> 5.5331689
B25: Target: Net Debt | C25: ($M) | D25: =IFERROR((INPUT!H54+INPUT!H55-INPUT!H34)/1000,"–") -> 268.379
B26: Target: Shares Outstanding | C26: (M) | D26: =INPUT!H96/1000 -> 14.68114
B28: IMPLIED VALUATION
B29: EV / EBITDA — Implied EV ($M) | D29: =IFERROR(D23*H18,"–") -> 3.5408722 | E29: =IFERROR(D23*H15,"–") -> 1793.4243 | F29: =IFERROR(D23*H16,"–") -> 2080.1779 | G29: =IFERROR(D23*H17,"–") -> 3337.6839
B30: EV / Revenue — Implied EV ($M) | D30: =IFERROR(D22*I18,"–") -> 1.7121997 | E30: =IFERROR(D22*I15,"–") -> 2269.4654 | F30: =IFERROR(D22*I16,"–") -> 3298.8645 | G30: =IFERROR(D22*I17,"–") -> 3891.8949
B31: P/E — Implied Equity Value ($M) | D31: =IFERROR(D24*K18*D26,"–") -> 1311.6042 | E31: =IFERROR(D24*K15*D26,"–") -> 1934.7719 | F31: =IFERROR(D24*K16*D26,"–") -> 2026.1285 | G31: =IFERROR(D24*K17*D26,"–") -> 2375.2265
B33: Implied Enterprise Value (Average of 3 Methods) | C33: ($M) | D33: =IFERROR(AVERAGE(D29,D30),"–") -> 2.626536 | E33: =IFERROR(AVERAGE(E29,E30),"–") -> 2031.4449 | F33: =IFERROR(AVERAGE(F29,F30),"–") -> 2689.5212 | G33: =IFERROR(AVERAGE(G29,G30),"–") -> 3614.7894
B34: (-) Net Debt | C34: ($M) | D34: =D25 -> 268.379 | E34: =D25 -> 268.379 | F34: =D25 -> 268.379 | G34: =D25 -> 268.379
B35: Implied Equity Value ($M) | C35: ($M) | D35: =IFERROR(D33-D34,"–") -> -265.75246 | E35: =IFERROR(E33-E34,"–") -> 1763.0659 | F35: =IFERROR(F33-F34,"–") -> 2421.1422 | G35: =IFERROR(G33-G34,"–") -> 3346.4104
B36: Implied Share Price ($) | C36: ($) | D36: =IFERROR(D35/D26,"–") -> -18.101623 | E36: =IFERROR(E35/D26,"–") -> 120.09053 | F36: =IFERROR(F35/D26,"–") -> 164.91514 | G36: =IFERROR(G35/D26,"–") -> 227.93941
B37: Current Share Price ($) | C37: ($) | D37: =INPUT!H95 -> 261.3 | E37: =INPUT!H95 -> 261.3 | F37: =INPUT!H95 -> 261.3 | G37: =INPUT!H95 -> 261.3
B38: Implied Upside / (Downside) | C38: (%) | D38: =IFERROR(D36/D37-1,"–") -> -1.0692753 | E38: =IFERROR(E36/D37-1,"–") -> -0.5404113 | F38: =IFERROR(F36/D37-1,"–") -> -0.36886668 | G38: =IFERROR(G36/D37-1,"–") -> -0.1276716
B41: (1) Target company EV based on LTM EV/EBITDA and EV/Revenue multiples relative to comparable peer set.
B43: © 2015 to 2024 FinSight
B44: This Excel model is for educational purposes only.
B45: https://finsight.com/
B47: Company | C47: EV/EBITDA (x) | D47: EV/Revenue (x) | E47: P/E (x)
B48: =B9 -> Microsoft Corporation | C48: =IFERROR(H9*1,0) -> 15.999724 | D48: =IFERROR(I9*1,0) -> 9.1801203 | E48: =IFERROR(K9*1,0) -> 23.203379
B49: =B10 -> Alphabet Inc. | C49: =IFERROR(H10*1,0) -> 25.085937 | D49: =IFERROR(I10*1,0) -> 9.3518972 | E49: =IFERROR(K10*1,0) -> 29.239593
B50: =B11 -> Meta Platforms, Inc. | C50: =IFERROR(H11*1,0) -> 15.634558 | D50: =IFERROR(I11*1,0) -> 7.9268949 | E50: =IFERROR(K11*1,0) -> 26.680851
...

Sheet SCENARIOS
B1: FinSight | H1: SCENARIOS — Scenario Analysis
B3: SCENARIOS
B4: All figures in USD millions unless stated | 3 scenarios: Pessimistic / Realistic (Base) / Optimistic
B5: METRIC | C5: (Units) | E5: =TEXT(INPUT!D117-3,"0") -> 2022 | F5: =TEXT(INPUT!D117-2,"0") -> 2023 | G5: =TEXT(INPUT!D117-1,"0") -> 2024 | H5: =INPUT!D117&" (LTM)" -> 2025 (LTM) | I5: =TEXT(INPUT!D117+1,"0")&"F" -> 2026F | J5: =TEXT(INPUT!D117+2,"0")&"F" -> 2027F | K5: =TEXT(INPUT!D117+3,"0")&"F" -> 2028F | L5: =TEXT(INPUT!D117+4,"0")&"F" -> 2029F | M5: =TEXT(INPUT!D117+5,"0")&"F" -> 2030F
B6: ▶ SELECT SCENARIO | D6: Realistic
B7: SCENARIO ASSUMPTIONS
B8: DRIVER | C8: (Units) | D8: Pessimistic | E8: Realistic | F8: Optimistic
B9: Revenue Growth Rate (Y1-Y5) | C9: (%) | D9: {=IFERROR(INDEX(SECTOR_REF!$C$2:$E$61,MATCH(1,(SECTOR_REF!$A$2:$A$61=INPUT!$D$116)*(SECTOR_REF!$B$2:$B$61="Revenue Growth Rate (Y1-Y5)"),0),MATCH("Pessimiste",{"Pessimiste","Realiste","Optimiste"},0)),IFERROR(INPUT!H9/INPUT!G9-1,0.02))} -> 0.064255118 | E9: {=IFERROR(INDEX(SECTOR_REF!$C$2:$E$61,MATCH(1,(SECTOR_REF!$A$2:$A$61=INPUT!$D$116)*(SECTOR_REF!$B$2:$B$61="Revenue Growth Rate (Y1-Y5)"),0),MATCH("Realiste",{"Pessimiste","Realiste","Optimiste"},0)),IFERROR(INPUT!H9/INPUT!G9-1,0.05))} -> 0.064255118 | F9: {=IFERROR(INDEX(SECTOR_REF!$C$2:$E$61,MATCH(1,(SECTOR_REF!$A$2:$A$61=INPUT!$D$116)*(SECTOR_REF!$B$2:$B$61="Revenue Growth Rate (Y1-Y5)"),0),MATCH("Optimiste",{"Pessimiste","Realiste","Optimiste"},0)),IFERROR(INPUT!H9/INPUT!G9-1,0.09))} -> 0.064255118
B10: Gross Margin | C10: (%) | D10: {=IFERROR(INDEX(SECTOR_REF!$C$2:$E$61,MATCH(1,(SECTOR_REF!$A$2:$A$61=INPUT!$D$116)*(SECTOR_REF!$B$2:$B$61="Gross Margin"),0),MATCH("Pessimiste",{"Pessimiste","Realiste","Optimiste"},0)),IFERROR(INPUT!H11/INPUT!H9,0.4)-0.03)} -> 0.43905164 | E10: {=IFERROR(INDEX(SECTOR_REF!$C$2:$E$61,MATCH(1,(SECTOR_REF!$A$2:$A$61=INPUT!$D$116)*(SECTOR_REF!$B$2:$B$61="Gross Margin"),0),MATCH("Realiste",{"Pessimiste","Realiste","Optimiste"},0)),IFERROR(INPUT!H11/INPUT!H9,0.4))} -> 0.46905164 | F10: {=IFERROR(INDEX(SECTOR_REF!$C$2:$E$61,MATCH(1,(SECTOR_REF!$A$2:$A$61=INPUT!$D$116)*(SECTOR_REF!$B$2:$B$61="Gross Margin"),0),MATCH("Optimiste",{"Pessimiste","Realiste","Optimiste"},0)),IFERROR(INPUT!H11/INPUT!H9,0.4)+0.03)} -> 0.49905164
B11: EBITDA Margin | C11: (%) | D11: {=IFERROR(INDEX(SECTOR_REF!$C$2:$E$61,MATCH(1,(SECTOR_REF!$A$2:$A$61=INPUT!$D$116)*(SECTOR_REF!$B$2:$B$61="EBITDA Margin"),0),MATCH("Pessimiste",{"Pessimiste","Realiste","Optimiste"},0)),IFERROR(INPUT!H30/INPUT!H9,0.15)-0.03)} -> 0.289708 | E11: {=IFERROR(INDEX(SECTOR_REF!$C$2:$E$61,MATCH(1,(SECTOR_REF!$A$2:$A$61=INPUT!$D$116)*(SECTOR_REF!$B$2:$B$61="EBITDA Margin"),0),MATCH("Realiste",{"Pessimiste","Realiste","Optimiste"},0)),IFERROR(INPUT!H30/INPUT!H9,0.15))} -> 0.319708 | F11: {=IFERROR(INDEX(SECTOR_REF!$C$2:$E$61,MATCH(1,(SECTOR_REF!$A$2:$A$61=INPUT!$D$116)*(SECTOR_REF!$B$2:$B$61="EBITDA Margin"),0),MATCH("Optimiste",{"Pessimiste","Realiste","Optimiste"},0)),IFERROR(INPUT!H30/INPUT!H9,0.15)+0.03)} -> 0.349708
B12: Terminal Growth Rate | C12: (%) | D12: {=IFERROR(INDEX(SECTOR_REF!$C$2:$E$61,MATCH(1,(SECTOR_REF!$A$2:$A$61=INPUT!$D$116)*(SECTOR_REF!$B$2:$B$61="Terminal Growth Rate"),0),MATCH("Pessimiste",{"Pessimiste","Realiste","Optimiste"},0)),DCF!D67-0.01)} -> 0.02 | E12: {=IFERROR(INDEX(SECTOR_REF!$C$2:$E$61,MATCH(1,(SECTOR_REF!$A$2:$A$61=INPUT!$D$116)*(SECTOR_REF!$B$2:$B$61="Terminal Growth Rate"),0),MATCH("Realiste",{"Pessimiste","Realiste","Optimiste"},0)),DCF!D67)} -> 0.03 | F12: {=IFERROR(INDEX(SECTOR_REF!$C$2:$E$61,MATCH(1,(SECTOR_REF!$A$2:$A$61=INPUT!$D$116)*(SECTOR_REF!$B$2:$B$61="Terminal Growth Rate"),0),MATCH("Optimiste",{"Pessimiste","Realiste","Optimiste"},0)),DCF!D67+0.01)} -> 0.04
B13: WACC | C13: (%) | D13: {=IFERROR(INDEX(SECTOR_REF!$C$2:$E$61,MATCH(1,(SECTOR_REF!$A$2:$A$61=INPUT!$D$116)*(SECTOR_REF!$B$2:$B$61="WACC"),0),MATCH("Pessimiste",{"Pessimiste","Realiste","Optimiste"},0)),DCF!D63+0.015)} -> 0.11761386 | E13: {=IFERROR(INDEX(SECTOR_REF!$C$2:$E$61,MATCH(1,(SECTOR_REF!$A$2:$A$61=INPUT!$D$116)*(SECTOR_REF!$B$2:$B$61="WACC"),0),MATCH("Realiste",{"Pessimiste","Realiste","Optimiste"},0)),DCF!D63)} -> 0.10261386 | F13: {=IFERROR(INDEX(SECTOR_REF!$C$2:$E$61,MATCH(1,(SECTOR_REF!$A$2:$A$61=INPUT!$D$116)*(SECTOR_REF!$B$2:$B$61="WACC"),0),MATCH("Optimiste",{"Pessimiste","Realiste","Optimiste"},0)),DCF!D63-0.015)} -> 0.087613857
B14: ▶ Secteur actif : | D14: =IF(INPUT!$D$116="","— Aucun secteur sélectionné (INPUT!D116) —",INPUT!$D$116) -> Technology
B15: SCENARIO RESULTS — DYNAMIC VIEW
B16: METRIC | C16: (Units) | D16: =TEXT(INPUT!D117-3,"0") -> 2022 | E16: =TEXT(INPUT!D117-2,"0") -> 2023 | F16: =TEXT(INPUT!D117-1,"0") -> 2024 | G16: =INPUT!D117&" (LTM)" -> 2025 (LTM) | H16: =TEXT(INPUT!D117+1,"0")&"F" -> 2026F | I16: =TEXT(INPUT!D117+2,"0")&"F" -> 2027F | J16: =TEXT(INPUT!D117+3,"0")&"F" -> 2028F | K16: =TEXT(INPUT!D117+4,"0")&"F" -> 2029F | L16: =TEXT(INPUT!D117+5,"0")&"F" -> 2030F
B17: Revenue | C17: 0 | D17: =INPUT!E9 -> 394328 | E17: =INPUT!F9 -> 383285 | F17: =INPUT!G9 -> 391035 | G17: =INPUT!H9 -> 416161 | H17: =INPUT!H9*(1+IF($D$6="Pessimistic",$D$9,IF($D$6="Realistic",$E$9,$F$9))) -> 442901.47 | I17: =H17*(1+IF($D$6="Pessimistic",$D$9,IF($D$6="Realistic",$E$9,$F$9))) -> 471360.16 | J17: =I17*(1+IF($D$6="Pessimistic",$D$9,IF($D$6="Realistic",$E$9,$F$9))) -> 501647.46 | K17: =J17*(1+IF($D$6="Pessimistic",$D$9,IF($D$6="Realistic",$E$9,$F$9))) -> 533880.88 | L17: =K17*(1+IF($D$6="Pessimistic",$D$9,IF($D$6="Realistic",$E$9,$F$9))) -> 568185.46
B18: Gross Profit | C18: 0 | D18: =INPUT!E11 -> 170782 | E18: =INPUT!F11 -> 169148 | F18: =INPUT!G11 -> 180683 | G18: =INPUT!H11 -> 195201 | H18: =H17*IF($D$6="Pessimistic",$D$10,IF($D$6="Realistic",$E$10,$F$10)) -> 207743.66 | I18: =I17*IF($D$6="Pessimistic",$D$10,IF($D$6="Realistic",$E$10,$F$10)) -> 221092.26 | J18: =J17*IF($D$6="Pessimistic",$D$10,IF($D$6="Realistic",$E$10,$F$10)) -> 235298.57 | K18: =K17*IF($D$6="Pessimistic",$D$10,IF($D$6="Realistic",$E$10,$F$10)) -> 250417.7 | L18: =L17*IF($D$6="Pessimistic",$D$10,IF($D$6="Realistic",$E$10,$F$10)) -> 266508.32
B19: EBITDA | C19: 0 | D19: =INPUT!E30 -> 119437 | E19: =INPUT!F30 -> 114301 | F19: =INPUT!G30 -> 123216 | G19: =INPUT!H30 -> 133050 | H19: =H17*IF($D$6="Pessimistic",$D$11,IF($D$6="Realistic",$E$11,$F$11)) -> 141599.14 | I19: =I17*IF($D$6="Pessimistic",$D$11,IF($D$6="Realistic",$E$11,$F$11)) -> 150697.61 | J19: =J17*IF($D$6="Pessimistic",$D$11,IF($D$6="Realistic",$E$11,$F$11)) -> 160380.71 | K19: =K17*IF($D$6="Pessimistic",$D$11,IF($D$6="Realistic",$E$11,$F$11)) -> 170685.99 | L19: =L17*IF($D$6="Pessimistic",$D$11,IF($D$6="Realistic",$E$11,$F$11)) -> 181653.44
B20: Net Income | C20: 0 | D20: =INPUT!E26 -> 90694 | E20: =INPUT!F26 -> 87496 | F20: =INPUT!G26 -> 84845 | G20: =INPUT!H26 -> 102457 | H20: =H19*0.6 -> 84959.486 | I20: =I19*0.6 -> 90418.568 | J20: =J19*0.6 -> 96228.424 | K20: =K19*0.6 -> 102411.59 | L20: =L19*0.6 -> 108992.06
B21: Free Cash Flow (Est.) | C21: 0 | D21: =IFERROR(INPUT!E75+INPUT!E78,"–") -> 93685 | E21: =IFERROR(INPUT!F75+INPUT!F78,"–") -> 81905 | F21: =IFERROR(INPUT!G75+INPUT!G78,"–") -> 84407 | G21: =IFERROR(INPUT!H75+INPUT!H78,"–") -> 96624 | H21: =H19*0.5 -> 70799.572 | I21: =I19*0.5 -> 75348.807 | J21: =J19*0.5 -> 80190.353 | K21: =K19*0.5 -> 85342.994 | L21: =L19*0.5 -> 90826.718
B22: EBITDA Margin | C22: (%) | D22: =IFERROR(INPUT!E30/INPUT!E9,"–") -> 0.30288744 | E22: =IFERROR(INPUT!F30/INPUT!F9,"–") -> 0.29821412 | F22: =IFERROR(INPUT!G30/INPUT!G9,"–") -> 0.31510223 | G22: =IFERROR(INPUT!H30/INPUT!H9,"–") -> 0.319708 | H22: =IFERROR(H19/H17,"–") -> 0.319708 | I22: =IFERROR(I19/I17,"–") -> 0.319708 | J22: =IFERROR(J19/J17,"–") -> 0.319708 | K22: =IFERROR(K19/K17,"–") -> 0.319708 | L22: =IFERROR(L19/L17,"–") -> 0.319708
B23: Implied Share Price | C23: ($) | M23: =IFERROR("$"&TEXT(IF($D$6="Pessimistic",DCF!D91*(1+$D$9+$D$11-$E$9-$E$11)*0.8,IF($D$6="Realistic",DCF!D91,DCF!D91*(1+$F$9+$F$11-$E$9-$E$11)*1.2)),"#,##0.00"),"–") -> $68,963.99
B25: SCENARIO SUMMARY COMPARISON
B26: METRIC (Year 5) | D26: Pessimistic | E26: Realistic | F26: Optimistic
B27: Revenue (Year 5) | C27: 0 | D27: =INPUT!H9*(1+$D$9)^5 -> 568185.46 | E27: =INPUT!H9*(1+$E$9)^5 -> 568185.46 | F27: =INPUT!H9*(1+$F$9)^5 -> 568185.46
B28: EBITDA (Year 5) | C28: 0 | D28: =D27*$D$11 -> 164607.87 | E28: =E27*$E$11 -> 181653.44 | F28: =F27*$F$11 -> 198699
B29: Net Income (Year 5) | C29: 0 | D29: =D28*0.6 -> 98764.723 | E29: =E28*0.6 -> 108992.06 | F29: =F28*0.6 -> 119219.4
B30: FCF (Year 5) | C30: 0 | D30: =D28*0.5 -> 82303.936 | E30: =E28*0.5 -> 90826.718 | F30: =F28*0.5 -> 99349.5
B31: EBITDA Margin (Year 5) | C31: (%) | D31: =$D$11 -> 0.289708 | E31: =$E$11 -> 0.319708 | F31: =$F$11 -> 0.349708
B32: Implied Share Price | C32: ($) | D32: =IFERROR("$"&TEXT(DCF!D91*(1+$D$9+$D$11-$E$9-$E$11)*0.8,"#,##0.00"),"–") -> $53,516.06 | E32: =IFERROR("$"&TEXT(DCF!D91,"#,##0.00"),"–") -> $68,963.99 | F32: =IFERROR("$"&TEXT(DCF!D91*(1+$F$9+$F$11-$E$9-$E$11)*1.2,"#,##0.00"),"–") -> $85,239.49
B33: Delta (Opt. vs Pess.) | D33: ="—" -> — | E33: ="—" -> — | F33: =IFERROR(F27/D27-1,"–") -> 0
B34: Revenue
B35: ="▶ SCÉNARIO SÉLECTIONNÉ : "&$D$6 -> ▶ SCÉNARIO SÉLECTIONNÉ : Realistic
B37: CHART DATA: Revenue by Scenario
B38: Year | D38: =TEXT(INPUT!D117+1,"0")&"F" -> 2026F | E38: =TEXT(INPUT!D117+2,"0")&"F" -> 2027F | F38: =TEXT(INPUT!D117+3,"0")&"F" -> 2028F | G38: =TEXT(INPUT!D117+4,"0")&"F" -> 2029F | H38: =TEXT(INPUT!D117+5,"0")&"F" -> 2030F
B39: Pessimistic | D39: =IF(INPUT!H9="",NA(),INPUT!H9*(1+$D$9)) -> 442901.47 | E39: =IF(INPUT!H9="",NA(),D39*(1+$D$9)) -> 471360.16 | F39: =IF(INPUT!H9="",NA(),E39*(1+$D$9)) -> 501647.46 | G39: =IF(INPUT!H9="",NA(),F39*(1+$D$9)) -> 533880.88 | H39: =IF(INPUT!H9="",NA(),G39*(1+$D$9)) -> 568185.46
B40: Realistic | D40: =IF(INPUT!H9="",NA(),INPUT!H9*(1+$E$9)) -> 442901.47 | E40: =IF(INPUT!H9="",NA(),D40*(1+$E$9)) -> 471360.16 | F40: =IF(INPUT!H9="",NA(),E40*(1+$E$9)) -> 501647.46 | G40: =IF(INPUT!H9="",NA(),F40*(1+$E$9)) -> 533880.88 | H40: =IF(INPUT!H9="",NA(),G40*(1+$E$9)) -> 568185.46
B41: Optimistic | D41: =IF(INPUT!H9="",NA(),INPUT!H9*(1+$F$9)) -> 442901.47 | E41: =IF(INPUT!H9="",NA(),D41*(1+$F$9)) -> 471360.16 | F41: =IF(INPUT!H9="",NA(),E41*(1+$F$9)) -> 501647.46 | G41: =IF(INPUT!H9="",NA(),F41*(1+$F$9)) -> 533880.88 | H41: =IF(INPUT!H9="",NA(),G41*(1+$F$9)) -> 568185.46
B42: SCENARIO SUMMARY COMPARISON
B43: CHART DATA: EBITDA by Scenario
...

Sheet DASHBOARD
B1: FinSight | Q1: Année | R1: 2022 | S1: 2023 | T1: 2024
Q2: Année | R2: Cumul Revenue | S2: =RATIOS!F78 -> 1168648 | T2: =RATIOS!G78 -> 1584809
B3: Financial Performance | Q3: 2022 | R3: =RATIOS!E78 -> 777613
Q4: 2023 | R4: =RATIOS!F78 -> 1168648
M5: ="All figures in "&INPUT!D118&" "&INPUT!D119&" unless stated" -> All figures in USD M unless stated | Q5: 2024 | R5: =RATIOS!G78 -> 1584809
Q7: Year | R7: Revenue | S7: Net Income | T7: Net Margin
B8: Revenue & Profitability | H8: Profit Margins | Q8: 2022 | R8: =RATIOS!E75 -> 394328 | S8: =RATIOS!E77 -> 87496 | T8: =RATIOS!E82 -> 0.22999635
Q9: 2023 | R9: =RATIOS!F75 -> 383285 | S9: =RATIOS!F77 -> 84845 | T9: =RATIOS!F82 -> 0.22827922
Q10: 2024 | R10: =RATIOS!G75 -> 391035 | S10: =RATIOS!G77 -> 84845 | T10: =RATIOS!G82 -> 0.21697546
Q11: 2025 (LTM) | R11: =RATIOS!H75 -> 416161 | S11: =RATIOS!H77 -> 102457 | T11: =RATIOS!H82 -> 0.24619558
B25: Cumulative revenue | H25: Expense Breakdown
B42: Performance Summary (Five-Year) | H42: Income Statement (LTM)
C44: 5-Yr Avg | D44: Trend | I44: Actual | J44: Prev Year | K44: Variance | L44: Var %
B45: Revenue | C45: =AVERAGE(INPUT!D9:H9) -> 396202.25 | H45: Revenue | I45: =INPUT!H9 -> 416161 | J45: =INPUT!G9 -> 391035 | K45: =I45-J45 -> 25126 | L45: =IF(J45=0,NA(),K45/ABS(J45)) -> 0.064255118
B47: COGS | C47: =ABS(AVERAGE(INPUT!D10:H10)) -> 217248.75 | H47: COGS | I47: =ABS(INPUT!H10) -> 220960 | J47: =ABS(INPUT!G10) -> 210352 | K47: =I47-J47 -> 10608 | L47: =IF(J47=0,NA(),K47/ABS(J47)) -> 0.050429756
B49: Expenses | C49: =ABS(AVERAGE(INPUT!D13:H13)) -> 54315.2 | H49: Expenses | I49: =ABS(INPUT!H13) -> 73849 | J49: =ABS(INPUT!G13) -> 68912 | K49: =I49-J49 -> 4937 | L49: =IF(J49=0,NA(),K49/ABS(J49)) -> 0.071642094
B51: Net Income | C51: =AVERAGE(INPUT!D26:H26) -> 73098.4 | H51: Net Income | I51: =INPUT!H26 -> 102457 | J51: =INPUT!G26 -> 84845 | K51: =I51-J51 -> 17612 | L51: =IF(J51=0,NA(),K51/ABS(J51)) -> 0.20757853
B53: Net Margin (%) | C53: =AVERAGE(INPUT!D26:H26)/AVERAGE(INPUT!D9:H9) -> 0.18449769 | H53: Net Margin (%) | I53: =INPUT!H26/INPUT!H9 -> 0.24619558 | J53: =INPUT!G26/INPUT!G9 -> 0.21697546 | K53: =I53-J53 -> 0.02922012 | L53: =IF(J53=0,NA(),K53/ABS(J53)) -> 0.13467016
B58: P&L Summary (LTM) | C58: P&L Summary (LTM) | D58: P&L Summary (LTM) | E58: P&L Summary (LTM) | H58: Balance Sheet Summary (LTM)
B60: Revenue | D60: =INPUT!H9 -> 416161 | E60: =INPUT!H9 -> 416161 | H60: Assets
B61: COGS | D61: =INPUT!H10 -> -220960 | E61: =ABS(INPUT!H10) -> 220960 | H61: Current Assets | J61: =INPUT!H38 -> 96014 | K61: =INPUT!H38 -> 96014
H62: Non-current Assets | J62: =SUM(INPUT!H41:H43) -> 114173 | K62: =SUM(INPUT!H41:H43) -> 114173
B63: Expenses | D63: =ABS(INPUT!H14) -> 27601
B64: SG&A | D64: =ABS(INPUT!H15) -> 34550 | E64: =ABS(INPUT!H15) -> 34550 | H64: Total Assets | J64: =INPUT!H44 -> 210187 | K64: =INPUT!H44 -> 210187
B65: R&D | D65: =ABS(INPUT!H16) -> 11698 | E65: =ABS(INPUT!H16) -> 11698
B66: D&A | D66: =ABS(INPUT!H20) -> 0 | E66: =ABS(INPUT!H20) -> 0 | H66: Liabilities | J66: =INPUT!H51 -> 147657
B67: Interest | D67: =SUM(D64:D66) -> 46248 | E67: =SUM(E64:E66) -> 46248 | H67: Current Liabilities | J67: =INPUT!H54 -> 78328 | K67: =INPUT!H51 -> 147657
B68: Total Expenses | D68: =SUM(D64:D67) -> 92496 | E68: =SUM(E64:E67) -> 92496 | H68: Long-term Liabilities | J68: =INPUT!H60 -> 79304 | K68: =INPUT!H54 -> 78328
H69: Shareholders' Equity | J69: =INPUT!F60 -> 73598 | K69: =INPUT!H60 -> 79304
D70: =D60+D61-D68 -> 102705 | J70: =INPUT!H63 -> 305289
B71: Net Operating Profit | D71: =D60+D61-D68 -> 102705 | E71: =E60-E61-E68 -> 102705 | H71: Liabilities & Shareholders' Equity | J71: =INPUT!F63 -> 306126 | K71: =INPUT!H63 -> 305289
C81: =IF(INPUT!D5="",NA(),INPUT!D5) -> #N/A | D81: =INPUT!E5 -> 2022 | E81: =INPUT!F5 -> 2023 | F81: =INPUT!G5 -> 2024 | G81: =INPUT!H5 -> 2025 (LTM) | I81: =IF(INPUT!D5="",NA(),INPUT!D5) -> #N/A | J81: =INPUT!E5 -> 2022 | K81: =INPUT!F5 -> 2023 | L81: =INPUT!G5 -> 2024 | M81: =INPUT!H5 -> 2025 (LTM)
B82: Revenue | C82: =IF(INPUT!D9="",NA(),INPUT!D9) -> #N/A | D82: =IF(INPUT!E9="",NA(),INPUT!E9) -> 394328 | E82: =IF(INPUT!F9="",NA(),INPUT!F9) -> 383285 | F82: =IF(INPUT!G9="",NA(),INPUT!G9) -> 391035 | G82: =IF(INPUT!H9="",NA(),INPUT!H9) -> 416161
C83: EBITDA | D83: =IF(INPUT!D30="",NA(),INPUT!D30) -> 0 | E83: =IF(INPUT!E30="",NA(),INPUT!E30) -> 119437 | F83: =IF(INPUT!F30="",NA(),INPUT!F30) -> 114301 | G83: =IF(INPUT!G30="",NA(),INPUT!G30) -> 123216 | H83: =IF(INPUT!H30="",NA(),INPUT!H30) -> 133050
C84: Net Income | D84: =IF(INPUT!D26="",NA(),INPUT!D26) -> 0 | E84: =IF(INPUT!E26="",NA(),INPUT!E26) -> 90694 | F84: =IF(INPUT!F26="",NA(),INPUT!F26) -> 87496 | G84: =IF(INPUT!G26="",NA(),INPUT!G26) -> 84845 | H84: =IF(INPUT!H26="",NA(),INPUT!H26) -> 102457
J85: =IF(INPUT!D5="",NA(),INPUT!D5) -> #N/A | K85: =INPUT!E5 -> 2022 | L85: =INPUT!F5 -> 2023 | M85: =INPUT!G5 -> 2024 | N85: =INPUT!H5 -> 2025 (LTM)
I86: Gross Margin | J86: =IF(INPUT!D9="",NA(),INPUT!D11/INPUT!D9) -> #N/A | K86: =IF(INPUT!E9="",NA(),INPUT!E11/INPUT!E9) -> 0.43309631 | L86: =IF(INPUT!F9="",NA(),INPUT!F11/INPUT!F9) -> 0.4413113 | M86: =IF(INPUT!G9="",NA(),INPUT!G11/INPUT!G9) -> 0.4620635 | N86: =IF(INPUT!H9="",NA(),INPUT!H11/INPUT!H9) -> 0.46905164
I87: EBITDA Margin | J87: =IF(INPUT!D9="",NA(),INPUT!D30/INPUT!D9) -> #N/A | K87: =IF(INPUT!E9="",NA(),INPUT!E30/INPUT!E9) -> 0.30288744 | L87: =IF(INPUT!F9="",NA(),INPUT!F30/INPUT!F9) -> 0.29821412 | M87: =IF(INPUT!G9="",NA(),INPUT!G30/INPUT!G9) -> 0.31510223 | N87: =IF(INPUT!H9="",NA(),INPUT!H30/INPUT!H9) -> 0.319708
D88: =IF(INPUT!D5="",NA(),INPUT!D5) -> #N/A | E88: =INPUT!E5 -> 2022 | F88: =INPUT!F5 -> 2023 | G88: =INPUT!G5 -> 2024 | H88: =INPUT!H5 -> 2025 (LTM) | I88: Net Margin | J88: =IF(INPUT!D9="",NA(),INPUT!D26/INPUT!D9) -> #N/A | K88: =IF(INPUT!E9="",NA(),INPUT!E26/INPUT!E9) -> 0.22999635 | L88: =IF(INPUT!F9="",NA(),INPUT!F26/INPUT!F9) -> 0.22827922 | M88: =IF(INPUT!G9="",NA(),INPUT!G26/INPUT!G9) -> 0.21697546 | N88: =IF(INPUT!H9="",NA(),INPUT!H26/INPUT!H9) -> 0.24619558
C89: Revenue | D89: =IF(INPUT!D9="",NA(),INPUT!D9) -> #N/A | E89: =IF(INPUT!E9="",NA(),INPUT!E9) -> 394328 | F89: =IF(INPUT!F9="",NA(),INPUT!F9) -> 383285 | G89: =IF(INPUT!G9="",NA(),INPUT!G9) -> 391035 | H89: =IF(INPUT!H9="",NA(),INPUT!H9) -> 416161
...

Sheet DASHBOARD 2
B1: FinSight | R1: =INPUT!D114&" ("&INPUT!D115&") — "&INPUT!D116 -> Apple Inc. (AAPL) — Technology
B3: Projected Business Performance | Q3: Football Field Chart — Valuation Inputs
B5: All figures in USD Thousands unless stated | T5: Low ($) | U5: Delta ($) | V5: High ($)
B6: Company Information | Q6: 52-Week Trading Range | T6: =INPUT!H95*0.75 -> 195.975 | U6: =V6-T6 -> 182.91 | V6: =INPUT!H95*1.45 -> 378.885
C7: Company Name | D7: =INPUT!D114 -> Apple Inc. | Q7: Consensus Research | T7: =INPUT!H95*1.1 -> 287.43 | U7: =V7-T7 -> 130.65 | V7: =INPUT!H95*1.6 -> 418.08
C8: Ticker Symbol | D8: =INPUT!D115 -> AAPL | Q8: Precedent Transactions | T8: =INPUT!H95*1.2 -> 313.56 | U8: =V8-T8 -> 143.715 | V8: =INPUT!H95*1.75 -> 457.275
C9: Sector | D9: =INPUT!D116 -> Technology | Q9: Sum-of-the-Parts | T9: =INPUT!H95*1.3 -> 339.69 | U9: =V9-T9 -> 143.715 | V9: =INPUT!H95*1.85 -> 483.405
C10: Base Year (LTM) | D10: =INPUT!D117 -> 2025 | Q10: Discounted Cash Flow | T10: =INPUT!H95*1.15 -> 300.495 | U10: =V10-T10 -> 143.715 | V10: =INPUT!H95*1.7 -> 444.21
C11: Currency | D11: =INPUT!D118 -> USD | Q11: Current Share Price | T11: =INPUT!H95 -> 261.3
C12: Analysis Date | D12: =INPUT!D120 -> 2026-04-10
Q15: Financial Data — Multi-Year
Q17: All figures in USD Thousands unless stated | T17: =INPUT!E5 -> 2022 | U17: =INPUT!E5 -> 2022 | V17: =INPUT!F5 -> 2023 | W17: =INPUT!G5 -> 2024 | X17: =INPUT!H5 -> 2025 (LTM)
B19: Stock Chart: Trailing 52-Weeks | I19: Valuation Summary: Football Field Chart | Q19: Revenue Growth (%) | T19: ="" | U19: =IF(INPUT!D9=0,"",INPUT!E9/INPUT!D9-1) | V19: =IF(INPUT!E9=0,"",INPUT!F9/INPUT!E9-1) -> -0.028004605 | W19: =IF(INPUT!F9=0,"",INPUT!G9/INPUT!F9-1) -> 0.020219941 | X19: =IF(INPUT!G9=0,"",INPUT!H9/INPUT!G9-1) -> 0.064255118
Q20: EBITDA Growth (%) | T20: ="" | U20: ="" | V20: =IF(INPUT!D30=0,"",INPUT!F30/INPUT!E30-1) | W20: =IF(INPUT!E30=0,"",INPUT!G30/INPUT!F30-1) -> 0.077995818 | X20: =IF(INPUT!F30=0,"",INPUT!H30/INPUT!G30-1) -> 0.079811063
Q22: Revenue
Q23: Revenue — Products | T23: =INPUT!E9 -> 394328 | U23: =INPUT!E9 -> 394328 | V23: =INPUT!F9 -> 383285 | W23: =INPUT!G9 -> 391035 | X23: =INPUT!H9 -> 416161
Q24: Cost of Revenue (COGS) | T24: =ABS(INPUT!E10) -> 223546 | U24: =ABS(INPUT!E10) -> 223546 | V24: =ABS(INPUT!F10) -> 214137 | W24: =ABS(INPUT!G10) -> 210352 | X24: =ABS(INPUT!H10) -> 220960
Q25: Gross Profit | T25: =INPUT!E11 -> 170782 | U25: =INPUT!E11 -> 170782 | V25: =INPUT!F11 -> 169148 | W25: =INPUT!G11 -> 180683 | X25: =INPUT!H11 -> 195201
Q26: SG&A | T26: =ABS(INPUT!E14) -> 25094 | U26: =ABS(INPUT!E14) -> 25094 | V26: =ABS(INPUT!F14) -> 24932 | W26: =ABS(INPUT!G14) -> 26097 | X26: =ABS(INPUT!H14) -> 27601
Q27: Total Revenue | T27: =INPUT!E9 -> 394328 | U27: =INPUT!E9 -> 394328 | V27: =INPUT!F9 -> 383285 | W27: =INPUT!G9 -> 391035 | X27: =INPUT!H9 -> 416161
Q29: EBITDA | T29: =INPUT!E30 -> 119437 | U29: =INPUT!E30 -> 119437 | V29: =INPUT!F30 -> 114301 | W29: =INPUT!G30 -> 123216 | X29: =INPUT!H30 -> 133050
Q30: Cash from Ops (CFO) | T30: =INPUT!E75 -> 104393 | U30: =INPUT!E75 -> 104393 | V30: =INPUT!F75 -> 92864 | W30: =INPUT!G75 -> 93854 | X30: =INPUT!H75 -> 109339
