Workbook

Sheet SYNTHÈSE
A1: FinSight | C1: COMPARATIF SECTORIEL — Technologie vs Healthcare
A2: ="Données : "&COUNTA(DATA_TECH!A4:A91)&" valeurs Technologie · "&COUNTA(DATA_HC!A4:A9)&" valeurs Healthcare · Médiane sectorielle · Toutes formules dynamiques" -> Données : 88 valeurs Technologie · 6 valeurs Healthcare · Médiane sectorielle · Toutes formules dynamiques
A4: TABLEAU COMPARATIF — MÉDIANES SECTORIELLES
A5: INDICATEUR | B5: DESCRIPTION | C5: TECHNOLOGIE | D5: HEALTHCARE | E5: Δ ABSOLU | F5: Δ % | G5: AVANTAGE
A6: Nb valeurs | B6: Taille de l'échantillon | C6: =COUNTA(DATA_TECH!A4:A91) -> 88 | D6: =COUNTA(DATA_HC!A4:A9) -> 6 | E6: =C6-D6 -> 82 | F6: ="" | G6: =IF(C6>D6,"Tech","HC") -> Tech
A7: Score FinSight médian | B7: Qualité fondamentale agrégée (0–100) | C7: =AGRÉGATS!D6 -> 52 | D7: =AGRÉGATS!D15 -> 74.5 | E7: =C7-D7 -> -22.5 | F7: =IFERROR(TEXT((C7-D7)/D7*100,"0.0")&"%","—") -> -3.0% | G7: =IF(C7>D7,"✓ Tech","✓ HC") -> ✓ HC
A8: Marge EBITDA médiane | B8: Profitabilité opérationnelle | C8: =AGRÉGATS!D7/100 -> 0.275 | D8: =AGRÉGATS!D16/100 -> 0.3175 | E8: =C8-D8 -> -0.0425 | F8: =IFERROR(TEXT((C8-D8)/D8*100,"0.0")&"%","—") -> -1.3% | G8: =IF(C8>D8,"✓ Tech","✓ HC") -> ✓ HC
A9: P/E médian | B9: Valorisation bénéfices (×) | C9: =AGRÉGATS!D8 -> 34.75 | D9: =AGRÉGATS!D17 -> 18.25 | E9: =C9-D9 -> 16.5 | F9: =IFERROR(TEXT((C9-D9)/D9*100,"0.0")&"%","—") -> 9.0% | G9: =IF(C9>D9,"Prime Tech","Prime HC") -> Prime Tech
A10: EV/EBITDA médian | B10: Valorisation hors structure (×) | C10: =AGRÉGATS!D9 -> 21.5 | D10: =AGRÉGATS!D18 -> 14.2 | E10: =C10-D10 -> 7.3 | F10: =IFERROR(TEXT((C10-D10)/D10*100,"0.0")&"%","—") -> 5.1% | G10: =IF(C10>D10,"Prime Tech","Prime HC") -> Prime Tech
A11: ROE médian | B11: Rentabilité des fonds propres | C11: =AGRÉGATS!D10/100 -> 0.192 | D11: =AGRÉGATS!D19/100 -> 0.2475 | E11: =C11-D11 -> -0.0555 | F11: =IFERROR(TEXT((C11-D11)/D11*100,"0.0")&"%","—") -> -2.2% | G11: =IF(C11>D11,"✓ Tech","✓ HC") -> ✓ HC
A12: Croiss. revenus médiane | B12: Dynamique commerciale YoY | C12: =AGRÉGATS!D11/100 -> 0.097 | D12: =AGRÉGATS!D20/100 -> 0.1245 | E12: =C12-D12 -> -0.0275 | F12: =IFERROR(TEXT((C12-D12)/D12*100,"0.0")&"%","—") -> -2.2% | G12: =IF(C12>D12,"✓ Tech","✓ HC") -> ✓ HC
A14: STATISTIQUES AVANCÉES — DISPERSION & AMPLITUDE SECTORIELLES
A15: INDICATEUR | B15: TECH Médiane | C15: TECH Moyenne | D15: TECH Min | E15: TECH Max | F15: HC Médiane | G15: HC Min | H15: HC Max | I15: Δ Médiane
A16: Score FinSight | B16: =AGRÉGATS!D6 -> 52 | C16: =AGRÉGATS!E6 -> 49.863636 | D16: =AGRÉGATS!F6 -> 0 | E16: =AGRÉGATS!G6 -> 88 | F16: =AGRÉGATS!D15 -> 74.5 | G16: =AGRÉGATS!F15 -> 58 | H16: =AGRÉGATS!G15 -> 81 | I16: =B16-F16 -> -22.5
A17: Marge EBITDA | B17: =AGRÉGATS!D7/100 -> 0.275 | C17: =AGRÉGATS!E7/100 -> 0.2819186 | D17: =AGRÉGATS!F7/100 -> -0.17 | E17: =AGRÉGATS!G7/100 -> 0.71 | F17: =AGRÉGATS!D16/100 -> 0.3175 | G17: =AGRÉGATS!F16/100 -> 0.273 | H17: =AGRÉGATS!G16/100 -> 0.423 | I17: =B17-F17 -> -0.0425
A18: P/E | B18: =AGRÉGATS!D8 -> 34.75 | C18: =AGRÉGATS!E8 -> 45.359375 | D18: =AGRÉGATS!F8 -> 6.6 | E18: =AGRÉGATS!G8 -> 221.5 | F18: =AGRÉGATS!D17 -> 18.25 | G18: =AGRÉGATS!F17 -> 13.1 | H18: =AGRÉGATS!G17 -> 61.8 | I18: =B18-F18 -> 16.5
A19: EV/EBITDA | B19: =AGRÉGATS!D9 -> 21.5 | C19: =AGRÉGATS!E9 -> 28.811429 | D19: =AGRÉGATS!F9 -> 5.5 | E19: =AGRÉGATS!G9 -> 87.7 | F19: =AGRÉGATS!D18 -> 14.2 | G19: =AGRÉGATS!F18 -> 9.4 | H19: =AGRÉGATS!G18 -> 43.2 | I19: =B19-F19 -> 7.3
A20: ROE | B20: =AGRÉGATS!D10/100 -> 0.192 | C20: =AGRÉGATS!E10/100 -> 0.19570115 | D20: =AGRÉGATS!F10/100 -> -7.309 | E20: =AGRÉGATS!G10/100 -> 4.068 | F20: =AGRÉGATS!D19/100 -> 0.2475 | G20: =AGRÉGATS!F19/100 -> 0.147 | H20: =AGRÉGATS!G19/100 -> 0.872 | I20: =B20-F20 -> -0.0555
A21: Croiss. Rev. | B21: =AGRÉGATS!D11/100 -> 0.097 | C21: =AGRÉGATS!E11/100 -> 0.11748276 | D21: =AGRÉGATS!F11/100 -> -2 | E21: =AGRÉGATS!G11/100 -> 1.7 | F21: =AGRÉGATS!D20/100 -> 0.1245 | G21: =AGRÉGATS!F20/100 -> 0.031 | H21: =AGRÉGATS!G20/100 -> 0.318 | I21: =B21-F21 -> -0.0275
A23: TOP PERFORMERS — N°1 PAR SECTEUR (Score FinSight)
A24: SECTEUR | B24: TICKER | C24: SOCIÉTÉ | D24: SCORE | E24: MARGE EBITDA | F24: ROE | G24: CROISS. REV.
A25: Technologie | B25: =TOP_TECH!B5 -> NVDA | C25: =TOP_TECH!C5 -> NVIDIA Corporation | D25: =TOP_TECH!D5 -> 88 | E25: =TOP_TECH!G5/100 -> 0.669 | F25: =TOP_TECH!H5/100 -> 0.763 | G25: =TOP_TECH!I5/100 -> 0.655
A26: Healthcare | B26: =TOP_HC!B5 -> NVO | C26: =TOP_HC!C5 -> Novo Nordisk A/S | D26: =TOP_HC!D5 -> 81 | E26: =TOP_HC!G5/100 -> 0.423 | F26: =TOP_HC!H5/100 -> 0.872 | G26: =TOP_HC!I5/100 -> 0.241
A28: MÉDIANES PONDÉRÉES PAR SCORE FINSIGHT — Valeurs de qualité supérieure surpondérées
A29: Les médianes pondérées donnent plus de poids aux valeurs avec un Score FinSight élevé (SUMPRODUCT Score × KPI / SUM Score)
A30: INDICATEUR | B30: MG EBITDA pondérée | C30: P/E pondéré | D30: EV/EBITDA pondéré | E30: ROE pondéré | F30: CROISS. REV. pondérée
A31: Technologie (pondérée) | B31: {=IFERROR(SUMPRODUCT((DATA_TECH!$C$4:$C$91)*(DATA_TECH!F4:F91)*(ISNUMBER(DATA_TECH!F4:F91)))/SUMPRODUCT((DATA_TECH!$C$4:$C$91)*(ISNUMBER(DATA_TECH!F4:F91))),"")} -> 30.763739 | C31: {=IFERROR(SUMPRODUCT((DATA_TECH!$C$4:$C$91)*(DATA_TECH!D4:D91)*(ISNUMBER(DATA_TECH!D4:D91)))/SUMPRODUCT((DATA_TECH!$C$4:$C$91)*(ISNUMBER(DATA_TECH!D4:D91))),"")} -> 43.532602 | D31: {=IFERROR(SUMPRODUCT((DATA_TECH!$C$4:$C$91)*(DATA_TECH!E4:E91)*(ISNUMBER(DATA_TECH!E4:E91)))/SUMPRODUCT((DATA_TECH!$C$4:$C$91)*(ISNUMBER(DATA_TECH!E4:E91))),"")} -> 29.01267 | E31: {=IFERROR(SUMPRODUCT((DATA_TECH!$C$4:$C$91)*(DATA_TECH!G4:G91)*(ISNUMBER(DATA_TECH!G4:G91)))/SUMPRODUCT((DATA_TECH!$C$4:$C$91)*(ISNUMBER(DATA_TECH!G4:G91))),"")} -> 21.526581 | F31: {=IFERROR(SUMPRODUCT((DATA_TECH!$C$4:$C$91)*(DATA_TECH!H4:H91)*(ISNUMBER(DATA_TECH!H4:H91)))/SUMPRODUCT((DATA_TECH!$C$4:$C$91)*(ISNUMBER(DATA_TECH!H4:H91))),"")} -> 13.798183
A32: Healthcare (pondérée) | B32: {=IFERROR(SUMPRODUCT((DATA_HC!$C$4:$C$9)*(DATA_HC!F4:F9)*(ISNUMBER(DATA_HC!F4:F9)))/SUMPRODUCT((DATA_HC!$C$4:$C$9)*(ISNUMBER(DATA_HC!F4:F9))),"")} -> 34.013457 | C32: {=IFERROR(SUMPRODUCT((DATA_HC!$C$4:$C$9)*(DATA_HC!D4:D9)*(ISNUMBER(DATA_HC!D4:D9)))/SUMPRODUCT((DATA_HC!$C$4:$C$9)*(ISNUMBER(DATA_HC!D4:D9))),"")} -> 27.684687 | D32: {=IFERROR(SUMPRODUCT((DATA_HC!$C$4:$C$9)*(DATA_HC!E4:E9)*(ISNUMBER(DATA_HC!E4:E9)))/SUMPRODUCT((DATA_HC!$C$4:$C$9)*(ISNUMBER(DATA_HC!E4:E9))),"")} -> 20.27587 | E32: {=IFERROR(SUMPRODUCT((DATA_HC!$C$4:$C$9)*(DATA_HC!G4:G9)*(ISNUMBER(DATA_HC!G4:G9)))/SUMPRODUCT((DATA_HC!$C$4:$C$9)*(ISNUMBER(DATA_HC!G4:G9))),"")} -> 39.233179 | F32: {=IFERROR(SUMPRODUCT((DATA_HC!$C$4:$C$9)*(DATA_HC!H4:H9)*(ISNUMBER(DATA_HC!H4:H9)))/SUMPRODUCT((DATA_HC!$C$4:$C$9)*(ISNUMBER(DATA_HC!H4:H9))),"")} -> 16.011833

Sheet AGRÉGATS
A1: FinSight | C1: AGRÉGATS — Statistiques comparatives Technologie vs Healthcare
A2: Médiane · Moyenne · Min · Max · Écart-type — liés à DATA_TECH (88 valeurs) et DATA_HC (6 valeurs)
A4: TECHNOLOGIE — 88 valeurs
A5: SECTEUR | B5: INDICATEUR | C5: N | D5: MÉDIANE | E5: MOYENNE | F5: MIN | G5: MAX | H5: ÉCART-TYPE | I5: Q1 (25e) | J5: Q3 (75e) | K5: IQR | L5: UNITÉ
A6: Technologie | B6: Score FinSight | C6: =COUNT(DATA_TECH!C4:C91) -> 88 | D6: =MEDIAN(DATA_TECH!C4:C91) -> 52 | E6: =AVERAGE(DATA_TECH!C4:C91) -> 49.863636 | F6: =MIN(DATA_TECH!C4:C91) -> 0 | G6: =MAX(DATA_TECH!C4:C91) -> 88 | H6: =STDEV(DATA_TECH!C4:C91) -> 16.21634 | I6: =QUARTILE(DATA_TECH!C4:C91,1) -> 39 | J6: =QUARTILE(DATA_TECH!C4:C91,3) -> 60 | K6: =J6-I6 -> 21 | L6: entier
A7: Technologie | B7: Marge EBITDA | C7: =COUNT(DATA_TECH!F4:F91) -> 86 | D7: =MEDIAN(DATA_TECH!F4:F91) -> 27.5 | E7: =AVERAGE(DATA_TECH!F4:F91) -> 28.19186 | F7: =MIN(DATA_TECH!F4:F91) -> -17 | G7: =MAX(DATA_TECH!F4:F91) -> 71 | H7: =STDEV(DATA_TECH!F4:F91) -> 14.402142 | I7: =QUARTILE(DATA_TECH!F4:F91,1) -> 20.025 | J7: =QUARTILE(DATA_TECH!F4:F91,3) -> 35.4 | K7: =J7-I7 -> 15.375 | L7: % (pts)
A8: Technologie | B8: P/E | C8: =COUNT(DATA_TECH!D4:D91) -> 32 | D8: =MEDIAN(DATA_TECH!D4:D91) -> 34.75 | E8: =AVERAGE(DATA_TECH!D4:D91) -> 45.359375 | F8: =MIN(DATA_TECH!D4:D91) -> 6.6 | G8: =MAX(DATA_TECH!D4:D91) -> 221.5 | H8: =STDEV(DATA_TECH!D4:D91) -> 40.569525 | I8: =QUARTILE(DATA_TECH!D4:D91,1) -> 22.575 | J8: =QUARTILE(DATA_TECH!D4:D91,3) -> 56.175 | K8: =J8-I8 -> 33.6 | L8: x
A9: Technologie | B9: EV/EBITDA | C9: =COUNT(DATA_TECH!E4:E91) -> 35 | D9: =MEDIAN(DATA_TECH!E4:E91) -> 21.5 | E9: =AVERAGE(DATA_TECH!E4:E91) -> 28.811429 | F9: =MIN(DATA_TECH!E4:E91) -> 5.5 | G9: =MAX(DATA_TECH!E4:E91) -> 87.7 | H9: =STDEV(DATA_TECH!E4:E91) -> 21.328988 | I9: =QUARTILE(DATA_TECH!E4:E91,1) -> 15.15 | J9: =QUARTILE(DATA_TECH!E4:E91,3) -> 36.55 | K9: =J9-I9 -> 21.4 | L9: x
A10: Technologie | B10: ROE | C10: =COUNT(DATA_TECH!G4:G91) -> 87 | D10: =MEDIAN(DATA_TECH!G4:G91) -> 19.2 | E10: =AVERAGE(DATA_TECH!G4:G91) -> 19.570115 | F10: =MIN(DATA_TECH!G4:G91) -> -730.9 | G10: =MAX(DATA_TECH!G4:G91) -> 406.8 | H10: =STDEV(DATA_TECH!G4:G91) -> 108.5421 | I10: =QUARTILE(DATA_TECH!G4:G91,1) -> 8.5 | J10: =QUARTILE(DATA_TECH!G4:G91,3) -> 33.35 | K10: =J10-I10 -> 24.85 | L10: % (pts)
A11: Technologie | B11: Croiss. Revenus | C11: =COUNT(DATA_TECH!H4:H91) -> 87 | D11: =MEDIAN(DATA_TECH!H4:H91) -> 9.7 | E11: =AVERAGE(DATA_TECH!H4:H91) -> 11.748276 | F11: =MIN(DATA_TECH!H4:H91) -> -200 | G11: =MAX(DATA_TECH!H4:H91) -> 170 | H11: =STDEV(DATA_TECH!H4:H91) -> 33.170745 | I11: =QUARTILE(DATA_TECH!H4:H91,1) -> 6.15 | J11: =QUARTILE(DATA_TECH!H4:H91,3) -> 18.55 | K11: =J11-I11 -> 12.4 | L11: % (pts)
A13: HEALTHCARE — 6 valeurs
A14: SECTEUR | B14: INDICATEUR | C14: N | D14: MÉDIANE | E14: MOYENNE | F14: MIN | G14: MAX | H14: ÉCART-TYPE | I14: Q1 (25e) | J14: Q3 (75e) | K14: IQR | L14: UNITÉ
A15: Healthcare | B15: Score FinSight | C15: =COUNT(DATA_HC!C4:C9) -> 6 | D15: =MEDIAN(DATA_HC!C4:C9) -> 74.5 | E15: =AVERAGE(DATA_HC!C4:C9) -> 71.833333 | F15: =MIN(DATA_HC!C4:C9) -> 58 | G15: =MAX(DATA_HC!C4:C9) -> 81 | H15: =STDEV(DATA_HC!C4:C9) -> 9.108604 | I15: =QUARTILE(DATA_HC!C4:C9,1) -> 66 | J15: =QUARTILE(DATA_HC!C4:C9,3) -> 78.5 | K15: =J15-I15 -> 12.5 | L15: entier
A16: Healthcare | B16: Marge EBITDA | C16: =COUNT(DATA_HC!F4:F9) -> 6 | D16: =MEDIAN(DATA_HC!F4:F9) -> 31.75 | E16: =AVERAGE(DATA_HC!F4:F9) -> 33.5 | F16: =MIN(DATA_HC!F4:F9) -> 27.3 | G16: =MAX(DATA_HC!F4:F9) -> 42.3 | H16: =STDEV(DATA_HC!F4:F9) -> 5.8511537 | I16: =QUARTILE(DATA_HC!F4:F9,1) -> 29.5 | J16: =QUARTILE(DATA_HC!F4:F9,3) -> 37.3 | K16: =J16-I16 -> 7.8 | L16: % (pts)
A17: Healthcare | B17: P/E | C17: =COUNT(DATA_HC!D4:D9) -> 6 | D17: =MEDIAN(DATA_HC!D4:D9) -> 18.25 | E17: =AVERAGE(DATA_HC!D4:D9) -> 26.416667 | F17: =MIN(DATA_HC!D4:D9) -> 13.1 | G17: =MAX(DATA_HC!D4:D9) -> 61.8 | H17: =STDEV(DATA_HC!D4:D9) -> 18.731729 | I17: =QUARTILE(DATA_HC!D4:D9,1) -> 14.825 | J17: =QUARTILE(DATA_HC!D4:D9,3) -> 29.625 | K17: =J17-I17 -> 14.8 | L17: x
A18: Healthcare | B18: EV/EBITDA | C18: =COUNT(DATA_HC!E4:E9) -> 6 | D18: =MEDIAN(DATA_HC!E4:E9) -> 14.2 | E18: =AVERAGE(DATA_HC!E4:E9) -> 19.383333 | F18: =MIN(DATA_HC!E4:E9) -> 9.4 | G18: =MAX(DATA_HC!E4:E9) -> 43.2 | H18: =STDEV(DATA_HC!E4:E9) -> 12.757495 | I18: =QUARTILE(DATA_HC!E4:E9,1) -> 11.6 | J18: =QUARTILE(DATA_HC!E4:E9,3) -> 21.975 | K18: =J18-I18 -> 10.375 | L18: x
A19: Healthcare | B19: ROE | C19: =COUNT(DATA_HC!G4:G9) -> 6 | D19: =MEDIAN(DATA_HC!G4:G9) -> 24.75 | E19: =AVERAGE(DATA_HC!G4:G9) -> 37.033333 | F19: =MIN(DATA_HC!G4:G9) -> 14.7 | G19: =MAX(DATA_HC!G4:G9) -> 87.2 | H19: =STDEV(DATA_HC!G4:G9) -> 27.992475 | I19: =QUARTILE(DATA_HC!G4:G9,1) -> 19.5 | J19: =QUARTILE(DATA_HC!G4:G9,3) -> 45.975 | K19: =J19-I19 -> 26.475 | L19: % (pts)
A20: Healthcare | B20: Croiss. Revenus | C20: =COUNT(DATA_HC!H4:H9) -> 6 | D20: =MEDIAN(DATA_HC!H4:H9) -> 12.45 | E20: =AVERAGE(DATA_HC!H4:H9) -> 14.95 | F20: =MIN(DATA_HC!H4:H9) -> 3.1 | G20: =MAX(DATA_HC!H4:H9) -> 31.8 | H20: =STDEV(DATA_HC!H4:H9) -> 11.661346 | I20: =QUARTILE(DATA_HC!H4:H9,1) -> 5.925 | J20: =QUARTILE(DATA_HC!H4:H9,3) -> 22.725 | K20: =J20-I20 -> 16.8 | L20: % (pts)
A22: DELTA — Différentiel Technologie vs Healthcare (Tech − HC)
A23: COMPARAISON | B23: INDICATEUR | C23: — | D23: Δ MÉDIANE | E23: Δ MOYENNE | F23: Δ MIN | G23: Δ MAX | H23: Δ ÉCART-TYPE
A24: Tech vs HC | B24: Score FinSight | C24: — | D24: =D6-D15 -> -22.5 | E24: =E6-E15 -> -21.969697 | F24: =F6-F15 -> -58 | G24: =G6-G15 -> 7 | H24: =H6-H15 -> 7.1077364
A25: Tech vs HC | B25: Marge EBITDA | C25: — | D25: =D7-D16 -> -4.25 | E25: =E7-E16 -> -5.3081395 | F25: =F7-F16 -> -44.3 | G25: =G7-G16 -> 28.7 | H25: =H7-H16 -> 8.5509884
A26: Tech vs HC | B26: P/E | C26: — | D26: =D8-D17 -> 16.5 | E26: =E8-E17 -> 18.942708 | F26: =F8-F17 -> -6.5 | G26: =G8-G17 -> 159.7 | H26: =H8-H17 -> 21.837796
A27: Tech vs HC | B27: EV/EBITDA | C27: — | D27: =D9-D18 -> 7.3 | E27: =E9-E18 -> 9.4280952 | F27: =F9-F18 -> -3.9 | G27: =G9-G18 -> 44.5 | H27: =H9-H18 -> 8.5714939
A28: Tech vs HC | B28: ROE | C28: — | D28: =D10-D19 -> -5.55 | E28: =E10-E19 -> -17.463218 | F28: =F10-F19 -> -745.6 | G28: =G10-G19 -> 319.6 | H28: =H10-H19 -> 80.549624
A29: Tech vs HC | B29: Croiss. Revenus | C29: — | D29: =D11-D20 -> -2.75 | E29: =E11-E20 -> -3.2017241 | F29: =F11-F20 -> -203.1 | G29: =G11-G20 -> 138.2 | H29: =H11-H20 -> 21.509399

Sheet TOP_TECH
A1: FinSight | C1: TOP TECH — Classement dynamique Technologie par Score FinSight (Top 20)
A2: Classement calculé dynamiquement via LARGE / INDEX / MATCH depuis DATA_TECH · Se met à jour automatiquement
A3: TOP 20 — TECHNOLOGIE
A4: RANG | B4: TICKER | C4: SOCIÉTÉ | D4: SCORE | E4: P/E | F4: EV/EBITDA | G4: MG EBITDA | H4: ROE | I4: CROISS. REV.
A5: 1 | B5: =IFERROR(INDEX(DATA_TECH!$A$4:$A$91,MATCH(LARGE(DATA_TECH!$C$4:$C$91,1),DATA_TECH!$C$4:$C$91,0)),"") -> NVDA | C5: =IFERROR(INDEX(DATA_TECH!$B$4:$B$91,MATCH(LARGE(DATA_TECH!$C$4:$C$91,1),DATA_TECH!$C$4:$C$91,0)),"") -> NVIDIA Corporation | D5: =LARGE(DATA_TECH!$C$4:$C$91,1) -> 88 | E5: =IFERROR(INDEX(DATA_TECH!$D$4:$D$91,MATCH(LARGE(DATA_TECH!$C$4:$C$91,1),DATA_TECH!$C$4:$C$91,0)),"") -> 0 | F5: =IFERROR(INDEX(DATA_TECH!$E$4:$E$91,MATCH(LARGE(DATA_TECH!$C$4:$C$91,1),DATA_TECH!$C$4:$C$91,0)),"") -> 0 | G5: =IFERROR(INDEX(DATA_TECH!$F$4:$F$91,MATCH(LARGE(DATA_TECH!$C$4:$C$91,1),DATA_TECH!$C$4:$C$91,0)),"") -> 66.9 | H5: =IFERROR(INDEX(DATA_TECH!$G$4:$G$91,MATCH(LARGE(DATA_TECH!$C$4:$C$91,1),DATA_TECH!$C$4:$C$91,0)),"") -> 76.3 | I5: =IFERROR(INDEX(DATA_TECH!$H$4:$H$91,MATCH(LARGE(DATA_TECH!$C$4:$C$91,1),DATA_TECH!$C$4:$C$91,0)),"") -> 65.5
A6: 2 | B6: =IFERROR(INDEX(DATA_TECH!$A$4:$A$91,MATCH(LARGE(DATA_TECH!$C$4:$C$91,2),DATA_TECH!$C$4:$C$91,0)),"") -> ANET | C6: =IFERROR(INDEX(DATA_TECH!$B$4:$B$91,MATCH(LARGE(DATA_TECH!$C$4:$C$91,2),DATA_TECH!$C$4:$C$91,0)),"") -> Arista Networks, Inc. | D6: =LARGE(DATA_TECH!$C$4:$C$91,2) -> 84 | E6: =IFERROR(INDEX(DATA_TECH!$D$4:$D$91,MATCH(LARGE(DATA_TECH!$C$4:$C$91,2),DATA_TECH!$C$4:$C$91,0)),"") -> 0 | F6: =IFERROR(INDEX(DATA_TECH!$E$4:$E$91,MATCH(LARGE(DATA_TECH!$C$4:$C$91,2),DATA_TECH!$C$4:$C$91,0)),"") -> 0 | G6: =IFERROR(INDEX(DATA_TECH!$F$4:$F$91,MATCH(LARGE(DATA_TECH!$C$4:$C$91,2),DATA_TECH!$C$4:$C$91,0)),"") -> 43.6 | H6: =IFERROR(INDEX(DATA_TECH!$G$4:$G$91,MATCH(LARGE(DATA_TECH!$C$4:$C$91,2),DATA_TECH!$C$4:$C$91,0)),"") -> 28.4 | I6: =IFERROR(INDEX(DATA_TECH!$H$4:$H$91,MATCH(LARGE(DATA_TECH!$C$4:$C$91,2),DATA_TECH!$C$4:$C$91,0)),"") -> 28.6
A7: 3 | B7: =IFERROR(INDEX(DATA_TECH!$A$4:$A$91,MATCH(LARGE(DATA_TECH!$C$4:$C$91,3),DATA_TECH!$C$4:$C$91,0)),"") -> AVGO | C7: =IFERROR(INDEX(DATA_TECH!$B$4:$B$91,MATCH(LARGE(DATA_TECH!$C$4:$C$91,3),DATA_TECH!$C$4:$C$91,0)),"") -> Broadcom Inc. | D7: =LARGE(DATA_TECH!$C$4:$C$91,3) -> 83 | E7: =IFERROR(INDEX(DATA_TECH!$D$4:$D$91,MATCH(LARGE(DATA_TECH!$C$4:$C$91,3),DATA_TECH!$C$4:$C$91,0)),"") -> 0 | F7: =IFERROR(INDEX(DATA_TECH!$E$4:$E$91,MATCH(LARGE(DATA_TECH!$C$4:$C$91,3),DATA_TECH!$C$4:$C$91,0)),"") -> 0 | G7: =IFERROR(INDEX(DATA_TECH!$F$4:$F$91,MATCH(LARGE(DATA_TECH!$C$4:$C$91,3),DATA_TECH!$C$4:$C$91,0)),"") -> 54.3 | H7: =IFERROR(INDEX(DATA_TECH!$G$4:$G$91,MATCH(LARGE(DATA_TECH!$C$4:$C$91,3),DATA_TECH!$C$4:$C$91,0)),"") -> 28.4 | I7: =IFERROR(INDEX(DATA_TECH!$H$4:$H$91,MATCH(LARGE(DATA_TECH!$C$4:$C$91,3),DATA_TECH!$C$4:$C$91,0)),"") -> 23.9
A8: 4 | B8: =IFERROR(INDEX(DATA_TECH!$A$4:$A$91,MATCH(LARGE(DATA_TECH!$C$4:$C$91,4),DATA_TECH!$C$4:$C$91,0)),"") -> AMD | C8: =IFERROR(INDEX(DATA_TECH!$B$4:$B$91,MATCH(LARGE(DATA_TECH!$C$4:$C$91,4),DATA_TECH!$C$4:$C$91,0)),"") -> Advanced Micro Devices, Inc. | D8: =LARGE(DATA_TECH!$C$4:$C$91,4) -> 73 | E8: =IFERROR(INDEX(DATA_TECH!$D$4:$D$91,MATCH(LARGE(DATA_TECH!$C$4:$C$91,4),DATA_TECH!$C$4:$C$91,0)),"") -> 0 | F8: =IFERROR(INDEX(DATA_TECH!$E$4:$E$91,MATCH(LARGE(DATA_TECH!$C$4:$C$91,4),DATA_TECH!$C$4:$C$91,0)),"") -> 0 | G8: =IFERROR(INDEX(DATA_TECH!$F$4:$F$91,MATCH(LARGE(DATA_TECH!$C$4:$C$91,4),DATA_TECH!$C$4:$C$91,0)),"") -> 21 | H8: =IFERROR(INDEX(DATA_TECH!$G$4:$G$91,MATCH(LARGE(DATA_TECH!$C$4:$C$91,4),DATA_TECH!$C$4:$C$91,0)),"") -> 6.9 | I8: =IFERROR(INDEX(DATA_TECH!$H$4:$H$91,MATCH(LARGE(DATA_TECH!$C$4:$C$91,4),DATA_TECH!$C$4:$C$91,0)),"") -> 34.3
A9: 5 | B9: =IFERROR(INDEX(DATA_TECH!$A$4:$A$91,MATCH(LARGE(DATA_TECH!$C$4:$C$91,5),DATA_TECH!$C$4:$C$91,0)),"") -> AMD | C9: =IFERROR(INDEX(DATA_TECH!$B$4:$B$91,MATCH(LARGE(DATA_TECH!$C$4:$C$91,5),DATA_TECH!$C$4:$C$91,0)),"") -> Advanced Micro Devices, Inc. | D9: =LARGE(DATA_TECH!$C$4:$C$91,5) -> 73 | E9: =IFERROR(INDEX(DATA_TECH!$D$4:$D$91,MATCH(LARGE(DATA_TECH!$C$4:$C$91,5),DATA_TECH!$C$4:$C$91,0)),"") -> 0 | F9: =IFERROR(INDEX(DATA_TECH!$E$4:$E$91,MATCH(LARGE(DATA_TECH!$C$4:$C$91,5),DATA_TECH!$C$4:$C$91,0)),"") -> 0 | G9: =IFERROR(INDEX(DATA_TECH!$F$4:$F$91,MATCH(LARGE(DATA_TECH!$C$4:$C$91,5),DATA_TECH!$C$4:$C$91,0)),"") -> 21 | H9: =IFERROR(INDEX(DATA_TECH!$G$4:$G$91,MATCH(LARGE(DATA_TECH!$C$4:$C$91,5),DATA_TECH!$C$4:$C$91,0)),"") -> 6.9 | I9: =IFERROR(INDEX(DATA_TECH!$H$4:$H$91,MATCH(LARGE(DATA_TECH!$C$4:$C$91,5),DATA_TECH!$C$4:$C$91,0)),"") -> 34.3
A10: 6 | B10: =IFERROR(INDEX(DATA_TECH!$A$4:$A$91,MATCH(LARGE(DATA_TECH!$C$4:$C$91,6),DATA_TECH!$C$4:$C$91,0)),"") -> ASML.AS | C10: =IFERROR(INDEX(DATA_TECH!$B$4:$B$91,MATCH(LARGE(DATA_TECH!$C$4:$C$91,6),DATA_TECH!$C$4:$C$91,0)),"") -> ASML Holding N.V. | D10: =LARGE(DATA_TECH!$C$4:$C$91,6) -> 72 | E10: =IFERROR(INDEX(DATA_TECH!$D$4:$D$91,MATCH(LARGE(DATA_TECH!$C$4:$C$91,6),DATA_TECH!$C$4:$C$91,0)),"") -> 0 | F10: =IFERROR(INDEX(DATA_TECH!$E$4:$E$91,MATCH(LARGE(DATA_TECH!$C$4:$C$91,6),DATA_TECH!$C$4:$C$91,0)),"") -> 0 | G10: =IFERROR(INDEX(DATA_TECH!$F$4:$F$91,MATCH(LARGE(DATA_TECH!$C$4:$C$91,6),DATA_TECH!$C$4:$C$91,0)),"") -> 38.4 | H10: =IFERROR(INDEX(DATA_TECH!$G$4:$G$91,MATCH(LARGE(DATA_TECH!$C$4:$C$91,6),DATA_TECH!$C$4:$C$91,0)),"") -> 49 | I10: =IFERROR(INDEX(DATA_TECH!$H$4:$H$91,MATCH(LARGE(DATA_TECH!$C$4:$C$91,6),DATA_TECH!$C$4:$C$91,0)),"") -> 15.6
A11: 7 | B11: =IFERROR(INDEX(DATA_TECH!$A$4:$A$91,MATCH(LARGE(DATA_TECH!$C$4:$C$91,7),DATA_TECH!$C$4:$C$91,0)),"") -> ADI | C11: =IFERROR(INDEX(DATA_TECH!$B$4:$B$91,MATCH(LARGE(DATA_TECH!$C$4:$C$91,7),DATA_TECH!$C$4:$C$91,0)),"") -> Analog Devices, Inc. | D11: =LARGE(DATA_TECH!$C$4:$C$91,7) -> 71 | E11: =IFERROR(INDEX(DATA_TECH!$D$4:$D$91,MATCH(LARGE(DATA_TECH!$C$4:$C$91,7),DATA_TECH!$C$4:$C$91,0)),"") -> 0 | F11: =IFERROR(INDEX(DATA_TECH!$E$4:$E$91,MATCH(LARGE(DATA_TECH!$C$4:$C$91,7),DATA_TECH!$C$4:$C$91,0)),"") -> 0 | G11: =IFERROR(INDEX(DATA_TECH!$F$4:$F$91,MATCH(LARGE(DATA_TECH!$C$4:$C$91,7),DATA_TECH!$C$4:$C$91,0)),"") -> 45.6 | H11: =IFERROR(INDEX(DATA_TECH!$G$4:$G$91,MATCH(LARGE(DATA_TECH!$C$4:$C$91,7),DATA_TECH!$C$4:$C$91,0)),"") -> 6.7 | I11: =IFERROR(INDEX(DATA_TECH!$H$4:$H$91,MATCH(LARGE(DATA_TECH!$C$4:$C$91,7),DATA_TECH!$C$4:$C$91,0)),"") -> 16.9
A12: 8 | B12: =IFERROR(INDEX(DATA_TECH!$A$4:$A$91,MATCH(LARGE(DATA_TECH!$C$4:$C$91,8),DATA_TECH!$C$4:$C$91,0)),"") -> GLW | C12: =IFERROR(INDEX(DATA_TECH!$B$4:$B$91,MATCH(LARGE(DATA_TECH!$C$4:$C$91,8),DATA_TECH!$C$4:$C$91,0)),"") -> Corning Incorporated | D12: =LARGE(DATA_TECH!$C$4:$C$91,8) -> 68 | E12: =IFERROR(INDEX(DATA_TECH!$D$4:$D$91,MATCH(LARGE(DATA_TECH!$C$4:$C$91,8),DATA_TECH!$C$4:$C$91,0)),"") -> 0 | F12: =IFERROR(INDEX(DATA_TECH!$E$4:$E$91,MATCH(LARGE(DATA_TECH!$C$4:$C$91,8),DATA_TECH!$C$4:$C$91,0)),"") -> 0 | G12: =IFERROR(INDEX(DATA_TECH!$F$4:$F$91,MATCH(LARGE(DATA_TECH!$C$4:$C$91,8),DATA_TECH!$C$4:$C$91,0)),"") -> 23.9 | H12: =IFERROR(INDEX(DATA_TECH!$G$4:$G$91,MATCH(LARGE(DATA_TECH!$C$4:$C$91,8),DATA_TECH!$C$4:$C$91,0)),"") -> 13.5 | I12: =IFERROR(INDEX(DATA_TECH!$H$4:$H$91,MATCH(LARGE(DATA_TECH!$C$4:$C$91,8),DATA_TECH!$C$4:$C$91,0)),"") -> 19.1
A13: 9 | B13: =IFERROR(INDEX(DATA_TECH!$A$4:$A$91,MATCH(LARGE(DATA_TECH!$C$4:$C$91,9),DATA_TECH!$C$4:$C$91,0)),"") -> GLW | C13: =IFERROR(INDEX(DATA_TECH!$B$4:$B$91,MATCH(LARGE(DATA_TECH!$C$4:$C$91,9),DATA_TECH!$C$4:$C$91,0)),"") -> Corning Incorporated | D13: =LARGE(DATA_TECH!$C$4:$C$91,9) -> 68 | E13: =IFERROR(INDEX(DATA_TECH!$D$4:$D$91,MATCH(LARGE(DATA_TECH!$C$4:$C$91,9),DATA_TECH!$C$4:$C$91,0)),"") -> 0 | F13: =IFERROR(INDEX(DATA_TECH!$E$4:$E$91,MATCH(LARGE(DATA_TECH!$C$4:$C$91,9),DATA_TECH!$C$4:$C$91,0)),"") -> 0 | G13: =IFERROR(INDEX(DATA_TECH!$F$4:$F$91,MATCH(LARGE(DATA_TECH!$C$4:$C$91,9),DATA_TECH!$C$4:$C$91,0)),"") -> 23.9 | H13: =IFERROR(INDEX(DATA_TECH!$G$4:$G$91,MATCH(LARGE(DATA_TECH!$C$4:$C$91,9),DATA_TECH!$C$4:$C$91,0)),"") -> 13.5 | I13: =IFERROR(INDEX(DATA_TECH!$H$4:$H$91,MATCH(LARGE(DATA_TECH!$C$4:$C$91,9),DATA_TECH!$C$4:$C$91,0)),"") -> 19.1
A14: 10 | B14: =IFERROR(INDEX(DATA_TECH!$A$4:$A$91,MATCH(LARGE(DATA_TECH!$C$4:$C$91,10),DATA_TECH!$C$4:$C$91,0)),"") -> APH | C14: =IFERROR(INDEX(DATA_TECH!$B$4:$B$91,MATCH(LARGE(DATA_TECH!$C$4:$C$91,10),DATA_TECH!$C$4:$C$91,0)),"") -> Amphenol Corporation | D14: =LARGE(DATA_TECH!$C$4:$C$91,10) -> 67 | E14: =IFERROR(INDEX(DATA_TECH!$D$4:$D$91,MATCH(LARGE(DATA_TECH!$C$4:$C$91,10),DATA_TECH!$C$4:$C$91,0)),"") -> 0 | F14: =IFERROR(INDEX(DATA_TECH!$E$4:$E$91,MATCH(LARGE(DATA_TECH!$C$4:$C$91,10),DATA_TECH!$C$4:$C$91,0)),"") -> 0 | G14: =IFERROR(INDEX(DATA_TECH!$F$4:$F$91,MATCH(LARGE(DATA_TECH!$C$4:$C$91,10),DATA_TECH!$C$4:$C$91,0)),"") -> 29.8 | H14: =IFERROR(INDEX(DATA_TECH!$G$4:$G$91,MATCH(LARGE(DATA_TECH!$C$4:$C$91,10),DATA_TECH!$C$4:$C$91,0)),"") -> 31.8 | I14: =IFERROR(INDEX(DATA_TECH!$H$4:$H$91,MATCH(LARGE(DATA_TECH!$C$4:$C$91,10),DATA_TECH!$C$4:$C$91,0)),"") -> 51.7
A15: 11 | B15: =IFERROR(INDEX(DATA_TECH!$A$4:$A$91,MATCH(LARGE(DATA_TECH!$C$4:$C$91,11),DATA_TECH!$C$4:$C$91,0)),"") -> APH | C15: =IFERROR(INDEX(DATA_TECH!$B$4:$B$91,MATCH(LARGE(DATA_TECH!$C$4:$C$91,11),DATA_TECH!$C$4:$C$91,0)),"") -> Amphenol Corporation | D15: =LARGE(DATA_TECH!$C$4:$C$91,11) -> 67 | E15: =IFERROR(INDEX(DATA_TECH!$D$4:$D$91,MATCH(LARGE(DATA_TECH!$C$4:$C$91,11),DATA_TECH!$C$4:$C$91,0)),"") -> 0 | F15: =IFERROR(INDEX(DATA_TECH!$E$4:$E$91,MATCH(LARGE(DATA_TECH!$C$4:$C$91,11),DATA_TECH!$C$4:$C$91,0)),"") -> 0 | G15: =IFERROR(INDEX(DATA_TECH!$F$4:$F$91,MATCH(LARGE(DATA_TECH!$C$4:$C$91,11),DATA_TECH!$C$4:$C$91,0)),"") -> 29.8 | H15: =IFERROR(INDEX(DATA_TECH!$G$4:$G$91,MATCH(LARGE(DATA_TECH!$C$4:$C$91,11),DATA_TECH!$C$4:$C$91,0)),"") -> 31.8 | I15: =IFERROR(INDEX(DATA_TECH!$H$4:$H$91,MATCH(LARGE(DATA_TECH!$C$4:$C$91,11),DATA_TECH!$C$4:$C$91,0)),"") -> 51.7
A16: 12 | B16: =IFERROR(INDEX(DATA_TECH!$A$4:$A$91,MATCH(LARGE(DATA_TECH!$C$4:$C$91,12),DATA_TECH!$C$4:$C$91,0)),"") -> CDNS | C16: =IFERROR(INDEX(DATA_TECH!$B$4:$B$91,MATCH(LARGE(DATA_TECH!$C$4:$C$91,12),DATA_TECH!$C$4:$C$91,0)),"") -> Cadence Design Systems, Inc. | D16: =LARGE(DATA_TECH!$C$4:$C$91,12) -> 66 | E16: =IFERROR(INDEX(DATA_TECH!$D$4:$D$91,MATCH(LARGE(DATA_TECH!$C$4:$C$91,12),DATA_TECH!$C$4:$C$91,0)),"") -> 0 | F16: =IFERROR(INDEX(DATA_TECH!$E$4:$E$91,MATCH(LARGE(DATA_TECH!$C$4:$C$91,12),DATA_TECH!$C$4:$C$91,0)),"") -> 0 | G16: =IFERROR(INDEX(DATA_TECH!$F$4:$F$91,MATCH(LARGE(DATA_TECH!$C$4:$C$91,12),DATA_TECH!$C$4:$C$91,0)),"") -> 35.4 | H16: =IFERROR(INDEX(DATA_TECH!$G$4:$G$91,MATCH(LARGE(DATA_TECH!$C$4:$C$91,12),DATA_TECH!$C$4:$C$91,0)),"") -> 20.3 | I16: =IFERROR(INDEX(DATA_TECH!$H$4:$H$91,MATCH(LARGE(DATA_TECH!$C$4:$C$91,12),DATA_TECH!$C$4:$C$91,0)),"") -> 14.1
A17: 13 | B17: =IFERROR(INDEX(DATA_TECH!$A$4:$A$91,MATCH(LARGE(DATA_TECH!$C$4:$C$91,13),DATA_TECH!$C$4:$C$91,0)),"") -> CDNS | C17: =IFERROR(INDEX(DATA_TECH!$B$4:$B$91,MATCH(LARGE(DATA_TECH!$C$4:$C$91,13),DATA_TECH!$C$4:$C$91,0)),"") -> Cadence Design Systems, Inc. | D17: =LARGE(DATA_TECH!$C$4:$C$91,13) -> 66 | E17: =IFERROR(INDEX(DATA_TECH!$D$4:$D$91,MATCH(LARGE(DATA_TECH!$C$4:$C$91,13),DATA_TECH!$C$4:$C$91,0)),"") -> 0 | F17: =IFERROR(INDEX(DATA_TECH!$E$4:$E$91,MATCH(LARGE(DATA_TECH!$C$4:$C$91,13),DATA_TECH!$C$4:$C$91,0)),"") -> 0 | G17: =IFERROR(INDEX(DATA_TECH!$F$4:$F$91,MATCH(LARGE(DATA_TECH!$C$4:$C$91,13),DATA_TECH!$C$4:$C$91,0)),"") -> 35.4 | H17: =IFERROR(INDEX(DATA_TECH!$G$4:$G$91,MATCH(LARGE(DATA_TECH!$C$4:$C$91,13),DATA_TECH!$C$4:$C$91,0)),"") -> 20.3 | I17: =IFERROR(INDEX(DATA_TECH!$H$4:$H$91,MATCH(LARGE(DATA_TECH!$C$4:$C$91,13),DATA_TECH!$C$4:$C$91,0)),"") -> 14.1
A18: 14 | B18: =IFERROR(INDEX(DATA_TECH!$A$4:$A$91,MATCH(LARGE(DATA_TECH!$C$4:$C$91,14),DATA_TECH!$C$4:$C$91,0)),"") -> GRMN | C18: =IFERROR(INDEX(DATA_TECH!$B$4:$B$91,MATCH(LARGE(DATA_TECH!$C$4:$C$91,14),DATA_TECH!$C$4:$C$91,0)),"") -> Garmin Ltd. | D18: =LARGE(DATA_TECH!$C$4:$C$91,14) -> 65 | E18: =IFERROR(INDEX(DATA_TECH!$D$4:$D$91,MATCH(LARGE(DATA_TECH!$C$4:$C$91,14),DATA_TECH!$C$4:$C$91,0)),"") -> 0 | F18: =IFERROR(INDEX(DATA_TECH!$E$4:$E$91,MATCH(LARGE(DATA_TECH!$C$4:$C$91,14),DATA_TECH!$C$4:$C$91,0)),"") -> 0 | G18: =IFERROR(INDEX(DATA_TECH!$F$4:$F$91,MATCH(LARGE(DATA_TECH!$C$4:$C$91,14),DATA_TECH!$C$4:$C$91,0)),"") -> 28.5 | H18: =IFERROR(INDEX(DATA_TECH!$G$4:$G$91,MATCH(LARGE(DATA_TECH!$C$4:$C$91,14),DATA_TECH!$C$4:$C$91,0)),"") -> 18.5 | I18: =IFERROR(INDEX(DATA_TECH!$H$4:$H$91,MATCH(LARGE(DATA_TECH!$C$4:$C$91,14),DATA_TECH!$C$4:$C$91,0)),"") -> 15.1
A19: 15 | B19: =IFERROR(INDEX(DATA_TECH!$A$4:$A$91,MATCH(LARGE(DATA_TECH!$C$4:$C$91,15),DATA_TECH!$C$4:$C$91,0)),"") -> ADSK | C19: =IFERROR(INDEX(DATA_TECH!$B$4:$B$91,MATCH(LARGE(DATA_TECH!$C$4:$C$91,15),DATA_TECH!$C$4:$C$91,0)),"") -> Autodesk, Inc. | D19: =LARGE(DATA_TECH!$C$4:$C$91,15) -> 64 | E19: =IFERROR(INDEX(DATA_TECH!$D$4:$D$91,MATCH(LARGE(DATA_TECH!$C$4:$C$91,15),DATA_TECH!$C$4:$C$91,0)),"") -> 0 | F19: =IFERROR(INDEX(DATA_TECH!$E$4:$E$91,MATCH(LARGE(DATA_TECH!$C$4:$C$91,15),DATA_TECH!$C$4:$C$91,0)),"") -> 0 | G19: =IFERROR(INDEX(DATA_TECH!$F$4:$F$91,MATCH(LARGE(DATA_TECH!$C$4:$C$91,15),DATA_TECH!$C$4:$C$91,0)),"") -> 27.6 | H19: =IFERROR(INDEX(DATA_TECH!$G$4:$G$91,MATCH(LARGE(DATA_TECH!$C$4:$C$91,15),DATA_TECH!$C$4:$C$91,0)),"") -> 36.9 | I19: =IFERROR(INDEX(DATA_TECH!$H$4:$H$91,MATCH(LARGE(DATA_TECH!$C$4:$C$91,15),DATA_TECH!$C$4:$C$91,0)),"") -> 17.5
A20: 16 | B20: =IFERROR(INDEX(DATA_TECH!$A$4:$A$91,MATCH(LARGE(DATA_TECH!$C$4:$C$91,16),DATA_TECH!$C$4:$C$91,0)),"") -> MSFT | C20: =IFERROR(INDEX(DATA_TECH!$B$4:$B$91,MATCH(LARGE(DATA_TECH!$C$4:$C$91,16),DATA_TECH!$C$4:$C$91,0)),"") -> Microsoft Corporation | D20: =LARGE(DATA_TECH!$C$4:$C$91,16) -> 63 | E20: =IFERROR(INDEX(DATA_TECH!$D$4:$D$91,MATCH(LARGE(DATA_TECH!$C$4:$C$91,16),DATA_TECH!$C$4:$C$91,0)),"") -> 0 | F20: =IFERROR(INDEX(DATA_TECH!$E$4:$E$91,MATCH(LARGE(DATA_TECH!$C$4:$C$91,16),DATA_TECH!$C$4:$C$91,0)),"") -> 0 | G20: =IFERROR(INDEX(DATA_TECH!$F$4:$F$91,MATCH(LARGE(DATA_TECH!$C$4:$C$91,16),DATA_TECH!$C$4:$C$91,0)),"") -> 56.9 | H20: =IFERROR(INDEX(DATA_TECH!$G$4:$G$91,MATCH(LARGE(DATA_TECH!$C$4:$C$91,16),DATA_TECH!$C$4:$C$91,0)),"") -> 29.6 | I20: =IFERROR(INDEX(DATA_TECH!$H$4:$H$91,MATCH(LARGE(DATA_TECH!$C$4:$C$91,16),DATA_TECH!$C$4:$C$91,0)),"") -> 14.9
A21: 17 | B21: =IFERROR(INDEX(DATA_TECH!$A$4:$A$91,MATCH(LARGE(DATA_TECH!$C$4:$C$91,17),DATA_TECH!$C$4:$C$91,0)),"") -> MSFT | C21: =IFERROR(INDEX(DATA_TECH!$B$4:$B$91,MATCH(LARGE(DATA_TECH!$C$4:$C$91,17),DATA_TECH!$C$4:$C$91,0)),"") -> Microsoft Corporation | D21: =LARGE(DATA_TECH!$C$4:$C$91,17) -> 63 | E21: =IFERROR(INDEX(DATA_TECH!$D$4:$D$91,MATCH(LARGE(DATA_TECH!$C$4:$C$91,17),DATA_TECH!$C$4:$C$91,0)),"") -> 0 | F21: =IFERROR(INDEX(DATA_TECH!$E$4:$E$91,MATCH(LARGE(DATA_TECH!$C$4:$C$91,17),DATA_TECH!$C$4:$C$91,0)),"") -> 0 | G21: =IFERROR(INDEX(DATA_TECH!$F$4:$F$91,MATCH(LARGE(DATA_TECH!$C$4:$C$91,17),DATA_TECH!$C$4:$C$91,0)),"") -> 56.9 | H21: =IFERROR(INDEX(DATA_TECH!$G$4:$G$91,MATCH(LARGE(DATA_TECH!$C$4:$C$91,17),DATA_TECH!$C$4:$C$91,0)),"") -> 29.6 | I21: =IFERROR(INDEX(DATA_TECH!$H$4:$H$91,MATCH(LARGE(DATA_TECH!$C$4:$C$91,17),DATA_TECH!$C$4:$C$91,0)),"") -> 14.9
A22: 18 | B22: =IFERROR(INDEX(DATA_TECH!$A$4:$A$91,MATCH(LARGE(DATA_TECH!$C$4:$C$91,18),DATA_TECH!$C$4:$C$91,0)),"") -> CPAY | C22: =IFERROR(INDEX(DATA_TECH!$B$4:$B$91,MATCH(LARGE(DATA_TECH!$C$4:$C$91,18),DATA_TECH!$C$4:$C$91,0)),"") -> Corpay, Inc. | D22: =LARGE(DATA_TECH!$C$4:$C$91,18) -> 62 | E22: =IFERROR(INDEX(DATA_TECH!$D$4:$D$91,MATCH(LARGE(DATA_TECH!$C$4:$C$91,18),DATA_TECH!$C$4:$C$91,0)),"") -> 0 | F22: =IFERROR(INDEX(DATA_TECH!$E$4:$E$91,MATCH(LARGE(DATA_TECH!$C$4:$C$91,18),DATA_TECH!$C$4:$C$91,0)),"") -> 0 | G22: =IFERROR(INDEX(DATA_TECH!$F$4:$F$91,MATCH(LARGE(DATA_TECH!$C$4:$C$91,18),DATA_TECH!$C$4:$C$91,0)),"") -> 51.6 | H22: =IFERROR(INDEX(DATA_TECH!$G$4:$G$91,MATCH(LARGE(DATA_TECH!$C$4:$C$91,18),DATA_TECH!$C$4:$C$91,0)),"") -> 27.5 | I22: =IFERROR(INDEX(DATA_TECH!$H$4:$H$91,MATCH(LARGE(DATA_TECH!$C$4:$C$91,18),DATA_TECH!$C$4:$C$91,0)),"") -> 13.9
A23: 19 | B23: =IFERROR(INDEX(DATA_TECH!$A$4:$A$91,MATCH(LARGE(DATA_TECH!$C$4:$C$91,19),DATA_TECH!$C$4:$C$91,0)),"") -> CPAY | C23: =IFERROR(INDEX(DATA_TECH!$B$4:$B$91,MATCH(LARGE(DATA_TECH!$C$4:$C$91,19),DATA_TECH!$C$4:$C$91,0)),"") -> Corpay, Inc. | D23: =LARGE(DATA_TECH!$C$4:$C$91,19) -> 62 | E23: =IFERROR(INDEX(DATA_TECH!$D$4:$D$91,MATCH(LARGE(DATA_TECH!$C$4:$C$91,19),DATA_TECH!$C$4:$C$91,0)),"") -> 0 | F23: =IFERROR(INDEX(DATA_TECH!$E$4:$E$91,MATCH(LARGE(DATA_TECH!$C$4:$C$91,19),DATA_TECH!$C$4:$C$91,0)),"") -> 0 | G23: =IFERROR(INDEX(DATA_TECH!$F$4:$F$91,MATCH(LARGE(DATA_TECH!$C$4:$C$91,19),DATA_TECH!$C$4:$C$91,0)),"") -> 51.6 | H23: =IFERROR(INDEX(DATA_TECH!$G$4:$G$91,MATCH(LARGE(DATA_TECH!$C$4:$C$91,19),DATA_TECH!$C$4:$C$91,0)),"") -> 27.5 | I23: =IFERROR(INDEX(DATA_TECH!$H$4:$H$91,MATCH(LARGE(DATA_TECH!$C$4:$C$91,19),DATA_TECH!$C$4:$C$91,0)),"") -> 13.9
A24: 20 | B24: =IFERROR(INDEX(DATA_TECH!$A$4:$A$91,MATCH(LARGE(DATA_TECH!$C$4:$C$91,20),DATA_TECH!$C$4:$C$91,0)),"") -> CPAY | C24: =IFERROR(INDEX(DATA_TECH!$B$4:$B$91,MATCH(LARGE(DATA_TECH!$C$4:$C$91,20),DATA_TECH!$C$4:$C$91,0)),"") -> Corpay, Inc. | D24: =LARGE(DATA_TECH!$C$4:$C$91,20) -> 62 | E24: =IFERROR(INDEX(DATA_TECH!$D$4:$D$91,MATCH(LARGE(DATA_TECH!$C$4:$C$91,20),DATA_TECH!$C$4:$C$91,0)),"") -> 0 | F24: =IFERROR(INDEX(DATA_TECH!$E$4:$E$91,MATCH(LARGE(DATA_TECH!$C$4:$C$91,20),DATA_TECH!$C$4:$C$91,0)),"") -> 0 | G24: =IFERROR(INDEX(DATA_TECH!$F$4:$F$91,MATCH(LARGE(DATA_TECH!$C$4:$C$91,20),DATA_TECH!$C$4:$C$91,0)),"") -> 51.6 | H24: =IFERROR(INDEX(DATA_TECH!$G$4:$G$91,MATCH(LARGE(DATA_TECH!$C$4:$C$91,20),DATA_TECH!$C$4:$C$91,0)),"") -> 27.5 | I24: =IFERROR(INDEX(DATA_TECH!$H$4:$H$91,MATCH(LARGE(DATA_TECH!$C$4:$C$91,20),DATA_TECH!$C$4:$C$91,0)),"") -> 13.9

Sheet TOP_HC
A1: FinSight | C1: TOP HC — Classement dynamique Healthcare par Score FinSight
A2: Classement calculé dynamiquement via LARGE / INDEX / MATCH depuis DATA_HC · 6 entités
A3: TOUTES VALEURS — HEALTHCARE (classées par Score)
A4: RANG | B4: TICKER | C4: SOCIÉTÉ | D4: SCORE | E4: P/E | F4: EV/EBITDA | G4: MG EBITDA | H4: ROE | I4: CROISS. REV.
A5: 1 | B5: =IFERROR(INDEX(DATA_HC!$A$4:$A$9,MATCH(LARGE(DATA_HC!$C$4:$C$9,1),DATA_HC!$C$4:$C$9,0)),"") -> NVO | C5: =IFERROR(INDEX(DATA_HC!$B$4:$B$9,MATCH(LARGE(DATA_HC!$C$4:$C$9,1),DATA_HC!$C$4:$C$9,0)),"") -> Novo Nordisk A/S | D5: =LARGE(DATA_HC!$C$4:$C$9,1) -> 81 | E5: =IFERROR(INDEX(DATA_HC!$D$4:$D$9,MATCH(LARGE(DATA_HC!$C$4:$C$9,1),DATA_HC!$C$4:$C$9,0)),"") -> 32.4 | F5: =IFERROR(INDEX(DATA_HC!$E$4:$E$9,MATCH(LARGE(DATA_HC!$C$4:$C$9,1),DATA_HC!$C$4:$C$9,0)),"") -> 24.1 | G5: =IFERROR(INDEX(DATA_HC!$F$4:$F$9,MATCH(LARGE(DATA_HC!$C$4:$C$9,1),DATA_HC!$C$4:$C$9,0)),"") -> 42.3 | H5: =IFERROR(INDEX(DATA_HC!$G$4:$G$9,MATCH(LARGE(DATA_HC!$C$4:$C$9,1),DATA_HC!$C$4:$C$9,0)),"") -> 87.2 | I5: =IFERROR(INDEX(DATA_HC!$H$4:$H$9,MATCH(LARGE(DATA_HC!$C$4:$C$9,1),DATA_HC!$C$4:$C$9,0)),"") -> 24.1
A6: 2 | B6: =IFERROR(INDEX(DATA_HC!$A$4:$A$9,MATCH(LARGE(DATA_HC!$C$4:$C$9,2),DATA_HC!$C$4:$C$9,0)),"") -> LLY | C6: =IFERROR(INDEX(DATA_HC!$B$4:$B$9,MATCH(LARGE(DATA_HC!$C$4:$C$9,2),DATA_HC!$C$4:$C$9,0)),"") -> Eli Lilly and Company | D6: =LARGE(DATA_HC!$C$4:$C$9,2) -> 79 | E6: =IFERROR(INDEX(DATA_HC!$D$4:$D$9,MATCH(LARGE(DATA_HC!$C$4:$C$9,2),DATA_HC!$C$4:$C$9,0)),"") -> 61.8 | F6: =IFERROR(INDEX(DATA_HC!$E$4:$E$9,MATCH(LARGE(DATA_HC!$C$4:$C$9,2),DATA_HC!$C$4:$C$9,0)),"") -> 43.2 | G6: =IFERROR(INDEX(DATA_HC!$F$4:$F$9,MATCH(LARGE(DATA_HC!$C$4:$C$9,2),DATA_HC!$C$4:$C$9,0)),"") -> 38.7 | H6: =IFERROR(INDEX(DATA_HC!$G$4:$G$9,MATCH(LARGE(DATA_HC!$C$4:$C$9,2),DATA_HC!$C$4:$C$9,0)),"") -> 52.6 | I6: =IFERROR(INDEX(DATA_HC!$H$4:$H$9,MATCH(LARGE(DATA_HC!$C$4:$C$9,2),DATA_HC!$C$4:$C$9,0)),"") -> 31.8
A7: 3 | B7: =IFERROR(INDEX(DATA_HC!$A$4:$A$9,MATCH(LARGE(DATA_HC!$C$4:$C$9,3),DATA_HC!$C$4:$C$9,0)),"") -> AZN.L | C7: =IFERROR(INDEX(DATA_HC!$B$4:$B$9,MATCH(LARGE(DATA_HC!$C$4:$C$9,3),DATA_HC!$C$4:$C$9,0)),"") -> AstraZeneca PLC | D7: =LARGE(DATA_HC!$C$4:$C$9,3) -> 77 | E7: =IFERROR(INDEX(DATA_HC!$D$4:$D$9,MATCH(LARGE(DATA_HC!$C$4:$C$9,3),DATA_HC!$C$4:$C$9,0)),"") -> 21.3 | F7: =IFERROR(INDEX(DATA_HC!$E$4:$E$9,MATCH(LARGE(DATA_HC!$C$4:$C$9,3),DATA_HC!$C$4:$C$9,0)),"") -> 15.6 | G7: =IFERROR(INDEX(DATA_HC!$F$4:$F$9,MATCH(LARGE(DATA_HC!$C$4:$C$9,3),DATA_HC!$C$4:$C$9,0)),"") -> 30.4 | H7: =IFERROR(INDEX(DATA_HC!$G$4:$G$9,MATCH(LARGE(DATA_HC!$C$4:$C$9,3),DATA_HC!$C$4:$C$9,0)),"") -> 26.1 | I7: =IFERROR(INDEX(DATA_HC!$H$4:$H$9,MATCH(LARGE(DATA_HC!$C$4:$C$9,3),DATA_HC!$C$4:$C$9,0)),"") -> 18.6
A8: 4 | B8: =IFERROR(INDEX(DATA_HC!$A$4:$A$9,MATCH(LARGE(DATA_HC!$C$4:$C$9,4),DATA_HC!$C$4:$C$9,0)),"") -> JNJ | C8: =IFERROR(INDEX(DATA_HC!$B$4:$B$9,MATCH(LARGE(DATA_HC!$C$4:$C$9,4),DATA_HC!$C$4:$C$9,0)),"") -> Johnson & Johnson | D8: =LARGE(DATA_HC!$C$4:$C$9,4) -> 72 | E8: =IFERROR(INDEX(DATA_HC!$D$4:$D$9,MATCH(LARGE(DATA_HC!$C$4:$C$9,4),DATA_HC!$C$4:$C$9,0)),"") -> 15.2 | F8: =IFERROR(INDEX(DATA_HC!$E$4:$E$9,MATCH(LARGE(DATA_HC!$C$4:$C$9,4),DATA_HC!$C$4:$C$9,0)),"") -> 12.8 | G8: =IFERROR(INDEX(DATA_HC!$F$4:$F$9,MATCH(LARGE(DATA_HC!$C$4:$C$9,4),DATA_HC!$C$4:$C$9,0)),"") -> 33.1 | H8: =IFERROR(INDEX(DATA_HC!$G$4:$G$9,MATCH(LARGE(DATA_HC!$C$4:$C$9,4),DATA_HC!$C$4:$C$9,0)),"") -> 23.4 | I8: =IFERROR(INDEX(DATA_HC!$H$4:$H$9,MATCH(LARGE(DATA_HC!$C$4:$C$9,4),DATA_HC!$C$4:$C$9,0)),"") -> 6.3
A9: 5 | B9: =IFERROR(INDEX(DATA_HC!$A$4:$A$9,MATCH(LARGE(DATA_HC!$C$4:$C$9,5),DATA_HC!$C$4:$C$9,0)),"") -> SAN.PA | C9: =IFERROR(INDEX(DATA_HC!$B$4:$B$9,MATCH(LARGE(DATA_HC!$C$4:$C$9,5),DATA_HC!$C$4:$C$9,0)),"") -> Sanofi S.A. | D9: =LARGE(DATA_HC!$C$4:$C$9,5) -> 64 | E9: =IFERROR(INDEX(DATA_HC!$D$4:$D$9,MATCH(LARGE(DATA_HC!$C$4:$C$9,5),DATA_HC!$C$4:$C$9,0)),"") -> 13.1 | F9: =IFERROR(INDEX(DATA_HC!$E$4:$E$9,MATCH(LARGE(DATA_HC!$C$4:$C$9,5),DATA_HC!$C$4:$C$9,0)),"") -> 9.4 | G9: =IFERROR(INDEX(DATA_HC!$F$4:$F$9,MATCH(LARGE(DATA_HC!$C$4:$C$9,5),DATA_HC!$C$4:$C$9,0)),"") -> 29.2 | H9: =IFERROR(INDEX(DATA_HC!$G$4:$G$9,MATCH(LARGE(DATA_HC!$C$4:$C$9,5),DATA_HC!$C$4:$C$9,0)),"") -> 14.7 | I9: =IFERROR(INDEX(DATA_HC!$H$4:$H$9,MATCH(LARGE(DATA_HC!$C$4:$C$9,5),DATA_HC!$C$4:$C$9,0)),"") -> 5.8
A10: 6 | B10: =IFERROR(INDEX(DATA_HC!$A$4:$A$9,MATCH(LARGE(DATA_HC!$C$4:$C$9,6),DATA_HC!$C$4:$C$9,0)),"") -> MDT | C10: =IFERROR(INDEX(DATA_HC!$B$4:$B$9,MATCH(LARGE(DATA_HC!$C$4:$C$9,6),DATA_HC!$C$4:$C$9,0)),"") -> Medtronic plc | D10: =LARGE(DATA_HC!$C$4:$C$9,6) -> 58 | E10: =IFERROR(INDEX(DATA_HC!$D$4:$D$9,MATCH(LARGE(DATA_HC!$C$4:$C$9,6),DATA_HC!$C$4:$C$9,0)),"") -> 14.7 | F10: =IFERROR(INDEX(DATA_HC!$E$4:$E$9,MATCH(LARGE(DATA_HC!$C$4:$C$9,6),DATA_HC!$C$4:$C$9,0)),"") -> 11.2 | G10: =IFERROR(INDEX(DATA_HC!$F$4:$F$9,MATCH(LARGE(DATA_HC!$C$4:$C$9,6),DATA_HC!$C$4:$C$9,0)),"") -> 27.3 | H10: =IFERROR(INDEX(DATA_HC!$G$4:$G$9,MATCH(LARGE(DATA_HC!$C$4:$C$9,6),DATA_HC!$C$4:$C$9,0)),"") -> 18.2 | I10: =IFERROR(INDEX(DATA_HC!$H$4:$H$9,MATCH(LARGE(DATA_HC!$C$4:$C$9,6),DATA_HC!$C$4:$C$9,0)),"") -> 3.1

Sheet DATA_TECH
A1: FinSight | C1: DATA TECH — Données brutes Technologie · 88 valeurs
A2: Source : FinSight IA · Univers Technologie S&P500 / Nasdaq / Europe · Données au 12.04.2026
A3: TICKER | B3: SOCIÉTÉ | C3: SCORE FINSIGHT | D3: P/E | E3: EV/EBITDA | F3: MARGE EBITDA | G3: ROE | H3: CROISS. REV.
A4: NVDA | B4: NVIDIA Corporation | C4: 88 | F4: 66.9 | G4: 76.3 | H4: 65.5
A5: ANET | B5: Arista Networks, Inc. | C5: 84 | F5: 43.6 | G5: 28.4 | H5: 28.6
A6: AVGO | B6: Broadcom Inc. | C6: 83 | F6: 54.3 | G6: 28.4 | H6: 23.9
A7: AMD | B7: Advanced Micro Devices, Inc. | C7: 73 | F7: 21 | G7: 6.9 | H7: 34.3
A8: PTC | B8: PTC Inc. | C8: 73 | D8: 21.6 | E8: 14.9 | F8: 41.3 | G8: 19.2 | H8: 19.2
A9: ASML.AS | B9: ASML Holding N.V. | C9: 72 | F9: 38.4 | G9: 49 | H9: 15.6
A10: ADI | B10: Analog Devices, Inc. | C10: 71 | F10: 45.6 | G10: 6.7 | H10: 16.9
A11: GLW | B11: Corning Incorporated | C11: 68 | F11: 23.9 | G11: 13.5 | H11: 19.1
A12: KLAC | B12: KLA Corporation | C12: 68 | D12: 56.1 | E12: 43.4 | F12: 43.9 | G12: 86.6 | H12: 23.9
A13: APH | B13: Amphenol Corporation | C13: 67 | F13: 29.8 | G13: 31.8 | H13: 51.7
A14: INTC | B14: Intel Corporation | C14: 67 | E14: 24.1 | F14: 27.2 | G14: -20 | H14: -50
A15: CDNS | B15: Cadence Design Systems, Inc. | C15: 66 | F15: 35.4 | G15: 20.3 | H15: 14.1
A16: MU | B16: Micron Technology, Inc. | C16: 66 | D16: 55.6 | E16: 25.8 | F16: 49.4 | G16: 15.8 | H16: 48.9
A17: GRMN | B17: Garmin Ltd. | C17: 65 | F17: 28.5 | G17: 18.5 | H17: 15.1
A18: ADSK | B18: Autodesk, Inc. | C18: 64 | F18: 27.6 | G18: 36.9 | H18: 17.5
A19: MSFT | B19: Microsoft Corporation | C19: 63 | F19: 56.9 | G19: 29.6 | H19: 14.9
A20: FFIV | B20: F5, Inc. | C20: 63 | F20: 28.6 | G20: 19.3 | H20: 9.7
A21: CPAY | B21: Corpay, Inc. | C21: 62 | F21: 51.6 | G21: 27.5 | H21: 13.9
A22: LRCX | B22: Lam Research Corporation | C22: 62 | D22: 61.5 | E22: 50.2 | F22: 35.4 | G22: 54.3 | H22: 23.7
A23: WDC | B23: Western Digital Corporation | C23: 62 | D23: 62.6 | E23: 61.4 | F23: 20.4 | G23: 35 | H23: 50.7
A24: AMAT | B24: Applied Materials, Inc. | C24: 60 | F24: 35.2 | G24: 34.3 | H24: 4.4
A25: CIEN | B25: Ciena Corporation | C25: 60 | F25: 8.1 | G25: 4.5 | H25: 18.8
A26: FSLR | B26: First Solar, Inc. | C26: 60 | F26: 41.3 | G26: 16 | H26: 24.1
A27: MPWR | B27: Monolithic Power Systems, Inc. | C27: 60 | D27: 107 | E27: 83.9 | F27: 28 | G27: 17.6 | H27: 26.4
A28: SAP.DE | B28: SAP SE | C28: 59 | F28: 32.8 | G28: 16.1 | H28: 7.7
A29: IBM | B29: International Business Machines Corp. | C29: 59 | F29: 25.6 | G29: 32.4 | H29: 7.6
A30: FICO | B30: Fair Isaac Corporation | C30: 59 | F30: 47.8 | G30: -37.3 | H30: 15.9
A31: FTNT | B31: Fortinet, Inc. | C31: 59 | F31: 36.1 | G31: 149.8 | H31: 14.2
A32: NTAP | B32: NetApp, Inc. | C32: 59 | D32: 16 | E32: 11.5 | F32: 25.7 | G32: 114 | H32: 4.9
A33: ADBE | B33: Adobe Inc. | C33: 58 | F33: 41.3 | G33: 61.3 | H33: 10.5
A34: STX | B34: Seagate Technology Holdings plc | C34: 58 | D34: 76.7 | E34: 56.2 | F34: 22.9 | G34: -324.3 | H34: 38.9
A35: UBER | B35: Uber Technologies, Inc. | C35: 58 | D35: 14.3 | E35: 21.1 | F35: 13.4 | G35: 37.2 | H35: 18.3
A36: KEYS | B36: Keysight Technologies, Inc. | C36: 56 | D36: 65.4 | E36: 38.8 | F36: 27.1 | G36: 14.5 | H36: 8
A37: MSI | B37: Motorola Solutions, Inc. | C37: 56 | D37: 33.5 | E37: 22.2 | F37: 30.8 | G37: 89.4 | H37: 8
A38: SNPS | B38: Synopsys, Inc. | C38: 56 | D38: 56.4 | E38: 34.3 | F38: 35.4 | G38: 4.7 | H38: 15.1
A39: VRSN | B39: VeriSign, Inc. | C39: 56 | D39: 28.9 | E39: 21.4 | F39: 71 | G39: -38.3 | H39: 6.4
A40: XYZ | B40: Block, Inc. | C40: 55 | F40: 14.1 | G40: 5.9 | H40: 30
...

Sheet DATA_HC
A1: FinSight | C1: DATA HC — Données brutes Healthcare · 6 valeurs
A2: Source : FinSight IA · Univers Healthcare · Benchmark sectoriel · Données au 12.04.2026
A3: TICKER | B3: SOCIÉTÉ | C3: SCORE FINSIGHT | D3: P/E | E3: EV/EBITDA | F3: MARGE EBITDA | G3: ROE | H3: CROISS. REV.
A4: JNJ | B4: Johnson & Johnson | C4: 72 | D4: 15.2 | E4: 12.8 | F4: 33.1 | G4: 23.4 | H4: 6.3
A5: NVO | B5: Novo Nordisk A/S | C5: 81 | D5: 32.4 | E5: 24.1 | F5: 42.3 | G5: 87.2 | H5: 24.1
A6: LLY | B6: Eli Lilly and Company | C6: 79 | D6: 61.8 | E6: 43.2 | F6: 38.7 | G6: 52.6 | H6: 31.8
A7: SAN.PA | B7: Sanofi S.A. | C7: 64 | D7: 13.1 | E7: 9.4 | F7: 29.2 | G7: 14.7 | H7: 5.8
A8: AZN.L | B8: AstraZeneca PLC | C8: 77 | D8: 21.3 | E8: 15.6 | F8: 30.4 | G8: 26.1 | H8: 18.6
A9: MDT | B9: Medtronic plc | C9: 58 | D9: 14.7 | E9: 11.2 | F9: 27.3 | G9: 18.2 | H9: 3.1
