Workbook

Sheet INPUT
B3: INPUT — Raw Data
B4: All figures in USD millions unless stated
B5: METRIC | C5: UNIT | E5: 2022 | F5: 2023 | G5: 2024 | H5: 2025 (LTM)
B7: INPUT
B9: Revenue | C9: ($M) | E9: 263310 | F9: 218945 | G9: 195610 | H9: 182344
B10: Cost of Goods Sold (COGS) | C10: ($M) | E10: -182099 | F10: -156572 | G10: -140078 | H10: -130497
B11: Gross Profit | C11: ($M) | D11: =D9+D10 -> 0 | E11: =E9+E10 -> 81211 | F11: =F9+F10 -> 62373 | G11: =G9+G10 -> 55532 | H11: =H9+H10 -> 51847
D13: =SUM(D14:D16) -> 0 | E13: =SUM(E14:E16) -> -20701 | F13: =SUM(F14:F16) -> -22587 | G13: =SUM(G14:G16) -> -22797 | H13: =SUM(H14:H16) -> -26092
B14: Operating Expenses (SG&A) | C14: ($M) | E14: -3946 | F14: -4800 | G14: -5150 | H14: -5834
B15: Research & Development | C15: ($M) | E15: -3075 | F15: -3969 | G15: -4540 | H15: -6411
B16: Depreciation & Amortization | C16: ($M) | E16: -13680 | F16: -13818 | G16: -13107 | H16: -13847
B17: EBIT (Operating Profit) | C17: ($M) | D17: =D11+D13 -> 0 | E17: =E11+E13 -> 60510 | F17: =F11+F13 -> 39786 | G17: =G11+G13 -> 32735 | H17: =H11+H13 -> 25755
D19: =D17+D20+D21 -> 0 | E19: =E17+E20+E21 -> 59577 | F19: =F17+F20+F21 -> 39434 | G19: =G17+G20+G21 -> 32157 | H19: =H17+H20+H21 -> 24312
B20: Interest Expense | C20: ($M) | E20: -2076 | F20: -2153 | G20: -2364 | H20: -2558
B21: Interest Income | C21: ($M) | E21: 1143 | F21: 1801 | G21: 1786 | H21: 1115
B22: Earnings Before Tax (EBT) | C22: ($M) | D22: =D19 -> 0 | E22: =E19 -> 59577 | F22: =F19 -> 39434 | G22: =G19 -> 32157 | H22: =H19 -> 24312
D24: =-ROUND(D22*0.21,0) -> 0 | E24: =-ROUND(E22*E104,0) -> -23831 | F24: =-ROUND(F22*F104,0) -> -15123 | G24: =-ROUND(G22*G104,0) -> -12863 | H24: =-ROUND(H22*H104,0) -> -9380
B25: Income Tax Expense | C25: ($M) | E25: -22242 | F25: -13301 | G25: -10775 | H25: -9092
B26: Net Income | C26: ($M) | D26: =D22+D24 -> 0 | E26: =E22+E24 -> 35746 | F26: =F22+F24 -> 24311 | G26: =G22+G24 -> 19294 | H26: =H22+H24 -> 14932
B29: Common Dividends | C29: ($M) | E29: -7711 | F29: -9167 | G29: -7995 | H29: -7714
B30: EBITDA | C30: ($M) | D30: =D17-D16 -> 0 | E30: =E17-E16 -> 74190 | F30: =F17-F16 -> 53604 | G30: =G17-G16 -> 45842 | H30: =H17-H16 -> 39602
B32: BALANCE SHEET
B34: Cash & Cash Equivalents | C34: ($M) | E34: 33026 | F34: 27263 | G34: 25844 | H34: 24152
B35: Accounts Receivable | C35: ($M) | E35: 24378 | F35: 23442 | G35: 19281 | H35: 18559
B36: Inventories | C36: ($M) | E36: 22936 | F36: 19317 | G36: 18868 | H36: 16663
B37: Other Current Assets | C37: ($M) | E37: 63 | F37: 60 | G37: 71 | H37: 105
B38: Total Current Assets | C38: ($M) | D38: =SUM(D34:D37) -> 0 | E38: =SUM(E34:E37) -> 80403 | F38: =SUM(F34:F37) -> 70082 | G38: =SUM(G34:G37) -> 64064 | H38: =SUM(H34:H37) -> 59479
B41: PP&E (Net) | C41: ($M) | E41: 128054 | F41: 129277 | G41: 128945 | H41: 135394
B42: Intangible Assets | C42: ($M) | E42: 10978 | F42: 12722 | G42: 14388 | H42: 16645
B43: Other Long-Term Assets | C43: ($M) | E43: 301 | F43: 330 | G43: 154 | H43: 288
B44: Total Assets | C44: ($M) | D44: =D38+SUM(D41:D43) -> 0 | E44: =E38+SUM(E41:E43) -> 219736 | F44: =F38+SUM(F41:F43) -> 212411 | G44: =G38+SUM(G41:G43) -> 207551 | H44: =H38+SUM(H41:H43) -> 211806
B47: Accounts Payable | C47: ($M) | E47: 41346 | F47: 41335 | G47: 39932 | H47: 38065
B48: Short-Term Debt | C48: ($M) | E48: 14065 | F48: 7869 | G48: 7929 | H48: 10162
B49: Income Tax Payable | C49: ($M) | E49: 14780 | F49: 13974 | G49: 12561 | H49: 10427
B50: Other Current Liabilities | C50: ($M) | E50: 35841 | F50: 21070 | G50: 22285 | H50: 27890
B51: Total Current Liabilities | C51: ($M) | D51: =SUM(D47:D50) -> 0 | E51: =SUM(E47:E50) -> 106032 | F51: =SUM(F47:F50) -> 84248 | G51: =SUM(G47:G50) -> 82707 | H51: =SUM(H47:H50) -> 86544
B54: Long-Term Debt | C54: ($M) | E54: 41518 | F54: 38280 | G54: 41220 | H54: 48033
B55: Total Liabilities | C55: ($M) | D55: =D51+D54 -> 0 | E55: =E51+E54 -> 147550 | F55: =F51+F54 -> 122528 | G55: =G51+G54 -> 123927 | H55: =H51+H54 -> 134577
B58: Common Equity (Paid-In Capital) | C58: ($M) | E58: 132114 | F58: 134473 | G58: 143073 | H58: 132919
B59: Retained Earnings | C59: ($M) | E59: 12885 | F59: 27882 | G59: 35209 | H59: 39003
...

Sheet RATIOS
B1: FinSight | H1: RATIOS — Financial Ratio Analysis
B3: RATIOS
B5: Year | E5: =IF(INPUT!E5="","",INPUT!E5) -> 2022 | F5: =IF(INPUT!F5="","",INPUT!F5) -> 2023 | G5: =IF(INPUT!G5="","",INPUT!G5) -> 2024 | H5: =IF(INPUT!H5="","",INPUT!H5) -> 2025 (LTM)
B7: VALUATION RATIOS — OIL & GAS
B9: EV / DACF (Debt-Adjusted Cash Flow) | D9: – | E9: – | F9: – | G9: – | H9: =IFERROR(INPUT!H98/(INPUT!H75+ABS(INPUT!H20)*(1-INPUT!H104)),"–") -> 6.9386674
B10: EV / EBITDAX | D10: – | E10: – | F10: – | G10: – | H10: =IFERROR(INPUT!H98/(INPUT!H30+ABS(INPUT!H15)),"–") -> 4.3414925
B11: EV / Revenue | D11: – | E11: – | F11: – | G11: – | H11: =IFERROR(INPUT!H98/INPUT!H9,"–") -> 1.0955397
B12: Price / Earnings (P/E) | D12: – | E12: – | F12: – | G12: – | H12: =IFERROR(INPUT!H95/(INPUT!H26/INPUT!H96),"–") -> 11.098453
B13: EV / Production ($/BOE/d) | D13: – | E13: – | F13: – | G13: – | H13: –
B14: Price / Reserves 1P (EV/BOE) | D14: – | E14: – | F14: – | G14: – | H14: –
B15: FCF Yield @ current strip | D15: – | E15: =IFERROR((INPUT!E75+INPUT!E80)/INPUT!E97,"–") -> 0.018719135 | F15: =IFERROR((INPUT!F75+INPUT!F80)/INPUT!F97,"–") -> 0.0048343587 | G15: =IFERROR((INPUT!G75+INPUT!G80)/INPUT!G97,"–") -> 0.0069766079 | H15: =IFERROR((INPUT!H75+INPUT!H80)/INPUT!H97,"–") -> 0.063932333
B17: PROFITABILITY RATIOS
B19: Gross Profit Margin | D19: =IFERROR(INPUT!D11/INPUT!D9,"–") -> – | E19: =IFERROR(INPUT!E11/INPUT!E9,"–") -> 0.30842353 | F19: =IFERROR(INPUT!F11/INPUT!F9,"–") -> 0.28487976 | G19: =IFERROR(INPUT!G11/INPUT!G9,"–") -> 0.28389142 | H19: =IFERROR(INPUT!H11/INPUT!H9,"–") -> 0.2843362
B20: EBITDAX Margin | D20: =IFERROR(INPUT!D30/INPUT!D9,"–") -> – | E20: =IFERROR(INPUT!E30/INPUT!E9,"–") -> 0.28175914 | F20: =IFERROR(INPUT!F30/INPUT!F9,"–") -> 0.24482861 | G20: =IFERROR(INPUT!G30/INPUT!G9,"–") -> 0.23435407 | H20: =IFERROR(INPUT!H30/INPUT!H9,"–") -> 0.21718291
B21: EBIT (Operating) Margin | D21: =IFERROR(INPUT!D17/INPUT!D9,"–") -> – | E21: =IFERROR(INPUT!E17/INPUT!E9,"–") -> 0.22980517 | F21: =IFERROR(INPUT!F17/INPUT!F9,"–") -> 0.18171687 | G21: =IFERROR(INPUT!G17/INPUT!G9,"–") -> 0.1673483 | H21: =IFERROR(INPUT!H17/INPUT!H9,"–") -> 0.14124402
B22: Net Profit Margin | D22: =IFERROR(INPUT!D26/INPUT!D9,"–") -> – | E22: =IFERROR(INPUT!E26/INPUT!E9,"–") -> 0.13575633 | F22: =IFERROR(INPUT!F26/INPUT!F9,"–") -> 0.11103702 | G22: =IFERROR(INPUT!G26/INPUT!G9,"–") -> 0.098635039 | H22: =IFERROR(INPUT!H26/INPUT!H9,"–") -> 0.081889177
B23: Return on Equity (ROE) | D23: =IFERROR(INPUT!D26/INPUT!D60,"–") -> – | E23: =IFERROR(INPUT!E26/INPUT!E60,"–") -> 0.24652584 | F23: =IFERROR(INPUT!F26/INPUT!F60,"–") -> 0.14973977 | G23: =IFERROR(INPUT!G26/INPUT!G60,"–") -> 0.10822181 | H23: =IFERROR(INPUT!H26/INPUT!H60,"–") -> 0.08685334
B24: Return on Assets (ROA) | D24: =IFERROR(INPUT!D26/INPUT!D44,"–") -> – | E24: =IFERROR(INPUT!E26/INPUT!E44,"–") -> 0.16267703 | F24: =IFERROR(INPUT!F26/INPUT!F44,"–") -> 0.11445264 | G24: =IFERROR(INPUT!G26/INPUT!G44,"–") -> 0.092960284 | H24: =IFERROR(INPUT!H26/INPUT!H44,"–") -> 0.070498475
B25: Return on Invested Capital (ROIC) | D25: =IFERROR(INPUT!D17*(1-INPUT!D104)/(INPUT!D58+INPUT!D59),"–") -> – | E25: =IFERROR(INPUT!E17*(1-INPUT!E104)/(INPUT!E58+INPUT!E59),"–") -> 0.25038793 | F25: =IFERROR(INPUT!F17*(1-INPUT!F104)/(INPUT!F58+INPUT!F59),"–") -> 0.15107677 | G25: =IFERROR(INPUT!G17*(1-INPUT!G104)/(INPUT!G58+INPUT!G59),"–") -> 0.11016816 | H25: =IFERROR(INPUT!H17*(1-INPUT!H104)/(INPUT!H58+INPUT!H59),"–") -> 0.092011034
B27: LIQUIDITY & SOLVENCY RATIOS
B29: Current Ratio | D29: =IFERROR(INPUT!D38/INPUT!D51,"–") -> – | E29: =IFERROR(INPUT!E38/INPUT!E51,"–") -> 0.75828995 | F29: =IFERROR(INPUT!F38/INPUT!F51,"–") -> 0.83185358 | G29: =IFERROR(INPUT!G38/INPUT!G51,"–") -> 0.77458982 | H29: =IFERROR(INPUT!H38/INPUT!H51,"–") -> 0.6872689
B30: Quick Ratio | D30: =IFERROR((INPUT!D38-INPUT!D36)/INPUT!D51,"–") -> – | E30: =IFERROR((INPUT!E38-INPUT!E36)/INPUT!E51,"–") -> 0.54197789 | F30: =IFERROR((INPUT!F38-INPUT!F36)/INPUT!F51,"–") -> 0.60256623 | G30: =IFERROR((INPUT!G38-INPUT!G36)/INPUT!G51,"–") -> 0.54645919 | H30: =IFERROR((INPUT!H38-INPUT!H36)/INPUT!H51,"–") -> 0.494731
B31: Cash Ratio | D31: =IFERROR(INPUT!D34/INPUT!D51,"–") -> – | E31: =IFERROR(INPUT!E34/INPUT!E51,"–") -> 0.31147201 | F31: =IFERROR(INPUT!F34/INPUT!F51,"–") -> 0.32360412 | G31: =IFERROR(INPUT!G34/INPUT!G51,"–") -> 0.31247657 | H31: =IFERROR(INPUT!H34/INPUT!H51,"–") -> 0.27907192
B32: Debt / Equity Ratio | D32: =IFERROR((INPUT!D49+INPUT!D55)/INPUT!D60,"–") -> – | E32: =IFERROR((INPUT!E49+INPUT!E55)/INPUT!E60,"–") -> 1.119525 | F32: =IFERROR((INPUT!F49+INPUT!F55)/INPUT!F60,"–") -> 0.84076253 | G32: =IFERROR((INPUT!G49+INPUT!G55)/INPUT!G60,"–") -> 0.76557364 | H32: =IFERROR((INPUT!H49+INPUT!H55)/INPUT!H60,"–") -> 0.843429
B33: Net Debt / EBITDA | D33: =IFERROR((INPUT!D49+INPUT!D55-INPUT!D34)/INPUT!D30,"–") -> – | E33: =IFERROR((INPUT!E49+INPUT!E55-INPUT!E34)/INPUT!E30,"–") -> 1.7428764 | F33: =IFERROR((INPUT!F49+INPUT!F55-INPUT!F34)/INPUT!F30,"–") -> 2.037889 | G33: =IFERROR((INPUT!G49+INPUT!G55-INPUT!G34)/INPUT!G30,"–") -> 2.4135945 | H33: =IFERROR((INPUT!H49+INPUT!H55-INPUT!H34)/INPUT!H30,"–") -> 3.0516641
B34: Interest Coverage (EBIT/Interest) | D34: =IFERROR(INPUT!D17/ABS(INPUT!D20),"–") -> – | E34: =IFERROR(INPUT!E17/ABS(INPUT!E20),"–") -> 29.147399 | F34: =IFERROR(INPUT!F17/ABS(INPUT!F20),"–") -> 18.479331 | G34: =IFERROR(INPUT!G17/ABS(INPUT!G20),"–") -> 13.847293 | H34: =IFERROR(INPUT!H17/ABS(INPUT!H20),"–") -> 10.068413
B35: Debt / Total Assets | D35: =IFERROR((INPUT!D49+INPUT!D55)/INPUT!D44,"–") -> – | E35: =IFERROR((INPUT!E49+INPUT!E55)/INPUT!E44,"–") -> 0.73875014 | F35: =IFERROR((INPUT!F49+INPUT!F55)/INPUT!F44,"–") -> 0.6426315 | G35: =IFERROR((INPUT!G49+INPUT!G55)/INPUT!G44,"–") -> 0.65761186 | H35: =IFERROR((INPUT!H49+INPUT!H55)/INPUT!H44,"–") -> 0.68460761
B36: Equity Ratio | D36: =IFERROR(INPUT!D60/INPUT!D44,"–") -> – | E36: =IFERROR(INPUT!E60/INPUT!E44,"–") -> 0.65987822 | F36: =IFERROR(INPUT!F60/INPUT!F44,"–") -> 0.76434365 | G36: =IFERROR(INPUT!G60/INPUT!G44,"–") -> 0.85897924 | H36: =IFERROR(INPUT!H60/INPUT!H44,"–") -> 0.81169561
B38: OPERATIONAL EFFICIENCY RATIOS
B40: Asset Turnover | D40: =IFERROR(INPUT!D9/INPUT!D44,"–") -> – | E40: =IFERROR(INPUT!E9/INPUT!E44,"–") -> 1.1983016 | F40: =IFERROR(INPUT!F9/INPUT!F44,"–") -> 1.0307611 | G40: =IFERROR(INPUT!G9/INPUT!G44,"–") -> 0.94246715 | H40: =IFERROR(INPUT!H9/INPUT!H44,"–") -> 0.86090101
B42: GROWTH RATIOS
B44: Revenue Growth (YoY) | D44: – | E44: =IFERROR(INPUT!E9/INPUT!D9-1,"–") -> – | F44: =IFERROR(INPUT!F9/INPUT!E9-1,"–") -> -0.16848961 | G44: =IFERROR(INPUT!G9/INPUT!F9-1,"–") -> -0.10657928 | H44: =IFERROR(INPUT!H9/INPUT!G9-1,"–") -> -0.067818619
B45: EBITDA Growth (YoY) | D45: – | E45: =IFERROR(INPUT!E30/INPUT!D30-1,"–") -> – | F45: =IFERROR(INPUT!F30/INPUT!E30-1,"–") -> -0.27747675 | G45: =IFERROR(INPUT!G30/INPUT!F30-1,"–") -> -0.14480263 | H45: =IFERROR(INPUT!H30/INPUT!G30-1,"–") -> -0.13611972
B46: Net Income Growth (YoY) | D46: – | E46: =IFERROR(INPUT!E26/INPUT!D26-1,"–") -> – | F46: =IFERROR(INPUT!F26/INPUT!E26-1,"–") -> -0.31989593 | G46: =IFERROR(INPUT!G26/INPUT!F26-1,"–") -> -0.20636749 | H46: =IFERROR(INPUT!H26/INPUT!G26-1,"–") -> -0.22608065
B47: EPS Growth (YoY) | D47: – | E47: =IFERROR((INPUT!E26/INPUT!E96)/(INPUT!D26/INPUT!D96)-1,"–") -> – | F47: =IFERROR((INPUT!F26/INPUT!F96)/(INPUT!E26/INPUT!E96)-1,"–") -> -0.30260624 | G47: =IFERROR((INPUT!G26/INPUT!G96)/(INPUT!F26/INPUT!F96)-1,"–") -> -0.18550682 | H47: =IFERROR((INPUT!H26/INPUT!H96)/(INPUT!G26/INPUT!G96)-1,"–") -> 4.5901915
B48: Total Assets Growth (YoY) | D48: – | E48: =IFERROR(INPUT!E44/INPUT!D44-1,"–") -> – | F48: =IFERROR(INPUT!F44/INPUT!E44-1,"–") -> -0.033335457 | G48: =IFERROR(INPUT!G44/INPUT!F44-1,"–") -> -0.022880171 | H48: =IFERROR(INPUT!H44/INPUT!G44-1,"–") -> 0.020500985
B50: CASH FLOW RATIOS
B52: Operating Cash Flow Margin | D52: =IFERROR(INPUT!D75/INPUT!D9,"–") -> – | E52: =IFERROR(INPUT!E75/INPUT!E9,"–") -> 0.20725381 | F52: =IFERROR(INPUT!F75/INPUT!F9,"–") -> 0.1398068 | G52: =IFERROR(INPUT!G75/INPUT!G9,"–") -> 0.19864015 | H52: =IFERROR(INPUT!H75/INPUT!H9,"–") -> 0.1492728
B53: Free Cash Flow (FCF) | D53: =IFERROR(INPUT!D75+INPUT!D78,"–") -> 0 | E53: =IFERROR(INPUT!E75+INPUT!E78,"–") -> 38882 | F53: =IFERROR(INPUT!F75+INPUT!F78,"–") -> 12888 | G53: =IFERROR(INPUT!G75+INPUT!G78,"–") -> 23947 | H53: =IFERROR(INPUT!H75+INPUT!H78,"–") -> 10266
B54: FCF Margin | D54: =IFERROR(D53/INPUT!D9,"–") -> – | E54: =IFERROR(E53/INPUT!E9,"–") -> 0.14766625 | F54: =IFERROR(F53/INPUT!F9,"–") -> 0.058864098 | G54: =IFERROR(G53/INPUT!G9,"–") -> 0.12242217 | H54: =IFERROR(H53/INPUT!H9,"–") -> 0.05630018
...

Sheet DCF
B1: FinSight | K1: DCF — Discounted Cash Flow Valuation
B3: DCF
B4: All figures in USD millions unless stated
B5: METRIC | C5: (Units) | D5: =IF(INPUT!D5="","",INPUT!D5) | E5: =IF(INPUT!E5="","",INPUT!E5) -> 2022 | F5: =IF(INPUT!F5="","",INPUT!F5) -> 2023 | G5: =IF(INPUT!G5="","",INPUT!G5) -> 2024 | H5: =IF(INPUT!H5="","",INPUT!H5) -> 2025 (LTM) | I5: =TEXT(INPUT!D117+1,"0")&"F" -> 2026F | J5: =TEXT(INPUT!D117+2,"0")&"F" -> 2027F | K5: =TEXT(INPUT!D117+3,"0")&"F" -> 2028F | L5: =TEXT(INPUT!D117+4,"0")&"F" -> 2029F | M5: =TEXT(INPUT!D117+5,"0")&"F" -> 2030F | N5: Terminal
B7: INCOME STATEMENT
B9: Revenue | D9: =INPUT!D9 -> 0 | E9: =INPUT!E9 -> 263310 | F9: =INPUT!F9 -> 218945 | G9: =INPUT!G9 -> 195610 | H9: =IF(INPUT!H9<>"",INPUT!H9,INPUT!G9) -> 182344 | I9: =H9*(1+$I$29) -> 190844 | J9: =I9*(1+$I$29) -> 199740.23 | K9: =J9*(1+$I$29) -> 209051.16 | L9: =K9*(1+$I$29) -> 218796.12 | M9: =L9*(1+$I$29) -> 228995.34
B10: Cost of Goods Sold | D10: =INPUT!D10 -> 0 | E10: =INPUT!E10 -> -182099 | F10: =INPUT!F10 -> -156572 | G10: =INPUT!G10 -> -140078 | H10: =IF(INPUT!H10<>"",INPUT!H10,INPUT!G10) -> -130497 | I10: =-I9*(1-$I$30) -> -135426.2 | J10: =-J9*(1-$I$30) -> -141739.12 | K10: =-K9*(1-$I$30) -> -148346.31 | L10: =-L9*(1-$I$30) -> -155261.5 | M10: =-M9*(1-$I$30) -> -162499.05
B11: Gross Profit | D11: =SUM(D9:D10) -> 0 | E11: =SUM(E9:E10) -> 81211 | F11: =SUM(F9:F10) -> 62373 | G11: =SUM(G9:G10) -> 55532 | H11: =SUM(H9:H10) -> 51847 | I11: =SUM(I9:I10) -> 55417.801 | J11: =SUM(J9:J10) -> 58001.113 | K11: =SUM(K9:K10) -> 60704.845 | ... M11: =SUM(M9:M10) -> 66496.291
B13: SG&A Expenses | D13: =INPUT!D14 -> 0 | E13: =INPUT!E14 -> -3946 | F13: =INPUT!F14 -> -4800 | G13: =INPUT!G14 -> -5150 | H13: =IF(INPUT!H14<>"",INPUT!H14,INPUT!G14) -> -5834 | I13: =-I9*$I$31 -> -4543.6054 | J13: =-J9*$I$31 -> -4755.4065 | K13: =-K9*$I$31 -> -4977.0806 | L13: =-L9*$I$31 -> -5209.0882 | M13: =-M9*$I$31 -> -5451.9108
B14: Research & Development | D14: =INPUT!D15 -> 0 | E14: =INPUT!E15 -> -3075 | F14: =INPUT!F15 -> -3969 | G14: =INPUT!G15 -> -4540 | H14: =IF(INPUT!H15<>"",INPUT!H15,INPUT!G15) -> -6411 | I14: =-I9*$I$32 -> -4206.8868 | J14: =-J9*$I$32 -> -4402.9916 | K14: =-K9*$I$32 -> -4608.2379 | L14: =-L9*$I$32 -> -4823.0518 | M14: =-M9*$I$32 -> -5047.8793
B15: EBITDA | D15: =INPUT!D30 -> 0 | E15: =INPUT!E30 -> 74190 | F15: =INPUT!F30 -> 53604 | G15: =INPUT!G30 -> 45842 | H15: =IF(INPUT!H30<>"",INPUT!H30,INPUT!G30) -> 39602 | I15: =I11+I13+I14 -> 46667.309 | J15: =J11+J13+J14 -> 48842.715 | K15: =K11+K13+K14 -> 51119.527 | L15: =L11+L13+L14 -> 53502.473 | M15: =M11+M13+M14 -> 55996.501
B17: Depreciation & Amortization | D17: =INPUT!D16 -> 0 | E17: =INPUT!E16 -> -13680 | F17: =INPUT!F16 -> -13818 | G17: =INPUT!G16 -> -13107 | H17: =IF(INPUT!H16<>"",INPUT!H16,INPUT!G16) -> -13847 | I17: =-I9*$I$33 -> -12309.933 | J17: =-J9*$I$33 -> -12883.763 | K17: =-K9*$I$33 -> -13484.342 | L17: =-L9*$I$33 -> -14112.917 | M17: =-M9*$I$33 -> -14770.793
B18: EBIT (Operating Profit) | D18: =D15+D17 -> 0 | E18: =E15+E17 -> 60510 | F18: =F15+F17 -> 39786 | G18: =G15+G17 -> 32735 | H18: =H15+H17 -> 25755 | I18: =I15+I17 -> 34357.376 | J18: =J15+J17 -> 35958.952 | K18: =K15+K17 -> 37635.185 | ... M18: =M15+M17 -> 41225.708
B20: Interest Expense | D20: =INPUT!D20 -> 0 | E20: =INPUT!E20 -> -2076 | F20: =INPUT!F20 -> -2153 | G20: =INPUT!G20 -> -2364 | H20: =IF(INPUT!H20<>"",INPUT!H20,INPUT!G20) -> -2558 | I20: =-I18*(INPUT!H103)/(1-$I$34) -> -2487.7189 | J20: =-J18*(INPUT!H103)/(1-$I$34) -> -2603.6843 | K20: =-K18*(INPUT!H103)/(1-$I$34) -> -2725.0556 | L20: =-L18*(INPUT!H103)/(1-$I$34) -> -2852.0846 | M20: =-M18*(INPUT!H103)/(1-$I$34) -> -2985.035
B21: Earnings Before Tax (EBT) | D21: =D18+D20 -> 0 | E21: =E18+E20 -> 58434 | F21: =F18+F20 -> 37633 | G21: =G18+G20 -> 30371 | H21: =H18+H20 -> 23197 | I21: =I18+I20 -> 31869.657 | J21: =J18+J20 -> 33355.267 | K21: =K18+K20 -> 34910.13 | ... M21: =M18+M20 -> 38240.673
B23: Income Taxes | D23: =INPUT!D24 -> 0 | E23: =INPUT!E24 -> -23831 | F23: =INPUT!F24 -> -15123 | G23: =INPUT!G24 -> -12863 | H23: =IF(INPUT!H24<>"",INPUT!H24,INPUT!G24) -> -9380 | I23: =-I21*$I$34 -> -12503.263 | J23: =-J21*$I$34 -> -13086.105 | K23: =-K21*$I$34 -> -13696.117 | L23: =-L21*$I$34 -> -14334.564 | M23: =-M21*$I$34 -> -15002.772
B24: Net Income | D24: =D21+D23 -> 0 | E24: =E21+E23 -> 34603 | F24: =F21+F23 -> 22510 | G24: =G21+G23 -> 17508 | H24: =H21+H23 -> 13817 | I24: =I21+I23 -> 19366.394 | J24: =J21+J23 -> 20269.162 | K24: =K21+K23 -> 21214.013 | ... M24: =M21+M23 -> 23237.901
B26: ASSUMPTIONS & DRIVERS
B27: All figures in USD millions unless stated
B28: INCOME STATEMENT DRIVERS
B29: Revenue Growth Rate (YoY) | D29: =IFERROR(IF(NOT(ISBLANK(INPUT!H9)),INPUT!H9/INPUT!G9-1,IF(NOT(ISBLANK(INPUT!G9)),INPUT!G9/INPUT!F9-1,IF(NOT(ISBLANK(INPUT!F9)),INPUT!F9/INPUT!E9-1,IF(NOT(ISBLANK(INPUT!E9)),INPUT!E9/INPUT!D9-1,0.05)))),0.05) -> -0.067818619 | I29: =IF(D46="Yes",D45,IFERROR(AVERAGE(IF(ISNUMBER(RATIOS!F44),RATIOS!F44,0),IF(ISNUMBER(RATIOS!G44),RATIOS!G44,0),IF(ISNUMBER(RATIOS!H44),RATIOS!H44,0)),0.05)) -> 0.046615189
B30: Gross Margin | D30: =IFERROR(INPUT!H11/INPUT!H9,0.4) -> 0.2843362 | I30: =IFERROR(AVERAGE(IF(INPUT!E9<>0,INPUT!E11/INPUT!E9),IF(INPUT!F9<>0,INPUT!F11/INPUT!F9),IF(INPUT!G9<>0,INPUT!G11/INPUT!G9),IF(INPUT!H9<>0,INPUT!H11/INPUT!H9)),0.4) -> 0.29038273
B31: SG&A (% of Revenue) | D31: =IFERROR(ABS(INPUT!H14)/INPUT!H9,0.15) -> 0.031994472 | I31: =IFERROR(AVERAGE(IF(INPUT!E9<>0,ABS(INPUT!E14)/INPUT!E9),IF(INPUT!F9<>0,ABS(INPUT!F14)/INPUT!F9),IF(INPUT!G9<>0,ABS(INPUT!G14)/INPUT!G9),IF(INPUT!H9<>0,ABS(INPUT!H14)/INPUT!H9)),0.15) -> 0.023807955
B32: R&D (% of Revenue) | D32: =IFERROR(ABS(INPUT!H15)/INPUT!H9,0.05) -> 0.035158821 | I32: =IFERROR(AVERAGE(IF(INPUT!E9<>0,ABS(INPUT!E15)/INPUT!E9),IF(INPUT!F9<>0,ABS(INPUT!F15)/INPUT!F9),IF(INPUT!G9<>0,ABS(INPUT!G15)/INPUT!G9),IF(INPUT!H9<>0,ABS(INPUT!H15)/INPUT!H9)),0.05) -> 0.02204359
B33: D&A (% of Revenue) | D33: =IFERROR(ABS(INPUT!H16)/INPUT!H9,0.04) -> 0.075938885 | I33: =IFERROR(AVERAGE(IF(INPUT!E9<>0,ABS(INPUT!E16)/INPUT!E9),IF(INPUT!F9<>0,ABS(INPUT!F16)/INPUT!F9),IF(INPUT!G9<>0,ABS(INPUT!G16)/INPUT!G9),IF(INPUT!H9<>0,ABS(INPUT!H16)/INPUT!H9)),0.04) -> 0.064502593
B34: Effective Tax Rate | D34: =IFERROR(INPUT!H104,0.21) -> 0.3858 | I34: =IFERROR(AVERAGEIF(INPUT!E104:H104,"<>0"),0.21) -> 0.392325
B36: BALANCE SHEET / CASH FLOW DRIVERS
B37: CapEx (% of Revenue) | D37: =IFERROR(ABS(INPUT!H78)/INPUT!H9,0.05) -> 0.092972623 | E37: =I37 -> 0.077430217 | F37: =I37 -> 0.077430217 | I37: =IFERROR(AVERAGE(IF(INPUT!E9<>0,ABS(INPUT!E78)/INPUT!E9),IF(INPUT!F9<>0,ABS(INPUT!F78)/INPUT!F9),IF(INPUT!G9<>0,ABS(INPUT!G78)/INPUT!G9),IF(INPUT!H9<>0,ABS(INPUT!H78)/INPUT!H9)),0.05) -> 0.077430217 | J37: =I37 -> 0.077430217 | K37: =I37 -> 0.077430217 | L37: =I37 -> 0.077430217 | M37: =I37 -> 0.077430217
B38: Change in NWC (% of Revenue Change) | D38: =IFERROR(ABS((INPUT!H71+INPUT!H72+INPUT!H73)/INPUT!H9),0.1) -> 0.010869565 | E38: =I38 -> 0.024771968 | F38: =I38 -> 0.024771968 | I38: =IFERROR(AVERAGE(IF(INPUT!E9<>0,ABS((INPUT!E71+INPUT!E72+INPUT!E73)/INPUT!E9)),IF(INPUT!F9<>0,ABS((INPUT!F71+INPUT!F72+INPUT!F73)/INPUT!F9)),IF(INPUT!G9<>0,ABS((INPUT!G71+INPUT!G72+INPUT!G73)/INPUT!G9)),IF(INPUT!H9<>0,ABS((INPUT!H71+INPUT!H72+INPUT!H73)/INPUT!H9))),0.1) -> 0.024771968 | J38: =I38 -> 0.024771968 | K38: =I38 -> 0.024771968 | L38: =I38 -> 0.024771968 | M38: =I38 -> 0.024771968
B40: OIL PRICE DECK & REVENUE SENSITIVITY
B41: Brent Crude — Bear / Base / Bull ($/bbl) | D41: Bear ($60) | E41: Base ($75) | F41: Bull ($90) | G41: Bear | Base | Bull
B42: Active Brent Price ($/bbl) — change here | D42: Base | E42: =IF(D42="Bear",60,IF(D42="Base",75,IF(D42="Bull",90,75))) -> 75
B43: Revenue Sensitivity (per $1/bbl Brent) | D43: 1700 | E43: =E18 -> 60510 | F43: =F18 -> 39786 | G43: =G18 -> 32735 | H43: =H18 -> 25755 | I43: =I18 -> 34357.376 | J43: =J18 -> 35958.952 | K43: =K18 -> 37635.185 | L43: =L18 -> 39389.556 | M43: =M18 -> 41225.708
B44: Brent Reference Price LTM ($/bbl) | D44: 70 | E44: =E18*(-INPUT!E104) -> -24204 | F44: =F18*(-INPUT!F104) -> -15257.931 | G44: =G18*(-INPUT!G104) -> -13094 | H44: =H18*(-INPUT!H104) -> -9936.279 | I44: =I18*(-$I$34) -> -13479.258 | J44: =J18*(-$I$34) -> -14107.596 | K44: =K18*(-$I$34) -> -14765.224 | L44: =L18*(-$I$34) -> -15453.508 | M44: =M18*(-$I$34) -> -16173.876
B45: Brent-Adjusted Revenue Growth (Y1-Y5) | D45: =IFERROR(((INPUT!H9+(E42-D44)*D43)/INPUT!H9)-1,0) -> 0.046615189 | E45: =E43+E44 -> 36306 | F45: =F43+F44 -> 24528.069 | G45: =G43+G44 -> 19641 | H45: =H43+H44 -> 15818.721 | I45: =I43+I44 -> 20878.119 | J45: =J43+J44 -> 21851.356 | K45: =K43+K44 -> 22869.961 | L45: =L43+L44 -> 23936.049 | M45: =M43+M44 -> 25051.832
B46: Use Brent Deck? (Yes = Brent-adj. / No = Historical) | D46: Yes
B48: FREE CASH FLOW CALCULATION
B49: (+) Depreciation & Amortization | E49: =ABS(E17) -> 13680 | F49: =ABS(F17) -> 13818 | G49: =ABS(G17) -> 13107 | H49: =ABS(H17) -> 13847 | I49: =ABS(I17) -> 12309.933 | J49: =ABS(J17) -> 12883.763 | K49: =ABS(K17) -> 13484.342 | L49: =ABS(L17) -> 14112.917 | M49: =ABS(M17) -> 14770.793
B50: (-) Capital Expenditures (CapEx) | E50: =INPUT!E78 -> -15690 | F50: =INPUT!F78 -> -17722 | G50: =INPUT!G78 -> -14909 | H50: =IF(INPUT!H78<>"",INPUT!H78,INPUT!G78) -> -16953 | I50: =-I9*$I$37 -> -14777.092 | J50: =-J9*$I$37 -> -15465.929 | K50: =-K9*$I$37 -> -16186.877 | L50: =-L9*$I$37 -> -16941.431 | M50: =-M9*$I$37 -> -17731.159
B51: (-) Change in Working Capital | E51: =INPUT!E70+INPUT!E71+INPUT!E72+INPUT!E73 -> 18394 | F51: =INPUT!F70+INPUT!F71+INPUT!F72+INPUT!F73 -> 5049 | G51: =INPUT!G70+INPUT!G71+INPUT!G72+INPUT!G73 -> 19027 | H51: =IF(INPUT!H70<>"",INPUT!H70,INPUT!G70)+IF(INPUT!H71<>"",INPUT!H71,INPUT!G71)+IF(INPUT!H72<>"",INPUT!H72,INPUT!G72)+IF(INPUT!H73<>"",INPUT!H73,INPUT!G73) -> 11865 | I51: =-(I9-H9)*$I$38 -> -210.56173 | J51: =-(J9-I9)*$I$38 -> -220.37711 | K51: =-(K9-J9)*$I$38 -> -230.65003 | L51: =-(L9-K9)*$I$38 -> -241.40182 | M51: =-(M9-L9)*$I$38 -> -252.65481
...

Sheet SOTP
B1: FinSight | J1: SOTP — Sum-of-the-Parts Valuation
B2: SOTP
B3: All figures in USD millions unless stated | Segments: Upstream / iGRP (LNG+Gas) / Renewables & Power / Refining & Chemicals
B4: SEGMENT OVERVIEW | C4: Segment | D4: EBITDA ($M) | E4: EV/EBITDA (x) | F4: Implied EV ($M) | G4: % of Total EV
B6: 1. Exploration & Production (Upstream) | C6: Upstream | D6: 18500 | E6: 5.5 | F6: =D6*E6 -> 101750 | G6: =IFERROR(F6/F11,"–") -> 0.45495193
B7: 2. Integrated Gas, Renewables & Power (iGRP) | C7: iGRP / LNG | D7: 12000 | E7: 7.5 | F7: =D7*E7 -> 90000 | G7: =IFERROR(F7/F11,"–") -> 0.40241449
B8: 3. Renewables & Power (R&P) | C8: Renewables | D8: 2200 | E8: 12 | F8: =D8*E8 -> 26400 | G8: =IFERROR(F8/F11,"–") -> 0.11804158
B9: 4. Refining, Chemicals & Marketing (RCM) | C9: Refining | D9: 4500 | E9: 4 | F9: =D9*E9 -> 18000 | G9: =IFERROR(F9/F11,"–") -> 0.080482897
B10: 5. Corporate / Holding (Overhead & Eliminations) | C10: Corporate | D10: -2500 | E10: 5 | F10: =D10*E10 -> -12500 | G10: =IFERROR(F10/F11,"–") -> -0.055890901
B11: TOTAL GROSS ASSET VALUE (Sum of Parts) | F11: =SUM(F6:F10) -> 223650 | G11: =IFERROR(F11/F11,"–") -> 1
B13: BRIDGE TO EQUITY VALUE
B15: Total Gross Asset Value (Segment EV) | F15: =F11 -> 223650
B16: (-) Net Debt (LTM) | F16: =-(INPUT!H48+INPUT!H54-INPUT!H34) -> -34043
B17: (+) Minorities & Hybrid Adj. (approx.) | F17: -8000
B18: IMPLIED EQUITY VALUE (SOTP) | F18: =F15+F16+F17 -> 181607
B20: Shares Outstanding (Diluted, M) | F20: =INPUT!H96 -> 2133.12
B21: IMPLIED SHARE PRICE (SOTP) ($) | F21: =IFERROR(F18/(F20),"–") -> 85.136795
B22: Current Share Price ($) | F22: =INPUT!H95 -> 77.69
B23: Implied Upside / (Downside) | F23: =IFERROR(F21/F22-1,"–") -> 0.095852683
B25: SENSITIVITY — Implied Share Price ($) vs Upstream EV/EBITDA & LNG EV/EBITDA
B26: LNG (iGRP) EV/EBITDA → | D26: 6 | E26: 7.5 | F26: 9
B27: Upstream (E6) ↓ | C27: 4.5 | D27: =IFERROR((D6*C27+D7*D26+F8+F9+F10+F16+F17)/(F20),"–") -> 68.025709 | E27: =IFERROR((D6*C27+D7*E26+F8+F9+F10+F16+F17)/(F20),"–") -> 76.464053 | F27: =IFERROR((D6*C27+D7*F26+F8+F9+F10+F16+F17)/(F20),"–") -> 84.902396
C28: 5.5 | D28: =IFERROR((D6*C28+D7*D26+F8+F9+F10+F16+F17)/(F20),"–") -> 76.698451 | E28: =IFERROR((D6*C28+D7*E26+F8+F9+F10+F16+F17)/(F20),"–") -> 85.136795 | F28: =IFERROR((D6*C28+D7*F26+F8+F9+F10+F16+F17)/(F20),"–") -> 93.575139
C29: 6.5 | D29: =IFERROR((D6*C29+D7*D26+F8+F9+F10+F16+F17)/(F20),"–") -> 85.371193 | E29: =IFERROR((D6*C29+D7*E26+F8+F9+F10+F16+F17)/(F20),"–") -> 93.809537 | F29: =IFERROR((D6*C29+D7*F26+F8+F9+F10+F16+F17)/(F20),"–") -> 102.24788
B32: METHODOLOGY NOTES
B33: (1) EBITDA by segment are estimates based on TTE Factbook 2024 & analyst consensus. Update D6:D10 with actual reported segment EBITDA when available.
B34: (2) EV/EBITDA multiples sourced from Bloomberg sector comparables (E&P peers, LNG peers, Renewables peers, Refining peers).
B35: (3) Net Debt linked to INPUT LTM Balance Sheet (ST Debt + LT Debt - Cash). Minorities adj. ($8B) is an estimate.
B36: (4) Sensitivity table (rows 27-29): Yellow = base case (Upstream 5.5x / LNG 7.5x). Adjust inputs in D6:E10.
B38: © 2015 to 2024 FinSight
B39: This Excel model is for educational purposes only.
B40: https://finsight.com/

Sheet COMPARABLES
B1: FinSight | K1: COMPARABLES — Trading Comparables
B3: COMPARABLES
B4: All figures in USD millions unless stated
B6: COMPARABLE TRADING ANALYSIS
D7: Share Price | E7: Enterprise Value | F7: Revenue (LTM) | G7: EBITDAX (LTM) | H7: EV / EBITDA | I7: EV / Revenue | J7: EPS (LTM) | K7: P / E (LTM)
B8: PEER COMPANIES | C8: TICKER | D8: (USD/sh) | E8: ($M) | F8: ($M) | G8: ($M) | H8: (x) | I8: (x) | J8: (USD/sh) | K8: (x)
B9: XOM | C9: XOM | D9: 75.33 | E9: 173303.61 | F9: 185019.01 | G9: 17629 | H9: =IFERROR(E9/G9,"–") -> 9.8305979 | I9: =IFERROR(E9/F9,"–") -> 0.93668002 | J9: 15.98 | K9: =IFERROR(D9/J9,"–") -> 4.7140175
B10: SHEL.L | C10: SHEL.L | D10: 11.62 | E10: 183371.55 | F10: 187267.01 | G10: 5393 | H10: =IFERROR(E10/G10,"–") -> 34.001771 | I10: =IFERROR(E10/F10,"–") -> 0.97919836 | J10: 10.81 | K10: =IFERROR(D10/J10,"–") -> 1.0749306
B11: BP.L | C11: BP.L | D11: 525.72 | E11: 1333326.9 | F11: 200966 | G11: 101892 | H11: =IFERROR(E11/G11,"–") -> 13.085688 | I11: =IFERROR(E11/F11,"–") -> 6.6345895 | J11: 23.5 | K11: =IFERROR(D11/J11,"–") -> 22.371064
B12: ENI.MI | C12: ENI.MI | D12: 78.46 | E12: 144410 | F12: 133453 | G12: 15742 | H12: =IFERROR(E12/G12,"–") -> 9.1735485 | I12: =IFERROR(E12/F12,"–") -> 1.0821038 | J12: 1.3 | K12: =IFERROR(D12/J12,"–") -> 60.353846
B13: REP.MC | C13: REP.MC | D13: 87.8 | E13: 258704.92 | F13: 321913 | G13: 24292 | H13: =IFERROR(E13/G13,"–") -> 10.649799 | I13: =IFERROR(E13/F13,"–") -> 0.80364856 | K13: =IFERROR(D13/J13,"–") -> –
B15: Mean | D15: =IFERROR(AVERAGE(D9:D13),"–") -> 155.786 | E15: =IFERROR(AVERAGE(E9:E13),"–") -> 418623.4 | F15: =IFERROR(AVERAGE(F9:F13),"–") -> 205723.6 | G15: =IFERROR(AVERAGE(G9:G13),"–") -> 32989.6 | H15: =IFERROR(AVERAGE(H9:H13),"–") -> 15.348281 | I15: =IFERROR(AVERAGE(I9:I13),"–") -> 2.087244 | J15: =IFERROR(AVERAGE(J9:J13),"–") -> 12.8975 | K15: =IFERROR(AVERAGE(K9:K13),"–") -> 22.128465
B16: Median | D16: =IFERROR(MEDIAN(D9:D13),"–") -> 78.46 | E16: =IFERROR(MEDIAN(E9:E13),"–") -> 183371.55 | F16: =IFERROR(MEDIAN(F9:F13),"–") -> 187267.01 | G16: =IFERROR(MEDIAN(G9:G13),"–") -> 17629 | H16: =IFERROR(MEDIAN(H9:H13),"–") -> 10.649799 | I16: =IFERROR(MEDIAN(I9:I13),"–") -> 0.97919836 | J16: =IFERROR(MEDIAN(J9:J13),"–") -> 13.395 | K16: =IFERROR(MEDIAN(K9:K13),"–") -> 13.542541
B17: Maximum | D17: =IFERROR(MAX(D9:D13),"–") -> 525.72 | E17: =IFERROR(MAX(E9:E13),"–") -> 1333326.9 | F17: =IFERROR(MAX(F9:F13),"–") -> 321913 | G17: =IFERROR(MAX(G9:G13),"–") -> 101892 | H17: =IFERROR(MAX(H9:H13),"–") -> 34.001771 | I17: =IFERROR(MAX(I9:I13),"–") -> 6.6345895 | J17: =IFERROR(MAX(J9:J13),"–") -> 23.5 | K17: =IFERROR(MAX(K9:K13),"–") -> 60.353846
B18: Minimum | D18: =IFERROR(MIN(D9:D13),"–") -> 11.62 | E18: =IFERROR(MIN(E9:E13),"–") -> 144410 | F18: =IFERROR(MIN(F9:F13),"–") -> 133453 | G18: =IFERROR(MIN(G9:G13),"–") -> 5393 | H18: =IFERROR(MIN(H9:H13),"–") -> 9.1735485 | I18: =IFERROR(MIN(I9:I13),"–") -> 0.80364856 | J18: =IFERROR(MIN(J9:J13),"–") -> 1.3 | K18: =IFERROR(MIN(K9:K13),"–") -> 1.0749306
B20: TARGET COMPANY VALUATION (Based on Peer Multiples)
B21: TARGET COMPANY METRICS (from INPUT) | D21: =INPUT!H5 -> 2025 (LTM)
B22: Target: Revenue (LTM) | C22: ($M) | D22: =INPUT!H9/1000 -> 182.344
B23: Target: EBITDAX (LTM) | C23: ($M) | D23: =INPUT!H30/1000 -> 39.602
B24: Target: DACF (LTM) | C24: ($) | D24: =IFERROR(INPUT!H75+ABS(INPUT!H20)*(1-INPUT!H104),"–") -> 28790.124
B25: Target: Net Debt | C25: ($M) | D25: =IFERROR((INPUT!H54+INPUT!H55-INPUT!H34)/1000,"–") -> 158.458
B26: Target: Shares Outstanding | C26: (M) | D26: =INPUT!H96/1000 -> 2.13312
B28: IMPLIED VALUATION
B29: EV / EBITDAX — Implied EV ($M) | D29: =IFERROR(D23*H18,"–") -> 363.29087 | E29: =IFERROR(D23*H15,"–") -> 607.82262 | F29: =IFERROR(D23*H16,"–") -> 421.75334 | G29: =IFERROR(D23*H17,"–") -> 1346.5381
B30: EV / DACF — Implied EV ($M) | D30: =IFERROR(D22*I18,"–") -> 146.54049 | E30: =IFERROR(D22*I15,"–") -> 380.59643 | F30: =IFERROR(D22*I16,"–") -> 178.55095 | G30: =IFERROR(D22*I17,"–") -> 1209.7776
B31: P/E — Implied Equity Value ($M) | D31: =IFERROR(D24*K18*D26,"–") -> 66014.487 | E31: =IFERROR(D24*K15*D26,"–") -> 1358970.7 | F31: =IFERROR(D24*K16*D26,"–") -> 831685.19 | G31: =IFERROR(D24*K17*D26,"–") -> 3706498
B33: Implied Enterprise Value (Average of 3 Methods) | C33: ($M) | D33: =IFERROR(AVERAGE(D29,D30),"–") -> 254.91568 | E33: =IFERROR(AVERAGE(E29,E30),"–") -> 494.20952 | F33: =IFERROR(AVERAGE(F29,F30),"–") -> 300.15215 | G33: =IFERROR(AVERAGE(G29,G30),"–") -> 1278.1579
B34: (-) Net Debt | C34: ($M) | D34: =D25 -> 158.458 | E34: =D25 -> 158.458 | F34: =D25 -> 158.458 | G34: =D25 -> 158.458
B35: Implied Equity Value ($M) | C35: ($M) | D35: =IFERROR(D33-D34,"–") -> 96.45768 | E35: =IFERROR(E33-E34,"–") -> 335.75152 | F35: =IFERROR(F33-F34,"–") -> 141.69415 | G35: =IFERROR(G33-G34,"–") -> 1119.6999
B36: Implied Share Price ($) | C36: ($) | D36: =IFERROR(D35/D26,"–") -> 45.219059 | E36: =IFERROR(E35/D26,"–") -> 157.39927 | F36: =IFERROR(F35/D26,"–") -> 66.425773 | G36: =IFERROR(G35/D26,"–") -> 524.9118
B37: Current Share Price ($) | C37: ($) | D37: =INPUT!H95 -> 77.69 | E37: =INPUT!H95 -> 77.69 | F37: =INPUT!H95 -> 77.69 | G37: =INPUT!H95 -> 77.69
B38: Implied Upside / (Downside) | C38: (%) | D38: =IFERROR(D36/D37-1,"–") -> -0.41795521 | E38: =IFERROR(E36/D37-1,"–") -> 1.0259913 | F38: =IFERROR(F36/D37-1,"–") -> -0.1449894 | G38: =IFERROR(G36/D37-1,"–") -> 5.7564912
B41: (1) Target company EV based on LTM EV/EBITDA and EV/Revenue multiples relative to comparable peer set.
B43: © 2015 to 2024 FinSight
B44: This Excel model is for educational purposes only.
B45: https://finsight.com/
B47: Company | C47: EV/EBITDA (x) | D47: EV/Revenue (x) | E47: P/E (x)
B48: =B9 -> XOM | C48: =IFERROR(H9*1,0) -> 9.8305979 | D48: =IFERROR(I9*1,0) -> 0.93668002 | E48: =IFERROR(K9*1,0) -> 4.7140175
B49: =B10 -> SHEL.L | C49: =IFERROR(H10*1,0) -> 34.001771 | D49: =IFERROR(I10*1,0) -> 0.97919836 | E49: =IFERROR(K10*1,0) -> 1.0749306
B50: =B11 -> BP.L | C50: =IFERROR(H11*1,0) -> 13.085688 | D50: =IFERROR(I11*1,0) -> 6.6345895 | E50: =IFERROR(K11*1,0) -> 22.371064
...

Sheet SCENARIOS
B1: FinSight | H1: SCENARIOS — Scenario Analysis
B3: SCENARIOS
B4: All figures in USD millions unless stated | 3 scenarios: Pessimistic / Realistic (Base) / Optimistic
B5: METRIC | E5: =TEXT(INPUT!D117-3,"0") -> 2022 | F5: =TEXT(INPUT!D117-2,"0") -> 2023 | G5: =TEXT(INPUT!D117-1,"0") -> 2024 | H5: =INPUT!D117&" (LTM)" -> 2025 (LTM) | I5: =TEXT(INPUT!D117+1,"0")&"F" -> 2026F | J5: =TEXT(INPUT!D117+2,"0")&"F" -> 2027F | K5: =TEXT(INPUT!D117+3,"0")&"F" -> 2028F | L5: =TEXT(INPUT!D117+4,"0")&"F" -> 2029F | M5: =TEXT(INPUT!D117+5,"0")&"F" -> 2030F
B6: ▶ SELECT SCENARIO | D6: Realistic
B7: DRIVER | D7: Pessimistic | E7: Realistic | F7: Optimistic
B8: Revenue Growth Rate (Y1-Y5) | D8: {=IFERROR(INDEX(SECTOR_REF!$C$2:$E$71,MATCH(1,(SECTOR_REF!$A$2:$A$71=INPUT!$D$116)*(SECTOR_REF!$B$2:$B$71="Revenue Growth Rate (Y1-Y5)"),0),MATCH("Pessimiste",{"Pessimiste","Realiste","Optimiste"},0)),IFERROR(INPUT!H9/INPUT!G9-1,0.02))} -> -0.05 | E8: {=IFERROR(INDEX(SECTOR_REF!$C$2:$E$71,MATCH(1,(SECTOR_REF!$A$2:$A$71=INPUT!$D$116)*(SECTOR_REF!$B$2:$B$71="Revenue Growth Rate (Y1-Y5)"),0),MATCH("Realiste",{"Pessimiste","Realiste","Optimiste"},0)),IFERROR(INPUT!H9/INPUT!G9-1,0.05))} -> 0.02 | F8: {=IFERROR(INDEX(SECTOR_REF!$C$2:$E$71,MATCH(1,(SECTOR_REF!$A$2:$A$71=INPUT!$D$116)*(SECTOR_REF!$B$2:$B$71="Revenue Growth Rate (Y1-Y5)"),0),MATCH("Optimiste",{"Pessimiste","Realiste","Optimiste"},0)),IFERROR(INPUT!H9/INPUT!G9-1,0.09))} -> 0.06
B9: EBITDAX Margin (OIL_GAS) | D9: {=IFERROR(INDEX(SECTOR_REF!$C$2:$E$71,MATCH(1,(SECTOR_REF!$A$2:$A$71=INPUT!$D$116)*(SECTOR_REF!$B$2:$B$71="Gross Margin"),0),MATCH("Pessimiste",{"Pessimiste","Realiste","Optimiste"},0)),IFERROR(INPUT!H11/INPUT!H9,0.4)-0.03)} -> 0.2543362 | E9: {=IFERROR(INDEX(SECTOR_REF!$C$2:$E$71,MATCH(1,(SECTOR_REF!$A$2:$A$71=INPUT!$D$116)*(SECTOR_REF!$B$2:$B$71="Gross Margin"),0),MATCH("Realiste",{"Pessimiste","Realiste","Optimiste"},0)),IFERROR(INPUT!H11/INPUT!H9,0.4))} -> 0.2843362 | F9: {=IFERROR(INDEX(SECTOR_REF!$C$2:$E$71,MATCH(1,(SECTOR_REF!$A$2:$A$71=INPUT!$D$116)*(SECTOR_REF!$B$2:$B$71="Gross Margin"),0),MATCH("Optimiste",{"Pessimiste","Realiste","Optimiste"},0)),IFERROR(INPUT!H11/INPUT!H9,0.4)+0.03)} -> 0.3143362
B10: EBITDA Margin | D10: {=IFERROR(INDEX(SECTOR_REF!$C$2:$E$71,MATCH(1,(SECTOR_REF!$A$2:$A$71=INPUT!$D$116)*(SECTOR_REF!$B$2:$B$71="EBITDA Margin"),0),MATCH("Pessimiste",{"Pessimiste","Realiste","Optimiste"},0)),IFERROR(INPUT!H30/INPUT!H9,0.15)-0.03)} -> 0.15 | E10: {=IFERROR(INDEX(SECTOR_REF!$C$2:$E$71,MATCH(1,(SECTOR_REF!$A$2:$A$71=INPUT!$D$116)*(SECTOR_REF!$B$2:$B$71="EBITDA Margin"),0),MATCH("Realiste",{"Pessimiste","Realiste","Optimiste"},0)),IFERROR(INPUT!H30/INPUT!H9,0.15))} -> 0.22 | F10: {=IFERROR(INDEX(SECTOR_REF!$C$2:$E$71,MATCH(1,(SECTOR_REF!$A$2:$A$71=INPUT!$D$116)*(SECTOR_REF!$B$2:$B$71="EBITDA Margin"),0),MATCH("Optimiste",{"Pessimiste","Realiste","Optimiste"},0)),IFERROR(INPUT!H30/INPUT!H9,0.15)+0.03)} -> 0.28
B11: Terminal Growth Rate | D11: {=IFERROR(INDEX(SECTOR_REF!$C$2:$E$71,MATCH(1,(SECTOR_REF!$A$2:$A$71=INPUT!$D$116)*(SECTOR_REF!$B$2:$B$71="Terminal Growth Rate"),0),MATCH("Pessimiste",{"Pessimiste","Realiste","Optimiste"},0)),DCF!D70-0.01)} -> 0.01 | E11: {=IFERROR(INDEX(SECTOR_REF!$C$2:$E$71,MATCH(1,(SECTOR_REF!$A$2:$A$71=INPUT!$D$116)*(SECTOR_REF!$B$2:$B$71="Terminal Growth Rate"),0),MATCH("Realiste",{"Pessimiste","Realiste","Optimiste"},0)),DCF!D70)} -> 0.02 | F11: {=IFERROR(INDEX(SECTOR_REF!$C$2:$E$71,MATCH(1,(SECTOR_REF!$A$2:$A$71=INPUT!$D$116)*(SECTOR_REF!$B$2:$B$71="Terminal Growth Rate"),0),MATCH("Optimiste",{"Pessimiste","Realiste","Optimiste"},0)),DCF!D70+0.01)} -> 0.03
B12: WACC | D12: {=IFERROR(INDEX(SECTOR_REF!$C$2:$E$71,MATCH(1,(SECTOR_REF!$A$2:$A$71=INPUT!$D$116)*(SECTOR_REF!$B$2:$B$71="WACC"),0),MATCH("Pessimiste",{"Pessimiste","Realiste","Optimiste"},0)),DCF!D66+0.015)} -> 0.09 | E12: {=IFERROR(INDEX(SECTOR_REF!$C$2:$E$71,MATCH(1,(SECTOR_REF!$A$2:$A$71=INPUT!$D$116)*(SECTOR_REF!$B$2:$B$71="WACC"),0),MATCH("Realiste",{"Pessimiste","Realiste","Optimiste"},0)),DCF!D66)} -> 0.08 | F12: {=IFERROR(INDEX(SECTOR_REF!$C$2:$E$71,MATCH(1,(SECTOR_REF!$A$2:$A$71=INPUT!$D$116)*(SECTOR_REF!$B$2:$B$71="WACC"),0),MATCH("Optimiste",{"Pessimiste","Realiste","Optimiste"},0)),DCF!D66-0.015)} -> 0.07
B13: ▶ Secteur actif : | D13: =IF(INPUT!$D$116="","— Aucun secteur sélectionné (INPUT!D116) —",INPUT!$D$116) -> Energie / Oil & Gas
B14: SCENARIO RESULTS — DYNAMIC VIEW
B15: METRIC | D15: =TEXT(INPUT!D117-3,"0") -> 2022 | E15: =TEXT(INPUT!D117-2,"0") -> 2023 | F15: =TEXT(INPUT!D117-1,"0") -> 2024 | G15: =INPUT!D117&" (LTM)" -> 2025 (LTM) | H15: =TEXT(INPUT!D117+1,"0")&"F" -> 2026F | I15: =TEXT(INPUT!D117+2,"0")&"F" -> 2027F | J15: =TEXT(INPUT!D117+3,"0")&"F" -> 2028F | K15: =TEXT(INPUT!D117+4,"0")&"F" -> 2029F | L15: =TEXT(INPUT!D117+5,"0")&"F" -> 2030F
B16: Revenue | D16: =INPUT!E9 -> 263310 | E16: =INPUT!F9 -> 218945 | F16: =INPUT!G9 -> 195610 | G16: =INPUT!H9 -> 182344 | H16: =INPUT!H9*(1+IF($D$6="Pessimistic",$D$8,IF($D$6="Realistic",$E$8,$F$8))) -> 185990.88 | I16: =H16*(1+IF($D$6="Pessimistic",$D$8,IF($D$6="Realistic",$E$8,$F$8))) -> 189710.7 | J16: =I16*(1+IF($D$6="Pessimistic",$D$8,IF($D$6="Realistic",$E$8,$F$8))) -> 193504.91 | K16: =J16*(1+IF($D$6="Pessimistic",$D$8,IF($D$6="Realistic",$E$8,$F$8))) -> 197375.01 | L16: =K16*(1+IF($D$6="Pessimistic",$D$8,IF($D$6="Realistic",$E$8,$F$8))) -> 201322.51
B17: Gross Profit | D17: =INPUT!E11 -> 81211 | E17: =INPUT!F11 -> 62373 | F17: =INPUT!G11 -> 55532 | G17: =INPUT!H11 -> 51847 | H17: =H16*IF($D$6="Pessimistic",$D$9,IF($D$6="Realistic",$E$9,$F$9)) -> 52883.94 | I17: =I16*IF($D$6="Pessimistic",$D$9,IF($D$6="Realistic",$E$9,$F$9)) -> 53941.619 | J17: =J16*IF($D$6="Pessimistic",$D$9,IF($D$6="Realistic",$E$9,$F$9)) -> 55020.451 | K17: =K16*IF($D$6="Pessimistic",$D$9,IF($D$6="Realistic",$E$9,$F$9)) -> 56120.86 | L17: =L16*IF($D$6="Pessimistic",$D$9,IF($D$6="Realistic",$E$9,$F$9)) -> 57243.277
B18: EBITDA (EBITDAX) | D18: =INPUT!E30 -> 74190 | E18: =INPUT!F30 -> 53604 | F18: =INPUT!G30 -> 45842 | G18: =INPUT!H30 -> 39602 | H18: =H16*IF($D$6="Pessimistic",$D$10,IF($D$6="Realistic",$E$10,$F$10)) -> 40917.994 | I18: =I16*IF($D$6="Pessimistic",$D$10,IF($D$6="Realistic",$E$10,$F$10)) -> 41736.353 | J18: =J16*IF($D$6="Pessimistic",$D$10,IF($D$6="Realistic",$E$10,$F$10)) -> 42571.081 | K18: =K16*IF($D$6="Pessimistic",$D$10,IF($D$6="Realistic",$E$10,$F$10)) -> 43422.502 | L18: =L16*IF($D$6="Pessimistic",$D$10,IF($D$6="Realistic",$E$10,$F$10)) -> 44290.952
B19: Net Income | D19: =INPUT!E26 -> 35746 | E19: =INPUT!F26 -> 24311 | F19: =INPUT!G26 -> 19294 | G19: =INPUT!H26 -> 14932 | H19: =H18*0.6 -> 24550.796 | I19: =I18*0.6 -> 25041.812 | J19: =J18*0.6 -> 25542.648 | K19: =K18*0.6 -> 26053.501 | L19: =L18*0.6 -> 26574.571
B20: Free Cash Flow (Est.) | D20: =IFERROR(INPUT!E75+INPUT!E78,"–") -> 38882 | E20: =IFERROR(INPUT!F75+INPUT!F78,"–") -> 12888 | F20: =IFERROR(INPUT!G75+INPUT!G78,"–") -> 23947 | G20: =IFERROR(INPUT!H75+INPUT!H78,"–") -> 10266 | H20: =H18*0.5 -> 20458.997 | I20: =I18*0.5 -> 20868.177 | J20: =J18*0.5 -> 21285.54 | K20: =K18*0.5 -> 21711.251 | L20: =L18*0.5 -> 22145.476
B21: EBITDA Margin | D21: =IFERROR(INPUT!E30/INPUT!E9,"–") -> 0.28175914 | E21: =IFERROR(INPUT!F30/INPUT!F9,"–") -> 0.24482861 | F21: =IFERROR(INPUT!G30/INPUT!G9,"–") -> 0.23435407 | G21: =IFERROR(INPUT!H30/INPUT!H9,"–") -> 0.21718291 | H21: =IFERROR(H18/H16,"–") -> 0.22 | I21: =IFERROR(I18/I16,"–") -> 0.22 | J21: =IFERROR(J18/J16,"–") -> 0.22 | K21: =IFERROR(K18/K16,"–") -> 0.22 | L21: =IFERROR(L18/L16,"–") -> 0.22
B22: Implied Share Price | M22: =IFERROR("$"&TEXT(IF($D$6="Pessimistic",DCF!D94*(1+$D$8+$D$10-$E$8-$E$10)*0.8,IF($D$6="Realistic",DCF!D94,DCF!D94*(1+$F$8+$F$10-$E$8-$E$10)*1.2)),"#,##0.00"),"–") -> $145,428.36
B24: SCENARIO SUMMARY COMPARISON
B25: METRIC (Year 5) | D25: Pessimistic | E25: Realistic | F25: Optimistic
B26: Revenue (Year 5) | C26: 0 | D26: =INPUT!H9*(1+$D$8)^5 -> 141094.31 | E26: =INPUT!H9*(1+$E$8)^5 -> 201322.51 | F26: =INPUT!H9*(1+$F$8)^5 -> 244017.4
B27: EBITDA (Year 5) | C27: 0 | D27: =D26*$D$10 -> 21164.147 | E27: =E26*$E$10 -> 44290.952 | F27: =F26*$F$10 -> 68324.873
B28: Net Income (Year 5) | C28: 0 | D28: =D27*0.6 -> 12698.488 | E28: =E27*0.6 -> 26574.571 | F28: =F27*0.6 -> 40994.924
B29: FCF (Year 5) | C29: 0 | D29: =D27*0.5 -> 10582.073 | E29: =E27*0.5 -> 22145.476 | F29: =F27*0.5 -> 34162.437
B30: EBITDA Margin (Year 5) | D30: =$D$10 -> 0.15 | E30: =$E$10 -> 0.22 | F30: =$F$10 -> 0.28
B31: Implied Share Price | D31: =IFERROR("$"&TEXT(DCF!D94*(1+$D$8+$D$10-$E$8-$E$10)*0.8,"#,##0.00"),"–") -> $100,054.71 | E31: =IFERROR("$"&TEXT(DCF!D94,"#,##0.00"),"–") -> $145,428.36 | F31: =IFERROR("$"&TEXT(DCF!D94*(1+$F$8+$F$10-$E$8-$E$10)*1.2,"#,##0.00"),"–") -> $191,965.43
B32: Delta (Opt. vs Pess.) | D32: ="—" -> — | E32: ="—" -> — | F32: =IFERROR(F26/D26-1,"–") -> 0.7294631
B33: Revenue
B34: ="▶ SCÉNARIO SÉLECTIONNÉ : "&$D$6 -> ▶ SCÉNARIO SÉLECTIONNÉ : Realistic
B36: CHART DATA: Revenue by Scenario
B37: Year | D37: =TEXT(INPUT!D117+1,"0")&"F" -> 2026F | E37: =TEXT(INPUT!D117+2,"0")&"F" -> 2027F | F37: =TEXT(INPUT!D117+3,"0")&"F" -> 2028F | G37: =TEXT(INPUT!D117+4,"0")&"F" -> 2029F | H37: =TEXT(INPUT!D117+5,"0")&"F" -> 2030F
B38: Pessimistic | D38: =IF(INPUT!H9="",NA(),INPUT!H9*(1+$D$8)) -> 173226.8 | E38: =IF(INPUT!H9="",NA(),D38*(1+$D$8)) -> 164565.46 | F38: =IF(INPUT!H9="",NA(),E38*(1+$D$8)) -> 156337.19 | G38: =IF(INPUT!H9="",NA(),F38*(1+$D$8)) -> 148520.33 | H38: =IF(INPUT!H9="",NA(),G38*(1+$D$8)) -> 141094.31
B39: Realistic | D39: =IF(INPUT!H9="",NA(),INPUT!H9*(1+$E$8)) -> 185990.88 | E39: =IF(INPUT!H9="",NA(),D39*(1+$E$8)) -> 189710.7 | F39: =IF(INPUT!H9="",NA(),E39*(1+$E$8)) -> 193504.91 | G39: =IF(INPUT!H9="",NA(),F39*(1+$E$8)) -> 197375.01 | H39: =IF(INPUT!H9="",NA(),G39*(1+$E$8)) -> 201322.51
B40: Optimistic | D40: =IF(INPUT!H9="",NA(),INPUT!H9*(1+$F$8)) -> 193284.64 | E40: =IF(INPUT!H9="",NA(),D40*(1+$F$8)) -> 204881.72 | F40: =IF(INPUT!H9="",NA(),E40*(1+$F$8)) -> 217174.62 | G40: =IF(INPUT!H9="",NA(),F40*(1+$F$8)) -> 230205.1 | H40: =IF(INPUT!H9="",NA(),G40*(1+$F$8)) -> 244017.4
B41: SCENARIO SUMMARY COMPARISON
B42: CHART DATA: EBITDA by Scenario
B43: Year | D43: =TEXT(INPUT!D117+1,"0")&"F" -> 2026F | E43: =TEXT(INPUT!D117+2,"0")&"F" -> 2027F | F43: =TEXT(INPUT!D117+3,"0")&"F" -> 2028F | G43: =TEXT(INPUT!D117+4,"0")&"F" -> 2029F | H43: =TEXT(INPUT!D117+5,"0")&"F" -> 2030F
...

Sheet DASHBOARD
B1: FinSight | Q1: Année | R1: 2022 | S1: 2023 | T1: 2024
Q2: Année | R2: Cumul Revenue | S2: =RATIOS!F80 -> 677865 | T2: =RATIOS!G80 -> 677865
B3: Financial Performance | Q3: 2022 | R3: =RATIOS!E80 -> 482255
B4: ="All figures in "&INPUT!D118&" "&INPUT!D119&" unless stated" -> All figures in USD M unless stated | Q4: 2023 | R4: =RATIOS!F80 -> 677865
Q5: 2024 | R5: =RATIOS!G80 -> 677865
Q6: Year
B7: Revenue & Profitability | H7: Profit Margins | Q7: 2022 | R7: Revenue | S7: Net Income | T7: Net Margin
Q8: 2023 | R8: =RATIOS!E77 -> 263310 | S8: =RATIOS!E79 -> 24311 | T8: =RATIOS!E84 -> 0.13575633
Q9: 2024 | R9: =RATIOS!F77 -> 218945 | S9: =RATIOS!F79 -> 19294 | T9: =RATIOS!F84 -> 0.11103702
Q10: 2025 (LTM) | R10: =RATIOS!G77 -> 195610 | S10: =RATIOS!G79 -> 19294 | T10: =RATIOS!G84 -> 0.098635039
R11: =RATIOS!H77 -> 182344 | S11: =RATIOS!H79 -> 14932 | T11: =RATIOS!H84 -> 0.081889177
B24: Cumulative revenue | H24: Expense Breakdown
B41: Performance Summary (Five-Year) | H41: Income Statement (LTM)
C43: 5-Yr Avg | D43: Trend | I43: Actual | J43: Prev Year | K43: Variance | L43: Var %
B44: Revenue | C44: =AVERAGE(INPUT!D9:H9) -> 215052.25 | D44: =IF(INPUT!H9>INPUT!G9,"▲",IF(INPUT!H9<INPUT!G9,"▼","→")) -> ▼ | H44: Revenue | I44: =INPUT!H9 -> 182344 | J44: =INPUT!G9 -> 195610 | K44: =I44-J44 -> -13266 | L44: =IF(J44=0,NA(),K44/ABS(J44)) -> -0.067818619
B46: COGS | C46: =ABS(AVERAGE(INPUT!D10:H10)) -> 152311.5 | D46: =IF(ABS(INPUT!H10)<ABS(INPUT!G10),"▲",IF(ABS(INPUT!H10)>ABS(INPUT!G10),"▼","→")) -> ▲ | H46: COGS | I46: =ABS(INPUT!H10) -> 130497 | J46: =ABS(INPUT!G10) -> 140078 | K46: =I46-J46 -> -9581 | L46: =IF(J46=0,NA(),K46/ABS(J46)) -> -0.068397607
B48: Expenses | C48: =ABS(AVERAGE(INPUT!D13:H13)) -> 18435.4 | D48: =IF(ABS(INPUT!H13)<ABS(INPUT!G13),"▲",IF(ABS(INPUT!H13)>ABS(INPUT!G13),"▼","→")) -> ▼ | H48: Expenses | I48: =ABS(INPUT!H13) -> 26092 | J48: =ABS(INPUT!G13) -> 22797 | K48: =I48-J48 -> 3295 | L48: =IF(J48=0,NA(),K48/ABS(J48)) -> 0.14453656
B50: Net Income | C50: =AVERAGE(INPUT!D26:H26) -> 18856.6 | D50: =IF(INPUT!H26>INPUT!G26,"▲",IF(INPUT!H26<INPUT!G26,"▼","→")) -> ▼ | H50: Net Income | I50: =INPUT!H26 -> 14932 | J50: =INPUT!G26 -> 19294 | K50: =I50-J50 -> -4362 | L50: =IF(J50=0,NA(),K50/ABS(J50)) -> -0.22608065
B52: Net Margin (%) | C52: =AVERAGE(INPUT!D26:H26)/AVERAGE(INPUT!D9:H9) -> 0.087683807 | D52: =IF(INPUT!H26/INPUT!H9>INPUT!G26/INPUT!G9,"▲",IF(INPUT!H26/INPUT!H9<INPUT!G26/INPUT!G9,"▼","→")) -> ▼ | H52: Net Margin (%) | I52: =INPUT!H26/INPUT!H9 -> 0.081889177 | J52: =INPUT!G26/INPUT!G9 -> 0.098635039 | K52: =I52-J52 -> -0.016745863 | L52: =IF(J52=0,NA(),K52/ABS(J52)) -> -0.169776
B54: OIL & GAS KPIs (LTM)
B55: EV/DACF | C55: =IFERROR(INPUT!H98/(INPUT!H75+ABS(INPUT!H20)*(1-INPUT!H104)),"–") -> 6.9386674 | D55: Bmk: 5-8x • FCF Yield: | E55: =IFERROR((INPUT!H75+INPUT!H78)/INPUT!H97,"–") -> 0.061947082
B56: Net Debt/EBITDAX | C56: =IFERROR((INPUT!H49+INPUT!H55-INPUT!H34)/(INPUT!H30+ABS(INPUT!H15)),"–") -> 2.6264751 | D56: =IFERROR(IF((INPUT!H49+INPUT!H55-INPUT!H34)/(INPUT!H30+ABS(INPUT!H15))>2.5,"⚠️ Levier élevé (>2.5x)",IF((INPUT!H49+INPUT!H55-INPUT!H34)/(INPUT!H30+ABS(INPUT!H15))>1.5,"🟡 Levier modéré (1.5-2.5x)","✅ Levier faible (<1.5x)")),"–") -> ⚠️ Levier élevé (>2.5x)
B58: P&L Summary (LTM) | H58: Balance Sheet Summary (LTM)
D60: =INPUT!G5 -> 2024 | E60: =INPUT!H5 -> 2025 (LTM) | J60: =INPUT!G5 -> 2024 | K60: =INPUT!H5 -> 2025 (LTM) | S60: =INPUT!G9 -> 195610 | T60: =INPUT!H9 -> 182344
H61: Assets
B62: COGS | D62: =-ABS(INPUT!G10) -> -140078 | E62: =-ABS(INPUT!H10) -> -130497 | H62: Current Assets | J62: =INPUT!G38 -> 64064 | K62: =INPUT!H38 -> 59479
B63: Gross Profit | D63: =S60+D62 -> 55532 | E63: =T60+E62 -> 51847 | H63: Non-current Assets | J63: =SUM(INPUT!G41:G43) -> 143487 | K63: =SUM(INPUT!H41:H43) -> 152327
B64: SG&A | D64: =-ABS(INPUT!G14) -> -5150 | E64: =-ABS(INPUT!H14) -> -5834
B65: R&D | D65: =-ABS(INPUT!G15) -> -4540 | E65: =-ABS(INPUT!H15) -> -6411 | H65: Total Assets | J65: =INPUT!G44 -> 207551 | K65: =INPUT!H44 -> 211806
B66: D&A | D66: =-ABS(INPUT!G16) -> -13107 | E66: =-ABS(INPUT!H16) -> -13847
B67: EBIT (Operating Profit) | D67: =D63+D64+D65+D66 -> 32735 | E67: =E63+E64+E65+E66 -> 25755 | H67: Liabilities
B68: Net Interest | D68: =-ABS(INPUT!G20) -> -2364 | E68: =-ABS(INPUT!H20) -> -2558 | H68: Current Liabilities | J68: =INPUT!G51 -> 82707 | K68: =INPUT!H51 -> 86544
B69: EBT (Pre-Tax Income) | D69: =D67+D68 -> 30371 | E69: =E67+E68 -> 23197 | H69: Long-term Liabilities | J69: =INPUT!G54 -> 41220 | K69: =INPUT!H54 -> 48033
B70: Income Tax | D70: =-ABS(INPUT!G21) -> -1786 | E70: =-ABS(INPUT!H21) -> -1115 | H70: Total Liabilities | J70: =INPUT!G55 -> 123927 | K70: =INPUT!H55 -> 134577
B71: Net Income | D71: =D69+D70 -> 28585 | E71: =E69+E70 -> 22082 | H71: Shareholders' Equity | J71: =INPUT!G60 -> 178282 | K71: =INPUT!H60 -> 171922
B72: EBITDA | D72: =D67+ABS(D66) -> 45842 | E72: =E67+ABS(E66) -> 39602 | H72: Total Liabilities & Equity | J72: =INPUT!G63 -> 302209 | K72: =INPUT!H63 -> 306499
G82: =INPUT!H5 -> 2025 (LTM) | I82: =IF(INPUT!D5="",NA(),INPUT!D5) -> #N/A | J82: =INPUT!E5 -> 2022 | K82: =INPUT!F5 -> 2023 | L82: =INPUT!G5 -> 2024 | M82: =INPUT!H5 -> 2025 (LTM)
G83: =IF(INPUT!H9="",NA(),INPUT!H9) -> 182344
C84: =IF(INPUT!D5="",NA(),INPUT!D5) -> #N/A | D84: =INPUT!E5 -> 2022 | E84: =INPUT!F5 -> 2023 | F84: =INPUT!G5 -> 2024 | G84: =IF(INPUT!G30="",NA(),INPUT!G30) -> 45842 | H84: =IF(INPUT!H30="",NA(),INPUT!H30) -> 39602
B85: Revenue | C85: =IF(INPUT!D9="",NA(),INPUT!D9) -> #N/A | D85: =IF(INPUT!E9="",NA(),INPUT!E9) -> 263310 | E85: =IF(INPUT!F9="",NA(),INPUT!F9) -> 218945 | F85: =IF(INPUT!G9="",NA(),INPUT!G9) -> 195610 | G85: =IF(INPUT!G26="",NA(),INPUT!G26) -> 19294 | H85: =IF(INPUT!H26="",NA(),INPUT!H26) -> 14932
...

Sheet DASHBOARD 2
B1: FinSight | R1: =INPUT!D114&" ("&INPUT!D115&") — "&INPUT!D116 -> TTE.PA (TTE.PA) — Energie / Oil & Gas
B3: Projected Business Performance | F3: Football Field Chart — Valuation Inputs | M3: Financial Data — Multi-Year
B5: All figures in USD Thousands unless stated | I5: Low ($) | J5: Delta ($) | K5: High ($) | M5: All figures in USD Thousands unless stated | P5: =INPUT!E5 -> 2022 | Q5: =INPUT!F5 -> 2023 | R5: =INPUT!G5 -> 2024 | S5: =INPUT!H5 -> 2025 (LTM)
B6: Company Information | F6: 52-Week Trading Range | I6: =INPUT!H95*0.75 -> 58.2675 | J6: =K6-I6 -> 54.383 | K6: =INPUT!H95*1.45 -> 112.6505
C7: Company Name | D7: =INPUT!D114 -> TTE.PA | F7: Consensus Research | I7: =INPUT!H95*1.1 -> 85.459 | J7: =K7-I7 -> 38.845 | K7: =INPUT!H95*1.6 -> 124.304 | M7: Revenue Growth (%) | P7: =IF(INPUT!D9=0,"",INPUT!E9/INPUT!D9-1) | Q7: =IF(INPUT!E9=0,"",INPUT!F9/INPUT!E9-1) -> -0.16848961 | R7: =IF(INPUT!F9=0,"",INPUT!G9/INPUT!F9-1) -> -0.10657928 | S7: =IF(INPUT!G9=0,"",INPUT!H9/INPUT!G9-1) -> -0.067818619
C8: Ticker Symbol | D8: =INPUT!D115 -> TTE.PA | F8: Precedent Transactions | I8: =INPUT!H95*1.2 -> 93.228 | J8: =K8-I8 -> 42.7295 | K8: =INPUT!H95*1.75 -> 135.9575 | M8: EBITDA Growth (%) | P8: ="" | Q8: =IF(INPUT!D30=0,"",INPUT!F30/INPUT!E30-1) | R8: =IF(INPUT!E30=0,"",INPUT!G30/INPUT!F30-1) -> -0.14480263 | S8: =IF(INPUT!F30=0,"",INPUT!H30/INPUT!G30-1) -> -0.13611972
C9: Sector | D9: =INPUT!D116 -> Energie / Oil & Gas | F9: Sum-of-the-Parts | I9: =INPUT!H95*1.3 -> 100.997 | J9: =K9-I9 -> 42.7295 | K9: =INPUT!H95*1.85 -> 143.7265
C10: Base Year (LTM) | D10: =INPUT!D117 -> 2025 | F10: Discounted Cash Flow | I10: =INPUT!H95*1.15 -> 89.3435 | J10: =K10-I10 -> 42.7295 | K10: =INPUT!H95*1.7 -> 132.073 | M10: Revenue
C11: Currency | D11: =INPUT!D118 -> USD | F11: Current Share Price | I11: =INPUT!H95 -> 77.69 | M11: Revenue — Products | P11: =INPUT!E9 -> 263310 | Q11: =INPUT!E9 -> 263310 | R11: =INPUT!F9 -> 218945 | S11: =INPUT!G9 -> 195610 | T11: =INPUT!H9 -> 182344
C12: Analysis Date | D12: =INPUT!D120 -> 2026-04-15 | M12: Cost of Revenue (COGS) | P12: =ABS(INPUT!E10) -> 182099 | Q12: =ABS(INPUT!E10) -> 182099 | R12: =ABS(INPUT!F10) -> 156572 | S12: =ABS(INPUT!G10) -> 140078 | T12: =ABS(INPUT!H10) -> 130497
M13: Gross Profit | P13: =INPUT!E11 -> 81211 | Q13: =INPUT!E11 -> 81211 | R13: =INPUT!F11 -> 62373 | S13: =INPUT!G11 -> 55532 | T13: =INPUT!H11 -> 51847
M14: SG&A | P14: =ABS(INPUT!E14) -> 3946 | Q14: =ABS(INPUT!E14) -> 3946 | R14: =ABS(INPUT!F14) -> 4800 | S14: =ABS(INPUT!G14) -> 5150 | T14: =ABS(INPUT!H14) -> 5834
M15: Total Revenue | P15: =INPUT!E9 -> 263310 | Q15: =INPUT!E9 -> 263310 | R15: =INPUT!F9 -> 218945 | S15: =INPUT!G9 -> 195610 | T15: =INPUT!H9 -> 182344
M17: EBITDA | P17: =INPUT!E30 -> 74190 | Q17: =INPUT!E30 -> 74190 | R17: =INPUT!F30 -> 53604 | S17: =INPUT!G30 -> 45842 | T17: =INPUT!H30 -> 39602
M18: Cash from Ops (CFO) | P18: =INPUT!E75 -> 54572 | Q18: =INPUT!E75 -> 54572 | R18: =INPUT!F75 -> 30610 | S18: =INPUT!G75 -> 38856 | T18: =INPUT!H75 -> 27219
M19: Net Income | P19: =INPUT!E26 -> 35746 | Q19: =INPUT!E26 -> 35746 | R19: =INPUT!F26 -> 24311 | S19: =INPUT!G26 -> 19294 | T19: =INPUT!H26 -> 14932
B22: Stock Chart: Trailing 52-Weeks | I22: Valuation Summary: Football Field Chart | P22: Other Financial Metrics ($ Millier)
B42: Total Revenue ($M)
V84: Low | W84: Delta | X84: High
S85: 52-Week Trading Range | V85: =I6 -> 58.2675 | W85: =J6 -> 54.383 | X85: =K6 -> 112.6505
S86: Consensus Research | V86: =I7 -> 85.459 | W86: =J7 -> 38.845 | X86: =K7 -> 124.304
S87: Precedent Trans. | V87: =I8 -> 93.228 | W87: =J8 -> 42.7295 | X87: =K8 -> 135.9575
S88: Sum-of-the-Parts | V88: =I9 -> 100.997 | W88: =J9 -> 42.7295 | X88: =K9 -> 143.7265
S89: Discounted Cash Flow | V89: =I10 -> 89.3435 | W89: =J10 -> 42.7295 | X89: =K10 -> 132.073
Q92: =K104 -> 2022 | R92: =L104 -> 2023 | S92: =M103 -> 2024 | T92: =N103 -> 2025 (LTM)
Q93: =IF(INPUT!E9="",NA(),INPUT!E30/1000) -> 74.19 | R93: =IF(INPUT!F9="",NA(),INPUT!F30/1000) -> 53.604 | S93: =IF(INPUT!G9="",NA(),INPUT!G30/1000) -> 45.842 | T93: =IF(INPUT!H9="",NA(),INPUT!H30/1000) -> 39.602
Q94: =IF(INPUT!E9="",NA(),INPUT!E75/1000) -> 54.572 | R94: =IF(INPUT!F9="",NA(),INPUT!F75/1000) -> 30.61 | S94: =IF(INPUT!G9="",NA(),INPUT!G75/1000) -> 38.856 | T94: =IF(INPUT!H9="",NA(),INPUT!H75/1000) -> 27.219
Q95: =IF(INPUT!E9="",NA(),INPUT!E26/1000) -> 35.746 | S95: 2022 | T95: 2023 | U95: 2024 | V95: 2025 (LTM)
R96: EBITDA | S96: =Q17 -> 74190 | T96: =R17 -> 53604 | U96: =S17 -> 45842 | V96: =T17 -> 39602
R97: CFO | S97: =Q18 -> 54572 | T97: =R18 -> 30610 | U97: =S18 -> 38856 | V97: =T18 -> 27219
R98: Net Income | S98: =Q19 -> 35746 | T98: =R19 -> 24311 | U98: =S19 -> 19294 | V98: =T19 -> 14932
A101: Revenue
M103: =IF(INPUT!G9="",NA(),'DASHBOARD 2'!R5) -> 2024 | N103: =IF(INPUT!H9="",NA(),'DASHBOARD 2'!S5) -> 2025 (LTM) | P103: =J104
I104: Year | J104: =IF(INPUT!D9="","",INPUT!D5) | K104: =IF(INPUT!E9="",NA(),'DASHBOARD 2'!P5) -> 2022 | L104: =IF(INPUT!F9="",NA(),'DASHBOARD 2'!Q5) -> 2023 | M104: =IF(INPUT!G9="",NA(),INPUT!G30) -> 45842 | N104: =IF(INPUT!H9="",NA(),INPUT!H30) -> 39602 | P104: =IF(INPUT!D9="",NA(),INPUT!D30/1000) -> #N/A
I105: EBITDA ($M) | J105: =IF(INPUT!D9="","",INPUT!D30) | K105: =IF(INPUT!E9="",NA(),INPUT!E30) -> 74190 | L105: =IF(INPUT!F9="",NA(),INPUT!F30) -> 53604 | M105: =IF(INPUT!G9="",NA(),INPUT!G75) -> 38856 | N105: =IF(INPUT!H9="",NA(),INPUT!H75) -> 27219 | P105: =IF(INPUT!D9="",NA(),INPUT!D75/1000) -> #N/A
B106: Year | C106: =IF(INPUT!D9="","",INPUT!D5) | D106: =IF(INPUT!E9="",NA(),'DASHBOARD 2'!P5) -> 2022 | E106: =IF(INPUT!F9="",NA(),'DASHBOARD 2'!Q5) -> 2023 | F106: =IF(INPUT!G9="",NA(),'DASHBOARD 2'!R5) -> 2024 | G106: =IF(INPUT!H9="",NA(),'DASHBOARD 2'!S5) -> 2025 (LTM) | I106: CFO ($M) | J106: =IF(INPUT!D9="","",INPUT!D75) | K106: =IF(INPUT!E9="",NA(),INPUT!E75) -> 54572 | L106: =IF(INPUT!F9="",NA(),INPUT!F75) -> 30610 | M106: =IF(INPUT!G9="",NA(),INPUT!G26) -> 19294 | N106: =IF(INPUT!H9="",NA(),INPUT!H26) -> 14932 | P106: =IF(INPUT!D9="",NA(),INPUT!D26/1000) -> #N/A
B107: Revenue Growth (%) | C107: ="" | D107: =IF(INPUT!E9="",NA(),'DASHBOARD 2'!P7) | E107: =IF(INPUT!F9="",NA(),'DASHBOARD 2'!Q7) -> -0.16848961 | F107: =IF(INPUT!G9="",NA(),'DASHBOARD 2'!R7) -> -0.10657928 | G107: =IF(INPUT!H9="",NA(),'DASHBOARD 2'!S7) -> -0.067818619 | I107: Net Income ($M) | J107: =IF(INPUT!D9="","",INPUT!D26) | K107: =IF(INPUT!E9="",NA(),INPUT!E26) -> 35746 | L107: =IF(INPUT!F9="",NA(),INPUT!F26) -> 24311
B108: Total Revenue ($M) | C108: =IF(INPUT!D9="","",INPUT!D9) | D108: =IF(INPUT!E9="",NA(),INPUT!E9) -> 263310 | E108: =IF(INPUT!F9="",NA(),INPUT!F9) -> 218945 | F108: =IF(INPUT!G9="",NA(),INPUT!G9) -> 195610 | G108: =IF(INPUT!H9="",NA(),INPUT!H9) -> 182344

Sheet STOCK_DATA
A1: STOCK_DATA — Apple Inc. (AAPL) — Trailing 52 Weeks
A2: # | B2: Month | C2: Close Price ($)
A3: 1 | B3: May-25 | C3: 48.75
A4: 2 | B4: Jun-25 | C4: 49.16
A5: 3 | B5: Jul-25 | C5: 49.87
A6: 4 | B6: Aug-25 | C6: 51.28
A7: 5 | B7: Sep-25 | C7: 49.59
A8: 6 | B8: Oct-25 | C8: 51.72
A9: 7 | B9: Nov-25 | C9: 55.36
A10: 8 | B10: Dec-25 | C10: 54.18
A11: 9 | B11: Jan-26 | C11: 60.51
A12: 10 | B12: Feb-26 | C12: 66.57
A13: 11 | B13: Mar-26 | C13: 80.06
A14: 12 | B14: Apr-26 | C14: 77.69
A15: 13
A17: ⚠️ Données simulées. Remplacer par données réelles (Bloomberg/FactSet) en colonne B (Mois) et C (Prix).

Sheet SECTOR_REF
A1: 0.08 | B1: Driver | C1: Pessimiste | D1: Realiste | E1: Optimiste
A2: Technologie / SaaS | B2: Revenue Growth Rate (Y1-Y5) | C2: 0.05 | D2: 0.12 | E2: 0.22
A3: Technologie / SaaS | B3: Gross Margin | C3: 0.55 | D3: 0.68 | E3: 0.78
A4: Technologie / SaaS | B4: EBITDA Margin | C4: 0.08 | D4: 0.18 | E4: 0.28
A5: Technologie / SaaS | B5: SG&A (% Revenue) | C5: 0.3 | D5: 0.22 | E5: 0.15
A6: Technologie / SaaS | B6: R&D (% Revenue) | C6: 0.18 | D6: 0.12 | E6: 0.08
A7: Technologie / SaaS | B7: CapEx (% Revenue) | C7: 0.08 | D7: 0.05 | E7: 0.03
A8: Technologie / SaaS | B8: Change in NWC (% Rev Change) | C8: 0.05 | D8: 0.03 | E8: 0.02
A9: Technologie / SaaS | B9: Terminal Growth Rate | C9: 0.02 | D9: 0.03 | E9: 0.04
A10: Technologie / SaaS | B10: WACC | C10: 0.11 | D10: 0.09 | E10: 0.07
A11: Technologie / SaaS | B11: EV/EBITDA Exit Multiple | C11: 12 | D11: 16 | E11: 22
A12: Industrie / Manufacturing | B12: Revenue Growth Rate (Y1-Y5) | C12: 0.01 | D12: 0.04 | E12: 0.07
A13: Industrie / Manufacturing | B13: Gross Margin | C13: 0.18 | D13: 0.25 | E13: 0.32
... A71: Energie / Oil & Gas | B71: EV/EBITDA Exit Multiple | C71: 4 | D71: 6 | E71: 8
