Workbook

Sheet INPUT
B1: FinSight
B3: INPUT — Raw Data
B4: All figures in USD millions unless stated
B5: METRIC | C5: UNIT | E5: 2022 | F5: 2023 | G5: 2024 | H5: 2025 (LTM)
B7: INPUT
B9: Revenue | C9: ($M) | E9: 127727 | F9: 154952 | G9: 169439 | H9: 181847
B10: Cost of Goods Sold (COGS) | C10: ($M) | E10: -60609 | F10: -79113 | G10: -80240 | H10: -77733
B11: Gross Profit | C11: ($M) | D11: =D9+D10 -> 0 | E11: =E9+E10 -> 67118 | F11: =F9+F10 -> 75839 | G11: =G9+G10 -> 89199 | H11: =H9+H10 -> 104114
D13: =SUM(D14:D16) -> 0 | E13: =SUM(E14:E16) -> -55673 | F13: =SUM(F14:F16) -> -62537 | G13: =SUM(G14:G16) -> -68809 | H13: =SUM(H14:H16) -> -75250
B14: Operating Expenses (SG&A) | C14: ($M) | E14: -45547 | F14: -51056 | G14: -56331 | H14: -60018
B15: Research & Development | C15: ($M) | E15: -3075 | F15: -3969 | G15: -4540 | H15: -6411
B16: Depreciation & Amortization | C16: ($M) | E16: -7051 | F16: -7512 | G16: -7938 | H16: -8821
B17: EBIT (Operating Profit) | C17: ($M) | D17: =D11+D13 -> 0 | E17: =E11+E13 -> 11445 | F17: =F11+F13 -> 13302 | G17: =G11+G13 -> 20390 | H17: =H11+H13 -> 28864
D19: =D17+D20+D21 -> 0 | E19: =E17+E20+E21 -> 78155 | F19: =F17+F20+F21 -> 102569 | G19: =G17+G20+G21 -> 112973 | H19: =H17+H20+H21 -> 124307
B20: Interest Expense | C20: ($M) | E20: -26097 | F20: -81321 | G20: -101350 | H20: -97898
B21: Interest Income | C21: ($M) | E21: 92807 | F21: 170588 | G21: 193933 | H21: 193341
B22: Earnings Before Tax (EBT) | C22: ($M) | D22: =D19 -> 0 | E22: =E19 -> 78155 | F22: =F19 -> 102569 | G22: =G19 -> 112973 | H22: =H19 -> 124307
D24: =-ROUND(D22*0.21,0) -> 0 | E24: =-ROUND(E22*E104,0) -> -14373 | F24: =-ROUND(F22*F104,0) -> -20073 | G24: =-ROUND(G22*G104,0) -> -24990 | H24: =-ROUND(H22*H104,0) -> -20250
B25: Income Tax Expense | C25: ($M) | E25: -8490 | F25: -12060 | G25: -16610 | H25: -15547
B26: Net Income | C26: ($M) | D26: =D22+D24 -> 0 | E26: =E22+E24 -> 63782 | F26: =F22+F24 -> 82496 | G26: =G22+G24 -> 87983 | H26: =H22+H24 -> 104057
B29: Common Dividends | C29: ($M) | E29: -3162 | F29: -9824 | G29: -18830 | H29: -31591
B30: EBITDA | C30: ($M) | D30: =D17-D16 -> 0 | E30: =E17-E16 -> 18496 | F30: =F17-F16 -> 20814 | G30: =G17-G16 -> 28328 | H30: =H17-H16 -> 37685
B32: BALANCE SHEET
B34: Cash & Cash Equivalents | C34: ($M) | E34: 567234 | F34: 624151 | G34: 469317 | H34: 343338
B35: Accounts Receivable | C35: ($M) | E35: 125189 | F35: 107363 | G35: 101223 | H35: 111599
B36: Inventories | C36: ($M) | E36: 12839 | F36: 13626 | G36: 12017 | H36: 12392
B37: Other Current Assets | C37: ($M) | E37: 2941 | F37: 3388 | G37: 5362 | H37: 7615
B38: Total Current Assets | C38: ($M) | D38: =SUM(D34:D37) -> 0 | E38: =SUM(E34:E37) -> 708203 | F38: =SUM(F34:F37) -> 748528 | G38: =SUM(G34:G37) -> 587919 | H38: =SUM(H34:H37) -> 474944
B41: PP&E (Net) | C41: ($M) | E41: 27734 | F41: 30157 | G41: 32223 | H41: 36244
B42: Intangible Assets | C42: ($M) | E42: 60859 | F42: 64381 | G42: 64560 | H42: 64458
B43: Other Long-Term Assets | C43: ($M) | E43: 3865 | F43: 4531 | G43: 4215 | H43: 4664
B44: Total Assets | C44: ($M) | D44: =D38+SUM(D41:D43) -> 0 | E44: =E38+SUM(E41:E43) -> 800661 | F44: =F38+SUM(F41:F43) -> 847597 | G44: =G38+SUM(G41:G43) -> 688917 | H44: =H38+SUM(H41:H43) -> 580310
B47: Accounts Payable | C47: ($M) | E47: 188692 | F47: 161960 | G47: 153153 | H47: 186658
B48: Short-Term Debt | C48: ($M) | E48: 44027 | F48: 44712 | G48: 52893 | H48: 66012
B49: Income Tax Payable | C49: ($M) | E49: 1235 | F49: 1204 | G49: 1367 | H49: 1594
B50: Other Current Liabilities | C50: ($M) | E50: 354 | F50: 517 | G50: 1549 | H50: 1932
B51: Total Current Liabilities | C51: ($M) | D51: =SUM(D47:D50) -> 0 | E51: =SUM(E47:E50) -> 234308 | F51: =SUM(F47:F50) -> 208393 | G51: =SUM(G47:G50) -> 208962 | H51: =SUM(H47:H50) -> 256196
B54: Long-Term Debt | C54: ($M) | E54: 295865 | F54: 391825 | G54: 401418 | H54: 433970
B55: Total Liabilities | C55: ($M) | D55: =D51+D54 -> 0 | E55: =E51+E54 -> 530173 | F55: =F51+F54 -> 600218 | G55: =G51+G54 -> 610380 | H55: =H51+H54 -> 690166
B58: Common Equity (Paid-In Capital) | C58: ($M) | E58: 120553 | F58: 121637 | G58: 115066 | H58: 115264
...

Sheet RATIOS
B1: FinSight | G1: RATIOS — Bank Financial Analysis
B2: BANK Profile — JPMorgan Chase & Co. | Financial Services
B3: Key ratios for bank analysis: P/TBV · ROE vs CoE · NIM · CET1 · Cost/Income · Dividend Yield
B4: Note: EV/EBITDA, Debt/EBITDA, Interest Coverage and standard DCF are NOT applicable for banks — see DDM sheet
C5: METRIC | D5: UNIT | E5: 2022 | F5: 2023 | G5: 2024 | H5: 2025 (LTM) | I5: Benchmark Low | J5: Benchmark High
B7: CRITICAL BANK RATIOS
C8: P/TBV (Price / Tangible Book Value) | D8: x | E8: =IFERROR(INPUT!E97/(INPUT!E60-INPUT!E42),"–") -> 5.918714 | F8: =IFERROR(INPUT!F97/(INPUT!F60-INPUT!F42),"–") -> 7.0927216 | G8: =IFERROR(INPUT!G97/(INPUT!G60-INPUT!G42),"–") -> 8.161323 | H8: =IFERROR(INPUT!H97/(INPUT!H60-INPUT!H42),"–") -> 1.7856408 | I8: 0.8 | J8: 1.8
C9: P/E (Price / Earnings) | D9: x | E9: =IFERROR(INPUT!E97/INPUT!E26,"–") -> 33.049293 | F9: =IFERROR(INPUT!F97/INPUT!F26,"–") -> 33.544354 | G9: =IFERROR(INPUT!G97/INPUT!G26,"–") -> 39.578191 | H9: =IFERROR(INPUT!H97/INPUT!H26,"–") -> 8.0114364 | I9: 8 | J9: 14
C10: ROE (Return on Equity) | D10: % | E10: =IFERROR(INPUT!E26/INPUT!E60,"–") -> 0.15295114 | F10: =IFERROR(INPUT!F26/INPUT!F60,"–") -> 0.18149418 | G10: =IFERROR(INPUT!G26/INPUT!G60,"–") -> 0.17910682 | H10: =IFERROR(INPUT!H26/INPUT!H60,"–") -> 0.19584656 | I10: 0.08 | J10: 0.18
C11: NIM (Net Interest Margin) | D11: % | E11: =IFERROR(INPUT!E21/INPUT!E44,"–") -> 0.11591298 | F11: =IFERROR(INPUT!F21/INPUT!F44,"–") -> 0.20126074 | G11: =IFERROR(INPUT!G21/INPUT!G44,"–") -> 0.28150416 | H11: =IFERROR((INPUT!H21+INPUT!H20)/(INPUT!H44*0.65),"–") -> 0.25302922 | J11: 0.04
C12: Cost / Income Ratio | D12: % | E12: =IFERROR(ABS(INPUT!E14+INPUT!E15+INPUT!E16)/(INPUT!E21+ABS(INPUT!E20)),"–") -> 0.46821806 | F12: =IFERROR(ABS(INPUT!F14+INPUT!F15+INPUT!F16)/(INPUT!F21+ABS(INPUT!F20)),"–") -> 0.24825235 | G12: =IFERROR(ABS(INPUT!G14+INPUT!G15+INPUT!G16)/(INPUT!G21+ABS(INPUT!G20)),"–") -> 0.2330273 | H12: =IFERROR(ABS(INPUT!H10)/INPUT!H9,"–") -> 0.42746375 | I12: 0.45 | J12: 0.65
B14: IMPORTANT BANK RATIOS
C15: ROA (Return on Assets) | D15: % | E15: =IFERROR(INPUT!E26/INPUT!E44,"–") -> 0.07966168 | F15: =IFERROR(INPUT!F26/INPUT!F44,"–") -> 0.097329273 | G15: =IFERROR(INPUT!G26/INPUT!G44,"–") -> 0.12771205 | H15: =IFERROR(INPUT!H26/INPUT!H44,"–") -> 0.17931278 | I15: 0.005 | J15: 0.015
C16: Loan / Deposit Ratio | D16: % | E16: =IFERROR(INPUT!E35/INPUT!E47,"–") -> 0.66345685 | F16: =IFERROR(INPUT!F35/INPUT!F47,"–") -> 0.66289825 | G16: =IFERROR(INPUT!G35/INPUT!G47,"–") -> 0.66092731 | H16: =IFERROR(INPUT!H26/INPUT!H44,"–") -> 0.17931278 | I16: 0.6 | J16: 0.85
C17: Dividend Yield | D17: % | E17: =IFERROR(ABS(INPUT!E29)/INPUT!E97,"–") -> 0.0015000356 | F17: =IFERROR(ABS(INPUT!F29)/INPUT!F97,"–") -> 0.0035500628 | G17: =IFERROR(ABS(INPUT!G29)/INPUT!G97,"–") -> 0.0054074886 | H17: =IFERROR(ABS(INPUT!H29)/INPUT!H97,"–") -> 0.03789498 | I17: 0.02 | J17: 0.05
B19: UNIVERSAL RATIOS — All Profiles
C20: Revenue Growth YoY | D20: % | E20: =IFERROR((INPUT!F9-INPUT!E9)/INPUT!E9,"–") -> 0.21314992 | F20: =IFERROR((INPUT!G9-INPUT!F9)/INPUT!F9,"–") -> 0.093493469 | G20: =IFERROR((INPUT!H9-INPUT!G9)/INPUT!G9,"–") -> 0.073229894 | H20: =IFERROR((INPUT!H9-INPUT!G9)/INPUT!G9,"–") -> 0.073229894
C21: Gross Profit Margin | D21: % | E21: =IFERROR(INPUT!F11/INPUT!F9,"–") -> 0.48943544 | F21: =IFERROR(INPUT!G11/INPUT!G9,"–") -> 0.52643724 | G21: =IFERROR(INPUT!H11/INPUT!H9,"–") -> 0.57253625 | H21: =IFERROR(INPUT!H11/INPUT!H9,"–") -> 0.57253625
C22: EBITDA Margin | D22: % | E22: =IFERROR(INPUT!F30/INPUT!F9,"–") -> 0.13432547 | F22: =IFERROR(INPUT!G30/INPUT!G9,"–") -> 0.16718701 | G22: =IFERROR(INPUT!H30/INPUT!H9,"–") -> 0.20723465 | H22: =IFERROR(INPUT!H30/INPUT!H9,"–") -> 0.20723465
C23: Net Profit Margin | D23: % | E23: =IFERROR(INPUT!F26/INPUT!F9,"–") -> 0.53239713 | F23: =IFERROR(INPUT!G26/INPUT!G9,"–") -> 0.51926062 | G23: =IFERROR(INPUT!H26/INPUT!H9,"–") -> 0.5722228 | H23: =IFERROR(INPUT!H26/INPUT!H9,"–") -> 0.5722228
C24: ROE (Return on Equity) | D24: % | E24: =IFERROR(INPUT!F26/INPUT!F60,"–") -> 0.18149418 | F24: =IFERROR(INPUT!G26/INPUT!G60,"–") -> 0.17910682 | G24: =IFERROR(INPUT!H26/INPUT!H60,"–") -> 0.19584656 | H24: =IFERROR(INPUT!H26/INPUT!H60,"–") -> 0.19584656
C25: ROA (Return on Assets) | D25: % | E25: =IFERROR(INPUT!F26/INPUT!F44,"–") -> 0.097329273 | F25: =IFERROR(INPUT!G26/INPUT!G44,"–") -> 0.12771205 | G25: =IFERROR(INPUT!H26/INPUT!H44,"–") -> 0.17931278 | H25: =IFERROR(INPUT!H26/INPUT!H44,"–") -> 0.17931278
C26: Free Cash Flow (FCF) | D26: $M | E26: =INPUT!E75-ABS(INPUT!E78) -> 118895 | F26: =INPUT!F75-ABS(INPUT!F78) -> 81746 | G26: =INPUT!G75-ABS(INPUT!G78) -> 92268 | H26: =INPUT!H75-ABS(INPUT!H78) -> 82804
C27: FCF Margin | D27: % | E27: =IFERROR((INPUT!E75-ABS(INPUT!E78))/INPUT!E9,"–") -> 0.93085252 | F27: =IFERROR((INPUT!F75-ABS(INPUT!F78))/INPUT!F9,"–") -> 0.52755692 | G27: =IFERROR((INPUT!G75-ABS(INPUT!G78))/INPUT!G9,"–") -> 0.54454996 | H27: =IFERROR((INPUT!H75-ABS(INPUT!H78))/INPUT!H9,"–") -> 0.45534983
C28: Debt / Equity | D28: x | E28: =IFERROR((INPUT!E54+INPUT!E48)/INPUT!E60,"–") -> 0.81507114 | F28: =IFERROR((INPUT!F54+INPUT!F48)/INPUT!F60,"–") -> 0.96039715 | G28: =IFERROR((INPUT!G54+INPUT!G48)/INPUT!G60,"–") -> 0.92483999 | H28: =IFERROR((INPUT!H54+INPUT!H48)/INPUT!H60,"–") -> 0.94102037
C29: Net Debt / EBITDA (⚠️ N/A for banks — use P/TBV) | D29: x | E29: =IFERROR((INPUT!E54+INPUT!E48-INPUT!E34)/INPUT!E30,"–") -> -12.291414 | F29: =IFERROR((INPUT!F54+INPUT!F48-INPUT!F34)/INPUT!F30,"–") -> -9.0138368 | G29: =IFERROR((INPUT!G54+INPUT!G48-INPUT!G34)/INPUT!G30,"–") -> -0.52972324 | H29: =IFERROR((INPUT!H54+INPUT!H48-INPUT!H34)/INPUT!H30,"–") -> 4.1566671
C30: Interest Coverage (⚠️ N/A for banks — use NIM) | D30: x | E30: =IFERROR(INPUT!E17/ABS(INPUT!E20),"–") -> 0.43855616 | F30: =IFERROR(INPUT!F17/ABS(INPUT!F20),"–") -> 0.16357398 | G30: =IFERROR(INPUT!G17/ABS(INPUT!G20),"–") -> 0.20118402 | H30: =IFERROR(INPUT!H17/ABS(INPUT!H20),"–") -> 0.29483748
C31: EV / EBITDA | D31: x | E31: =IFERROR(INPUT!E98/INPUT!E30,"–") -> 101.67647 | F31: =IFERROR(INPUT!F98/INPUT!F30,"–") -> 123.93874 | G31: =IFERROR(INPUT!G98/INPUT!G30,"–") -> 122.39487 | H31: =IFERROR(INPUT!H98/INPUT!H30,"–") -> 26.278096
C32: P/E (Price/Earnings) | D32: x | E32: =IFERROR(INPUT!E97/INPUT!E26,"–") -> 33.049293 | F32: =IFERROR(INPUT!F97/INPUT!F26,"–") -> 33.544354 | G32: =IFERROR(INPUT!G97/INPUT!G26,"–") -> 39.578191 | H32: =IFERROR(INPUT!H97/INPUT!H26,"–") -> 8.0114364
C33: EV / Revenue | D33: x | E33: =IFERROR(INPUT!E98/INPUT!E9,"–") -> 14.723653 | F33: =IFERROR(INPUT!F98/INPUT!F9,"–") -> 16.64813 | G33: =IFERROR(INPUT!G98/INPUT!G9,"–") -> 20.462833 | H33: =IFERROR(INPUT!H98/INPUT!H9,"–") -> 5.4457321
B35: ⚠️ BANK PROFILE NOTE
C36: BANK profile active: EV/EBITDA · Net Debt/EBITDA · Interest Coverage · standard DCF are NOT applicable. Applicable models: P/TBV · DDM Gordon Growth · Justified P/B (ROE-g)/(k-g).

Sheet TEXAS RATIO
B1: FinSight | F1: TEXAS RATIO — Bank Credit Stress Indicator
B3: TEXAS RATIO — Bank Credit Stress Indicator
B4: Measures a bank's ability to absorb credit losses: Texas Ratio = Non-Performing Assets / (Tangible Common Equity + Loan Loss Reserves)
B5: COMPONENT | C5: UNIT | E5: =IF(INPUT!E5="","",INPUT!E5) -> 2022 | F5: =IF(INPUT!F5="","",INPUT!F5) -> 2023 | G5: =IF(INPUT!G5="","",INPUT!G5) -> 2024 | H5: =IF(INPUT!H5="","",INPUT!H5) -> 2025 (LTM)
B7: BASE FINANCIAL DATA (from INPUT)
B8: Non-Performing Assets (Loans 90+ days past due + OREO) | C8: $M | E8: =IFERROR(INPUT!E35*0.01,"–") -> 1251.89 | F8: =IFERROR(INPUT!F35*0.01,"–") -> 1073.63 | G8: =IFERROR(INPUT!G35*0.01,"–") -> 1012.23 | H8: =IFERROR(INPUT!H35*0.01,"–") -> 1115.99
B9: Tangible Common Equity (Equity – Intangibles) | C9: $M | E9: =IFERROR(INPUT!E60-INPUT!E42,"–") -> 356150 | F9: =IFERROR(INPUT!F60-INPUT!F42,"–") -> 390157 | G9: =IFERROR(INPUT!G60-INPUT!G42,"–") -> 426672 | H9: =IFERROR(INPUT!H60-INPUT!H42,"–") -> 466861
B10: Loan Loss Reserves (Allowance for Credit Losses) | C10: $M | E10: =IFERROR(INPUT!E35*0.015,"–") -> 1877.835 | F10: =IFERROR(INPUT!F35*0.015,"–") -> 1610.445 | G10: =IFERROR(INPUT!G35*0.015,"–") -> 1518.345 | H10: =IFERROR(INPUT!H35*0.015,"–") -> 1673.985
B11: Total Equity | C11: $M | E11: =INPUT!E60 -> 417009 | F11: =INPUT!F60 -> 454538 | G11: =INPUT!G60 -> 491232 | H11: =INPUT!H60 -> 531319
B12: Intangible Assets | C12: $M | E12: =INPUT!E42 -> 60859 | F12: =INPUT!F42 -> 64381 | G12: =INPUT!G42 -> 64560 | H12: =INPUT!H42 -> 64458
B13: Total Assets | C13: $M | E13: =INPUT!E44 -> 800661 | F13: =INPUT!F44 -> 847597 | G13: =INPUT!G44 -> 688917 | H13: =INPUT!H44 -> 580310
B15: TEXAS RATIO CALCULATION
B16: Numerator: Non-Performing Assets ($M) | C16: $M | E16: =E8 -> 1251.89 | F16: =F8 -> 1073.63 | G16: =G8 -> 1012.23 | H16: =H8 -> 1115.99
B17: Denominator: Tangible Common Equity + Loan Loss Reserves ($M) | C17: $M | E17: =IFERROR(E9+E10,"–") -> 358027.84 | F17: =IFERROR(F9+F10,"–") -> 391767.45 | G17: =IFERROR(G9+G10,"–") -> 428190.34 | H17: =IFERROR(H9+H10,"–") -> 468534.98
B18: TEXAS RATIO | C18: x | E18: =IFERROR(E16/E17,"–") -> 0.0034966276 | F18: =IFERROR(F16/F17,"–") -> 0.0027404778 | G18: =IFERROR(G16/G17,"–") -> 0.002363972 | H18: =IFERROR(H16/H17,"–") -> 0.0023818712
B19: ZONE | E19: =IFERROR(IF(E18>1,"🚨 DISTRESS",IF(E18>=0.75,"🔴 STRESS",IF(E18>=0.25,"⚠️ WATCH","✅ SOUND"))),"–") -> ✅ SOUND | F19: =IFERROR(IF(F18>1,"🚨 DISTRESS",IF(F18>=0.75,"🔴 STRESS",IF(F18>=0.25,"⚠️ WATCH","✅ SOUND"))),"–") -> ✅ SOUND | G19: =IFERROR(IF(G18>1,"🚨 DISTRESS",IF(G18>=0.75,"🔴 STRESS",IF(G18>=0.25,"⚠️ WATCH","✅ SOUND"))),"–") -> ✅ SOUND | H19: =IFERROR(IF(H18>1,"🚨 DISTRESS",IF(H18>=0.75,"🔴 STRESS",IF(H18>=0.25,"⚠️ WATCH","✅ SOUND"))),"–") -> ✅ SOUND
B21: ZONE INTERPRETATION
B22: ZONE | C22: Threshold | D22: Interpretation
B23: ✅ SOUND | C23: < 0.25x | D23: Strong capital buffer — very low credit risk
B24: ⚠️ WATCH | C24: 0.25x – 0.75x | D24: Elevated NPAs — monitor closely
B25: 🔴 STRESS | C25: 0.75x – 1.00x | D25: High credit stress — capital at risk
B26: 🚨 DISTRESS | C26: > 1.00x | D26: Critical — insolvency risk (100% = bank failure threshold)
B28: NOTE: Texas Ratio developed by Gerard Cassidy (1992). Texas Ratio = Non-Performing Assets / (Tangible Common Equity + Loan Loss Reserves). A ratio > 1.0x historically predicts bank failure within 2 years.
B29: NPA and LLR figures are estimated from INPUT (1.0% × net loans for NPA; 1.5% × net loans for LLR). For precise values, enter actual NPA and LLR figures directly in rows 8 and 10.

Sheet CAMELS
B1: FinSight | F1: CAMELS — Bank Safety & Soundness Assessment
B3: CAMELS — Bank Regulatory Safety & Soundness Framework
B4: Capital · Asset Quality · Management · Earnings · Liquidity · Sensitivity — Each component scored 1 (Strong) to 5 (Critical)
B5: COMPONENT | D5: FORMULA / BASIS | F5: LTM VALUE | G5: BENCHMARK | H5: SCORE (1-5)
B7: CAPITAL ADEQUACY
B8: Equity / Total Assets (Leverage Ratio) | D8: =IFERROR(INPUT!H60/INPUT!H44,"–") -> 0.91557788 | F8: =IFERROR(INPUT!H60/INPUT!H44,"–") -> 0.91557788 | G8: > 8% ✅ | H8: =IFERROR(IF(F8>0.1,1,IF(F8>0.08,2,IF(F8>0.06,3,IF(F8>0.04,4,5)))),"–") -> 1
B9: P/TBV (Market Signal of Capital Adequacy) | D9: =IFERROR(INPUT!H97/(INPUT!H60-INPUT!H42),"–") -> 1.7856408 | F9: =IFERROR(INPUT!H97/(INPUT!H60-INPUT!H42),"–") -> 1.7856408 | G9: 1.0–2.0x ✅ | H9: =IFERROR(IF(F9>2,2,IF(F9>1,1,IF(F9>0.7,3,IF(F9>0.5,4,5)))),"–") -> 1
B10: ROE vs CoE Spread (Value Creation) | D10: =IFERROR(INPUT!H26/INPUT!H60-INPUT!H102,"–") -> 0.089546563 | F10: =IFERROR(INPUT!H26/INPUT!H60-INPUT!H102,"–") -> 0.089546563 | G10: > 5% ✅ | H10: =IFERROR(IF(F10>0.05,1,IF(F10>0.02,2,IF(F10>0,3,IF(F10>-0.03,4,5)))),"–") -> 1
B12: ASSET QUALITY
B13: NIM (Net Interest Margin) | D13: =IFERROR(INPUT!H21/INPUT!H44,"–") -> 0.33316848 | F13: =IFERROR(INPUT!H21/INPUT!H44,"–") -> 0.33316848 | G13: 2–4% ✅ | H13: =IFERROR(IF(F13>0.03,1,IF(F13>0.02,2,IF(F13>0.015,3,IF(F13>0.01,4,5)))),"–") -> 1
B14: Loan/Deposit Ratio | D14: =IFERROR(INPUT!H35/INPUT!H47,"–") -> 0.59787954 | F14: =IFERROR(INPUT!H35/INPUT!H47,"–") -> 0.59787954 | G14: 60–85% ✅ | H14: =IFERROR(IF(AND(F14>0.6,F14<0.85),1,IF(AND(F14>=0.5,F14<=0.9),2,IF(AND(F14>=0.4,F14<=1),3,IF(F14<1.1,4,5)))),"–") -> 2
B15: Cost / Income Efficiency | D15: =IFERROR(ABS(INPUT!H14+INPUT!H15+INPUT!H16)/(INPUT!H21+ABS(INPUT!H20)),"–") -> 0.25837886 | F15: =IFERROR(ABS(INPUT!H14+INPUT!H15+INPUT!H16)/(INPUT!H21+ABS(INPUT!H20)),"–") -> 0.25837886 | G15: < 55% ✅ | H15: =IFERROR(IF(F15<0.45,1,IF(F15<0.55,2,IF(F15<0.65,3,IF(F15<0.75,4,5)))),"–") -> 1
B17: EARNINGS
B18: ROE (Return on Equity) | D18: =IFERROR(INPUT!H26/INPUT!H60,"–") -> 0.19584656 | F18: =IFERROR(INPUT!H26/INPUT!H60,"–") -> 0.19584656 | G18: > 10% ✅ | H18: =IFERROR(IF(F18>0.15,1,IF(F18>0.1,2,IF(F18>0.07,3,IF(F18>0.03,4,5)))),"–") -> 1
B19: ROA (Return on Assets) | D19: =IFERROR(INPUT!H26/INPUT!H44,"–") -> 0.17931278 | F19: =IFERROR(INPUT!H26/INPUT!H44,"–") -> 0.17931278 | G19: > 1% ✅ | H19: =IFERROR(IF(F19>0.015,1,IF(F19>0.01,2,IF(F19>0.007,3,IF(F19>0.004,4,5)))),"–") -> 1
B20: Dividend Yield (Shareholder Return) | D20: =IFERROR(ABS(INPUT!H29)/INPUT!H97,"–") -> 0.03789498 | F20: =IFERROR(ABS(INPUT!H29)/INPUT!H97,"–") -> 0.03789498 | G20: 2–5% ✅ | H20: =IFERROR(IF(AND(F20>0.02,F20<0.06),1,IF(AND(F20>0.01,F20<0.08),2,IF(F20>0.005,3,IF(F20>0,4,5)))),"–") -> 1
B22: LIQUIDITY
B23: Loan / Deposit Ratio (Funding Stability) | D23: =IFERROR(INPUT!H35/INPUT!H47,"–") -> 0.59787954 | F23: =IFERROR(INPUT!H35/INPUT!H47,"–") -> 0.59787954 | G23: 60–85% ✅ | H23: =IFERROR(IF(AND(F23>0.6,F23<0.85),1,IF(AND(F23>=0.5,F23<=0.9),2,IF(F23<1,3,IF(F23<1.1,4,5)))),"–") -> 2
B24: Cash / Total Assets (Liquidity Buffer) | D24: =IFERROR(INPUT!H34/INPUT!H44,"–") -> 0.59164584 | F24: =IFERROR(INPUT!H34/INPUT!H44,"–") -> 0.59164584 | G24: > 3% ✅ | H24: =IFERROR(IF(F24>0.05,1,IF(F24>0.03,2,IF(F24>0.02,3,IF(F24>0.01,4,5)))),"–") -> 1
B26: SENSITIVITY TO MARKET RISK
B27: P/TBV Premium vs Justified P/B | D27: =IFERROR((INPUT!H97/(INPUT!H60-INPUT!H42))/((INPUT!H26/INPUT!H60-INPUT!H109)/(INPUT!H102-INPUT!H109)),"–") -> 0.849725 | F27: =IFERROR((INPUT!H97/(INPUT!H60-INPUT!H42))/((INPUT!H26/INPUT!H60-INPUT!H109)/(INPUT!H102-INPUT!H109)),"–") -> 0.849725 | G27: < 1.3x ✅ | H27: =IFERROR(IF(F27<1,1,IF(F27<1.3,2,IF(F27<1.6,3,IF(F27<2,4,5)))),"–") -> 1
B28: NIM Sensitivity (Earnings at Risk) | D28: =IFERROR(INPUT!H21/INPUT!H44*1000,"–") -> 333.16848 | F28: =IFERROR(INPUT!H21/INPUT!H44*1000,"–") -> 333.16848 | G28: > 2.5 ✅ | H28: =IFERROR(IF(F28>5,1,IF(F28>2.5,2,IF(F28>1.5,3,IF(F28>0.5,4,5)))),"–") -> 1
B30: COMPOSITE CAMELS SCORE
B31: Average Score (all components, excl. M) | C31: 1–5 | H31: =IFERROR(AVERAGE(H8:H10,H13:H15,H18:H20,H23:H24,H27:H28),"–") -> 1.1538462
B32: COMPOSITE RATING | H32: =IFERROR(IF(H31<=1.5,"1 — STRONG",IF(H31<=2.5,"2 — SATISFACTORY",IF(H31<=3.5,"3 — FAIR",IF(H31<=4.5,"4 — MARGINAL","5 — UNSATISFACTORY")))),"–") -> 1 — STRONG
B34: NOTE: CAMELS is the primary regulatory framework used by the FDIC, OCC, and Federal Reserve for bank safety & soundness examinations.
B35: Scores here are quantitative approximations based on public financial data. The M (Management) component requires qualitative judgment and is not auto-scored.

Sheet BANK VALUATION
B1: FinSight | I1: BANK VALUATION — DDM · Justified P/B · Excess Return Model | R1: Method | S1: Left Grey | T1: Blue Bar | U1: Right Grey | V1: _unused | W1: PriceX | X1: PriceY
B2: ▶ BANK MODEL: DDM (Gordon Growth) + Justified P/B — Standard DCF not applicable for banks | L2: Method | M2: Base | N2: Pre-marker | O2: Marker | P2: Post-marker | R2: DDM Gordon Growth | S2: =SCENARIOS!D22 -> 73.906877 | T2: =SCENARIOS!F22-SCENARIOS!D22 -> 278.26642 | U2: =800-SCENARIOS!F22 -> 447.82671 | W2: =D21 -> 311.12 | X2: 0 | Z2: =ROUND(S2+T2,0) -> 352
L3: DDM Gordon Growth | M3: =D18 -> 148.64248 | N3: 0 | O3: 0 | P3: 0 | W3: =D21 -> 311.12 | X3: 2
B4: DDM (Gordon Growth Model) | L4: Justified P/B | M4: =D31 -> 366.14199 | N4: 0 | O4: 0 | P4: 0 | R4: Justified P/B | S4: =J38 -> 143.93274 | T4: =D44-J38 -> 568.84423 | U4: =800-D44 -> 87.223023 | W4: =D21 -> 311.12 | X4: 4 | Z4: =ROUND(S4+T4,0) -> 713
L5: Excess Return Model | M5: =F77 -> 529.26697 | N5: 0 | O5: 0 | P5: 0 | W5: =D21 -> 311.12 | X5: 6
B6: Net Income LTM ($M) | D6: =INPUT!H26 -> 104057 | L6: Blended (3 Methods) | M6: =F85 -> 348.01714 | N6: 0 | O6: 0 | P6: 0 | R6: Excess Return Model | S6: =F77*0.55 -> 291.09683 | T6: =F77*1.35-F77*0.55 -> 423.41358 | U6: =800-F77*1.35 -> 85.489592 | Z6: =ROUND(S6+T6,0) -> 715
B7: Common Equity ($M) | D7: =INPUT!H60 -> 531319 | L7: Current Market Price | M7: =D21 -> 311.12 | N7: 0 | O7: 0 | P7: 0
B8: Shares Outstanding (M) | D8: =INPUT!H96 -> 2679.5 | R8: Blended (3 Methods) | S8: =AVERAGE(S2,S4,S6) -> 169.64548 | T8: =AVERAGE(T2,T4,T6) -> 423.50807 | U8: =800-AVERAGE(S2,S4,S6)-AVERAGE(T2,T4,T6) -> 206.84644 | Z8: =ROUND(S8+T8,0) -> 593
B9: Cost of Equity — ke (CAPM) | D9: =INPUT!H102 -> 0.1063
B10: Long-Term Growth Rate — g | D10: =INPUT!H109 -> 0.025
B11: Sustainable ROE | D11: =IFERROR(D6/D7,"-") -> 0.19584656
B12: Dividend Payout Ratio | D12: =IFERROR(ABS(INPUT!H29)/INPUT!H26,"-") -> 0.30359322
B13: DPS — Dividends Per Share ($) | D13: =IFERROR(ABS(INPUT!H29)/INPUT!H96,"-") -> 11.789886
B14: EPS — Earnings Per Share ($) | D14: =IFERROR(INPUT!H26/INPUT!H96,"-") -> 38.834484
B16: DDM OUTPUTS
B18: DDM Implied Price ($/share) | D18: =IFERROR(D13*(1+D10)/(D9-D10),"N/A — ke≤g") -> 148.64248
B19: Retention Ratio (b = 1 − Payout) | D19: =IFERROR(1-D12,"-") -> 0.69640678
B20: Sustainable Growth Rate (ROE × b) | D20: =IFERROR(D11*D19,"-") -> 0.13638887
B21: Current Price ($) | D21: =INPUT!H95 -> 311.12
B22: Implied Upside / (Downside) | D22: =IFERROR((D18-D21)/D21,"N/A") -> -0.52223426
B24: JUSTIFIED P/B MODEL (Damodaran)
B26: ROE (LTM) | D26: =D11 -> 0.19584656
B27: Cost of Equity — ke | D27: =D9 -> 0.1063
B28: Long-Term Growth Rate — g | D28: =D10 -> 0.025
B29: TBV Per Share ($) | D29: =IFERROR((INPUT!H60-INPUT!H42)/INPUT!H96,"-") -> 174.23437
B30: Justified P/B Multiple | D30: =IFERROR((D26-D28)/(D27-D28),"N/A — ke≤g") -> 2.1014337
B31: Justified P/B Implied Price ($) | D31: =IFERROR(D30*D29,"N/A") -> 366.14199
B32: Current Price ($) | D32: =D21 -> 311.12
B33: Implied Upside / (Downside) | D33: =IFERROR((D31-D32)/D32,"N/A") -> 0.17685134
B35: SENSITIVITY: Justified P/B Implied Price vs ROE × Cost of Equity
B37: Justified P/B Price ($) — g fixed at 2.5% | C37: ke → | D37: 0.08 | E37: 0.09 | F37: 0.1 | G37: 0.1063 | H37: 0.12 | I37: 0.13 | J37: 0.14
B38: ROE ↓ | C38: 0.12 | D38: =IFERROR(((C38-$D$28)/(D$37-$D$28))*$D$29,"-") -> 300.95028 | E38: =IFERROR(((C38-$D$28)/(E$37-$D$28))*$D$29,"-") -> 254.65024 | F38: =IFERROR(((C38-$D$28)/(F$37-$D$28))*$D$29,"-") -> 220.69687 | G38: =IFERROR(((C38-$D$28)/(G$37-$D$28))*$D$29,"-") -> 203.5949 | H38: =IFERROR(((C38-$D$28)/(H$37-$D$28))*$D$29,"-") -> 174.23437 | I38: =IFERROR(((C38-$D$28)/(I$37-$D$28))*$D$29,"-") -> 157.64062 | J38: =IFERROR(((C38-$D$28)/(J$37-$D$28))*$D$29,"-") -> 143.93274
C39: 0.14 | D39: =IFERROR(((C39-$D$28)/(D$37-$D$28))*$D$29,"-") -> 364.30823 | E39: =IFERROR(((C39-$D$28)/(E$37-$D$28))*$D$29,"-") -> 308.26081 | F39: =IFERROR(((C39-$D$28)/(F$37-$D$28))*$D$29,"-") -> 267.15937 | G39: =IFERROR(((C39-$D$28)/(G$37-$D$28))*$D$29,"-") -> 246.45698 | H39: =IFERROR(((C39-$D$28)/(H$37-$D$28))*$D$29,"-") -> 210.91529 | I39: =IFERROR(((C39-$D$28)/(I$37-$D$28))*$D$29,"-") -> 190.82812 | J39: =IFERROR(((C39-$D$28)/(J$37-$D$28))*$D$29,"-") -> 174.23437
C40: 0.16 | D40: =IFERROR(((C40-$D$28)/(D$37-$D$28))*$D$29,"-") -> 427.66619 | E40: =IFERROR(((C40-$D$28)/(E$37-$D$28))*$D$29,"-") -> 361.87139 | F40: =IFERROR(((C40-$D$28)/(F$37-$D$28))*$D$29,"-") -> 313.62187 | G40: =IFERROR(((C40-$D$28)/(G$37-$D$28))*$D$29,"-") -> 289.31907 | H40: =IFERROR(((C40-$D$28)/(H$37-$D$28))*$D$29,"-") -> 247.59621 | I40: =IFERROR(((C40-$D$28)/(I$37-$D$28))*$D$29,"-") -> 224.01562 | J40: =IFERROR(((C40-$D$28)/(J$37-$D$28))*$D$29,"-") -> 204.536
C41: 0.18 | D41: =IFERROR(((C41-$D$28)/(D$37-$D$28))*$D$29,"-") -> 491.02414 | E41: =IFERROR(((C41-$D$28)/(E$37-$D$28))*$D$29,"-") -> 415.48196 | F41: =IFERROR(((C41-$D$28)/(F$37-$D$28))*$D$29,"-") -> 360.08437 | G41: =IFERROR(((C41-$D$28)/(G$37-$D$28))*$D$29,"-") -> 332.18115 | H41: =IFERROR(((C41-$D$28)/(H$37-$D$28))*$D$29,"-") -> 284.27713 | I41: =IFERROR(((C41-$D$28)/(I$37-$D$28))*$D$29,"-") -> 257.20312 | J41: =IFERROR(((C41-$D$28)/(J$37-$D$28))*$D$29,"-") -> 234.83763
C42: 0.1958 | D42: =IFERROR(((C42-$D$28)/(D$37-$D$28))*$D$29,"-") -> 541.07692 | E42: =IFERROR(((C42-$D$28)/(E$37-$D$28))*$D$29,"-") -> 457.83432 | F42: =IFERROR(((C42-$D$28)/(F$37-$D$28))*$D$29,"-") -> 396.78974 | G42: =IFERROR(((C42-$D$28)/(G$37-$D$28))*$D$29,"-") -> 366.0422 | H42: =IFERROR(((C42-$D$28)/(H$37-$D$28))*$D$29,"-") -> 313.25506 | I42: =IFERROR(((C42-$D$28)/(I$37-$D$28))*$D$29,"-") -> 283.42125 | J42: =IFERROR(((C42-$D$28)/(J$37-$D$28))*$D$29,"-") -> 258.77592
C43: 0.22 | D43: =IFERROR(((C43-$D$28)/(D$37-$D$28))*$D$29,"-") -> 617.74005 | E43: =IFERROR(((C43-$D$28)/(E$37-$D$28))*$D$29,"-") -> 522.70312 | F43: =IFERROR(((C43-$D$28)/(F$37-$D$28))*$D$29,"-") -> 453.00937 | G43: =IFERROR(((C43-$D$28)/(G$37-$D$28))*$D$29,"-") -> 417.90532 | H43: =IFERROR(((C43-$D$28)/(H$37-$D$28))*$D$29,"-") -> 357.63897 | I43: =IFERROR(((C43-$D$28)/(I$37-$D$28))*$D$29,"-") -> 323.57812 | J43: =IFERROR(((C43-$D$28)/(J$37-$D$28))*$D$29,"-") -> 295.44089
C44: 0.25 | D44: =IFERROR(((C44-$D$28)/(D$37-$D$28))*$D$29,"-") -> 712.77698 | E44: =IFERROR(((C44-$D$28)/(E$37-$D$28))*$D$29,"-") -> 603.11898 | F44: =IFERROR(((C44-$D$28)/(F$37-$D$28))*$D$29,"-") -> 522.70312 | G44: =IFERROR(((C44-$D$28)/(G$37-$D$28))*$D$29,"-") -> 482.19845 | H44: =IFERROR(((C44-$D$28)/(H$37-$D$28))*$D$29,"-") -> 412.66035 | I44: =IFERROR(((C44-$D$28)/(I$37-$D$28))*$D$29,"-") -> 373.35937 | J44: =IFERROR(((C44-$D$28)/(J$37-$D$28))*$D$29,"-") -> 340.89334
B45: Base case: ROE=19.6%, ke=10.6%, g=2.5% — Yellow cell = current assumptions
B47: EXCESS RETURN MODEL (Damodaran) — Bank Standard IB Valuation
...

Sheet COMPARABLES
B1: FinSight | K1: COMPARABLES — Bank Peer Analysis
B2: BANK peers — P/TBV · ROE · NIM · Cost/Income · CET1 · NPL Ratio · Dividend Yield · P/E
B4: Company | C4: Ticker | D4: Price ($) | E4: Mkt Cap ($B) | F4: P/E | G4: P/TBV | H4: ROE | I4: NIM | J4: Cost/Income | K4: CET1 | L4: NPL Ratio | M4: Div Yield | N4: Rating
B5: JPMorgan Chase & Co. | C5: JPM | D5: =IFERROR(INPUT!H95,"-") -> 311.12 | E5: =IFERROR(INPUT!H97/1000,"-") -> 833.64604 | F5: =IFERROR(INPUT!H97/INPUT!H26,"-") -> 8.0114364 | G5: =IFERROR(INPUT!H97/(INPUT!H60-INPUT!H42),"-") -> 1.7856408 | H5: =IFERROR(INPUT!H26/INPUT!H60,"-") -> 0.19584656 | I5: =IFERROR((INPUT!H21-INPUT!H20)/INPUT!H44,"-") -> 0.50186797 | J5: =IFERROR(ABS(INPUT!H14+INPUT!H15+INPUT!H16)/(INPUT!H21+ABS(INPUT!H20)),"-") -> 0.25837886 | M5: =IFERROR(ABS(INPUT!H29)/INPUT!H97,"-") -> 0.03789498 | N5: —
B6: Bank of America Corporation | C6: BAC | D6: — | E6: — | F6: — | G6: — | H6: — | I6: — | J6: — | K6: — | L6: — | M6: — | N6: —
B7: Wells Fargo & Company | C7: WFC | D7: — | E7: — | F7: — | G7: — | H7: — | I7: — | J7: — | K7: — | L7: — | M7: — | N7: —
B8: The Goldman Sachs Group, Inc. | C8: GS | D8: — | E8: — | F8: — | G8: — | H8: — | I8: — | J8: — | K8: — | L8: — | M8: — | N8: —
B9: Morgan Stanley | C9: MS | D9: — | E9: — | F9: — | G9: — | H9: — | I9: — | J9: — | K9: — | L9: — | M9: — | N9: —
B10: Citigroup Inc. | C10: C | D10: — | E10: — | F10: — | G10: — | H10: — | I10: — | J10: — | K10: — | L10: — | M10: — | N10: —
B12: PEER STATISTICS
B13: Mean (ex-JPM) | D13: =IFERROR(AVERAGE(D6:D10),"—") -> — | E13: =IFERROR(AVERAGE(E6:E10),"—") -> — | F13: =IFERROR(AVERAGE(F6:F10),"—") -> — | G13: =IFERROR(AVERAGE(G6:G10),"—") -> — | H13: =IFERROR(AVERAGE(H6:H10),"—") -> — | I13: =IFERROR(AVERAGE(I6:I10),"—") -> — | J13: =IFERROR(AVERAGE(J6:J10),"—") -> — | K13: =IFERROR(AVERAGE(K6:K10),"—") -> — | ... M13: =IFERROR(AVERAGE(M6:M10),"—") -> —
B14: Median (ex-JPM) | D14: =IFERROR(MEDIAN(D6:D10),"—") -> — | E14: =IFERROR(MEDIAN(E6:E10),"—") -> — | F14: =IFERROR(MEDIAN(F6:F10),"—") -> — | G14: =IFERROR(MEDIAN(G6:G10),"—") -> — | H14: =IFERROR(MEDIAN(H6:H10),"—") -> — | I14: =IFERROR(MEDIAN(I6:I10),"—") -> — | J14: =IFERROR(MEDIAN(J6:J10),"—") -> — | K14: =IFERROR(MEDIAN(K6:K10),"—") -> — | ... M14: =IFERROR(MEDIAN(M6:M10),"—") -> —
B15: Maximum | D15: =IFERROR(MAX(D5:D10),"—") -> 311.12 | E15: =IFERROR(MAX(E5:E10),"—") -> 833.64604 | F15: =IFERROR(MAX(F5:F10),"—") -> 8.0114364 | G15: =IFERROR(MAX(G5:G10),"—") -> 1.7856408 | H15: =IFERROR(MAX(H5:H10),"—") -> 0.19584656 | I15: =IFERROR(MAX(I5:I10),"—") -> 0.50186797 | J15: =IFERROR(MAX(J5:J10),"—") -> 0.25837886 | K15: =IFERROR(IF(COUNT(K5:K10)=0,"—",MAX(K5:K10)),"—") -> — | L15: =IFERROR(IF(COUNT(L5:L10)=0,"—",MAX(L5:L10)),"—") -> — | M15: =IFERROR(MAX(M5:M10),"—") -> 0.03789498
B16: Minimum | D16: =IFERROR(MIN(D5:D10),"—") -> 311.12 | E16: =IFERROR(MIN(E5:E10),"—") -> 833.64604 | F16: =IFERROR(MIN(F5:F10),"—") -> 8.0114364 | G16: =IFERROR(MIN(G5:G10),"—") -> 1.7856408 | H16: =IFERROR(MIN(H5:H10),"—") -> 0.19584656 | I16: =IFERROR(MIN(I5:I10),"—") -> 0.50186797 | J16: =IFERROR(MIN(J5:J10),"—") -> 0.25837886 | K16: =IFERROR(IF(COUNT(K5:K10)=0,"—",MIN(K5:K10)),"—") -> — | L16: =IFERROR(IF(COUNT(L5:L10)=0,"—",MIN(L5:L10)),"—") -> — | M16: =IFERROR(MIN(M5:M10),"—") -> 0.03789498
B18: JPM — PEER-IMPLIED VALUATION (P/TBV)
B19: Peer Median P/TBV | D19: =IFERROR(MEDIAN(G6:G10),"N/A — fill peers") -> N/A — fill peers
B20: JPM TBV/Share ($) | D20: =IFERROR((INPUT!H60-INPUT!H42)/INPUT!H96,"—") -> 174.23437
B21: Implied Price — P/TBV ($) | D21: =IFERROR(IF(ISNUMBER(D19),D19*D20,"N/A"),"N/A") -> N/A
B22: Current Market Price ($) | D22: =INPUT!H95 -> 311.12
B23: Implied Upside / (Downside) | D23: =IFERROR(IF(ISNUMBER(D21),(D21-D22)/D22,"N/A"),"N/A") -> N/A
B25: NOTE: Complete columns C–M for peer companies (grey cells). Implied valuation auto-calculates from peer median P/TBV once data is entered. NIM = (Interest Income − Interest Expense) / Total Assets.

Sheet SCENARIOS
B1: FinSight | D1: SCENARIOS — Bank Stress & Upside Analysis
A2: BANK profile — NIM sensitivity · Credit stress (NPL/provisions) · Cost/Income efficiency · DDM-implied price per scenario
A4: SCENARIO ASSUMPTIONS
B5: DRIVER | C5: BASE (LTM) | D5: BEAR | E5: BASE | F5: BULL
B6: Net Interest Margin (NIM) | C6: =IFERROR((INPUT!H21-INPUT!H20)/INPUT!H44,"-") -> 0.50186797 | D6: 0.024 | E6: 0.028 | F6: 0.032
B7: Cost/Income Ratio (CIR) | C7: =IFERROR((INPUT!H10+INPUT!H17*0)/(INPUT!H9-INPUT!H20),"-") -> -0.27787092 | D7: 0.65 | E7: 0.6 | F7: 0.54
B8: NPL Provision Rate (% of Loans) | C8: =IFERROR(INPUT!H20/INPUT!H44,"-") -> -0.16869949 | D8: 0.012 | E8: 0.007 | F8: 0.004
B9: Loan Growth (YoY) | C9: 0.05 | D9: -0.02 | E9: 0.05 | F9: 0.09
B10: CET1 Capital Ratio | C10: =IFERROR(INPUT!H60/INPUT!H44,"-") -> 0.91557788 | D10: 0.13 | E10: 0.15 | F10: 0.165
B11: Dividend Payout Ratio | C11: =IFERROR(ABS(INPUT!H29)/INPUT!H26,"-") -> 0.30359322 | D11: 0.25 | E11: 0.3 | F11: 0.4
B12: Long-Term Growth Rate (g) | C12: ='BANK VALUATION'!D10 -> 0.025 | D12: 0.015 | E12: 0.025 | F12: 0.035
B13: Cost of Equity — ke | C13: ='BANK VALUATION'!D9 -> 0.1063 | D13: 0.115 | E13: 0.106 | F13: 0.095
A15: SCENARIO OUTPUTS — DDM-IMPLIED VALUATION
B16: METRIC | C16: LTM ACTUAL | D16: BEAR | E16: BASE | F16: BULL
B17: Implied Net Interest Income ($M) | C17: =IFERROR((INPUT!H21-INPUT!H20),"—") -> 291239 | D17: =IFERROR(D6*INPUT!H44*(1+D9),"—") -> 13648.891 | E17: =IFERROR(E6*INPUT!H44*(1+E9),"—") -> 17061.114 | F17: =IFERROR(F6*INPUT!H44*(1+F9),"—") -> 20241.213
B18: Implied Net Income ($M) | C18: =IFERROR(INPUT!H26,"—") -> 104057 | D18: =IFERROR(INPUT!H26*(D6/E6)*((1-D7)/(1-E7)),"—") -> 78042.75 | E18: =IFERROR(INPUT!H26*(E6/E6)*((1-E7)/(1-E7)),"—") -> 104057 | F18: =IFERROR(INPUT!H26*(F6/E6)*((1-F7)/(1-E7)),"—") -> 136760.63
B19: EPS ($) | C19: =IFERROR(INPUT!H26/INPUT!H96,"—") -> 38.834484 | D19: =IFERROR(D18/INPUT!H96,"—") -> 29.125863 | E19: =IFERROR(E18/INPUT!H96,"—") -> 38.834484 | F19: =IFERROR(F18/INPUT!H96,"—") -> 51.039608
B20: DPS ($) | C20: =IFERROR(ABS(INPUT!H29)/INPUT!H96,"—") -> 11.789886 | D20: =IFERROR('BANK VALUATION'!D13*(D6/E6)*((1-D7)/(1-E7))*D11/'BANK VALUATION'!D12,"—") -> 7.2814658 | E20: =IFERROR('BANK VALUATION'!D13*(E6/E6)*((1-E7)/(1-E7))*E11/'BANK VALUATION'!D12,"—") -> 11.650345 | F20: =IFERROR('BANK VALUATION'!D13*(F6/E6)*((1-F7)/(1-E7))*F11/'BANK VALUATION'!D12,"—") -> 20.415843
B21: Return on Equity (ROE) | C21: =IFERROR(INPUT!H26/INPUT!H60,"—") -> 0.19584656 | D21: =IFERROR(D18/INPUT!H60,"—") -> 0.14688492 | E21: =IFERROR(E18/INPUT!H60,"—") -> 0.19584656 | F21: =IFERROR(F18/INPUT!H60,"—") -> 0.25739834
B22: DDM Implied Price — Gordon Growth ($) | C22: =IFERROR('BANK VALUATION'!D18,"—") -> 148.64248 | D22: =IFERROR((D20*(1+D12))/(D13-D12),"ke≤g") -> 73.906877 | E22: =IFERROR((E20*(1+E12))/(E13-E12),"ke≤g") -> 147.42721 | F22: =IFERROR((F20*(1+F12))/(F13-F12),"ke≤g") -> 352.17329
B23: Current Market Price ($) | C23: =INPUT!H95 -> 311.12 | D23: =INPUT!H95 -> 311.12 | E23: =INPUT!H95 -> 311.12 | F23: =INPUT!H95 -> 311.12
B24: Implied Upside / (Downside) | C24: =IFERROR((C22-C23)/C23,"N/A") -> -0.52223426 | D24: =IFERROR((D22-D23)/D23,"N/A") -> -0.76244897 | E24: =IFERROR((E22-E23)/E23,"N/A") -> -0.52614037 | F24: =IFERROR((F22-F23)/F23,"N/A") -> 0.13195324
D26: ⬆ BULL | E26: → BASE | F26: ⬇ BEAR
B44: NOTE: Net Income in scenarios is a simplified estimate — NII × (1−CIR) × (1−effective tax proxy). For full precision, update INPUT sheet assumptions. DDM implied price uses scenario-specific DPS, ke, and g.
B47: DDM Implied Price by Scenario
B48: Scenario | C48: DDM Implied Price ($) | D48: Current Market Price ($)
B49: Bear | C49: =D22 -> 73.906877 | D49: =D23 -> 311.12
B50: Base | C50: =E22 -> 147.42721 | D50: =E23 -> 311.12
B51: Bull | C51: =F22 -> 352.17329 | D51: =F23 -> 311.12
B54: Net Income by Scenario
B55: Scenario | C55: Net Income ($M)
B56: LTM Actual | C56: =C18 -> 104057
B57: Bear | C57: =D18 -> 78042.75
B58: Base | C58: =E18 -> 104057
B59: Bull | C59: =F18 -> 136760.63
B79: Chart Data: EBITDA by Scenario | C79: =INPUT!D117+1 -> 2026 | D79: =INPUT!D117+2 -> 2027 | E79: =INPUT!D117+3 -> 2028 | F79: =INPUT!D117+4 -> 2029 | G79: =INPUT!D117+5 -> 2030
B80: Pessimistic | C80: =IF(INPUT!H9="",NA(),INPUT!H9*(1+$C$9)*$C$11) -> 57967.893 | D80: =IF(C80=0,0,C80*(1+$C$9)) -> 60866.287 | E80: =IF(D80=0,0,D80*(1+$C$9)) -> 63909.602 | F80: =IF(E80=0,0,E80*(1+$C$9)) -> 67105.082 | G80: =IF(F80=0,0,F80*(1+$C$9)) -> 70460.336
B81: Realistic | C81: =IF(INPUT!H9="",NA(),INPUT!H9*(1+$D$9)*$D$11) -> 44552.515 | D81: =IF(C81=0,0,C81*(1+$D$9)) -> 43661.465 | E81: =IF(D81=0,0,D81*(1+$D$9)) -> 42788.235 | F81: =IF(E81=0,0,E81*(1+$D$9)) -> 41932.471 | G81: =IF(F81=0,0,F81*(1+$D$9)) -> 41093.821
B82: Optimistic | C82: =IF(INPUT!H9="",NA(),INPUT!H9*(1+$E$9)*$E$11) -> 57281.805 | D82: =IF(C82=0,0,C82*(1+$E$9)) -> 60145.895 | E82: =IF(D82=0,0,D82*(1+$E$9)) -> 63153.19 | F82: =IF(E82=0,0,E82*(1+$E$9)) -> 66310.85 | G82: =IF(F82=0,0,F82*(1+$E$9)) -> 69626.392

Sheet DASHBOARD
B1: FinSight | J1: DASHBOARD — Sector-Adaptive Financial Analysis
B2: =INPUT!D114&" ("&INPUT!D115&") — "&INPUT!D116&" | Price: $"&TEXT(INPUT!H95,"#,##0.00")&" | Market Cap: $"&TEXT(INPUT!H97/1000,"#,##0.0")&"B | EV: $"&TEXT(INPUT!H98/1000,"#,##0.0")&"B | Year: "&INPUT!D117 -> JPMorgan Chase & Co. (JPM) — Financial Services | Price: $311,120.00 | Market Cap: $833,646.0B | EV: $990,290.0B | Year: 2025
B3: ="Profile: "&IFERROR(_xlfn.XLOOKUP(INPUT!D116,SECTOR_REF!A7:A19,SECTOR_REF!C7:C19),"STANDARD")&" | Valuation: "&IFERROR(_xlfn.XLOOKUP(INPUT!D116,SECTOR_REF!A7:A19,SECTOR_REF!D7:D19),"DCF 3-phase")&" | DCF applicable: "&IFERROR(_xlfn.XLOOKUP(INPUT!D116,SECTOR_REF!A7:A19,SECTOR_REF!E7:E19),"YES") -> Profile: Banks & Financial Institutions | Valuation: DDM (Gordon) + Justified P/B | DCF applicable: NO
Q4: 2023 | R4: 0.166 | S4: 0.106
B5: Métrique | F5: VALUATION | K5: Financial Data
B6: P/TBV | C6: =IFERROR(RATIOS!H8,"N/A") -> 1.7856408 | D6: 0.8x – 1.8x | F6: Current Price | G6: =INPUT!H95 -> 311.12 | K6: P&L Summary (LTM) | P6: Balance Sheet Summary (LTM)
B7: ROE | C7: =IFERROR(RATIOS!H10,"N/A") -> 0.19584656 | D7: 8% – 18% | F7: Comps Implied | G7: =IFERROR(IF(ISNUMBER(COMPARABLES!D21),COMPARABLES!D21,"N/A"),"N/A") -> N/A
B8: CET1 | C8: 0.157 | D8: 12% – 16% | F8: Model Implied | G8: =IFERROR('BANK VALUATION'!F85,"N/A") -> 348.01714 | K8: Revenue | M8: =INPUT!H9 -> 181847 | N8: =INPUT!H9 -> 181847 | P8: Assets
B9: NIM | C9: =IFERROR(RATIOS!H11,"N/A") -> 0.25302922 | D9: 2.0% – 4.0% | F9: Upside / (Down) | G9: =IFERROR((G8-G6)/G6,"N/A") -> 0.11859458 | K9: COGS | M9: =INPUT!H10 -> -77733 | N9: =ABS(INPUT!H10) -> 77733 | P9: Current Assets | R9: =INPUT!H38 -> 474944 | S9: =INPUT!H38 -> 474944
B10: Cost/Income | C10: =IFERROR(RATIOS!H12,"N/A") -> 0.42746375 | D10: 45% – 65% | F10: DDM (Bear) | G10: =IFERROR(SCENARIOS!D22,"N/A") -> 73.906877 | P10: Non-current Assets | R10: =SUM(INPUT!H41:H43) -> 105366 | S10: =SUM(INPUT!H41:H43) -> 105366
B11: Div Yield | C11: =IFERROR(RATIOS!H17,"N/A") -> 0.03789498 | D11: 2% – 5% | F11: DDM (Bull) | G11: =IFERROR(SCENARIOS!F22,"N/A") -> 352.17329 | K11: Expenses | M11: =ABS(INPUT!H14) -> 60018
K12: SG&A | M12: =ABS(INPUT!H15) -> 6411 | N12: =ABS(INPUT!H15) -> 6411 | P12: Total Assets | R12: =INPUT!H44 -> 580310 | S12: =INPUT!H44 -> 580310
B13: KEY FINANCIALS (LTM) | K13: R&D | M13: =ABS(INPUT!H16) -> 8821 | N13: =ABS(INPUT!H16) -> 8821
B14: Revenue | C14: =INPUT!H9 -> 181847 | D14: $M | F14: Net Margin | G14: =IFERROR(INPUT!H26/INPUT!H9,"N/A") -> 0.5722228 | K14: D&A | M14: =ABS(INPUT!H20) -> 97898 | N14: =ABS(INPUT!H20) -> 97898 | P14: Liabilities | R14: =INPUT!H51 -> 256196
B15: EBITDA | C15: =INPUT!H30 -> 37685 | D15: $M | F15: ROA | G15: =IFERROR(RATIOS!H15,"N/A") -> 0.17931278 | K15: Interest | M15: =SUM(M12:M14) -> 113130 | N15: =SUM(N12:N14) -> 113130 | P15: Current Liabilities | R15: =INPUT!H54 -> 433970 | S15: =INPUT!H51 -> 256196
B16: Net Income | C16: =INPUT!H26 -> 104057 | D16: $M | F16: Market Cap | G16: =IFERROR(INPUT!H97,"N/A") -> 833646.04 | K16: Total Expenses | M16: =SUM(M12:M15) -> 226260 | N16: =SUM(N12:N15) -> 226260 | P16: Long-term Liabilities | R16: =INPUT!H60 -> 531319 | S16: =INPUT!H54 -> 433970
B17: FCF | C17: =IFERROR(INPUT!H75-ABS(INPUT!H78),"N/A") -> 82804 | D17: $M | F17: Equity | G17: =IFERROR(INPUT!H60,"N/A") -> 531319 | P17: Shareholders' Equity | R17: =INPUT!F60 -> 454538 | S17: =INPUT!H60 -> 531319
B18: Total Assets | C18: =INPUT!H44 -> 580310 | D18: $M | F18: TBV/Share | G18: =IFERROR((INPUT!H60-INPUT!H42)/INPUT!H96,"N/A") -> 174.23437 | M18: =M8+M9-M16 -> -122146 | R18: =INPUT!H63 -> 1221485
B19: Net Debt | C19: =IFERROR(INPUT!H54+INPUT!H48-INPUT!H34,"N/A") -> 156644 | D19: $M | F19: EPS | G19: =IFERROR(INPUT!H26/INPUT!H96,"N/A") -> 38.834484 | K19: Net Operating Profit | M19: =M8+M9-M16 -> -122146 | N19: =N8-N9-N16 -> -122146 | P19: Liabilities & Shareholders' Equity | R19: =INPUT!F63 -> 1054756 | S19: =INPUT!H63 -> 1221485
Q20: Bear | R20: =SCENARIOS!D22 -> 73.906877 | S20: =INPUT!H95 -> 311.12
C22: Profit Margins | K22: Performance Summary (Five-Year) | P22: Income Statement (LTM)
L24: 5-Yr Avg | M24: Trend | Q24: Actual | R24: Prev Year | S24: Variance | T24: Var %
K25: Revenue | L25: =AVERAGE(INPUT!D9:H9) -> 158491.25 | M25: =IF(INPUT!H9>INPUT!E9,"▲",IF(INPUT!H9<INPUT!E9,"▼","→")) -> ▲ | P25: Revenue | Q25: =INPUT!H9 -> 181847 | R25: =INPUT!G9 -> 169439 | S25: =Q25-R25 -> 12408 | T25: =IF(R25=0,NA(),S25/ABS(R25)) -> 0.073229894
K27: COGS | L27: =ABS(AVERAGE(INPUT!D10:H10)) -> 74423.75 | M27: =IF(ABS(INPUT!H10)<ABS(INPUT!E10),"▲",IF(ABS(INPUT!H10)>ABS(INPUT!E10),"▼","→")) -> ▼ | P27: COGS | Q27: =ABS(INPUT!H10) -> 77733 | R27: =ABS(INPUT!G10) -> 80240 | S27: =Q27-R27 -> -2507 | T27: =IF(R27=0,NA(),S27/ABS(R27)) -> -0.031243769
K29: Expenses | L29: =ABS(AVERAGE(INPUT!D13:H13)) -> 52453.8 | M29: =IF(ABS(INPUT!H13)<ABS(INPUT!E13),"▲",IF(ABS(INPUT!H13)>ABS(INPUT!E13),"▼","→")) -> ▼ | P29: Expenses | Q29: =ABS(INPUT!H13) -> 75250 | R29: =ABS(INPUT!G13) -> 68809 | S29: =Q29-R29 -> 6441 | T29: =IF(R29=0,NA(),S29/ABS(R29)) -> 0.093606941
K31: Net Income | L31: =AVERAGE(INPUT!D26:H26) -> 67663.6 | M31: =IF(INPUT!H26>INPUT!E26,"▲",IF(INPUT!H26<INPUT!E26,"▼","→")) -> ▲ | P31: Net Income | Q31: =INPUT!H26 -> 104057 | R31: =INPUT!G26 -> 87983 | S31: =Q31-R31 -> 16074 | T31: =IF(R31=0,NA(),S31/ABS(R31)) -> 0.18269438
K33: Net Margin (%) | L33: =AVERAGE(INPUT!D26:H26)/AVERAGE(INPUT!D9:H9) -> 0.42692325 | M33: =IF((INPUT!H26/INPUT!H9)>(INPUT!E26/INPUT!E9),"▲",IF((INPUT!H26/INPUT!H9)<(INPUT!E26/INPUT!E9),"▼","→")) -> ▲ | P33: Net Margin (%) | Q33: =INPUT!H26/INPUT!H9 -> 0.5722228 | R33: =INPUT!G26/INPUT!G9 -> 0.51926062 | S33: =Q33-R33 -> 0.052962184 | T33: =IF(R33=0,NA(),S33/ABS(R33)) -> 0.10199538
Q34: LTM DDM | R34: ='BANK VALUATION'!D18 -> 148.64248 | S34: =INPUT!H95 -> 311.12
C42: Cumulative revenue | I42: Expense Breakdown | P42: ROE vs Cost of Equity
D98: =IF(INPUT!D5="",NA(),INPUT!D5) -> #N/A | E98: =INPUT!E5 -> 2022 | F98: =INPUT!F5 -> 2023 | G98: =INPUT!G5 -> 2024 | H98: =INPUT!H5 -> 2025 (LTM) | J98: =IF(INPUT!D5="",NA(),INPUT!D5) -> #N/A | K98: =INPUT!E5 -> 2022 | L98: =INPUT!F5 -> 2023 | M98: =INPUT!G5 -> 2024 | N98: =INPUT!H5 -> 2025 (LTM)
C99: Revenue | D99: =IF(INPUT!D9="",NA(),INPUT!D9) -> #N/A | E99: =IF(INPUT!E9="",NA(),INPUT!E9) -> 127727 | F99: =IF(INPUT!F9="",NA(),INPUT!F9) -> 154952 | G99: =IF(INPUT!G9="",NA(),INPUT!G9) -> 169439 | H99: =IF(INPUT!H9="",NA(),INPUT!H9) -> 181847
D100: EBITDA | E100: =IF(INPUT!D30="",NA(),INPUT!D30) -> 0 | F100: =IF(INPUT!E30="",NA(),INPUT!E30) -> 18496 | G100: =IF(INPUT!F30="",NA(),INPUT!F30) -> 20814 | H100: =IF(INPUT!G30="",NA(),INPUT!G30) -> 28328 | I100: =IF(INPUT!H30="",NA(),INPUT!H30) -> 37685
D101: Net Income | E101: =IF(INPUT!D26="",NA(),INPUT!D26) -> 0 | F101: =IF(INPUT!E26="",NA(),INPUT!E26) -> 63782 | G101: =IF(INPUT!F26="",NA(),INPUT!F26) -> 82496 | H101: =IF(INPUT!G26="",NA(),INPUT!G26) -> 87983 | I101: =IF(INPUT!H26="",NA(),INPUT!H26) -> 104057
K102: =IF(INPUT!D5="",NA(),INPUT!D5) -> #N/A | L102: =INPUT!E5 -> 2022 | M102: =INPUT!F5 -> 2023 | N102: =INPUT!G5 -> 2024 | O102: =INPUT!H5 -> 2025 (LTM)
J103: Gross Margin | K103: =IF(INPUT!D9="",NA(),INPUT!D11/INPUT!D9) -> #N/A | L103: =IF(INPUT!E9="",NA(),INPUT!E11/INPUT!E9) -> 0.52548013 | M103: =IF(INPUT!F9="",NA(),INPUT!F11/INPUT!F9) -> 0.48943544 | N103: =IF(INPUT!G9="",NA(),INPUT!G11/INPUT!G9) -> 0.52643724 | O103: =IF(INPUT!H9="",NA(),INPUT!H11/INPUT!H9) -> 0.57253625
J104: EBITDA Margin | K104: =IF(INPUT!D9="",NA(),INPUT!D30/INPUT!D9) -> #N/A | L104: =IF(INPUT!E9="",NA(),INPUT!E30/INPUT!E9) -> 0.14480885 | M104: =IF(INPUT!F9="",NA(),INPUT!F30/INPUT!F9) -> 0.13432547 | N104: =IF(INPUT!G9="",NA(),INPUT!G30/INPUT!G9) -> 0.16718701 | O104: =IF(INPUT!H9="",NA(),INPUT!H30/INPUT!H9) -> 0.20723465
E105: =IF(INPUT!D5="",NA(),INPUT!D5) -> #N/A | F105: =INPUT!E5 -> 2022 | G105: =INPUT!F5 -> 2023 | H105: =INPUT!G5 -> 2024 | I105: =INPUT!H5 -> 2025 (LTM) | J105: Net Margin | K105: =IF(INPUT!D9="",NA(),INPUT!D26/INPUT!D9) -> #N/A | L105: =IF(INPUT!E9="",NA(),INPUT!E26/INPUT!E9) -> 0.49936192 | M105: =IF(INPUT!F9="",NA(),INPUT!F26/INPUT!F9) -> 0.53239713 | N105: =IF(INPUT!G9="",NA(),INPUT!G26/INPUT!G9) -> 0.51926062 | O105: =IF(INPUT!H9="",NA(),INPUT!H26/INPUT!H9) -> 0.5722228
D106: Revenue | E106: =IF(INPUT!D9="",NA(),INPUT!D9) -> #N/A | F106: =IF(INPUT!E9="",NA(),INPUT!E9) -> 127727 | G106: =IF(INPUT!F9="",NA(),INPUT!F9) -> 154952 | H106: =IF(INPUT!G9="",NA(),INPUT!G9) -> 169439 | I106: =IF(INPUT!H9="",NA(),INPUT!H9) -> 181847
K107: =IF(INPUT!D5="",NA(),INPUT!D5) -> #N/A | L107: =INPUT!E5 -> 2022 | M107: =INPUT!F5 -> 2023 | N107: =INPUT!G5 -> 2024 | O107: =INPUT!H5 -> 2025 (LTM)
J108: SG&A | K108: =IF(INPUT!D14="",NA(),ABS(INPUT!D14)) -> #N/A | L108: =IF(INPUT!E14="",NA(),ABS(INPUT!E14)) -> 45547 | M108: =IF(INPUT!F14="",NA(),ABS(INPUT!F14)) -> 51056 | N108: =IF(INPUT!G14="",NA(),ABS(INPUT!G14)) -> 56331 | O108: =IF(INPUT!H14="",NA(),ABS(INPUT!H14)) -> 60018
...

Sheet DASHBOARD 2
B1: FinSight | P1: =INPUT!D114&" ("&INPUT!D115&") — "&INPUT!D116 -> JPMorgan Chase & Co. (JPM) — Financial Services | AA1: Method | AB1: LeftGrey | AC1: Blue | AD1: RightGrey | AF1: PriceX | AG1: PriceY
AA2: DDM Gordon Growth | AB2: =I6 -> 73.906877 | AC2: =J6 -> 278.26642 | AD2: =800-K6 -> 447.82671 | AF2: =I10 -> 311.12 | AG2: 0
B3: Projected Business Performance | F3: Football Field Chart — Valuation Inputs | M3: Other Financial Metrics ($ Millier) | AA3: Justified P/B | AB3: =I7 -> 143.93274 | AC3: =J7 -> 568.84423 | AD3: =800-K7 -> 87.223023 | AF3: =I10 -> 311.12 | AG3: 1
AA4: Excess Return Model | AB4: =I8 -> 291.09683 | AC4: =J8 -> 423.41358 | AD4: =800-K8 -> 85.489592 | AF4: =I10 -> 311.12 | AG4: 2
B5: All figures in USD Thousands unless stated | I5: Low ($) | J5: Delta ($) | K5: High ($) | AA5: Blended (3 Methods) | AB5: =I9 -> 169.64548 | AC5: =J9 -> 423.50807 | AD5: =800-K9 -> 206.84644 | AF5: =I10 -> 311.12 | AG5: 3
B6: Company Information | F6: DDM Gordon Growth | I6: ='BANK VALUATION'!S2 -> 73.906877 | J6: ='BANK VALUATION'!T2 -> 278.26642 | K6: ='BANK VALUATION'!S2+'BANK VALUATION'!T2 -> 352.17329 | AA6: Current Price | AB6: =I10-2 -> 309.12 | AD6: =800-K10-2 -> 486.88
B7: Company Name | D7: =INPUT!D114 -> JPMorgan Chase & Co. | F7: Justified P/B | I7: ='BANK VALUATION'!S4 -> 143.93274 | J7: ='BANK VALUATION'!T4 -> 568.84423 | K7: ='BANK VALUATION'!S4+'BANK VALUATION'!T4 -> 712.77698
B8: Ticker Symbol | D8: =INPUT!D115 -> JPM | F8: Excess Return Model | I8: ='BANK VALUATION'!S6 -> 291.09683 | J8: ='BANK VALUATION'!T6 -> 423.41358 | K8: ='BANK VALUATION'!S6+'BANK VALUATION'!T6 -> 714.51041
B9: Sector | D9: =INPUT!D116 -> Financial Services | F9: Blended (3 Methods) | I9: ='BANK VALUATION'!S8 -> 169.64548 | J9: ='BANK VALUATION'!T8 -> 423.50807 | K9: ='BANK VALUATION'!S8+'BANK VALUATION'!T8 -> 593.15356
B10: Base Year (LTM) | D10: =INPUT!D117 -> 2025 | F10: Current Share Price | I10: =INPUT!H95 -> 311.12 | J10: 0 | K10: =INPUT!H95 -> 311.12
B11: Currency | D11: =INPUT!D118 -> USD | F11: Current Share Price | I11: =INPUT!H95 -> 311.12
B12: Analysis Date | D12: =INPUT!D120 -> 2026-04-15
B14: Financial Data — Multi-Year
B16: All figures in USD Thousands unless stated | E16: =INPUT!E5 -> 2022 | F16: =INPUT!F5 -> 2023 | G16: =INPUT!G5 -> 2024 | H16: =INPUT!H5 -> 2025 (LTM)
B18: Revenue Growth (%) | E18: =IF(INPUT!D9=0,"",INPUT!E9/INPUT!D9-1) | F18: =IF(INPUT!E9=0,"",INPUT!F9/INPUT!E9-1) -> 0.21314992 | G18: =IF(INPUT!F9=0,"",INPUT!G9/INPUT!F9-1) -> 0.093493469 | H18: =IF(INPUT!G9=0,"",INPUT!H9/INPUT!G9-1) -> 0.073229894 | M18: Valuation Summary: Football Field Chart
B19: EBITDA Growth (%) | E19: ="" | F19: =IF(INPUT!E30=0,"",INPUT!F30/INPUT!E30-1) -> 0.12532439 | G19: =IF(INPUT!E30=0,"",INPUT!G30/INPUT!F30-1) -> 0.36100701 | H19: =IF(INPUT!F30=0,"",INPUT!H30/INPUT!G30-1) -> 0.33030923
B21: Revenue
B22: Revenue — Products | E22: =INPUT!E9 -> 127727 | F22: =INPUT!F9 -> 154952 | G22: =INPUT!G9 -> 169439 | H22: =INPUT!H9 -> 181847
B23: Cost of Revenue (COGS) | E23: =ABS(INPUT!E10) -> 60609 | F23: =ABS(INPUT!F10) -> 79113 | G23: =ABS(INPUT!G10) -> 80240 | H23: =ABS(INPUT!H10) -> 77733
B24: Gross Profit | E24: =INPUT!E11 -> 67118 | F24: =INPUT!F11 -> 75839 | G24: =INPUT!G11 -> 89199 | H24: =INPUT!H11 -> 104114
B25: SG&A | E25: =ABS(INPUT!E14) -> 45547 | F25: =ABS(INPUT!F14) -> 51056 | G25: =ABS(INPUT!G14) -> 56331 | H25: =ABS(INPUT!H14) -> 60018
B26: Total Revenue | E26: =INPUT!E9 -> 127727 | F26: =INPUT!F9 -> 154952 | G26: =INPUT!G9 -> 169439 | H26: =INPUT!H9 -> 181847
B28: EBITDA | E28: =INPUT!E30 -> 18496 | F28: =INPUT!F30 -> 20814 | G28: =INPUT!G30 -> 28328 | H28: =INPUT!H30 -> 37685
B29: Cash from Ops (CFO) | E29: =INPUT!E75 -> 126067 | F29: =INPUT!F75 -> 90645 | G29: =INPUT!G75 -> 103610 | H29: =INPUT!H75 -> 91331
B30: Net Income | E30: =INPUT!E26 -> 63782 | F30: =INPUT!F26 -> 82496 | G30: =INPUT!G26 -> 87983 | H30: =INPUT!H26 -> 104057
B35: Stock Chart: Trailing 52-Weeks | M35: Total Revenue ($M)
V98: Low | W98: Delta | X98: High
S99: 52-Week Trading Range | V99: =I6 -> 73.906877 | W99: =J6 -> 278.26642 | X99: =K6 -> 352.17329
S100: Consensus Research | V100: =I7 -> 143.93274 | W100: =J7 -> 568.84423 | X100: =K7 -> 712.77698
S101: Precedent Trans. | V101: =I8 -> 291.09683 | W101: =J8 -> 423.41358 | X101: =K8 -> 714.51041
S102: Sum-of-the-Parts | V102: =I9 -> 169.64548 | W102: =J9 -> 423.50807 | X102: =K9 -> 593.15356
S103: Discounted Cash Flow | V103: =I10 -> 311.12 | W103: =J10 -> 0 | X103: =K10 -> 311.12
R104: =L119 -> 2023
Q105: =K119 -> 2022 | R105: =IF(INPUT!F9="",NA(),INPUT!F30/1000) -> 20.814
Q106: =IF(INPUT!E9="",NA(),INPUT!E30/1000) -> 18.496 | R106: =IF(INPUT!F9="",NA(),INPUT!F75/1000) -> 90.645 | S106: =M118 -> 2024 | T106: =N118 -> 2025 (LTM)
Q107: =IF(INPUT!E9="",NA(),INPUT!E75/1000) -> 126.067 | S107: =IF(INPUT!G9="",NA(),INPUT!G30/1000) -> 28.328 | T107: =IF(INPUT!H9="",NA(),INPUT!H30/1000) -> 37.685
Q108: =IF(INPUT!E9="",NA(),INPUT!E26/1000) -> 63.782 | R108: EBITDA | S108: =IF(INPUT!G9="",NA(),INPUT!G75/1000) -> 103.61 | T108: =IF(INPUT!H9="",NA(),INPUT!H75/1000) -> 91.331
R109: CFO | S109: 2022 | T109: 2023 | U109: 2024 | V109: 2025 (LTM)
R110: Net Income | S110: =E28 -> 18496 | T110: =F28 -> 20814 | U110: =G28 -> 28328 | V110: =H28 -> 37685
S111: =E29 -> 126067 | T111: =F29 -> 90645 | U111: =G29 -> 103610 | V111: =H29 -> 91331
...

Sheet STOCK_DATA
A1: STOCK_DATA — Apple Inc. (AAPL) — Trailing 52 Weeks
A2: # | B2: Month | C2: Close Price ($)
A3: 1 | B3: May-25 | C3: 258.96
A4: 2 | B4: Jun-25 | C4: 284.38
A5: 3 | B5: Jul-25 | C5: 290.59
A6: 4 | B6: Aug-25 | C6: 297.09
A7: 5 | B7: Sep-25 | C7: 310.9
A8: 6 | B8: Oct-25 | C8: 306.66
A9: 7 | B9: Nov-25 | C9: 310.09
A10: 8 | B10: Dec-25 | C10: 319.14
A11: 9 | B11: Jan-26 | C11: 302.97
A12: 10 | B12: Feb-26 | C12: 298.77
A13: 11 | B13: Mar-26 | C13: 292.66
A14: 12 | B14: Apr-26 | C14: 311.12
A15: 13
A17: ⚠️ Données simulées. Remplacer par données réelles (Bloomberg/FactSet) en colonne B (Mois) et C (Prix).

Sheet SECTOR_REF
A1: SECTOR_REF — Master Reference Table
A2: All ratios, benchmarks, drivers and valuation models by sector profile. Referenced dynamically by RATIOS, SCENARIOS, COMPARABLES, DCF, DASHBOARD.
A3: Sector key in INPUT!D116. Supported values listed in column A of each section.
A5: SECTION 1 — PROFILE DETECTION
A6: INPUT Value (D116) | B6: Profile Code | C6: Display Name | D6: Valuation Model | E6: DCF Applicable?
A7: Financial Services | B7: BANK | C7: Banks & Financial Institutions | D7: DDM (Gordon) + Justified P/B | E7: NO
A8: Insurance | B8: INSURANCE | C8: Insurers (P&C, Life, Health, Re) | D8: P/B anchored ROE or Embedded Value | E8: NO
A9: Real Estate | B9: REIT | C9: REITs & Listed Property | D9: NAV + P/FFO multiple | E9: NO
A10: Utilities | B10: UTILITY | C10: Regulated Utilities | D10: RAB × sector multiple (SOTP) | E10: NO
A11: Energy | B11: OIL_GAS | C11: Oil & Gas E&P + Integrated | D11: NAV 1P+2P reserves | E11: NO
A12: Technology | B12: TECH | C12: Technology / SaaS | D12: EV/Rev + EV/FCF exit multiple | E12: YES
A13: Consumer Discretionary | B13: RETAIL | C13: Retail / Consumer Discretionary | D13: EV/EBITDA growth-adjusted | E13: YES
A14: Consumer Staples | B14: STAPLES | C14: Consumer Staples | D14: EV/EBITDA + dividend | E14: YES
A15: Healthcare | B15: PHARMA | C15: Pharma / Biotech | D15: rNPV pipeline + DCF residual | E15: YES
A16: Industrials | B16: STANDARD | C16: Industrials / Manufacturing | D16: DCF 3-phase | E16: YES
A17: Communication Services | B17: TELECOM | C17: Telecom | D17: EV/EBITDA + DCF + dividend support | E17: YES
... A19: Airlines | B19: AIRLINES | C19: Airlines | D19: EV/EBITDAR + replacement value | E19: YES
A21: SECTION 2 — RATIOS P1/P2/P3 BY PROFILE
A22: Profile | B22: Priority | C22: Ratio Name | D22: Benchmark Low | E22: Benchmark High | F22: Unit | G22: Notes
A23: BANK | B23: P1 | C23: P/TBV | D23: 0.8 | E23: 1.5 | F23: x | G23: Premium justified if ROE > cost of equity
A24: BANK | B24: P1 | C24: P/E | D24: 8 | E24: 14 | F24: x | G24: Cycle-dependent
A25: BANK | B25: P1 | C25: ROE | D25: 0.1 | E25: 0.15 | F25: % | G25: Target 10-15%
A26: BANK | B26: P1 | C26: NIM | D26: 0.015 | E26: 0.04 | F26: % | G26: 1.5-3.5% EU, 2.5-4% US
A27: BANK | B27: P1 | C27: CET1 Ratio | D27: 0.11 | E27: 0.145 | F27: % | G27: ≥11% Basel III, ≥12.5% SIFI
A28: BANK | B28: P1 | C28: Cost/Income | D28: 0.45 | E28: 0.65 | F28: % | G28: Lower is better
A29: BANK | B29: P2 | C29: ROA | D29: 0.009 | E29: 0.013 | F29: % | G29: 0.9-1.3%
A30: BANK | B30: P2 | C30: NPL Ratio | D30: 0 | E30: 0.03 | F30: % | G30: <3% developed, <1.5% quality
A31: BANK | B31: P2 | C31: Loan/Deposit | D31: 0.8 | E31: 0.95 | F31: x | G31: 80-95%
A32: BANK | B32: P2 | C32: Dividend Yield | D32: 0.03 | E32: 0.07 | F32: % | G32: 3-7%
A33: BANK | B33: P3 | C33: P/PPOP | D33: 5 | E33: 10 | F33: x | G33: Pre-Provision Operating Profit
A34: BANK | B34: P3 | C34: LCR | D34: 1 | E34: 1.5 | F34: x | G34: >100% Basel III minimum
... A95: STAPLES | B95: P1 | C95: FCF Yield | D95: 0.04 | E95: 0.08 | F95: % | G95: 4-8%
A97: SECTION 3 — SCENARIO DRIVERS BY PROFILE
A98: Profile | B98: Driver Name | C98: Bear | D98: Base | E98: Bull | F98: Unit
A99: BANK | B99: NIM | C99: -0.002 | D99: 0 | E99: 0.002 | F99: bps
A100: BANK | B100: Cost/Income | C100: 0.05 | D100: 0 | E100: -0.05 | F100: %pt delta
A101: BANK | B101: NPL Provisions | C101: 0.005 | D101: 0.003 | E101: 0.001 | F101: % loans
A102: BANK | B102: ROE Delta | C102: -0.02 | D102: 0 | E102: 0.02 | F102: %pt
A103: INSURANCE | B103: Combined Ratio | C103: 0.03 | D103: 0 | E103: -0.03 | F103: %pt delta
A104: INSURANCE | B104: Investment Yield | C104: -0.005 | D104: 0 | E104: 0.005 | F104: bps
...
