Workbook

Sheet DASHBOARD
B1: FinSight IA · Technology Screening — Tableau de Bord · 22/03/2026
C3: =COUNTA('DONNÉES BRUTES'!A$3:A$90) -> 88 | H3: =ROUND(AVERAGE('DONNÉES BRUTES'!AB$3:AB$90),0)&"/100" -> 50/100 | L3: =IFERROR(_xlfn.XLOOKUP(MAX('DONNÉES BRUTES'!AB$3:AB$90),'DONNÉES BRUTES'!AB$3:AB$90,'DONNÉES BRUTES'!A$3:A$90)&" — "&MAX('DONNÉES BRUTES'!AB$3:AB$90)&"/100","—") -> NVDA — 88/100 | Q3: 46026
C4: SOCIÉTÉS ANALYSÉES | H4: SCORE MOYEN SECTEUR | L4: MEILLEUR SCORE GLOBAL | Q4: DATE D'ANALYSE
B6: TOP 5 · Classements par Facteur · Growth | H6: Quality | N6: Momentum
B7: # | C7: Ticker | D7: Société | E7: Score | F7: Croiss. Rev | H7: # | I7: Ticker | J7: Société | K7: Score | L7: Altman Z | N7: # | O7: Ticker | P7: Société | Q7: Score | R7: Mom 52W
B8: 1 | C8: =IFERROR(_xlfn.XLOOKUP(LARGE('DONNÉES BRUTES'!Y$3:Y$90,1),'DONNÉES BRUTES'!Y$3:Y$90,'DONNÉES BRUTES'!A$3:A$90),"—") -> INTC | D8: =IFERROR(_xlfn.XLOOKUP(C8,'DONNÉES BRUTES'!A$3:A$90,'DONNÉES BRUTES'!B$3:B$90),"—") -> Intel Corporation | E8: =IFERROR(_xlfn.XLOOKUP(C8,'DONNÉES BRUTES'!A$3:A$90,'DONNÉES BRUTES'!Y$3:Y$90)&"/100","—") -> 100/100 | F8: =IFERROR(_xlfn.XLOOKUP(C8,'DONNÉES BRUTES'!A$3:A$90,'DONNÉES BRUTES'!P$3:P$90),"—") -> -0.5% | H8: 1 | I8: =IFERROR(_xlfn.XLOOKUP(LARGE('DONNÉES BRUTES'!Z$3:Z$90,1),'DONNÉES BRUTES'!Z$3:Z$90,'DONNÉES BRUTES'!A$3:A$90),"—") -> DSY.PA | J8: =IFERROR(_xlfn.XLOOKUP(I8,'DONNÉES BRUTES'!A$3:A$90,'DONNÉES BRUTES'!B$3:B$90),"—") -> Dassault Systèmes SE | K8: =IFERROR(_xlfn.XLOOKUP(I8,'DONNÉES BRUTES'!A$3:A$90,'DONNÉES BRUTES'!Z$3:Z$90)&"/100","—") -> 100/100 | L8: =IFERROR(_xlfn.XLOOKUP(I8,'DONNÉES BRUTES'!A$3:A$90,'DONNÉES BRUTES'!U$3:U$90),"—") -> — | N8: 1 | O8: =IFERROR(_xlfn.XLOOKUP(LARGE('DONNÉES BRUTES'!AA$3:AA$90,1),'DONNÉES BRUTES'!AA$3:AA$90,'DONNÉES BRUTES'!A$3:A$90),"—") -> SNDK | P8: =IFERROR(_xlfn.XLOOKUP(O8,'DONNÉES BRUTES'!A$3:A$90,'DONNÉES BRUTES'!B$3:B$90),"—") -> Sandisk Corporation | Q8: =IFERROR(_xlfn.XLOOKUP(O8,'DONNÉES BRUTES'!A$3:A$90,'DONNÉES BRUTES'!AA$3:AA$90)&"/100","—") -> 100/100 | R8: =IFERROR(_xlfn.XLOOKUP(O8,'DONNÉES BRUTES'!A$3:A$90,'DONNÉES BRUTES'!W$3:W$90),"—") -> —
B9: 2 | C9: =IFERROR(_xlfn.XLOOKUP(LARGE('DONNÉES BRUTES'!Y$3:Y$90,2),'DONNÉES BRUTES'!Y$3:Y$90,'DONNÉES BRUTES'!A$3:A$90),"—") -> WDC | D9: =IFERROR(_xlfn.XLOOKUP(C9,'DONNÉES BRUTES'!A$3:A$90,'DONNÉES BRUTES'!B$3:B$90),"—") -> Western Digital Corporation | E9: =IFERROR(_xlfn.XLOOKUP(C9,'DONNÉES BRUTES'!A$3:A$90,'DONNÉES BRUTES'!Y$3:Y$90)&"/100","—") -> 99/100 | F9: =IFERROR(_xlfn.XLOOKUP(C9,'DONNÉES BRUTES'!A$3:A$90,'DONNÉES BRUTES'!P$3:P$90),"—") -> +50.7% | H9: 2 | I9: =IFERROR(_xlfn.XLOOKUP(LARGE('DONNÉES BRUTES'!Z$3:Z$90,2),'DONNÉES BRUTES'!Z$3:Z$90,'DONNÉES BRUTES'!A$3:A$90),"—") -> VRSN | J9: =IFERROR(_xlfn.XLOOKUP(I9,'DONNÉES BRUTES'!A$3:A$90,'DONNÉES BRUTES'!B$3:B$90),"—") -> VeriSign, Inc. | K9: =IFERROR(_xlfn.XLOOKUP(I9,'DONNÉES BRUTES'!A$3:A$90,'DONNÉES BRUTES'!Z$3:Z$90)&"/100","—") -> 99/100 | L9: =IFERROR(_xlfn.XLOOKUP(I9,'DONNÉES BRUTES'!A$3:A$90,'DONNÉES BRUTES'!U$3:U$90),"—") -> -27.16 | N9: 2 | O9: =IFERROR(_xlfn.XLOOKUP(LARGE('DONNÉES BRUTES'!AA$3:AA$90,2),'DONNÉES BRUTES'!AA$3:AA$90,'DONNÉES BRUTES'!A$3:A$90),"—") -> WDC | P9: =IFERROR(_xlfn.XLOOKUP(O9,'DONNÉES BRUTES'!A$3:A$90,'DONNÉES BRUTES'!B$3:B$90),"—") -> Western Digital Corporation | Q9: =IFERROR(_xlfn.XLOOKUP(O9,'DONNÉES BRUTES'!A$3:A$90,'DONNÉES BRUTES'!AA$3:AA$90)&"/100","—") -> 99/100 | R9: =IFERROR(_xlfn.XLOOKUP(O9,'DONNÉES BRUTES'!A$3:A$90,'DONNÉES BRUTES'!W$3:W$90),"—") -> +477.2%
B10: 3 | C10: =IFERROR(_xlfn.XLOOKUP(LARGE('DONNÉES BRUTES'!Y$3:Y$90,3),'DONNÉES BRUTES'!Y$3:Y$90,'DONNÉES BRUTES'!A$3:A$90),"—") -> MU | D10: =IFERROR(_xlfn.XLOOKUP(C10,'DONNÉES BRUTES'!A$3:A$90,'DONNÉES BRUTES'!B$3:B$90),"—") -> Micron Technology, Inc. | E10: =IFERROR(_xlfn.XLOOKUP(C10,'DONNÉES BRUTES'!A$3:A$90,'DONNÉES BRUTES'!Y$3:Y$90)&"/100","—") -> 98/100 | F10: =IFERROR(_xlfn.XLOOKUP(C10,'DONNÉES BRUTES'!A$3:A$90,'DONNÉES BRUTES'!P$3:P$90),"—") -> +48.9% | H10: 3 | I10: =IFERROR(_xlfn.XLOOKUP(LARGE('DONNÉES BRUTES'!Z$3:Z$90,3),'DONNÉES BRUTES'!Z$3:Z$90,'DONNÉES BRUTES'!A$3:A$90),"—") -> NVDA | J10: =IFERROR(_xlfn.XLOOKUP(I10,'DONNÉES BRUTES'!A$3:A$90,'DONNÉES BRUTES'!B$3:B$90),"—") -> NVIDIA Corporation | K10: =IFERROR(_xlfn.XLOOKUP(I10,'DONNÉES BRUTES'!A$3:A$90,'DONNÉES BRUTES'!Z$3:Z$90)&"/100","—") -> 98/100 | L10: =IFERROR(_xlfn.XLOOKUP(I10,'DONNÉES BRUTES'!A$3:A$90,'DONNÉES BRUTES'!U$3:U$90),"—") -> 13.22 | N10: 3 | O10: =IFERROR(_xlfn.XLOOKUP(LARGE('DONNÉES BRUTES'!AA$3:AA$90,3),'DONNÉES BRUTES'!AA$3:AA$90,'DONNÉES BRUTES'!A$3:A$90),"—") -> CIEN | P10: =IFERROR(_xlfn.XLOOKUP(O10,'DONNÉES BRUTES'!A$3:A$90,'DONNÉES BRUTES'!B$3:B$90),"—") -> Ciena Corporation | Q10: =IFERROR(_xlfn.XLOOKUP(O10,'DONNÉES BRUTES'!A$3:A$90,'DONNÉES BRUTES'!AA$3:AA$90)&"/100","—") -> 98/100 | R10: =IFERROR(_xlfn.XLOOKUP(O10,'DONNÉES BRUTES'!A$3:A$90,'DONNÉES BRUTES'!W$3:W$90),"—") -> +454.6%
B11: 4 | C11: =IFERROR(_xlfn.XLOOKUP(LARGE('DONNÉES BRUTES'!Y$3:Y$90,4),'DONNÉES BRUTES'!Y$3:Y$90,'DONNÉES BRUTES'!A$3:A$90),"—") -> STX | D11: =IFERROR(_xlfn.XLOOKUP(C11,'DONNÉES BRUTES'!A$3:A$90,'DONNÉES BRUTES'!B$3:B$90),"—") -> Seagate Technology Holdings plc | E11: =IFERROR(_xlfn.XLOOKUP(C11,'DONNÉES BRUTES'!A$3:A$90,'DONNÉES BRUTES'!Y$3:Y$90)&"/100","—") -> 97/100 | F11: =IFERROR(_xlfn.XLOOKUP(C11,'DONNÉES BRUTES'!A$3:A$90,'DONNÉES BRUTES'!P$3:P$90),"—") -> +38.9% | H11: 4 | I11: =IFERROR(_xlfn.XLOOKUP(LARGE('DONNÉES BRUTES'!Z$3:Z$90,4),'DONNÉES BRUTES'!Z$3:Z$90,'DONNÉES BRUTES'!A$3:A$90),"—") -> ADBE | J11: =IFERROR(_xlfn.XLOOKUP(I11,'DONNÉES BRUTES'!A$3:A$90,'DONNÉES BRUTES'!B$3:B$90),"—") -> Adobe Inc. | K11: =IFERROR(_xlfn.XLOOKUP(I11,'DONNÉES BRUTES'!A$3:A$90,'DONNÉES BRUTES'!Z$3:Z$90)&"/100","—") -> 97/100 | L11: =IFERROR(_xlfn.XLOOKUP(I11,'DONNÉES BRUTES'!A$3:A$90,'DONNÉES BRUTES'!U$3:U$90),"—") -> 7.74 | N11: 4 | O11: =IFERROR(_xlfn.XLOOKUP(LARGE('DONNÉES BRUTES'!AA$3:AA$90,4),'DONNÉES BRUTES'!AA$3:AA$90,'DONNÉES BRUTES'!A$3:A$90),"—") -> TER | P11: =IFERROR(_xlfn.XLOOKUP(O11,'DONNÉES BRUTES'!A$3:A$90,'DONNÉES BRUTES'!B$3:B$90),"—") -> Teradyne, Inc. | Q11: =IFERROR(_xlfn.XLOOKUP(O11,'DONNÉES BRUTES'!A$3:A$90,'DONNÉES BRUTES'!AA$3:AA$90)&"/100","—") -> 97/100 | R11: =IFERROR(_xlfn.XLOOKUP(O11,'DONNÉES BRUTES'!A$3:A$90,'DONNÉES BRUTES'!W$3:W$90),"—") -> +292.0%
B12: 5 | C12: =IFERROR(_xlfn.XLOOKUP(LARGE('DONNÉES BRUTES'!Y$3:Y$90,5),'DONNÉES BRUTES'!Y$3:Y$90,'DONNÉES BRUTES'!A$3:A$90),"—") -> NVDA | D12: =IFERROR(_xlfn.XLOOKUP(C12,'DONNÉES BRUTES'!A$3:A$90,'DONNÉES BRUTES'!B$3:B$90),"—") -> NVIDIA Corporation | E12: =IFERROR(_xlfn.XLOOKUP(C12,'DONNÉES BRUTES'!A$3:A$90,'DONNÉES BRUTES'!Y$3:Y$90)&"/100","—") -> 95/100 | F12: =IFERROR(_xlfn.XLOOKUP(C12,'DONNÉES BRUTES'!A$3:A$90,'DONNÉES BRUTES'!P$3:P$90),"—") -> +65.5% | H12: 5 | I12: =IFERROR(_xlfn.XLOOKUP(LARGE('DONNÉES BRUTES'!Z$3:Z$90,5),'DONNÉES BRUTES'!Z$3:Z$90,'DONNÉES BRUTES'!A$3:A$90),"—") -> FICO | J12: =IFERROR(_xlfn.XLOOKUP(I12,'DONNÉES BRUTES'!A$3:A$90,'DONNÉES BRUTES'!B$3:B$90),"—") -> Fair Isaac Corporation | K12: =IFERROR(_xlfn.XLOOKUP(I12,'DONNÉES BRUTES'!A$3:A$90,'DONNÉES BRUTES'!Z$3:Z$90)&"/100","—") -> 95/100 | L12: =IFERROR(_xlfn.XLOOKUP(I12,'DONNÉES BRUTES'!A$3:A$90,'DONNÉES BRUTES'!U$3:U$90),"—") -> 10.30 | N12: 5 | O12: =IFERROR(_xlfn.XLOOKUP(LARGE('DONNÉES BRUTES'!AA$3:AA$90,5),'DONNÉES BRUTES'!AA$3:AA$90,'DONNÉES BRUTES'!A$3:A$90),"—") -> MU | P12: =IFERROR(_xlfn.XLOOKUP(O12,'DONNÉES BRUTES'!A$3:A$90,'DONNÉES BRUTES'!B$3:B$90),"—") -> Micron Technology, Inc. | Q12: =IFERROR(_xlfn.XLOOKUP(O12,'DONNÉES BRUTES'!A$3:A$90,'DONNÉES BRUTES'!AA$3:AA$90)&"/100","—") -> 95/100 | R12: =IFERROR(_xlfn.XLOOKUP(O12,'DONNÉES BRUTES'!A$3:A$90,'DONNÉES BRUTES'!W$3:W$90),"—") -> +283.3%
B14: TOP 10 GLOBAL · Score Composite · Growth / Quality / Momentum
B15: # | C15: Ticker | D15: Société | E15: Score | G15: Growth | H15: Quality | I15: Momentum | K15: Mg EBITDA | L15: Croiss. Rev | N15: Next Earn. | O15: Signal
B16: 1 | C16: =IFERROR(_xlfn.XLOOKUP(LARGE('DONNÉES BRUTES'!AB$3:AB$90,1),'DONNÉES BRUTES'!AB$3:AB$90,'DONNÉES BRUTES'!A$3:A$90),"—") -> NVDA | D16: =IFERROR(_xlfn.XLOOKUP(C16,'DONNÉES BRUTES'!A$3:A$90,'DONNÉES BRUTES'!B$3:B$90),"—") -> NVIDIA Corporation | E16: =IFERROR(_xlfn.XLOOKUP(C16,'DONNÉES BRUTES'!A$3:A$90,'DONNÉES BRUTES'!AB$3:AB$90)&"/100","—") -> 88/100 | G16: =IFERROR(_xlfn.XLOOKUP(C16,'DONNÉES BRUTES'!A$3:A$90,'DONNÉES BRUTES'!Y$3:Y$90),"—") -> 95 | H16: =IFERROR(_xlfn.XLOOKUP(C16,'DONNÉES BRUTES'!A$3:A$90,'DONNÉES BRUTES'!Z$3:Z$90),"—") -> 98 | I16: =IFERROR(_xlfn.XLOOKUP(C16,'DONNÉES BRUTES'!A$3:A$90,'DONNÉES BRUTES'!AA$3:AA$90),"—") -> 70 | K16: =IFERROR(_xlfn.XLOOKUP(C16,'DONNÉES BRUTES'!A$3:A$90,'DONNÉES BRUTES'!N$3:N$90),"—") -> 66.9% | L16: =IFERROR(_xlfn.XLOOKUP(C16,'DONNÉES BRUTES'!A$3:A$90,'DONNÉES BRUTES'!P$3:P$90),"—") -> +65.5% | N16: =IFERROR(_xlfn.XLOOKUP(C16,'DONNÉES BRUTES'!A$3:A$90,'DONNÉES BRUTES'!AC$3:AC$90),"—") -> 2026-05-20 | O16: =IFERROR(_xlfn.XLOOKUP(C16,'DONNÉES BRUTES'!A$3:A$90,'DONNÉES BRUTES'!AD$3:AD$90),"—") -> Surpondérer
B17: 2 | C17: =IFERROR(_xlfn.XLOOKUP(LARGE('DONNÉES BRUTES'!AB$3:AB$90,2),'DONNÉES BRUTES'!AB$3:AB$90,'DONNÉES BRUTES'!A$3:A$90),"—") -> KLAC | D17: =IFERROR(_xlfn.XLOOKUP(C17,'DONNÉES BRUTES'!A$3:A$90,'DONNÉES BRUTES'!B$3:B$90),"—") -> KLA Corporation | E17: =IFERROR(_xlfn.XLOOKUP(C17,'DONNÉES BRUTES'!A$3:A$90,'DONNÉES BRUTES'!AB$3:AB$90)&"/100","—") -> 84/100 | G17: =IFERROR(_xlfn.XLOOKUP(C17,'DONNÉES BRUTES'!A$3:A$90,'DONNÉES BRUTES'!Y$3:Y$90),"—") -> 85 | H17: =IFERROR(_xlfn.XLOOKUP(C17,'DONNÉES BRUTES'!A$3:A$90,'DONNÉES BRUTES'!Z$3:Z$90),"—") -> 79 | I17: =IFERROR(_xlfn.XLOOKUP(C17,'DONNÉES BRUTES'!A$3:A$90,'DONNÉES BRUTES'!AA$3:AA$90),"—") -> 88 | K17: =IFERROR(_xlfn.XLOOKUP(C17,'DONNÉES BRUTES'!A$3:A$90,'DONNÉES BRUTES'!N$3:N$90),"—") -> 43.9% | L17: =IFERROR(_xlfn.XLOOKUP(C17,'DONNÉES BRUTES'!A$3:A$90,'DONNÉES BRUTES'!P$3:P$90),"—") -> +23.9% | N17: =IFERROR(_xlfn.XLOOKUP(C17,'DONNÉES BRUTES'!A$3:A$90,'DONNÉES BRUTES'!AC$3:AC$90),"—") -> 2026-04-29 | O17: =IFERROR(_xlfn.XLOOKUP(C17,'DONNÉES BRUTES'!A$3:A$90,'DONNÉES BRUTES'!AD$3:AD$90),"—") -> Surpondérer
B18: 3 | C18: =IFERROR(_xlfn.XLOOKUP(LARGE('DONNÉES BRUTES'!AB$3:AB$90,3),'DONNÉES BRUTES'!AB$3:AB$90,'DONNÉES BRUTES'!A$3:A$90),"—") -> ANET | D18: =IFERROR(_xlfn.XLOOKUP(C18,'DONNÉES BRUTES'!A$3:A$90,'DONNÉES BRUTES'!B$3:B$90),"—") -> Arista Networks, Inc. | E18: =IFERROR(_xlfn.XLOOKUP(C18,'DONNÉES BRUTES'!A$3:A$90,'DONNÉES BRUTES'!AB$3:AB$90)&"/100","—") -> 83/100 | G18: =IFERROR(_xlfn.XLOOKUP(C18,'DONNÉES BRUTES'!A$3:A$90,'DONNÉES BRUTES'!Y$3:Y$90),"—") -> 84 | H18: =IFERROR(_xlfn.XLOOKUP(C18,'DONNÉES BRUTES'!A$3:A$90,'DONNÉES BRUTES'!Z$3:Z$90),"—") -> 89 | I18: =IFERROR(_xlfn.XLOOKUP(C18,'DONNÉES BRUTES'!A$3:A$90,'DONNÉES BRUTES'!AA$3:AA$90),"—") -> 76 | K18: =IFERROR(_xlfn.XLOOKUP(C18,'DONNÉES BRUTES'!A$3:A$90,'DONNÉES BRUTES'!N$3:N$90),"—") -> 43.6% | L18: =IFERROR(_xlfn.XLOOKUP(C18,'DONNÉES BRUTES'!A$3:A$90,'DONNÉES BRUTES'!P$3:P$90),"—") -> +28.6% | N18: =IFERROR(_xlfn.XLOOKUP(C18,'DONNÉES BRUTES'!A$3:A$90,'DONNÉES BRUTES'!AC$3:AC$90),"—") -> 2026-05-05 | O18: =IFERROR(_xlfn.XLOOKUP(C18,'DONNÉES BRUTES'!A$3:A$90,'DONNÉES BRUTES'!AD$3:AD$90),"—") -> Surpondérer
B19: 4 | C19: =IFERROR(_xlfn.XLOOKUP(LARGE('DONNÉES BRUTES'!AB$3:AB$90,4),'DONNÉES BRUTES'!AB$3:AB$90,'DONNÉES BRUTES'!A$3:A$90),"—") -> AVGO | D19: =IFERROR(_xlfn.XLOOKUP(C19,'DONNÉES BRUTES'!A$3:A$90,'DONNÉES BRUTES'!B$3:B$90),"—") -> Broadcom Inc. | E19: =IFERROR(_xlfn.XLOOKUP(C19,'DONNÉES BRUTES'!A$3:A$90,'DONNÉES BRUTES'!AB$3:AB$90)&"/100","—") -> 81/100 | G19: =IFERROR(_xlfn.XLOOKUP(C19,'DONNÉES BRUTES'!A$3:A$90,'DONNÉES BRUTES'!Y$3:Y$90),"—") -> 90 | H19: =IFERROR(_xlfn.XLOOKUP(C19,'DONNÉES BRUTES'!A$3:A$90,'DONNÉES BRUTES'!Z$3:Z$90),"—") -> 85 | I19: =IFERROR(_xlfn.XLOOKUP(C19,'DONNÉES BRUTES'!A$3:A$90,'DONNÉES BRUTES'!AA$3:AA$90),"—") -> 69 | K19: =IFERROR(_xlfn.XLOOKUP(C19,'DONNÉES BRUTES'!A$3:A$90,'DONNÉES BRUTES'!N$3:N$90),"—") -> 54.3% | L19: =IFERROR(_xlfn.XLOOKUP(C19,'DONNÉES BRUTES'!A$3:A$90,'DONNÉES BRUTES'!P$3:P$90),"—") -> +23.9% | N19: =IFERROR(_xlfn.XLOOKUP(C19,'DONNÉES BRUTES'!A$3:A$90,'DONNÉES BRUTES'!AC$3:AC$90),"—") -> 2026-06-03 | O19: =IFERROR(_xlfn.XLOOKUP(C19,'DONNÉES BRUTES'!A$3:A$90,'DONNÉES BRUTES'!AD$3:AD$90),"—") -> Surpondérer
B20: 5 | C20: =IFERROR(_xlfn.XLOOKUP(LARGE('DONNÉES BRUTES'!AB$3:AB$90,5),'DONNÉES BRUTES'!AB$3:AB$90,'DONNÉES BRUTES'!A$3:A$90),"—") -> MU | D20: =IFERROR(_xlfn.XLOOKUP(C20,'DONNÉES BRUTES'!A$3:A$90,'DONNÉES BRUTES'!B$3:B$90),"—") -> Micron Technology, Inc. | E20: =IFERROR(_xlfn.XLOOKUP(C20,'DONNÉES BRUTES'!A$3:A$90,'DONNÉES BRUTES'!AB$3:AB$90)&"/100","—") -> 78/100 | G20: =IFERROR(_xlfn.XLOOKUP(C20,'DONNÉES BRUTES'!A$3:A$90,'DONNÉES BRUTES'!Y$3:Y$90),"—") -> 98 | H20: =IFERROR(_xlfn.XLOOKUP(C20,'DONNÉES BRUTES'!A$3:A$90,'DONNÉES BRUTES'!Z$3:Z$90),"—") -> 41 | I20: =IFERROR(_xlfn.XLOOKUP(C20,'DONNÉES BRUTES'!A$3:A$90,'DONNÉES BRUTES'!AA$3:AA$90),"—") -> 95 | K20: =IFERROR(_xlfn.XLOOKUP(C20,'DONNÉES BRUTES'!A$3:A$90,'DONNÉES BRUTES'!N$3:N$90),"—") -> 49.4% | L20: =IFERROR(_xlfn.XLOOKUP(C20,'DONNÉES BRUTES'!A$3:A$90,'DONNÉES BRUTES'!P$3:P$90),"—") -> +48.9% | N20: =IFERROR(_xlfn.XLOOKUP(C20,'DONNÉES BRUTES'!A$3:A$90,'DONNÉES BRUTES'!AC$3:AC$90),"—") -> — | O20: =IFERROR(_xlfn.XLOOKUP(C20,'DONNÉES BRUTES'!A$3:A$90,'DONNÉES BRUTES'!AD$3:AD$90),"—") -> Surpondérer
B21: 6 | C21: =IFERROR(_xlfn.XLOOKUP(LARGE('DONNÉES BRUTES'!AB$3:AB$90,6),'DONNÉES BRUTES'!AB$3:AB$90,'DONNÉES BRUTES'!A$3:A$90),"—") -> MU | D21: =IFERROR(_xlfn.XLOOKUP(C21,'DONNÉES BRUTES'!A$3:A$90,'DONNÉES BRUTES'!B$3:B$90),"—") -> Micron Technology, Inc. | E21: =IFERROR(_xlfn.XLOOKUP(C21,'DONNÉES BRUTES'!A$3:A$90,'DONNÉES BRUTES'!AB$3:AB$90)&"/100","—") -> 78/100 | G21: =IFERROR(_xlfn.XLOOKUP(C21,'DONNÉES BRUTES'!A$3:A$90,'DONNÉES BRUTES'!Y$3:Y$90),"—") -> 98 | H21: =IFERROR(_xlfn.XLOOKUP(C21,'DONNÉES BRUTES'!A$3:A$90,'DONNÉES BRUTES'!Z$3:Z$90),"—") -> 41 | I21: =IFERROR(_xlfn.XLOOKUP(C21,'DONNÉES BRUTES'!A$3:A$90,'DONNÉES BRUTES'!AA$3:AA$90),"—") -> 95 | K21: =IFERROR(_xlfn.XLOOKUP(C21,'DONNÉES BRUTES'!A$3:A$90,'DONNÉES BRUTES'!N$3:N$90),"—") -> 49.4% | L21: =IFERROR(_xlfn.XLOOKUP(C21,'DONNÉES BRUTES'!A$3:A$90,'DONNÉES BRUTES'!P$3:P$90),"—") -> +48.9% | N21: =IFERROR(_xlfn.XLOOKUP(C21,'DONNÉES BRUTES'!A$3:A$90,'DONNÉES BRUTES'!AC$3:AC$90),"—") -> — | O21: =IFERROR(_xlfn.XLOOKUP(C21,'DONNÉES BRUTES'!A$3:A$90,'DONNÉES BRUTES'!AD$3:AD$90),"—") -> Surpondérer
B22: 7 | C22: =IFERROR(_xlfn.XLOOKUP(LARGE('DONNÉES BRUTES'!AB$3:AB$90,7),'DONNÉES BRUTES'!AB$3:AB$90,'DONNÉES BRUTES'!A$3:A$90),"—") -> LRCX | D22: =IFERROR(_xlfn.XLOOKUP(C22,'DONNÉES BRUTES'!A$3:A$90,'DONNÉES BRUTES'!B$3:B$90),"—") -> Lam Research Corporation | E22: =IFERROR(_xlfn.XLOOKUP(C22,'DONNÉES BRUTES'!A$3:A$90,'DONNÉES BRUTES'!AB$3:AB$90)&"/100","—") -> 77/100 | G22: =IFERROR(_xlfn.XLOOKUP(C22,'DONNÉES BRUTES'!A$3:A$90,'DONNÉES BRUTES'!Y$3:Y$90),"—") -> 83 | H22: =IFERROR(_xlfn.XLOOKUP(C22,'DONNÉES BRUTES'!A$3:A$90,'DONNÉES BRUTES'!Z$3:Z$90),"—") -> 57 | I22: =IFERROR(_xlfn.XLOOKUP(C22,'DONNÉES BRUTES'!A$3:A$90,'DONNÉES BRUTES'!AA$3:AA$90),"—") -> 92 | K22: =IFERROR(_xlfn.XLOOKUP(C22,'DONNÉES BRUTES'!A$3:A$90,'DONNÉES BRUTES'!N$3:N$90),"—") -> 35.4% | L22: =IFERROR(_xlfn.XLOOKUP(C22,'DONNÉES BRUTES'!A$3:A$90,'DONNÉES BRUTES'!P$3:P$90),"—") -> +23.7% | N22: =IFERROR(_xlfn.XLOOKUP(C22,'DONNÉES BRUTES'!A$3:A$90,'DONNÉES BRUTES'!AC$3:AC$90),"—") -> 2026-04-22 | O22: =IFERROR(_xlfn.XLOOKUP(C22,'DONNÉES BRUTES'!A$3:A$90,'DONNÉES BRUTES'!AD$3:AD$90),"—") -> Surpondérer
B23: 8 | C23: =IFERROR(_xlfn.XLOOKUP(LARGE('DONNÉES BRUTES'!AB$3:AB$90,8),'DONNÉES BRUTES'!AB$3:AB$90,'DONNÉES BRUTES'!A$3:A$90),"—") -> LRCX | D23: =IFERROR(_xlfn.XLOOKUP(C23,'DONNÉES BRUTES'!A$3:A$90,'DONNÉES BRUTES'!B$3:B$90),"—") -> Lam Research Corporation | E23: =IFERROR(_xlfn.XLOOKUP(C23,'DONNÉES BRUTES'!A$3:A$90,'DONNÉES BRUTES'!AB$3:AB$90)&"/100","—") -> 77/100 | G23: =IFERROR(_xlfn.XLOOKUP(C23,'DONNÉES BRUTES'!A$3:A$90,'DONNÉES BRUTES'!Y$3:Y$90),"—") -> 83 | H23: =IFERROR(_xlfn.XLOOKUP(C23,'DONNÉES BRUTES'!A$3:A$90,'DONNÉES BRUTES'!Z$3:Z$90),"—") -> 57 | I23: =IFERROR(_xlfn.XLOOKUP(C23,'DONNÉES BRUTES'!A$3:A$90,'DONNÉES BRUTES'!AA$3:AA$90),"—") -> 92 | K23: =IFERROR(_xlfn.XLOOKUP(C23,'DONNÉES BRUTES'!A$3:A$90,'DONNÉES BRUTES'!N$3:N$90),"—") -> 35.4% | L23: =IFERROR(_xlfn.XLOOKUP(C23,'DONNÉES BRUTES'!A$3:A$90,'DONNÉES BRUTES'!P$3:P$90),"—") -> +23.7% | N23: =IFERROR(_xlfn.XLOOKUP(C23,'DONNÉES BRUTES'!A$3:A$90,'DONNÉES BRUTES'!AC$3:AC$90),"—") -> 2026-04-22 | O23: =IFERROR(_xlfn.XLOOKUP(C23,'DONNÉES BRUTES'!A$3:A$90,'DONNÉES BRUTES'!AD$3:AD$90),"—") -> Surpondérer
B24: 9 | C24: =IFERROR(_xlfn.XLOOKUP(LARGE('DONNÉES BRUTES'!AB$3:AB$90,9),'DONNÉES BRUTES'!AB$3:AB$90,'DONNÉES BRUTES'!A$3:A$90),"—") -> PTC | D24: =IFERROR(_xlfn.XLOOKUP(C24,'DONNÉES BRUTES'!A$3:A$90,'DONNÉES BRUTES'!B$3:B$90),"—") -> PTC Inc. | E24: =IFERROR(_xlfn.XLOOKUP(C24,'DONNÉES BRUTES'!A$3:A$90,'DONNÉES BRUTES'!AB$3:AB$90)&"/100","—") -> 74/100 | G24: =IFERROR(_xlfn.XLOOKUP(C24,'DONNÉES BRUTES'!A$3:A$90,'DONNÉES BRUTES'!Y$3:Y$90),"—") -> 91 | H24: =IFERROR(_xlfn.XLOOKUP(C24,'DONNÉES BRUTES'!A$3:A$90,'DONNÉES BRUTES'!Z$3:Z$90),"—") -> 94 | I24: =IFERROR(_xlfn.XLOOKUP(C24,'DONNÉES BRUTES'!A$3:A$90,'DONNÉES BRUTES'!AA$3:AA$90),"—") -> 37 | K24: =IFERROR(_xlfn.XLOOKUP(C24,'DONNÉES BRUTES'!A$3:A$90,'DONNÉES BRUTES'!N$3:N$90),"—") -> 41.3% | L24: =IFERROR(_xlfn.XLOOKUP(C24,'DONNÉES BRUTES'!A$3:A$90,'DONNÉES BRUTES'!P$3:P$90),"—") -> +19.2% | N24: =IFERROR(_xlfn.XLOOKUP(C24,'DONNÉES BRUTES'!A$3:A$90,'DONNÉES BRUTES'!AC$3:AC$90),"—") -> 2026-04-29 | O24: =IFERROR(_xlfn.XLOOKUP(C24,'DONNÉES BRUTES'!A$3:A$90,'DONNÉES BRUTES'!AD$3:AD$90),"—") -> Neutre
B25: 10 | C25: =IFERROR(_xlfn.XLOOKUP(LARGE('DONNÉES BRUTES'!AB$3:AB$90,10),'DONNÉES BRUTES'!AB$3:AB$90,'DONNÉES BRUTES'!A$3:A$90),"—") -> AMD | D25: =IFERROR(_xlfn.XLOOKUP(C25,'DONNÉES BRUTES'!A$3:A$90,'DONNÉES BRUTES'!B$3:B$90),"—") -> Advanced Micro Devices, Inc. | E25: =IFERROR(_xlfn.XLOOKUP(C25,'DONNÉES BRUTES'!A$3:A$90,'DONNÉES BRUTES'!AB$3:AB$90)&"/100","—") -> 73/100 | G25: =IFERROR(_xlfn.XLOOKUP(C25,'DONNÉES BRUTES'!A$3:A$90,'DONNÉES BRUTES'!Y$3:Y$90),"—") -> 92 | H25: =IFERROR(_xlfn.XLOOKUP(C25,'DONNÉES BRUTES'!A$3:A$90,'DONNÉES BRUTES'!Z$3:Z$90),"—") -> 40 | I25: =IFERROR(_xlfn.XLOOKUP(C25,'DONNÉES BRUTES'!A$3:A$90,'DONNÉES BRUTES'!AA$3:AA$90),"—") -> 87 | K25: =IFERROR(_xlfn.XLOOKUP(C25,'DONNÉES BRUTES'!A$3:A$90,'DONNÉES BRUTES'!N$3:N$90),"—") -> 21.0% | L25: =IFERROR(_xlfn.XLOOKUP(C25,'DONNÉES BRUTES'!A$3:A$90,'DONNÉES BRUTES'!P$3:P$90),"—") -> +34.3% | N25: =IFERROR(_xlfn.XLOOKUP(C25,'DONNÉES BRUTES'!A$3:A$90,'DONNÉES BRUTES'!AC$3:AC$90),"—") -> 2026-05-05 | O25: =IFERROR(_xlfn.XLOOKUP(C25,'DONNÉES BRUTES'!A$3:A$90,'DONNÉES BRUTES'!AD$3:AD$90),"—") -> Neutre
B27: FinSight IA · Screening Technologie · Scores calculés sur métriques Growth, Quality, Momentum · Ne constitue pas un conseil en investissement

Sheet VALUE
B1: FinSight IA · Analyse VALUE · Technology Screening · 22/03/2026 (ScoreVal N/A → classé par Score Global) | P1: Ticker | Q1: Score | S1: Ticker | T1: Mg% | V1: Ticker | W1: Altman Z | Y1: Signal | Z1: Nb
B2: Usage confidentiel · Calculs FinSight IA · Screening Technology | P2: NVDA | Q2: 88 | S2: NVDA | T2: 66.9 | V2: NVDA | W2: 13.22 | Y2: Surpondérer | Z2: 8
C3: =COUNTA('DONNÉES BRUTES'!A$3:A$90) -> 88 | H3: =IFERROR(_xlfn.XLOOKUP(LARGE('DONNÉES BRUTES'!AB$3:AB$90,1),'DONNÉES BRUTES'!AB$3:AB$90,'DONNÉES BRUTES'!A$3:A$90),"—") -> NVDA | M3: =IFERROR(ROUND(AVERAGE('DONNÉES BRUTES'!AB$3:AB$90),0)&"/100","—") -> 50/100 | P3: KLAC | Q3: 84 | S3: KLAC | T3: 43.9 | V3: KLAC | W3: 5.64 | Y3: Neutre | Z3: 29
C4: Sociétés | H4: #1 Score Global | M4: Moy. Score Score Global | P4: ANET | Q4: 83 | S4: ANET | T4: 43.6 | V4: ANET | W4: 8.46 | Y4: Sous-pondérer | Z4: 51
B5: ANALYSE DÉTAILLÉE · TECHNOLOGY · TOP 20 par Score Global · Triée par Score Score Global | P5: AVGO | Q5: 81 | S5: AVGO | T5: 54.3 | V5: AVGO | W5: 2.66
B6: # | C6: Ticker | D6: Société | F6: Score | G6: EV/EBITDA | H6: EV/Rev | I6: P/E | J6: Mg Brute | K6: Mg EBITDA | L6: Altman Z | M6: FCF Yield | N6: Signal | P6: MU | Q6: 78 | S6: MU | T6: 49.4 | V6: MU | W6: 6.1
B7: 1 | C7: =IFERROR(_xlfn.XLOOKUP(LARGE('DONNÉES BRUTES'!AB$3:AB$90,1),'DONNÉES BRUTES'!AB$3:AB$90,'DONNÉES BRUTES'!A$3:A$90),"—") -> NVDA | D7: =IFERROR(_xlfn.XLOOKUP(C7,'DONNÉES BRUTES'!A$3:A$90,'DONNÉES BRUTES'!B$3:B$90),"—") -> NVIDIA Corporation | F7: =IFERROR(_xlfn.XLOOKUP(C7,'DONNÉES BRUTES'!A$3:A$90,'DONNÉES BRUTES'!AB$3:AB$90)&"/100","—") -> 88/100 | G7: =IFERROR(_xlfn.XLOOKUP(C7,'DONNÉES BRUTES'!A$3:A$90,'DONNÉES BRUTES'!I$3:I$90),"—") -> — | H7: =IFERROR(_xlfn.XLOOKUP(C7,'DONNÉES BRUTES'!A$3:A$90,'DONNÉES BRUTES'!J$3:J$90),"—") -> — | I7: =IFERROR(_xlfn.XLOOKUP(C7,'DONNÉES BRUTES'!A$3:A$90,'DONNÉES BRUTES'!K$3:K$90),"—") -> — | J7: =IFERROR(_xlfn.XLOOKUP(C7,'DONNÉES BRUTES'!A$3:A$90,'DONNÉES BRUTES'!M$3:M$90),"—") -> 71.1% | K7: =IFERROR(_xlfn.XLOOKUP(C7,'DONNÉES BRUTES'!A$3:A$90,'DONNÉES BRUTES'!N$3:N$90),"—") -> 66.9% | L7: =IFERROR(_xlfn.XLOOKUP(C7,'DONNÉES BRUTES'!A$3:A$90,'DONNÉES BRUTES'!U$3:U$90),"—") -> 13.22 | M7: — | N7: =IFERROR(_xlfn.XLOOKUP(C7,'DONNÉES BRUTES'!A$3:A$90,'DONNÉES BRUTES'!AD$3:AD$90),"—") -> Surpondérer | P7: MPWR | Q7: 78 | S7: MPWR | T7: 28 | V7: MPWR | W7: 11.63
B8: 2 | C8: =IFERROR(_xlfn.XLOOKUP(LARGE('DONNÉES BRUTES'!AB$3:AB$90,2),'DONNÉES BRUTES'!AB$3:AB$90,'DONNÉES BRUTES'!A$3:A$90),"—") -> KLAC | D8: =IFERROR(_xlfn.XLOOKUP(C8,'DONNÉES BRUTES'!A$3:A$90,'DONNÉES BRUTES'!B$3:B$90),"—") -> KLA Corporation | F8: =IFERROR(_xlfn.XLOOKUP(C8,'DONNÉES BRUTES'!A$3:A$90,'DONNÉES BRUTES'!AB$3:AB$90)&"/100","—") -> 84/100 | G8: =IFERROR(_xlfn.XLOOKUP(C8,'DONNÉES BRUTES'!A$3:A$90,'DONNÉES BRUTES'!I$3:I$90),"—") -> — | H8: =IFERROR(_xlfn.XLOOKUP(C8,'DONNÉES BRUTES'!A$3:A$90,'DONNÉES BRUTES'!J$3:J$90),"—") -> — | I8: =IFERROR(_xlfn.XLOOKUP(C8,'DONNÉES BRUTES'!A$3:A$90,'DONNÉES BRUTES'!K$3:K$90),"—") -> — | J8: =IFERROR(_xlfn.XLOOKUP(C8,'DONNÉES BRUTES'!A$3:A$90,'DONNÉES BRUTES'!M$3:M$90),"—") -> 60.9% | K8: =IFERROR(_xlfn.XLOOKUP(C8,'DONNÉES BRUTES'!A$3:A$90,'DONNÉES BRUTES'!N$3:N$90),"—") -> 43.9% | L8: =IFERROR(_xlfn.XLOOKUP(C8,'DONNÉES BRUTES'!A$3:A$90,'DONNÉES BRUTES'!U$3:U$90),"—") -> 5.64 | M8: — | N8: =IFERROR(_xlfn.XLOOKUP(C8,'DONNÉES BRUTES'!A$3:A$90,'DONNÉES BRUTES'!AD$3:AD$90),"—") -> Surpondérer | P8: LRCX | Q8: 77 | S8: LRCX | T8: 35.4 | V8: LRCX | W8: 9.7
B9: 3 | C9: =IFERROR(_xlfn.XLOOKUP(LARGE('DONNÉES BRUTES'!AB$3:AB$90,3),'DONNÉES BRUTES'!AB$3:AB$90,'DONNÉES BRUTES'!A$3:A$90),"—") -> ANET | D9: =IFERROR(_xlfn.XLOOKUP(C9,'DONNÉES BRUTES'!A$3:A$90,'DONNÉES BRUTES'!B$3:B$90),"—") -> Arista Networks, Inc. | F9: =IFERROR(_xlfn.XLOOKUP(C9,'DONNÉES BRUTES'!A$3:A$90,'DONNÉES BRUTES'!AB$3:AB$90)&"/100","—") -> 83/100 | G9: =IFERROR(_xlfn.XLOOKUP(C9,'DONNÉES BRUTES'!A$3:A$90,'DONNÉES BRUTES'!I$3:I$90),"—") -> — | H9: =IFERROR(_xlfn.XLOOKUP(C9,'DONNÉES BRUTES'!A$3:A$90,'DONNÉES BRUTES'!J$3:J$90),"—") -> — | I9: =IFERROR(_xlfn.XLOOKUP(C9,'DONNÉES BRUTES'!A$3:A$90,'DONNÉES BRUTES'!K$3:K$90),"—") -> — | J9: =IFERROR(_xlfn.XLOOKUP(C9,'DONNÉES BRUTES'!A$3:A$90,'DONNÉES BRUTES'!M$3:M$90),"—") -> 64.1% | K9: =IFERROR(_xlfn.XLOOKUP(C9,'DONNÉES BRUTES'!A$3:A$90,'DONNÉES BRUTES'!N$3:N$90),"—") -> 43.6% | L9: =IFERROR(_xlfn.XLOOKUP(C9,'DONNÉES BRUTES'!A$3:A$90,'DONNÉES BRUTES'!U$3:U$90),"—") -> 8.46 | M9: — | N9: =IFERROR(_xlfn.XLOOKUP(C9,'DONNÉES BRUTES'!A$3:A$90,'DONNÉES BRUTES'!AD$3:AD$90),"—") -> Surpondérer | P9: WDC | Q9: 77 | S9: WDC | T9: 20.4 | V9: WDC | W9: 1.76
B10: 4 | C10: =IFERROR(_xlfn.XLOOKUP(LARGE('DONNÉES BRUTES'!AB$3:AB$90,4),'DONNÉES BRUTES'!AB$3:AB$90,'DONNÉES BRUTES'!A$3:A$90),"—") -> AVGO | D10: =IFERROR(_xlfn.XLOOKUP(C10,'DONNÉES BRUTES'!A$3:A$90,'DONNÉES BRUTES'!B$3:B$90),"—") -> Broadcom Inc. | F10: =IFERROR(_xlfn.XLOOKUP(C10,'DONNÉES BRUTES'!A$3:A$90,'DONNÉES BRUTES'!AB$3:AB$90)&"/100","—") -> 81/100 | G10: =IFERROR(_xlfn.XLOOKUP(C10,'DONNÉES BRUTES'!A$3:A$90,'DONNÉES BRUTES'!I$3:I$90),"—") -> — | H10: =IFERROR(_xlfn.XLOOKUP(C10,'DONNÉES BRUTES'!A$3:A$90,'DONNÉES BRUTES'!J$3:J$90),"—") -> — | I10: =IFERROR(_xlfn.XLOOKUP(C10,'DONNÉES BRUTES'!A$3:A$90,'DONNÉES BRUTES'!K$3:K$90),"—") -> — | J10: =IFERROR(_xlfn.XLOOKUP(C10,'DONNÉES BRUTES'!A$3:A$90,'DONNÉES BRUTES'!M$3:M$90),"—") -> 67.8% | K10: =IFERROR(_xlfn.XLOOKUP(C10,'DONNÉES BRUTES'!A$3:A$90,'DONNÉES BRUTES'!N$3:N$90),"—") -> 54.3% | L10: =IFERROR(_xlfn.XLOOKUP(C10,'DONNÉES BRUTES'!A$3:A$90,'DONNÉES BRUTES'!U$3:U$90),"—") -> 2.66 | M10: — | N10: =IFERROR(_xlfn.XLOOKUP(C10,'DONNÉES BRUTES'!A$3:A$90,'DONNÉES BRUTES'!AD$3:AD$90),"—") -> Surpondérer | P10: PTC | Q10: 74 | S10: PTC | T10: 41.3 | V10: PTC | W10: 3.62
B11: 5 | C11: =IFERROR(_xlfn.XLOOKUP(LARGE('DONNÉES BRUTES'!AB$3:AB$90,5),'DONNÉES BRUTES'!AB$3:AB$90,'DONNÉES BRUTES'!A$3:A$90),"—") -> MU | D11: =IFERROR(_xlfn.XLOOKUP(C11,'DONNÉES BRUTES'!A$3:A$90,'DONNÉES BRUTES'!B$3:B$90),"—") -> Micron Technology, Inc. | F11: =IFERROR(_xlfn.XLOOKUP(C11,'DONNÉES BRUTES'!A$3:A$90,'DONNÉES BRUTES'!AB$3:AB$90)&"/100","—") -> 78/100 | G11: =IFERROR(_xlfn.XLOOKUP(C11,'DONNÉES BRUTES'!A$3:A$90,'DONNÉES BRUTES'!I$3:I$90),"—") -> — | H11: =IFERROR(_xlfn.XLOOKUP(C11,'DONNÉES BRUTES'!A$3:A$90,'DONNÉES BRUTES'!J$3:J$90),"—") -> — | I11: =IFERROR(_xlfn.XLOOKUP(C11,'DONNÉES BRUTES'!A$3:A$90,'DONNÉES BRUTES'!K$3:K$90),"—") -> — | J11: =IFERROR(_xlfn.XLOOKUP(C11,'DONNÉES BRUTES'!A$3:A$90,'DONNÉES BRUTES'!M$3:M$90),"—") -> 39.8% | K11: =IFERROR(_xlfn.XLOOKUP(C11,'DONNÉES BRUTES'!A$3:A$90,'DONNÉES BRUTES'!N$3:N$90),"—") -> 49.4% | L11: =IFERROR(_xlfn.XLOOKUP(C11,'DONNÉES BRUTES'!A$3:A$90,'DONNÉES BRUTES'!U$3:U$90),"—") -> 6.10 | M11: — | N11: =IFERROR(_xlfn.XLOOKUP(C11,'DONNÉES BRUTES'!A$3:A$90,'DONNÉES BRUTES'!AD$3:AD$90),"—") -> Surpondérer | P11: AMD | Q11: 73 | S11: AMD | T11: 21 | V11: AMD | W11: 6.9
B12: 6 | C12: =IFERROR(_xlfn.XLOOKUP(LARGE('DONNÉES BRUTES'!AB$3:AB$90,6),'DONNÉES BRUTES'!AB$3:AB$90,'DONNÉES BRUTES'!A$3:A$90),"—") -> MU | D12: =IFERROR(_xlfn.XLOOKUP(C12,'DONNÉES BRUTES'!A$3:A$90,'DONNÉES BRUTES'!B$3:B$90),"—") -> Micron Technology, Inc. | F12: =IFERROR(_xlfn.XLOOKUP(C12,'DONNÉES BRUTES'!A$3:A$90,'DONNÉES BRUTES'!AB$3:AB$90)&"/100","—") -> 78/100 | G12: =IFERROR(_xlfn.XLOOKUP(C12,'DONNÉES BRUTES'!A$3:A$90,'DONNÉES BRUTES'!I$3:I$90),"—") -> — | H12: =IFERROR(_xlfn.XLOOKUP(C12,'DONNÉES BRUTES'!A$3:A$90,'DONNÉES BRUTES'!J$3:J$90),"—") -> — | I12: =IFERROR(_xlfn.XLOOKUP(C12,'DONNÉES BRUTES'!A$3:A$90,'DONNÉES BRUTES'!K$3:K$90),"—") -> — | J12: =IFERROR(_xlfn.XLOOKUP(C12,'DONNÉES BRUTES'!A$3:A$90,'DONNÉES BRUTES'!M$3:M$90),"—") -> 39.8% | K12: =IFERROR(_xlfn.XLOOKUP(C12,'DONNÉES BRUTES'!A$3:A$90,'DONNÉES BRUTES'!N$3:N$90),"—") -> 49.4% | L12: =IFERROR(_xlfn.XLOOKUP(C12,'DONNÉES BRUTES'!A$3:A$90,'DONNÉES BRUTES'!U$3:U$90),"—") -> 6.10 | M12: — | N12: =IFERROR(_xlfn.XLOOKUP(C12,'DONNÉES BRUTES'!A$3:A$90,'DONNÉES BRUTES'!AD$3:AD$90),"—") -> Surpondérer | P12: ASML | Q12: 72 | S12: ASML | T12: 38.4 | V12: ASML.AS | W12: 4.15
B13: 7 | C13: =IFERROR(_xlfn.XLOOKUP(LARGE('DONNÉES BRUTES'!AB$3:AB$90,7),'DONNÉES BRUTES'!AB$3:AB$90,'DONNÉES BRUTES'!A$3:A$90),"—") -> LRCX | D13: =IFERROR(_xlfn.XLOOKUP(C13,'DONNÉES BRUTES'!A$3:A$90,'DONNÉES BRUTES'!B$3:B$90),"—") -> Lam Research Corporation | F13: =IFERROR(_xlfn.XLOOKUP(C13,'DONNÉES BRUTES'!A$3:A$90,'DONNÉES BRUTES'!AB$3:AB$90)&"/100","—") -> 77/100 | G13: =IFERROR(_xlfn.XLOOKUP(C13,'DONNÉES BRUTES'!A$3:A$90,'DONNÉES BRUTES'!I$3:I$90),"—") -> — | H13: =IFERROR(_xlfn.XLOOKUP(C13,'DONNÉES BRUTES'!A$3:A$90,'DONNÉES BRUTES'!J$3:J$90),"—") -> — | I13: =IFERROR(_xlfn.XLOOKUP(C13,'DONNÉES BRUTES'!A$3:A$90,'DONNÉES BRUTES'!K$3:K$90),"—") -> — | J13: =IFERROR(_xlfn.XLOOKUP(C13,'DONNÉES BRUTES'!A$3:A$90,'DONNÉES BRUTES'!M$3:M$90),"—") -> 48.7% | K13: =IFERROR(_xlfn.XLOOKUP(C13,'DONNÉES BRUTES'!A$3:A$90,'DONNÉES BRUTES'!N$3:N$90),"—") -> 35.4% | L13: =IFERROR(_xlfn.XLOOKUP(C13,'DONNÉES BRUTES'!A$3:A$90,'DONNÉES BRUTES'!U$3:U$90),"—") -> 9.70 | M13: — | N13: =IFERROR(_xlfn.XLOOKUP(C13,'DONNÉES BRUTES'!A$3:A$90,'DONNÉES BRUTES'!AD$3:AD$90),"—") -> Surpondérer | P13: ADI | Q13: 71 | S13: ADI | T13: 45.6 | V13: ADI | W13: 4.17
B14: 8 | C14: =IFERROR(_xlfn.XLOOKUP(LARGE('DONNÉES BRUTES'!AB$3:AB$90,8),'DONNÉES BRUTES'!AB$3:AB$90,'DONNÉES BRUTES'!A$3:A$90),"—") -> LRCX | D14: =IFERROR(_xlfn.XLOOKUP(C14,'DONNÉES BRUTES'!A$3:A$90,'DONNÉES BRUTES'!B$3:B$90),"—") -> Lam Research Corporation | F14: =IFERROR(_xlfn.XLOOKUP(C14,'DONNÉES BRUTES'!A$3:A$90,'DONNÉES BRUTES'!AB$3:AB$90)&"/100","—") -> 77/100 | G14: =IFERROR(_xlfn.XLOOKUP(C14,'DONNÉES BRUTES'!A$3:A$90,'DONNÉES BRUTES'!I$3:I$90),"—") -> — | H14: =IFERROR(_xlfn.XLOOKUP(C14,'DONNÉES BRUTES'!A$3:A$90,'DONNÉES BRUTES'!J$3:J$90),"—") -> — | I14: =IFERROR(_xlfn.XLOOKUP(C14,'DONNÉES BRUTES'!A$3:A$90,'DONNÉES BRUTES'!K$3:K$90),"—") -> — | J14: =IFERROR(_xlfn.XLOOKUP(C14,'DONNÉES BRUTES'!A$3:A$90,'DONNÉES BRUTES'!M$3:M$90),"—") -> 48.7% | K14: =IFERROR(_xlfn.XLOOKUP(C14,'DONNÉES BRUTES'!A$3:A$90,'DONNÉES BRUTES'!N$3:N$90),"—") -> 35.4% | L14: =IFERROR(_xlfn.XLOOKUP(C14,'DONNÉES BRUTES'!A$3:A$90,'DONNÉES BRUTES'!U$3:U$90),"—") -> 9.70 | M14: — | N14: =IFERROR(_xlfn.XLOOKUP(C14,'DONNÉES BRUTES'!A$3:A$90,'DONNÉES BRUTES'!AD$3:AD$90),"—") -> Surpondérer | P14: GLW | Q14: 68 | S14: GLW | T14: 23.9 | V14: GLW | W14: 3.62
B15: 9 | C15: =IFERROR(_xlfn.XLOOKUP(LARGE('DONNÉES BRUTES'!AB$3:AB$90,9),'DONNÉES BRUTES'!AB$3:AB$90,'DONNÉES BRUTES'!A$3:A$90),"—") -> PTC | D15: =IFERROR(_xlfn.XLOOKUP(C15,'DONNÉES BRUTES'!A$3:A$90,'DONNÉES BRUTES'!B$3:B$90),"—") -> PTC Inc. | F15: =IFERROR(_xlfn.XLOOKUP(C15,'DONNÉES BRUTES'!A$3:A$90,'DONNÉES BRUTES'!AB$3:AB$90)&"/100","—") -> 74/100 | G15: =IFERROR(_xlfn.XLOOKUP(C15,'DONNÉES BRUTES'!A$3:A$90,'DONNÉES BRUTES'!I$3:I$90),"—") -> — | H15: =IFERROR(_xlfn.XLOOKUP(C15,'DONNÉES BRUTES'!A$3:A$90,'DONNÉES BRUTES'!J$3:J$90),"—") -> — | I15: =IFERROR(_xlfn.XLOOKUP(C15,'DONNÉES BRUTES'!A$3:A$90,'DONNÉES BRUTES'!K$3:K$90),"—") -> — | J15: =IFERROR(_xlfn.XLOOKUP(C15,'DONNÉES BRUTES'!A$3:A$90,'DONNÉES BRUTES'!M$3:M$90),"—") -> 83.8% | K15: =IFERROR(_xlfn.XLOOKUP(C15,'DONNÉES BRUTES'!A$3:A$90,'DONNÉES BRUTES'!N$3:N$90),"—") -> 41.3% | L15: =IFERROR(_xlfn.XLOOKUP(C15,'DONNÉES BRUTES'!A$3:A$90,'DONNÉES BRUTES'!U$3:U$90),"—") -> 3.62 | M15: — | N15: =IFERROR(_xlfn.XLOOKUP(C15,'DONNÉES BRUTES'!A$3:A$90,'DONNÉES BRUTES'!AD$3:AD$90),"—") -> Neutre | P15: INTC | Q15: 67 | S15: INTC | T15: 27.2 | V15: INTC | W15: 3.25
B16: 10 | C16: =IFERROR(_xlfn.XLOOKUP(LARGE('DONNÉES BRUTES'!AB$3:AB$90,10),'DONNÉES BRUTES'!AB$3:AB$90,'DONNÉES BRUTES'!A$3:A$90),"—") -> AMD | D16: =IFERROR(_xlfn.XLOOKUP(C16,'DONNÉES BRUTES'!A$3:A$90,'DONNÉES BRUTES'!B$3:B$90),"—") -> Advanced Micro Devices, Inc. | F16: =IFERROR(_xlfn.XLOOKUP(C16,'DONNÉES BRUTES'!A$3:A$90,'DONNÉES BRUTES'!AB$3:AB$90)&"/100","—") -> 73/100 | G16: =IFERROR(_xlfn.XLOOKUP(C16,'DONNÉES BRUTES'!A$3:A$90,'DONNÉES BRUTES'!I$3:I$90),"—") -> — | H16: =IFERROR(_xlfn.XLOOKUP(C16,'DONNÉES BRUTES'!A$3:A$90,'DONNÉES BRUTES'!J$3:J$90),"—") -> — | I16: =IFERROR(_xlfn.XLOOKUP(C16,'DONNÉES BRUTES'!A$3:A$90,'DONNÉES BRUTES'!K$3:K$90),"—") -> — | J16: =IFERROR(_xlfn.XLOOKUP(C16,'DONNÉES BRUTES'!A$3:A$90,'DONNÉES BRUTES'!M$3:M$90),"—") -> 49.5% | K16: =IFERROR(_xlfn.XLOOKUP(C16,'DONNÉES BRUTES'!A$3:A$90,'DONNÉES BRUTES'!N$3:N$90),"—") -> 21.0% | L16: =IFERROR(_xlfn.XLOOKUP(C16,'DONNÉES BRUTES'!A$3:A$90,'DONNÉES BRUTES'!U$3:U$90),"—") -> 6.90 | M16: — | N16: =IFERROR(_xlfn.XLOOKUP(C16,'DONNÉES BRUTES'!A$3:A$90,'DONNÉES BRUTES'!AD$3:AD$90),"—") -> Neutre | P16: KEYS | Q16: 67 | S16: KEYS | T16: 27.1 | V16: KEYS | W16: 5.33
B17: 11 | C17: =IFERROR(_xlfn.XLOOKUP(LARGE('DONNÉES BRUTES'!AB$3:AB$90,11),'DONNÉES BRUTES'!AB$3:AB$90,'DONNÉES BRUTES'!A$3:A$90),"—") -> AMD | D17: =IFERROR(_xlfn.XLOOKUP(C17,'DONNÉES BRUTES'!A$3:A$90,'DONNÉES BRUTES'!B$3:B$90),"—") -> Advanced Micro Devices, Inc. | F17: =IFERROR(_xlfn.XLOOKUP(C17,'DONNÉES BRUTES'!A$3:A$90,'DONNÉES BRUTES'!AB$3:AB$90)&"/100","—") -> 73/100 | G17: =IFERROR(_xlfn.XLOOKUP(C17,'DONNÉES BRUTES'!A$3:A$90,'DONNÉES BRUTES'!I$3:I$90),"—") -> — | H17: =IFERROR(_xlfn.XLOOKUP(C17,'DONNÉES BRUTES'!A$3:A$90,'DONNÉES BRUTES'!J$3:J$90),"—") -> — | I17: =IFERROR(_xlfn.XLOOKUP(C17,'DONNÉES BRUTES'!A$3:A$90,'DONNÉES BRUTES'!K$3:K$90),"—") -> — | J17: =IFERROR(_xlfn.XLOOKUP(C17,'DONNÉES BRUTES'!A$3:A$90,'DONNÉES BRUTES'!M$3:M$90),"—") -> 49.5% | K17: =IFERROR(_xlfn.XLOOKUP(C17,'DONNÉES BRUTES'!A$3:A$90,'DONNÉES BRUTES'!N$3:N$90),"—") -> 21.0% | L17: =IFERROR(_xlfn.XLOOKUP(C17,'DONNÉES BRUTES'!A$3:A$90,'DONNÉES BRUTES'!U$3:U$90),"—") -> 6.90 | M17: — | N17: =IFERROR(_xlfn.XLOOKUP(C17,'DONNÉES BRUTES'!A$3:A$90,'DONNÉES BRUTES'!AD$3:AD$90),"—") -> Neutre | P17: APH | Q17: 66 | S17: APH | T17: 29.8 | V17: APH | W17: 5.05
B18: 12 | C18: =IFERROR(_xlfn.XLOOKUP(LARGE('DONNÉES BRUTES'!AB$3:AB$90,12),'DONNÉES BRUTES'!AB$3:AB$90,'DONNÉES BRUTES'!A$3:A$90),"—") -> ASML.AS | D18: =IFERROR(_xlfn.XLOOKUP(C18,'DONNÉES BRUTES'!A$3:A$90,'DONNÉES BRUTES'!B$3:B$90),"—") -> ASML Holding N.V. | F18: =IFERROR(_xlfn.XLOOKUP(C18,'DONNÉES BRUTES'!A$3:A$90,'DONNÉES BRUTES'!AB$3:AB$90)&"/100","—") -> 72/100 | G18: =IFERROR(_xlfn.XLOOKUP(C18,'DONNÉES BRUTES'!A$3:A$90,'DONNÉES BRUTES'!I$3:I$90),"—") -> — | H18: =IFERROR(_xlfn.XLOOKUP(C18,'DONNÉES BRUTES'!A$3:A$90,'DONNÉES BRUTES'!J$3:J$90),"—") -> — | I18: =IFERROR(_xlfn.XLOOKUP(C18,'DONNÉES BRUTES'!A$3:A$90,'DONNÉES BRUTES'!K$3:K$90),"—") -> — | J18: =IFERROR(_xlfn.XLOOKUP(C18,'DONNÉES BRUTES'!A$3:A$90,'DONNÉES BRUTES'!M$3:M$90),"—") -> 52.8% | K18: =IFERROR(_xlfn.XLOOKUP(C18,'DONNÉES BRUTES'!A$3:A$90,'DONNÉES BRUTES'!N$3:N$90),"—") -> 38.4% | L18: =IFERROR(_xlfn.XLOOKUP(C18,'DONNÉES BRUTES'!A$3:A$90,'DONNÉES BRUTES'!U$3:U$90),"—") -> 4.15 | M18: — | N18: =IFERROR(_xlfn.XLOOKUP(C18,'DONNÉES BRUTES'!A$3:A$90,'DONNÉES BRUTES'!AD$3:AD$90),"—") -> Neutre | P18: CDNS | Q18: 66 | S18: CDNS | T18: 35.4 | V18: CDNS | W18: 6.55
B19: 13 | C19: =IFERROR(_xlfn.XLOOKUP(LARGE('DONNÉES BRUTES'!AB$3:AB$90,13),'DONNÉES BRUTES'!AB$3:AB$90,'DONNÉES BRUTES'!A$3:A$90),"—") -> ADI | D19: =IFERROR(_xlfn.XLOOKUP(C19,'DONNÉES BRUTES'!A$3:A$90,'DONNÉES BRUTES'!B$3:B$90),"—") -> Analog Devices, Inc. | F19: =IFERROR(_xlfn.XLOOKUP(C19,'DONNÉES BRUTES'!A$3:A$90,'DONNÉES BRUTES'!AB$3:AB$90)&"/100","—") -> 71/100 | G19: =IFERROR(_xlfn.XLOOKUP(C19,'DONNÉES BRUTES'!A$3:A$90,'DONNÉES BRUTES'!I$3:I$90),"—") -> — | H19: =IFERROR(_xlfn.XLOOKUP(C19,'DONNÉES BRUTES'!A$3:A$90,'DONNÉES BRUTES'!J$3:J$90),"—") -> — | I19: =IFERROR(_xlfn.XLOOKUP(C19,'DONNÉES BRUTES'!A$3:A$90,'DONNÉES BRUTES'!K$3:K$90),"—") -> — | J19: =IFERROR(_xlfn.XLOOKUP(C19,'DONNÉES BRUTES'!A$3:A$90,'DONNÉES BRUTES'!M$3:M$90),"—") -> 61.5% | K19: =IFERROR(_xlfn.XLOOKUP(C19,'DONNÉES BRUTES'!A$3:A$90,'DONNÉES BRUTES'!N$3:N$90),"—") -> 45.6% | L19: =IFERROR(_xlfn.XLOOKUP(C19,'DONNÉES BRUTES'!A$3:A$90,'DONNÉES BRUTES'!U$3:U$90),"—") -> 4.17 | M19: — | N19: =IFERROR(_xlfn.XLOOKUP(C19,'DONNÉES BRUTES'!A$3:A$90,'DONNÉES BRUTES'!AD$3:AD$90),"—") -> Neutre | P19: SNPS | Q19: 66 | S19: SNPS | T19: 35.4 | V19: SNPS | W19: 2.76
B20: 14 | C20: =IFERROR(_xlfn.XLOOKUP(LARGE('DONNÉES BRUTES'!AB$3:AB$90,14),'DONNÉES BRUTES'!AB$3:AB$90,'DONNÉES BRUTES'!A$3:A$90),"—") -> GLW | D20: =IFERROR(_xlfn.XLOOKUP(C20,'DONNÉES BRUTES'!A$3:A$90,'DONNÉES BRUTES'!B$3:B$90),"—") -> Corning Incorporated | F20: =IFERROR(_xlfn.XLOOKUP(C20,'DONNÉES BRUTES'!A$3:A$90,'DONNÉES BRUTES'!AB$3:AB$90)&"/100","—") -> 68/100 | G20: =IFERROR(_xlfn.XLOOKUP(C20,'DONNÉES BRUTES'!A$3:A$90,'DONNÉES BRUTES'!I$3:I$90),"—") -> — | H20: =IFERROR(_xlfn.XLOOKUP(C20,'DONNÉES BRUTES'!A$3:A$90,'DONNÉES BRUTES'!J$3:J$90),"—") -> — | I20: =IFERROR(_xlfn.XLOOKUP(C20,'DONNÉES BRUTES'!A$3:A$90,'DONNÉES BRUTES'!K$3:K$90),"—") -> — | J20: =IFERROR(_xlfn.XLOOKUP(C20,'DONNÉES BRUTES'!A$3:A$90,'DONNÉES BRUTES'!M$3:M$90),"—") -> 36.0% | K20: =IFERROR(_xlfn.XLOOKUP(C20,'DONNÉES BRUTES'!A$3:A$90,'DONNÉES BRUTES'!N$3:N$90),"—") -> 23.9% | L20: =IFERROR(_xlfn.XLOOKUP(C20,'DONNÉES BRUTES'!A$3:A$90,'DONNÉES BRUTES'!U$3:U$90),"—") -> 3.62 | M20: — | N20: =IFERROR(_xlfn.XLOOKUP(C20,'DONNÉES BRUTES'!A$3:A$90,'DONNÉES BRUTES'!AD$3:AD$90),"—") -> Neutre | P20: TER | Q20: 66 | S20: TER | T20: 24.7 | V20: TER | W20: 5.06
B21: 15 | C21: =IFERROR(_xlfn.XLOOKUP(LARGE('DONNÉES BRUTES'!AB$3:AB$90,15),'DONNÉES BRUTES'!AB$3:AB$90,'DONNÉES BRUTES'!A$3:A$90),"—") -> INTC | D21: =IFERROR(_xlfn.XLOOKUP(C21,'DONNÉES BRUTES'!A$3:A$90,'DONNÉES BRUTES'!B$3:B$90),"—") -> Intel Corporation | F21: =IFERROR(_xlfn.XLOOKUP(C21,'DONNÉES BRUTES'!A$3:A$90,'DONNÉES BRUTES'!AB$3:AB$90)&"/100","—") -> 67/100 | G21: =IFERROR(_xlfn.XLOOKUP(C21,'DONNÉES BRUTES'!A$3:A$90,'DONNÉES BRUTES'!I$3:I$90),"—") -> — | H21: =IFERROR(_xlfn.XLOOKUP(C21,'DONNÉES BRUTES'!A$3:A$90,'DONNÉES BRUTES'!J$3:J$90),"—") -> — | I21: =IFERROR(_xlfn.XLOOKUP(C21,'DONNÉES BRUTES'!A$3:A$90,'DONNÉES BRUTES'!K$3:K$90),"—") -> — | J21: =IFERROR(_xlfn.XLOOKUP(C21,'DONNÉES BRUTES'!A$3:A$90,'DONNÉES BRUTES'!M$3:M$90),"—") -> 34.8% | K21: =IFERROR(_xlfn.XLOOKUP(C21,'DONNÉES BRUTES'!A$3:A$90,'DONNÉES BRUTES'!N$3:N$90),"—") -> 27.2% | L21: =IFERROR(_xlfn.XLOOKUP(C21,'DONNÉES BRUTES'!A$3:A$90,'DONNÉES BRUTES'!U$3:U$90),"—") -> 3.25 | M21: — | N21: =IFERROR(_xlfn.XLOOKUP(C21,'DONNÉES BRUTES'!A$3:A$90,'DONNÉES BRUTES'!AD$3:AD$90),"—") -> Neutre | P21: ADSK | Q21: 65 | S21: ADSK | T21: 27.6 | V21: ADSK | W21: 0.48
B22: 16 | C22: =IFERROR(_xlfn.XLOOKUP(LARGE('DONNÉES BRUTES'!AB$3:AB$90,16),'DONNÉES BRUTES'!AB$3:AB$90,'DONNÉES BRUTES'!A$3:A$90),"—") -> INTC | D22: =IFERROR(_xlfn.XLOOKUP(C22,'DONNÉES BRUTES'!A$3:A$90,'DONNÉES BRUTES'!B$3:B$90),"—") -> Intel Corporation | F22: =IFERROR(_xlfn.XLOOKUP(C22,'DONNÉES BRUTES'!A$3:A$90,'DONNÉES BRUTES'!AB$3:AB$90)&"/100","—") -> 67/100 | G22: =IFERROR(_xlfn.XLOOKUP(C22,'DONNÉES BRUTES'!A$3:A$90,'DONNÉES BRUTES'!I$3:I$90),"—") -> — | H22: =IFERROR(_xlfn.XLOOKUP(C22,'DONNÉES BRUTES'!A$3:A$90,'DONNÉES BRUTES'!J$3:J$90),"—") -> — | I22: =IFERROR(_xlfn.XLOOKUP(C22,'DONNÉES BRUTES'!A$3:A$90,'DONNÉES BRUTES'!K$3:K$90),"—") -> — | J22: =IFERROR(_xlfn.XLOOKUP(C22,'DONNÉES BRUTES'!A$3:A$90,'DONNÉES BRUTES'!M$3:M$90),"—") -> 34.8% | K22: =IFERROR(_xlfn.XLOOKUP(C22,'DONNÉES BRUTES'!A$3:A$90,'DONNÉES BRUTES'!N$3:N$90),"—") -> 27.2% | L22: =IFERROR(_xlfn.XLOOKUP(C22,'DONNÉES BRUTES'!A$3:A$90,'DONNÉES BRUTES'!U$3:U$90),"—") -> 3.25 | M22: — | N22: =IFERROR(_xlfn.XLOOKUP(C22,'DONNÉES BRUTES'!A$3:A$90,'DONNÉES BRUTES'!AD$3:AD$90),"—") -> Neutre
B23: 17 | C23: =IFERROR(_xlfn.XLOOKUP(LARGE('DONNÉES BRUTES'!AB$3:AB$90,17),'DONNÉES BRUTES'!AB$3:AB$90,'DONNÉES BRUTES'!A$3:A$90),"—") -> APH | D23: =IFERROR(_xlfn.XLOOKUP(C23,'DONNÉES BRUTES'!A$3:A$90,'DONNÉES BRUTES'!B$3:B$90),"—") -> Amphenol Corporation | F23: =IFERROR(_xlfn.XLOOKUP(C23,'DONNÉES BRUTES'!A$3:A$90,'DONNÉES BRUTES'!AB$3:AB$90)&"/100","—") -> 66/100 | G23: =IFERROR(_xlfn.XLOOKUP(C23,'DONNÉES BRUTES'!A$3:A$90,'DONNÉES BRUTES'!I$3:I$90),"—") -> — | H23: =IFERROR(_xlfn.XLOOKUP(C23,'DONNÉES BRUTES'!A$3:A$90,'DONNÉES BRUTES'!J$3:J$90),"—") -> — | I23: =IFERROR(_xlfn.XLOOKUP(C23,'DONNÉES BRUTES'!A$3:A$90,'DONNÉES BRUTES'!K$3:K$90),"—") -> — | J23: =IFERROR(_xlfn.XLOOKUP(C23,'DONNÉES BRUTES'!A$3:A$90,'DONNÉES BRUTES'!M$3:M$90),"—") -> 36.9% | K23: =IFERROR(_xlfn.XLOOKUP(C23,'DONNÉES BRUTES'!A$3:A$90,'DONNÉES BRUTES'!N$3:N$90),"—") -> 29.8% | L23: =IFERROR(_xlfn.XLOOKUP(C23,'DONNÉES BRUTES'!A$3:A$90,'DONNÉES BRUTES'!U$3:U$90),"—") -> 5.05 | M23: — | N23: =IFERROR(_xlfn.XLOOKUP(C23,'DONNÉES BRUTES'!A$3:A$90,'DONNÉES BRUTES'!AD$3:AD$90),"—") -> Neutre
B24: 18 | C24: =IFERROR(_xlfn.XLOOKUP(LARGE('DONNÉES BRUTES'!AB$3:AB$90,18),'DONNÉES BRUTES'!AB$3:AB$90,'DONNÉES BRUTES'!A$3:A$90),"—") -> APH | D24: =IFERROR(_xlfn.XLOOKUP(C24,'DONNÉES BRUTES'!A$3:A$90,'DONNÉES BRUTES'!B$3:B$90),"—") -> Amphenol Corporation | F24: =IFERROR(_xlfn.XLOOKUP(C24,'DONNÉES BRUTES'!A$3:A$90,'DONNÉES BRUTES'!AB$3:AB$90)&"/100","—") -> 66/100 | G24: =IFERROR(_xlfn.XLOOKUP(C24,'DONNÉES BRUTES'!A$3:A$90,'DONNÉES BRUTES'!I$3:I$90),"—") -> — | H24: =IFERROR(_xlfn.XLOOKUP(C24,'DONNÉES BRUTES'!A$3:A$90,'DONNÉES BRUTES'!J$3:J$90),"—") -> — | I24: =IFERROR(_xlfn.XLOOKUP(C24,'DONNÉES BRUTES'!A$3:A$90,'DONNÉES BRUTES'!K$3:K$90),"—") -> — | J24: =IFERROR(_xlfn.XLOOKUP(C24,'DONNÉES BRUTES'!A$3:A$90,'DONNÉES BRUTES'!M$3:M$90),"—") -> 36.9% | K24: =IFERROR(_xlfn.XLOOKUP(C24,'DONNÉES BRUTES'!A$3:A$90,'DONNÉES BRUTES'!N$3:N$90),"—") -> 29.8% | L24: =IFERROR(_xlfn.XLOOKUP(C24,'DONNÉES BRUTES'!A$3:A$90,'DONNÉES BRUTES'!U$3:U$90),"—") -> 5.05 | M24: — | N24: =IFERROR(_xlfn.XLOOKUP(C24,'DONNÉES BRUTES'!A$3:A$90,'DONNÉES BRUTES'!AD$3:AD$90),"—") -> Neutre
B25: 19 | C25: =IFERROR(_xlfn.XLOOKUP(LARGE('DONNÉES BRUTES'!AB$3:AB$90,19),'DONNÉES BRUTES'!AB$3:AB$90,'DONNÉES BRUTES'!A$3:A$90),"—") -> APH | D25: =IFERROR(_xlfn.XLOOKUP(C25,'DONNÉES BRUTES'!A$3:A$90,'DONNÉES BRUTES'!B$3:B$90),"—") -> Amphenol Corporation | F25: =IFERROR(_xlfn.XLOOKUP(C25,'DONNÉES BRUTES'!A$3:A$90,'DONNÉES BRUTES'!AB$3:AB$90)&"/100","—") -> 66/100 | G25: =IFERROR(_xlfn.XLOOKUP(C25,'DONNÉES BRUTES'!A$3:A$90,'DONNÉES BRUTES'!I$3:I$90),"—") -> — | H25: =IFERROR(_xlfn.XLOOKUP(C25,'DONNÉES BRUTES'!A$3:A$90,'DONNÉES BRUTES'!J$3:J$90),"—") -> — | I25: =IFERROR(_xlfn.XLOOKUP(C25,'DONNÉES BRUTES'!A$3:A$90,'DONNÉES BRUTES'!K$3:K$90),"—") -> — | J25: =IFERROR(_xlfn.XLOOKUP(C25,'DONNÉES BRUTES'!A$3:A$90,'DONNÉES BRUTES'!M$3:M$90),"—") -> 36.9% | K25: =IFERROR(_xlfn.XLOOKUP(C25,'DONNÉES BRUTES'!A$3:A$90,'DONNÉES BRUTES'!N$3:N$90),"—") -> 29.8% | L25: =IFERROR(_xlfn.XLOOKUP(C25,'DONNÉES BRUTES'!A$3:A$90,'DONNÉES BRUTES'!U$3:U$90),"—") -> 5.05 | M25: — | N25: =IFERROR(_xlfn.XLOOKUP(C25,'DONNÉES BRUTES'!A$3:A$90,'DONNÉES BRUTES'!AD$3:AD$90),"—") -> Neutre
B26: 20 | C26: =IFERROR(_xlfn.XLOOKUP(LARGE('DONNÉES BRUTES'!AB$3:AB$90,20),'DONNÉES BRUTES'!AB$3:AB$90,'DONNÉES BRUTES'!A$3:A$90),"—") -> APH | D26: =IFERROR(_xlfn.XLOOKUP(C26,'DONNÉES BRUTES'!A$3:A$90,'DONNÉES BRUTES'!B$3:B$90),"—") -> Amphenol Corporation | F26: =IFERROR(_xlfn.XLOOKUP(C26,'DONNÉES BRUTES'!A$3:A$90,'DONNÉES BRUTES'!AB$3:AB$90)&"/100","—") -> 66/100 | G26: =IFERROR(_xlfn.XLOOKUP(C26,'DONNÉES BRUTES'!A$3:A$90,'DONNÉES BRUTES'!I$3:I$90),"—") -> — | H26: =IFERROR(_xlfn.XLOOKUP(C26,'DONNÉES BRUTES'!A$3:A$90,'DONNÉES BRUTES'!J$3:J$90),"—") -> — | I26: =IFERROR(_xlfn.XLOOKUP(C26,'DONNÉES BRUTES'!A$3:A$90,'DONNÉES BRUTES'!K$3:K$90),"—") -> — | J26: =IFERROR(_xlfn.XLOOKUP(C26,'DONNÉES BRUTES'!A$3:A$90,'DONNÉES BRUTES'!M$3:M$90),"—") -> 36.9% | K26: =IFERROR(_xlfn.XLOOKUP(C26,'DONNÉES BRUTES'!A$3:A$90,'DONNÉES BRUTES'!N$3:N$90),"—") -> 29.8% | L26: =IFERROR(_xlfn.XLOOKUP(C26,'DONNÉES BRUTES'!A$3:A$90,'DONNÉES BRUTES'!U$3:U$90),"—") -> 5.05 | M26: — | N26: =IFERROR(_xlfn.XLOOKUP(C26,'DONNÉES BRUTES'!A$3:A$90,'DONNÉES BRUTES'!AD$3:AD$90),"—") -> Neutre
B28: FinSight IA · Screening Technology · Ne constitue pas un conseil en investissement

Sheet GROWTH
B1: FinSight IA · Analyse GROWTH · Technology Screening · 22/03/2026 | N1: Ticker | O1: Score | Q1: Ticker | R1: Rev% | T1: Ticker | U1: Mg EBITDA (%) | W1: Score Growth | X1: Score Global | Z1: Signal | AA1: Nb
B2: Usage confidentiel · Calculs FinSight IA · Screening Technology | N2: INTC | O2: 100 | Q2: INTC | R2: -0.5 | T2: INTC | U2: 27.2 | W2: 100 | X2: 67 | Z2: Surpondérer | AA2: 8
C3: =COUNTA('DONNÉES BRUTES'!A$3:A$90) -> 88 | G3: =IFERROR(_xlfn.XLOOKUP(LARGE('DONNÉES BRUTES'!Y$3:Y$90,1),'DONNÉES BRUTES'!Y$3:Y$90,'DONNÉES BRUTES'!A$3:A$90),"—") -> INTC | L3: =IFERROR(ROUND(AVERAGE('DONNÉES BRUTES'!Y$3:Y$90),0)&"/100","—") -> 49/100 | N3: WDC | O3: 99 | Q3: WDC | R3: 50.7 | T3: WDC | U3: 20.4 | W3: 99 | X3: 77 | Z3: Neutre | AA3: 29
C4: Sociétés | G4: #1 Growth | L4: Moy. Score Growth | N4: MU | O4: 98 | Q4: MU | R4: 48.9 | T4: MU | U4: 49.4 | W4: 98 | X4: 78 | Z4: Sous-pondérer | AA4: 51
B5: ANALYSE DÉTAILLÉE · TECHNOLOGY · TOP 20 par Growth · Triée par Score Growth | N5: STX | O5: 97 | Q5: STX | R5: 38.9 | T5: STX | U5: 22.9 | W5: 97 | X5: 73
B6: # | C6: Ticker | D6: Société | F6: Score | G6: Croiss. Rev | H6: Mg EBITDA | I6: Mg Nette | J6: ROE | K6: Score Global | L6: Next Earn. | M6: Signal | N6: NVDA | O6: 95 | Q6: NVDA | R6: 65.5 | T6: NVDA | U6: 66.9 | W6: 95 | X6: 88
B7: 1 | C7: =IFERROR(_xlfn.XLOOKUP(LARGE('DONNÉES BRUTES'!Y$3:Y$90,1),'DONNÉES BRUTES'!Y$3:Y$90,'DONNÉES BRUTES'!A$3:A$90),"—") -> INTC | D7: =IFERROR(_xlfn.XLOOKUP(C7,'DONNÉES BRUTES'!A$3:A$90,'DONNÉES BRUTES'!B$3:B$90),"—") -> Intel Corporation | F7: =IFERROR(_xlfn.XLOOKUP(C7,'DONNÉES BRUTES'!A$3:A$90,'DONNÉES BRUTES'!Y$3:Y$90)&"/100","—") -> 100/100 | G7: =IFERROR(_xlfn.XLOOKUP(C7,'DONNÉES BRUTES'!A$3:A$90,'DONNÉES BRUTES'!P$3:P$90),"—") -> -0.5% | H7: =IFERROR(_xlfn.XLOOKUP(C7,'DONNÉES BRUTES'!A$3:A$90,'DONNÉES BRUTES'!N$3:N$90),"—") -> 27.2% | I7: =IFERROR(_xlfn.XLOOKUP(C7,'DONNÉES BRUTES'!A$3:A$90,'DONNÉES BRUTES'!O$3:O$90),"—") -> -0.5% | J7: =IFERROR(_xlfn.XLOOKUP(C7,'DONNÉES BRUTES'!A$3:A$90,'DONNÉES BRUTES'!Q$3:Q$90),"—") -> -0.2% | K7: =IFERROR(_xlfn.XLOOKUP(C7,'DONNÉES BRUTES'!A$3:A$90,'DONNÉES BRUTES'!AB$3:AB$90),"—") -> 67 | L7: =IFERROR(_xlfn.XLOOKUP(C7,'DONNÉES BRUTES'!A$3:A$90,'DONNÉES BRUTES'!AC$3:AC$90),"—") -> 2026-04-23 | M7: =IFERROR(_xlfn.XLOOKUP(C7,'DONNÉES BRUTES'!A$3:A$90,'DONNÉES BRUTES'!AD$3:AD$90),"—") -> Neutre | N7: APH | O7: 94 | Q7: APH | R7: 51.7 | T7: APH | U7: 29.8 | W7: 94 | X7: 66
B8: 2 | C8: =IFERROR(_xlfn.XLOOKUP(LARGE('DONNÉES BRUTES'!Y$3:Y$90,2),'DONNÉES BRUTES'!Y$3:Y$90,'DONNÉES BRUTES'!A$3:A$90),"—") -> WDC | D8: =IFERROR(_xlfn.XLOOKUP(C8,'DONNÉES BRUTES'!A$3:A$90,'DONNÉES BRUTES'!B$3:B$90),"—") -> Western Digital Corporation | F8: =IFERROR(_xlfn.XLOOKUP(C8,'DONNÉES BRUTES'!A$3:A$90,'DONNÉES BRUTES'!Y$3:Y$90)&"/100","—") -> 99/100 | G8: =IFERROR(_xlfn.XLOOKUP(C8,'DONNÉES BRUTES'!A$3:A$90,'DONNÉES BRUTES'!P$3:P$90),"—") -> +50.7% | H8: =IFERROR(_xlfn.XLOOKUP(C8,'DONNÉES BRUTES'!A$3:A$90,'DONNÉES BRUTES'!N$3:N$90),"—") -> 20.4% | I8: =IFERROR(_xlfn.XLOOKUP(C8,'DONNÉES BRUTES'!A$3:A$90,'DONNÉES BRUTES'!O$3:O$90),"—") -> 19.5% | J8: =IFERROR(_xlfn.XLOOKUP(C8,'DONNÉES BRUTES'!A$3:A$90,'DONNÉES BRUTES'!Q$3:Q$90),"—") -> +35.0% | K8: =IFERROR(_xlfn.XLOOKUP(C8,'DONNÉES BRUTES'!A$3:A$90,'DONNÉES BRUTES'!AB$3:AB$90),"—") -> 77 | L8: =IFERROR(_xlfn.XLOOKUP(C8,'DONNÉES BRUTES'!A$3:A$90,'DONNÉES BRUTES'!AC$3:AC$90),"—") -> 2026-05-06 | M8: =IFERROR(_xlfn.XLOOKUP(C8,'DONNÉES BRUTES'!A$3:A$90,'DONNÉES BRUTES'!AD$3:AD$90),"—") -> Surpondérer | N8: SAP.DE | O8: 93 | Q8: SAP.DE | R8: 7.7 | T8: SAP.DE | U8: 32.8 | W8: 93 | X8: 59
B9: 3 | C9: =IFERROR(_xlfn.XLOOKUP(LARGE('DONNÉES BRUTES'!Y$3:Y$90,3),'DONNÉES BRUTES'!Y$3:Y$90,'DONNÉES BRUTES'!A$3:A$90),"—") -> MU | D9: =IFERROR(_xlfn.XLOOKUP(C9,'DONNÉES BRUTES'!A$3:A$90,'DONNÉES BRUTES'!B$3:B$90),"—") -> Micron Technology, Inc. | F9: =IFERROR(_xlfn.XLOOKUP(C9,'DONNÉES BRUTES'!A$3:A$90,'DONNÉES BRUTES'!Y$3:Y$90)&"/100","—") -> 98/100 | G9: =IFERROR(_xlfn.XLOOKUP(C9,'DONNÉES BRUTES'!A$3:A$90,'DONNÉES BRUTES'!P$3:P$90),"—") -> +48.9% | H9: =IFERROR(_xlfn.XLOOKUP(C9,'DONNÉES BRUTES'!A$3:A$90,'DONNÉES BRUTES'!N$3:N$90),"—") -> 49.4% | I9: =IFERROR(_xlfn.XLOOKUP(C9,'DONNÉES BRUTES'!A$3:A$90,'DONNÉES BRUTES'!O$3:O$90),"—") -> 22.8% | J9: =IFERROR(_xlfn.XLOOKUP(C9,'DONNÉES BRUTES'!A$3:A$90,'DONNÉES BRUTES'!Q$3:Q$90),"—") -> +15.8% | K9: =IFERROR(_xlfn.XLOOKUP(C9,'DONNÉES BRUTES'!A$3:A$90,'DONNÉES BRUTES'!AB$3:AB$90),"—") -> 78 | L9: =IFERROR(_xlfn.XLOOKUP(C9,'DONNÉES BRUTES'!A$3:A$90,'DONNÉES BRUTES'!AC$3:AC$90),"—") -> — | M9: =IFERROR(_xlfn.XLOOKUP(C9,'DONNÉES BRUTES'!A$3:A$90,'DONNÉES BRUTES'!AD$3:AD$90),"—") -> Surpondérer | N9: AMD | O9: 92 | Q9: AMD | R9: 34.3 | T9: AMD | U9: 21 | W9: 92 | X9: 73
B10: 4 | C10: =IFERROR(_xlfn.XLOOKUP(LARGE('DONNÉES BRUTES'!Y$3:Y$90,4),'DONNÉES BRUTES'!Y$3:Y$90,'DONNÉES BRUTES'!A$3:A$90),"—") -> STX | D10: =IFERROR(_xlfn.XLOOKUP(C10,'DONNÉES BRUTES'!A$3:A$90,'DONNÉES BRUTES'!B$3:B$90),"—") -> Seagate Technology Holdings plc | F10: =IFERROR(_xlfn.XLOOKUP(C10,'DONNÉES BRUTES'!A$3:A$90,'DONNÉES BRUTES'!Y$3:Y$90)&"/100","—") -> 97/100 | G10: =IFERROR(_xlfn.XLOOKUP(C10,'DONNÉES BRUTES'!A$3:A$90,'DONNÉES BRUTES'!P$3:P$90),"—") -> +38.9% | H10: =IFERROR(_xlfn.XLOOKUP(C10,'DONNÉES BRUTES'!A$3:A$90,'DONNÉES BRUTES'!N$3:N$90),"—") -> 22.9% | I10: =IFERROR(_xlfn.XLOOKUP(C10,'DONNÉES BRUTES'!A$3:A$90,'DONNÉES BRUTES'!O$3:O$90),"—") -> 16.1% | J10: =IFERROR(_xlfn.XLOOKUP(C10,'DONNÉES BRUTES'!A$3:A$90,'DONNÉES BRUTES'!Q$3:Q$90),"—") -> -324.3% | K10: =IFERROR(_xlfn.XLOOKUP(C10,'DONNÉES BRUTES'!A$3:A$90,'DONNÉES BRUTES'!AB$3:AB$90),"—") -> 73 | L10: =IFERROR(_xlfn.XLOOKUP(C10,'DONNÉES BRUTES'!A$3:A$90,'DONNÉES BRUTES'!AC$3:AC$90),"—") -> 2026-05-05 | M10: =IFERROR(_xlfn.XLOOKUP(C10,'DONNÉES BRUTES'!A$3:A$90,'DONNÉES BRUTES'!AD$3:AD$90),"—") -> Neutre | N10: PTC | O10: 91 | Q10: PTC | R10: 19.2 | T10: PTC | U10: 41.3 | W10: 91 | X10: 74
B11: 5 | C11: =IFERROR(_xlfn.XLOOKUP(LARGE('DONNÉES BRUTES'!Y$3:Y$90,5),'DONNÉES BRUTES'!Y$3:Y$90,'DONNÉES BRUTES'!A$3:A$90),"—") -> NVDA | D11: =IFERROR(_xlfn.XLOOKUP(C11,'DONNÉES BRUTES'!A$3:A$90,'DONNÉES BRUTES'!B$3:B$90),"—") -> NVIDIA Corporation | F11: =IFERROR(_xlfn.XLOOKUP(C11,'DONNÉES BRUTES'!A$3:A$90,'DONNÉES BRUTES'!Y$3:Y$90)&"/100","—") -> 95/100 | G11: =IFERROR(_xlfn.XLOOKUP(C11,'DONNÉES BRUTES'!A$3:A$90,'DONNÉES BRUTES'!P$3:P$90),"—") -> +65.5% | H11: =IFERROR(_xlfn.XLOOKUP(C11,'DONNÉES BRUTES'!A$3:A$90,'DONNÉES BRUTES'!N$3:N$90),"—") -> 66.9% | I11: =IFERROR(_xlfn.XLOOKUP(C11,'DONNÉES BRUTES'!A$3:A$90,'DONNÉES BRUTES'!O$3:O$90),"—") -> 55.6% | J11: =IFERROR(_xlfn.XLOOKUP(C11,'DONNÉES BRUTES'!A$3:A$90,'DONNÉES BRUTES'!Q$3:Q$90),"—") -> +76.3% | K11: =IFERROR(_xlfn.XLOOKUP(C11,'DONNÉES BRUTES'!A$3:A$90,'DONNÉES BRUTES'!AB$3:AB$90),"—") -> 88 | L11: =IFERROR(_xlfn.XLOOKUP(C11,'DONNÉES BRUTES'!A$3:A$90,'DONNÉES BRUTES'!AC$3:AC$90),"—") -> 2026-05-20 | M11: =IFERROR(_xlfn.XLOOKUP(C11,'DONNÉES BRUTES'!A$3:A$90,'DONNÉES BRUTES'!AD$3:AD$90),"—") -> Surpondérer | N11: AVGO | O11: 90 | Q11: AVGO | R11: 23.9 | T11: AVGO | U11: 54.3 | W11: 90 | X11: 81
B12: 6 | C12: =IFERROR(_xlfn.XLOOKUP(LARGE('DONNÉES BRUTES'!Y$3:Y$90,6),'DONNÉES BRUTES'!Y$3:Y$90,'DONNÉES BRUTES'!A$3:A$90),"—") -> APH | D12: =IFERROR(_xlfn.XLOOKUP(C12,'DONNÉES BRUTES'!A$3:A$90,'DONNÉES BRUTES'!B$3:B$90),"—") -> Amphenol Corporation | F12: =IFERROR(_xlfn.XLOOKUP(C12,'DONNÉES BRUTES'!A$3:A$90,'DONNÉES BRUTES'!Y$3:Y$90)&"/100","—") -> 94/100 | G12: =IFERROR(_xlfn.XLOOKUP(C12,'DONNÉES BRUTES'!A$3:A$90,'DONNÉES BRUTES'!P$3:P$90),"—") -> +51.7% | H12: =IFERROR(_xlfn.XLOOKUP(C12,'DONNÉES BRUTES'!A$3:A$90,'DONNÉES BRUTES'!N$3:N$90),"—") -> 29.8% | I12: =IFERROR(_xlfn.XLOOKUP(C12,'DONNÉES BRUTES'!A$3:A$90,'DONNÉES BRUTES'!O$3:O$90),"—") -> 18.5% | J12: =IFERROR(_xlfn.XLOOKUP(C12,'DONNÉES BRUTES'!A$3:A$90,'DONNÉES BRUTES'!Q$3:Q$90),"—") -> +31.8% | K12: =IFERROR(_xlfn.XLOOKUP(C12,'DONNÉES BRUTES'!A$3:A$90,'DONNÉES BRUTES'!AB$3:AB$90),"—") -> 66 | L12: =IFERROR(_xlfn.XLOOKUP(C12,'DONNÉES BRUTES'!A$3:A$90,'DONNÉES BRUTES'!AC$3:AC$90),"—") -> 2026-04-29 | M12: =IFERROR(_xlfn.XLOOKUP(C12,'DONNÉES BRUTES'!A$3:A$90,'DONNÉES BRUTES'!AD$3:AD$90),"—") -> Neutre | N12: GLW | O12: 88 | Q12: GLW | R12: 19.1 | T12: GLW | U12: 23.9 | W12: 88 | X12: 68
B13: 7 | C13: =IFERROR(_xlfn.XLOOKUP(LARGE('DONNÉES BRUTES'!Y$3:Y$90,7),'DONNÉES BRUTES'!Y$3:Y$90,'DONNÉES BRUTES'!A$3:A$90),"—") -> SAP.DE | D13: =IFERROR(_xlfn.XLOOKUP(C13,'DONNÉES BRUTES'!A$3:A$90,'DONNÉES BRUTES'!B$3:B$90),"—") -> SAP SE | F13: =IFERROR(_xlfn.XLOOKUP(C13,'DONNÉES BRUTES'!A$3:A$90,'DONNÉES BRUTES'!Y$3:Y$90)&"/100","—") -> 93/100 | G13: =IFERROR(_xlfn.XLOOKUP(C13,'DONNÉES BRUTES'!A$3:A$90,'DONNÉES BRUTES'!P$3:P$90),"—") -> +7.7% | H13: =IFERROR(_xlfn.XLOOKUP(C13,'DONNÉES BRUTES'!A$3:A$90,'DONNÉES BRUTES'!N$3:N$90),"—") -> 32.8% | I13: =IFERROR(_xlfn.XLOOKUP(C13,'DONNÉES BRUTES'!A$3:A$90,'DONNÉES BRUTES'!O$3:O$90),"—") -> 19.5% | J13: =IFERROR(_xlfn.XLOOKUP(C13,'DONNÉES BRUTES'!A$3:A$90,'DONNÉES BRUTES'!Q$3:Q$90),"—") -> +16.1% | K13: =IFERROR(_xlfn.XLOOKUP(C13,'DONNÉES BRUTES'!A$3:A$90,'DONNÉES BRUTES'!AB$3:AB$90),"—") -> 59 | L13: =IFERROR(_xlfn.XLOOKUP(C13,'DONNÉES BRUTES'!A$3:A$90,'DONNÉES BRUTES'!AC$3:AC$90),"—") -> 2026-04-23 | M13: =IFERROR(_xlfn.XLOOKUP(C13,'DONNÉES BRUTES'!A$3:A$90,'DONNÉES BRUTES'!AD$3:AD$90),"—") -> Neutre | N13: XYZ | O13: 87 | Q13: XYZ | R13: 0.3 | T13: XYZ | U13: 14.1 | W13: 87 | X13: 53
B14: 8 | C14: =IFERROR(_xlfn.XLOOKUP(LARGE('DONNÉES BRUTES'!Y$3:Y$90,8),'DONNÉES BRUTES'!Y$3:Y$90,'DONNÉES BRUTES'!A$3:A$90),"—") -> AMD | D14: =IFERROR(_xlfn.XLOOKUP(C14,'DONNÉES BRUTES'!A$3:A$90,'DONNÉES BRUTES'!B$3:B$90),"—") -> Advanced Micro Devices, Inc. | F14: =IFERROR(_xlfn.XLOOKUP(C14,'DONNÉES BRUTES'!A$3:A$90,'DONNÉES BRUTES'!Y$3:Y$90)&"/100","—") -> 92/100 | G14: =IFERROR(_xlfn.XLOOKUP(C14,'DONNÉES BRUTES'!A$3:A$90,'DONNÉES BRUTES'!P$3:P$90),"—") -> +34.3% | H14: =IFERROR(_xlfn.XLOOKUP(C14,'DONNÉES BRUTES'!A$3:A$90,'DONNÉES BRUTES'!N$3:N$90),"—") -> 21.0% | I14: =IFERROR(_xlfn.XLOOKUP(C14,'DONNÉES BRUTES'!A$3:A$90,'DONNÉES BRUTES'!O$3:O$90),"—") -> 12.5% | J14: =IFERROR(_xlfn.XLOOKUP(C14,'DONNÉES BRUTES'!A$3:A$90,'DONNÉES BRUTES'!Q$3:Q$90),"—") -> +6.9% | K14: =IFERROR(_xlfn.XLOOKUP(C14,'DONNÉES BRUTES'!A$3:A$90,'DONNÉES BRUTES'!AB$3:AB$90),"—") -> 73 | L14: =IFERROR(_xlfn.XLOOKUP(C14,'DONNÉES BRUTES'!A$3:A$90,'DONNÉES BRUTES'!AC$3:AC$90),"—") -> 2026-05-05 | M14: =IFERROR(_xlfn.XLOOKUP(C14,'DONNÉES BRUTES'!A$3:A$90,'DONNÉES BRUTES'!AD$3:AD$90),"—") -> Neutre | N14: MPWR | O14: 86 | Q14: MPWR | R14: 26.4 | T14: MPWR | U14: 28 | W14: 86 | X14: 78
B15: 9 | C15: =IFERROR(_xlfn.XLOOKUP(LARGE('DONNÉES BRUTES'!Y$3:Y$90,9),'DONNÉES BRUTES'!Y$3:Y$90,'DONNÉES BRUTES'!A$3:A$90),"—") -> PTC | D15: =IFERROR(_xlfn.XLOOKUP(C15,'DONNÉES BRUTES'!A$3:A$90,'DONNÉES BRUTES'!B$3:B$90),"—") -> PTC Inc. | F15: =IFERROR(_xlfn.XLOOKUP(C15,'DONNÉES BRUTES'!A$3:A$90,'DONNÉES BRUTES'!Y$3:Y$90)&"/100","—") -> 91/100 | G15: =IFERROR(_xlfn.XLOOKUP(C15,'DONNÉES BRUTES'!A$3:A$90,'DONNÉES BRUTES'!P$3:P$90),"—") -> +19.2% | H15: =IFERROR(_xlfn.XLOOKUP(C15,'DONNÉES BRUTES'!A$3:A$90,'DONNÉES BRUTES'!N$3:N$90),"—") -> 41.3% | I15: =IFERROR(_xlfn.XLOOKUP(C15,'DONNÉES BRUTES'!A$3:A$90,'DONNÉES BRUTES'!O$3:O$90),"—") -> 26.8% | J15: =IFERROR(_xlfn.XLOOKUP(C15,'DONNÉES BRUTES'!A$3:A$90,'DONNÉES BRUTES'!Q$3:Q$90),"—") -> +19.2% | K15: =IFERROR(_xlfn.XLOOKUP(C15,'DONNÉES BRUTES'!A$3:A$90,'DONNÉES BRUTES'!AB$3:AB$90),"—") -> 74 | L15: =IFERROR(_xlfn.XLOOKUP(C15,'DONNÉES BRUTES'!A$3:A$90,'DONNÉES BRUTES'!AC$3:AC$90),"—") -> 2026-04-29 | M15: =IFERROR(_xlfn.XLOOKUP(C15,'DONNÉES BRUTES'!A$3:A$90,'DONNÉES BRUTES'!AD$3:AD$90),"—") -> Neutre | N15: KLAC | O15: 85 | Q15: KLAC | R15: 23.9 | T15: KLAC | U15: 43.9 | W15: 85 | X15: 84
B16: 10 | C16: =IFERROR(_xlfn.XLOOKUP(LARGE('DONNÉES BRUTES'!Y$3:Y$90,10),'DONNÉES BRUTES'!Y$3:Y$90,'DONNÉES BRUTES'!A$3:A$90),"—") -> AVGO | D16: =IFERROR(_xlfn.XLOOKUP(C16,'DONNÉES BRUTES'!A$3:A$90,'DONNÉES BRUTES'!B$3:B$90),"—") -> Broadcom Inc. | F16: =IFERROR(_xlfn.XLOOKUP(C16,'DONNÉES BRUTES'!A$3:A$90,'DONNÉES BRUTES'!Y$3:Y$90)&"/100","—") -> 90/100 | G16: =IFERROR(_xlfn.XLOOKUP(C16,'DONNÉES BRUTES'!A$3:A$90,'DONNÉES BRUTES'!P$3:P$90),"—") -> +23.9% | H16: =IFERROR(_xlfn.XLOOKUP(C16,'DONNÉES BRUTES'!A$3:A$90,'DONNÉES BRUTES'!N$3:N$90),"—") -> 54.3% | I16: =IFERROR(_xlfn.XLOOKUP(C16,'DONNÉES BRUTES'!A$3:A$90,'DONNÉES BRUTES'!O$3:O$90),"—") -> 36.2% | J16: =IFERROR(_xlfn.XLOOKUP(C16,'DONNÉES BRUTES'!A$3:A$90,'DONNÉES BRUTES'!Q$3:Q$90),"—") -> +28.4% | K16: =IFERROR(_xlfn.XLOOKUP(C16,'DONNÉES BRUTES'!A$3:A$90,'DONNÉES BRUTES'!AB$3:AB$90),"—") -> 81 | L16: =IFERROR(_xlfn.XLOOKUP(C16,'DONNÉES BRUTES'!A$3:A$90,'DONNÉES BRUTES'!AC$3:AC$90),"—") -> 2026-06-03 | M16: =IFERROR(_xlfn.XLOOKUP(C16,'DONNÉES BRUTES'!A$3:A$90,'DONNÉES BRUTES'!AD$3:AD$90),"—") -> Surpondérer | N16: ANET | O16: 84 | Q16: ANET | R16: 28.6 | T16: ANET | U16: 43.6 | W16: 84 | X16: 83
B17: 11 | C17: =IFERROR(_xlfn.XLOOKUP(LARGE('DONNÉES BRUTES'!Y$3:Y$90,11),'DONNÉES BRUTES'!Y$3:Y$90,'DONNÉES BRUTES'!A$3:A$90),"—") -> GLW | D17: =IFERROR(_xlfn.XLOOKUP(C17,'DONNÉES BRUTES'!A$3:A$90,'DONNÉES BRUTES'!B$3:B$90),"—") -> Corning Incorporated | F17: =IFERROR(_xlfn.XLOOKUP(C17,'DONNÉES BRUTES'!A$3:A$90,'DONNÉES BRUTES'!Y$3:Y$90)&"/100","—") -> 88/100 | G17: =IFERROR(_xlfn.XLOOKUP(C17,'DONNÉES BRUTES'!A$3:A$90,'DONNÉES BRUTES'!P$3:P$90),"—") -> +19.1% | H17: =IFERROR(_xlfn.XLOOKUP(C17,'DONNÉES BRUTES'!A$3:A$90,'DONNÉES BRUTES'!N$3:N$90),"—") -> 23.9% | I17: =IFERROR(_xlfn.XLOOKUP(C17,'DONNÉES BRUTES'!A$3:A$90,'DONNÉES BRUTES'!O$3:O$90),"—") -> 10.2% | J17: =IFERROR(_xlfn.XLOOKUP(C17,'DONNÉES BRUTES'!A$3:A$90,'DONNÉES BRUTES'!Q$3:Q$90),"—") -> +13.5% | K17: =IFERROR(_xlfn.XLOOKUP(C17,'DONNÉES BRUTES'!A$3:A$90,'DONNÉES BRUTES'!AB$3:AB$90),"—") -> 68 | L17: =IFERROR(_xlfn.XLOOKUP(C17,'DONNÉES BRUTES'!A$3:A$90,'DONNÉES BRUTES'!AC$3:AC$90),"—") -> 2026-04-28 | M17: =IFERROR(_xlfn.XLOOKUP(C17,'DONNÉES BRUTES'!A$3:A$90,'DONNÉES BRUTES'!AD$3:AD$90),"—") -> Neutre | N17: LRCX | O17: 83 | Q17: LRCX | R17: 23.7 | T17: LRCX | U17: 35.4 | W17: 83 | X17: 77
B18: 12 | C18: =IFERROR(_xlfn.XLOOKUP(LARGE('DONNÉES BRUTES'!Y$3:Y$90,12),'DONNÉES BRUTES'!Y$3:Y$90,'DONNÉES BRUTES'!A$3:A$90),"—") -> XYZ | D18: =IFERROR(_xlfn.XLOOKUP(C18,'DONNÉES BRUTES'!A$3:A$90,'DONNÉES BRUTES'!B$3:B$90),"—") -> Block, Inc. | F18: =IFERROR(_xlfn.XLOOKUP(C18,'DONNÉES BRUTES'!A$3:A$90,'DONNÉES BRUTES'!Y$3:Y$90)&"/100","—") -> 87/100 | G18: =IFERROR(_xlfn.XLOOKUP(C18,'DONNÉES BRUTES'!A$3:A$90,'DONNÉES BRUTES'!P$3:P$90),"—") -> +0.3% | H18: =IFERROR(_xlfn.XLOOKUP(C18,'DONNÉES BRUTES'!A$3:A$90,'DONNÉES BRUTES'!N$3:N$90),"—") -> 14.1% | I18: =IFERROR(_xlfn.XLOOKUP(C18,'DONNÉES BRUTES'!A$3:A$90,'DONNÉES BRUTES'!O$3:O$90),"—") -> 5.4% | J18: =IFERROR(_xlfn.XLOOKUP(C18,'DONNÉES BRUTES'!A$3:A$90,'DONNÉES BRUTES'!Q$3:Q$90),"—") -> +5.9% | K18: =IFERROR(_xlfn.XLOOKUP(C18,'DONNÉES BRUTES'!A$3:A$90,'DONNÉES BRUTES'!AB$3:AB$90),"—") -> 53 | L18: =IFERROR(_xlfn.XLOOKUP(C18,'DONNÉES BRUTES'!A$3:A$90,'DONNÉES BRUTES'!AC$3:AC$90),"—") -> 2026-04-30 | M18: =IFERROR(_xlfn.XLOOKUP(C18,'DONNÉES BRUTES'!A$3:A$90,'DONNÉES BRUTES'!AD$3:AD$90),"—") -> Sous-pondérer | N18: SMCI | O18: 81 | Q18: SMCI | R18: 46.6 | T18: SMCI | U18: 6.1 | W18: 81 | X18: 32
B19: 13 | C19: =IFERROR(_xlfn.XLOOKUP(LARGE('DONNÉES BRUTES'!Y$3:Y$90,13),'DONNÉES BRUTES'!Y$3:Y$90,'DONNÉES BRUTES'!A$3:A$90),"—") -> MPWR | D19: =IFERROR(_xlfn.XLOOKUP(C19,'DONNÉES BRUTES'!A$3:A$90,'DONNÉES BRUTES'!B$3:B$90),"—") -> Monolithic Power Systems, Inc. | F19: =IFERROR(_xlfn.XLOOKUP(C19,'DONNÉES BRUTES'!A$3:A$90,'DONNÉES BRUTES'!Y$3:Y$90)&"/100","—") -> 86/100 | G19: =IFERROR(_xlfn.XLOOKUP(C19,'DONNÉES BRUTES'!A$3:A$90,'DONNÉES BRUTES'!P$3:P$90),"—") -> +26.4% | H19: =IFERROR(_xlfn.XLOOKUP(C19,'DONNÉES BRUTES'!A$3:A$90,'DONNÉES BRUTES'!N$3:N$90),"—") -> 28.0% | I19: =IFERROR(_xlfn.XLOOKUP(C19,'DONNÉES BRUTES'!A$3:A$90,'DONNÉES BRUTES'!O$3:O$90),"—") -> 22.3% | J19: =IFERROR(_xlfn.XLOOKUP(C19,'DONNÉES BRUTES'!A$3:A$90,'DONNÉES BRUTES'!Q$3:Q$90),"—") -> +17.6% | K19: =IFERROR(_xlfn.XLOOKUP(C19,'DONNÉES BRUTES'!A$3:A$90,'DONNÉES BRUTES'!AB$3:AB$90),"—") -> 78 | L19: =IFERROR(_xlfn.XLOOKUP(C19,'DONNÉES BRUTES'!A$3:A$90,'DONNÉES BRUTES'!AC$3:AC$90),"—") -> 2026-04-30 | M19: =IFERROR(_xlfn.XLOOKUP(C19,'DONNÉES BRUTES'!A$3:A$90,'DONNÉES BRUTES'!AD$3:AD$90),"—") -> Surpondérer | N19: NOW | O19: 80 | Q19: NOW | R19: 20.9 | T19: NOW | U19: 22.8 | W19: 80 | X19: 53
