Workbook

Sheet INPUT
B3: INPUT — Raw Data
B4: All figures in USD millions unless stated
B5: METRIC | C5: UNIT | E5: 2022 | F5: 2023 | G5: 2024 | H5: 2025 (LTM)
B7: INPUT
B9: Revenue | C9: ($M) | E9: 5973.69 | F9: 8023.47 | G9: 8201.61 | H9: 8790.13
B10: Cost of Goods Sold (COGS) | C10: ($M) | E10: -1509.09 | F10: -2010.34 | G10: -2057.24 | H10: -2234.65
B11: Gross Profit | C11: ($M) | D11: =D9+D10 -> 0 | E11: =E9+E10 -> 4464.6 | F11: =F9+F10 -> 6013.13 | G11: =G9+G10 -> 6144.37 | H11: =H9+H10 -> 6555.48
D13: =SUM(D14:D16) -> 0 | E13: =SUM(E14:E16) -> -5218.86 | F13: =SUM(F14:F16) -> -6844.3 | G13: =SUM(G14:G16) -> -7539.28 | H13: =SUM(H14:H16) -> -9506.14
B14: Operating Expenses (SG&A) | C14: ($M) | E14: -331.08 | F14: -390.41 | G14: -418.76 | H14: -469.11
B15: Research & Development | C15: ($M) | E15: -3075 | F15: -3969 | G15: -4540 | H15: -6411
B16: Depreciation & Amortization | C16: ($M) | E16: -1812.78 | F16: -2484.89 | G16: -2580.52 | H16: -2626.03
B17: EBIT (Operating Profit) | C17: ($M) | D17: =D11+D13 -> 0 | E17: =E11+E13 -> -754.26 | F17: =F11+F13 -> -831.17 | G17: =G11+G13 -> -1394.91 | H17: =H11+H13 -> -2950.66
D19: =D17+D20+D21 -> 0 | E19: =E17+E20+E21 -> -1046.16 | F19: =F17+F20+F21 -> -1449.89 | G19: =G17+G20+G21 -> -2232.21 | H19: =H17+H20+H21 -> -3922.92
B20: Interest Expense | C20: ($M) | E20: -291.9 | F20: -618.72 | G20: -837.3 | H20: -972.26
B21: Interest Income | C21: ($M) | E21: 0 | F21: 0 | G21: 0 | H21: 0
B22: Earnings Before Tax (EBT) | C22: ($M) | D22: =D19 -> 0 | E22: =E19 -> -1046.16 | F22: =F19 -> -1449.89 | G22: =G19 -> -2232.21 | H22: =H19 -> -3922.92
D24: =-ROUND(D22*0.21,0) -> 0 | E24: =-ROUND(E22*E126,0) -> 52 | F24: =-ROUND(F22*F126,0) -> 94 | G24: =-ROUND(G22*G126,0) -> 112 | H24: =-ROUND(H22*H126,0) -> 212
B25: Income Tax Expense | C25: ($M) | E25: -135.41 | F25: -211.04 | G25: -166.94 | H25: -204.02
B26: Net Income | C26: ($M) | D26: =D22+D24 -> 0 | E26: =E22+E24 -> -994.16 | F26: =F22+F24 -> -1355.89 | G26: =G22+G24 -> -2120.21 | H26: =H22+H24 -> -3710.92
B29: Common Dividends | C29: ($M) | E29: 0 | F29: -3228.59 | G29: -3570.48 | H29: -3764.74
B30: EBITDA | C30: ($M) | D30: =D17-D16 -> 0 | E30: =E17-E16 -> 1058.52 | F30: =F17-F16 -> 1653.72 | G30: =G17-G16 -> 1185.61 | H30: =H17-H16 -> -324.63
B32: BALANCE SHEET
B34: Cash & Cash Equivalents | C34: ($M) | E34: 278.48 | F34: 530.39 | G34: 1318.59 | H34: 1145.65
B35: Accounts Receivable | C35: ($M) | E35: 378 | F35: 325.7 | G35: 407.46 | H35: 601.34
B36: Inventories | C36: ($M) | E36: 22936 | F36: 19317 | G36: 18868 | H36: 16663
B37: Other Current Assets | C37: ($M) | E37: 63 | F37: 60 | G37: 71 | H37: 105
B38: Total Current Assets | C38: ($M) | D38: =SUM(D34:D37) -> 0 | E38: =SUM(E34:E37) -> 23655.48 | F38: =SUM(F34:F37) -> 20233.09 | G38: =SUM(G34:G37) -> 20665.05 | H38: =SUM(H34:H37) -> 18514.99
B41: PP&E (Net) | C41: ($M) | E41: 855.33 | F41: 891.74 | G41: 920.13 | H41: 893.37
B42: Intangible Assets | C42: ($M) | E42: 1183.01 | F42: 1010.62 | G42: 764.55 | H42: 588.43
B43: Other Long-Term Assets | C43: ($M) | E43: 1652.87 | F43: 1955.9 | G43: 2513.2 | H43: 3223.96
B44: Total Assets | C44: ($M) | D44: =D38+SUM(D41:D43) -> 0 | E44: =E38+SUM(E41:E43) -> 27346.69 | F44: =F38+SUM(F41:F43) -> 24091.35 | G44: =G38+SUM(G41:G43) -> 24862.93 | H44: =H38+SUM(H41:H43) -> 23220.75
B47: Accounts Payable | C47: ($M) | E47: 1711.88 | F47: 1766.02 | G47: 1769.33 | H47: 1963.64
B48: Short-Term Debt | C48: ($M) | E48: 1538.46 | F48: 979.31 | G48: 224.97 | H48: 44.68
B49: Income Tax Payable | C49: ($M) | E49: 99.76 | F49: 118.68 | G49: 141.13 | H49: 156.02
B50: Other Current Liabilities | C50: ($M) | E50: 4.54 | F50: 14.18 | G50: 1.95 | H50: 0.69
B51: Total Current Liabilities | C51: ($M) | D51: =SUM(D47:D50) -> 0 | E51: =SUM(E47:E50) -> 3354.64 | F51: =SUM(F47:F50) -> 2878.19 | G51: =SUM(G47:G50) -> 2137.38 | H51: =SUM(H47:H50) -> 2165.03
H52: 932
B54: Long-Term Debt | C54: ($M) | E54: 22337.5 | F54: 28021.19 | G54: 30654.3 | H54: 34992.39
B55: Total Liabilities | C55: ($M) | D55: =D51+D54 -> 0 | E55: =E51+E54 -> 25692.14 | F55: =F51+F54 -> 30899.38 | G55: =G51+G54 -> 32791.68 | H55: =H51+H54 -> 37157.42
B58: Common Equity (Paid-In Capital) | C58: ($M) | E58: 54138.59 | F58: 54322.99 | G58: 54537.27 | H58: 54771.88
...

Sheet RATIOS
B1: FinSight | H1: RATIOS — Financial Ratio Analysis
B3: RATIOS
B5: Year | E5: =IF(INPUT!E5="","",INPUT!E5) -> 2022 | F5: =IF(INPUT!F5="","",INPUT!F5) -> 2023 | G5: =IF(INPUT!G5="","",INPUT!G5) -> 2024 | H5: =IF(INPUT!H5="","",INPUT!H5) -> 2025 (LTM)
B7: RATIOS DE VALORISATION — REIT
B9: P/FFO (Price / Funds From Operations) | E9: =IFERROR(INPUT!E117/INPUT!E102,"–") -> 2575.0043 | F9: =IFERROR(INPUT!F117/INPUT!F102,"–") -> 2451.085 | G9: =IFERROR(INPUT!G117/INPUT!G102,"–") -> 7564.9193 | H9: =IFERROR(INPUT!H117/INPUT!H102,"–") -> -120.1023
B10: P/AFFO (Price / Adj. FFO per share) | E10: =IFERROR(INPUT!E117/INPUT!E103,"–") -> 1629.4971 | F10: =IFERROR(INPUT!F117/INPUT!F103,"–") -> 1549.4261 | G10: =IFERROR(INPUT!G117/INPUT!G103,"–") -> 2823.4653 | H10: =IFERROR(INPUT!H117/INPUT!H103,"–") -> -587.21793
B11: FFO / Share | E11: =IFERROR(INPUT!E102,"–") -> 0.050485353 | F11: =IFERROR(INPUT!F102,"–") -> 0.071396952 | G11: =IFERROR(INPUT!G102,"–") -> 0.02987474 | H11: =IFERROR(INPUT!H102,"–") -> -1.1637579
B12: AFFO / Share | E12: =IFERROR(INPUT!E103,"–") -> 0.079779217 | F12: =IFERROR(INPUT!F103,"–") -> 0.11294505 | G12: =IFERROR(INPUT!G103,"–") -> 0.080043484 | H12: =IFERROR(INPUT!H103,"–") -> -0.23802066
B13: P/NAV (Price / Net Asset Value) | E13: =IFERROR(INPUT!E117/NAV!C69,"–") -> 0.13948498 | F13: =IFERROR(INPUT!F117/NAV!C69,"–") -> 0.18776824 | G13: =IFERROR(INPUT!G117/NAV!C69,"–") -> 0.24248927 | H13: =IFERROR(INPUT!H117/NAV!C69,"–") -> 0.14996781
B14: Dividend Yield | E14: =IFERROR(INPUT!E110/INPUT!E117,"–") -> 0.0096923077 | F14: =IFERROR(INPUT!F110/INPUT!F117,"–") -> 0.008 | G14: =IFERROR(INPUT!G110/INPUT!G117,"–") -> 0.0069026549 | H14: =IFERROR(INPUT!H110/INPUT!H117,"–") -> 0.012449023
B15: Dividend Coverage (FFO / Divs Paid) | E15: – | F15: =IFERROR(INPUT!F100/ABS(INPUT!F29),"–") -> 0.34968825 | G15: =IFERROR(INPUT!G100/ABS(INPUT!G29),"–") -> 0.12892104 | H15: =IFERROR(INPUT!H100/ABS(INPUT!H29),"–") -> -0.28817129
B17: FONDAMENTAUX IMMOBILIERS — REIT
B19: Occupancy Rate | E19: =IFERROR(INPUT!E107,"–") -> 0.971 | F19: =IFERROR(INPUT!F107,"–") -> 0.978 | G19: =IFERROR(INPUT!G107,"–") -> 0.982 | H19: =IFERROR(INPUT!H107,"–") -> 0.965
B20: Same-Store NOI Growth (YoY) | E20: =IFERROR(INPUT!E108,"–") -> 0.042 | F20: =IFERROR(INPUT!F108,"–") -> 0.068 | G20: =IFERROR(INPUT!G108,"–") -> 0.052 | H20: =IFERROR(INPUT!H108,"–") -> 0.038
B21: WALT (Weighted Avg Lease Term, yrs) | E21: =IFERROR(INPUT!E109,"–") -> 4.2 | F21: =IFERROR(INPUT!F109,"–") -> 4.5 | G21: =IFERROR(INPUT!G109,"–") -> 4.8 | H21: =IFERROR(INPUT!H109,"–") -> 5.1
B22: Cap Rate (implied) | E22: =IFERROR(INPUT!E104,"–") -> 0.045 | F22: =IFERROR(INPUT!F104,"–") -> 0.048 | G22: =IFERROR(INPUT!G104,"–") -> 0.052 | H22: =IFERROR(INPUT!H104,"–") -> 0.055
B23: LTV = Net Debt / Asset Value | E23: =IFERROR(INPUT!E111,"–") -> 0.32774278 | F23: =IFERROR(INPUT!F111,"–") -> 0.2983767 | G23: =IFERROR(INPUT!G111,"–") -> 0.27400274 | H23: =IFERROR(INPUT!H111,"–") -> 0.30338999
B24: Net Debt / EBITDA | E24: =IFERROR((INPUT!E54+INPUT!E48-INPUT!E34)/INPUT!E30,"–") -> 22.2929 | F24: =IFERROR((INPUT!F54+INPUT!F48-INPUT!F34)/INPUT!F30,"–") -> 17.215798 | G24: =IFERROR((INPUT!G54+INPUT!G48-INPUT!G34)/INPUT!G30,"–") -> 24.932887 | H24: =IFERROR((INPUT!H54+INPUT!H48-INPUT!H34)/INPUT!H30,"–") -> -104.40015
B25: ICR — Interest Coverage (EBITDA / Interest) | E25: =IFERROR(INPUT!E30/ABS(INPUT!E20),"–") -> 3.6263104 | F25: =IFERROR(INPUT!F30/ABS(INPUT!F20),"–") -> 2.6728084 | G25: =IFERROR(INPUT!G30/ABS(INPUT!G20),"–") -> 1.4159919 | H25: =IFERROR(INPUT!H30/ABS(INPUT!H20),"–") -> -0.33389217
B27: STRUCTURE DE CAPITAL — REIT
B29: Net Debt ($M) | E29: =IFERROR(INPUT!E54+INPUT!E48-INPUT!E34,"–") -> 23597.48 | F29: =IFERROR(INPUT!F54+INPUT!F48-INPUT!F34,"–") -> 28470.11 | G29: =IFERROR(INPUT!G54+INPUT!G48-INPUT!G34,"–") -> 29560.68 | H29: =IFERROR(INPUT!H54+INPUT!H48-INPUT!H34,"–") -> 33891.42
B30: Total Debt ($M) | E30: =IFERROR(INPUT!E54+INPUT!E48,"–") -> 23875.96 | F30: =IFERROR(INPUT!F54+INPUT!F48,"–") -> 29000.5 | G30: =IFERROR(INPUT!G54+INPUT!G48,"–") -> 30879.27 | H30: =IFERROR(INPUT!H54+INPUT!H48,"–") -> 35037.07
B31: Debt / Equity Ratio | E31: =IFERROR((INPUT!E54+INPUT!E48)/INPUT!E60,"–") -> 0.4447757 | F31: =IFERROR((INPUT!F54+INPUT!F48)/INPUT!F60,"–") -> 0.54008759 | G31: =IFERROR((INPUT!G54+INPUT!G48)/INPUT!G60,"–") -> 0.57108366 | H31: =IFERROR((INPUT!H54+INPUT!H48)/INPUT!H60,"–") -> 0.65040705
B32: Interest Coverage (EBIT / Interest) | E32: =IFERROR(INPUT!E17/ABS(INPUT!E20),"–") -> -2.5839671 | F32: =IFERROR(INPUT!F17/ABS(INPUT!F20),"–") -> -1.3433702 | G32: =IFERROR(INPUT!G17/ABS(INPUT!G20),"–") -> -1.665962 | H32: =IFERROR(INPUT!H17/ABS(INPUT!H20),"–") -> -3.0348466
B33: Operating CF / Total Debt (FFO/Debt proxy) | E33: =IFERROR(INPUT!E75/(INPUT!E54+INPUT!E48),"–") -> -0.13340909 | F33: =IFERROR(INPUT!F75/(INPUT!F54+INPUT!F48),"–") -> 0.13524801 | G33: =IFERROR(INPUT!G75/(INPUT!G54+INPUT!G48),"–") -> -0.003022416 | H33: =IFERROR(INPUT!H75/(INPUT!H54+INPUT!H48),"–") -> 0.039516718
B34: Current Ratio | E34: =IFERROR(INPUT!E38/INPUT!E51,"–") -> 7.0515704 | F34: =IFERROR(INPUT!F38/INPUT!F51,"–") -> 7.0297965 | G34: =IFERROR(INPUT!G38/INPUT!G51,"–") -> 9.6684024 | H34: =IFERROR(INPUT!H38/INPUT!H51,"–") -> 8.5518399
B36: PERFORMANCE OPÉRATIONNELLE — REIT
B38: NOI Margin (NOI / Revenue) | E38: =IFERROR(IF(INPUT!E94<>"",INPUT!E94/INPUT!E9,INPUT!E30/INPUT!E9),"–") -> 0.54237833 | F38: =IFERROR(IF(INPUT!F94<>"",INPUT!F94/INPUT!F9,INPUT!F30/INPUT!F9),"–") -> 0.57082534 | G38: =IFERROR(IF(INPUT!G94<>"",INPUT!G94/INPUT!G9,INPUT!G30/INPUT!G9),"–") -> 0.68401204 | H38: =IFERROR(IF(INPUT!H94<>"",INPUT!H94/INPUT!H9,INPUT!H30/INPUT!H9),"–") -> 0.69896577
B40: GROWTH RATIOS
B42: Revenue Growth (YoY) | D42: – | F42: =IFERROR(INPUT!F9/INPUT!E9-1,"–") -> 0.34313465 | G42: =IFERROR(INPUT!G9/INPUT!F9-1,"–") -> 0.022202364 | H42: =IFERROR(INPUT!H9/INPUT!G9-1,"–") -> 0.071756643
B43: NOI Growth (YoY) — proxy EBITDA | D43: – | F43: =IFERROR(INPUT!F30/INPUT!E30-1,"–") -> 0.56229452 | G43: =IFERROR(INPUT!G30/INPUT!F30-1,"–") -> -0.28306485 | H43: =IFERROR(INPUT!H30/INPUT!G30-1,"–") -> -1.2738084
B44: FFO Growth (YoY) | D44: – | F44: =IFERROR((INPUT!F100-INPUT!E100)/ABS(INPUT!E100),"–") -> 0.37915028 | G44: =IFERROR((INPUT!G100-INPUT!F100)/ABS(INPUT!F100),"–") -> -0.59228521 | H44: =IFERROR((INPUT!H100-INPUT!G100)/ABS(INPUT!G100),"–") -> -3.3568682
B45: FFO per Share Growth (YoY) | D45: – | F45: =IFERROR((INPUT!F102-INPUT!E102)/ABS(INPUT!E102),"–") -> 0.4142112 | G45: =IFERROR((INPUT!G102-INPUT!F102)/ABS(INPUT!F102),"–") -> -0.58156841 | H45: =IFERROR((INPUT!H102-INPUT!G102)/ABS(INPUT!G102),"–") -> -39.954577
B46: Total Assets Growth (YoY) | D46: – | F46: =IFERROR(INPUT!F44/INPUT!E44-1,"–") -> -0.11903964 | G46: =IFERROR(INPUT!G44/INPUT!F44-1,"–") -> 0.032027263 | H46: =IFERROR(INPUT!H44/INPUT!G44-1,"–") -> -0.066049335
B48: CASH FLOW RATIOS
B50: Operating Cash Flow Margin | D50: =IFERROR(INPUT!D75/INPUT!D9,"–") -> – | E50: =IFERROR(INPUT!E75/INPUT!E9,"–") -> -0.53321649 | F50: =IFERROR(INPUT!F75/INPUT!F9,"–") -> 0.48884834 | G50: =IFERROR(INPUT!G75/INPUT!G9,"–") -> -0.011379473 | H50: =IFERROR(INPUT!H75/INPUT!H9,"–") -> 0.15751189
B51: AFFO ($M) — Adjusted Funds From Operations | D51: =IFERROR(INPUT!D75+INPUT!D78,"–") -> 0 | E51: =IFERROR(INPUT!E101,"–") -> 1293.62 | F51: =IFERROR(INPUT!F101,"–") -> 1786 | G51: =IFERROR(INPUT!G101,"–") -> 1233.31 | H51: =IFERROR(INPUT!H101,"–") -> -221.89
B52: AFFO Margin (AFFO / Revenue) | D52: =IFERROR(D51/INPUT!D9,"–") -> – | E52: =IFERROR(INPUT!E101/INPUT!E9,"–") -> 0.21655292 | F52: =IFERROR(INPUT!F101/INPUT!F9,"–") -> 0.22259696 | G52: =IFERROR(INPUT!G101/INPUT!G9,"–") -> 0.15037413 | H52: =IFERROR(INPUT!H101/INPUT!H9,"–") -> -0.025243085
B53: CapEx Intensity (Total CapEx / Revenue) | D53: =IFERROR(ABS(INPUT!D78)/INPUT!D9,"–") -> – | E53: =IFERROR(ABS(INPUT!E78)/INPUT!E9,"–") -> 2.6265173 | F53: =IFERROR(ABS(INPUT!F78)/INPUT!F9,"–") -> 2.20877 | G53: =IFERROR(ABS(INPUT!G78)/INPUT!G9,"–") -> 1.8178138 | H53: =IFERROR(ABS(INPUT!H78)/INPUT!H9,"–") -> 1.9286404
B54: AFFO Payout Ratio (Divs / AFFO) | D54: =IFERROR(ABS(INPUT!D85)/INPUT!D26,"–") -> – | E54: =IFERROR(ABS(INPUT!E29)/INPUT!E101,"–") -> 0 | F54: =IFERROR(ABS(INPUT!F29)/INPUT!F101,"–") -> 1.8077212 | G54: =IFERROR(ABS(INPUT!G29)/INPUT!G101,"–") -> 2.8950386 | H54: =IFERROR(ABS(INPUT!H29)/INPUT!H101,"–") -> -16.966695
...

Sheet NAV
B1: FinSight | H1: NAV — Net Asset Value Valuation (REIT) | K1: DCF — Discounted Cash Flow Valuation
B3: NAV
B4: All figures in USD millions unless stated
B5: METRIC | D5: =IF(INPUT!D5="","",INPUT!D5) | E5: =IF(INPUT!E5="","",INPUT!E5) -> 2022 | F5: =IF(INPUT!F5="","",INPUT!F5) -> 2023 | G5: =IF(INPUT!G5="","",INPUT!G5) -> 2024 | H5: =IF(INPUT!H5="","",INPUT!H5) -> 2025 (LTM) | I5: =TEXT(INPUT!D139+1,"0")&"F" -> 2026F | J5: =TEXT(INPUT!D139+2,"0")&"F" -> 2027F | K5: =TEXT(INPUT!D139+3,"0")&"F" -> 2028F | L5: =TEXT(INPUT!D139+4,"0")&"F" -> 2029F | M5: =TEXT(INPUT!D139+5,"0")&"F" -> 2030F | N5: Terminal
B6: COMPTE DE RÉSULTAT — REIT (Historique + Projection)
B8: Revenue (Rental Income) | D8: =INPUT!D9 -> 0 | E8: =INPUT!E9 -> 5973.69 | F8: =INPUT!F9 -> 8023.47 | G8: =INPUT!G9 -> 8201.61 | H8: =IF(INPUT!H9<>"",INPUT!H9,INPUT!G9) -> 8790.13 | I8: =H8*(1+$I$30) -> 23504.679 | J8: =I8*(1+$I$30) -> 62851.166 | K8: =J8*(1+$I$30) -> 168063.1 | L8: =K8*(1+$I$30) -> 449398.26 | M8: =L8*(1+$I$30) -> 1201684.3
B9: Property Operating Expenses | D9: =INPUT!D10 -> 0 | E9: =INPUT!E10 -> -1509.09 | F9: =INPUT!F10 -> -2010.34 | G9: =INPUT!G10 -> -2057.24 | H9: =IF(INPUT!H10<>"",INPUT!H10,INPUT!G10) -> -2234.65 | I9: =-I8*(1-$I$31) -> -5924.5687 | J9: =-J8*(1-$I$31) -> -15842.21 | K9: =-K8*(1-$I$31) -> -42361.837 | L9: =-L8*(1-$I$31) -> -113274.93 | M9: =-M8*(1-$I$31) -> -302895.5
B10: NOI — Net Operating Income | D10: =SUM(D8:D9) -> 0 | E10: =SUM(E8:E9) -> 4464.6 | F10: =SUM(F8:F9) -> 6013.13 | G10: =SUM(G8:G9) -> 6144.37 | H10: =SUM(H8:H9) -> 6555.48 | I10: =SUM(I8:I9) -> 17580.11 | J10: =SUM(J8:J9) -> 47008.956 | K10: =SUM(K8:K9) -> 125701.26 | ... M10: =SUM(M8:M9) -> 898788.85
B12: G&A Expenses | D12: =INPUT!D14 -> 0 | E12: =INPUT!E14 -> -331.08 | F12: =INPUT!F14 -> -390.41 | G12: =INPUT!G14 -> -418.76 | H12: =IF(INPUT!H14<>"",INPUT!H14,INPUT!G14) -> -469.11 | I12: =-I8*$I$32 -> -1225.2261 | J12: =-J8*$I$32 -> -3276.2366 | K12: =-K8*$I$32 -> -8760.6086 | L12: =-L8*$I$32 -> -23425.739 | M12: =-M8*$I$32 -> -62640.082
B13: — (ligne non applicable REIT) | D13: =INPUT!D15 -> 0 | E13: =INPUT!E15 -> -3075 | F13: =INPUT!F15 -> -3969 | G13: =INPUT!G15 -> -4540 | H13: =IF(INPUT!H15<>"",INPUT!H15,INPUT!G15) -> -6411 | I13: =-I8*$I$33 -> -1175.2339 | J13: =-J8*$I$33 -> -3142.5583 | K13: =-K8*$I$33 -> -8403.1548 | L13: =-L8*$I$33 -> -22469.913 | M13: =-M8*$I$33 -> -60084.217
B14: EBITDA | D14: =INPUT!D30 -> 0 | E14: =INPUT!E30 -> 1058.52 | F14: =INPUT!F30 -> 1653.72 | G14: =INPUT!G30 -> 1185.61 | H14: =IF(INPUT!H30<>"",INPUT!H30,INPUT!G30) -> -324.63 | I14: =I10+I12+I13 -> 15179.65 | J14: =J10+J12+J13 -> 40590.162 | K14: =K10+K12+K13 -> 108537.5 | L14: =L10+L12+L13 -> 290227.67 | M14: =M10+M12+M13 -> 776064.55
B16: Depreciation & Amortization | D16: =INPUT!D16 -> 0 | E16: =INPUT!E16 -> -1812.78 | F16: =INPUT!F16 -> -2484.89 | G16: =INPUT!G16 -> -2580.52 | H16: =IF(INPUT!H16<>"",INPUT!H16,INPUT!G16) -> -2626.03 | I16: =-I8*$I$34 -> -1292.7573 | J16: =-J8*$I$34 -> -3456.8141 | K16: =-K8*$I$34 -> -9243.4703 | L16: =-L8*$I$34 -> -24716.904 | M16: =-M8*$I$34 -> -66092.639
B17: EBIT | D17: =D14+D16 -> 0 | E17: =E14+E16 -> -754.26 | F17: =F14+F16 -> -831.17 | G17: =G14+G16 -> -1394.91 | H17: =H14+H16 -> -2950.66 | I17: =I14+I16 -> 13886.893 | J17: =J14+J16 -> 37133.347 | K17: =K14+K16 -> 99294.026 | ... M17: =M14+M16 -> 709971.91
B19: Interest Expense | D19: =INPUT!D20 -> 0 | E19: =INPUT!E20 -> -291.9 | F19: =INPUT!F20 -> -618.72 | G19: =INPUT!G20 -> -837.3 | H19: =IF(INPUT!H20<>"",INPUT!H20,INPUT!G20) -> -972.26 | I19: =-I17*(INPUT!H125)/(1-$I$35) -> -406.90424 | J19: =-J17*(INPUT!H125)/(1-$I$35) -> -1088.056 | K19: =-K17*(INPUT!H125)/(1-$I$35) -> -2909.4457 | L19: =-L17*(INPUT!H125)/(1-$I$35) -> -7779.8153 | M19: =-M17*(INPUT!H125)/(1-$I$35) -> -20803.112
B20: EBT (Earnings Before Tax) | D20: =D17+D19 -> 0 | E20: =E17+E19 -> -1046.16 | F20: =F17+F19 -> -1449.89 | G20: =G17+G19 -> -2232.21 | H20: =H17+H19 -> -3922.92 | I20: =I17+I19 -> 13479.988 | J20: =J17+J19 -> 36045.291 | K20: =K17+K19 -> 96384.581 | ... M20: =M17+M19 -> 689168.8
B22: Income Taxes | D22: =INPUT!D24 -> 0 | E22: =INPUT!E24 -> 52 | F22: =INPUT!F24 -> 94 | G22: =INPUT!G24 -> 112 | H22: =IF(INPUT!H24<>"",INPUT!H24,INPUT!G24) -> 212 | I22: =-I20*$I$35 -> -736.68137 | J22: =-J20*$I$35 -> -1969.8752 | K22: =-K20*$I$35 -> -5267.4173 | L22: =-L20*$I$35 -> -14084.997 | M22: =-M20*$I$35 -> -37663.075
B23: Net Income (biaisé par D&A — voir FFO) | D23: =D20+D22 -> 0 | E23: =E20+E22 -> -994.16 | F23: =F20+F22 -> -1355.89 | G23: =G20+G22 -> -2120.21 | H23: =H20+H22 -> -3710.92 | I23: =I20+I22 -> 12743.307 | J23: =J20+J22 -> 34075.416 | K23: =K20+K22 -> 91117.163 | ... M23: =M20+M22 -> 651505.72
B25: HYPOTHÈSES — MODÈLE NAV
B26: All figures in USD millions unless stated | H26: GAV ($M) | I26: =IFERROR(C62,"–") -> 111709.09
B28: SCÉNARIO
B29: NAV/Share ($) | D29: Base | I29: =IFERROR(C70,"–") -> 83.495355
B30: Revenue Growth Rate (YoY) | D30: =IFERROR(IF(NOT(ISBLANK(INPUT!H9)),INPUT!H9/INPUT!G9-1,IF(NOT(ISBLANK(INPUT!G9)),INPUT!G9/INPUT!F9-1,IF(NOT(ISBLANK(INPUT!F9)),INPUT!F9/INPUT!E9-1,IF(NOT(ISBLANK(INPUT!E9)),INPUT!E9/INPUT!D9-1,0.05)))),0.05) -> 0.071756643 | I30: =IFERROR(C72,"–") -> 1.6739853
B31: NOI Margin (NOI / Revenue) | D31: =IFERROR(INPUT!H11/INPUT!H9,"–") -> 0.74577737 | I31: =IFERROR(AVERAGE(IF(INPUT!E9<>0,INPUT!E11/INPUT!E9),IF(INPUT!F9<>0,INPUT!F11/INPUT!F9),IF(INPUT!G9<>0,INPUT!G11/INPUT!G9),IF(INPUT!H9<>0,INPUT!H11/INPUT!H9)),0.4) -> 0.74794088
B32: G&A (% of Revenue) | D32: =IFERROR(ABS(INPUT!H14)/INPUT!H9,0.15) -> 0.053367811 | I32: =IFERROR(AVERAGE(IF(INPUT!E9<>0,ABS(INPUT!E14)/INPUT!E9),IF(INPUT!F9<>0,ABS(INPUT!F14)/INPUT!F9),IF(INPUT!G9<>0,ABS(INPUT!G14)/INPUT!G9),IF(INPUT!H9<>0,ABS(INPUT!H14)/INPUT!H9)),0.15) -> 0.052126902
B33: Cap Rate — Bull Case (%) | D33: 0.05 | I33: 0.05
B34: Cap Rate — Actif (selon scénario) | D34: =IF(D29="Bull",D33,IF(D29="Bear",I36,0.055)) -> 0.055 | I34: 0.055
B35: Tax Rate (effective) | D35: =I35 -> 0.05465 | I35: =IFERROR(AVERAGEIF(INPUT!E126:H126,"<>0"),0.21) -> 0.05465
B36: Cap Rate — Bear Case (%) | I36: 0.065
B37: Recurring CapEx (% Revenue — maintenance) | D37: 0.05
B38: Straight-Line Rent Adj. + SBC (% Revenue) | D38: 0.02
B39: (+) Depreciation & Amortization | E39: =ABS(E16) -> 1812.78 | F39: =ABS(F16) -> 2484.89 | G39: =ABS(G16) -> 2580.52 | H39: =ABS(H16) -> 2626.03 | I39: =ABS(I16) -> 1292.7573 | J39: =ABS(J16) -> 3456.8141 | K39: =ABS(K16) -> 9243.4703 | L39: =ABS(L16) -> 24716.904 | M39: =ABS(M16) -> 66092.639
B40: (−) Recurring CapEx (Maintenance) | E40: =INPUT!E78 -> -15690 | F40: =INPUT!F78 -> -17722 | G40: =INPUT!G78 -> -14909 | H40: =IF(INPUT!H78<>"",INPUT!H78,INPUT!G78) -> -16953 | I40: =-I8*$D$37 -> -1175.2339 | J40: =-J8*$D$37 -> -3142.5583 | K40: =-K8*$D$37 -> -8403.1548 | L40: =-L8*$D$37 -> -22469.913 | M40: =-M8*$D$37 -> -60084.217
B41: (−) Straight-Line Rent Adj. + SBC | E41: =INPUT!E70+INPUT!E71+INPUT!E72+INPUT!E73 -> -1947.14 | F41: =INPUT!F70+INPUT!F71+INPUT!F72+INPUT!F73 -> 5816.57 | G41: =INPUT!G70+INPUT!G71+INPUT!G72+INPUT!G73 -> 2592.6 | H41: =IF(INPUT!H70<>"",INPUT!H70,INPUT!G70)+IF(INPUT!H71<>"",INPUT!H71,INPUT!G71)+IF(INPUT!H72<>"",INPUT!H72,INPUT!G72)+IF(INPUT!H73<>"",INPUT!H73,INPUT!G73) -> 5700.91 | I41: =-I8*$D$38 -> -470.09357 | J41: =-J8*$D$38 -> -1257.0233 | K41: =-K8*$D$38 -> -3361.2619 | L41: =-L8*$D$38 -> -8987.9651 | M41: =-M8*$D$38 -> -24033.687
B42: FFO = NI + D&A | E42: =E23+E39+E40+E41 -> -16818.52 | F42: =F23+F39+F40+F41 -> -10776.43 | G42: =G23+G39+G40+G41 -> -11856.09 | H42: =H23+H39+H40+H41 -> -12336.98 | I42: =I23+I39+I40+I41 -> 12390.737 | J42: =J23+J39+J40+J41 -> 33132.649 | K42: =K23+K39+K40+K41 -> 88596.217 | L42: =L23+L39+L40+L41 -> 236904.98 | M42: =M23+M39+M40+M41 -> 633480.46
B43: AFFO = FFO − Recurring CapEx − SL Rent − SBC
B44: COÛT DU CAPITAL — REIT
B46: Risk-Free Rate (Rf) | D46: =INPUT!H122 -> 0.0428 | N46: =D46 -> 0.0428
B47: Beta (Levered) | D47: =INPUT!H121 -> 1.412 | N47: =D47 -> 1.412
B48: Equity Risk Premium (ERP) | D48: =INPUT!H123 -> 0.05 | N48: =D48 -> 0.05
B49: Cost of Equity (CAPM) | D49: =D46+D47*D48 -> 0.1134 | N49: =D49 -> 0.1134
...

Sheet COMPARABLES
B1: FinSight | K1: COMPARABLES — Trading Comparables
B3: COMPARABLES
B4: All figures in USD millions unless stated
B6: COMPARABLE TRADING ANALYSIS
D7: Share Price | E7: Enterprise Value | F7: FFO/Share (LTM) | G7: P/FFO (x) | H7: P/AFFO (x) | I7: Div Yield (%) | J7: Occupancy (%) | K7: LTV (%)
B8: PEER COMPANIES | C8: TICKER | D8: (USD/sh) | E8: ($M) | F8: (USD/sh)
B9: DRE | C9: DRE | D9: 75.33 | E9: 173303.61 | F9: 4.21 | G9: 17.9 | H9: 19.2 | I9: 0.028 | J9: 0.971 | K9: 0.31
B10: EastGroup Properties, Inc. | C10: EGP | D10: 165.56 | E10: 10227.04 | F10: 6.84 | G10: 24.2 | H10: 26.1 | I10: 0.031 | J10: 0.983 | K10: 0.27
B11: STAG Industrial, Inc. | C11: STAG | D11: 32.58 | E11: 9053.32 | F11: 2.18 | G11: 14.9 | H11: 15.8 | I11: 0.048 | J11: 0.965 | K11: 0.35
B12: First Industrial Realty Trust, Inc. | C12: FR | D12: 51.96 | E12: 9075.56 | F12: 2.97 | G12: 17.5 | H12: 18.9 | I12: 0.022 | J12: 0.978 | K12: 0.29
B13: Rexford Industrial Realty, Inc. | C13: REXR | D13: 30.24 | E13: 10034.51 | F13: 1.63 | G13: 18.6 | H13: 20.3 | I13: 0.033 | J13: 0.974 | K13: 0.32
B15: Mean | D15: =IFERROR(AVERAGE(D9:D13),"–") -> 71.134 | E15: =IFERROR(AVERAGE(E9:E13),"–") -> 42338.808 | F15: =IFERROR(AVERAGE(F9:F13),"–") -> 3.566 | G15: =IFERROR(AVERAGE(G9:G13),"–") -> 18.62 | H15: =IFERROR(AVERAGE(H9:H13),"–") -> 20.06 | I15: =IFERROR(AVERAGE(I9:I13),"–") -> 0.0324 | J15: =IFERROR(AVERAGE(J9:J13),"–") -> 0.9742 | K15: =IFERROR(AVERAGE(K9:K13),"–") -> 0.308
B16: Median | D16: =IFERROR(MEDIAN(D9:D13),"–") -> 51.96 | E16: =IFERROR(MEDIAN(E9:E13),"–") -> 10034.51 | F16: =IFERROR(MEDIAN(F9:F13),"–") -> 2.97 | G16: =IFERROR(MEDIAN(G9:G13),"–") -> 17.9 | H16: =IFERROR(MEDIAN(H9:H13),"–") -> 19.2 | I16: =IFERROR(MEDIAN(I9:I13),"–") -> 0.031 | J16: =IFERROR(MEDIAN(J9:J13),"–") -> 0.974 | K16: =IFERROR(MEDIAN(K9:K13),"–") -> 0.31
B17: Maximum | D17: =IFERROR(MAX(D9:D13),"–") -> 165.56 | E17: =IFERROR(MAX(E9:E13),"–") -> 173303.61 | F17: =IFERROR(MAX(F9:F13),"–") -> 6.84 | G17: =IFERROR(MAX(G9:G13),"–") -> 24.2 | H17: =IFERROR(MAX(H9:H13),"–") -> 26.1 | I17: =IFERROR(MAX(I9:I13),"–") -> 0.048 | J17: =IFERROR(MAX(J9:J13),"–") -> 0.983 | K17: =IFERROR(MAX(K9:K13),"–") -> 0.35
B18: Minimum | D18: =IFERROR(MIN(D9:D13),"–") -> 30.24 | E18: =IFERROR(MIN(E9:E13),"–") -> 9053.32 | F18: =IFERROR(MIN(F9:F13),"–") -> 1.63 | G18: =IFERROR(MIN(G9:G13),"–") -> 14.9 | H18: =IFERROR(MIN(H9:H13),"–") -> 15.8 | I18: =IFERROR(MIN(I9:I13),"–") -> 0.022 | J18: =IFERROR(MIN(J9:J13),"–") -> 0.965 | K18: =IFERROR(MIN(K9:K13),"–") -> 0.27
B20: TARGET COMPANY VALUATION (Based on Peer Multiples)
B21: TARGET COMPANY METRICS (from INPUT) | D21: =INPUT!H5 -> 2025 (LTM)
B23: 2025 (LTM) | C23: ($M) | D23: =INPUT!H9/1000 -> 8.79013
B24: Target: Revenue (LTM) | C24: ($M) | D24: =IFERROR(INPUT!H9,"–") -> 8790.13
B25: Target: NOI / EBITDA (LTM) | C25: ($M) | D25: =IFERROR(IF(INPUT!H94<>"",INPUT!H94,INPUT!H30),"–") -> 6144
B26: Target: FFO (LTM) | C26: ($M) | D26: =IFERROR(INPUT!H100,"–") -> -1084.89
B27: Target: AFFO (LTM) | C27: ($M) | D27: =IFERROR(INPUT!H101,"–") -> -221.89
B28: Target: Net Debt | C28: ($M) | D28: =IFERROR(INPUT!H54+INPUT!H48-INPUT!H34,"–") -> 33891.42
B30: Target: Shares Outstanding | C30: (M) | D30: =IFERROR(INPUT!H118,"–") -> 932.23
B31: IMPLIED VALUATION — REIT (P/FFO Multiple Method) | D31: =IFERROR(D24*H18,"–") -> 138884.05 | E31: =IFERROR(D24*H15,"–") -> 176330.01 | F31: =IFERROR(D24*H16,"–") -> 168770.5 | G31: =IFERROR(D24*H17,"–") -> 229422.39
B32: P/FFO Median — Implied Market Cap ($M) | D32: =IFERROR(D26*18,"–") -> -19528.02 | E32: =IFERROR(D23*I15,"–") -> 0.28480021 | F32: =IFERROR(D23*I16,"–") -> 0.27249403 | G32: =IFERROR(D23*I17,"–") -> 0.42192624
B33: P/AFFO Median — Implied Market Cap ($M) | D33: =IFERROR(D27*20,"–") -> -4437.8 | E33: =IFERROR(D25*K15*D27,"–") -> -419893.99 | F33: =IFERROR(D25*K16*D27,"–") -> -422620.57 | G33: =IFERROR(D25*K17*D27,"–") -> -477152.26
B35: Implied Market Cap (Average, $M) | C35: ($M) | D35: =IFERROR(AVERAGE(D32,D33),"–") -> -11982.91 | E35: =IFERROR(AVERAGE(E31,E32),"–") -> 88165.146 | F35: =IFERROR(AVERAGE(F31,F32),"–") -> 84385.384 | G35: =IFERROR(AVERAGE(G31,G32),"–") -> 114711.41
B36: (−) Net Debt ($M) | C36: ($M) | D36: =IFERROR(D28,"–") -> 33891.42 | E36: =D26 -> -1084.89 | F36: =D26 -> -1084.89 | G36: =D26 -> -1084.89
B37: Implied Equity Value ($M) | C37: ($M) | D37: =IFERROR(D35,"–") -> -11982.91 | E37: =IFERROR(E35-E36,"–") -> 89250.036 | F37: =IFERROR(F35-F36,"–") -> 85470.274 | G37: =IFERROR(G35-G36,"–") -> 115796.3
B38: Implied Share Price ($) | C38: ($) | D38: =IFERROR(D37/D30,"–") -> -12.854027 | E38: =IFERROR(E37/D27,"–") -> -402.22649 | F38: =IFERROR(F37/D27,"–") -> -385.1921 | G38: =IFERROR(G37/D27,"–") -> -521.86352
B39: Current Share Price ($) | C39: ($) | D39: =IFERROR(INPUT!H117,"–") -> 139.77 | E39: =INPUT!H117 -> 139.77 | F39: =INPUT!H117 -> 139.77 | G39: =INPUT!H117 -> 139.77
B40: Implied Upside / (Downside) | C40: (%) | D40: =IFERROR((D38-D39)/D39,"–") -> -1.0919656 | E40: =IFERROR(E38/D39-1,"–") -> -3.8777741 | F40: =IFERROR(F38/D39-1,"–") -> -3.7558997 | G40: =IFERROR(G38/D39-1,"–") -> -4.7337306
B45: © 2015 to 2024 FinSight
B46: This Excel model is for educational purposes only.
B47: https://finsight.com/
B49: Company | C49: EV/EBITDA (x) | D49: EV/Revenue (x) | E49: P/E (x)
B50: =B9 -> DRE | C50: =IFERROR(H9*1,0) -> 19.2 | D50: =IFERROR(I9*1,0) -> 0.028 | E50: =IFERROR(K9*1,0) -> 0.31
B51: =B10 -> EastGroup Properties, Inc. | C51: =IFERROR(H10*1,0) -> 26.1 | D51: =IFERROR(I10*1,0) -> 0.031 | E51: =IFERROR(K10*1,0) -> 0.27
B52: =B11 -> STAG Industrial, Inc. | C52: =IFERROR(H11*1,0) -> 15.8 | D52: =IFERROR(I11*1,0) -> 0.048 | E52: =IFERROR(K11*1,0) -> 0.35
...

Sheet SCENARIOS
B1: FinSight | H1: SCENARIOS — Scenario Analysis
B3: SCENARIOS
B4: All figures in USD millions unless stated | 3 scenarios: Pessimistic / Realistic (Base) / Optimistic
B5: METRIC
B6: ▶ SELECT SCENARIO | D6: Realistic
B7: DRIVER | C7: Pessimistic | D7: Realistic | E7: Optimistic
B8: Revenue Growth Rate (Y1-Y5) | C8: 0.04 | D8: 0.04 | E8: 0.09
B9: Cap Rate (exit, %) | C9: 0.065 | D9: 0.055 | E9: 0.05
B10: Same-Store NOI Growth | C10: 0.58 | D10: 0.62 | E10: 0.66
B11: Occupancy Rate | C11: 0.93 | D11: 0.95 | E11: 0.97
B12: WACC (Cost of Capital) | C12: {=IFERROR(INDEX(SECTOR_REF!$C$2:$E$71,MATCH(1,(SECTOR_REF!$A$2:$A$71=INPUT!$D$138)*(SECTOR_REF!$B$2:$B$71="WACC"),0),MATCH("Pessimiste",{"Pessimiste","Realiste","Optimiste"},0)),NAV!$D$56+0.015)} -> 0.10992262 | D12: {=IFERROR(INDEX(SECTOR_REF!$C$2:$E$71,MATCH(1,(SECTOR_REF!$A$2:$A$71=INPUT!$D$138)*(SECTOR_REF!$B$2:$B$71="WACC"),0),MATCH("Realiste",{"Pessimiste","Realiste","Optimiste"},0)),NAV!$D$56)} -> 0.094922623 | E12: {=IFERROR(INDEX(SECTOR_REF!$C$2:$E$71,MATCH(1,(SECTOR_REF!$A$2:$A$71=INPUT!$D$138)*(SECTOR_REF!$B$2:$B$71="WACC"),0),MATCH("Optimiste",{"Pessimiste","Realiste","Optimiste"},0)),NAV!D56-0.015)} -> 0.079922623
B13: ▶ Secteur actif : | D13: =IF(INPUT!$D$138="","— Aucun secteur sélectionné (INPUT!D116) —",INPUT!$D$138) -> Real Estate
B14: SCENARIO RESULTS — DYNAMIC VIEW
B15: METRIC | D15: =TEXT(INPUT!D139-3,"0") -> 2022 | E15: =TEXT(INPUT!D139-2,"0") -> 2023 | F15: =TEXT(INPUT!D139-1,"0") -> 2024 | G15: =INPUT!D139&" (LTM)" -> 2025 (LTM) | H15: =TEXT(INPUT!D139+1,"0")&"F" -> 2026F | I15: =TEXT(INPUT!D139+2,"0")&"F" -> 2027F | J15: =TEXT(INPUT!D139+3,"0")&"F" -> 2028F | K15: =TEXT(INPUT!D139+4,"0")&"F" -> 2029F | L15: =TEXT(INPUT!D139+5,"0")&"F" -> 2030F
B16: Revenue | D16: =INPUT!E9 -> 5973.69 | E16: =INPUT!F9 -> 8023.47 | F16: =INPUT!G9 -> 8201.61 | G16: =INPUT!H9 -> 8790.13 | H16: =INPUT!H9*(1+IF($D$6="Pessimistic",$D$8,IF($D$6="Realistic",$D$8,$E$8))) -> 9141.7352 | I16: =H16*(1+IF($D$6="Pessimistic",$D$8,IF($D$6="Realistic",$D$8,$E$8))) -> 9507.4046 | J16: =I16*(1+IF($D$6="Pessimistic",$D$8,IF($D$6="Realistic",$D$8,$E$8))) -> 9887.7008 | K16: =J16*(1+IF($D$6="Pessimistic",$D$8,IF($D$6="Realistic",$D$8,$E$8))) -> 10283.209 | L16: =K16*(1+IF($D$6="Pessimistic",$D$8,IF($D$6="Realistic",$D$8,$E$8))) -> 10694.537
B17: NOI (Net Operating Income) | D17: =INPUT!E11 -> 4464.6 | E17: =INPUT!F11 -> 6013.13 | F17: =INPUT!G11 -> 6144.37 | G17: =INPUT!H11 -> 6555.48 | H17: =H16*IF($D$6="Pessimistic",$D$9,IF($D$6="Realistic",$D$9,$E$9)) -> 502.79544 | I17: =I16*IF($D$6="Pessimistic",$D$9,IF($D$6="Realistic",$D$9,$E$9)) -> 522.90725 | J17: =J16*IF($D$6="Pessimistic",$D$9,IF($D$6="Realistic",$D$9,$E$9)) -> 543.82354 | K17: =K16*IF($D$6="Pessimistic",$D$9,IF($D$6="Realistic",$D$9,$E$9)) -> 565.57649 | L17: =L16*IF($D$6="Pessimistic",$D$9,IF($D$6="Realistic",$D$9,$E$9)) -> 588.19954
B18: EBITDA | D18: =INPUT!E30 -> 1058.52 | E18: =INPUT!F30 -> 1653.72 | F18: =INPUT!G30 -> 1185.61 | G18: =INPUT!H30 -> -324.63 | H18: =H16*IF($D$6="Pessimistic",$D$10,IF($D$6="Realistic",$D$10,$E$10)) -> 5667.8758 | I18: =I16*IF($D$6="Pessimistic",$D$10,IF($D$6="Realistic",$D$10,$E$10)) -> 5894.5909 | J18: =J16*IF($D$6="Pessimistic",$D$10,IF($D$6="Realistic",$D$10,$E$10)) -> 6130.3745 | K18: =K16*IF($D$6="Pessimistic",$D$10,IF($D$6="Realistic",$D$10,$E$10)) -> 6375.5895 | L18: =L16*IF($D$6="Pessimistic",$D$10,IF($D$6="Realistic",$D$10,$E$10)) -> 6630.613
B19: Net Income (biaisé par D&A — voir FFO) | D19: =INPUT!E26 -> -994.16 | E19: =INPUT!F26 -> -1355.89 | F19: =INPUT!G26 -> -2120.21 | G19: =INPUT!H26 -> -3710.92 | H19: =H18*0.6 -> 3400.7255 | I19: =I18*0.6 -> 3536.7545 | J19: =J18*0.6 -> 3678.2247 | K19: =K18*0.6 -> 3825.3537 | L19: =L18*0.6 -> 3978.3678
B20: FFO (NI + D&A) | D20: =IFERROR(INPUT!E75+INPUT!E78,"–") -> -18875.27 | E20: =IFERROR(INPUT!F75+INPUT!F78,"–") -> -13799.74 | F20: =IFERROR(INPUT!G75+INPUT!G78,"–") -> -15002.33 | G20: =IFERROR(INPUT!H75+INPUT!H78,"–") -> -15568.45 | H20: =H18*0.5 -> 2833.9379 | I20: =I18*0.5 -> 2947.2954 | J20: =J18*0.5 -> 3065.1872 | K20: =K18*0.5 -> 3187.7947 | L20: =L18*0.5 -> 3315.3065
B21: Cap Rate (scenario) | D21: =IFERROR(INPUT!E30/INPUT!E9,"–") -> 0.17719701 | E21: =IFERROR(INPUT!F30/INPUT!F9,"–") -> 0.20611032 | F21: =IFERROR(INPUT!G30/INPUT!G9,"–") -> 0.1445582 | G21: =IFERROR(INPUT!H30/INPUT!H9,"–") -> -0.036931194 | H21: =IFERROR(H18/H16,"–") -> 0.62 | I21: =IFERROR(IF(C6="Pessimistic",C9,IF(C6="Optimistic",$E$9,D9)),"–") -> 0.055 | J21: =IFERROR(IF(C6="Pessimistic",C9,IF(C6="Optimistic",$E$9,D9)),"–") -> 0.055 | K21: =IFERROR(IF($D$6="Pessimistic",$D$9,IF($D$6="Optimistic",$E$9,$D$9)),"–") -> 0.055 | L21: =IFERROR(IF($D$6="Pessimistic",$D$9,IF($D$6="Optimistic",$E$9,$D$9)),"–") -> 0.055 | M21: =IFERROR(IF($D$6="Pessimistic",$D$9,IF($D$6="Optimistic",$E$9,$D$9)),"–") -> 0.055
B22: Implied NAV / Share ($) | M22: =IFERROR(IF($D$6="Pessimistic",D31,IF($D$6="Optimistic",F31,E31)),"–") -> 105.92365
B24: SCENARIO SUMMARY COMPARISON
B25: METRIC (Year 5) | D25: Pessimistic | E25: Realistic | F25: Optimistic
B26: Revenue (Year 5) | C26: 0 | D26: =INPUT!H9*(1+$D$8)^5 -> 10694.537 | E26: =INPUT!H9*(1+IF($D$6="Pessimistic",$D$8,IF($D$6="Realistic",$D$8,$E$8)))^5 -> 10694.537 | F26: =INPUT!H9*(1+$E$8)^5 -> 13524.705
B27: NOI (Year 5) | C27: 0 | D27: =D26*$D$10 -> 6630.613 | E27: =E26*IF($D$6="Pessimistic",$D$10,IF($D$6="Realistic",$D$10,$E$10)) -> 6630.613 | F27: =F26*$E$10 -> 8926.305
B28: FFO (Year 5) | C28: 0 | D28: =D27*0.6 -> 3978.3678 | E28: =E27*0.6 -> 3978.3678 | F28: =F27*0.6 -> 5355.783
B29: AFFO (Year 5) | C29: 0 | D29: =D27*0.5 -> 3315.3065 | E29: =E27*0.5 -> 3315.3065 | F29: =F27*0.5 -> 4463.1525
B30: Cap Rate Scenario | D30: =$D$10 -> 0.62 | E30: =$E$9 -> 0.05 | F30: =$E$10 -> 0.66
B31: Implied NAV / Share ($) | D31: =IFERROR((D27/D9-INPUT!H54-INPUT!H48+INPUT!H34)/INPUT!H52,"–") -> 92.988392 | E31: =IFERROR((E27/$E$9-INPUT!H54-INPUT!H48+INPUT!H34)/INPUT!H52,"–") -> 105.92365 | F31: =IFERROR((F27/E9-INPUT!H54-INPUT!H48+INPUT!H34)/INPUT!H52,"–") -> 155.18743
B32: Upside / (Downside) vs Current Price | D32: =IFERROR(D31/INPUT!H117-1,"–") -> -0.33470422 | E32: =IFERROR(E31/INPUT!H117-1,"–") -> -0.24215748 | F32: =IFERROR(F31/INPUT!H117-1,"–") -> 0.11030568
B33: Revenue
B34: ="▶ SCÉNARIO SÉLECTIONNÉ : "&$D$6 -> ▶ SCÉNARIO SÉLECTIONNÉ : Realistic
B36: CHART DATA: Revenue by Scenario
B37: Year | D37: =TEXT(INPUT!D139+1,"0")&"F" -> 2026F | E37: =TEXT(INPUT!D139+2,"0")&"F" -> 2027F | F37: =TEXT(INPUT!D139+3,"0")&"F" -> 2028F | G37: =TEXT(INPUT!D139+4,"0")&"F" -> 2029F | H37: =TEXT(INPUT!D139+5,"0")&"F" -> 2030F
B38: Pessimistic | D38: =IF(INPUT!H9="",NA(),INPUT!H9*(1+$D$8)) -> 9141.7352 | E38: =IF(INPUT!H9="",NA(),D38*(1+$D$8)) -> 9507.4046 | F38: =IF(INPUT!H9="",NA(),E38*(1+$D$8)) -> 9887.7008 | G38: =IF(INPUT!H9="",NA(),F38*(1+$D$8)) -> 10283.209 | H38: =IF(INPUT!H9="",NA(),G38*(1+$D$8)) -> 10694.537
B39: Realistic | D39: =IF(INPUT!H9="",NA(),INPUT!H9*(1+IF($D$6="Pessimistic",$D$8,IF($D$6="Realistic",$D$8,$E$8)))) -> 9141.7352 | E39: =IF(INPUT!H9="",NA(),D39*(1+IF($D$6="Pessimistic",$D$8,IF($D$6="Realistic",$D$8,$E$8)))) -> 9507.4046 | F39: =IF(INPUT!H9="",NA(),E39*(1+IF($D$6="Pessimistic",$D$8,IF($D$6="Realistic",$D$8,$E$8)))) -> 9887.7008 | G39: =IF(INPUT!H9="",NA(),F39*(1+IF($D$6="Pessimistic",$D$8,IF($D$6="Realistic",$D$8,$E$8)))) -> 10283.209 | H39: =IF(INPUT!H9="",NA(),G39*(1+IF($D$6="Pessimistic",$D$8,IF($D$6="Realistic",$D$8,$E$8)))) -> 10694.537
B40: Optimistic | D40: =IF(INPUT!H9="",NA(),INPUT!H9*(1+$E$8)) -> 9581.2417 | E40: =IF(INPUT!H9="",NA(),D40*(1+$E$8)) -> 10443.553 | F40: =IF(INPUT!H9="",NA(),E40*(1+$E$8)) -> 11383.473 | G40: =IF(INPUT!H9="",NA(),F40*(1+$E$8)) -> 12407.986 | H40: =IF(INPUT!H9="",NA(),G40*(1+$E$8)) -> 13524.705
B41: SCENARIO SUMMARY COMPARISON
B42: CHART DATA: NOI by Scenario
B43: Year | D43: =TEXT(INPUT!D139+1,"0")&"F" -> 2026F | E43: =TEXT(INPUT!D139+2,"0")&"F" -> 2027F | F43: =TEXT(INPUT!D139+3,"0")&"F" -> 2028F | G43: =TEXT(INPUT!D139+4,"0")&"F" -> 2029F | H43: =TEXT(INPUT!D139+5,"0")&"F" -> 2030F
...

Sheet DASHBOARD
B1: FinSight | Q1: Année | R1: 2022 | S1: 2023 | T1: 2024
Q2: Année | R2: Cumul Revenue | S2: =RATIOS!F70 -> 22198.77 | T2: =RATIOS!G70 -> 22198.77
B3: Financial Performance | Q3: 2022 | R3: =RATIOS!E70 -> 13997.16
B4: ="All figures in "&INPUT!D140&" "&INPUT!D141&" unless stated" -> All figures in USD M unless stated | Q4: 2023 | R4: =RATIOS!F70 -> 22198.77
Q5: 2024 | R5: =RATIOS!G70 -> 22198.77
Q6: Year
B7: Revenue & Profitability | H7: Profit Margins | Q7: 2022 | R7: Revenue | S7: Net Income | T7: Net Margin
Q8: 2023 | R8: =RATIOS!E67 -> 5973.69 | S8: =RATIOS!E69 -> -1355.89 | T8: =RATIOS!E74 -> -0.1664231
Q9: 2024 | R9: =RATIOS!F67 -> 8023.47 | S9: =RATIOS!F69 -> -2120.21 | T9: =RATIOS!F74 -> -0.16899047
Q10: 2025 (LTM) | R10: =RATIOS!G67 -> 8201.61 | S10: =RATIOS!G69 -> -2120.21 | T10: =RATIOS!G74 -> -0.25851144
R11: =RATIOS!H67 -> 8790.13 | S11: =RATIOS!H69 -> -3710.92 | T11: =RATIOS!H74 -> -0.42216896
B24: Cumulative revenue | H24: Expense Breakdown
B41: Performance Summary (Five-Year) | H41: Income Statement (LTM)
C43: 5-Yr Avg | D43: Trend | I43: Actual | J43: Prev Year | K43: Variance | L43: Var %
B44: Revenue | C44: =AVERAGE(INPUT!D9:H9) -> 7747.225 | D44: =IF(INPUT!H9>INPUT!G9,"▲",IF(INPUT!H9<INPUT!G9,"▼","→")) -> ▲ | H44: Revenue | I44: =INPUT!H9 -> 8790.13 | J44: =INPUT!G9 -> 8201.61 | K44: =I44-J44 -> 588.52 | L44: =IF(J44=0,NA(),K44/ABS(J44)) -> 0.071756643
B46: COGS | C46: =ABS(AVERAGE(INPUT!D10:H10)) -> 1952.83 | D46: =IF(ABS(INPUT!H10)<ABS(INPUT!G10),"▲",IF(ABS(INPUT!H10)>ABS(INPUT!G10),"▼","→")) -> ▼ | H46: COGS | I46: =ABS(INPUT!H10) -> 2234.65 | J46: =ABS(INPUT!G10) -> 2057.24 | K46: =I46-J46 -> 177.41 | L46: =IF(J46=0,NA(),K46/ABS(J46)) -> 0.0862369
B48: Expenses | C48: =ABS(AVERAGE(INPUT!D13:H13)) -> 5821.716 | D48: =IF(ABS(INPUT!H13)<ABS(INPUT!G13),"▲",IF(ABS(INPUT!H13)>ABS(INPUT!G13),"▼","→")) -> ▼ | H48: Expenses | I48: =ABS(INPUT!H13) -> 9506.14 | J48: =ABS(INPUT!G13) -> 7539.28 | K48: =I48-J48 -> 1966.86 | L48: =IF(J48=0,NA(),K48/ABS(J48)) -> 0.26088168
B50: Net Income | C50: =AVERAGE(INPUT!D26:H26) -> -1636.236 | D50: =IF(INPUT!H26>INPUT!G26,"▲",IF(INPUT!H26<INPUT!G26,"▼","→")) -> ▼ | H50: Net Income | I50: =INPUT!H26 -> -3710.92 | J50: =INPUT!G26 -> -2120.21 | K50: =I50-J50 -> -1590.71 | L50: =IF(J50=0,NA(),K50/ABS(J50)) -> -0.75026059
B52: Net Margin (%) | C52: =AVERAGE(INPUT!D26:H26)/AVERAGE(INPUT!D9:H9) -> -0.21120285 | D52: =IF(INPUT!H26/INPUT!H9>INPUT!G26/INPUT!G9,"▲",IF(INPUT!H26/INPUT!H9<INPUT!G26/INPUT!G9,"▼","→")) -> ▼ | H52: Net Margin (%) | I52: =INPUT!H26/INPUT!H9 -> -0.42216896 | J52: =INPUT!G26/INPUT!G9 -> -0.25851144 | K52: =I52-J52 -> -0.16365752 | L52: =IF(J52=0,NA(),K52/ABS(J52)) -> -0.6330765
B54: MÉTRIQUES REIT — Top 3 KPIs (LTM)
B55: P/NAV | C55: =IFERROR(RATIOS!H13,"–") -> 0.14996781 | D55: Bmk : 0.85-1.15x • n.d. si NAV manquante
B56: Occupancy Rate | C56: =IFERROR(INPUT!H107,"–") -> 0.965 | D56: Bmk : >95% (Industrial) • Excellent si >98%
B57: FFO Growth (YoY) | C57: =IFERROR((INPUT!H100-INPUT!G100)/ABS(INPUT!G100),"–") -> -3.3568682 | D57: Bmk : 5-10% target • Source : RATIOS
B58: P&L Summary (LTM) | H58: Balance Sheet Summary (LTM)
D60: =INPUT!G5 -> 2024 | E60: =INPUT!H5 -> 2025 (LTM) | J60: =INPUT!G5 -> 2024 | K60: =INPUT!H5 -> 2025 (LTM) | S60: =INPUT!G9 -> 8201.61 | T60: =INPUT!H9 -> 8790.13
H61: Assets
B62: COGS | D62: =-ABS(INPUT!G10) -> -2057.24 | E62: =-ABS(INPUT!H10) -> -2234.65 | H62: Current Assets | J62: =INPUT!G38 -> 20665.05 | K62: =INPUT!H38 -> 18514.99
B63: Gross Profit | D63: =S60+D62 -> 6144.37 | E63: =T60+E62 -> 6555.48 | H63: Non-current Assets | J63: =SUM(INPUT!G41:G43) -> 4197.88 | K63: =SUM(INPUT!H41:H43) -> 4705.76
B64: SG&A | D64: =-ABS(INPUT!G14) -> -418.76 | E64: =-ABS(INPUT!H14) -> -469.11
B65: R&D | D65: =-ABS(INPUT!G15) -> -4540 | E65: =-ABS(INPUT!H15) -> -6411 | H65: Total Assets | J65: =INPUT!G44 -> 24862.93 | K65: =INPUT!H44 -> 23220.75
B66: D&A | D66: =-ABS(INPUT!G16) -> -2580.52 | E66: =-ABS(INPUT!H16) -> -2626.03
B67: EBIT (Operating Profit) | D67: =D63+D64+D65+D66 -> -1394.91 | E67: =E63+E64+E65+E66 -> -2950.66 | H67: Liabilities
B68: Net Interest | D68: =-ABS(INPUT!G20) -> -837.3 | E68: =-ABS(INPUT!H20) -> -972.26 | H68: Current Liabilities | J68: =INPUT!G51 -> 2137.38 | K68: =INPUT!H51 -> 2165.03
B69: EBT (Pre-Tax Income) | D69: =D67+D68 -> -2232.21 | E69: =E67+E68 -> -3922.92 | H69: Long-term Liabilities | J69: =INPUT!G54 -> 30654.3 | K69: =INPUT!H54 -> 34992.39
B70: Income Tax | D70: =-ABS(INPUT!G21) -> 0 | E70: =-ABS(INPUT!H21) -> 0 | H70: Total Liabilities | J70: =INPUT!G55 -> 32791.68 | K70: =INPUT!H55 -> 37157.42
B71: Net Income | D71: =D69+D70 -> -2232.21 | E71: =E69+E70 -> -3922.92 | H71: Shareholders' Equity | J71: =INPUT!G60 -> 54071.36 | K71: =INPUT!H60 -> 53869.45
B72: EBITDA | D72: =D67+ABS(D66) -> 1185.61 | E72: =E67+ABS(E66) -> -324.63 | H72: Total Liabilities & Equity | J72: =INPUT!G63 -> 86863.04 | K72: =INPUT!H63 -> 91026.87
G82: =INPUT!H5 -> 2025 (LTM) | I82: =IF(INPUT!D5="",NA(),INPUT!D5) -> #N/A | J82: =INPUT!E5 -> 2022 | K82: =INPUT!F5 -> 2023 | L82: =INPUT!G5 -> 2024 | M82: =INPUT!H5 -> 2025 (LTM)
G83: =IF(INPUT!H9="",NA(),INPUT!H9) -> 8790.13
C84: =IF(INPUT!D5="",NA(),INPUT!D5) -> #N/A | D84: =INPUT!E5 -> 2022 | E84: =INPUT!F5 -> 2023 | F84: =INPUT!G5 -> 2024 | G84: =IF(INPUT!G30="",NA(),INPUT!G30) -> 1185.61 | H84: =IF(INPUT!H30="",NA(),INPUT!H30) -> -324.63
...

Sheet DASHBOARD 2
B1: FinSight | R1: =INPUT!D136&" ("&INPUT!D137&") — "&INPUT!D138 -> Prologis, Inc. (PLD) — Real Estate
B3: Projected Business Performance | F3: Football Field Chart — Valuation Inputs | M3: Financial Data — Multi-Year
B4: All figures in USD Thousands unless stated
B5: Company Information | I5: Low ($) | J5: Delta ($) | K5: High ($) | M5: All figures in USD Thousands unless stated | P5: =INPUT!E5 -> 2022 | Q5: =INPUT!F5 -> 2023 | R5: =INPUT!G5 -> 2024 | S5: =INPUT!H5 -> 2025 (LTM)
C6: Company Name | D6: =INPUT!D136 -> Prologis, Inc. | F6: 52-Week Trading Range | I6: =INPUT!H117*0.75 -> 104.8275 | J6: =K6-I6 -> 97.839 | K6: =INPUT!H117*1.45 -> 202.6665
C7: Ticker Symbol | D7: =INPUT!D137 -> PLD | F7: Consensus Research | I7: =INPUT!H117*1.1 -> 153.747 | J7: =K7-I7 -> 69.885 | K7: =INPUT!H117*1.6 -> 223.632 | M7: Revenue Growth (%) | P7: =IF(INPUT!D9=0,"",INPUT!E9/INPUT!D9-1) | Q7: =IF(INPUT!E9=0,"",INPUT!F9/INPUT!E9-1) -> 0.34313465 | R7: =IF(INPUT!F9=0,"",INPUT!G9/INPUT!F9-1) -> 0.022202364 | S7: =IF(INPUT!G9=0,"",INPUT!H9/INPUT!G9-1) -> 0.071756643
C8: Sector | D8: =INPUT!D138 -> Real Estate | F8: Precedent Transactions | I8: =INPUT!H117*1.2 -> 167.724 | J8: =K8-I8 -> 76.8735 | K8: =INPUT!H117*1.75 -> 244.5975 | M8: EBITDA Growth (%) | P8: ="" | Q8: =IF(INPUT!D30=0,"",INPUT!F30/INPUT!E30-1) | R8: =IF(INPUT!F30=0,"",INPUT!G30/INPUT!F30-1) -> -0.28306485 | S8: =IF(INPUT!G30=0,"",INPUT!H30/INPUT!G30-1) -> -1.2738084
C9: Base Year (LTM) | D9: =INPUT!D139 -> 2025 | F9: Sum-of-the-Parts | I9: =INPUT!H117*1.3 -> 181.701 | J9: =K9-I9 -> 76.8735 | K9: =INPUT!H117*1.85 -> 258.5745
C10: Currency | D10: =INPUT!D140 -> USD | F10: Discounted Cash Flow | I10: =INPUT!H117*1.15 -> 160.7355 | J10: =K10-I10 -> 76.8735 | K10: =INPUT!H117*1.7 -> 237.609 | M10: Revenue
C11: Analysis Date | D11: =INPUT!D142 -> 2026-04-16 | F11: Current Share Price | I11: =INPUT!H117 -> 139.77 | M11: Revenue — Products | P11: =INPUT!E9 -> 5973.69 | Q11: =INPUT!F9 -> 8023.47 | R11: =INPUT!G9 -> 8201.61 | S11: =INPUT!H9 -> 8790.13
M12: Cost of Revenue (COGS) | P12: =ABS(INPUT!E10) -> 1509.09 | Q12: =ABS(INPUT!F10) -> 2010.34 | R12: =ABS(INPUT!G10) -> 2057.24 | S12: =ABS(INPUT!H10) -> 2234.65
M13: Gross Profit | P13: =INPUT!E11 -> 4464.6 | Q13: =INPUT!F11 -> 6013.13 | R13: =INPUT!G11 -> 6144.37 | S13: =INPUT!H11 -> 6555.48
M14: SG&A | P14: =ABS(INPUT!E14) -> 331.08 | Q14: =ABS(INPUT!F14) -> 390.41 | R14: =ABS(INPUT!G14) -> 418.76 | S14: =ABS(INPUT!H14) -> 469.11
M15: Total Revenue | P15: =INPUT!E9 -> 5973.69 | Q15: =INPUT!F9 -> 8023.47 | R15: =INPUT!G9 -> 8201.61 | S15: =INPUT!H9 -> 8790.13
M17: EBITDA | P17: =INPUT!E30 -> 1058.52 | Q17: =INPUT!F30 -> 1653.72 | R17: =INPUT!G30 -> 1185.61 | S17: =INPUT!H30 -> -324.63
M18: Cash from Ops (CFO) | P18: =INPUT!E75 -> -3185.27 | Q18: =INPUT!F75 -> 3922.26 | R18: =INPUT!G75 -> -93.33 | S18: =INPUT!H75 -> 1384.55
M19: Net Income | P19: =INPUT!E26 -> -994.16 | Q19: =INPUT!F26 -> -1355.89 | R19: =INPUT!G26 -> -2120.21 | S19: =INPUT!H26 -> -3710.92
B22: Stock Chart: Trailing 52-Weeks | I22: Valuation Summary: Football Field Chart | P22: Other Financial Metrics ($ Millier)
B42: Total Revenue ($M)
U84: Low | V84: Delta | W84: High
S85: 52-Week Trading Range | U85: =I6 -> 104.8275 | V85: =J6 -> 97.839 | W85: =K6 -> 202.6665
S86: Consensus Research | U86: =I7 -> 153.747 | V86: =J7 -> 69.885 | W86: =K7 -> 223.632
S87: Precedent Trans. | U87: =I8 -> 167.724 | V87: =J8 -> 76.8735 | W87: =K8 -> 244.5975
S88: Sum-of-the-Parts | U88: =I9 -> 181.701 | V88: =J9 -> 76.8735 | W88: =K9 -> 258.5745
S89: Discounted Cash Flow | U89: =I10 -> 160.7355 | V89: =J10 -> 76.8735 | W89: =K10 -> 237.609
Q92: =K104 -> 2022 | R92: =L104 -> 2023 | S92: =M103 -> 2024
Q93: =IF(INPUT!E9="",NA(),INPUT!E30/1000) -> 1.05852 | R93: =IF(INPUT!F9="",NA(),INPUT!F30/1000) -> 1.65372 | S93: =IF(INPUT!G9="",NA(),INPUT!G30/1000) -> 1.18561
Q94: =IF(INPUT!E9="",NA(),INPUT!E75/1000) -> -3.18527 | R94: =IF(INPUT!F9="",NA(),INPUT!F75/1000) -> 3.92226 | S94: =IF(INPUT!G9="",NA(),INPUT!G75/1000) -> -0.09333
Q95: =IF(INPUT!E9="",NA(),INPUT!E26/1000) -> -0.99416 | S95: 2022 | T95: 2024 | U95: 2025 (LTM)
R96: EBITDA | S96: =Q17 -> 1653.72 | T96: =S17 -> -324.63 | U96: =#REF! -> #REF!
R97: CFO | S97: =Q18 -> 3922.26 | T97: =S18 -> 1384.55 | U97: =#REF! -> #REF!
R98: Net Income | S98: =Q19 -> -1355.89 | T98: =S19 -> -3710.92 | U98: =#REF! -> #REF!
A101: Revenue
M103: =IF(INPUT!G9="",NA(),'DASHBOARD 2'!R5) -> 2024 | N103: =IF(INPUT!H9="",NA(),'DASHBOARD 2'!S5) -> 2025 (LTM) | P103: =J104
I104: Year | J104: =IF(INPUT!D9="","",INPUT!D5) | K104: =IF(INPUT!E9="",NA(),'DASHBOARD 2'!P5) -> 2022 | L104: =IF(INPUT!F9="",NA(),'DASHBOARD 2'!Q5) -> 2023 | M104: =IF(INPUT!G9="",NA(),INPUT!G30) -> 1185.61 | N104: =IF(INPUT!H9="",NA(),INPUT!H30) -> -324.63 | P104: =IF(INPUT!D9="",NA(),INPUT!D30/1000) -> #N/A
I105: EBITDA ($M) | J105: =IF(INPUT!D9="","",INPUT!D30) | K105: =IF(INPUT!E9="",NA(),INPUT!E30) -> 1058.52 | L105: =IF(INPUT!F9="",NA(),INPUT!F30) -> 1653.72 | M105: =IF(INPUT!G9="",NA(),INPUT!G75) -> -93.33 | N105: =IF(INPUT!H9="",NA(),INPUT!H75) -> 1384.55 | P105: =IF(INPUT!D9="",NA(),INPUT!D75/1000) -> #N/A
B106: Year | C106: =IF(INPUT!D9="","",INPUT!D5) | D106: =IF(INPUT!E9="",NA(),'DASHBOARD 2'!P5) -> 2022 | E106: =IF(INPUT!F9="",NA(),'DASHBOARD 2'!Q5) -> 2023 | F106: =IF(INPUT!G9="",NA(),'DASHBOARD 2'!R5) -> 2024 | G106: =IF(INPUT!H9="",NA(),'DASHBOARD 2'!S5) -> 2025 (LTM) | I106: CFO ($M) | J106: =IF(INPUT!D9="","",INPUT!D75) | K106: =IF(INPUT!E9="",NA(),INPUT!E75) -> -3185.27 | L106: =IF(INPUT!F9="",NA(),INPUT!F75) -> 3922.26 | M106: =IF(INPUT!G9="",NA(),INPUT!G26) -> -2120.21 | N106: =IF(INPUT!H9="",NA(),INPUT!H26) -> -3710.92 | P106: =IF(INPUT!D9="",NA(),INPUT!D26/1000) -> #N/A
B107: Revenue Growth (%) | C107: ="" | D107: =IF(INPUT!E9="",NA(),'DASHBOARD 2'!P7) | E107: =IF(INPUT!F9="",NA(),'DASHBOARD 2'!Q7) -> 0.34313465 | F107: =IF(INPUT!G9="",NA(),'DASHBOARD 2'!R7) -> 0.022202364 | G107: =IF(INPUT!H9="",NA(),'DASHBOARD 2'!S7) -> 0.071756643 | I107: Net Income ($M) | J107: =IF(INPUT!D9="","",INPUT!D26) | K107: =IF(INPUT!E9="",NA(),INPUT!E26) -> -994.16 | L107: =IF(INPUT!F9="",NA(),INPUT!F26) -> -1355.89
B108: Total Revenue ($M) | C108: =IF(INPUT!D9="","",INPUT!D9) | D108: =IF(INPUT!E9="",NA(),INPUT!E9) -> 5973.69 | E108: =IF(INPUT!F9="",NA(),INPUT!F9) -> 8023.47 | F108: =IF(INPUT!G9="",NA(),INPUT!G9) -> 8201.61 | G108: =IF(INPUT!H9="",NA(),INPUT!H9) -> 8790.13

Sheet STOCK_DATA
A1: STOCK_DATA — Apple Inc. (AAPL) — Trailing 52 Weeks
A2: # | B2: Month | C2: Close Price ($)
A3: 1 | B3: May-25 | C3: 104.95
A4: 2 | B4: Jun-25 | C4: 101.59
A5: 3 | B5: Jul-25 | C5: 104.18
A6: 4 | B6: Aug-25 | C6: 111.01
A7: 5 | B7: Sep-25 | C7: 111.73
A8: 6 | B8: Oct-25 | C8: 122.15
A9: 7 | B9: Nov-25 | C9: 126.52
A10: 8 | B10: Dec-25 | C10: 125.66
A11: 9 | B11: Jan-26 | C11: 129.52
A12: 10 | B12: Feb-26 | C12: 141.43
A13: 11 | B13: Mar-26 | C13: 131.13
A14: 12 | B14: Apr-26 | C14: 139.77
A15: 13
A17: ⚠️ Données simulées. Remplacer par données réelles (Bloomberg/FactSet) en colonne B (Mois) et C (Prix).

Sheet SECTOR_REF
A1: 0.08 | B1: Driver | C1: Pessimiste | D1: Realiste | E1: Optimiste
A2: Technologie / SaaS | B2: Revenue Growth Rate (Y1-Y5) | C2: 0.05 | D2: 0.12 | E2: 0.22
A3: Technologie / SaaS | B3: Gross Margin | C3: 0.55 | D3: 0.68 | E3: 0.78
A4: Technologie / SaaS | B4: EBITDA Margin | C4: 0.08 | D4: 0.18 | E4: 0.28
A5: Technologie / SaaS | B5: SG&A (% Revenue) | C5: 0.3 | D5: 0.22 | E5: 0.15
A6: Technologie / SaaS | B6: R&D (% Revenue) | C6: 0.18 | D6: 0.12 | E6: 0.08
A7: Technologie / SaaS | B7: CapEx (% Revenue) | C7: 0.08 | D7: 0.05 | E7: 0.03
A8: Technologie / SaaS | B8: Change in NWC (% Rev Change) | C8: 0.05 | D8: 0.03 | E8: 0.02
A9: Technologie / SaaS | B9: Terminal Growth Rate | C9: 0.02 | D9: 0.03 | E9: 0.04
A10: Technologie / SaaS | B10: WACC | C10: 0.11 | D10: 0.09 | E10: 0.07
A11: Technologie / SaaS | B11: EV/EBITDA Exit Multiple | C11: 12 | D11: 16 | E11: 22
A12: Industrie / Manufacturing | B12: Revenue Growth Rate (Y1-Y5) | C12: 0.01 | D12: 0.04 | E12: 0.07
A13: Industrie / Manufacturing | B13: Gross Margin | C13: 0.18 | D13: 0.25 | E13: 0.32
... A82: Immobilier / REIT | B82: EV/EBITDA Exit Multiple | C82: 15 | D82: 18 | E82: 22
