Workbook

Sheet DASHBOARD
A1: FinSight IA · Tableau de Bord — Screening Euro Stoxx 50 | R1: Confidentiel · Usage interne
D3: =COUNTA('DONNÉES BRUTES'!A:A)-2 -> 40 | J3: {=COUNTA(_xlfn.UNIQUE(_xlfn._xlws.FILTER('DONNÉES BRUTES'!C3:C42,'DONNÉES BRUTES'!C3:C42<>"")))} -> 10 | P3: =_xlfn.XLOOKUP(MAX('DONNÉES BRUTES'!AB3:AB42),'DONNÉES BRUTES'!AB3:AB42,'DONNÉES BRUTES'!A3:A42)&" — "&MAX('DONNÉES BRUTES'!AB3:AB42)&"/100" -> ASML.AS — 75/100 | V3: 12/04/2026
D4: SOCIÉTÉS ANALYSÉES | J4: SECTEURS COUVERTS | P4: MEILLEUR SCORE GLOBAL | V4: DATE D'ANALYSE
B6: TOP 5 · Classements par Facteur d'Investissement
B7: # | C7: Ticker | D7: Société | E7: Score | F7: Mét. | H7: # | I7: Ticker | J7: Société | K7: Score | L7: Mét. | N7: # | O7: Ticker | P7: Société | Q7: Score | R7: Mét. | T7: # | U7: Ticker | V7: Société | W7: Score | X7: Mét.
B8: 1 | C8: {=IFERROR(INDEX('DONNÉES BRUTES'!A$3:A$42,MATCH(_xlfn.AGGREGATE(14,6,'DONNÉES BRUTES'!AB$3:AB$42*1000+(40-ROW('DONNÉES BRUTES'!AB$3:AB$42)+ROW('DONNÉES BRUTES'!AB$3)),1),'DONNÉES BRUTES'!AB$3:AB$42*1000+(40-ROW('DONNÉES BRUTES'!AB$3:AB$42)+ROW('DONNÉES BRUTES'!AB$3)),0)),"—")} -> ASML.AS | D8: {=IFERROR(LEFT(INDEX('DONNÉES BRUTES'!B$3:B$42,MATCH(_xlfn.AGGREGATE(14,6,'DONNÉES BRUTES'!AB$3:AB$42*1000+(40-ROW('DONNÉES BRUTES'!AB$3:AB$42)+ROW('DONNÉES BRUTES'!AB$3)),1),'DONNÉES BRUTES'!AB$3:AB$42*1000+(40-ROW('DONNÉES BRUTES'!AB$3:AB$42)+ROW('DONNÉES BRUTES'!AB$3)),0)),18),"—")} -> ASML Holding N.V. | E8: {=IFERROR(INT(_xlfn.AGGREGATE(14,6,'DONNÉES BRUTES'!AB$3:AB$42*1000+(40-ROW('DONNÉES BRUTES'!AB$3:AB$42)+ROW('DONNÉES BRUTES'!AB$3)),1)/1000)&"/100","—")} -> 75/100 | F8: {=IFERROR(INDEX('DONNÉES BRUTES'!I$3:I$42,MATCH(_xlfn.AGGREGATE(14,6,'DONNÉES BRUTES'!AB$3:AB$42*1000+(40-ROW('DONNÉES BRUTES'!AB$3:AB$42)+ROW('DONNÉES BRUTES'!AB$3)),1),'DONNÉES BRUTES'!AB$3:AB$42*1000+(40-ROW('DONNÉES BRUTES'!AB$3:AB$42)+ROW('DONNÉES BRUTES'!AB$3)),0)),"—")} -> — | H8: 1 | I8: {=IFERROR(INDEX('DONNÉES BRUTES'!A$3:A$42,MATCH(_xlfn.AGGREGATE(14,6,'DONNÉES BRUTES'!Y$3:Y$42*1000+(40-ROW('DONNÉES BRUTES'!Y$3:Y$42)+ROW('DONNÉES BRUTES'!Y$3)),1),'DONNÉES BRUTES'!Y$3:Y$42*1000+(40-ROW('DONNÉES BRUTES'!Y$3:Y$42)+ROW('DONNÉES BRUTES'!Y$3)),0)),"—")} -> ASML.AS | J8: {=IFERROR(LEFT(INDEX('DONNÉES BRUTES'!B$3:B$42,MATCH(_xlfn.AGGREGATE(14,6,'DONNÉES BRUTES'!Y$3:Y$42*1000+(40-ROW('DONNÉES BRUTES'!Y$3:Y$42)+ROW('DONNÉES BRUTES'!Y$3)),1),'DONNÉES BRUTES'!Y$3:Y$42*1000+(40-ROW('DONNÉES BRUTES'!Y$3:Y$42)+ROW('DONNÉES BRUTES'!Y$3)),0)),18),"—")} -> ASML Holding N.V. | K8: {=IFERROR(INT(_xlfn.AGGREGATE(14,6,'DONNÉES BRUTES'!Y$3:Y$42*1000+(40-ROW('DONNÉES BRUTES'!Y$3:Y$42)+ROW('DONNÉES BRUTES'!Y$3)),1)/1000)&"/100","—")} -> 92/100 | L8: {=IFERROR(INDEX('DONNÉES BRUTES'!P$3:P$42,MATCH(_xlfn.AGGREGATE(14,6,'DONNÉES BRUTES'!Y$3:Y$42*1000+(40-ROW('DONNÉES BRUTES'!Y$3:Y$42)+ROW('DONNÉES BRUTES'!Y$3)),1),'DONNÉES BRUTES'!Y$3:Y$42*1000+(40-ROW('DONNÉES BRUTES'!Y$3:Y$42)+ROW('DONNÉES BRUTES'!Y$3)),0)),"—")} -> +15.6% | N8: 1 | O8: {=IFERROR(INDEX('DONNÉES BRUTES'!A$3:A$42,MATCH(_xlfn.AGGREGATE(14,6,'DONNÉES BRUTES'!Z$3:Z$42*1000+(40-ROW('DONNÉES BRUTES'!Z$3:Z$42)+ROW('DONNÉES BRUTES'!Z$3)),1),'DONNÉES BRUTES'!Z$3:Z$42*1000+(40-ROW('DONNÉES BRUTES'!Z$3:Z$42)+ROW('DONNÉES BRUTES'!Z$3)),0)),"—")} -> RMS.PA | P8: {=IFERROR(LEFT(INDEX('DONNÉES BRUTES'!B$3:B$42,MATCH(_xlfn.AGGREGATE(14,6,'DONNÉES BRUTES'!Z$3:Z$42*1000+(40-ROW('DONNÉES BRUTES'!Z$3:Z$42)+ROW('DONNÉES BRUTES'!Z$3)),1),'DONNÉES BRUTES'!Z$3:Z$42*1000+(40-ROW('DONNÉES BRUTES'!Z$3:Z$42)+ROW('DONNÉES BRUTES'!Z$3)),0)),18),"—")} -> Hermès Internation | Q8: {=IFERROR(INT(_xlfn.AGGREGATE(14,6,'DONNÉES BRUTES'!Z$3:Z$42*1000+(40-ROW('DONNÉES BRUTES'!Z$3:Z$42)+ROW('DONNÉES BRUTES'!Z$3)),1)/1000)&"/100","—")} -> 99/100 | R8: {=IFERROR(INDEX('DONNÉES BRUTES'!U$3:U$42,MATCH(_xlfn.AGGREGATE(14,6,'DONNÉES BRUTES'!Z$3:Z$42*1000+(40-ROW('DONNÉES BRUTES'!Z$3:Z$42)+ROW('DONNÉES BRUTES'!Z$3)),1),'DONNÉES BRUTES'!Z$3:Z$42*1000+(40-ROW('DONNÉES BRUTES'!Z$3:Z$42)+ROW('DONNÉES BRUTES'!Z$3)),0)),"—")} -> 9.47 | T8: 1 | U8: {=IFERROR(INDEX('DONNÉES BRUTES'!A$3:A$42,MATCH(_xlfn.AGGREGATE(14,6,'DONNÉES BRUTES'!AA$3:AA$42*1000+(40-ROW('DONNÉES BRUTES'!AA$3:AA$42)+ROW('DONNÉES BRUTES'!AA$3)),1),'DONNÉES BRUTES'!AA$3:AA$42*1000+(40-ROW('DONNÉES BRUTES'!AA$3:AA$42)+ROW('DONNÉES BRUTES'!AA$3)),0)),"—")} -> ASML.AS | V8: {=IFERROR(LEFT(INDEX('DONNÉES BRUTES'!B$3:B$42,MATCH(_xlfn.AGGREGATE(14,6,'DONNÉES BRUTES'!AA$3:AA$42*1000+(40-ROW('DONNÉES BRUTES'!AA$3:AA$42)+ROW('DONNÉES BRUTES'!AA$3)),1),'DONNÉES BRUTES'!AA$3:AA$42*1000+(40-ROW('DONNÉES BRUTES'!AA$3:AA$42)+ROW('DONNÉES BRUTES'!AA$3)),0)),18),"—")} -> ASML Holding N.V. | W8: {=IFERROR(INT(_xlfn.AGGREGATE(14,6,'DONNÉES BRUTES'!AA$3:AA$42*1000+(40-ROW('DONNÉES BRUTES'!AA$3:AA$42)+ROW('DONNÉES BRUTES'!AA$3)),1)/1000)&"/100","—")} -> 98/100 | X8: {=IFERROR(INDEX('DONNÉES BRUTES'!P$3:P$42,MATCH(_xlfn.AGGREGATE(14,6,'DONNÉES BRUTES'!AA$3:AA$42*1000+(40-ROW('DONNÉES BRUTES'!AA$3:AA$42)+ROW('DONNÉES BRUTES'!AA$3)),1),'DONNÉES BRUTES'!AA$3:AA$42*1000+(40-ROW('DONNÉES BRUTES'!AA$3:AA$42)+ROW('DONNÉES BRUTES'!AA$3)),0)),"—")} -> +15.6%
B9: 2 | C9: {=IFERROR(INDEX('DONNÉES BRUTES'!A$3:A$42,MATCH(_xlfn.AGGREGATE(14,6,'DONNÉES BRUTES'!AB$3:AB$42*1000+(40-ROW('DONNÉES BRUTES'!AB$3:AB$42)+ROW('DONNÉES BRUTES'!AB$3)),2),'DONNÉES BRUTES'!AB$3:AB$42*1000+(40-ROW('DONNÉES BRUTES'!AB$3:AB$42)+ROW('DONNÉES BRUTES'!AB$3)),0)),"—")} -> RIO.L | D9: {=IFERROR(LEFT(INDEX('DONNÉES BRUTES'!B$3:B$42,MATCH(_xlfn.AGGREGATE(14,6,'DONNÉES BRUTES'!AB$3:AB$42*1000+(40-ROW('DONNÉES BRUTES'!AB$3:AB$42)+ROW('DONNÉES BRUTES'!AB$3)),2),'DONNÉES BRUTES'!AB$3:AB$42*1000+(40-ROW('DONNÉES BRUTES'!AB$3:AB$42)+ROW('DONNÉES BRUTES'!AB$3)),0)),18),"—")} -> Rio Tinto Group | E9: {=IFERROR(INT(_xlfn.AGGREGATE(14,6,'DONNÉES BRUTES'!AB$3:AB$42*1000+(40-ROW('DONNÉES BRUTES'!AB$3:AB$42)+ROW('DONNÉES BRUTES'!AB$3)),2)/1000)&"/100","—")} -> 70/100 | F9: {=IFERROR(INDEX('DONNÉES BRUTES'!I$3:I$42,MATCH(_xlfn.AGGREGATE(14,6,'DONNÉES BRUTES'!AB$3:AB$42*1000+(40-ROW('DONNÉES BRUTES'!AB$3:AB$42)+ROW('DONNÉES BRUTES'!AB$3)),2),'DONNÉES BRUTES'!AB$3:AB$42*1000+(40-ROW('DONNÉES BRUTES'!AB$3:AB$42)+ROW('DONNÉES BRUTES'!AB$3)),0)),"—")} -> 401.8 | H9: 2 | I9: {=IFERROR(INDEX('DONNÉES BRUTES'!A$3:A$42,MATCH(_xlfn.AGGREGATE(14,6,'DONNÉES BRUTES'!Y$3:Y$42*1000+(40-ROW('DONNÉES BRUTES'!Y$3:Y$42)+ROW('DONNÉES BRUTES'!Y$3)),2),'DONNÉES BRUTES'!Y$3:Y$42*1000+(40-ROW('DONNÉES BRUTES'!Y$3:Y$42)+ROW('DONNÉES BRUTES'!Y$3)),0)),"—")} -> AZN.L | J9: {=IFERROR(LEFT(INDEX('DONNÉES BRUTES'!B$3:B$42,MATCH(_xlfn.AGGREGATE(14,6,'DONNÉES BRUTES'!Y$3:Y$42*1000+(40-ROW('DONNÉES BRUTES'!Y$3:Y$42)+ROW('DONNÉES BRUTES'!Y$3)),2),'DONNÉES BRUTES'!Y$3:Y$42*1000+(40-ROW('DONNÉES BRUTES'!Y$3:Y$42)+ROW('DONNÉES BRUTES'!Y$3)),0)),18),"—")} -> AstraZeneca PLC | K9: {=IFERROR(INT(_xlfn.AGGREGATE(14,6,'DONNÉES BRUTES'!Y$3:Y$42*1000+(40-ROW('DONNÉES BRUTES'!Y$3:Y$42)+ROW('DONNÉES BRUTES'!Y$3)),2)/1000)&"/100","—")} -> 87/100 | L9: {=IFERROR(INDEX('DONNÉES BRUTES'!P$3:P$42,MATCH(_xlfn.AGGREGATE(14,6,'DONNÉES BRUTES'!Y$3:Y$42*1000+(40-ROW('DONNÉES BRUTES'!Y$3:Y$42)+ROW('DONNÉES BRUTES'!Y$3)),2),'DONNÉES BRUTES'!Y$3:Y$42*1000+(40-ROW('DONNÉES BRUTES'!Y$3:Y$42)+ROW('DONNÉES BRUTES'!Y$3)),0)),"—")} -> +8.6% | N9: 2 | O9: {=IFERROR(INDEX('DONNÉES BRUTES'!A$3:A$42,MATCH(_xlfn.AGGREGATE(14,6,'DONNÉES BRUTES'!Z$3:Z$42*1000+(40-ROW('DONNÉES BRUTES'!Z$3:Z$42)+ROW('DONNÉES BRUTES'!Z$3)),2),'DONNÉES BRUTES'!Z$3:Z$42*1000+(40-ROW('DONNÉES BRUTES'!Z$3:Z$42)+ROW('DONNÉES BRUTES'!Z$3)),0)),"—")} -> ASML.AS | P9: {=IFERROR(LEFT(INDEX('DONNÉES BRUTES'!B$3:B$42,MATCH(_xlfn.AGGREGATE(14,6,'DONNÉES BRUTES'!Z$3:Z$42*1000+(40-ROW('DONNÉES BRUTES'!Z$3:Z$42)+ROW('DONNÉES BRUTES'!Z$3)),2),'DONNÉES BRUTES'!Z$3:Z$42*1000+(40-ROW('DONNÉES BRUTES'!Z$3:Z$42)+ROW('DONNÉES BRUTES'!Z$3)),0)),18),"—")} -> ASML Holding N.V. | Q9: {=IFERROR(INT(_xlfn.AGGREGATE(14,6,'DONNÉES BRUTES'!Z$3:Z$42*1000+(40-ROW('DONNÉES BRUTES'!Z$3:Z$42)+ROW('DONNÉES BRUTES'!Z$3)),2)/1000)&"/100","—")} -> 86/100 | R9: {=IFERROR(INDEX('DONNÉES BRUTES'!U$3:U$42,MATCH(_xlfn.AGGREGATE(14,6,'DONNÉES BRUTES'!Z$3:Z$42*1000+(40-ROW('DONNÉES BRUTES'!Z$3:Z$42)+ROW('DONNÉES BRUTES'!Z$3)),2),'DONNÉES BRUTES'!Z$3:Z$42*1000+(40-ROW('DONNÉES BRUTES'!Z$3:Z$42)+ROW('DONNÉES BRUTES'!Z$3)),0)),"—")} -> 4.15 | T9: 2 | U9: {=IFERROR(INDEX('DONNÉES BRUTES'!A$3:A$42,MATCH(_xlfn.AGGREGATE(14,6,'DONNÉES BRUTES'!AA$3:AA$42*1000+(40-ROW('DONNÉES BRUTES'!AA$3:AA$42)+ROW('DONNÉES BRUTES'!AA$3)),2),'DONNÉES BRUTES'!AA$3:AA$42*1000+(40-ROW('DONNÉES BRUTES'!AA$3:AA$42)+ROW('DONNÉES BRUTES'!AA$3)),0)),"—")} -> RWE.DE | V9: {=IFERROR(LEFT(INDEX('DONNÉES BRUTES'!B$3:B$42,MATCH(_xlfn.AGGREGATE(14,6,'DONNÉES BRUTES'!AA$3:AA$42*1000+(40-ROW('DONNÉES BRUTES'!AA$3:AA$42)+ROW('DONNÉES BRUTES'!AA$3)),2),'DONNÉES BRUTES'!AA$3:AA$42*1000+(40-ROW('DONNÉES BRUTES'!AA$3:AA$42)+ROW('DONNÉES BRUTES'!AA$3)),0)),18),"—")} -> RWE Aktiengesellsc | W9: {=IFERROR(INT(_xlfn.AGGREGATE(14,6,'DONNÉES BRUTES'!AA$3:AA$42*1000+(40-ROW('DONNÉES BRUTES'!AA$3:AA$42)+ROW('DONNÉES BRUTES'!AA$3)),2)/1000)&"/100","—")} -> 96/100 | X9: {=IFERROR(INDEX('DONNÉES BRUTES'!P$3:P$42,MATCH(_xlfn.AGGREGATE(14,6,'DONNÉES BRUTES'!AA$3:AA$42*1000+(40-ROW('DONNÉES BRUTES'!AA$3:AA$42)+ROW('DONNÉES BRUTES'!AA$3)),2),'DONNÉES BRUTES'!AA$3:AA$42*1000+(40-ROW('DONNÉES BRUTES'!AA$3:AA$42)+ROW('DONNÉES BRUTES'!AA$3)),0)),"—")} -> -27.2%
B10: 3 | C10: {=IFERROR(INDEX('DONNÉES BRUTES'!A$3:A$42,MATCH(_xlfn.AGGREGATE(14,6,'DONNÉES BRUTES'!AB$3:AB$42*1000+(40-ROW('DONNÉES BRUTES'!AB$3:AB$42)+ROW('DONNÉES BRUTES'!AB$3)),3),'DONNÉES BRUTES'!AB$3:AB$42*1000+(40-ROW('DONNÉES BRUTES'!AB$3:AB$42)+ROW('DONNÉES BRUTES'!AB$3)),0)),"—")} -> RMS.PA | D10: {=IFERROR(LEFT(INDEX('DONNÉES BRUTES'!B$3:B$42,MATCH(_xlfn.AGGREGATE(14,6,'DONNÉES BRUTES'!AB$3:AB$42*1000+(40-ROW('DONNÉES BRUTES'!AB$3:AB$42)+ROW('DONNÉES BRUTES'!AB$3)),3),'DONNÉES BRUTES'!AB$3:AB$42*1000+(40-ROW('DONNÉES BRUTES'!AB$3:AB$42)+ROW('DONNÉES BRUTES'!AB$3)),0)),18),"—")} -> Hermès Internation | E10: {=IFERROR(INT(_xlfn.AGGREGATE(14,6,'DONNÉES BRUTES'!AB$3:AB$42*1000+(40-ROW('DONNÉES BRUTES'!AB$3:AB$42)+ROW('DONNÉES BRUTES'!AB$3)),3)/1000)&"/100","—")} -> 65/100 | F10: {=IFERROR(INDEX('DONNÉES BRUTES'!I$3:I$42,MATCH(_xlfn.AGGREGATE(14,6,'DONNÉES BRUTES'!AB$3:AB$42*1000+(40-ROW('DONNÉES BRUTES'!AB$3:AB$42)+ROW('DONNÉES BRUTES'!AB$3)),3),'DONNÉES BRUTES'!AB$3:AB$42*1000+(40-ROW('DONNÉES BRUTES'!AB$3:AB$42)+ROW('DONNÉES BRUTES'!AB$3)),0)),"—")} -> 22.9 | H10: 3 | I10: {=IFERROR(INDEX('DONNÉES BRUTES'!A$3:A$42,MATCH(_xlfn.AGGREGATE(14,6,'DONNÉES BRUTES'!Y$3:Y$42*1000+(40-ROW('DONNÉES BRUTES'!Y$3:Y$42)+ROW('DONNÉES BRUTES'!Y$3)),3),'DONNÉES BRUTES'!Y$3:Y$42*1000+(40-ROW('DONNÉES BRUTES'!Y$3:Y$42)+ROW('DONNÉES BRUTES'!Y$3)),0)),"—")} -> RMS.PA | J10: {=IFERROR(LEFT(INDEX('DONNÉES BRUTES'!B$3:B$42,MATCH(_xlfn.AGGREGATE(14,6,'DONNÉES BRUTES'!Y$3:Y$42*1000+(40-ROW('DONNÉES BRUTES'!Y$3:Y$42)+ROW('DONNÉES BRUTES'!Y$3)),3),'DONNÉES BRUTES'!Y$3:Y$42*1000+(40-ROW('DONNÉES BRUTES'!Y$3:Y$42)+ROW('DONNÉES BRUTES'!Y$3)),0)),18),"—")} -> Hermès Internation | K10: {=IFERROR(INT(_xlfn.AGGREGATE(14,6,'DONNÉES BRUTES'!Y$3:Y$42*1000+(40-ROW('DONNÉES BRUTES'!Y$3:Y$42)+ROW('DONNÉES BRUTES'!Y$3)),3)/1000)&"/100","—")} -> 81/100 | L10: {=IFERROR(INDEX('DONNÉES BRUTES'!P$3:P$42,MATCH(_xlfn.AGGREGATE(14,6,'DONNÉES BRUTES'!Y$3:Y$42*1000+(40-ROW('DONNÉES BRUTES'!Y$3:Y$42)+ROW('DONNÉES BRUTES'!Y$3)),3),'DONNÉES BRUTES'!Y$3:Y$42*1000+(40-ROW('DONNÉES BRUTES'!Y$3:Y$42)+ROW('DONNÉES BRUTES'!Y$3)),0)),"—")} -> +5.5% | N10: 3 | O10: {=IFERROR(INDEX('DONNÉES BRUTES'!A$3:A$42,MATCH(_xlfn.AGGREGATE(14,6,'DONNÉES BRUTES'!Z$3:Z$42*1000+(40-ROW('DONNÉES BRUTES'!Z$3:Z$42)+ROW('DONNÉES BRUTES'!Z$3)),3),'DONNÉES BRUTES'!Z$3:Z$42*1000+(40-ROW('DONNÉES BRUTES'!Z$3:Z$42)+ROW('DONNÉES BRUTES'!Z$3)),0)),"—")} -> ITX.MC | P10: {=IFERROR(LEFT(INDEX('DONNÉES BRUTES'!B$3:B$42,MATCH(_xlfn.AGGREGATE(14,6,'DONNÉES BRUTES'!Z$3:Z$42*1000+(40-ROW('DONNÉES BRUTES'!Z$3:Z$42)+ROW('DONNÉES BRUTES'!Z$3)),3),'DONNÉES BRUTES'!Z$3:Z$42*1000+(40-ROW('DONNÉES BRUTES'!Z$3:Z$42)+ROW('DONNÉES BRUTES'!Z$3)),0)),18),"—")} -> Industria de Diseñ | Q10: {=IFERROR(INT(_xlfn.AGGREGATE(14,6,'DONNÉES BRUTES'!Z$3:Z$42*1000+(40-ROW('DONNÉES BRUTES'!Z$3:Z$42)+ROW('DONNÉES BRUTES'!Z$3)),3)/1000)&"/100","—")} -> 83/100 | R10: {=IFERROR(INDEX('DONNÉES BRUTES'!U$3:U$42,MATCH(_xlfn.AGGREGATE(14,6,'DONNÉES BRUTES'!Z$3:Z$42*1000+(40-ROW('DONNÉES BRUTES'!Z$3:Z$42)+ROW('DONNÉES BRUTES'!Z$3)),3),'DONNÉES BRUTES'!Z$3:Z$42*1000+(40-ROW('DONNÉES BRUTES'!Z$3:Z$42)+ROW('DONNÉES BRUTES'!Z$3)),0)),"—")} -> 4.57 | T10: 3 | U10: {=IFERROR(INDEX('DONNÉES BRUTES'!A$3:A$42,MATCH(_xlfn.AGGREGATE(14,6,'DONNÉES BRUTES'!AA$3:AA$42*1000+(40-ROW('DONNÉES BRUTES'!AA$3:AA$42)+ROW('DONNÉES BRUTES'!AA$3)),3),'DONNÉES BRUTES'!AA$3:AA$42*1000+(40-ROW('DONNÉES BRUTES'!AA$3:AA$42)+ROW('DONNÉES BRUTES'!AA$3)),0)),"—")} -> NOKIA.HE | V10: {=IFERROR(LEFT(INDEX('DONNÉES BRUTES'!B$3:B$42,MATCH(_xlfn.AGGREGATE(14,6,'DONNÉES BRUTES'!AA$3:AA$42*1000+(40-ROW('DONNÉES BRUTES'!AA$3:AA$42)+ROW('DONNÉES BRUTES'!AA$3)),3),'DONNÉES BRUTES'!AA$3:AA$42*1000+(40-ROW('DONNÉES BRUTES'!AA$3:AA$42)+ROW('DONNÉES BRUTES'!AA$3)),0)),18),"—")} -> Nokia Oyj | W10: {=IFERROR(INT(_xlfn.AGGREGATE(14,6,'DONNÉES BRUTES'!AA$3:AA$42*1000+(40-ROW('DONNÉES BRUTES'!AA$3:AA$42)+ROW('DONNÉES BRUTES'!AA$3)),3)/1000)&"/100","—")} -> 94/100 | X10: {=IFERROR(INDEX('DONNÉES BRUTES'!P$3:P$42,MATCH(_xlfn.AGGREGATE(14,6,'DONNÉES BRUTES'!AA$3:AA$42*1000+(40-ROW('DONNÉES BRUTES'!AA$3:AA$42)+ROW('DONNÉES BRUTES'!AA$3)),3),'DONNÉES BRUTES'!AA$3:AA$42*1000+(40-ROW('DONNÉES BRUTES'!AA$3:AA$42)+ROW('DONNÉES BRUTES'!AA$3)),0)),"—")} -> +3.5%
B11: 4 | C11: {=IFERROR(INDEX('DONNÉES BRUTES'!A$3:A$42,MATCH(_xlfn.AGGREGATE(14,6,'DONNÉES BRUTES'!AB$3:AB$42*1000+(40-ROW('DONNÉES BRUTES'!AB$3:AB$42)+ROW('DONNÉES BRUTES'!AB$3)),4),'DONNÉES BRUTES'!AB$3:AB$42*1000+(40-ROW('DONNÉES BRUTES'!AB$3:AB$42)+ROW('DONNÉES BRUTES'!AB$3)),0)),"—")} -> SAP.DE | D11: {=IFERROR(LEFT(INDEX('DONNÉES BRUTES'!B$3:B$42,MATCH(_xlfn.AGGREGATE(14,6,'DONNÉES BRUTES'!AB$3:AB$42*1000+(40-ROW('DONNÉES BRUTES'!AB$3:AB$42)+ROW('DONNÉES BRUTES'!AB$3)),4),'DONNÉES BRUTES'!AB$3:AB$42*1000+(40-ROW('DONNÉES BRUTES'!AB$3:AB$42)+ROW('DONNÉES BRUTES'!AB$3)),0)),18),"—")} -> SAP SE | E11: {=IFERROR(INT(_xlfn.AGGREGATE(14,6,'DONNÉES BRUTES'!AB$3:AB$42*1000+(40-ROW('DONNÉES BRUTES'!AB$3:AB$42)+ROW('DONNÉES BRUTES'!AB$3)),4)/1000)&"/100","—")} -> 62/100 | F11: {=IFERROR(INDEX('DONNÉES BRUTES'!I$3:I$42,MATCH(_xlfn.AGGREGATE(14,6,'DONNÉES BRUTES'!AB$3:AB$42*1000+(40-ROW('DONNÉES BRUTES'!AB$3:AB$42)+ROW('DONNÉES BRUTES'!AB$3)),4),'DONNÉES BRUTES'!AB$3:AB$42*1000+(40-ROW('DONNÉES BRUTES'!AB$3:AB$42)+ROW('DONNÉES BRUTES'!AB$3)),0)),"—")} -> 13.3 | H11: 4 | I11: {=IFERROR(INDEX('DONNÉES BRUTES'!A$3:A$42,MATCH(_xlfn.AGGREGATE(14,6,'DONNÉES BRUTES'!Y$3:Y$42*1000+(40-ROW('DONNÉES BRUTES'!Y$3:Y$42)+ROW('DONNÉES BRUTES'!Y$3)),4),'DONNÉES BRUTES'!Y$3:Y$42*1000+(40-ROW('DONNÉES BRUTES'!Y$3:Y$42)+ROW('DONNÉES BRUTES'!Y$3)),0)),"—")} -> SAP.DE | J11: {=IFERROR(LEFT(INDEX('DONNÉES BRUTES'!B$3:B$42,MATCH(_xlfn.AGGREGATE(14,6,'DONNÉES BRUTES'!Y$3:Y$42*1000+(40-ROW('DONNÉES BRUTES'!Y$3:Y$42)+ROW('DONNÉES BRUTES'!Y$3)),4),'DONNÉES BRUTES'!Y$3:Y$42*1000+(40-ROW('DONNÉES BRUTES'!Y$3:Y$42)+ROW('DONNÉES BRUTES'!Y$3)),0)),18),"—")} -> SAP SE | K11: {=IFERROR(INT(_xlfn.AGGREGATE(14,6,'DONNÉES BRUTES'!Y$3:Y$42*1000+(40-ROW('DONNÉES BRUTES'!Y$3:Y$42)+ROW('DONNÉES BRUTES'!Y$3)),4)/1000)&"/100","—")} -> 78/100 | L11: {=IFERROR(INDEX('DONNÉES BRUTES'!P$3:P$42,MATCH(_xlfn.AGGREGATE(14,6,'DONNÉES BRUTES'!Y$3:Y$42*1000+(40-ROW('DONNÉES BRUTES'!Y$3:Y$42)+ROW('DONNÉES BRUTES'!Y$3)),4),'DONNÉES BRUTES'!Y$3:Y$42*1000+(40-ROW('DONNÉES BRUTES'!Y$3:Y$42)+ROW('DONNÉES BRUTES'!Y$3)),0)),"—")} -> +7.7% | N11: 4 | O11: {=IFERROR(INDEX('DONNÉES BRUTES'!A$3:A$42,MATCH(_xlfn.AGGREGATE(14,6,'DONNÉES BRUTES'!Z$3:Z$42*1000+(40-ROW('DONNÉES BRUTES'!Z$3:Z$42)+ROW('DONNÉES BRUTES'!Z$3)),4),'DONNÉES BRUTES'!Z$3:Z$42*1000+(40-ROW('DONNÉES BRUTES'!Z$3:Z$42)+ROW('DONNÉES BRUTES'!Z$3)),0)),"—")} -> SAP.DE | P11: {=IFERROR(LEFT(INDEX('DONNÉES BRUTES'!B$3:B$42,MATCH(_xlfn.AGGREGATE(14,6,'DONNÉES BRUTES'!Z$3:Z$42*1000+(40-ROW('DONNÉES BRUTES'!Z$3:Z$42)+ROW('DONNÉES BRUTES'!Z$3)),4),'DONNÉES BRUTES'!Z$3:Z$42*1000+(40-ROW('DONNÉES BRUTES'!Z$3:Z$42)+ROW('DONNÉES BRUTES'!Z$3)),0)),18),"—")} -> SAP SE | Q11: {=IFERROR(INT(_xlfn.AGGREGATE(14,6,'DONNÉES BRUTES'!Z$3:Z$42*1000+(40-ROW('DONNÉES BRUTES'!Z$3:Z$42)+ROW('DONNÉES BRUTES'!Z$3)),4)/1000)&"/100","—")} -> 80/100 | R11: {=IFERROR(INDEX('DONNÉES BRUTES'!U$3:U$42,MATCH(_xlfn.AGGREGATE(14,6,'DONNÉES BRUTES'!Z$3:Z$42*1000+(40-ROW('DONNÉES BRUTES'!Z$3:Z$42)+ROW('DONNÉES BRUTES'!Z$3)),4),'DONNÉES BRUTES'!Z$3:Z$42*1000+(40-ROW('DONNÉES BRUTES'!Z$3:Z$42)+ROW('DONNÉES BRUTES'!Z$3)),0)),"—")} -> 5.34 | T11: 4 | U11: {=IFERROR(INDEX('DONNÉES BRUTES'!A$3:A$42,MATCH(_xlfn.AGGREGATE(14,6,'DONNÉES BRUTES'!AA$3:AA$42*1000+(40-ROW('DONNÉES BRUTES'!AA$3:AA$42)+ROW('DONNÉES BRUTES'!AA$3)),4),'DONNÉES BRUTES'!AA$3:AA$42*1000+(40-ROW('DONNÉES BRUTES'!AA$3:AA$42)+ROW('DONNÉES BRUTES'!AA$3)),0)),"—")} -> RIO.L | V11: {=IFERROR(LEFT(INDEX('DONNÉES BRUTES'!B$3:B$42,MATCH(_xlfn.AGGREGATE(14,6,'DONNÉES BRUTES'!AA$3:AA$42*1000+(40-ROW('DONNÉES BRUTES'!AA$3:AA$42)+ROW('DONNÉES BRUTES'!AA$3)),4),'DONNÉES BRUTES'!AA$3:AA$42*1000+(40-ROW('DONNÉES BRUTES'!AA$3:AA$42)+ROW('DONNÉES BRUTES'!AA$3)),0)),18),"—")} -> Rio Tinto Group | W11: {=IFERROR(INT(_xlfn.AGGREGATE(14,6,'DONNÉES BRUTES'!AA$3:AA$42*1000+(40-ROW('DONNÉES BRUTES'!AA$3:AA$42)+ROW('DONNÉES BRUTES'!AA$3)),4)/1000)&"/100","—")} -> 91/100 | X11: {=IFERROR(INDEX('DONNÉES BRUTES'!P$3:P$42,MATCH(_xlfn.AGGREGATE(14,6,'DONNÉES BRUTES'!AA$3:AA$42*1000+(40-ROW('DONNÉES BRUTES'!AA$3:AA$42)+ROW('DONNÉES BRUTES'!AA$3)),4),'DONNÉES BRUTES'!AA$3:AA$42*1000+(40-ROW('DONNÉES BRUTES'!AA$3:AA$42)+ROW('DONNÉES BRUTES'!AA$3)),0)),"—")} -> +7.4%
B12: 5 | C12: {=IFERROR(INDEX('DONNÉES BRUTES'!A$3:A$42,MATCH(_xlfn.AGGREGATE(14,6,'DONNÉES BRUTES'!AB$3:AB$42*1000+(40-ROW('DONNÉES BRUTES'!AB$3:AB$42)+ROW('DONNÉES BRUTES'!AB$3)),5),'DONNÉES BRUTES'!AB$3:AB$42*1000+(40-ROW('DONNÉES BRUTES'!AB$3:AB$42)+ROW('DONNÉES BRUTES'!AB$3)),0)),"—")} -> AZN.L | D12: {=IFERROR(LEFT(INDEX('DONNÉES BRUTES'!B$3:B$42,MATCH(_xlfn.AGGREGATE(14,6,'DONNÉES BRUTES'!AB$3:AB$42*1000+(40-ROW('DONNÉES BRUTES'!AB$3:AB$42)+ROW('DONNÉES BRUTES'!AB$3)),5),'DONNÉES BRUTES'!AB$3:AB$42*1000+(40-ROW('DONNÉES BRUTES'!AB$3:AB$42)+ROW('DONNÉES BRUTES'!AB$3)),0)),18),"—")} -> AstraZeneca PLC | E12: {=IFERROR(INT(_xlfn.AGGREGATE(14,6,'DONNÉES BRUTES'!AB$3:AB$42*1000+(40-ROW('DONNÉES BRUTES'!AB$3:AB$42)+ROW('DONNÉES BRUTES'!AB$3)),5)/1000)&"/100","—")} -> 60/100 | F12: {=IFERROR(INDEX('DONNÉES BRUTES'!I$3:I$42,MATCH(_xlfn.AGGREGATE(14,6,'DONNÉES BRUTES'!AB$3:AB$42*1000+(40-ROW('DONNÉES BRUTES'!AB$3:AB$42)+ROW('DONNÉES BRUTES'!AB$3)),5),'DONNÉES BRUTES'!AB$3:AB$42*1000+(40-ROW('DONNÉES BRUTES'!AB$3:AB$42)+ROW('DONNÉES BRUTES'!AB$3)),0)),"—")} -> 1211.7 | H12: 5 | I12: {=IFERROR(INDEX('DONNÉES BRUTES'!A$3:A$42,MATCH(_xlfn.AGGREGATE(14,6,'DONNÉES BRUTES'!Y$3:Y$42*1000+(40-ROW('DONNÉES BRUTES'!Y$3:Y$42)+ROW('DONNÉES BRUTES'!Y$3)),5),'DONNÉES BRUTES'!Y$3:Y$42*1000+(40-ROW('DONNÉES BRUTES'!Y$3:Y$42)+ROW('DONNÉES BRUTES'!Y$3)),0)),"—")} -> GSK.L | J12: {=IFERROR(LEFT(INDEX('DONNÉES BRUTES'!B$3:B$42,MATCH(_xlfn.AGGREGATE(14,6,'DONNÉES BRUTES'!Y$3:Y$42*1000+(40-ROW('DONNÉES BRUTES'!Y$3:Y$42)+ROW('DONNÉES BRUTES'!Y$3)),5),'DONNÉES BRUTES'!Y$3:Y$42*1000+(40-ROW('DONNÉES BRUTES'!Y$3:Y$42)+ROW('DONNÉES BRUTES'!Y$3)),0)),18),"—")} -> GSK plc | K12: {=IFERROR(INT(_xlfn.AGGREGATE(14,6,'DONNÉES BRUTES'!Y$3:Y$42*1000+(40-ROW('DONNÉES BRUTES'!Y$3:Y$42)+ROW('DONNÉES BRUTES'!Y$3)),5)/1000)&"/100","—")} -> 78/100 | L12: {=IFERROR(INDEX('DONNÉES BRUTES'!P$3:P$42,MATCH(_xlfn.AGGREGATE(14,6,'DONNÉES BRUTES'!Y$3:Y$42*1000+(40-ROW('DONNÉES BRUTES'!Y$3:Y$42)+ROW('DONNÉES BRUTES'!Y$3)),5),'DONNÉES BRUTES'!Y$3:Y$42*1000+(40-ROW('DONNÉES BRUTES'!Y$3:Y$42)+ROW('DONNÉES BRUTES'!Y$3)),0)),"—")} -> +4.1% | N12: 5 | O12: {=IFERROR(INDEX('DONNÉES BRUTES'!A$3:A$42,MATCH(_xlfn.AGGREGATE(14,6,'DONNÉES BRUTES'!Z$3:Z$42*1000+(40-ROW('DONNÉES BRUTES'!Z$3:Z$42)+ROW('DONNÉES BRUTES'!Z$3)),5),'DONNÉES BRUTES'!Z$3:Z$42*1000+(40-ROW('DONNÉES BRUTES'!Z$3:Z$42)+ROW('DONNÉES BRUTES'!Z$3)),0)),"—")} -> RIO.L | P12: {=IFERROR(LEFT(INDEX('DONNÉES BRUTES'!B$3:B$42,MATCH(_xlfn.AGGREGATE(14,6,'DONNÉES BRUTES'!Z$3:Z$42*1000+(40-ROW('DONNÉES BRUTES'!Z$3:Z$42)+ROW('DONNÉES BRUTES'!Z$3)),5),'DONNÉES BRUTES'!Z$3:Z$42*1000+(40-ROW('DONNÉES BRUTES'!Z$3:Z$42)+ROW('DONNÉES BRUTES'!Z$3)),0)),18),"—")} -> Rio Tinto Group | Q12: {=IFERROR(INT(_xlfn.AGGREGATE(14,6,'DONNÉES BRUTES'!Z$3:Z$42*1000+(40-ROW('DONNÉES BRUTES'!Z$3:Z$42)+ROW('DONNÉES BRUTES'!Z$3)),5)/1000)&"/100","—")} -> 78/100 | R12: {=IFERROR(INDEX('DONNÉES BRUTES'!U$3:U$42,MATCH(_xlfn.AGGREGATE(14,6,'DONNÉES BRUTES'!Z$3:Z$42*1000+(40-ROW('DONNÉES BRUTES'!Z$3:Z$42)+ROW('DONNÉES BRUTES'!Z$3)),5),'DONNÉES BRUTES'!Z$3:Z$42*1000+(40-ROW('DONNÉES BRUTES'!Z$3:Z$42)+ROW('DONNÉES BRUTES'!Z$3)),0)),"—")} -> 3.45 | T12: 5 | U12: {=IFERROR(INDEX('DONNÉES BRUTES'!A$3:A$42,MATCH(_xlfn.AGGREGATE(14,6,'DONNÉES BRUTES'!AA$3:AA$42*1000+(40-ROW('DONNÉES BRUTES'!AA$3:AA$42)+ROW('DONNÉES BRUTES'!AA$3)),5),'DONNÉES BRUTES'!AA$3:AA$42*1000+(40-ROW('DONNÉES BRUTES'!AA$3:AA$42)+ROW('DONNÉES BRUTES'!AA$3)),0)),"—")} -> KER.PA | V12: {=IFERROR(LEFT(INDEX('DONNÉES BRUTES'!B$3:B$42,MATCH(_xlfn.AGGREGATE(14,6,'DONNÉES BRUTES'!AA$3:AA$42*1000+(40-ROW('DONNÉES BRUTES'!AA$3:AA$42)+ROW('DONNÉES BRUTES'!AA$3)),5),'DONNÉES BRUTES'!AA$3:AA$42*1000+(40-ROW('DONNÉES BRUTES'!AA$3:AA$42)+ROW('DONNÉES BRUTES'!AA$3)),0)),18),"—")} -> Kering SA | W12: {=IFERROR(INT(_xlfn.AGGREGATE(14,6,'DONNÉES BRUTES'!AA$3:AA$42*1000+(40-ROW('DONNÉES BRUTES'!AA$3:AA$42)+ROW('DONNÉES BRUTES'!AA$3)),5)/1000)&"/100","—")} -> 89/100 | X12: {=IFERROR(INDEX('DONNÉES BRUTES'!P$3:P$42,MATCH(_xlfn.AGGREGATE(14,6,'DONNÉES BRUTES'!AA$3:AA$42*1000+(40-ROW('DONNÉES BRUTES'!AA$3:AA$42)+ROW('DONNÉES BRUTES'!AA$3)),5),'DONNÉES BRUTES'!AA$3:AA$42*1000+(40-ROW('DONNÉES BRUTES'!AA$3:AA$42)+ROW('DONNÉES BRUTES'!AA$3)),0)),"—")} -> -13.0%
B14: TOP 10 GLOBAL · Score Composite · Value / Growth / Quality / Momentum
B15: # | C15: Ticker | D15: Société | E15: Secteur | F15: Score | H15: Growth | I15: Quality | J15: Momentum | K15: Mg.EBITDA | L15: Croiss. | N15: Next Earn. | R15: Signal
B16: 1 | C16: {=IFERROR(INDEX('DONNÉES BRUTES'!A$3:A$42,MATCH(_xlfn.AGGREGATE(14,6,'DONNÉES BRUTES'!AB$3:AB$42*1000+(40-ROW('DONNÉES BRUTES'!AB$3:AB$42)+ROW('DONNÉES BRUTES'!AB$3)),1),'DONNÉES BRUTES'!AB$3:AB$42*1000+(40-ROW('DONNÉES BRUTES'!AB$3:AB$42)+ROW('DONNÉES BRUTES'!AB$3)),0)),"—")} -> ASML.AS | D16: {=IFERROR(LEFT(IFERROR(INDEX('DONNÉES BRUTES'!B$3:B$42,MATCH(_xlfn.AGGREGATE(14,6,'DONNÉES BRUTES'!AB$3:AB$42*1000+(40-ROW('DONNÉES BRUTES'!AB$3:AB$42)+ROW('DONNÉES BRUTES'!AB$3)),1),'DONNÉES BRUTES'!AB$3:AB$42*1000+(40-ROW('DONNÉES BRUTES'!AB$3:AB$42)+ROW('DONNÉES BRUTES'!AB$3)),0)),"—"),18),"—")} -> ASML Holding N.V. | E16: {=IFERROR(INDEX('DONNÉES BRUTES'!C$3:C$42,MATCH(_xlfn.AGGREGATE(14,6,'DONNÉES BRUTES'!AB$3:AB$42*1000+(40-ROW('DONNÉES BRUTES'!AB$3:AB$42)+ROW('DONNÉES BRUTES'!AB$3)),1),'DONNÉES BRUTES'!AB$3:AB$42*1000+(40-ROW('DONNÉES BRUTES'!AB$3:AB$42)+ROW('DONNÉES BRUTES'!AB$3)),0)),"—")} -> Technologie | F16: {=IFERROR(INT(_xlfn.AGGREGATE(14,6,'DONNÉES BRUTES'!AB$3:AB$42*1000+(40-ROW('DONNÉES BRUTES'!AB$3:AB$42)+ROW('DONNÉES BRUTES'!AB$3)),1)/1000)&"/100","—")} -> 75/100 | H16: {=IFERROR(INDEX('DONNÉES BRUTES'!Y$3:Y$42,MATCH(_xlfn.AGGREGATE(14,6,'DONNÉES BRUTES'!AB$3:AB$42*1000+(40-ROW('DONNÉES BRUTES'!AB$3:AB$42)+ROW('DONNÉES BRUTES'!AB$3)),1),'DONNÉES BRUTES'!AB$3:AB$42*1000+(40-ROW('DONNÉES BRUTES'!AB$3:AB$42)+ROW('DONNÉES BRUTES'!AB$3)),0)),"—")} -> 92 | I16: {=IFERROR(INDEX('DONNÉES BRUTES'!Z$3:Z$42,MATCH(_xlfn.AGGREGATE(14,6,'DONNÉES BRUTES'!AB$3:AB$42*1000+(40-ROW('DONNÉES BRUTES'!AB$3:AB$42)+ROW('DONNÉES BRUTES'!AB$3)),1),'DONNÉES BRUTES'!AB$3:AB$42*1000+(40-ROW('DONNÉES BRUTES'!AB$3:AB$42)+ROW('DONNÉES BRUTES'!AB$3)),0)),"—")} -> 86 | J16: {=IFERROR(INDEX('DONNÉES BRUTES'!AA$3:AA$42,MATCH(_xlfn.AGGREGATE(14,6,'DONNÉES BRUTES'!AB$3:AB$42*1000+(40-ROW('DONNÉES BRUTES'!AB$3:AB$42)+ROW('DONNÉES BRUTES'!AB$3)),1),'DONNÉES BRUTES'!AB$3:AB$42*1000+(40-ROW('DONNÉES BRUTES'!AB$3:AB$42)+ROW('DONNÉES BRUTES'!AB$3)),0)),"—")} -> 98 | K16: {=IFERROR(INDEX('DONNÉES BRUTES'!N$3:N$42,MATCH(_xlfn.AGGREGATE(14,6,'DONNÉES BRUTES'!AB$3:AB$42*1000+(40-ROW('DONNÉES BRUTES'!AB$3:AB$42)+ROW('DONNÉES BRUTES'!AB$3)),1),'DONNÉES BRUTES'!AB$3:AB$42*1000+(40-ROW('DONNÉES BRUTES'!AB$3:AB$42)+ROW('DONNÉES BRUTES'!AB$3)),0)),"—")} -> 38.4% | L16: {=IFERROR(INDEX('DONNÉES BRUTES'!P$3:P$42,MATCH(_xlfn.AGGREGATE(14,6,'DONNÉES BRUTES'!AB$3:AB$42*1000+(40-ROW('DONNÉES BRUTES'!AB$3:AB$42)+ROW('DONNÉES BRUTES'!AB$3)),1),'DONNÉES BRUTES'!AB$3:AB$42*1000+(40-ROW('DONNÉES BRUTES'!AB$3:AB$42)+ROW('DONNÉES BRUTES'!AB$3)),0)),"—")} -> +15.6% | N16: {=IFERROR(INDEX('DONNÉES BRUTES'!AC$3:AC$42,MATCH(_xlfn.AGGREGATE(14,6,'DONNÉES BRUTES'!AB$3:AB$42*1000+(40-ROW('DONNÉES BRUTES'!AB$3:AB$42)+ROW('DONNÉES BRUTES'!AB$3)),1),'DONNÉES BRUTES'!AB$3:AB$42*1000+(40-ROW('DONNÉES BRUTES'!AB$3:AB$42)+ROW('DONNÉES BRUTES'!AB$3)),0)),"—")} -> 2026-04-15 | R16: {=IFERROR(INDEX('DONNÉES BRUTES'!AD$3:AD$42,MATCH(_xlfn.AGGREGATE(14,6,'DONNÉES BRUTES'!AB$3:AB$42*1000+(40-ROW('DONNÉES BRUTES'!AB$3:AB$42)+ROW('DONNÉES BRUTES'!AB$3)),1),'DONNÉES BRUTES'!AB$3:AB$42*1000+(40-ROW('DONNÉES BRUTES'!AB$3:AB$42)+ROW('DONNÉES BRUTES'!AB$3)),0)),"—")} -> Surpondérer
B17: 2 | C17: {=IFERROR(INDEX('DONNÉES BRUTES'!A$3:A$42,MATCH(_xlfn.AGGREGATE(14,6,'DONNÉES BRUTES'!AB$3:AB$42*1000+(40-ROW('DONNÉES BRUTES'!AB$3:AB$42)+ROW('DONNÉES BRUTES'!AB$3)),2),'DONNÉES BRUTES'!AB$3:AB$42*1000+(40-ROW('DONNÉES BRUTES'!AB$3:AB$42)+ROW('DONNÉES BRUTES'!AB$3)),0)),"—")} -> RIO.L | D17: {=IFERROR(LEFT(IFERROR(INDEX('DONNÉES BRUTES'!B$3:B$42,MATCH(_xlfn.AGGREGATE(14,6,'DONNÉES BRUTES'!AB$3:AB$42*1000+(40-ROW('DONNÉES BRUTES'!AB$3:AB$42)+ROW('DONNÉES BRUTES'!AB$3)),2),'DONNÉES BRUTES'!AB$3:AB$42*1000+(40-ROW('DONNÉES BRUTES'!AB$3:AB$42)+ROW('DONNÉES BRUTES'!AB$3)),0)),"—"),18),"—")} -> Rio Tinto Group | E17: {=IFERROR(INDEX('DONNÉES BRUTES'!C$3:C$42,MATCH(_xlfn.AGGREGATE(14,6,'DONNÉES BRUTES'!AB$3:AB$42*1000+(40-ROW('DONNÉES BRUTES'!AB$3:AB$42)+ROW('DONNÉES BRUTES'!AB$3)),2),'DONNÉES BRUTES'!AB$3:AB$42*1000+(40-ROW('DONNÉES BRUTES'!AB$3:AB$42)+ROW('DONNÉES BRUTES'!AB$3)),0)),"—")} -> Matériaux | F17: {=IFERROR(INT(_xlfn.AGGREGATE(14,6,'DONNÉES BRUTES'!AB$3:AB$42*1000+(40-ROW('DONNÉES BRUTES'!AB$3:AB$42)+ROW('DONNÉES BRUTES'!AB$3)),2)/1000)&"/100","—")} -> 70/100 | H17: {=IFERROR(INDEX('DONNÉES BRUTES'!Y$3:Y$42,MATCH(_xlfn.AGGREGATE(14,6,'DONNÉES BRUTES'!AB$3:AB$42*1000+(40-ROW('DONNÉES BRUTES'!AB$3:AB$42)+ROW('DONNÉES BRUTES'!AB$3)),2),'DONNÉES BRUTES'!AB$3:AB$42*1000+(40-ROW('DONNÉES BRUTES'!AB$3:AB$42)+ROW('DONNÉES BRUTES'!AB$3)),0)),"—")} -> 77 | I17: {=IFERROR(INDEX('DONNÉES BRUTES'!Z$3:Z$42,MATCH(_xlfn.AGGREGATE(14,6,'DONNÉES BRUTES'!AB$3:AB$42*1000+(40-ROW('DONNÉES BRUTES'!AB$3:AB$42)+ROW('DONNÉES BRUTES'!AB$3)),2),'DONNÉES BRUTES'!AB$3:AB$42*1000+(40-ROW('DONNÉES BRUTES'!AB$3:AB$42)+ROW('DONNÉES BRUTES'!AB$3)),0)),"—")} -> 78 | J17: {=IFERROR(INDEX('DONNÉES BRUTES'!AA$3:AA$42,MATCH(_xlfn.AGGREGATE(14,6,'DONNÉES BRUTES'!AB$3:AB$42*1000+(40-ROW('DONNÉES BRUTES'!AB$3:AB$42)+ROW('DONNÉES BRUTES'!AB$3)),2),'DONNÉES BRUTES'!AB$3:AB$42*1000+(40-ROW('DONNÉES BRUTES'!AB$3:AB$42)+ROW('DONNÉES BRUTES'!AB$3)),0)),"—")} -> 91 | K17: {=IFERROR(INDEX('DONNÉES BRUTES'!N$3:N$42,MATCH(_xlfn.AGGREGATE(14,6,'DONNÉES BRUTES'!AB$3:AB$42*1000+(40-ROW('DONNÉES BRUTES'!AB$3:AB$42)+ROW('DONNÉES BRUTES'!AB$3)),2),'DONNÉES BRUTES'!AB$3:AB$42*1000+(40-ROW('DONNÉES BRUTES'!AB$3:AB$42)+ROW('DONNÉES BRUTES'!AB$3)),0)),"—")} -> 39.9% | L17: {=IFERROR(INDEX('DONNÉES BRUTES'!P$3:P$42,MATCH(_xlfn.AGGREGATE(14,6,'DONNÉES BRUTES'!AB$3:AB$42*1000+(40-ROW('DONNÉES BRUTES'!AB$3:AB$42)+ROW('DONNÉES BRUTES'!AB$3)),2),'DONNÉES BRUTES'!AB$3:AB$42*1000+(40-ROW('DONNÉES BRUTES'!AB$3:AB$42)+ROW('DONNÉES BRUTES'!AB$3)),0)),"—")} -> +7.4% | N17: {=IFERROR(INDEX('DONNÉES BRUTES'!AC$3:AC$42,MATCH(_xlfn.AGGREGATE(14,6,'DONNÉES BRUTES'!AB$3:AB$42*1000+(40-ROW('DONNÉES BRUTES'!AB$3:AB$42)+ROW('DONNÉES BRUTES'!AB$3)),2),'DONNÉES BRUTES'!AB$3:AB$42*1000+(40-ROW('DONNÉES BRUTES'!AB$3:AB$42)+ROW('DONNÉES BRUTES'!AB$3)),0)),"—")} -> — | R17: {=IFERROR(INDEX('DONNÉES BRUTES'!AD$3:AD$42,MATCH(_xlfn.AGGREGATE(14,6,'DONNÉES BRUTES'!AB$3:AB$42*1000+(40-ROW('DONNÉES BRUTES'!AB$3:AB$42)+ROW('DONNÉES BRUTES'!AB$3)),2),'DONNÉES BRUTES'!AB$3:AB$42*1000+(40-ROW('DONNÉES BRUTES'!AB$3:AB$42)+ROW('DONNÉES BRUTES'!AB$3)),0)),"—")} -> Surpondérer
B18: 3 | C18: {=IFERROR(INDEX('DONNÉES BRUTES'!A$3:A$42,MATCH(_xlfn.AGGREGATE(14,6,'DONNÉES BRUTES'!AB$3:AB$42*1000+(40-ROW('DONNÉES BRUTES'!AB$3:AB$42)+ROW('DONNÉES BRUTES'!AB$3)),3),'DONNÉES BRUTES'!AB$3:AB$42*1000+(40-ROW('DONNÉES BRUTES'!AB$3:AB$42)+ROW('DONNÉES BRUTES'!AB$3)),0)),"—")} -> RMS.PA | D18: {=IFERROR(LEFT(IFERROR(INDEX('DONNÉES BRUTES'!B$3:B$42,MATCH(_xlfn.AGGREGATE(14,6,'DONNÉES BRUTES'!AB$3:AB$42*1000+(40-ROW('DONNÉES BRUTES'!AB$3:AB$42)+ROW('DONNÉES BRUTES'!AB$3)),3),'DONNÉES BRUTES'!AB$3:AB$42*1000+(40-ROW('DONNÉES BRUTES'!AB$3:AB$42)+ROW('DONNÉES BRUTES'!AB$3)),0)),"—"),18),"—")} -> Hermès Internation | E18: {=IFERROR(INDEX('DONNÉES BRUTES'!C$3:C$42,MATCH(_xlfn.AGGREGATE(14,6,'DONNÉES BRUTES'!AB$3:AB$42*1000+(40-ROW('DONNÉES BRUTES'!AB$3:AB$42)+ROW('DONNÉES BRUTES'!AB$3)),3),'DONNÉES BRUTES'!AB$3:AB$42*1000+(40-ROW('DONNÉES BRUTES'!AB$3:AB$42)+ROW('DONNÉES BRUTES'!AB$3)),0)),"—")} -> Conso. Cycl. | F18: {=IFERROR(INT(_xlfn.AGGREGATE(14,6,'DONNÉES BRUTES'!AB$3:AB$42*1000+(40-ROW('DONNÉES BRUTES'!AB$3:AB$42)+ROW('DONNÉES BRUTES'!AB$3)),3)/1000)&"/100","—")} -> 65/100 | H18: {=IFERROR(INDEX('DONNÉES BRUTES'!Y$3:Y$42,MATCH(_xlfn.AGGREGATE(14,6,'DONNÉES BRUTES'!AB$3:AB$42*1000+(40-ROW('DONNÉES BRUTES'!AB$3:AB$42)+ROW('DONNÉES BRUTES'!AB$3)),3),'DONNÉES BRUTES'!AB$3:AB$42*1000+(40-ROW('DONNÉES BRUTES'!AB$3:AB$42)+ROW('DONNÉES BRUTES'!AB$3)),0)),"—")} -> 81 | I18: {=IFERROR(INDEX('DONNÉES BRUTES'!Z$3:Z$42,MATCH(_xlfn.AGGREGATE(14,6,'DONNÉES BRUTES'!AB$3:AB$42*1000+(40-ROW('DONNÉES BRUTES'!AB$3:AB$42)+ROW('DONNÉES BRUTES'!AB$3)),3),'DONNÉES BRUTES'!AB$3:AB$42*1000+(40-ROW('DONNÉES BRUTES'!AB$3:AB$42)+ROW('DONNÉES BRUTES'!AB$3)),0)),"—")} -> 99 | J18: {=IFERROR(INDEX('DONNÉES BRUTES'!AA$3:AA$42,MATCH(_xlfn.AGGREGATE(14,6,'DONNÉES BRUTES'!AB$3:AB$42*1000+(40-ROW('DONNÉES BRUTES'!AB$3:AB$42)+ROW('DONNÉES BRUTES'!AB$3)),3),'DONNÉES BRUTES'!AB$3:AB$42*1000+(40-ROW('DONNÉES BRUTES'!AB$3:AB$42)+ROW('DONNÉES BRUTES'!AB$3)),0)),"—")} -> 4 | K18: {=IFERROR(INDEX('DONNÉES BRUTES'!N$3:N$42,MATCH(_xlfn.AGGREGATE(14,6,'DONNÉES BRUTES'!AB$3:AB$42*1000+(40-ROW('DONNÉES BRUTES'!AB$3:AB$42)+ROW('DONNÉES BRUTES'!AB$3)),3),'DONNÉES BRUTES'!AB$3:AB$42*1000+(40-ROW('DONNÉES BRUTES'!AB$3:AB$42)+ROW('DONNÉES BRUTES'!AB$3)),0)),"—")} -> 46.8% | L18: {=IFERROR(INDEX('DONNÉES BRUTES'!P$3:P$42,MATCH(_xlfn.AGGREGATE(14,6,'DONNÉES BRUTES'!AB$3:AB$42*1000+(40-ROW('DONNÉES BRUTES'!AB$3:AB$42)+ROW('DONNÉES BRUTES'!AB$3)),3),'DONNÉES BRUTES'!AB$3:AB$42*1000+(40-ROW('DONNÉES BRUTES'!AB$3:AB$42)+ROW('DONNÉES BRUTES'!AB$3)),0)),"—")} -> +5.5% | N18: {=IFERROR(INDEX('DONNÉES BRUTES'!AC$3:AC$42,MATCH(_xlfn.AGGREGATE(14,6,'DONNÉES BRUTES'!AB$3:AB$42*1000+(40-ROW('DONNÉES BRUTES'!AB$3:AB$42)+ROW('DONNÉES BRUTES'!AB$3)),3),'DONNÉES BRUTES'!AB$3:AB$42*1000+(40-ROW('DONNÉES BRUTES'!AB$3:AB$42)+ROW('DONNÉES BRUTES'!AB$3)),0)),"—")} -> — | R18: {=IFERROR(INDEX('DONNÉES BRUTES'!AD$3:AD$42,MATCH(_xlfn.AGGREGATE(14,6,'DONNÉES BRUTES'!AB$3:AB$42*1000+(40-ROW('DONNÉES BRUTES'!AB$3:AB$42)+ROW('DONNÉES BRUTES'!AB$3)),3),'DONNÉES BRUTES'!AB$3:AB$42*1000+(40-ROW('DONNÉES BRUTES'!AB$3:AB$42)+ROW('DONNÉES BRUTES'!AB$3)),0)),"—")} -> Surpondérer
B19: 4 | C19: {=IFERROR(INDEX('DONNÉES BRUTES'!A$3:A$42,MATCH(_xlfn.AGGREGATE(14,6,'DONNÉES BRUTES'!AB$3:AB$42*1000+(40-ROW('DONNÉES BRUTES'!AB$3:AB$42)+ROW('DONNÉES BRUTES'!AB$3)),4),'DONNÉES BRUTES'!AB$3:AB$42*1000+(40-ROW('DONNÉES BRUTES'!AB$3:AB$42)+ROW('DONNÉES BRUTES'!AB$3)),0)),"—")} -> SAP.DE | D19: {=IFERROR(LEFT(IFERROR(INDEX('DONNÉES BRUTES'!B$3:B$42,MATCH(_xlfn.AGGREGATE(14,6,'DONNÉES BRUTES'!AB$3:AB$42*1000+(40-ROW('DONNÉES BRUTES'!AB$3:AB$42)+ROW('DONNÉES BRUTES'!AB$3)),4),'DONNÉES BRUTES'!AB$3:AB$42*1000+(40-ROW('DONNÉES BRUTES'!AB$3:AB$42)+ROW('DONNÉES BRUTES'!AB$3)),0)),"—"),18),"—")} -> SAP SE | E19: {=IFERROR(INDEX('DONNÉES BRUTES'!C$3:C$42,MATCH(_xlfn.AGGREGATE(14,6,'DONNÉES BRUTES'!AB$3:AB$42*1000+(40-ROW('DONNÉES BRUTES'!AB$3:AB$42)+ROW('DONNÉES BRUTES'!AB$3)),4),'DONNÉES BRUTES'!AB$3:AB$42*1000+(40-ROW('DONNÉES BRUTES'!AB$3:AB$42)+ROW('DONNÉES BRUTES'!AB$3)),0)),"—")} -> Technologie | F19: {=IFERROR(INT(_xlfn.AGGREGATE(14,6,'DONNÉES BRUTES'!AB$3:AB$42*1000+(40-ROW('DONNÉES BRUTES'!AB$3:AB$42)+ROW('DONNÉES BRUTES'!AB$3)),4)/1000)&"/100","—")} -> 62/100 | H19: {=IFERROR(INDEX('DONNÉES BRUTES'!Y$3:Y$42,MATCH(_xlfn.AGGREGATE(14,6,'DONNÉES BRUTES'!AB$3:AB$42*1000+(40-ROW('DONNÉES BRUTES'!AB$3:AB$42)+ROW('DONNÉES BRUTES'!AB$3)),4),'DONNÉES BRUTES'!AB$3:AB$42*1000+(40-ROW('DONNÉES BRUTES'!AB$3:AB$42)+ROW('DONNÉES BRUTES'!AB$3)),0)),"—")} -> 78 | I19: {=IFERROR(INDEX('DONNÉES BRUTES'!Z$3:Z$42,MATCH(_xlfn.AGGREGATE(14,6,'DONNÉES BRUTES'!AB$3:AB$42*1000+(40-ROW('DONNÉES BRUTES'!AB$3:AB$42)+ROW('DONNÉES BRUTES'!AB$3)),4),'DONNÉES BRUTES'!AB$3:AB$42*1000+(40-ROW('DONNÉES BRUTES'!AB$3:AB$42)+ROW('DONNÉES BRUTES'!AB$3)),0)),"—")} -> 80 | J19: {=IFERROR(INDEX('DONNÉES BRUTES'!AA$3:AA$42,MATCH(_xlfn.AGGREGATE(14,6,'DONNÉES BRUTES'!AB$3:AB$42*1000+(40-ROW('DONNÉES BRUTES'!AB$3:AB$42)+ROW('DONNÉES BRUTES'!AB$3)),4),'DONNÉES BRUTES'!AB$3:AB$42*1000+(40-ROW('DONNÉES BRUTES'!AB$3:AB$42)+ROW('DONNÉES BRUTES'!AB$3)),0)),"—")} -> 0 | K19: {=IFERROR(INDEX('DONNÉES BRUTES'!N$3:N$42,MATCH(_xlfn.AGGREGATE(14,6,'DONNÉES BRUTES'!AB$3:AB$42*1000+(40-ROW('DONNÉES BRUTES'!AB$3:AB$42)+ROW('DONNÉES BRUTES'!AB$3)),4),'DONNÉES BRUTES'!AB$3:AB$42*1000+(40-ROW('DONNÉES BRUTES'!AB$3:AB$42)+ROW('DONNÉES BRUTES'!AB$3)),0)),"—")} -> 32.8% | L19: {=IFERROR(INDEX('DONNÉES BRUTES'!P$3:P$42,MATCH(_xlfn.AGGREGATE(14,6,'DONNÉES BRUTES'!AB$3:AB$42*1000+(40-ROW('DONNÉES BRUTES'!AB$3:AB$42)+ROW('DONNÉES BRUTES'!AB$3)),4),'DONNÉES BRUTES'!AB$3:AB$42*1000+(40-ROW('DONNÉES BRUTES'!AB$3:AB$42)+ROW('DONNÉES BRUTES'!AB$3)),0)),"—")} -> +7.7% | N19: {=IFERROR(INDEX('DONNÉES BRUTES'!AC$3:AC$42,MATCH(_xlfn.AGGREGATE(14,6,'DONNÉES BRUTES'!AB$3:AB$42*1000+(40-ROW('DONNÉES BRUTES'!AB$3:AB$42)+ROW('DONNÉES BRUTES'!AB$3)),4),'DONNÉES BRUTES'!AB$3:AB$42*1000+(40-ROW('DONNÉES BRUTES'!AB$3:AB$42)+ROW('DONNÉES BRUTES'!AB$3)),0)),"—")} -> 2026-04-23 | R19: {=IFERROR(INDEX('DONNÉES BRUTES'!AD$3:AD$42,MATCH(_xlfn.AGGREGATE(14,6,'DONNÉES BRUTES'!AB$3:AB$42*1000+(40-ROW('DONNÉES BRUTES'!AB$3:AB$42)+ROW('DONNÉES BRUTES'!AB$3)),4),'DONNÉES BRUTES'!AB$3:AB$42*1000+(40-ROW('DONNÉES BRUTES'!AB$3:AB$42)+ROW('DONNÉES BRUTES'!AB$3)),0)),"—")} -> Surpondérer
B20: 5 | C20: {=IFERROR(INDEX('DONNÉES BRUTES'!A$3:A$42,MATCH(_xlfn.AGGREGATE(14,6,'DONNÉES BRUTES'!AB$3:AB$42*1000+(40-ROW('DONNÉES BRUTES'!AB$3:AB$42)+ROW('DONNÉES BRUTES'!AB$3)),5),'DONNÉES BRUTES'!AB$3:AB$42*1000+(40-ROW('DONNÉES BRUTES'!AB$3:AB$42)+ROW('DONNÉES BRUTES'!AB$3)),0)),"—")} -> AZN.L | D20: {=IFERROR(LEFT(IFERROR(INDEX('DONNÉES BRUTES'!B$3:B$42,MATCH(_xlfn.AGGREGATE(14,6,'DONNÉES BRUTES'!AB$3:AB$42*1000+(40-ROW('DONNÉES BRUTES'!AB$3:AB$42)+ROW('DONNÉES BRUTES'!AB$3)),5),'DONNÉES BRUTES'!AB$3:AB$42*1000+(40-ROW('DONNÉES BRUTES'!AB$3:AB$42)+ROW('DONNÉES BRUTES'!AB$3)),0)),"—"),18),"—")} -> AstraZeneca PLC | E20: {=IFERROR(INDEX('DONNÉES BRUTES'!C$3:C$42,MATCH(_xlfn.AGGREGATE(14,6,'DONNÉES BRUTES'!AB$3:AB$42*1000+(40-ROW('DONNÉES BRUTES'!AB$3:AB$42)+ROW('DONNÉES BRUTES'!AB$3)),5),'DONNÉES BRUTES'!AB$3:AB$42*1000+(40-ROW('DONNÉES BRUTES'!AB$3:AB$42)+ROW('DONNÉES BRUTES'!AB$3)),0)),"—")} -> Santé | F20: {=IFERROR(INT(_xlfn.AGGREGATE(14,6,'DONNÉES BRUTES'!AB$3:AB$42*1000+(40-ROW('DONNÉES BRUTES'!AB$3:AB$42)+ROW('DONNÉES BRUTES'!AB$3)),5)/1000)&"/100","—")} -> 60/100 | H20: {=IFERROR(INDEX('DONNÉES BRUTES'!Y$3:Y$42,MATCH(_xlfn.AGGREGATE(14,6,'DONNÉES BRUTES'!AB$3:AB$42*1000+(40-ROW('DONNÉES BRUTES'!AB$3:AB$42)+ROW('DONNÉES BRUTES'!AB$3)),5),'DONNÉES BRUTES'!AB$3:AB$42*1000+(40-ROW('DONNÉES BRUTES'!AB$3:AB$42)+ROW('DONNÉES BRUTES'!AB$3)),0)),"—")} -> 87 | I20: {=IFERROR(INDEX('DONNÉES BRUTES'!Z$3:Z$42,MATCH(_xlfn.AGGREGATE(14,6,'DONNÉES BRUTES'!AB$3:AB$42*1000+(40-ROW('DONNÉES BRUTES'!AB$3:AB$42)+ROW('DONNÉES BRUTES'!AB$3)),5),'DONNÉES BRUTES'!AB$3:AB$42*1000+(40-ROW('DONNÉES BRUTES'!AB$3:AB$42)+ROW('DONNÉES BRUTES'!AB$3)),0)),"—")} -> 50 | J20: {=IFERROR(INDEX('DONNÉES BRUTES'!AA$3:AA$42,MATCH(_xlfn.AGGREGATE(14,6,'DONNÉES BRUTES'!AB$3:AB$42*1000+(40-ROW('DONNÉES BRUTES'!AB$3:AB$42)+ROW('DONNÉES BRUTES'!AB$3)),5),'DONNÉES BRUTES'!AB$3:AB$42*1000+(40-ROW('DONNÉES BRUTES'!AB$3:AB$42)+ROW('DONNÉES BRUTES'!AB$3)),0)),"—")} -> 70 | K20: {=IFERROR(INDEX('DONNÉES BRUTES'!N$3:N$42,MATCH(_xlfn.AGGREGATE(14,6,'DONNÉES BRUTES'!AB$3:AB$42*1000+(40-ROW('DONNÉES BRUTES'!AB$3:AB$42)+ROW('DONNÉES BRUTES'!AB$3)),5),'DONNÉES BRUTES'!AB$3:AB$42*1000+(40-ROW('DONNÉES BRUTES'!AB$3:AB$42)+ROW('DONNÉES BRUTES'!AB$3)),0)),"—")} -> 33.2% | L20: {=IFERROR(INDEX('DONNÉES BRUTES'!P$3:P$42,MATCH(_xlfn.AGGREGATE(14,6,'DONNÉES BRUTES'!AB$3:AB$42*1000+(40-ROW('DONNÉES BRUTES'!AB$3:AB$42)+ROW('DONNÉES BRUTES'!AB$3)),5),'DONNÉES BRUTES'!AB$3:AB$42*1000+(40-ROW('DONNÉES BRUTES'!AB$3:AB$42)+ROW('DONNÉES BRUTES'!AB$3)),0)),"—")} -> +8.6% | N20: {=IFERROR(INDEX('DONNÉES BRUTES'!AC$3:AC$42,MATCH(_xlfn.AGGREGATE(14,6,'DONNÉES BRUTES'!AB$3:AB$42*1000+(40-ROW('DONNÉES BRUTES'!AB$3:AB$42)+ROW('DONNÉES BRUTES'!AB$3)),5),'DONNÉES BRUTES'!AB$3:AB$42*1000+(40-ROW('DONNÉES BRUTES'!AB$3:AB$42)+ROW('DONNÉES BRUTES'!AB$3)),0)),"—")} -> 2026-04-29 | R20: {=IFERROR(INDEX('DONNÉES BRUTES'!AD$3:AD$42,MATCH(_xlfn.AGGREGATE(14,6,'DONNÉES BRUTES'!AB$3:AB$42*1000+(40-ROW('DONNÉES BRUTES'!AB$3:AB$42)+ROW('DONNÉES BRUTES'!AB$3)),5),'DONNÉES BRUTES'!AB$3:AB$42*1000+(40-ROW('DONNÉES BRUTES'!AB$3:AB$42)+ROW('DONNÉES BRUTES'!AB$3)),0)),"—")} -> Surpondérer
B21: 6 | C21: {=IFERROR(INDEX('DONNÉES BRUTES'!A$3:A$42,MATCH(_xlfn.AGGREGATE(14,6,'DONNÉES BRUTES'!AB$3:AB$42*1000+(40-ROW('DONNÉES BRUTES'!AB$3:AB$42)+ROW('DONNÉES BRUTES'!AB$3)),6),'DONNÉES BRUTES'!AB$3:AB$42*1000+(40-ROW('DONNÉES BRUTES'!AB$3:AB$42)+ROW('DONNÉES BRUTES'!AB$3)),0)),"—")} -> RWE.DE | D21: {=IFERROR(LEFT(IFERROR(INDEX('DONNÉES BRUTES'!B$3:B$42,MATCH(_xlfn.AGGREGATE(14,6,'DONNÉES BRUTES'!AB$3:AB$42*1000+(40-ROW('DONNÉES BRUTES'!AB$3:AB$42)+ROW('DONNÉES BRUTES'!AB$3)),6),'DONNÉES BRUTES'!AB$3:AB$42*1000+(40-ROW('DONNÉES BRUTES'!AB$3:AB$42)+ROW('DONNÉES BRUTES'!AB$3)),0)),"—"),18),"—")} -> RWE Aktiengesellsc | E21: {=IFERROR(INDEX('DONNÉES BRUTES'!C$3:C$42,MATCH(_xlfn.AGGREGATE(14,6,'DONNÉES BRUTES'!AB$3:AB$42*1000+(40-ROW('DONNÉES BRUTES'!AB$3:AB$42)+ROW('DONNÉES BRUTES'!AB$3)),6),'DONNÉES BRUTES'!AB$3:AB$42*1000+(40-ROW('DONNÉES BRUTES'!AB$3:AB$42)+ROW('DONNÉES BRUTES'!AB$3)),0)),"—")} -> Serv. Publ. | F21: {=IFERROR(INT(_xlfn.AGGREGATE(14,6,'DONNÉES BRUTES'!AB$3:AB$42*1000+(40-ROW('DONNÉES BRUTES'!AB$3:AB$42)+ROW('DONNÉES BRUTES'!AB$3)),6)/1000)&"/100","—")} -> 60/100 | H21: {=IFERROR(INDEX('DONNÉES BRUTES'!Y$3:Y$42,MATCH(_xlfn.AGGREGATE(14,6,'DONNÉES BRUTES'!AB$3:AB$42*1000+(40-ROW('DONNÉES BRUTES'!AB$3:AB$42)+ROW('DONNÉES BRUTES'!AB$3)),6),'DONNÉES BRUTES'!AB$3:AB$42*1000+(40-ROW('DONNÉES BRUTES'!AB$3:AB$42)+ROW('DONNÉES BRUTES'!AB$3)),0)),"—")} -> 37 | I21: {=IFERROR(INDEX('DONNÉES BRUTES'!Z$3:Z$42,MATCH(_xlfn.AGGREGATE(14,6,'DONNÉES BRUTES'!AB$3:AB$42*1000+(40-ROW('DONNÉES BRUTES'!AB$3:AB$42)+ROW('DONNÉES BRUTES'!AB$3)),6),'DONNÉES BRUTES'!AB$3:AB$42*1000+(40-ROW('DONNÉES BRUTES'!AB$3:AB$42)+ROW('DONNÉES BRUTES'!AB$3)),0)),"—")} -> 66 | J21: {=IFERROR(INDEX('DONNÉES BRUTES'!AA$3:AA$42,MATCH(_xlfn.AGGREGATE(14,6,'DONNÉES BRUTES'!AB$3:AB$42*1000+(40-ROW('DONNÉES BRUTES'!AB$3:AB$42)+ROW('DONNÉES BRUTES'!AB$3)),6),'DONNÉES BRUTES'!AB$3:AB$42*1000+(40-ROW('DONNÉES BRUTES'!AB$3:AB$42)+ROW('DONNÉES BRUTES'!AB$3)),0)),"—")} -> 96 | K21: {=IFERROR(INDEX('DONNÉES BRUTES'!N$3:N$42,MATCH(_xlfn.AGGREGATE(14,6,'DONNÉES BRUTES'!AB$3:AB$42*1000+(40-ROW('DONNÉES BRUTES'!AB$3:AB$42)+ROW('DONNÉES BRUTES'!AB$3)),6),'DONNÉES BRUTES'!AB$3:AB$42*1000+(40-ROW('DONNÉES BRUTES'!AB$3:AB$42)+ROW('DONNÉES BRUTES'!AB$3)),0)),"—")} -> 39.1% | L21: {=IFERROR(INDEX('DONNÉES BRUTES'!P$3:P$42,MATCH(_xlfn.AGGREGATE(14,6,'DONNÉES BRUTES'!AB$3:AB$42*1000+(40-ROW('DONNÉES BRUTES'!AB$3:AB$42)+ROW('DONNÉES BRUTES'!AB$3)),6),'DONNÉES BRUTES'!AB$3:AB$42*1000+(40-ROW('DONNÉES BRUTES'!AB$3:AB$42)+ROW('DONNÉES BRUTES'!AB$3)),0)),"—")} -> -27.2% | N21: {=IFERROR(INDEX('DONNÉES BRUTES'!AC$3:AC$42,MATCH(_xlfn.AGGREGATE(14,6,'DONNÉES BRUTES'!AB$3:AB$42*1000+(40-ROW('DONNÉES BRUTES'!AB$3:AB$42)+ROW('DONNÉES BRUTES'!AB$3)),6),'DONNÉES BRUTES'!AB$3:AB$42*1000+(40-ROW('DONNÉES BRUTES'!AB$3:AB$42)+ROW('DONNÉES BRUTES'!AB$3)),0)),"—")} -> 2026-05-13 | R21: {=IFERROR(INDEX('DONNÉES BRUTES'!AD$3:AD$42,MATCH(_xlfn.AGGREGATE(14,6,'DONNÉES BRUTES'!AB$3:AB$42*1000+(40-ROW('DONNÉES BRUTES'!AB$3:AB$42)+ROW('DONNÉES BRUTES'!AB$3)),6),'DONNÉES BRUTES'!AB$3:AB$42*1000+(40-ROW('DONNÉES BRUTES'!AB$3:AB$42)+ROW('DONNÉES BRUTES'!AB$3)),0)),"—")} -> Surpondérer
B22: 7 | C22: {=IFERROR(INDEX('DONNÉES BRUTES'!A$3:A$42,MATCH(_xlfn.AGGREGATE(14,6,'DONNÉES BRUTES'!AB$3:AB$42*1000+(40-ROW('DONNÉES BRUTES'!AB$3:AB$42)+ROW('DONNÉES BRUTES'!AB$3)),7),'DONNÉES BRUTES'!AB$3:AB$42*1000+(40-ROW('DONNÉES BRUTES'!AB$3:AB$42)+ROW('DONNÉES BRUTES'!AB$3)),0)),"—")} -> ITX.MC | D22: {=IFERROR(LEFT(IFERROR(INDEX('DONNÉES BRUTES'!B$3:B$42,MATCH(_xlfn.AGGREGATE(14,6,'DONNÉES BRUTES'!AB$3:AB$42*1000+(40-ROW('DONNÉES BRUTES'!AB$3:AB$42)+ROW('DONNÉES BRUTES'!AB$3)),7),'DONNÉES BRUTES'!AB$3:AB$42*1000+(40-ROW('DONNÉES BRUTES'!AB$3:AB$42)+ROW('DONNÉES BRUTES'!AB$3)),0)),"—"),18),"—")} -> Industria de Diseñ | E22: {=IFERROR(INDEX('DONNÉES BRUTES'!C$3:C$42,MATCH(_xlfn.AGGREGATE(14,6,'DONNÉES BRUTES'!AB$3:AB$42*1000+(40-ROW('DONNÉES BRUTES'!AB$3:AB$42)+ROW('DONNÉES BRUTES'!AB$3)),7),'DONNÉES BRUTES'!AB$3:AB$42*1000+(40-ROW('DONNÉES BRUTES'!AB$3:AB$42)+ROW('DONNÉES BRUTES'!AB$3)),0)),"—")} -> Conso. Cycl. | F22: {=IFERROR(INT(_xlfn.AGGREGATE(14,6,'DONNÉES BRUTES'!AB$3:AB$42*1000+(40-ROW('DONNÉES BRUTES'!AB$3:AB$42)+ROW('DONNÉES BRUTES'!AB$3)),7)/1000)&"/100","—")} -> 58/100 | H22: {=IFERROR(INDEX('DONNÉES BRUTES'!Y$3:Y$42,MATCH(_xlfn.AGGREGATE(14,6,'DONNÉES BRUTES'!AB$3:AB$42*1000+(40-ROW('DONNÉES BRUTES'!AB$3:AB$42)+ROW('DONNÉES BRUTES'!AB$3)),7),'DONNÉES BRUTES'!AB$3:AB$42*1000+(40-ROW('DONNÉES BRUTES'!AB$3:AB$42)+ROW('DONNÉES BRUTES'!AB$3)),0)),"—")} -> 67 | I22: {=IFERROR(INDEX('DONNÉES BRUTES'!Z$3:Z$42,MATCH(_xlfn.AGGREGATE(14,6,'DONNÉES BRUTES'!AB$3:AB$42*1000+(40-ROW('DONNÉES BRUTES'!AB$3:AB$42)+ROW('DONNÉES BRUTES'!AB$3)),7),'DONNÉES BRUTES'!AB$3:AB$42*1000+(40-ROW('DONNÉES BRUTES'!AB$3:AB$42)+ROW('DONNÉES BRUTES'!AB$3)),0)),"—")} -> 83 | J22: {=IFERROR(INDEX('DONNÉES BRUTES'!AA$3:AA$42,MATCH(_xlfn.AGGREGATE(14,6,'DONNÉES BRUTES'!AB$3:AB$42*1000+(40-ROW('DONNÉES BRUTES'!AB$3:AB$42)+ROW('DONNÉES BRUTES'!AB$3)),7),'DONNÉES BRUTES'!AB$3:AB$42*1000+(40-ROW('DONNÉES BRUTES'!AB$3:AB$42)+ROW('DONNÉES BRUTES'!AB$3)),0)),"—")} -> 51 | K22: {=IFERROR(INDEX('DONNÉES BRUTES'!N$3:N$42,MATCH(_xlfn.AGGREGATE(14,6,'DONNÉES BRUTES'!AB$3:AB$42*1000+(40-ROW('DONNÉES BRUTES'!AB$3:AB$42)+ROW('DONNÉES BRUTES'!AB$3)),7),'DONNÉES BRUTES'!AB$3:AB$42*1000+(40-ROW('DONNÉES BRUTES'!AB$3:AB$42)+ROW('DONNÉES BRUTES'!AB$3)),0)),"—")} -> 29.2% | L22: {=IFERROR(INDEX('DONNÉES BRUTES'!P$3:P$42,MATCH(_xlfn.AGGREGATE(14,6,'DONNÉES BRUTES'!AB$3:AB$42*1000+(40-ROW('DONNÉES BRUTES'!AB$3:AB$42)+ROW('DONNÉES BRUTES'!AB$3)),7),'DONNÉES BRUTES'!AB$3:AB$42*1000+(40-ROW('DONNÉES BRUTES'!AB$3:AB$42)+ROW('DONNÉES BRUTES'!AB$3)),0)),"—")} -> +3.2% | N22: {=IFERROR(INDEX('DONNÉES BRUTES'!AC$3:AC$42,MATCH(_xlfn.AGGREGATE(14,6,'DONNÉES BRUTES'!AB$3:AB$42*1000+(40-ROW('DONNÉES BRUTES'!AB$3:AB$42)+ROW('DONNÉES BRUTES'!AB$3)),7),'DONNÉES BRUTES'!AB$3:AB$42*1000+(40-ROW('DONNÉES BRUTES'!AB$3:AB$42)+ROW('DONNÉES BRUTES'!AB$3)),0)),"—")} -> 2026-06-03 | R22: {=IFERROR(INDEX('DONNÉES BRUTES'!AD$3:AD$42,MATCH(_xlfn.AGGREGATE(14,6,'DONNÉES BRUTES'!AB$3:AB$42*1000+(40-ROW('DONNÉES BRUTES'!AB$3:AB$42)+ROW('DONNÉES BRUTES'!AB$3)),7),'DONNÉES BRUTES'!AB$3:AB$42*1000+(40-ROW('DONNÉES BRUTES'!AB$3:AB$42)+ROW('DONNÉES BRUTES'!AB$3)),0)),"—")} -> Neutre
B23: 8 | C23: {=IFERROR(INDEX('DONNÉES BRUTES'!A$3:A$42,MATCH(_xlfn.AGGREGATE(14,6,'DONNÉES BRUTES'!AB$3:AB$42*1000+(40-ROW('DONNÉES BRUTES'!AB$3:AB$42)+ROW('DONNÉES BRUTES'!AB$3)),8),'DONNÉES BRUTES'!AB$3:AB$42*1000+(40-ROW('DONNÉES BRUTES'!AB$3:AB$42)+ROW('DONNÉES BRUTES'!AB$3)),0)),"—")} -> GSK.L | D23: {=IFERROR(LEFT(IFERROR(INDEX('DONNÉES BRUTES'!B$3:B$42,MATCH(_xlfn.AGGREGATE(14,6,'DONNÉES BRUTES'!AB$3:AB$42*1000+(40-ROW('DONNÉES BRUTES'!AB$3:AB$42)+ROW('DONNÉES BRUTES'!AB$3)),8),'DONNÉES BRUTES'!AB$3:AB$42*1000+(40-ROW('DONNÉES BRUTES'!AB$3:AB$42)+ROW('DONNÉES BRUTES'!AB$3)),0)),"—"),18),"—")} -> GSK plc | E23: {=IFERROR(INDEX('DONNÉES BRUTES'!C$3:C$42,MATCH(_xlfn.AGGREGATE(14,6,'DONNÉES BRUTES'!AB$3:AB$42*1000+(40-ROW('DONNÉES BRUTES'!AB$3:AB$42)+ROW('DONNÉES BRUTES'!AB$3)),8),'DONNÉES BRUTES'!AB$3:AB$42*1000+(40-ROW('DONNÉES BRUTES'!AB$3:AB$42)+ROW('DONNÉES BRUTES'!AB$3)),0)),"—")} -> Santé | F23: {=IFERROR(INT(_xlfn.AGGREGATE(14,6,'DONNÉES BRUTES'!AB$3:AB$42*1000+(40-ROW('DONNÉES BRUTES'!AB$3:AB$42)+ROW('DONNÉES BRUTES'!AB$3)),8)/1000)&"/100","—")} -> 56/100 | H23: {=IFERROR(INDEX('DONNÉES BRUTES'!Y$3:Y$42,MATCH(_xlfn.AGGREGATE(14,6,'DONNÉES BRUTES'!AB$3:AB$42*1000+(40-ROW('DONNÉES BRUTES'!AB$3:AB$42)+ROW('DONNÉES BRUTES'!AB$3)),8),'DONNÉES BRUTES'!AB$3:AB$42*1000+(40-ROW('DONNÉES BRUTES'!AB$3:AB$42)+ROW('DONNÉES BRUTES'!AB$3)),0)),"—")} -> 78 | I23: {=IFERROR(INDEX('DONNÉES BRUTES'!Z$3:Z$42,MATCH(_xlfn.AGGREGATE(14,6,'DONNÉES BRUTES'!AB$3:AB$42*1000+(40-ROW('DONNÉES BRUTES'!AB$3:AB$42)+ROW('DONNÉES BRUTES'!AB$3)),8),'DONNÉES BRUTES'!AB$3:AB$42*1000+(40-ROW('DONNÉES BRUTES'!AB$3:AB$42)+ROW('DONNÉES BRUTES'!AB$3)),0)),"—")} -> 41 | J23: {=IFERROR(INDEX('DONNÉES BRUTES'!AA$3:AA$42,MATCH(_xlfn.AGGREGATE(14,6,'DONNÉES BRUTES'!AB$3:AB$42*1000+(40-ROW('DONNÉES BRUTES'!AB$3:AB$42)+ROW('DONNÉES BRUTES'!AB$3)),8),'DONNÉES BRUTES'!AB$3:AB$42*1000+(40-ROW('DONNÉES BRUTES'!AB$3:AB$42)+ROW('DONNÉES BRUTES'!AB$3)),0)),"—")} -> 72 | K23: {=IFERROR(INDEX('DONNÉES BRUTES'!N$3:N$42,MATCH(_xlfn.AGGREGATE(14,6,'DONNÉES BRUTES'!AB$3:AB$42*1000+(40-ROW('DONNÉES BRUTES'!AB$3:AB$42)+ROW('DONNÉES BRUTES'!AB$3)),8),'DONNÉES BRUTES'!AB$3:AB$42*1000+(40-ROW('DONNÉES BRUTES'!AB$3:AB$42)+ROW('DONNÉES BRUTES'!AB$3)),0)),"—")} -> 31.8% | L23: {=IFERROR(INDEX('DONNÉES BRUTES'!P$3:P$42,MATCH(_xlfn.AGGREGATE(14,6,'DONNÉES BRUTES'!AB$3:AB$42*1000+(40-ROW('DONNÉES BRUTES'!AB$3:AB$42)+ROW('DONNÉES BRUTES'!AB$3)),8),'DONNÉES BRUTES'!AB$3:AB$42*1000+(40-ROW('DONNÉES BRUTES'!AB$3:AB$42)+ROW('DONNÉES BRUTES'!AB$3)),0)),"—")} -> +4.1% | N23: {=IFERROR(INDEX('DONNÉES BRUTES'!AC$3:AC$42,MATCH(_xlfn.AGGREGATE(14,6,'DONNÉES BRUTES'!AB$3:AB$42*1000+(40-ROW('DONNÉES BRUTES'!AB$3:AB$42)+ROW('DONNÉES BRUTES'!AB$3)),8),'DONNÉES BRUTES'!AB$3:AB$42*1000+(40-ROW('DONNÉES BRUTES'!AB$3:AB$42)+ROW('DONNÉES BRUTES'!AB$3)),0)),"—")} -> 2026-04-29 | R23: {=IFERROR(INDEX('DONNÉES BRUTES'!AD$3:AD$42,MATCH(_xlfn.AGGREGATE(14,6,'DONNÉES BRUTES'!AB$3:AB$42*1000+(40-ROW('DONNÉES BRUTES'!AB$3:AB$42)+ROW('DONNÉES BRUTES'!AB$3)),8),'DONNÉES BRUTES'!AB$3:AB$42*1000+(40-ROW('DONNÉES BRUTES'!AB$3:AB$42)+ROW('DONNÉES BRUTES'!AB$3)),0)),"—")} -> Neutre
B24: 9 | C24: {=IFERROR(INDEX('DONNÉES BRUTES'!A$3:A$42,MATCH(_xlfn.AGGREGATE(14,6,'DONNÉES BRUTES'!AB$3:AB$42*1000+(40-ROW('DONNÉES BRUTES'!AB$3:AB$42)+ROW('DONNÉES BRUTES'!AB$3)),9),'DONNÉES BRUTES'!AB$3:AB$42*1000+(40-ROW('DONNÉES BRUTES'!AB$3:AB$42)+ROW('DONNÉES BRUTES'!AB$3)),0)),"—")} -> PRX.AS | D24: {=IFERROR(LEFT(IFERROR(INDEX('DONNÉES BRUTES'!B$3:B$42,MATCH(_xlfn.AGGREGATE(14,6,'DONNÉES BRUTES'!AB$3:AB$42*1000+(40-ROW('DONNÉES BRUTES'!AB$3:AB$42)+ROW('DONNÉES BRUTES'!AB$3)),9),'DONNÉES BRUTES'!AB$3:AB$42*1000+(40-ROW('DONNÉES BRUTES'!AB$3:AB$42)+ROW('DONNÉES BRUTES'!AB$3)),0)),"—"),18),"—")} -> Prosus N.V. | E24: {=IFERROR(INDEX('DONNÉES BRUTES'!C$3:C$42,MATCH(_xlfn.AGGREGATE(14,6,'DONNÉES BRUTES'!AB$3:AB$42*1000+(40-ROW('DONNÉES BRUTES'!AB$3:AB$42)+ROW('DONNÉES BRUTES'!AB$3)),9),'DONNÉES BRUTES'!AB$3:AB$42*1000+(40-ROW('DONNÉES BRUTES'!AB$3:AB$42)+ROW('DONNÉES BRUTES'!AB$3)),0)),"—")} -> Conso. Cycl. | F24: {=IFERROR(INT(_xlfn.AGGREGATE(14,6,'DONNÉES BRUTES'!AB$3:AB$42*1000+(40-ROW('DONNÉES BRUTES'!AB$3:AB$42)+ROW('DONNÉES BRUTES'!AB$3)),9)/1000)&"/100","—")} -> 56/100 | H24: {=IFERROR(INDEX('DONNÉES BRUTES'!Y$3:Y$42,MATCH(_xlfn.AGGREGATE(14,6,'DONNÉES BRUTES'!AB$3:AB$42*1000+(40-ROW('DONNÉES BRUTES'!AB$3:AB$42)+ROW('DONNÉES BRUTES'!AB$3)),9),'DONNÉES BRUTES'!AB$3:AB$42*1000+(40-ROW('DONNÉES BRUTES'!AB$3:AB$42)+ROW('DONNÉES BRUTES'!AB$3)),0)),"—")} -> 66 | I24: {=IFERROR(INDEX('DONNÉES BRUTES'!Z$3:Z$42,MATCH(_xlfn.AGGREGATE(14,6,'DONNÉES BRUTES'!AB$3:AB$42*1000+(40-ROW('DONNÉES BRUTES'!AB$3:AB$42)+ROW('DONNÉES BRUTES'!AB$3)),9),'DONNÉES BRUTES'!AB$3:AB$42*1000+(40-ROW('DONNÉES BRUTES'!AB$3:AB$42)+ROW('DONNÉES BRUTES'!AB$3)),0)),"—")} -> 59 | J24: {=IFERROR(INDEX('DONNÉES BRUTES'!AA$3:AA$42,MATCH(_xlfn.AGGREGATE(14,6,'DONNÉES BRUTES'!AB$3:AB$42*1000+(40-ROW('DONNÉES BRUTES'!AB$3:AB$42)+ROW('DONNÉES BRUTES'!AB$3)),9),'DONNÉES BRUTES'!AB$3:AB$42*1000+(40-ROW('DONNÉES BRUTES'!AB$3:AB$42)+ROW('DONNÉES BRUTES'!AB$3)),0)),"—")} -> 15 | K24: {=IFERROR(INDEX('DONNÉES BRUTES'!N$3:N$42,MATCH(_xlfn.AGGREGATE(14,6,'DONNÉES BRUTES'!AB$3:AB$42*1000+(40-ROW('DONNÉES BRUTES'!AB$3:AB$42)+ROW('DONNÉES BRUTES'!AB$3)),9),'DONNÉES BRUTES'!AB$3:AB$42*1000+(40-ROW('DONNÉES BRUTES'!AB$3:AB$42)+ROW('DONNÉES BRUTES'!AB$3)),0)),"—")} -> — | L24: {=IFERROR(INDEX('DONNÉES BRUTES'!P$3:P$42,MATCH(_xlfn.AGGREGATE(14,6,'DONNÉES BRUTES'!AB$3:AB$42*1000+(40-ROW('DONNÉES BRUTES'!AB$3:AB$42)+ROW('DONNÉES BRUTES'!AB$3)),9),'DONNÉES BRUTES'!AB$3:AB$42*1000+(40-ROW('DONNÉES BRUTES'!AB$3:AB$42)+ROW('DONNÉES BRUTES'!AB$3)),0)),"—")} -> +12.9% | N24: {=IFERROR(INDEX('DONNÉES BRUTES'!AC$3:AC$42,MATCH(_xlfn.AGGREGATE(14,6,'DONNÉES BRUTES'!AB$3:AB$42*1000+(40-ROW('DONNÉES BRUTES'!AB$3:AB$42)+ROW('DONNÉES BRUTES'!AB$3)),9),'DONNÉES BRUTES'!AB$3:AB$42*1000+(40-ROW('DONNÉES BRUTES'!AB$3:AB$42)+ROW('DONNÉES BRUTES'!AB$3)),0)),"—")} -> — | R24: {=IFERROR(INDEX('DONNÉES BRUTES'!AD$3:AD$42,MATCH(_xlfn.AGGREGATE(14,6,'DONNÉES BRUTES'!AB$3:AB$42*1000+(40-ROW('DONNÉES BRUTES'!AB$3:AB$42)+ROW('DONNÉES BRUTES'!AB$3)),9),'DONNÉES BRUTES'!AB$3:AB$42*1000+(40-ROW('DONNÉES BRUTES'!AB$3:AB$42)+ROW('DONNÉES BRUTES'!AB$3)),0)),"—")} -> Neutre
B25: 10 | C25: {=IFERROR(INDEX('DONNÉES BRUTES'!A$3:A$42,MATCH(_xlfn.AGGREGATE(14,6,'DONNÉES BRUTES'!AB$3:AB$42*1000+(40-ROW('DONNÉES BRUTES'!AB$3:AB$42)+ROW('DONNÉES BRUTES'!AB$3)),10),'DONNÉES BRUTES'!AB$3:AB$42*1000+(40-ROW('DONNÉES BRUTES'!AB$3:AB$42)+ROW('DONNÉES BRUTES'!AB$3)),0)),"—")} -> OR.PA | D25: {=IFERROR(LEFT(IFERROR(INDEX('DONNÉES BRUTES'!B$3:B$42,MATCH(_xlfn.AGGREGATE(14,6,'DONNÉES BRUTES'!AB$3:AB$42*1000+(40-ROW('DONNÉES BRUTES'!AB$3:AB$42)+ROW('DONNÉES BRUTES'!AB$3)),10),'DONNÉES BRUTES'!AB$3:AB$42*1000+(40-ROW('DONNÉES BRUTES'!AB$3:AB$42)+ROW('DONNÉES BRUTES'!AB$3)),0)),"—"),18),"—")} -> L'Oréal S.A. | E25: {=IFERROR(INDEX('DONNÉES BRUTES'!C$3:C$42,MATCH(_xlfn.AGGREGATE(14,6,'DONNÉES BRUTES'!AB$3:AB$42*1000+(40-ROW('DONNÉES BRUTES'!AB$3:AB$42)+ROW('DONNÉES BRUTES'!AB$3)),10),'DONNÉES BRUTES'!AB$3:AB$42*1000+(40-ROW('DONNÉES BRUTES'!AB$3:AB$42)+ROW('DONNÉES BRUTES'!AB$3)),0)),"—")} -> Conso. Déf. | F25: {=IFERROR(INT(_xlfn.AGGREGATE(14,6,'DONNÉES BRUTES'!AB$3:AB$42*1000+(40-ROW('DONNÉES BRUTES'!AB$3:AB$42)+ROW('DONNÉES BRUTES'!AB$3)),10)/1000)&"/100","—")} -> 56/100 | H25: {=IFERROR(INDEX('DONNÉES BRUTES'!Y$3:Y$42,MATCH(_xlfn.AGGREGATE(14,6,'DONNÉES BRUTES'!AB$3:AB$42*1000+(40-ROW('DONNÉES BRUTES'!AB$3:AB$42)+ROW('DONNÉES BRUTES'!AB$3)),10),'DONNÉES BRUTES'!AB$3:AB$42*1000+(40-ROW('DONNÉES BRUTES'!AB$3:AB$42)+ROW('DONNÉES BRUTES'!AB$3)),0)),"—")} -> 57 | I25: {=IFERROR(INDEX('DONNÉES BRUTES'!Z$3:Z$42,MATCH(_xlfn.AGGREGATE(14,6,'DONNÉES BRUTES'!AB$3:AB$42*1000+(40-ROW('DONNÉES BRUTES'!AB$3:AB$42)+ROW('DONNÉES BRUTES'!AB$3)),10),'DONNÉES BRUTES'!AB$3:AB$42*1000+(40-ROW('DONNÉES BRUTES'!AB$3:AB$42)+ROW('DONNÉES BRUTES'!AB$3)),0)),"—")} -> 72 | J25: {=IFERROR(INDEX('DONNÉES BRUTES'!AA$3:AA$42,MATCH(_xlfn.AGGREGATE(14,6,'DONNÉES BRUTES'!AB$3:AB$42*1000+(40-ROW('DONNÉES BRUTES'!AB$3:AB$42)+ROW('DONNÉES BRUTES'!AB$3)),10),'DONNÉES BRUTES'!AB$3:AB$42*1000+(40-ROW('DONNÉES BRUTES'!AB$3:AB$42)+ROW('DONNÉES BRUTES'!AB$3)),0)),"—")} -> 21 | K25: {=IFERROR(INDEX('DONNÉES BRUTES'!N$3:N$42,MATCH(_xlfn.AGGREGATE(14,6,'DONNÉES BRUTES'!AB$3:AB$42*1000+(40-ROW('DONNÉES BRUTES'!AB$3:AB$42)+ROW('DONNÉES BRUTES'!AB$3)),10),'DONNÉES BRUTES'!AB$3:AB$42*1000+(40-ROW('DONNÉES BRUTES'!AB$3:AB$42)+ROW('DONNÉES BRUTES'!AB$3)),0)),"—")} -> 24.3% | L25: {=IFERROR(INDEX('DONNÉES BRUTES'!P$3:P$42,MATCH(_xlfn.AGGREGATE(14,6,'DONNÉES BRUTES'!AB$3:AB$42*1000+(40-ROW('DONNÉES BRUTES'!AB$3:AB$42)+ROW('DONNÉES BRUTES'!AB$3)),10),'DONNÉES BRUTES'!AB$3:AB$42*1000+(40-ROW('DONNÉES BRUTES'!AB$3:AB$42)+ROW('DONNÉES BRUTES'!AB$3)),0)),"—")} -> +1.3% | N25: {=IFERROR(INDEX('DONNÉES BRUTES'!AC$3:AC$42,MATCH(_xlfn.AGGREGATE(14,6,'DONNÉES BRUTES'!AB$3:AB$42*1000+(40-ROW('DONNÉES BRUTES'!AB$3:AB$42)+ROW('DONNÉES BRUTES'!AB$3)),10),'DONNÉES BRUTES'!AB$3:AB$42*1000+(40-ROW('DONNÉES BRUTES'!AB$3:AB$42)+ROW('DONNÉES BRUTES'!AB$3)),0)),"—")} -> — | R25: {=IFERROR(INDEX('DONNÉES BRUTES'!AD$3:AD$42,MATCH(_xlfn.AGGREGATE(14,6,'DONNÉES BRUTES'!AB$3:AB$42*1000+(40-ROW('DONNÉES BRUTES'!AB$3:AB$42)+ROW('DONNÉES BRUTES'!AB$3)),10),'DONNÉES BRUTES'!AB$3:AB$42*1000+(40-ROW('DONNÉES BRUTES'!AB$3:AB$42)+ROW('DONNÉES BRUTES'!AB$3)),0)),"—")} -> Neutre
B26: FinSight IA · Données issues de Supabase/Python · Scores calculés sur métriques Value, Growth, Quality, Momentum · Usage confidentiel

Sheet VALUE
A1: FinSight IA · Analyse VALUE · Euro Stoxx 50 | O1: Société | P1: Score Global | Q1: Signal
A2: Usage confidentiel · Calculs Python/yfinance | O2: =IF(B4<>"—",LEFT(C4,20),"—") -> SAP SE | P2: =IF(E4<>"—",VALUE(LEFT(E4,FIND("/",E4)-1)),"") -> 74
A3: Rang | B3: Ticker | C3: Société | D3: Secteur | E3: Score | F3: EV/EBITDA | G3: EV/Revenue | H3: P/E | I3: Marge Brute | J3: Marge EBITDA | K3: Altman Z | L3: FCF Yield | M3: Décote DCF estimée | O3: =IF(B5<>"—",LEFT(C5,20),"—") -> Prosus N.V. | P3: =IF(E5<>"—",VALUE(LEFT(E5,FIND("/",E5)-1)),"") -> 72
A4: 1 | B4: SAP.DE | C4: SAP SE | D4: Technologie | E4: 74/100 | F4: 13.3 | G4: 4.4 | H4: 22.7 | I4: 72.9% | J4: 32.8% | K4: 5.34 | L4: +5.2% | M4: -41.3 % | O4: =IF(B6<>"—",LEFT(C6,20),"—") -> Sanofi | P4: =IF(E6<>"—",VALUE(LEFT(E6,FIND("/",E6)-1)),"") -> 68
A5: 2 | B5: PRX.AS | C5: Prosus N.V. | D5: Conso. Cycl. | E5: 72/100 | F5: 7.4 | G5: 16 | H5: 7.3 | I5: 42.5% | J5: — | K5: 8.72 | L5: +2.0% | M5: +82.6 % | O5: =IF(B7<>"—",LEFT(C7,20),"—") -> L'Oréal S.A. | P5: =IF(E7<>"—",VALUE(LEFT(E7,FIND("/",E7)-1)),"") -> 66
A6: 3 | B6: SAN.PA | C6: Sanofi | D6: Santé | E6: 68/100 | F6: 8.6 | G6: 2.3 | H6: 12.4 | I6: 72.1% | J6: 26.7% | K6: — | L6: +7.5% | M6: +7.5 % | O6: =IF(B8<>"—",LEFT(C8,20),"—") -> Telefónica, S.A. | P6: =IF(E8<>"—",VALUE(LEFT(E8,FIND("/",E8)-1)),"") -> 60
A7: 4 | B7: OR.PA | C7: L'Oréal S.A. | D7: Conso. Déf. | E7: 66/100 | F7: 17.9 | G7: 4.4 | H7: 31.3 | I7: 74.3% | J7: 24.3% | K7: 3.38 | L7: +3.7% | M7: -57.4 % | O7: =IF(B9<>"—",LEFT(C9,20),"—") -> Hermès International | P7: =IF(E9<>"—",VALUE(LEFT(E9,FIND("/",E9)-1)),"") -> 60
A8: 5 | B8: TEF.MC | C8: Telefónica, S.A. | D8: Télécoms | E8: 60/100 | F8: 4.1 | G8: 1.2 | H8: — | I8: 69.6% | J8: 29.9% | K8: 1.01 | L8: +24.0% | M8: — | O8: =IF(B10<>"—",LEFT(C10,20),"—") -> TotalEnergies SE | P8: =IF(E10<>"—",VALUE(LEFT(E10,FIND("/",E10)-1)),"") -> 59
A9: 6 | B9: RMS.PA | C9: Hermès International Société en commandite par actions | D9: Conso. Cycl. | E9: 60/100 | F9: 22.9 | G9: 10.8 | H9: 40.7 | I9: 71.1% | J9: 46.8% | K9: 9.47 | L9: +2.9% | M9: -67.2 % | O9: =IF(B11<>"—",LEFT(C11,20),"—") -> Siemens Aktiengesell | P9: =IF(E11<>"—",VALUE(LEFT(E11,FIND("/",E11)-1)),"") -> 56
A10: 7 | B10: TTE.PA | C10: TotalEnergies SE | D10: Énergie | E10: 59/100 | F10: 6.2 | G10: 1.1 | H10: 15.9 | I10: 36.0% | J10: 18.0% | K10: — | L10: +9.5% | M10: -16.1 % | O10: =IF(B12<>"—",LEFT(C12,20),"—") -> Volkswagen AG | P10: =IF(E12<>"—",VALUE(LEFT(E12,FIND("/",E12)-1)),"") -> 56
A11: 8 | B11: SIE.DE | C11: Siemens Aktiengesellschaft | D11: Industrie | E11: 56/100 | F11: 13.4 | G11: 2.7 | H11: 18.2 | I11: 38.5% | J11: 20.1% | K11: 2.83 | L11: +6.2% | M11: -26.7 % | O11: =IF(B13<>"—",LEFT(C13,20),"—") -> Koninklijke Philips | P11: =IF(E13<>"—",VALUE(LEFT(E13,FIND("/",E13)-1)),"") -> 53
A12: 9 | B12: VOW3.DE | C12: Volkswagen AG | D12: Conso. Cycl. | E12: 56/100 | F12: 3.4 | G12: 0.5 | H12: 2.5 | I12: 15.9% | J12: 15.5% | K12: 1.61 | L12: -50.9% | M12: +433.3 % | O12: =IF(B14<>"—",LEFT(C14,20),"—") -> RWE Aktiengesellscha | P12: =IF(E14<>"—",VALUE(LEFT(E14,FIND("/",E14)-1)),"") -> 53
A13: 10 | B13: PHIA.AS | C13: Koninklijke Philips N.V. | D13: Santé | E13: 53/100 | F13: 10.4 | G13: 1.5 | H13: 25.8 | I13: 45.2% | J13: 14.6% | K13: 2.11 | L13: +2.2% | M13: -48.3 % | O13: =IF(B15<>"—",LEFT(C15,20),"—") -> Banco Santander, S.A | P13: =IF(E15<>"—",VALUE(LEFT(E15,FIND("/",E15)-1)),"") -> 48
A14: 11 | B14: RWE.DE | C14: RWE Aktiengesellschaft | D14: Serv. Publ. | E14: 53/100 | F14: 7.1 | G14: 2.8 | H14: 13.4 | I14: 32.8% | J14: 39.1% | K14: 2.35 | L14: -12.0% | M14: -0.5 % | O14: =IF(B16<>"—",LEFT(C16,20),"—") -> Schneider Electric S | P14: =IF(E16<>"—",VALUE(LEFT(E16,FIND("/",E16)-1)),"") -> 39
A15: 12 | B15: SAN.MC | C15: Banco Santander, S.A. | D15: Finance | E15: 48/100 | F15: 3.6 | G15: 4.9 | H15: 10.7 | I15: — | J15: — | K15: — | L15: -14.8% | M15: +24.6 % | O15: =IF(B17<>"—",LEFT(C17,20),"—") -> Rio Tinto Group | P15: =IF(E17<>"—",VALUE(LEFT(E17,FIND("/",E17)-1)),"") -> 38
A16: 13 | B16: SU.PA | C16: Schneider Electric S.E. | D16: Industrie | E16: 39/100 | F16: 19.1 | G16: 4 | H16: 35.1 | I16: 42.1% | J16: 20.9% | K16: — | L16: +3.1% | M16: -62.0 % | O16: =IF(B18<>"—",LEFT(C18,20),"—") -> GSK plc | P16: =IF(E18<>"—",VALUE(LEFT(E18,FIND("/",E18)-1)),"") -> 33
A17: 14 | B17: RIO.L | C17: Rio Tinto Group | D17: Matériaux | E17: 38/100 | F17: 401.8 | G17: 160.1 | H17: 925.1 | I17: 57.4% | J17: 39.9% | K17: 3.45 | L17: +0.0% | M17: -98.6 %
A18: 15 | B18: GSK.L | C18: GSK plc | D18: Santé | E18: 33/100 | F18: 837.4 | G18: 266.6 | H18: 1521.7 | I18: 72.4% | J18: 31.8% | K18: 1.4 | L18: +0.1% | M18: -99.1 %

Sheet GROWTH
A1: FinSight IA · Analyse GROWTH · Euro Stoxx 50 | O1: Société | P1: Score Gr
A2: Usage confidentiel · Calculs Python/yfinance | O2: =IF(B4<>"—",LEFT(C4,18),"—") -> ASML Holding N.V. | P2: =IF(E4<>"—",VALUE(LEFT(E4,FIND("/",E4)-1)),"") -> 92
A3: Rang | B3: Ticker | C3: Société | D3: Secteur | E3: Score | F3: Croissance Rev. YoY | G3: Marge EBITDA | H3: Marge Nette | I3: ROE | J3: Croissance EPS | K3: Révisions Analystes | L3: Signal | O3: =IF(B5<>"—",LEFT(C5,18),"—") -> AstraZeneca PLC | P3: =IF(E5<>"—",VALUE(LEFT(E5,FIND("/",E5)-1)),"") -> 87
A4: 1 | B4: ASML.AS | C4: ASML Holding N.V. | D4: Technologie | E4: 92/100 | F4: +15.6% | G4: 38.4% | H4: 29.4% | I4: +49.0% | J4: +26.9% | K4: — | L4: Surpondérer | O4: =IF(B6<>"—",LEFT(C6,18),"—") -> Hermès Internation | P4: =IF(E6<>"—",VALUE(LEFT(E6,FIND("/",E6)-1)),"") -> 81
A5: 2 | B5: AZN.L | C5: AstraZeneca PLC | D5: Santé | E5: 87/100 | F5: +8.6% | G5: 33.2% | H5: 17.4% | I5: +21.0% | J5: +53.9% | K5: — | L5: Surpondérer | O5: =IF(B7<>"—",LEFT(C7,18),"—") -> GSK plc | P5: =IF(E7<>"—",VALUE(LEFT(E7,FIND("/",E7)-1)),"") -> 78
