Workbook

Sheet DASHBOARD
B1: FinSight IA · Analyse Comparative | Y1: Pilier | Z1: =C10 -> Microsoft | AA1: =D10 -> Alphabet
B2: CONFIDENTIEL · Usage interne exclusif · FinSight IA · 4 avril 2026 | Y2: =B38 -> Valorisation | Z2: =C38 -> 34 | AA2: =D38 -> 100
Y3: =B39 -> Qualité financière | Z3: =C39 -> 89 | AA3: =D39 -> 78
B4: SYNTHÈSE — INDICATEURS CLÉS | Y4: =B40 -> Profitabilité | Z4: =C40 -> 77 | AA4: =D40 -> 51
B5: COURS ACTUEL vs DCF | C5: PIOTROSKI F-SCORE | D5: MARGE EBITDA | E5: SCORE FINSIGHT COMPOSITE | Y5: =B41 -> Croissance | Z5: =C41 -> 60 | AA5: =D41 -> 60
B6: =IFERROR(C15,"—") -> 0.157 | C6: =IFERROR(C22,"—") -> 8 | D6: =IFERROR(C29,"—") -> 0.458 | E6: =IFERROR(DATA_RAW!C47,"—") -> 82 | Y6: =B42 -> Risque & Momentum | Z6: =C42 -> 80 | AA6: =D42 -> 55
B7: Société A | C7: Société A | D7: Société A | E7: Société A
B8: =IFERROR(D15,"—") -> 0.158 | C8: =IFERROR(D22,"—") -> 7 | D8: =IFERROR(D29,"—") -> 0.321 | E8: =IFERROR(DATA_RAW!E47,"—") -> 74 | Y8: Scénario | Z8: =C10 -> Microsoft | AA8: =D10 -> Alphabet
B9: Société B | C9: Société B | D9: Société B | E9: Société B | Y9: ="Bear" -> Bear | Z9: =DATA_RAW!C13 -> 310 | AA9: =DATA_RAW!E13 -> 130
B10: MÉTRIQUE | C10: =DATA_RAW!C4 -> Microsoft | D10: =DATA_RAW!E5 -> Alphabet | E10: DELTA / AVANTAGE | Y10: ="Base" -> Base | Z10: =DATA_RAW!C11 -> 415.2 | AA10: =DATA_RAW!E11 -> 168.5
Y11: ="Bull" -> Bull | Z11: =DATA_RAW!C14 -> 610 | AA11: =DATA_RAW!E14 -> 255
B12: VALORISATION | Y12: ="Cours actuel" -> Cours actuel | Z12: =DATA_RAW!C10 -> 46116 | AA12: =DATA_RAW!E10 -> 46116
B13: Cours actuel | C13: =DATA_RAW!C11 -> 415.2 | D13: =DATA_RAW!E11 -> 168.5 | E13: =IF(C13=0,"—",IF(C13=D13,"Égal",IF(C13>D13,"▲ "&C10,"▲ "&D10))) -> ▲ Microsoft
B14: DCF Valeur intrinsèque (base) | C14: =DATA_RAW!C12 -> 480 | D14: =DATA_RAW!E12 -> 195 | E14: =IF(C14=0,"—",IF(C14=D14,"Égal",IF(C14>D14,"▲ "&C10,"▲ "&D10))) -> ▲ Microsoft
B15: Upside / Downside DCF | C15: =DATA_RAW!C15 -> 0.157 | D15: =DATA_RAW!E15 -> 0.158 | E15: =IF(C15=0,"—",IF(C15=D15,"Égal",IF(C15>D15,"▲ "&C10,"▲ "&D10))) -> ▲ Alphabet | Y15: Multiple | Z15: =C10 -> Microsoft | AA15: =D10 -> Alphabet
B16: Marge de sécurité | C16: =DATA_RAW!C16 -> 0.134 | D16: =DATA_RAW!E16 -> 0.157 | E16: =IF(C16=0,"—",IF(C16=D16,"Égal",IF(C16>D16,"▲ "&C10,"▲ "&D10))) -> ▲ Alphabet | Y16: ="PE Ratio" -> PE Ratio | Z16: =DATA_RAW!C16 -> 0.134 | AA16: =DATA_RAW!E16 -> 0.157
B17: PE (LTM) | C17: =DATA_RAW!C17 -> 33.4 | D17: =DATA_RAW!E17 -> 21.8 | E17: =IF(C17=0,"—",IF(C17=D17,"Égal",IF(C17<D17,"▲ "&C10,"▲ "&D10))) -> ▲ Alphabet | Y17: ="EV/EBITDA" -> EV/EBITDA | Z17: =DATA_RAW!C17 -> 33.4 | AA17: =DATA_RAW!E17 -> 21.8
B18: EV/EBITDA | C18: =DATA_RAW!C18 -> 22.1 | D18: =DATA_RAW!E18 -> 14.3 | E18: =IF(C18=0,"—",IF(C18=D18,"Égal",IF(C18<D18,"▲ "&C10,"▲ "&D10))) -> ▲ Alphabet | Y18: ="Price/Book" -> Price/Book | Z18: =DATA_RAW!C18 -> 22.1 | AA18: =DATA_RAW!E18 -> 14.3
B19: Current Ratio | C19: =DATA_RAW!C53 -> 2.41 | D19: =DATA_RAW!E53 -> 2.87 | E19: =IF(C19=0,"—",IF(C19=D19,"Égal",IF(C19>D19,"▲ "&C10,"▲ "&D10))) -> ▲ Alphabet
B20: Médiane PE Secteur | C20: =DATA_RAW!C59 -> 30.15 | D20: =DATA_RAW!C59 -> 30.15 | E20: =IF(C17=0,"—",IF(DATA_RAW!C59=0,"—",IF(C17<DATA_RAW!C59,"✓ "&C11,IF(D17<DATA_RAW!C59,"✓ "&D11,"Surévalués")))) -> ✓
B21: QUALITÉ FINANCIÈRE | Y21: ="FCF Yield %" -> FCF Yield % | Z21: =DATA_RAW!C19*100 -> 1210 | AA21: =DATA_RAW!E19*100 -> 680
B22: Piotroski F-Score | C22: =DATA_RAW!C28 -> 8 | D22: =DATA_RAW!E28 -> 7 | E22: =IF(C22=0,"—",IF(C22=D22,"Égal",IF(C22>D22,"▲ "&C10,"▲ "&D10))) -> ▲ Microsoft | Y22: ="PEG Ratio" -> PEG Ratio | Z22: =DATA_RAW!C20 -> 0.022 | AA22: =DATA_RAW!E20 -> 0.031
B23: Sloan Accruals Ratio | C23: =DATA_RAW!C29 -> -0.021 | D23: =DATA_RAW!E29 -> -0.008 | E23: =IF(C23=0,"—",IF(C23=D23,"Égal",IF(C23<D23,"▲ "&C10,"▲ "&D10))) -> ▲ Microsoft
B24: Cash Conversion Score | C24: =DATA_RAW!C30 -> 1.18 | D24: =DATA_RAW!E30 -> 1.42 | E24: =IF(C24=0,"—",IF(C24=D24,"Égal",IF(C24>D24,"▲ "&C10,"▲ "&D10))) -> ▲ Alphabet | Y24: Période | Z24: =C10 -> Microsoft | AA24: =D10 -> Alphabet
B25: Beneish M-Score | C25: =DATA_RAW!C31 -> -2.31 | D25: =DATA_RAW!E31 -> -2.85 | E25: =IF(C25=0,"—",IF(C25=D25,"Égal",IF(C25<D25,"▲ "&C10,"▲ "&D10))) -> ▲ Alphabet | Y25: ="N-2" -> N-2 | Z25: =DATA_RAW!C36*100 -> 45.8 | AA25: =DATA_RAW!E36*100 -> 32.1
B26: Altman Z-Score | C26: =DATA_RAW!C32 -> 4.12 | D26: =DATA_RAW!E32 -> 5.67 | E26: =IF(C26=0,"—",IF(C26=D26,"Égal",IF(C26>D26,"▲ "&C10,"▲ "&D10))) -> ▲ Alphabet | Y26: ="N-1" -> N-1 | Z26: =DATA_RAW!C35*100 -> 34.1 | AA26: =DATA_RAW!E35*100 -> 15.2
B27: PROFITABILITÉ & CROISSANCE | Y27: ="LTM" -> LTM | Z27: =DATA_RAW!C34*100 -> 31.2 | AA27: =DATA_RAW!E34*100 -> 18.7
B28: ROIC | C28: =DATA_RAW!C34 -> 0.312 | D28: =DATA_RAW!E34 -> 0.187 | E28: =IF(C28=0,"—",IF(C28=D28,"Égal",IF(C28>D28,"▲ "&C10,"▲ "&D10))) -> ▲ Microsoft | Y28: Métrique | Z28: =C10 -> Microsoft | AA28: =D10 -> Alphabet
B29: Marge EBITDA (LTM) | C29: =DATA_RAW!C36 -> 0.458 | D29: =DATA_RAW!E36 -> 0.321 | E29: =IF(C29=0,"—",IF(C29=D29,"Égal",IF(C29>D29,"▲ "&C10,"▲ "&D10))) -> ▲ Microsoft | Y29: FinSight (/100) | Z29: =IFERROR(DATA_RAW!C47,0) -> 82 | AA29: =IFERROR(DATA_RAW!E47,0) -> 74
B30: Tendance marges 3 ans | C30: =DATA_RAW!C39 -> Croissante | D30: =DATA_RAW!E39 -> Stable | E30: =IF(C30=D30,"Égal",IF(C30>D30,"▲ "&C11,"▲ "&D11)) -> ▲ | Y30: Momentum (/10) | Z30: =IFERROR(DATA_RAW!C48*10,0) -> 72 | AA30: =IFERROR(DATA_RAW!E48*10,0) -> 61
B31: Croissance CA (CAGR 3Y) | C31: =DATA_RAW!C40 -> 0.142 | D31: =DATA_RAW!E40 -> 0.118 | E31: =IF(C31=0,"—",IF(C31=D31,"Égal",IF(C31>D31,"▲ "&C10,"▲ "&D10))) -> ▲ Microsoft | Y31: Piotroski (/9) | Z31: =IFERROR(DATA_RAW!C28/9*100,0) -> 88.888889 | AA31: =IFERROR(DATA_RAW!E28/9*100,0) -> 77.777778
B32: Dette Nette / EBITDA | C32: =DATA_RAW!C42 -> -0.8 | D32: =DATA_RAW!E42 -> 0.4 | E32: =IF(C32=0,"—",IF(C32=D32,"Égal",IF(C32<D32,"▲ "&C10,"▲ "&D10))) -> ▲ Microsoft | Y32: Conviction (%) | Z32: =IFERROR(DATA_RAW!C50*100,0) -> 78 | AA32: =IFERROR(DATA_RAW!E50*100,0) -> 65
B33: Performance 1 mois | C33: =DATA_RAW!C56 -> 0.031 | D33: =DATA_RAW!E56 -> -0.018 | E33: =IF(C33=0,"—",IF(C33=D33,"Égal",IF(C33>D33,"▲ "&C10,"▲ "&D10))) -> ▲ Microsoft
Y34: ="Piotroski (/9)" -> Piotroski (/9) | Z34: =DATA_RAW!C27 -> 620 | AA34: =DATA_RAW!E27 -> 256
B35: SCORECARD — ANALYSE COMPARATIVE PAR PILIER | Y35: ="Conviction %" -> Conviction % | Z35: =DATA_RAW!C51*100 -> #VALUE! | AA35: =DATA_RAW!E51*100 -> #VALUE! | AB35: Société B
B36: PILIER | C36: SOCIÉTÉ A | D36: SOCIÉTÉ B | E36: AVANTAGE | Z36: Valorisation | AA36: =IF(V38="—",0,V38) -> 0 | AB36: =IF(W38="—",0,W38) -> 0
C37: =IFERROR(C10,"—") -> Microsoft | D37: =IFERROR(D10,"—") -> Alphabet | Z37: Qualité fin. | AA37: =IF(V39="—",0,V39) -> 0 | AB37: =IF(W39="—",0,W39) -> 0
B38: Valorisation | C38: =IFERROR(ROUND((IF(C15>0,34,0)+IF(C17<DATA_RAW!C59,33,0)+IF(C18<DATA_RAW!C60,33,0)),0),"—") -> 34 | D38: =IFERROR(ROUND((IF(D15>0,34,0)+IF(D17<DATA_RAW!C59,33,0)+IF(D18<DATA_RAW!C60,33,0)),0),"—") -> 100 | E38: =IF(C38="—","—",IF(C38=D38,"Égal",IF(C38>D38,"▲ "&C10,"▲ "&D10))) -> ▲ Alphabet | Z38: Profitabilité | AA38: =IF(V40="—",0,V40) -> 0 | AB38: =IF(W40="—",0,W40) -> 0
B39: Qualité financière | C39: =IFERROR(ROUND(C22/9*100,0),"—") -> 89 | D39: =IFERROR(ROUND(D22/9*100,0),"—") -> 78 | E39: =IF(C39="—","—",IF(C39=D39,"Égal",IF(C39>D39,"▲ "&C10,"▲ "&D10))) -> ▲ Microsoft | Z39: Croissance | AA39: =IF(V41="—",0,V41) -> 0 | AB39: =IF(W41="—",0,W41) -> 0
B40: Profitabilité | C40: =IFERROR(ROUND(C28*100+C29*100,0),"—") -> 77 | D40: =IFERROR(ROUND(D28*100+D29*100,0),"—") -> 51 | E40: =IF(C40="—","—",IF(C40=D40,"Égal",IF(C40>D40,"▲ "&C10,"▲ "&D10))) -> ▲ Microsoft | Z40: Risque/Mom. | AA40: =IF(V42="—",0,V42) -> 0 | AB40: =IF(W42="—",0,W42) -> 0
...

Sheet DATA_RAW
A1: METRIC | B1: TICKER_A | C1: VALUE_A | D1: TICKER_B | E1: VALUE_B | F1: UNIT | G1: SOURCE
A2: company_name_a | B2: TICKER_A | C2: MSFT | D2: TICKER_B | E2: GOOGL | F2: text | G2: yfinance
A3: company_name_b | B3: TICKER_A | C3: MSFT | D3: TICKER_B | E3: GOOGL | F3: text | G3: yfinance
A4: ticker_a | C4: Microsoft | E4: GOOGL | F4: text | G4: input
A5: ticker_b | C5: MSFT | E5: Alphabet | F5: text | G5: input
A6: sector_a | C6: Technology | E6: Technology | F6: text | G6: yfinance
A7: sector_b | C7: Technology | E7: Technology | F7: text | G7: yfinance
A8: currency_a | C8: USD | E8: USD | F8: text | G8: yfinance
A9: currency_b | C9: USD | E9: USD | F9: text | G9: yfinance
A10: analysis_date | C10: 46116 | E10: 46116 | F10: date | G10: system
A11: share_price | C11: 415.2 | E11: 168.5 | F11: USD | G11: yfinance
A12: dcf_base | C12: 480 | E12: 195 | F12: USD | G12: agent_quant
A13: dcf_bear | C13: 310 | E13: 130 | F13: USD | G13: agent_quant
A14: dcf_bull | C14: 610 | E14: 255 | F14: USD | G14: agent_quant
A15: dcf_upside_base | C15: 0.157 | E15: 0.158 | F15: % | G15: calc
A16: margin_of_safety | C16: 0.134 | E16: 0.157 | F16: % | G16: calc
A17: pe_ratio | C17: 33.4 | E17: 21.8 | F17: x | G17: yfinance
A18: ev_ebitda | C18: 22.1 | E18: 14.3 | F18: x | G18: yfinance
A19: price_to_book | C19: 12.1 | E19: 6.8 | F19: x | G19: yfinance
A20: fcf_yield | C20: 0.022 | E20: 0.031 | F20: % | G20: calc
A21: peg_ratio | C21: 2.31 | E21: 1.52 | F21: x | G21: calc
... A32: altman_z | C32: 4.12 | E32: 5.67 | F32: score | G32: agent_quant
A33: altman_model | C33: Public (>3) | E33: Public (>3) | F33: text | G33: agent_quant
A34: roic | C34: 0.312 | E34: 0.187 | F34: % | G34: agent_quant
A35: roe | C35: 0.341 | E35: 0.152 | F35: % | G35: yfinance
A36: ebitda_margin_ltm | C36: 0.458 | E36: 0.321 | F36: % | G36: agent_quant
A37: ebitda_margin_y1 | C37: 0.431 | E37: 0.298 | F37: % | G37: agent_quant
A38: ebitda_margin_y2 | C38: 0.412 | E38: 0.281 | F38: % | G38: agent_quant
A39: ebitda_margin_trend | C39: Croissante | E39: Stable | F39: text | G39: calc
A40: revenue_cagr_3y | C40: 0.142 | E40: 0.118 | F40: % | G40: agent_quant
A41: eps_growth | C41: 0.187 | E41: 0.143 | F41: % | G41: yfinance
A42: net_debt_ebitda | C42: -0.8 | E42: 0.4 | F42: x | G42: agent_quant
A43: interest_coverage | C43: 28.4 | E43: 19.7 | F43: x | G43: agent_quant
A44: beta | C44: 0.89 | E44: 1.04 | F44: x | G44: yfinance
A45: var_95_1m | C45: -0.068 | E45: -0.091 | F45: % | G45: agent_quant
A46: duration_implicit | C46: 12.3 | E46: 9.8 | F46: years | G46: agent_quant
A47: finsight_score | C47: 82 | E47: 74 | F47: /100 | G47: agent_synthese
A48: momentum_score | C48: 7.2 | E48: 6.1 | F48: /10 | G48: agent_quant
A49: recommendation | C49: ACHETER | E49: ACCUMULER | F49: text | G49: agent_synthese
A50: conviction | C50: 0.78 | E50: 0.65 | F50: % | G50: agent_synthese
...

Sheet SENSIBILITE
B1: ANALYSE DE SENSIBILITÉ DCF — FinSight IA
B2: CONFIDENTIEL · Usage interne exclusif · FinSight IA · 4 avril 2026
B4: SENSIBILITÉ DCF — SOC. A · Valeur intrinsèque (Base) | I4: Scénario | J4: =VALORISATION!C3 -> Microsoft | K4: =VALORISATION!D3 -> Alphabet
B5: WACC ↓ / g → | C5: 0.015 | D5: 0.02 | E5: 0.025 | F5: 0.03 | G5: 0.035 | I5: Bear | J5: =DATA_RAW!C13 -> 310 | K5: =DATA_RAW!E13 -> 130
B6: 0.07 | C6: =IFERROR(ROUND(DATA_RAW!C12*(1+(DATA_RAW!C22-0.07)*1.5+(0.015-DATA_RAW!C23)*0.8),0),"—") -> 488 | D6: =IFERROR(ROUND(DATA_RAW!C12*(1+(DATA_RAW!C22-0.07)*1.5+(0.02-DATA_RAW!C23)*0.8),0),"—") -> 490 | E6: =IFERROR(ROUND(DATA_RAW!C12*(1+(DATA_RAW!C22-0.07)*1.5+(0.025-DATA_RAW!C23)*0.8),0),"—") -> 492 | F6: =IFERROR(ROUND(DATA_RAW!C12*(1+(DATA_RAW!C22-0.07)*1.5+(0.03-DATA_RAW!C23)*0.8),0),"—") -> 494 | G6: =IFERROR(ROUND(DATA_RAW!C12*(1+(DATA_RAW!C22-0.07)*1.5+(0.035-DATA_RAW!C23)*0.8),0),"—") -> 496 | I6: Base | J6: =DATA_RAW!C12 -> 480 | K6: =DATA_RAW!E12 -> 195
B7: 0.08 | C7: =IFERROR(ROUND(DATA_RAW!C12*(1+(DATA_RAW!C22-0.08)*1.5+(0.015-DATA_RAW!C23)*0.8),0),"—") -> 481 | D7: =IFERROR(ROUND(DATA_RAW!C12*(1+(DATA_RAW!C22-0.08)*1.5+(0.02-DATA_RAW!C23)*0.8),0),"—") -> 483 | E7: =IFERROR(ROUND(DATA_RAW!C12*(1+(DATA_RAW!C22-0.08)*1.5+(0.025-DATA_RAW!C23)*0.8),0),"—") -> 485 | F7: =IFERROR(ROUND(DATA_RAW!C12*(1+(DATA_RAW!C22-0.08)*1.5+(0.03-DATA_RAW!C23)*0.8),0),"—") -> 486 | G7: =IFERROR(ROUND(DATA_RAW!C12*(1+(DATA_RAW!C22-0.08)*1.5+(0.035-DATA_RAW!C23)*0.8),0),"—") -> 488 | I7: Bull | J7: =DATA_RAW!C14 -> 610 | K7: =DATA_RAW!E14 -> 255
B8: 0.09 | C8: =IFERROR(ROUND(DATA_RAW!C12*(1+(DATA_RAW!C22-0.09)*1.5+(0.015-DATA_RAW!C23)*0.8),0),"—") -> 474 | D8: =IFERROR(ROUND(DATA_RAW!C12*(1+(DATA_RAW!C22-0.09)*1.5+(0.02-DATA_RAW!C23)*0.8),0),"—") -> 475 | E8: =IFERROR(ROUND(DATA_RAW!C12*(1+(DATA_RAW!C22-0.09)*1.5+(0.025-DATA_RAW!C23)*0.8),0),"—") -> 477 | F8: =IFERROR(ROUND(DATA_RAW!C12*(1+(DATA_RAW!C22-0.09)*1.5+(0.03-DATA_RAW!C23)*0.8),0),"—") -> 479 | G8: =IFERROR(ROUND(DATA_RAW!C12*(1+(DATA_RAW!C22-0.09)*1.5+(0.035-DATA_RAW!C23)*0.8),0),"—") -> 481 | I8: Cours actuel | J8: =DATA_RAW!C11 -> 415.2 | K8: =DATA_RAW!E11 -> 168.5
B9: 0.1 | C9: =IFERROR(ROUND(DATA_RAW!C12*(1+(DATA_RAW!C22-0.1)*1.5+(0.015-DATA_RAW!C23)*0.8),0),"—") -> 466 | D9: =IFERROR(ROUND(DATA_RAW!C12*(1+(DATA_RAW!C22-0.1)*1.5+(0.02-DATA_RAW!C23)*0.8),0),"—") -> 468 | E9: =IFERROR(ROUND(DATA_RAW!C12*(1+(DATA_RAW!C22-0.1)*1.5+(0.025-DATA_RAW!C23)*0.8),0),"—") -> 470 | F9: =IFERROR(ROUND(DATA_RAW!C12*(1+(DATA_RAW!C22-0.1)*1.5+(0.03-DATA_RAW!C23)*0.8),0),"—") -> 472 | G9: =IFERROR(ROUND(DATA_RAW!C12*(1+(DATA_RAW!C22-0.1)*1.5+(0.035-DATA_RAW!C23)*0.8),0),"—") -> 474
B10: 0.11 | C10: =IFERROR(ROUND(DATA_RAW!C12*(1+(DATA_RAW!C22-0.11)*1.5+(0.015-DATA_RAW!C23)*0.8),0),"—") -> 459 | D10: =IFERROR(ROUND(DATA_RAW!C12*(1+(DATA_RAW!C22-0.11)*1.5+(0.02-DATA_RAW!C23)*0.8),0),"—") -> 461 | E10: =IFERROR(ROUND(DATA_RAW!C12*(1+(DATA_RAW!C22-0.11)*1.5+(0.025-DATA_RAW!C23)*0.8),0),"—") -> 463 | F10: =IFERROR(ROUND(DATA_RAW!C12*(1+(DATA_RAW!C22-0.11)*1.5+(0.03-DATA_RAW!C23)*0.8),0),"—") -> 465 | G10: =IFERROR(ROUND(DATA_RAW!C12*(1+(DATA_RAW!C22-0.11)*1.5+(0.035-DATA_RAW!C23)*0.8),0),"—") -> 467
B11: ★ Case de base (WACC ≈ 9% / g ≈ 3%) en jaune · Valeurs en USD · Sensibilité : ×1.5 WACC, ×0.8 g terminal
B13: SENSIBILITÉ DCF — SOC. B · Valeur intrinsèque (Base)
B14: WACC ↓ / g → | C14: 0.015 | D14: 0.02 | E14: 0.025 | F14: 0.03 | G14: 0.035
B15: 0.07 | C15: =IFERROR(ROUND(DATA_RAW!E12*(1+(DATA_RAW!E22-0.07)*1.5+(0.015-DATA_RAW!E23)*0.8),0),"—") -> 200 | D15: =IFERROR(ROUND(DATA_RAW!E12*(1+(DATA_RAW!E22-0.07)*1.5+(0.02-DATA_RAW!E23)*0.8),0),"—") -> 201 | E15: =IFERROR(ROUND(DATA_RAW!E12*(1+(DATA_RAW!E22-0.07)*1.5+(0.025-DATA_RAW!E23)*0.8),0),"—") -> 202 | F15: =IFERROR(ROUND(DATA_RAW!E12*(1+(DATA_RAW!E22-0.07)*1.5+(0.03-DATA_RAW!E23)*0.8),0),"—") -> 203 | G15: =IFERROR(ROUND(DATA_RAW!E12*(1+(DATA_RAW!E22-0.07)*1.5+(0.035-DATA_RAW!E23)*0.8),0),"—") -> 204
B16: 0.08 | C16: =IFERROR(ROUND(DATA_RAW!E12*(1+(DATA_RAW!E22-0.08)*1.5+(0.015-DATA_RAW!E23)*0.8),0),"—") -> 198 | D16: =IFERROR(ROUND(DATA_RAW!E12*(1+(DATA_RAW!E22-0.08)*1.5+(0.02-DATA_RAW!E23)*0.8),0),"—") -> 198 | E16: =IFERROR(ROUND(DATA_RAW!E12*(1+(DATA_RAW!E22-0.08)*1.5+(0.025-DATA_RAW!E23)*0.8),0),"—") -> 199 | F16: =IFERROR(ROUND(DATA_RAW!E12*(1+(DATA_RAW!E22-0.08)*1.5+(0.03-DATA_RAW!E23)*0.8),0),"—") -> 200 | G16: =IFERROR(ROUND(DATA_RAW!E12*(1+(DATA_RAW!E22-0.08)*1.5+(0.035-DATA_RAW!E23)*0.8),0),"—") -> 201
B17: 0.09 | C17: =IFERROR(ROUND(DATA_RAW!E12*(1+(DATA_RAW!E22-0.09)*1.5+(0.015-DATA_RAW!E23)*0.8),0),"—") -> 195 | D17: =IFERROR(ROUND(DATA_RAW!E12*(1+(DATA_RAW!E22-0.09)*1.5+(0.02-DATA_RAW!E23)*0.8),0),"—") -> 195 | E17: =IFERROR(ROUND(DATA_RAW!E12*(1+(DATA_RAW!E22-0.09)*1.5+(0.025-DATA_RAW!E23)*0.8),0),"—") -> 196 | F17: =IFERROR(ROUND(DATA_RAW!E12*(1+(DATA_RAW!E22-0.09)*1.5+(0.03-DATA_RAW!E23)*0.8),0),"—") -> 197 | G17: =IFERROR(ROUND(DATA_RAW!E12*(1+(DATA_RAW!E22-0.09)*1.5+(0.035-DATA_RAW!E23)*0.8),0),"—") -> 198
B18: 0.1 | C18: =IFERROR(ROUND(DATA_RAW!E12*(1+(DATA_RAW!E22-0.1)*1.5+(0.015-DATA_RAW!E23)*0.8),0),"—") -> 192 | D18: =IFERROR(ROUND(DATA_RAW!E12*(1+(DATA_RAW!E22-0.1)*1.5+(0.02-DATA_RAW!E23)*0.8),0),"—") -> 192 | E18: =IFERROR(ROUND(DATA_RAW!E12*(1+(DATA_RAW!E22-0.1)*1.5+(0.025-DATA_RAW!E23)*0.8),0),"—") -> 193 | F18: =IFERROR(ROUND(DATA_RAW!E12*(1+(DATA_RAW!E22-0.1)*1.5+(0.03-DATA_RAW!E23)*0.8),0),"—") -> 194 | G18: =IFERROR(ROUND(DATA_RAW!E12*(1+(DATA_RAW!E22-0.1)*1.5+(0.035-DATA_RAW!E23)*0.8),0),"—") -> 195
B19: 0.11 | C19: =IFERROR(ROUND(DATA_RAW!E12*(1+(DATA_RAW!E22-0.11)*1.5+(0.015-DATA_RAW!E23)*0.8),0),"—") -> 189 | D19: =IFERROR(ROUND(DATA_RAW!E12*(1+(DATA_RAW!E22-0.11)*1.5+(0.02-DATA_RAW!E23)*0.8),0),"—") -> 190 | E19: =IFERROR(ROUND(DATA_RAW!E12*(1+(DATA_RAW!E22-0.11)*1.5+(0.025-DATA_RAW!E23)*0.8),0),"—") -> 190 | F19: =IFERROR(ROUND(DATA_RAW!E12*(1+(DATA_RAW!E22-0.11)*1.5+(0.03-DATA_RAW!E23)*0.8),0),"—") -> 191 | G19: =IFERROR(ROUND(DATA_RAW!E12*(1+(DATA_RAW!E22-0.11)*1.5+(0.035-DATA_RAW!E23)*0.8),0),"—") -> 192
B20: ★ Case de base (WACC ≈ 9% / g ≈ 3%) en jaune · Valeurs en USD · Sensibilité : ×1.5 WACC, ×0.8 g terminal

Sheet VALORISATION
B1: VALORISATION COMPARÉE — FinSight IA | N1: =C3 -> Microsoft | O1: =D3 -> Alphabet | R1: =C3 -> Microsoft | S1: =D3 -> Alphabet
B2: CONFIDENTIEL · Usage interne exclusif · FinSight IA · 4 avril 2026 | M2: PE (LTM) | N2: =DATA_RAW!C17 -> 33.4 | O2: =DATA_RAW!E17 -> 21.8 | Q2: FCF Yield (%) | R2: =DATA_RAW!C20*100 -> 2.2 | S2: =DATA_RAW!E20*100 -> 3.1
B3: MÉTRIQUE | C3: =DATA_RAW!C4 -> Microsoft | D3: =DATA_RAW!E5 -> Alphabet | E3: AVANTAGE RELATIF | M3: EV/EBITDA | N3: =DATA_RAW!C18 -> 22.1 | O3: =DATA_RAW!E18 -> 14.3 | Q3: PEG Ratio | R3: =DATA_RAW!C21 -> 2.31 | S3: =DATA_RAW!E21 -> 1.52 | Z3: Scénario | AA3: =IF(DATA_RAW!R4="","Soc. A",DATA_RAW!R4) -> Soc. A | AB3: =IF(DATA_RAW!T5="","Soc. B",DATA_RAW!T5) -> Soc. B
M4: P/Book | N4: =DATA_RAW!C19 -> 12.1 | O4: =DATA_RAW!E19 -> 6.8 | Z4: Bear | AA4: =DATA_RAW!R13 -> 0 | AB4: =DATA_RAW!T13 -> 0
B5: DISCOUNTED CASH FLOW — ANALYSE INTRINSÈQUE | Z5: Base | AA5: =DATA_RAW!R12 -> 0 | AB5: =DATA_RAW!T12 -> 0
B6: Cours actuel | C6: =DATA_RAW!C11 -> 415.2 | D6: =DATA_RAW!E11 -> 168.5 | E6: =IF(C6=0,"—",IF(C6=D6,"Égal",IF(C6>D6,"▲ "&C3,"▲ "&D3))) -> ▲ Microsoft | Z6: Bull | AA6: =DATA_RAW!R14 -> 0 | AB6: =DATA_RAW!T14 -> 0
B7: DCF — Scénario Bear | C7: =DATA_RAW!C13 -> 310 | D7: =DATA_RAW!E13 -> 130 | E7: =IF(C7=0,"—",IF(C7=D7,"Égal",IF(C7>D7,"▲ "&C3,"▲ "&D3))) -> ▲ Microsoft | Z7: Cours actuel | AA7: =DATA_RAW!R11 -> 0 | AB7: =DATA_RAW!T11 -> 0
B8: DCF — Scénario Base | C8: =DATA_RAW!C12 -> 480 | D8: =DATA_RAW!E12 -> 195 | E8: =IF(C8=0,"—",IF(C8=D8,"Égal",IF(C8>D8,"▲ "&C3,"▲ "&D3))) -> ▲ Microsoft
B9: DCF — Scénario Bull | C9: =DATA_RAW!C14 -> 610 | D9: =DATA_RAW!E14 -> 255 | E9: =IF(C9=0,"—",IF(C9=D9,"Égal",IF(C9>D9,"▲ "&C3,"▲ "&D3))) -> ▲ Microsoft
B10: Upside/Downside Base | C10: =DATA_RAW!C15 -> 0.157 | D10: =DATA_RAW!E15 -> 0.158 | E10: =IF(C10=0,"—",IF(C10=D10,"Égal",IF(C10>D10,"▲ "&C3,"▲ "&D3))) -> ▲ Alphabet
B11: Marge de sécurité (Base) | C11: =DATA_RAW!C16 -> 0.134 | D11: =DATA_RAW!E16 -> 0.157 | E11: =IF(C11=0,"—",IF(C11=D11,"Égal",IF(C11>D11,"▲ "&C3,"▲ "&D3))) -> ▲ Alphabet
B12: WACC utilisé | C12: =DATA_RAW!C22 -> 0.089 | D12: =DATA_RAW!E22 -> 0.094 | E12: =IF(C12=0,"—",IF(C12=D12,"Égal",IF(C12<D12,"▲ "&C3,"▲ "&D3))) -> ▲ Microsoft
B13: Taux croissance terminal | C13: =DATA_RAW!C23 -> 0.03 | D13: =DATA_RAW!E23 -> 0.025 | E13: =IF(C13=0,"—",IF(C13=D13,"Égal",IF(C13>D13,"▲ "&C3,"▲ "&D3))) -> ▲ Microsoft
B14: TAILLE & CONTEXTE DE MARCHÉ
B15: Market Cap ($bn) | C15: =DATA_RAW!C63 -> 3085 | D15: =DATA_RAW!E63 -> 2085 | E15: =IF(C15=0,"—",IF(C15=D15,"Égal",IF(C15>D15,"▲ "&C3,"▲ "&D3))) -> ▲ Microsoft
B16: Enterprise Value ($bn) | C16: =DATA_RAW!C64 -> 3012 | D16: =DATA_RAW!E64 -> 1940 | E16: =IF(C16=0,"—",IF(C16=D16,"Égal",IF(C16>D16,"▲ "&C3,"▲ "&D3))) -> ▲ Microsoft
B17: 52 semaines — Haut | C17: =DATA_RAW!C61 -> 468.35 | D17: =DATA_RAW!E61 -> 208.7 | E17: =IF(C6=0,"—",IF(C6/C17>D6/D17,"▲ "&C3&" plus proche du haut","▲ "&D3&" plus proche du haut")) -> ▲ Microsoft plus proche du haut
B18: 52 semaines — Bas | C18: =DATA_RAW!C62 -> 309.45 | D18: =DATA_RAW!E62 -> 140.53 | E18: =IF(C6=0,"—",IF((C6-C18)/(C17-C18)>(D6-D18)/(D17-D18),"▲ "&C3&" plus haut","▲ "&D3&" plus haut")) -> ▲ Microsoft plus haut
B19: Position dans range 52W (%) | C19: =IFERROR((C6-C18)/(C17-C18),"—") -> 0.6655129 | D19: =IFERROR((D6-D18)/(D17-D18),"—") -> 0.41029778 | E19: =IF(ISNUMBER(C19),IF(C19>D19,"▲ "&C3,"▲ "&D3),"—") -> ▲ Microsoft
B21: MONTE CARLO — 10 000 SIMULATIONS (INTERVALLES DE CONFIANCE)
B22: Percentile 10 (Pessimiste) | C22: =DATA_RAW!C25 -> 340 | D22: =DATA_RAW!E25 -> 138 | E22: =IF(C22=0,"—",IF(C22=D22,"Égal",IF(C22>D22,"▲ "&C3,"▲ "&D3))) -> ▲ Microsoft
B23: Percentile 50 (Médiane) | C23: =DATA_RAW!C26 -> 478 | D23: =DATA_RAW!E26 -> 193 | E23: =IF(C23=0,"—",IF(C23=D23,"Égal",IF(C23>D23,"▲ "&C3,"▲ "&D3))) -> ▲ Microsoft
B24: Percentile 90 (Optimiste) | C24: =DATA_RAW!C27 -> 620 | D24: =DATA_RAW!E27 -> 256 | E24: =IF(C24=0,"—",IF(C24=D24,"Égal",IF(C24>D24,"▲ "&C3,"▲ "&D3))) -> ▲ Microsoft
B26: MULTIPLES DE MARCHÉ
B27: PE Ratio (LTM) | C27: =DATA_RAW!C17 -> 33.4 | D27: =DATA_RAW!E17 -> 21.8 | E27: =IF(C27=0,"—",IF(C27=D27,"Égal",IF(C27<D27,"▲ "&C3,"▲ "&D3))) -> ▲ Alphabet
B28: EV / EBITDA | C28: =DATA_RAW!C18 -> 22.1 | D28: =DATA_RAW!E18 -> 14.3 | E28: =IF(C28=0,"—",IF(C28=D28,"Égal",IF(C28<D28,"▲ "&C3,"▲ "&D3))) -> ▲ Alphabet
B29: Price / Book | C29: =DATA_RAW!C19 -> 12.1 | D29: =DATA_RAW!E19 -> 6.8 | E29: =IF(C29=0,"—",IF(C29=D29,"Égal",IF(C29<D29,"▲ "&C3,"▲ "&D3))) -> ▲ Alphabet
B30: FCF Yield | C30: =DATA_RAW!C20 -> 0.022 | D30: =DATA_RAW!E20 -> 0.031 | E30: =IF(C30=0,"—",IF(C30=D30,"Égal",IF(C30>D30,"▲ "&C3,"▲ "&D3))) -> ▲ Alphabet
B31: PEG Ratio | C31: =DATA_RAW!C21 -> 2.31 | D31: =DATA_RAW!E21 -> 1.52 | E31: =IF(C31=0,"—",IF(C31=D31,"Égal",IF(C31<D31,"▲ "&C3,"▲ "&D3))) -> ▲ Alphabet
B32: BENCHMARK SECTORIEL — MÉDIANE DU SECTEUR
B33: Métrique | C33: Soc. A / Soc. B | D33: Médiane Secteur | E33: Vs Médiane
B34: PE Ratio (LTM) | C34: =DATA_RAW!C17 -> 33.4 | D34: =DATA_RAW!C59 -> 30.15 | E34: =IF(C34=0,"—",IF(D34=0,"—",IF(C34<D34,"✓ Décoté","✗ Surévalué"))) -> ✗ Surévalué
B35: EV / EBITDA | C35: =DATA_RAW!C18 -> 22.1 | D35: =DATA_RAW!C60 -> 20 | E35: =IF(C35=0,"—",IF(D35=0,"—",IF(C35<D35,"✓ Décoté","✗ Surévalué"))) -> ✗ Surévalué
B36: PE Ratio — Soc. B | C36: =DATA_RAW!E17 -> 21.8 | D36: =DATA_RAW!C59 -> 30.15 | E36: =IF(C36=0,"—",IF(D36=0,"—",IF(C36<D36,"✓ Décoté","✗ Surévalué"))) -> ✓ Décoté
B39: SENSIBILITÉ DCF — WACC × TAUX DE CROISSANCE TERMINAL
B40: Valeur intrinsèque DCF (base case) sous différentes hypothèses de WACC (lignes) et de taux de croissance terminal (colonnes) · Cellule centrale = scénario de base
B41: WACC \ g → | C41: 0.015 | D41: 0.02 | E41: 0.025 | F41: 0.03 | G41: 0.035 | H41: 0.04 | I41: 0.045
B42: 0.07 | C42: =IFERROR(IF(B42<=C41,"N/A",DATA_RAW!C12*((DATA_RAW!C22-DATA_RAW!C23)/(B42-C41))),"N/A") -> 514.90909 | D42: =IFERROR(IF(B42<=D41,"N/A",DATA_RAW!C12*((DATA_RAW!C22-DATA_RAW!C23)/(B42-D41))),"N/A") -> 566.4 | E42: =IFERROR(IF(B42<=E41,"N/A",DATA_RAW!C12*((DATA_RAW!C22-DATA_RAW!C23)/(B42-E41))),"N/A") -> 629.33333 | F42: =IFERROR(IF(B42<=F41,"N/A",DATA_RAW!C12*((DATA_RAW!C22-DATA_RAW!C23)/(B42-F41))),"N/A") -> 708 | G42: =IFERROR(IF(B42<=G41,"N/A",DATA_RAW!C12*((DATA_RAW!C22-DATA_RAW!C23)/(B42-G41))),"N/A") -> 809.14286 | H42: =IFERROR(IF(B42<=H41,"N/A",DATA_RAW!C12*((DATA_RAW!C22-DATA_RAW!C23)/(B42-H41))),"N/A") -> 944 | I42: =IFERROR(IF(B42<=I41,"N/A",DATA_RAW!C12*((DATA_RAW!C22-DATA_RAW!C23)/(B42-I41))),"N/A") -> 1132.8
B43: 0.075 | C43: =IFERROR(IF(B43<=C41,"N/A",DATA_RAW!C12*((DATA_RAW!C22-DATA_RAW!C23)/(B43-C41))),"N/A") -> 472 | D43: =IFERROR(IF(B43<=D41,"N/A",DATA_RAW!C12*((DATA_RAW!C22-DATA_RAW!C23)/(B43-D41))),"N/A") -> 514.90909 | E43: =IFERROR(IF(B43<=E41,"N/A",DATA_RAW!C12*((DATA_RAW!C22-DATA_RAW!C23)/(B43-E41))),"N/A") -> 566.4 | F43: =IFERROR(IF(B43<=F41,"N/A",DATA_RAW!C12*((DATA_RAW!C22-DATA_RAW!C23)/(B43-F41))),"N/A") -> 629.33333 | G43: =IFERROR(IF(B43<=G41,"N/A",DATA_RAW!C12*((DATA_RAW!C22-DATA_RAW!C23)/(B43-G41))),"N/A") -> 708 | H43: =IFERROR(IF(B43<=H41,"N/A",DATA_RAW!C12*((DATA_RAW!C22-DATA_RAW!C23)/(B43-H41))),"N/A") -> 809.14286 | I43: =IFERROR(IF(B43<=I41,"N/A",DATA_RAW!C12*((DATA_RAW!C22-DATA_RAW!C23)/(B43-I41))),"N/A") -> 944
B44: 0.08 | C44: =IFERROR(IF(B44<=C41,"N/A",DATA_RAW!C12*((DATA_RAW!C22-DATA_RAW!C23)/(B44-C41))),"N/A") -> 435.69231 | D44: =IFERROR(IF(B44<=D41,"N/A",DATA_RAW!C12*((DATA_RAW!C22-DATA_RAW!C23)/(B44-D41))),"N/A") -> 472 | E44: =IFERROR(IF(B44<=E41,"N/A",DATA_RAW!C12*((DATA_RAW!C22-DATA_RAW!C23)/(B44-E41))),"N/A") -> 514.90909 | F44: =IFERROR(IF(B44<=F41,"N/A",DATA_RAW!C12*((DATA_RAW!C22-DATA_RAW!C23)/(B44-F41))),"N/A") -> 566.4 | G44: =IFERROR(IF(B44<=G41,"N/A",DATA_RAW!C12*((DATA_RAW!C22-DATA_RAW!C23)/(B44-G41))),"N/A") -> 629.33333 | H44: =IFERROR(IF(B44<=H41,"N/A",DATA_RAW!C12*((DATA_RAW!C22-DATA_RAW!C23)/(B44-H41))),"N/A") -> 708 | I44: =IFERROR(IF(B44<=I41,"N/A",DATA_RAW!C12*((DATA_RAW!C22-DATA_RAW!C23)/(B44-I41))),"N/A") -> 809.14286
...

Sheet QUALITE_FINANCIERE
B1: QUALITÉ FINANCIÈRE — FinSight IA
B2: CONFIDENTIEL · Usage interne exclusif · FinSight IA · 4 avril 2026
B3: INDICATEUR | C3: =DATA_RAW!C4 -> Microsoft | D3: =DATA_RAW!E5 -> Alphabet | E3: INTERPRÉTATION
B5: PIOTROSKI F-SCORE — 9 CRITÈRES BINAIRES (>6 = QUALITY, <4 = TRAP)
B6: ROA > 0 (rentabilité positive) | C6: =IF(DATA_RAW!C68=1,"✓",IF(DATA_RAW!C68=0,"✗","—")) -> ✓ | D6: =IF(DATA_RAW!E68=1,"✓",IF(DATA_RAW!E68=0,"✗","—")) -> ✓ | E6: =IF(DATA_RAW!C68="","—",IF(DATA_RAW!C68=DATA_RAW!E68,"Égal",IF(DATA_RAW!C68>DATA_RAW!E68,"▲ "&C3,"▲ "&D3))) -> Égal
B7: CFO > 0 (cash flow opérationnel positif) | C7: =IF(DATA_RAW!C69=1,"✓",IF(DATA_RAW!C69=0,"✗","—")) -> ✓ | D7: =IF(DATA_RAW!E69=1,"✓",IF(DATA_RAW!E69=0,"✗","—")) -> ✓ | E7: =IF(DATA_RAW!C69="","—",IF(DATA_RAW!C69=DATA_RAW!E69,"Égal",IF(DATA_RAW!C69>DATA_RAW!E69,"▲ "&C3,"▲ "&D3))) -> Égal
B8: ΔROA > 0 (amélioration rentabilité) | C8: =IF(DATA_RAW!C70=1,"✓",IF(DATA_RAW!C70=0,"✗","—")) -> ✓ | D8: =IF(DATA_RAW!E70=1,"✓",IF(DATA_RAW!E70=0,"✗","—")) -> ✓ | E8: =IF(DATA_RAW!C70="","—",IF(DATA_RAW!C70=DATA_RAW!E70,"Égal",IF(DATA_RAW!C70>DATA_RAW!E70,"▲ "&C3,"▲ "&D3))) -> Égal
B9: Accruals < CFO (qualité bénéfices) | C9: =IF(DATA_RAW!C71=1,"✓",IF(DATA_RAW!C71=0,"✗","—")) -> ✓ | D9: =IF(DATA_RAW!E71=1,"✓",IF(DATA_RAW!E71=0,"✗","—")) -> ✗ | E9: =IF(DATA_RAW!C71="","—",IF(DATA_RAW!C71=DATA_RAW!E71,"Égal",IF(DATA_RAW!C71>DATA_RAW!E71,"▲ "&C3,"▲ "&D3))) -> ▲ Microsoft
B10: ΔLevier < 0 (réduction dette) | C10: =IF(DATA_RAW!C72=1,"✓",IF(DATA_RAW!C72=0,"✗","—")) -> ✓ | D10: =IF(DATA_RAW!E72=1,"✓",IF(DATA_RAW!E72=0,"✗","—")) -> ✓ | E10: =IF(DATA_RAW!C72="","—",IF(DATA_RAW!C72=DATA_RAW!E72,"Égal",IF(DATA_RAW!C72>DATA_RAW!E72,"▲ "&C3,"▲ "&D3))) -> Égal
B11: ΔLiquidité > 0 (amélioration liquidité) | C11: =IF(DATA_RAW!C73=1,"✓",IF(DATA_RAW!C73=0,"✗","—")) -> ✓ | D11: =IF(DATA_RAW!E73=1,"✓",IF(DATA_RAW!E73=0,"✗","—")) -> ✓ | E11: =IF(DATA_RAW!C73="","—",IF(DATA_RAW!C73=DATA_RAW!E73,"Égal",IF(DATA_RAW!C73>DATA_RAW!E73,"▲ "&C3,"▲ "&D3))) -> Égal
B12: Pas de dilution (pas d'émission actions) | C12: =IF(DATA_RAW!C74=1,"✓",IF(DATA_RAW!C74=0,"✗","—")) -> ✓ | D12: =IF(DATA_RAW!E74=1,"✓",IF(DATA_RAW!E74=0,"✗","—")) -> ✓ | E12: =IF(DATA_RAW!C74="","—",IF(DATA_RAW!C74=DATA_RAW!E74,"Égal",IF(DATA_RAW!C74>DATA_RAW!E74,"▲ "&C3,"▲ "&D3))) -> Égal
B13: ΔMarge Brute > 0 (expansion marges) | C13: =IF(DATA_RAW!C75=1,"✓",IF(DATA_RAW!C75=0,"✗","—")) -> ✓ | D13: =IF(DATA_RAW!E75=1,"✓",IF(DATA_RAW!E75=0,"✗","—")) -> ✓ | E13: =IF(DATA_RAW!C75="","—",IF(DATA_RAW!C75=DATA_RAW!E75,"Égal",IF(DATA_RAW!C75>DATA_RAW!E75,"▲ "&C3,"▲ "&D3))) -> Égal
B14: ΔRotation Actifs > 0 (efficacité opérationnelle) | C14: =IF(DATA_RAW!C76=1,"✓",IF(DATA_RAW!C76=0,"✗","—")) -> ✓ | D14: =IF(DATA_RAW!E76=1,"✓",IF(DATA_RAW!E76=0,"✗","—")) -> ✗ | E14: =IF(DATA_RAW!C76="","—",IF(DATA_RAW!C76=DATA_RAW!E76,"Égal",IF(DATA_RAW!C76>DATA_RAW!E76,"▲ "&C3,"▲ "&D3))) -> ▲ Microsoft
B15: SCORE TOTAL F-SCORE | C15: =DATA_RAW!C28 -> 8 | D15: =DATA_RAW!E28 -> 7 | E15: =IF(C15=0,"—",IF(C15=D15,"Égal",IF(C15>D15,"▲ "&C3,"▲ "&D3))) -> ▲ Microsoft
B17: INDICATEURS DE MANIPULATION COMPTABLE
B18: Sloan Accruals Ratio | C18: =DATA_RAW!C29 -> -0.021 | D18: =DATA_RAW!E29 -> -0.008 | E18: =IF(C18=0,"—",IF(C18=D18,"Égal",IF(C18<D18,"▲ "&C3,"▲ "&D3))) -> ▲ Microsoft
B19: Cash Conversion Score | C19: =DATA_RAW!C30 -> 1.18 | D19: =DATA_RAW!E30 -> 1.42 | E19: =IF(C19=0,"—",IF(C19=D19,"Égal",IF(C19>D19,"▲ "&C3,"▲ "&D3))) -> ▲ Alphabet
B20: Beneish M-Score | C20: =DATA_RAW!C31 -> -2.31 | D20: =DATA_RAW!E31 -> -2.85 | E20: =IF(C20=0,"—",IF(C20=D20,"Égal",IF(C20<D20,"▲ "&C3,"▲ "&D3))) -> ▲ Alphabet
B21: Altman Z-Score | C21: =DATA_RAW!C32 -> 4.12 | D21: =DATA_RAW!E32 -> 5.67 | E21: =IF(C21=0,"—",IF(C21=D21,"Égal",IF(C21>D21,"▲ "&C3,"▲ "&D3))) -> ▲ Alphabet
B22: Modèle Altman utilisé | C22: =DATA_RAW!C33 -> Public (>3) | D22: =DATA_RAW!E33 -> Public (>3) | E22: =IF(C22=0,"—",IF(C22=D22,"Égal",IF(C22>D22,"▲ "&C3,"▲ "&D3))) -> Égal
B24: LIQUIDITÉ & STRUCTURE DU BILAN
B25: Current Ratio (>1.5 = sain) | C25: =DATA_RAW!C53 -> 2.41 | D25: =DATA_RAW!E53 -> 2.87 | E25: =IF(C25=0,"—",IF(C25=D25,"Égal",IF(C25>D25,"▲ "&C3,"▲ "&D3))) -> ▲ Alphabet
B26: Quick Ratio (>1.0 = sain) | C26: =DATA_RAW!C54 -> 1.93 | D26: =DATA_RAW!E54 -> 2.31 | E26: =IF(C26=0,"—",IF(C26=D26,"Égal",IF(C26>D26,"▲ "&C3,"▲ "&D3))) -> ▲ Alphabet
B27: Capex / Revenus (intensité cap.) | C27: =DATA_RAW!C55 -> 0.048 | D27: =DATA_RAW!E55 -> 0.052 | E27: =IF(C27=0,"—",IF(C27=D27,"Égal",IF(C27<D27,"▲ "&C3,"▲ "&D3))) -> ▲ Microsoft

Sheet PROFITABILITE_CROISSANCE
B1: PROFITABILITÉ & CROISSANCE — FinSight IA | P1: Métrique | Q1: =DASHBOARD!C10 -> Microsoft | R1: =DASHBOARD!D10 -> Alphabet
B2: CONFIDENTIEL · Usage interne exclusif · FinSight IA · 4 avril 2026 | P2: ROIC (%) | Q2: =IFERROR(DATA_RAW!C34*100,0) -> 31.2 | R2: =IFERROR(DATA_RAW!E34*100,0) -> 18.7
B3: MÉTRIQUE | C3: =DATA_RAW!C4 -> Microsoft | D3: =DATA_RAW!E5 -> Alphabet | E3: AVANTAGE | P3: ROE (%) | Q3: =IFERROR(DATA_RAW!C35*100,0) -> 34.1 | R3: =IFERROR(DATA_RAW!E35*100,0) -> 15.2 | Z3: Période | AA3: =IF(DATA_RAW!C4="","Soc. A",DATA_RAW!C4) -> Microsoft | AB3: =IF(DATA_RAW!E5="","Soc. B",DATA_RAW!E5) -> Alphabet
P4: Mg. EBITDA (%) | Q4: =IFERROR(DATA_RAW!C36*100,0) -> 45.8 | R4: =IFERROR(DATA_RAW!E36*100,0) -> 32.1 | Z4: N-2 | AA4: =IF(DATA_RAW!C38=0,NA(),DATA_RAW!C38) -> 0.412 | AB4: =IF(DATA_RAW!E38=0,NA(),DATA_RAW!E38) -> 0.281
B5: RENTABILITÉ DU CAPITAL | P5: CAGR CA 3Y (%) | Q5: =IFERROR(DATA_RAW!C40*100,0) -> 14.2 | R5: =IFERROR(DATA_RAW!E40*100,0) -> 11.8 | Z5: N-1 | AA5: =IF(DATA_RAW!C37=0,NA(),DATA_RAW!C37) -> 0.431 | AB5: =IF(DATA_RAW!E37=0,NA(),DATA_RAW!E37) -> 0.298
B6: ROIC (Return on Invested Capital) | C6: =DATA_RAW!C34 -> 0.312 | D6: =DATA_RAW!E34 -> 0.187 | E6: =IF(C6=0,"—",IF(C6=D6,"Égal",IF(C6>D6,"▲ "&C3,"▲ "&D3))) -> ▲ Microsoft | P6: Croiss. BPA (%) | Q6: =IFERROR(DATA_RAW!C41*100,0) -> 18.7 | R6: =IFERROR(DATA_RAW!E41*100,0) -> 14.3 | Z6: LTM | AA6: =IF(DATA_RAW!C36=0,NA(),DATA_RAW!C36) -> 0.458 | AB6: =IF(DATA_RAW!E36=0,NA(),DATA_RAW!E36) -> 0.321
B7: ROE (Return on Equity) | C7: =DATA_RAW!C35 -> 0.341 | D7: =DATA_RAW!E35 -> 0.152 | E7: =IF(C7=0,"—",IF(C7=D7,"Égal",IF(C7>D7,"▲ "&C3,"▲ "&D3))) -> ▲ Microsoft | P7: Couv. Intérêts (x) | Q7: =IFERROR(DATA_RAW!C43,0) -> 28.4 | R7: =IFERROR(DATA_RAW!E43,0) -> 19.7
B8: Marge EBITDA (LTM) | C8: =DATA_RAW!C36 -> 0.458 | D8: =DATA_RAW!E36 -> 0.321 | E8: =IF(C8=0,"—",IF(C8=D8,"Égal",IF(C8>D8,"▲ "&C3,"▲ "&D3))) -> ▲ Microsoft
B9: Marge EBITDA (N-1) | C9: =DATA_RAW!C37 -> 0.431 | D9: =DATA_RAW!E37 -> 0.298 | E9: =IF(C9=0,"—",IF(C9=D9,"Égal",IF(C9>D9,"▲ "&C3,"▲ "&D3))) -> ▲ Microsoft
B10: Marge EBITDA (N-2) | C10: =DATA_RAW!C38 -> 0.412 | D10: =DATA_RAW!E38 -> 0.281 | E10: =IF(C10=0,"—",IF(C10=D10,"Égal",IF(C10>D10,"▲ "&C3,"▲ "&D3))) -> ▲ Microsoft
B11: Tendance marges 3 ans | C11: =DATA_RAW!C39 -> Croissante | D11: =DATA_RAW!E39 -> Stable | E11: =IF(C11=0,"—",IF(C11=D11,"Égal",IF(C11>D11,"▲ "&C3,"▲ "&D3))) -> ▲ Alphabet
B13: CROISSANCE & STRUCTURE FINANCIÈRE
B14: Croissance CA CAGR 3 ans | C14: =DATA_RAW!C40 -> 0.142 | D14: =DATA_RAW!E40 -> 0.118 | E14: =IF(C14=0,"—",IF(C14=D14,"Égal",IF(C14>D14,"▲ "&C3,"▲ "&D3))) -> ▲ Microsoft
B15: Croissance BPA | C15: =DATA_RAW!C41 -> 0.187 | D15: =DATA_RAW!E41 -> 0.143 | E15: =IF(C15=0,"—",IF(C15=D15,"Égal",IF(C15>D15,"▲ "&C3,"▲ "&D3))) -> ▲ Microsoft
B16: Dette Nette / EBITDA | C16: =DATA_RAW!C42 -> -0.8 | D16: =DATA_RAW!E42 -> 0.4 | E16: =IF(C16=0,"—",IF(C16=D16,"Égal",IF(C16<D16,"▲ "&C3,"▲ "&D3))) -> ▲ Microsoft
B17: Couverture des intérêts | C17: =DATA_RAW!C43 -> 28.4 | D17: =DATA_RAW!E43 -> 19.7 | E17: =IF(C17=0,"—",IF(C17=D17,"Égal",IF(C17>D17,"▲ "&C3,"▲ "&D3))) -> ▲ Microsoft
B20: ÉVOLUTION DES MARGES — ANALYSE TEMPORELLE (N-2 → LTM)
B21: MÉTRIQUE | C21: =IFERROR("N-2 · "&TEXT(DATA_RAW!C4,"@"),"N-2") -> N-2 · Microsoft | D21: =IFERROR("N-1 · "&TEXT(DATA_RAW!C4,"@"),"N-1") -> N-1 · Microsoft | E21: =IFERROR("LTM · "&TEXT(DATA_RAW!C4,"@"),"LTM") -> LTM · Microsoft
B22: =IFERROR(DATA_RAW!C4&" — Marge EBITDA","Marge EBITDA — A") -> Microsoft — Marge EBITDA | C22: =IF(DATA_RAW!C38=0,"—",DATA_RAW!C38) -> 0.412 | D22: =IF(DATA_RAW!C37=0,"—",DATA_RAW!C37) -> 0.431 | E22: =IF(DATA_RAW!C36=0,"—",DATA_RAW!C36) -> 0.458
B23: =IFERROR(DATA_RAW!E5&" — Marge EBITDA","Marge EBITDA — B") -> Alphabet — Marge EBITDA | C23: =IF(DATA_RAW!E38=0,"—",DATA_RAW!E38) -> 0.281 | D23: =IF(DATA_RAW!E37=0,"—",DATA_RAW!E37) -> 0.298 | E23: =IF(DATA_RAW!E36=0,"—",DATA_RAW!E36) -> 0.321
B24: =IFERROR(DATA_RAW!C4&" — ROE","ROE — A") -> Microsoft — ROE | C24: =IF(DATA_RAW!C35=0,"—",DATA_RAW!C35) -> 0.341 | D24: =IF(DATA_RAW!C35=0,"—",DATA_RAW!C35) -> 0.341 | E24: =IF(DATA_RAW!C35=0,"—",DATA_RAW!C35) -> 0.341
B25: =IFERROR(DATA_RAW!E5&" — ROE","ROE — B") -> Alphabet — ROE | C25: =IF(DATA_RAW!E35=0,"—",DATA_RAW!E35) -> 0.152 | D25: =IF(DATA_RAW!E35=0,"—",DATA_RAW!E35) -> 0.152 | E25: =IF(DATA_RAW!E35=0,"—",DATA_RAW!E35) -> 0.152
B26: =IFERROR(DATA_RAW!C4&" — ROIC","ROIC — A") -> Microsoft — ROIC | C26: =IF(DATA_RAW!C34=0,"—",DATA_RAW!C34) -> 0.312 | D26: =IF(DATA_RAW!C34=0,"—",DATA_RAW!C34) -> 0.312 | E26: =IF(DATA_RAW!C34=0,"—",DATA_RAW!C34) -> 0.312
B27: =IFERROR(DATA_RAW!E5&" — ROIC","ROIC — B") -> Alphabet — ROIC | C27: =IF(DATA_RAW!E34=0,"—",DATA_RAW!E34) -> 0.187 | D27: =IF(DATA_RAW!E34=0,"—",DATA_RAW!E34) -> 0.187 | E27: =IF(DATA_RAW!E34=0,"—",DATA_RAW!E34) -> 0.187
B28: =IFERROR(DATA_RAW!C4&" — Croissance CA","Croissance CA — A") -> Microsoft — Croissance CA | C28: =IF(DATA_RAW!C40=0,"—",DATA_RAW!C40) -> 0.142 | D28: =IF(DATA_RAW!C40=0,"—",DATA_RAW!C40) -> 0.142 | E28: =IF(DATA_RAW!C40=0,"—",DATA_RAW!C40) -> 0.142
B29: =IFERROR(DATA_RAW!E5&" — Croissance CA","Croissance CA — B") -> Alphabet — Croissance CA | C29: =IF(DATA_RAW!E40=0,"—",DATA_RAW!E40) -> 0.118 | D29: =IF(DATA_RAW!E40=0,"—",DATA_RAW!E40) -> 0.118 | E29: =IF(DATA_RAW!E40=0,"—",DATA_RAW!E40) -> 0.118

Sheet RISQUE_MOMENTUM
B1: RISQUE & MOMENTUM — FinSight IA
B2: CONFIDENTIEL · Usage interne exclusif · FinSight IA · 4 avril 2026
B3: INDICATEUR | C3: =DATA_RAW!C4 -> Microsoft | D3: =DATA_RAW!E5 -> Alphabet | E3: INTERPRÉTATION | Z3: Métrique | AA3: =IF(DATA_RAW!C4="","Soc. A",DATA_RAW!C4) -> Microsoft | AB3: =IF(DATA_RAW!E5="","Soc. B",DATA_RAW!E5) -> Alphabet
Z4: Score FinSight (/100) | AA4: =IF(DATA_RAW!C47=0,NA(),DATA_RAW!C47) -> 82 | AB4: =IF(DATA_RAW!E47=0,NA(),DATA_RAW!E47) -> 74
B5: INDICATEURS DE RISQUE | Z5: Score Momentum (/10) | AA5: =IF(DATA_RAW!C48=0,NA(),DATA_RAW!C48*10) -> 72 | AB5: =IF(DATA_RAW!E48=0,NA(),DATA_RAW!E48*10) -> 61
B6: Beta (sensibilité marché) | C6: =DATA_RAW!C44 -> 0.89 | D6: =DATA_RAW!E44 -> 1.04 | E6: =IF(C6=0,"—",IF(C6=D6,"Égal",IF(C6<D6,"▲ "&C3,"▲ "&D3))) -> ▲ Microsoft | Z6: Conviction (%) | AA6: =IF(DATA_RAW!C50=0,NA(),DATA_RAW!C50*100) -> 78 | AB6: =IF(DATA_RAW!E50=0,NA(),DATA_RAW!E50*100) -> 65
B7: VaR 95% à 1 mois | C7: =DATA_RAW!C45 -> -0.068 | D7: =DATA_RAW!E45 -> -0.091 | E7: =IF(C7=0,"—",IF(C7=D7,"Égal",IF(C7<D7,"▲ "&C3,"▲ "&D3))) -> ▲ Alphabet
B8: Duration implicite | C8: =DATA_RAW!C46 -> 12.3 | D8: =DATA_RAW!E46 -> 9.8 | E8: =IF(C8=0,"—",IF(C8=D8,"Égal",IF(C8>D8,"▲ "&C3,"▲ "&D3))) -> ▲ Microsoft
B10: SCORE FINSIGHT & MOMENTUM
B11: Score FinSight Composite | C11: =DATA_RAW!C47 -> 82 | D11: =DATA_RAW!E47 -> 74 | E11: =IF(C11=0,"—",IF(C11=D11,"Égal",IF(C11>D11,"▲ "&C3,"▲ "&D3))) -> ▲ Microsoft
B12: Score Momentum | C12: =DATA_RAW!C48 -> 7.2 | D12: =DATA_RAW!E48 -> 6.1 | E12: =IF(C12=0,"—",IF(C12=D12,"Égal",IF(C12>D12,"▲ "&C3,"▲ "&D3))) -> ▲ Microsoft
B13: Recommandation | C13: =DATA_RAW!C49 -> ACHETER | D13: =DATA_RAW!E49 -> ACCUMULER | E13: =IF(C13=0,"—",IF(C13=D13,"Égal",IF(C13>D13,"▲ "&C3,"▲ "&D3))) -> ▲ Microsoft
B14: Zone d'entrée optimale | C14: =DATA_RAW!C24 -> 1 | D14: =DATA_RAW!E24 -> 1 | E14: =IF(C14=0,"—",IF(C14=D14,"Égal",IF(C14>D14,"▲ "&C3,"▲ "&D3))) -> Égal
B15: Conviction (%) | C15: =DATA_RAW!C50 -> 0.78 | D15: =DATA_RAW!E50 -> 0.65 | E15: =IF(C15=0,"—",IF(C15=D15,"Égal",IF(C15>D15,"▲ "&C3,"▲ "&D3))) -> ▲ Microsoft
B17: PERFORMANCE RELATIVE (vs INDICE)
B18: Performance 1 mois | C18: =DATA_RAW!C56 -> 0.031 | D18: =DATA_RAW!E56 -> -0.018 | E18: =IF(C18=0,"—",IF(C18=D18,"Égal",IF(C18>D18,"▲ "&C3,"▲ "&D3))) -> ▲ Microsoft
B19: Performance 3 mois | C19: =DATA_RAW!C57 -> 0.112 | D19: =DATA_RAW!E57 -> 0.043 | E19: =IF(C19=0,"—",IF(C19=D19,"Égal",IF(C19>D19,"▲ "&C3,"▲ "&D3))) -> ▲ Microsoft
B20: Performance 1 an | C20: =DATA_RAW!C58 -> 0.187 | D20: =DATA_RAW!E58 -> 0.094 | E20: =IF(C20=0,"—",IF(C20=D20,"Égal",IF(C20>D20,"▲ "&C3,"▲ "&D3))) -> ▲ Microsoft
B22: DONNÉES DE MARCHÉ COMPLÉMENTAIRES
B23: Volume moyen 30j (M actions) | C23: =DATA_RAW!C65 -> 24.3 | D23: =DATA_RAW!E65 -> 28.1 | E23: =IF(C23=0,"—",IF(C23=D23,"Égal",IF(C23>D23,"▲ "&C3,"▲ "&D3))) -> ▲ Alphabet
B24: Rendement dividende (%) | C24: =DATA_RAW!C66 -> 0.008 | D24: =DATA_RAW!E66 -> 0 | E24: =IF(C24=0,"—",IF(C24=D24,"Égal",IF(C24>D24,"▲ "&C3,"▲ "&D3))) -> ▲ Microsoft
B25: Prochain résultat (date) | C25: =DATA_RAW!C67 -> 30 avr. 2026 | D25: =DATA_RAW!E67 -> 29 avr. 2026 | E25: =IF(C25="","—",IF(C25=D25,"Même date",IF(C25<D25,"▲ "&C3&" en premier","▲ "&D3&" en premier"))) -> ▲ Alphabet en premier
B27: =DATA_RAW!C51 -> MSFT privilégié

Sheet COMPARABLES
B1: ANALYSE DE COMPARABLES — FinSight IA
B2: CONFIDENTIEL · Usage interne exclusif · FinSight IA · 4 avril 2026
B4: SOCIÉTÉ | C4: TICKER | D4: PE (LTM) | E4: EV/EBITDA | F4: P/Book | G4: FCF Yield | H4: Rev. CAGR 3Y | I4: Mg. EBITDA | J4: ROIC | K4: Beta | L4: Recommandation
B5: SOCIÉTÉS ANALYSÉES
B6: =DATA_RAW!C4 -> Microsoft | C6: =DATA_RAW!C5 -> MSFT | D6: =DATA_RAW!C17 -> 33.4 | E6: =DATA_RAW!C18 -> 22.1 | F6: =DATA_RAW!C19 -> 12.1 | G6: =DATA_RAW!C20 -> 0.022 | H6: =DATA_RAW!C40 -> 0.142 | I6: =DATA_RAW!C36 -> 0.458 | J6: =DATA_RAW!C34 -> 0.312 | K6: =DATA_RAW!C44 -> 0.89 | L6: =DATA_RAW!C49 -> ACHETER
B7: =DATA_RAW!E4 -> GOOGL | C7: =DATA_RAW!E5 -> Alphabet | D7: =DATA_RAW!E17 -> 21.8 | E7: =DATA_RAW!E18 -> 14.3 | F7: =DATA_RAW!E19 -> 6.8 | G7: =DATA_RAW!E20 -> 0.031 | H7: =DATA_RAW!E40 -> 0.118 | I7: =DATA_RAW!E36 -> 0.321 | J7: =DATA_RAW!E34 -> 0.187 | K7: =DATA_RAW!E44 -> 1.04 | L7: =DATA_RAW!E49 -> ACCUMULER
B8: PAIRS SECTORIELS · Source : agent_quant
B9: Apple | C9: AAPL | D9: 31.2 | E9: 21.4 | F9: 47.2 | G9: 0.031 | H9: 0.081 | I9: 0.312 | J9: 0.541 | K9: 1.24 | L9: Neutre
B10: Meta | C10: META | D10: 24.1 | E10: 13.8 | F10: 8.6 | G10: 0.028 | H10: 0.192 | I10: 0.418 | J10: 0.281 | K10: 1.18 | L10: Acheter
B11: Amazon | C11: AMZN | D11: 41.3 | E11: 19.2 | F11: 9.1 | G11: 0.012 | H11: 0.118 | I11: 0.287 | J11: 0.198 | K11: 1.31 | L11: Acheter
B12: Salesforce | C12: CRM | D12: 44.8 | E12: 22.1 | F12: 6.4 | G12: 0.008 | H12: 0.091 | I12: 0.241 | J12: 0.121 | K12: 1.08 | L12: Neutre
B13: Oracle | C13: ORCL | D13: 28.4 | E13: 18.6 | F13: 12.3 | G13: 0.018 | H13: 0.072 | I13: 0.398 | J13: 0.287 | K13: 0.81 | L13: Acheter
B14: SAP | C14: SAP | D14: 29.1 | E14: 17.4 | F14: 5.8 | G14: 0.021 | H14: 0.068 | I14: 0.312 | J14: 0.198 | K14: 0.72 | L14: Neutre
B15: Adobe | C15: ADBE | D15: 27.3 | E15: 20.8 | F15: 12.1 | G15: 0.024 | H15: 0.084 | I15: 0.441 | J15: 0.312 | K15: 1.14 | L15: Acheter
B16: ServiceNow | C16: NOW | D16: 62.4 | E16: 35.2 | F16: 18.4 | G16: 0.004 | H16: 0.212 | I16: 0.281 | J16: 0.187 | K16: 1.28 | L16: Neutre
B18: STATISTIQUES DU GROUPE DE PAIRS
B19: Médiane | C19: (pairs seuls) | D19: =MEDIAN(D9:D16) -> 30.15 | E19: =MEDIAN(E9:E16) -> 20 | F19: =MEDIAN(F9:F16) -> 10.6 | G19: =MEDIAN(G9:G16) -> 0.0195 | H19: =MEDIAN(H9:H16) -> 0.0875 | I19: =MEDIAN(I9:I16) -> 0.312 | J19: =MEDIAN(J9:J16) -> 0.2395 | K19: =MEDIAN(K9:K16) -> 1.16 | L19: —
B20: Moyenne | C20: (pairs seuls) | D20: =AVERAGE(D9:D16) -> 36.075 | E20: =AVERAGE(E9:E16) -> 21.0625 | F20: =AVERAGE(F9:F16) -> 14.9875 | G20: =AVERAGE(G9:G16) -> 0.01825 | H20: =AVERAGE(H9:H16) -> 0.11475 | I20: =AVERAGE(I9:I16) -> 0.33625 | J20: =AVERAGE(J9:J16) -> 0.265625 | K20: =AVERAGE(K9:K16) -> 1.095 | L20: —
B21: Minimum | C21: (pairs seuls) | D21: =MIN(D9:D16) -> 24.1 | E21: =MIN(E9:E16) -> 13.8 | F21: =MIN(F9:F16) -> 5.8 | G21: =MIN(G9:G16) -> 0.004 | H21: =MIN(H9:H16) -> 0.068 | I21: =MIN(I9:I16) -> 0.241 | J21: =MIN(J9:J16) -> 0.121 | K21: =MIN(K9:K16) -> 0.72 | L21: —
B22: Maximum | C22: (pairs seuls) | D22: =MAX(D9:D16) -> 62.4 | E22: =MAX(E9:E16) -> 35.2 | F22: =MAX(F9:F16) -> 47.2 | G22: =MAX(G9:G16) -> 0.031 | H22: =MAX(H9:H16) -> 0.212 | I22: =MAX(I9:I16) -> 0.441 | J22: =MAX(J9:J16) -> 0.541 | K22: =MAX(K9:K16) -> 1.31 | L22: —
B23: ★ Médiane (pairs) alimentée automatiquement dans DATA_RAW!C59–C60 · Données peers : à renseigner par agent_quant
