Workbook

Sheet DASHBOARD
A1: FinSight IA · Tableau de Bord — Screening CAC 40 · 22/03/2026 | R1: Confidentiel · Usage interne
D3: =COUNTA('DONNÉES BRUTES'!A:A)-2 -> 40 | J3: {=COUNTA(_xlfn.UNIQUE(_xlfn._xlws.FILTER('DONNÉES BRUTES'!C3:C42,'DONNÉES BRUTES'!C3:C42<>"")))} -> 12 | P3: =_xlfn.XLOOKUP(MAX('DONNÉES BRUTES'!AB3:AB42),'DONNÉES BRUTES'!AB3:AB42,'DONNÉES BRUTES'!A3:A42)&" — "&MAX('DONNÉES BRUTES'!AB3:AB42)&"/100" -> RMS.PA — 75/100 | V3: 01/04/2026
D4: SOCIÉTÉS ANALYSÉES | J4: SECTEURS COUVERTS | P4: MEILLEUR SCORE GLOBAL | V4: DATE D'ANALYSE
B6: TOP 5 · Classements par Facteur d'Investissement
B7: # | C7: Ticker | D7: Société | E7: Score | F7: Mét. | H7: # | I7: Ticker | J7: Société | K7: Score | L7: Mét. | N7: # | O7: Ticker | P7: Société | Q7: Score | R7: Mét. | T7: # | U7: Ticker | V7: Société | W7: Score | X7: Mét.
B8: 1 | C8: {=IFERROR(INDEX('DONNÉES BRUTES'!A$3:A$42,MATCH(_xlfn.AGGREGATE(14,6,'DONNÉES BRUTES'!AB$3:AB$42*1000+(40-ROW('DONNÉES BRUTES'!AB$3:AB$42)+ROW('DONNÉES BRUTES'!AB$3)),1),'DONNÉES BRUTES'!AB$3:AB$42*1000+(40-ROW('DONNÉES BRUTES'!AB$3:AB$42)+ROW('DONNÉES BRUTES'!AB$3)),0)),"—")} -> RMS.PA | D8: {=IFERROR(LEFT(INDEX('DONNÉES BRUTES'!B$3:B$42,MATCH(_xlfn.AGGREGATE(14,6,'DONNÉES BRUTES'!AB$3:AB$42*1000+(40-ROW('DONNÉES BRUTES'!AB$3:AB$42)+ROW('DONNÉES BRUTES'!AB$3)),1),'DONNÉES BRUTES'!AB$3:AB$42*1000+(40-ROW('DONNÉES BRUTES'!AB$3:AB$42)+ROW('DONNÉES BRUTES'!AB$3)),0)),18),"—")} -> Hermès Internation | E8: {=IFERROR(INT(_xlfn.AGGREGATE(14,6,'DONNÉES BRUTES'!AB$3:AB$42*1000+(40-ROW('DONNÉES BRUTES'!AB$3:AB$42)+ROW('DONNÉES BRUTES'!AB$3)),1)/1000)&"/100","—")} -> 75/100 | F8: {=IFERROR(INDEX('DONNÉES BRUTES'!I$3:I$42,MATCH(_xlfn.AGGREGATE(14,6,'DONNÉES BRUTES'!AB$3:AB$42*1000+(40-ROW('DONNÉES BRUTES'!AB$3:AB$42)+ROW('DONNÉES BRUTES'!AB$3)),1),'DONNÉES BRUTES'!AB$3:AB$42*1000+(40-ROW('DONNÉES BRUTES'!AB$3:AB$42)+ROW('DONNÉES BRUTES'!AB$3)),0)),"—")} -> — | H8: 1 | I8: {=IFERROR(INDEX('DONNÉES BRUTES'!A$3:A$42,MATCH(_xlfn.AGGREGATE(14,6,'DONNÉES BRUTES'!Y$3:Y$42*1000+(40-ROW('DONNÉES BRUTES'!Y$3:Y$42)+ROW('DONNÉES BRUTES'!Y$3)),1),'DONNÉES BRUTES'!Y$3:Y$42*1000+(40-ROW('DONNÉES BRUTES'!Y$3:Y$42)+ROW('DONNÉES BRUTES'!Y$3)),0)),"—")} -> SAF.PA | J8: {=IFERROR(LEFT(INDEX('DONNÉES BRUTES'!B$3:B$42,MATCH(_xlfn.AGGREGATE(14,6,'DONNÉES BRUTES'!Y$3:Y$42*1000+(40-ROW('DONNÉES BRUTES'!Y$3:Y$42)+ROW('DONNÉES BRUTES'!Y$3)),1),'DONNÉES BRUTES'!Y$3:Y$42*1000+(40-ROW('DONNÉES BRUTES'!Y$3:Y$42)+ROW('DONNÉES BRUTES'!Y$3)),0)),18),"—")} -> Safran SA | K8: {=IFERROR(INT(_xlfn.AGGREGATE(14,6,'DONNÉES BRUTES'!Y$3:Y$42*1000+(40-ROW('DONNÉES BRUTES'!Y$3:Y$42)+ROW('DONNÉES BRUTES'!Y$3)),1)/1000)&"/100","—")} -> 100/100 | L8: {=IFERROR(INDEX('DONNÉES BRUTES'!P$3:P$42,MATCH(_xlfn.AGGREGATE(14,6,'DONNÉES BRUTES'!Y$3:Y$42*1000+(40-ROW('DONNÉES BRUTES'!Y$3:Y$42)+ROW('DONNÉES BRUTES'!Y$3)),1),'DONNÉES BRUTES'!Y$3:Y$42*1000+(40-ROW('DONNÉES BRUTES'!Y$3:Y$42)+ROW('DONNÉES BRUTES'!Y$3)),0)),"—")} -> +12.5% | N8: 1 | O8: {=IFERROR(INDEX('DONNÉES BRUTES'!A$3:A$42,MATCH(_xlfn.AGGREGATE(14,6,'DONNÉES BRUTES'!Z$3:Z$42*1000+(40-ROW('DONNÉES BRUTES'!Z$3:Z$42)+ROW('DONNÉES BRUTES'!Z$3)),1),'DONNÉES BRUTES'!Z$3:Z$42*1000+(40-ROW('DONNÉES BRUTES'!Z$3:Z$42)+ROW('DONNÉES BRUTES'!Z$3)),0)),"—")} -> DSY.PA | P8: {=IFERROR(LEFT(INDEX('DONNÉES BRUTES'!B$3:B$42,MATCH(_xlfn.AGGREGATE(14,6,'DONNÉES BRUTES'!Z$3:Z$42*1000+(40-ROW('DONNÉES BRUTES'!Z$3:Z$42)+ROW('DONNÉES BRUTES'!Z$3)),1),'DONNÉES BRUTES'!Z$3:Z$42*1000+(40-ROW('DONNÉES BRUTES'!Z$3:Z$42)+ROW('DONNÉES BRUTES'!Z$3)),0)),18),"—")} -> Dassault Systèmes | Q8: {=IFERROR(INT(_xlfn.AGGREGATE(14,6,'DONNÉES BRUTES'!Z$3:Z$42*1000+(40-ROW('DONNÉES BRUTES'!Z$3:Z$42)+ROW('DONNÉES BRUTES'!Z$3)),1)/1000)&"/100","—")} -> 100/100 | R8: {=IFERROR(INDEX('DONNÉES BRUTES'!U$3:U$42,MATCH(_xlfn.AGGREGATE(14,6,'DONNÉES BRUTES'!Z$3:Z$42*1000+(40-ROW('DONNÉES BRUTES'!Z$3:Z$42)+ROW('DONNÉES BRUTES'!Z$3)),1),'DONNÉES BRUTES'!Z$3:Z$42*1000+(40-ROW('DONNÉES BRUTES'!Z$3:Z$42)+ROW('DONNÉES BRUTES'!Z$3)),0)),"—")} -> — | T8: 1 | U8: {=IFERROR(INDEX('DONNÉES BRUTES'!A$3:A$42,MATCH(_xlfn.AGGREGATE(14,6,'DONNÉES BRUTES'!AA$3:AA$42*1000+(40-ROW('DONNÉES BRUTES'!AA$3:AA$42)+ROW('DONNÉES BRUTES'!AA$3)),1),'DONNÉES BRUTES'!AA$3:AA$42*1000+(40-ROW('DONNÉES BRUTES'!AA$3:AA$42)+ROW('DONNÉES BRUTES'!AA$3)),0)),"—")} -> ALO.PA | V8: {=IFERROR(LEFT(INDEX('DONNÉES BRUTES'!B$3:B$42,MATCH(_xlfn.AGGREGATE(14,6,'DONNÉES BRUTES'!AA$3:AA$42*1000+(40-ROW('DONNÉES BRUTES'!AA$3:AA$42)+ROW('DONNÉES BRUTES'!AA$3)),1),'DONNÉES BRUTES'!AA$3:AA$42*1000+(40-ROW('DONNÉES BRUTES'!AA$3:AA$42)+ROW('DONNÉES BRUTES'!AA$3)),0)),18),"—")} -> Alstom SA | W8: {=IFERROR(INT(_xlfn.AGGREGATE(14,6,'DONNÉES BRUTES'!AA$3:AA$42*1000+(40-ROW('DONNÉES BRUTES'!AA$3:AA$42)+ROW('DONNÉES BRUTES'!AA$3)),1)/1000)&"/100","—")} -> 100/100 | X8: {=IFERROR(INDEX('DONNÉES BRUTES'!P$3:P$42,MATCH(_xlfn.AGGREGATE(14,6,'DONNÉES BRUTES'!AA$3:AA$42*1000+(40-ROW('DONNÉES BRUTES'!AA$3:AA$42)+ROW('DONNÉES BRUTES'!AA$3)),1),'DONNÉES BRUTES'!AA$3:AA$42*1000+(40-ROW('DONNÉES BRUTES'!AA$3:AA$42)+ROW('DONNÉES BRUTES'!AA$3)),0)),"—")} -> +4.9%
B9: 2 | C9: {=IFERROR(INDEX('DONNÉES BRUTES'!A$3:A$42,MATCH(_xlfn.AGGREGATE(14,6,'DONNÉES BRUTES'!AB$3:AB$42*1000+(40-ROW('DONNÉES BRUTES'!AB$3:AB$42)+ROW('DONNÉES BRUTES'!AB$3)),2),'DONNÉES BRUTES'!AB$3:AB$42*1000+(40-ROW('DONNÉES BRUTES'!AB$3:AB$42)+ROW('DONNÉES BRUTES'!AB$3)),0)),"—")} -> AI.PA | D9: {=IFERROR(LEFT(INDEX('DONNÉES BRUTES'!B$3:B$42,MATCH(_xlfn.AGGREGATE(14,6,'DONNÉES BRUTES'!AB$3:AB$42*1000+(40-ROW('DONNÉES BRUTES'!AB$3:AB$42)+ROW('DONNÉES BRUTES'!AB$3)),2),'DONNÉES BRUTES'!AB$3:AB$42*1000+(40-ROW('DONNÉES BRUTES'!AB$3:AB$42)+ROW('DONNÉES BRUTES'!AB$3)),0)),18),"—")} -> L'Air Liquide S.A. | E9: {=IFERROR(INT(_xlfn.AGGREGATE(14,6,'DONNÉES BRUTES'!AB$3:AB$42*1000+(40-ROW('DONNÉES BRUTES'!AB$3:AB$42)+ROW('DONNÉES BRUTES'!AB$3)),2)/1000)&"/100","—")} -> 74/100 | F9: {=IFERROR(INDEX('DONNÉES BRUTES'!I$3:I$42,MATCH(_xlfn.AGGREGATE(14,6,'DONNÉES BRUTES'!AB$3:AB$42*1000+(40-ROW('DONNÉES BRUTES'!AB$3:AB$42)+ROW('DONNÉES BRUTES'!AB$3)),2),'DONNÉES BRUTES'!AB$3:AB$42*1000+(40-ROW('DONNÉES BRUTES'!AB$3:AB$42)+ROW('DONNÉES BRUTES'!AB$3)),0)),"—")} -> — | H9: 2 | I9: {=IFERROR(INDEX('DONNÉES BRUTES'!A$3:A$42,MATCH(_xlfn.AGGREGATE(14,6,'DONNÉES BRUTES'!Y$3:Y$42*1000+(40-ROW('DONNÉES BRUTES'!Y$3:Y$42)+ROW('DONNÉES BRUTES'!Y$3)),2),'DONNÉES BRUTES'!Y$3:Y$42*1000+(40-ROW('DONNÉES BRUTES'!Y$3:Y$42)+ROW('DONNÉES BRUTES'!Y$3)),0)),"—")} -> VIV.PA | J9: {=IFERROR(LEFT(INDEX('DONNÉES BRUTES'!B$3:B$42,MATCH(_xlfn.AGGREGATE(14,6,'DONNÉES BRUTES'!Y$3:Y$42*1000+(40-ROW('DONNÉES BRUTES'!Y$3:Y$42)+ROW('DONNÉES BRUTES'!Y$3)),2),'DONNÉES BRUTES'!Y$3:Y$42*1000+(40-ROW('DONNÉES BRUTES'!Y$3:Y$42)+ROW('DONNÉES BRUTES'!Y$3)),0)),18),"—")} -> Vivendi SE | K9: {=IFERROR(INT(_xlfn.AGGREGATE(14,6,'DONNÉES BRUTES'!Y$3:Y$42*1000+(40-ROW('DONNÉES BRUTES'!Y$3:Y$42)+ROW('DONNÉES BRUTES'!Y$3)),2)/1000)&"/100","—")} -> 97/100 | L9: {=IFERROR(INDEX('DONNÉES BRUTES'!P$3:P$42,MATCH(_xlfn.AGGREGATE(14,6,'DONNÉES BRUTES'!Y$3:Y$42*1000+(40-ROW('DONNÉES BRUTES'!Y$3:Y$42)+ROW('DONNÉES BRUTES'!Y$3)),2),'DONNÉES BRUTES'!Y$3:Y$42*1000+(40-ROW('DONNÉES BRUTES'!Y$3:Y$42)+ROW('DONNÉES BRUTES'!Y$3)),0)),"—")} -> +3.4% | N9: 2 | O9: {=IFERROR(INDEX('DONNÉES BRUTES'!A$3:A$42,MATCH(_xlfn.AGGREGATE(14,6,'DONNÉES BRUTES'!Z$3:Z$42*1000+(40-ROW('DONNÉES BRUTES'!Z$3:Z$42)+ROW('DONNÉES BRUTES'!Z$3)),2),'DONNÉES BRUTES'!Z$3:Z$42*1000+(40-ROW('DONNÉES BRUTES'!Z$3:Z$42)+ROW('DONNÉES BRUTES'!Z$3)),0)),"—")} -> SAN.PA | P9: {=IFERROR(LEFT(INDEX('DONNÉES BRUTES'!B$3:B$42,MATCH(_xlfn.AGGREGATE(14,6,'DONNÉES BRUTES'!Z$3:Z$42*1000+(40-ROW('DONNÉES BRUTES'!Z$3:Z$42)+ROW('DONNÉES BRUTES'!Z$3)),2),'DONNÉES BRUTES'!Z$3:Z$42*1000+(40-ROW('DONNÉES BRUTES'!Z$3:Z$42)+ROW('DONNÉES BRUTES'!Z$3)),0)),18),"—")} -> Sanofi | Q9: {=IFERROR(INT(_xlfn.AGGREGATE(14,6,'DONNÉES BRUTES'!Z$3:Z$42*1000+(40-ROW('DONNÉES BRUTES'!Z$3:Z$42)+ROW('DONNÉES BRUTES'!Z$3)),2)/1000)&"/100","—")} -> 97/100 | R9: {=IFERROR(INDEX('DONNÉES BRUTES'!U$3:U$42,MATCH(_xlfn.AGGREGATE(14,6,'DONNÉES BRUTES'!Z$3:Z$42*1000+(40-ROW('DONNÉES BRUTES'!Z$3:Z$42)+ROW('DONNÉES BRUTES'!Z$3)),2),'DONNÉES BRUTES'!Z$3:Z$42*1000+(40-ROW('DONNÉES BRUTES'!Z$3:Z$42)+ROW('DONNÉES BRUTES'!Z$3)),0)),"—")} -> — | T9: 2 | U9: {=IFERROR(INDEX('DONNÉES BRUTES'!A$3:A$42,MATCH(_xlfn.AGGREGATE(14,6,'DONNÉES BRUTES'!AA$3:AA$42*1000+(40-ROW('DONNÉES BRUTES'!AA$3:AA$42)+ROW('DONNÉES BRUTES'!AA$3)),2),'DONNÉES BRUTES'!AA$3:AA$42*1000+(40-ROW('DONNÉES BRUTES'!AA$3:AA$42)+ROW('DONNÉES BRUTES'!AA$3)),0)),"—")} -> AIR.PA | V9: {=IFERROR(LEFT(INDEX('DONNÉES BRUTES'!B$3:B$42,MATCH(_xlfn.AGGREGATE(14,6,'DONNÉES BRUTES'!AA$3:AA$42*1000+(40-ROW('DONNÉES BRUTES'!AA$3:AA$42)+ROW('DONNÉES BRUTES'!AA$3)),2),'DONNÉES BRUTES'!AA$3:AA$42*1000+(40-ROW('DONNÉES BRUTES'!AA$3:AA$42)+ROW('DONNÉES BRUTES'!AA$3)),0)),18),"—")} -> Airbus SE | W9: {=IFERROR(INT(_xlfn.AGGREGATE(14,6,'DONNÉES BRUTES'!AA$3:AA$42*1000+(40-ROW('DONNÉES BRUTES'!AA$3:AA$42)+ROW('DONNÉES BRUTES'!AA$3)),2)/1000)&"/100","—")} -> 97/100 | X9: {=IFERROR(INDEX('DONNÉES BRUTES'!P$3:P$42,MATCH(_xlfn.AGGREGATE(14,6,'DONNÉES BRUTES'!AA$3:AA$42*1000+(40-ROW('DONNÉES BRUTES'!AA$3:AA$42)+ROW('DONNÉES BRUTES'!AA$3)),2),'DONNÉES BRUTES'!AA$3:AA$42*1000+(40-ROW('DONNÉES BRUTES'!AA$3:AA$42)+ROW('DONNÉES BRUTES'!AA$3)),0)),"—")} -> +6.1%
B10: 3 | C10: {=IFERROR(INDEX('DONNÉES BRUTES'!A$3:A$42,MATCH(_xlfn.AGGREGATE(14,6,'DONNÉES BRUTES'!AB$3:AB$42*1000+(40-ROW('DONNÉES BRUTES'!AB$3:AB$42)+ROW('DONNÉES BRUTES'!AB$3)),3),'DONNÉES BRUTES'!AB$3:AB$42*1000+(40-ROW('DONNÉES BRUTES'!AB$3:AB$42)+ROW('DONNÉES BRUTES'!AB$3)),0)),"—")} -> DSY.PA | D10: {=IFERROR(LEFT(INDEX('DONNÉES BRUTES'!B$3:B$42,MATCH(_xlfn.AGGREGATE(14,6,'DONNÉES BRUTES'!AB$3:AB$42*1000+(40-ROW('DONNÉES BRUTES'!AB$3:AB$42)+ROW('DONNÉES BRUTES'!AB$3)),3),'DONNÉES BRUTES'!AB$3:AB$42*1000+(40-ROW('DONNÉES BRUTES'!AB$3:AB$42)+ROW('DONNÉES BRUTES'!AB$3)),0)),18),"—")} -> Dassault Systèmes | E10: {=IFERROR(INT(_xlfn.AGGREGATE(14,6,'DONNÉES BRUTES'!AB$3:AB$42*1000+(40-ROW('DONNÉES BRUTES'!AB$3:AB$42)+ROW('DONNÉES BRUTES'!AB$3)),3)/1000)&"/100","—")} -> 72/100 | F10: {=IFERROR(INDEX('DONNÉES BRUTES'!I$3:I$42,MATCH(_xlfn.AGGREGATE(14,6,'DONNÉES BRUTES'!AB$3:AB$42*1000+(40-ROW('DONNÉES BRUTES'!AB$3:AB$42)+ROW('DONNÉES BRUTES'!AB$3)),3),'DONNÉES BRUTES'!AB$3:AB$42*1000+(40-ROW('DONNÉES BRUTES'!AB$3:AB$42)+ROW('DONNÉES BRUTES'!AB$3)),0)),"—")} -> — | H10: 3 | I10: {=IFERROR(INDEX('DONNÉES BRUTES'!A$3:A$42,MATCH(_xlfn.AGGREGATE(14,6,'DONNÉES BRUTES'!Y$3:Y$42*1000+(40-ROW('DONNÉES BRUTES'!Y$3:Y$42)+ROW('DONNÉES BRUTES'!Y$3)),3),'DONNÉES BRUTES'!Y$3:Y$42*1000+(40-ROW('DONNÉES BRUTES'!Y$3:Y$42)+ROW('DONNÉES BRUTES'!Y$3)),0)),"—")} -> ALO.PA | J10: {=IFERROR(LEFT(INDEX('DONNÉES BRUTES'!B$3:B$42,MATCH(_xlfn.AGGREGATE(14,6,'DONNÉES BRUTES'!Y$3:Y$42*1000+(40-ROW('DONNÉES BRUTES'!Y$3:Y$42)+ROW('DONNÉES BRUTES'!Y$3)),3),'DONNÉES BRUTES'!Y$3:Y$42*1000+(40-ROW('DONNÉES BRUTES'!Y$3:Y$42)+ROW('DONNÉES BRUTES'!Y$3)),0)),18),"—")} -> Alstom SA | K10: {=IFERROR(INT(_xlfn.AGGREGATE(14,6,'DONNÉES BRUTES'!Y$3:Y$42*1000+(40-ROW('DONNÉES BRUTES'!Y$3:Y$42)+ROW('DONNÉES BRUTES'!Y$3)),3)/1000)&"/100","—")} -> 95/100 | L10: {=IFERROR(INDEX('DONNÉES BRUTES'!P$3:P$42,MATCH(_xlfn.AGGREGATE(14,6,'DONNÉES BRUTES'!Y$3:Y$42*1000+(40-ROW('DONNÉES BRUTES'!Y$3:Y$42)+ROW('DONNÉES BRUTES'!Y$3)),3),'DONNÉES BRUTES'!Y$3:Y$42*1000+(40-ROW('DONNÉES BRUTES'!Y$3:Y$42)+ROW('DONNÉES BRUTES'!Y$3)),0)),"—")} -> +4.9% | N10: 3 | O10: {=IFERROR(INDEX('DONNÉES BRUTES'!A$3:A$42,MATCH(_xlfn.AGGREGATE(14,6,'DONNÉES BRUTES'!Z$3:Z$42*1000+(40-ROW('DONNÉES BRUTES'!Z$3:Z$42)+ROW('DONNÉES BRUTES'!Z$3)),3),'DONNÉES BRUTES'!Z$3:Z$42*1000+(40-ROW('DONNÉES BRUTES'!Z$3:Z$42)+ROW('DONNÉES BRUTES'!Z$3)),0)),"—")} -> URW.PA | P10: {=IFERROR(LEFT(INDEX('DONNÉES BRUTES'!B$3:B$42,MATCH(_xlfn.AGGREGATE(14,6,'DONNÉES BRUTES'!Z$3:Z$42*1000+(40-ROW('DONNÉES BRUTES'!Z$3:Z$42)+ROW('DONNÉES BRUTES'!Z$3)),3),'DONNÉES BRUTES'!Z$3:Z$42*1000+(40-ROW('DONNÉES BRUTES'!Z$3:Z$42)+ROW('DONNÉES BRUTES'!Z$3)),0)),18),"—")} -> Unibail-Rodamco-We | Q10: {=IFERROR(INT(_xlfn.AGGREGATE(14,6,'DONNÉES BRUTES'!Z$3:Z$42*1000+(40-ROW('DONNÉES BRUTES'!Z$3:Z$42)+ROW('DONNÉES BRUTES'!Z$3)),3)/1000)&"/100","—")} -> 95/100 | R10: {=IFERROR(INDEX('DONNÉES BRUTES'!U$3:U$42,MATCH(_xlfn.AGGREGATE(14,6,'DONNÉES BRUTES'!Z$3:Z$42*1000+(40-ROW('DONNÉES BRUTES'!Z$3:Z$42)+ROW('DONNÉES BRUTES'!Z$3)),3),'DONNÉES BRUTES'!Z$3:Z$42*1000+(40-ROW('DONNÉES BRUTES'!Z$3:Z$42)+ROW('DONNÉES BRUTES'!Z$3)),0)),"—")} -> 1.22 | T10: 3 | U10: {=IFERROR(INDEX('DONNÉES BRUTES'!A$3:A$42,MATCH(_xlfn.AGGREGATE(14,6,'DONNÉES BRUTES'!AA$3:AA$42*1000+(40-ROW('DONNÉES BRUTES'!AA$3:AA$42)+ROW('DONNÉES BRUTES'!AA$3)),3),'DONNÉES BRUTES'!AA$3:AA$42*1000+(40-ROW('DONNÉES BRUTES'!AA$3:AA$42)+ROW('DONNÉES BRUTES'!AA$3)),0)),"—")} -> BNP.PA | V10: {=IFERROR(LEFT(INDEX('DONNÉES BRUTES'!B$3:B$42,MATCH(_xlfn.AGGREGATE(14,6,'DONNÉES BRUTES'!AA$3:AA$42*1000+(40-ROW('DONNÉES BRUTES'!AA$3:AA$42)+ROW('DONNÉES BRUTES'!AA$3)),3),'DONNÉES BRUTES'!AA$3:AA$42*1000+(40-ROW('DONNÉES BRUTES'!AA$3:AA$42)+ROW('DONNÉES BRUTES'!AA$3)),0)),18),"—")} -> BNP Paribas SA | W10: {=IFERROR(INT(_xlfn.AGGREGATE(14,6,'DONNÉES BRUTES'!AA$3:AA$42*1000+(40-ROW('DONNÉES BRUTES'!AA$3:AA$42)+ROW('DONNÉES BRUTES'!AA$3)),3)/1000)&"/100","—")} -> 95/100 | X10: {=IFERROR(INDEX('DONNÉES BRUTES'!P$3:P$42,MATCH(_xlfn.AGGREGATE(14,6,'DONNÉES BRUTES'!AA$3:AA$42*1000+(40-ROW('DONNÉES BRUTES'!AA$3:AA$42)+ROW('DONNÉES BRUTES'!AA$3)),3),'DONNÉES BRUTES'!AA$3:AA$42*1000+(40-ROW('DONNÉES BRUTES'!AA$3:AA$42)+ROW('DONNÉES BRUTES'!AA$3)),0)),"—")} -> +4.5%
B11: 4 | C11: {=IFERROR(INDEX('DONNÉES BRUTES'!A$3:A$42,MATCH(_xlfn.AGGREGATE(14,6,'DONNÉES BRUTES'!AB$3:AB$42*1000+(40-ROW('DONNÉES BRUTES'!AB$3:AB$42)+ROW('DONNÉES BRUTES'!AB$3)),4),'DONNÉES BRUTES'!AB$3:AB$42*1000+(40-ROW('DONNÉES BRUTES'!AB$3:AB$42)+ROW('DONNÉES BRUTES'!AB$3)),0)),"—")} -> ERF.PA | D11: {=IFERROR(LEFT(INDEX('DONNÉES BRUTES'!B$3:B$42,MATCH(_xlfn.AGGREGATE(14,6,'DONNÉES BRUTES'!AB$3:AB$42*1000+(40-ROW('DONNÉES BRUTES'!AB$3:AB$42)+ROW('DONNÉES BRUTES'!AB$3)),4),'DONNÉES BRUTES'!AB$3:AB$42*1000+(40-ROW('DONNÉES BRUTES'!AB$3:AB$42)+ROW('DONNÉES BRUTES'!AB$3)),0)),18),"—")} -> Eurofins Scientifi | E11: {=IFERROR(INT(_xlfn.AGGREGATE(14,6,'DONNÉES BRUTES'!AB$3:AB$42*1000+(40-ROW('DONNÉES BRUTES'!AB$3:AB$42)+ROW('DONNÉES BRUTES'!AB$3)),4)/1000)&"/100","—")} -> 72/100 | F11: {=IFERROR(INDEX('DONNÉES BRUTES'!I$3:I$42,MATCH(_xlfn.AGGREGATE(14,6,'DONNÉES BRUTES'!AB$3:AB$42*1000+(40-ROW('DONNÉES BRUTES'!AB$3:AB$42)+ROW('DONNÉES BRUTES'!AB$3)),4),'DONNÉES BRUTES'!AB$3:AB$42*1000+(40-ROW('DONNÉES BRUTES'!AB$3:AB$42)+ROW('DONNÉES BRUTES'!AB$3)),0)),"—")} -> — | H11: 4 | I11: {=IFERROR(INDEX('DONNÉES BRUTES'!A$3:A$42,MATCH(_xlfn.AGGREGATE(14,6,'DONNÉES BRUTES'!Y$3:Y$42*1000+(40-ROW('DONNÉES BRUTES'!Y$3:Y$42)+ROW('DONNÉES BRUTES'!Y$3)),4),'DONNÉES BRUTES'!Y$3:Y$42*1000+(40-ROW('DONNÉES BRUTES'!Y$3:Y$42)+ROW('DONNÉES BRUTES'!Y$3)),0)),"—")} -> URW.PA | J11: {=IFERROR(LEFT(INDEX('DONNÉES BRUTES'!B$3:B$42,MATCH(_xlfn.AGGREGATE(14,6,'DONNÉES BRUTES'!Y$3:Y$42*1000+(40-ROW('DONNÉES BRUTES'!Y$3:Y$42)+ROW('DONNÉES BRUTES'!Y$3)),4),'DONNÉES BRUTES'!Y$3:Y$42*1000+(40-ROW('DONNÉES BRUTES'!Y$3:Y$42)+ROW('DONNÉES BRUTES'!Y$3)),0)),18),"—")} -> Unibail-Rodamco-We | K11: {=IFERROR(INT(_xlfn.AGGREGATE(14,6,'DONNÉES BRUTES'!Y$3:Y$42*1000+(40-ROW('DONNÉES BRUTES'!Y$3:Y$42)+ROW('DONNÉES BRUTES'!Y$3)),4)/1000)&"/100","—")} -> 92/100 | L11: {=IFERROR(INDEX('DONNÉES BRUTES'!P$3:P$42,MATCH(_xlfn.AGGREGATE(14,6,'DONNÉES BRUTES'!Y$3:Y$42*1000+(40-ROW('DONNÉES BRUTES'!Y$3:Y$42)+ROW('DONNÉES BRUTES'!Y$3)),4),'DONNÉES BRUTES'!Y$3:Y$42*1000+(40-ROW('DONNÉES BRUTES'!Y$3:Y$42)+ROW('DONNÉES BRUTES'!Y$3)),0)),"—")} -> -6.1% | N11: 4 | O11: {=IFERROR(INDEX('DONNÉES BRUTES'!A$3:A$42,MATCH(_xlfn.AGGREGATE(14,6,'DONNÉES BRUTES'!Z$3:Z$42*1000+(40-ROW('DONNÉES BRUTES'!Z$3:Z$42)+ROW('DONNÉES BRUTES'!Z$3)),4),'DONNÉES BRUTES'!Z$3:Z$42*1000+(40-ROW('DONNÉES BRUTES'!Z$3:Z$42)+ROW('DONNÉES BRUTES'!Z$3)),0)),"—")} -> ACA.PA | P11: {=IFERROR(LEFT(INDEX('DONNÉES BRUTES'!B$3:B$42,MATCH(_xlfn.AGGREGATE(14,6,'DONNÉES BRUTES'!Z$3:Z$42*1000+(40-ROW('DONNÉES BRUTES'!Z$3:Z$42)+ROW('DONNÉES BRUTES'!Z$3)),4),'DONNÉES BRUTES'!Z$3:Z$42*1000+(40-ROW('DONNÉES BRUTES'!Z$3:Z$42)+ROW('DONNÉES BRUTES'!Z$3)),0)),18),"—")} -> Crédit Agricole S. | Q11: {=IFERROR(INT(_xlfn.AGGREGATE(14,6,'DONNÉES BRUTES'!Z$3:Z$42*1000+(40-ROW('DONNÉES BRUTES'!Z$3:Z$42)+ROW('DONNÉES BRUTES'!Z$3)),4)/1000)&"/100","—")} -> 92/100 | R11: {=IFERROR(INDEX('DONNÉES BRUTES'!U$3:U$42,MATCH(_xlfn.AGGREGATE(14,6,'DONNÉES BRUTES'!Z$3:Z$42*1000+(40-ROW('DONNÉES BRUTES'!Z$3:Z$42)+ROW('DONNÉES BRUTES'!Z$3)),4),'DONNÉES BRUTES'!Z$3:Z$42*1000+(40-ROW('DONNÉES BRUTES'!Z$3:Z$42)+ROW('DONNÉES BRUTES'!Z$3)),0)),"—")} -> — | T11: 4 | U11: {=IFERROR(INDEX('DONNÉES BRUTES'!A$3:A$42,MATCH(_xlfn.AGGREGATE(14,6,'DONNÉES BRUTES'!AA$3:AA$42*1000+(40-ROW('DONNÉES BRUTES'!AA$3:AA$42)+ROW('DONNÉES BRUTES'!AA$3)),4),'DONNÉES BRUTES'!AA$3:AA$42*1000+(40-ROW('DONNÉES BRUTES'!AA$3:AA$42)+ROW('DONNÉES BRUTES'!AA$3)),0)),"—")} -> CS.PA | V11: {=IFERROR(LEFT(INDEX('DONNÉES BRUTES'!B$3:B$42,MATCH(_xlfn.AGGREGATE(14,6,'DONNÉES BRUTES'!AA$3:AA$42*1000+(40-ROW('DONNÉES BRUTES'!AA$3:AA$42)+ROW('DONNÉES BRUTES'!AA$3)),4),'DONNÉES BRUTES'!AA$3:AA$42*1000+(40-ROW('DONNÉES BRUTES'!AA$3:AA$42)+ROW('DONNÉES BRUTES'!AA$3)),0)),18),"—")} -> AXA SA | W11: {=IFERROR(INT(_xlfn.AGGREGATE(14,6,'DONNÉES BRUTES'!AA$3:AA$42*1000+(40-ROW('DONNÉES BRUTES'!AA$3:AA$42)+ROW('DONNÉES BRUTES'!AA$3)),4)/1000)&"/100","—")} -> 92/100 | X11: {=IFERROR(INDEX('DONNÉES BRUTES'!P$3:P$42,MATCH(_xlfn.AGGREGATE(14,6,'DONNÉES BRUTES'!AA$3:AA$42*1000+(40-ROW('DONNÉES BRUTES'!AA$3:AA$42)+ROW('DONNÉES BRUTES'!AA$3)),4),'DONNÉES BRUTES'!AA$3:AA$42*1000+(40-ROW('DONNÉES BRUTES'!AA$3:AA$42)+ROW('DONNÉES BRUTES'!AA$3)),0)),"—")} -> +5.7%
B12: 5 | C12: {=IFERROR(INDEX('DONNÉES BRUTES'!A$3:A$42,MATCH(_xlfn.AGGREGATE(14,6,'DONNÉES BRUTES'!AB$3:AB$42*1000+(40-ROW('DONNÉES BRUTES'!AB$3:AB$42)+ROW('DONNÉES BRUTES'!AB$3)),5),'DONNÉES BRUTES'!AB$3:AB$42*1000+(40-ROW('DONNÉES BRUTES'!AB$3:AB$42)+ROW('DONNÉES BRUTES'!AB$3)),0)),"—")} -> SAN.PA | D12: {=IFERROR(LEFT(INDEX('DONNÉES BRUTES'!B$3:B$42,MATCH(_xlfn.AGGREGATE(14,6,'DONNÉES BRUTES'!AB$3:AB$42*1000+(40-ROW('DONNÉES BRUTES'!AB$3:AB$42)+ROW('DONNÉES BRUTES'!AB$3)),5),'DONNÉES BRUTES'!AB$3:AB$42*1000+(40-ROW('DONNÉES BRUTES'!AB$3:AB$42)+ROW('DONNÉES BRUTES'!AB$3)),0)),18),"—")} -> Sanofi | E12: {=IFERROR(INT(_xlfn.AGGREGATE(14,6,'DONNÉES BRUTES'!AB$3:AB$42*1000+(40-ROW('DONNÉES BRUTES'!AB$3:AB$42)+ROW('DONNÉES BRUTES'!AB$3)),5)/1000)&"/100","—")} -> 72/100 | F12: {=IFERROR(INDEX('DONNÉES BRUTES'!I$3:I$42,MATCH(_xlfn.AGGREGATE(14,6,'DONNÉES BRUTES'!AB$3:AB$42*1000+(40-ROW('DONNÉES BRUTES'!AB$3:AB$42)+ROW('DONNÉES BRUTES'!AB$3)),5),'DONNÉES BRUTES'!AB$3:AB$42*1000+(40-ROW('DONNÉES BRUTES'!AB$3:AB$42)+ROW('DONNÉES BRUTES'!AB$3)),0)),"—")} -> — | H12: 5 | I12: {=IFERROR(INDEX('DONNÉES BRUTES'!A$3:A$42,MATCH(_xlfn.AGGREGATE(14,6,'DONNÉES BRUTES'!Y$3:Y$42*1000+(40-ROW('DONNÉES BRUTES'!Y$3:Y$42)+ROW('DONNÉES BRUTES'!Y$3)),5),'DONNÉES BRUTES'!Y$3:Y$42*1000+(40-ROW('DONNÉES BRUTES'!Y$3:Y$42)+ROW('DONNÉES BRUTES'!Y$3)),0)),"—")} -> HO.PA | J12: {=IFERROR(LEFT(INDEX('DONNÉES BRUTES'!B$3:B$42,MATCH(_xlfn.AGGREGATE(14,6,'DONNÉES BRUTES'!Y$3:Y$42*1000+(40-ROW('DONNÉES BRUTES'!Y$3:Y$42)+ROW('DONNÉES BRUTES'!Y$3)),5),'DONNÉES BRUTES'!Y$3:Y$42*1000+(40-ROW('DONNÉES BRUTES'!Y$3:Y$42)+ROW('DONNÉES BRUTES'!Y$3)),0)),18),"—")} -> Thales S.A. | K12: {=IFERROR(INT(_xlfn.AGGREGATE(14,6,'DONNÉES BRUTES'!Y$3:Y$42*1000+(40-ROW('DONNÉES BRUTES'!Y$3:Y$42)+ROW('DONNÉES BRUTES'!Y$3)),5)/1000)&"/100","—")} -> 89/100 | L12: {=IFERROR(INDEX('DONNÉES BRUTES'!P$3:P$42,MATCH(_xlfn.AGGREGATE(14,6,'DONNÉES BRUTES'!Y$3:Y$42*1000+(40-ROW('DONNÉES BRUTES'!Y$3:Y$42)+ROW('DONNÉES BRUTES'!Y$3)),5),'DONNÉES BRUTES'!Y$3:Y$42*1000+(40-ROW('DONNÉES BRUTES'!Y$3:Y$42)+ROW('DONNÉES BRUTES'!Y$3)),0)),"—")} -> +7.6% | N12: 5 | O12: {=IFERROR(INDEX('DONNÉES BRUTES'!A$3:A$42,MATCH(_xlfn.AGGREGATE(14,6,'DONNÉES BRUTES'!Z$3:Z$42*1000+(40-ROW('DONNÉES BRUTES'!Z$3:Z$42)+ROW('DONNÉES BRUTES'!Z$3)),5),'DONNÉES BRUTES'!Z$3:Z$42*1000+(40-ROW('DONNÉES BRUTES'!Z$3:Z$42)+ROW('DONNÉES BRUTES'!Z$3)),0)),"—")} -> RMS.PA | P12: {=IFERROR(LEFT(INDEX('DONNÉES BRUTES'!B$3:B$42,MATCH(_xlfn.AGGREGATE(14,6,'DONNÉES BRUTES'!Z$3:Z$42*1000+(40-ROW('DONNÉES BRUTES'!Z$3:Z$42)+ROW('DONNÉES BRUTES'!Z$3)),5),'DONNÉES BRUTES'!Z$3:Z$42*1000+(40-ROW('DONNÉES BRUTES'!Z$3:Z$42)+ROW('DONNÉES BRUTES'!Z$3)),0)),18),"—")} -> Hermès Internation | Q12: {=IFERROR(INT(_xlfn.AGGREGATE(14,6,'DONNÉES BRUTES'!Z$3:Z$42*1000+(40-ROW('DONNÉES BRUTES'!Z$3:Z$42)+ROW('DONNÉES BRUTES'!Z$3)),5)/1000)&"/100","—")} -> 90/100 | R12: {=IFERROR(INDEX('DONNÉES BRUTES'!U$3:U$42,MATCH(_xlfn.AGGREGATE(14,6,'DONNÉES BRUTES'!Z$3:Z$42*1000+(40-ROW('DONNÉES BRUTES'!Z$3:Z$42)+ROW('DONNÉES BRUTES'!Z$3)),5),'DONNÉES BRUTES'!Z$3:Z$42*1000+(40-ROW('DONNÉES BRUTES'!Z$3:Z$42)+ROW('DONNÉES BRUTES'!Z$3)),0)),"—")} -> 9.47 | T12: 5 | U12: {=IFERROR(INDEX('DONNÉES BRUTES'!A$3:A$42,MATCH(_xlfn.AGGREGATE(14,6,'DONNÉES BRUTES'!AA$3:AA$42*1000+(40-ROW('DONNÉES BRUTES'!AA$3:AA$42)+ROW('DONNÉES BRUTES'!AA$3)),5),'DONNÉES BRUTES'!AA$3:AA$42*1000+(40-ROW('DONNÉES BRUTES'!AA$3:AA$42)+ROW('DONNÉES BRUTES'!AA$3)),0)),"—")} -> AI.PA | V12: {=IFERROR(LEFT(INDEX('DONNÉES BRUTES'!B$3:B$42,MATCH(_xlfn.AGGREGATE(14,6,'DONNÉES BRUTES'!AA$3:AA$42*1000+(40-ROW('DONNÉES BRUTES'!AA$3:AA$42)+ROW('DONNÉES BRUTES'!AA$3)),5),'DONNÉES BRUTES'!AA$3:AA$42*1000+(40-ROW('DONNÉES BRUTES'!AA$3:AA$42)+ROW('DONNÉES BRUTES'!AA$3)),0)),18),"—")} -> L'Air Liquide S.A. | W12: {=IFERROR(INT(_xlfn.AGGREGATE(14,6,'DONNÉES BRUTES'!AA$3:AA$42*1000+(40-ROW('DONNÉES BRUTES'!AA$3:AA$42)+ROW('DONNÉES BRUTES'!AA$3)),5)/1000)&"/100","—")} -> 90/100 | X12: {=IFERROR(INDEX('DONNÉES BRUTES'!P$3:P$42,MATCH(_xlfn.AGGREGATE(14,6,'DONNÉES BRUTES'!AA$3:AA$42*1000+(40-ROW('DONNÉES BRUTES'!AA$3:AA$42)+ROW('DONNÉES BRUTES'!AA$3)),5),'DONNÉES BRUTES'!AA$3:AA$42*1000+(40-ROW('DONNÉES BRUTES'!AA$3:AA$42)+ROW('DONNÉES BRUTES'!AA$3)),0)),"—")} -> -0.4%
B14: TOP 10 GLOBAL · Score Composite · Value / Growth / Quality / Momentum
B15: # | C15: Ticker | D15: Société | E15: Secteur | F15: Score | H15: Growth | I15: Quality | J15: Momentum | K15: Mg.EBITDA | L15: Croiss. | N15: Next Earn. | R15: Signal
B16: 1 | C16: {=IFERROR(INDEX('DONNÉES BRUTES'!A$3:A$42,MATCH(_xlfn.AGGREGATE(14,6,'DONNÉES BRUTES'!AB$3:AB$42*1000+(40-ROW('DONNÉES BRUTES'!AB$3:AB$42)+ROW('DONNÉES BRUTES'!AB$3)),1),'DONNÉES BRUTES'!AB$3:AB$42*1000+(40-ROW('DONNÉES BRUTES'!AB$3:AB$42)+ROW('DONNÉES BRUTES'!AB$3)),0)),"—")} -> RMS.PA | D16: {=IFERROR(LEFT(IFERROR(INDEX('DONNÉES BRUTES'!B$3:B$42,MATCH(_xlfn.AGGREGATE(14,6,'DONNÉES BRUTES'!AB$3:AB$42*1000+(40-ROW('DONNÉES BRUTES'!AB$3:AB$42)+ROW('DONNÉES BRUTES'!AB$3)),1),'DONNÉES BRUTES'!AB$3:AB$42*1000+(40-ROW('DONNÉES BRUTES'!AB$3:AB$42)+ROW('DONNÉES BRUTES'!AB$3)),0)),"—"),18),"—")} -> Hermès Internation | E16: {=IFERROR(INDEX('DONNÉES BRUTES'!C$3:C$42,MATCH(_xlfn.AGGREGATE(14,6,'DONNÉES BRUTES'!AB$3:AB$42*1000+(40-ROW('DONNÉES BRUTES'!AB$3:AB$42)+ROW('DONNÉES BRUTES'!AB$3)),1),'DONNÉES BRUTES'!AB$3:AB$42*1000+(40-ROW('DONNÉES BRUTES'!AB$3:AB$42)+ROW('DONNÉES BRUTES'!AB$3)),0)),"—")} -> Consumer Disc. | F16: {=IFERROR(INT(_xlfn.AGGREGATE(14,6,'DONNÉES BRUTES'!AB$3:AB$42*1000+(40-ROW('DONNÉES BRUTES'!AB$3:AB$42)+ROW('DONNÉES BRUTES'!AB$3)),1)/1000)&"/100","—")} -> 75/100 | H16: {=IFERROR(INDEX('DONNÉES BRUTES'!Y$3:Y$42,MATCH(_xlfn.AGGREGATE(14,6,'DONNÉES BRUTES'!AB$3:AB$42*1000+(40-ROW('DONNÉES BRUTES'!AB$3:AB$42)+ROW('DONNÉES BRUTES'!AB$3)),1),'DONNÉES BRUTES'!AB$3:AB$42*1000+(40-ROW('DONNÉES BRUTES'!AB$3:AB$42)+ROW('DONNÉES BRUTES'!AB$3)),0)),"—")} -> 74 | I16: {=IFERROR(INDEX('DONNÉES BRUTES'!Z$3:Z$42,MATCH(_xlfn.AGGREGATE(14,6,'DONNÉES BRUTES'!AB$3:AB$42*1000+(40-ROW('DONNÉES BRUTES'!AB$3:AB$42)+ROW('DONNÉES BRUTES'!AB$3)),1),'DONNÉES BRUTES'!AB$3:AB$42*1000+(40-ROW('DONNÉES BRUTES'!AB$3:AB$42)+ROW('DONNÉES BRUTES'!AB$3)),0)),"—")} -> 90 | J16: {=IFERROR(INDEX('DONNÉES BRUTES'!AA$3:AA$42,MATCH(_xlfn.AGGREGATE(14,6,'DONNÉES BRUTES'!AB$3:AB$42*1000+(40-ROW('DONNÉES BRUTES'!AB$3:AB$42)+ROW('DONNÉES BRUTES'!AB$3)),1),'DONNÉES BRUTES'!AB$3:AB$42*1000+(40-ROW('DONNÉES BRUTES'!AB$3:AB$42)+ROW('DONNÉES BRUTES'!AB$3)),0)),"—")} -> 62 | K16: {=IFERROR(INDEX('DONNÉES BRUTES'!N$3:N$42,MATCH(_xlfn.AGGREGATE(14,6,'DONNÉES BRUTES'!AB$3:AB$42*1000+(40-ROW('DONNÉES BRUTES'!AB$3:AB$42)+ROW('DONNÉES BRUTES'!AB$3)),1),'DONNÉES BRUTES'!AB$3:AB$42*1000+(40-ROW('DONNÉES BRUTES'!AB$3:AB$42)+ROW('DONNÉES BRUTES'!AB$3)),0)),"—")} -> 46.8% | L16: {=IFERROR(INDEX('DONNÉES BRUTES'!P$3:P$42,MATCH(_xlfn.AGGREGATE(14,6,'DONNÉES BRUTES'!AB$3:AB$42*1000+(40-ROW('DONNÉES BRUTES'!AB$3:AB$42)+ROW('DONNÉES BRUTES'!AB$3)),1),'DONNÉES BRUTES'!AB$3:AB$42*1000+(40-ROW('DONNÉES BRUTES'!AB$3:AB$42)+ROW('DONNÉES BRUTES'!AB$3)),0)),"—")} -> +5.5% | N16: {=IFERROR(INDEX('DONNÉES BRUTES'!AC$3:AC$42,MATCH(_xlfn.AGGREGATE(14,6,'DONNÉES BRUTES'!AB$3:AB$42*1000+(40-ROW('DONNÉES BRUTES'!AB$3:AB$42)+ROW('DONNÉES BRUTES'!AB$3)),1),'DONNÉES BRUTES'!AB$3:AB$42*1000+(40-ROW('DONNÉES BRUTES'!AB$3:AB$42)+ROW('DONNÉES BRUTES'!AB$3)),0)),"—")} -> — | R16: {=IFERROR(INDEX('DONNÉES BRUTES'!AD$3:AD$42,MATCH(_xlfn.AGGREGATE(14,6,'DONNÉES BRUTES'!AB$3:AB$42*1000+(40-ROW('DONNÉES BRUTES'!AB$3:AB$42)+ROW('DONNÉES BRUTES'!AB$3)),1),'DONNÉES BRUTES'!AB$3:AB$42*1000+(40-ROW('DONNÉES BRUTES'!AB$3:AB$42)+ROW('DONNÉES BRUTES'!AB$3)),0)),"—")} -> Surpondérer
B17: 2 | C17: {=IFERROR(INDEX('DONNÉES BRUTES'!A$3:A$42,MATCH(_xlfn.AGGREGATE(14,6,'DONNÉES BRUTES'!AB$3:AB$42*1000+(40-ROW('DONNÉES BRUTES'!AB$3:AB$42)+ROW('DONNÉES BRUTES'!AB$3)),2),'DONNÉES BRUTES'!AB$3:AB$42*1000+(40-ROW('DONNÉES BRUTES'!AB$3:AB$42)+ROW('DONNÉES BRUTES'!AB$3)),0)),"—")} -> AI.PA | D17: {=IFERROR(LEFT(IFERROR(INDEX('DONNÉES BRUTES'!B$3:B$42,MATCH(_xlfn.AGGREGATE(14,6,'DONNÉES BRUTES'!AB$3:AB$42*1000+(40-ROW('DONNÉES BRUTES'!AB$3:AB$42)+ROW('DONNÉES BRUTES'!AB$3)),2),'DONNÉES BRUTES'!AB$3:AB$42*1000+(40-ROW('DONNÉES BRUTES'!AB$3:AB$42)+ROW('DONNÉES BRUTES'!AB$3)),0)),"—"),18),"—")} -> L'Air Liquide S.A. | E17: {=IFERROR(INDEX('DONNÉES BRUTES'!C$3:C$42,MATCH(_xlfn.AGGREGATE(14,6,'DONNÉES BRUTES'!AB$3:AB$42*1000+(40-ROW('DONNÉES BRUTES'!AB$3:AB$42)+ROW('DONNÉES BRUTES'!AB$3)),2),'DONNÉES BRUTES'!AB$3:AB$42*1000+(40-ROW('DONNÉES BRUTES'!AB$3:AB$42)+ROW('DONNÉES BRUTES'!AB$3)),0)),"—")} -> Materials | F17: {=IFERROR(INT(_xlfn.AGGREGATE(14,6,'DONNÉES BRUTES'!AB$3:AB$42*1000+(40-ROW('DONNÉES BRUTES'!AB$3:AB$42)+ROW('DONNÉES BRUTES'!AB$3)),2)/1000)&"/100","—")} -> 74/100 | H17: {=IFERROR(INDEX('DONNÉES BRUTES'!Y$3:Y$42,MATCH(_xlfn.AGGREGATE(14,6,'DONNÉES BRUTES'!AB$3:AB$42*1000+(40-ROW('DONNÉES BRUTES'!AB$3:AB$42)+ROW('DONNÉES BRUTES'!AB$3)),2),'DONNÉES BRUTES'!AB$3:AB$42*1000+(40-ROW('DONNÉES BRUTES'!AB$3:AB$42)+ROW('DONNÉES BRUTES'!AB$3)),0)),"—")} -> 55 | I17: {=IFERROR(INDEX('DONNÉES BRUTES'!Z$3:Z$42,MATCH(_xlfn.AGGREGATE(14,6,'DONNÉES BRUTES'!AB$3:AB$42*1000+(40-ROW('DONNÉES BRUTES'!AB$3:AB$42)+ROW('DONNÉES BRUTES'!AB$3)),2),'DONNÉES BRUTES'!AB$3:AB$42*1000+(40-ROW('DONNÉES BRUTES'!AB$3:AB$42)+ROW('DONNÉES BRUTES'!AB$3)),0)),"—")} -> 77 | J17: {=IFERROR(INDEX('DONNÉES BRUTES'!AA$3:AA$42,MATCH(_xlfn.AGGREGATE(14,6,'DONNÉES BRUTES'!AB$3:AB$42*1000+(40-ROW('DONNÉES BRUTES'!AB$3:AB$42)+ROW('DONNÉES BRUTES'!AB$3)),2),'DONNÉES BRUTES'!AB$3:AB$42*1000+(40-ROW('DONNÉES BRUTES'!AB$3:AB$42)+ROW('DONNÉES BRUTES'!AB$3)),0)),"—")} -> 90 | K17: {=IFERROR(INDEX('DONNÉES BRUTES'!N$3:N$42,MATCH(_xlfn.AGGREGATE(14,6,'DONNÉES BRUTES'!AB$3:AB$42*1000+(40-ROW('DONNÉES BRUTES'!AB$3:AB$42)+ROW('DONNÉES BRUTES'!AB$3)),2),'DONNÉES BRUTES'!AB$3:AB$42*1000+(40-ROW('DONNÉES BRUTES'!AB$3:AB$42)+ROW('DONNÉES BRUTES'!AB$3)),0)),"—")} -> 27.9% | L17: {=IFERROR(INDEX('DONNÉES BRUTES'!P$3:P$42,MATCH(_xlfn.AGGREGATE(14,6,'DONNÉES BRUTES'!AB$3:AB$42*1000+(40-ROW('DONNÉES BRUTES'!AB$3:AB$42)+ROW('DONNÉES BRUTES'!AB$3)),2),'DONNÉES BRUTES'!AB$3:AB$42*1000+(40-ROW('DONNÉES BRUTES'!AB$3:AB$42)+ROW('DONNÉES BRUTES'!AB$3)),0)),"—")} -> -0.4% | N17: {=IFERROR(INDEX('DONNÉES BRUTES'!AC$3:AC$42,MATCH(_xlfn.AGGREGATE(14,6,'DONNÉES BRUTES'!AB$3:AB$42*1000+(40-ROW('DONNÉES BRUTES'!AB$3:AB$42)+ROW('DONNÉES BRUTES'!AB$3)),2),'DONNÉES BRUTES'!AB$3:AB$42*1000+(40-ROW('DONNÉES BRUTES'!AB$3:AB$42)+ROW('DONNÉES BRUTES'!AB$3)),0)),"—")} -> — | R17: {=IFERROR(INDEX('DONNÉES BRUTES'!AD$3:AD$42,MATCH(_xlfn.AGGREGATE(14,6,'DONNÉES BRUTES'!AB$3:AB$42*1000+(40-ROW('DONNÉES BRUTES'!AB$3:AB$42)+ROW('DONNÉES BRUTES'!AB$3)),2),'DONNÉES BRUTES'!AB$3:AB$42*1000+(40-ROW('DONNÉES BRUTES'!AB$3:AB$42)+ROW('DONNÉES BRUTES'!AB$3)),0)),"—")} -> Neutre
B18: 3 | C18: {=IFERROR(INDEX('DONNÉES BRUTES'!A$3:A$42,MATCH(_xlfn.AGGREGATE(14,6,'DONNÉES BRUTES'!AB$3:AB$42*1000+(40-ROW('DONNÉES BRUTES'!AB$3:AB$42)+ROW('DONNÉES BRUTES'!AB$3)),3),'DONNÉES BRUTES'!AB$3:AB$42*1000+(40-ROW('DONNÉES BRUTES'!AB$3:AB$42)+ROW('DONNÉES BRUTES'!AB$3)),0)),"—")} -> DSY.PA | D18: {=IFERROR(LEFT(IFERROR(INDEX('DONNÉES BRUTES'!B$3:B$42,MATCH(_xlfn.AGGREGATE(14,6,'DONNÉES BRUTES'!AB$3:AB$42*1000+(40-ROW('DONNÉES BRUTES'!AB$3:AB$42)+ROW('DONNÉES BRUTES'!AB$3)),3),'DONNÉES BRUTES'!AB$3:AB$42*1000+(40-ROW('DONNÉES BRUTES'!AB$3:AB$42)+ROW('DONNÉES BRUTES'!AB$3)),0)),"—"),18),"—")} -> Dassault Systèmes | E18: {=IFERROR(INDEX('DONNÉES BRUTES'!C$3:C$42,MATCH(_xlfn.AGGREGATE(14,6,'DONNÉES BRUTES'!AB$3:AB$42*1000+(40-ROW('DONNÉES BRUTES'!AB$3:AB$42)+ROW('DONNÉES BRUTES'!AB$3)),3),'DONNÉES BRUTES'!AB$3:AB$42*1000+(40-ROW('DONNÉES BRUTES'!AB$3:AB$42)+ROW('DONNÉES BRUTES'!AB$3)),0)),"—")} -> Technology | F18: {=IFERROR(INT(_xlfn.AGGREGATE(14,6,'DONNÉES BRUTES'!AB$3:AB$42*1000+(40-ROW('DONNÉES BRUTES'!AB$3:AB$42)+ROW('DONNÉES BRUTES'!AB$3)),3)/1000)&"/100","—")} -> 72/100 | H18: {=IFERROR(INDEX('DONNÉES BRUTES'!Y$3:Y$42,MATCH(_xlfn.AGGREGATE(14,6,'DONNÉES BRUTES'!AB$3:AB$42*1000+(40-ROW('DONNÉES BRUTES'!AB$3:AB$42)+ROW('DONNÉES BRUTES'!AB$3)),3),'DONNÉES BRUTES'!AB$3:AB$42*1000+(40-ROW('DONNÉES BRUTES'!AB$3:AB$42)+ROW('DONNÉES BRUTES'!AB$3)),0)),"—")} -> 42 | I18: {=IFERROR(INDEX('DONNÉES BRUTES'!Z$3:Z$42,MATCH(_xlfn.AGGREGATE(14,6,'DONNÉES BRUTES'!AB$3:AB$42*1000+(40-ROW('DONNÉES BRUTES'!AB$3:AB$42)+ROW('DONNÉES BRUTES'!AB$3)),3),'DONNÉES BRUTES'!AB$3:AB$42*1000+(40-ROW('DONNÉES BRUTES'!AB$3:AB$42)+ROW('DONNÉES BRUTES'!AB$3)),0)),"—")} -> 100 | J18: {=IFERROR(INDEX('DONNÉES BRUTES'!AA$3:AA$42,MATCH(_xlfn.AGGREGATE(14,6,'DONNÉES BRUTES'!AB$3:AB$42*1000+(40-ROW('DONNÉES BRUTES'!AB$3:AB$42)+ROW('DONNÉES BRUTES'!AB$3)),3),'DONNÉES BRUTES'!AB$3:AB$42*1000+(40-ROW('DONNÉES BRUTES'!AB$3:AB$42)+ROW('DONNÉES BRUTES'!AB$3)),0)),"—")} -> 74 | K18: {=IFERROR(INDEX('DONNÉES BRUTES'!N$3:N$42,MATCH(_xlfn.AGGREGATE(14,6,'DONNÉES BRUTES'!AB$3:AB$42*1000+(40-ROW('DONNÉES BRUTES'!AB$3:AB$42)+ROW('DONNÉES BRUTES'!AB$3)),3),'DONNÉES BRUTES'!AB$3:AB$42*1000+(40-ROW('DONNÉES BRUTES'!AB$3:AB$42)+ROW('DONNÉES BRUTES'!AB$3)),0)),"—")} -> 30.4% | L18: {=IFERROR(INDEX('DONNÉES BRUTES'!P$3:P$42,MATCH(_xlfn.AGGREGATE(14,6,'DONNÉES BRUTES'!AB$3:AB$42*1000+(40-ROW('DONNÉES BRUTES'!AB$3:AB$42)+ROW('DONNÉES BRUTES'!AB$3)),3),'DONNÉES BRUTES'!AB$3:AB$42*1000+(40-ROW('DONNÉES BRUTES'!AB$3:AB$42)+ROW('DONNÉES BRUTES'!AB$3)),0)),"—")} -> +0.4% | N18: {=IFERROR(INDEX('DONNÉES BRUTES'!AC$3:AC$42,MATCH(_xlfn.AGGREGATE(14,6,'DONNÉES BRUTES'!AB$3:AB$42*1000+(40-ROW('DONNÉES BRUTES'!AB$3:AB$42)+ROW('DONNÉES BRUTES'!AB$3)),3),'DONNÉES BRUTES'!AB$3:AB$42*1000+(40-ROW('DONNÉES BRUTES'!AB$3:AB$42)+ROW('DONNÉES BRUTES'!AB$3)),0)),"—")} -> 2026-04-23 | R18: {=IFERROR(INDEX('DONNÉES BRUTES'!AD$3:AD$42,MATCH(_xlfn.AGGREGATE(14,6,'DONNÉES BRUTES'!AB$3:AB$42*1000+(40-ROW('DONNÉES BRUTES'!AB$3:AB$42)+ROW('DONNÉES BRUTES'!AB$3)),3),'DONNÉES BRUTES'!AB$3:AB$42*1000+(40-ROW('DONNÉES BRUTES'!AB$3:AB$42)+ROW('DONNÉES BRUTES'!AB$3)),0)),"—")} -> Neutre
B19: 4 | C19: {=IFERROR(INDEX('DONNÉES BRUTES'!A$3:A$42,MATCH(_xlfn.AGGREGATE(14,6,'DONNÉES BRUTES'!AB$3:AB$42*1000+(40-ROW('DONNÉES BRUTES'!AB$3:AB$42)+ROW('DONNÉES BRUTES'!AB$3)),4),'DONNÉES BRUTES'!AB$3:AB$42*1000+(40-ROW('DONNÉES BRUTES'!AB$3:AB$42)+ROW('DONNÉES BRUTES'!AB$3)),0)),"—")} -> ERF.PA | D19: {=IFERROR(LEFT(IFERROR(INDEX('DONNÉES BRUTES'!B$3:B$42,MATCH(_xlfn.AGGREGATE(14,6,'DONNÉES BRUTES'!AB$3:AB$42*1000+(40-ROW('DONNÉES BRUTES'!AB$3:AB$42)+ROW('DONNÉES BRUTES'!AB$3)),4),'DONNÉES BRUTES'!AB$3:AB$42*1000+(40-ROW('DONNÉES BRUTES'!AB$3:AB$42)+ROW('DONNÉES BRUTES'!AB$3)),0)),"—"),18),"—")} -> Eurofins Scientifi | E19: {=IFERROR(INDEX('DONNÉES BRUTES'!C$3:C$42,MATCH(_xlfn.AGGREGATE(14,6,'DONNÉES BRUTES'!AB$3:AB$42*1000+(40-ROW('DONNÉES BRUTES'!AB$3:AB$42)+ROW('DONNÉES BRUTES'!AB$3)),4),'DONNÉES BRUTES'!AB$3:AB$42*1000+(40-ROW('DONNÉES BRUTES'!AB$3:AB$42)+ROW('DONNÉES BRUTES'!AB$3)),0)),"—")} -> Healthcare | F19: {=IFERROR(INT(_xlfn.AGGREGATE(14,6,'DONNÉES BRUTES'!AB$3:AB$42*1000+(40-ROW('DONNÉES BRUTES'!AB$3:AB$42)+ROW('DONNÉES BRUTES'!AB$3)),4)/1000)&"/100","—")} -> 72/100 | H19: {=IFERROR(INDEX('DONNÉES BRUTES'!Y$3:Y$42,MATCH(_xlfn.AGGREGATE(14,6,'DONNÉES BRUTES'!AB$3:AB$42*1000+(40-ROW('DONNÉES BRUTES'!AB$3:AB$42)+ROW('DONNÉES BRUTES'!AB$3)),4),'DONNÉES BRUTES'!AB$3:AB$42*1000+(40-ROW('DONNÉES BRUTES'!AB$3:AB$42)+ROW('DONNÉES BRUTES'!AB$3)),0)),"—")} -> 76 | I19: {=IFERROR(INDEX('DONNÉES BRUTES'!Z$3:Z$42,MATCH(_xlfn.AGGREGATE(14,6,'DONNÉES BRUTES'!AB$3:AB$42*1000+(40-ROW('DONNÉES BRUTES'!AB$3:AB$42)+ROW('DONNÉES BRUTES'!AB$3)),4),'DONNÉES BRUTES'!AB$3:AB$42*1000+(40-ROW('DONNÉES BRUTES'!AB$3:AB$42)+ROW('DONNÉES BRUTES'!AB$3)),0)),"—")} -> 72 | J19: {=IFERROR(INDEX('DONNÉES BRUTES'!AA$3:AA$42,MATCH(_xlfn.AGGREGATE(14,6,'DONNÉES BRUTES'!AB$3:AB$42*1000+(40-ROW('DONNÉES BRUTES'!AB$3:AB$42)+ROW('DONNÉES BRUTES'!AB$3)),4),'DONNÉES BRUTES'!AB$3:AB$42*1000+(40-ROW('DONNÉES BRUTES'!AB$3:AB$42)+ROW('DONNÉES BRUTES'!AB$3)),0)),"—")} -> 67 | K19: {=IFERROR(INDEX('DONNÉES BRUTES'!N$3:N$42,MATCH(_xlfn.AGGREGATE(14,6,'DONNÉES BRUTES'!AB$3:AB$42*1000+(40-ROW('DONNÉES BRUTES'!AB$3:AB$42)+ROW('DONNÉES BRUTES'!AB$3)),4),'DONNÉES BRUTES'!AB$3:AB$42*1000+(40-ROW('DONNÉES BRUTES'!AB$3:AB$42)+ROW('DONNÉES BRUTES'!AB$3)),0)),"—")} -> 21.0% | L19: {=IFERROR(INDEX('DONNÉES BRUTES'!P$3:P$42,MATCH(_xlfn.AGGREGATE(14,6,'DONNÉES BRUTES'!AB$3:AB$42*1000+(40-ROW('DONNÉES BRUTES'!AB$3:AB$42)+ROW('DONNÉES BRUTES'!AB$3)),4),'DONNÉES BRUTES'!AB$3:AB$42*1000+(40-ROW('DONNÉES BRUTES'!AB$3:AB$42)+ROW('DONNÉES BRUTES'!AB$3)),0)),"—")} -> +5.0% | N19: {=IFERROR(INDEX('DONNÉES BRUTES'!AC$3:AC$42,MATCH(_xlfn.AGGREGATE(14,6,'DONNÉES BRUTES'!AB$3:AB$42*1000+(40-ROW('DONNÉES BRUTES'!AB$3:AB$42)+ROW('DONNÉES BRUTES'!AB$3)),4),'DONNÉES BRUTES'!AB$3:AB$42*1000+(40-ROW('DONNÉES BRUTES'!AB$3:AB$42)+ROW('DONNÉES BRUTES'!AB$3)),0)),"—")} -> — | R19: {=IFERROR(INDEX('DONNÉES BRUTES'!AD$3:AD$42,MATCH(_xlfn.AGGREGATE(14,6,'DONNÉES BRUTES'!AB$3:AB$42*1000+(40-ROW('DONNÉES BRUTES'!AB$3:AB$42)+ROW('DONNÉES BRUTES'!AB$3)),4),'DONNÉES BRUTES'!AB$3:AB$42*1000+(40-ROW('DONNÉES BRUTES'!AB$3:AB$42)+ROW('DONNÉES BRUTES'!AB$3)),0)),"—")} -> Neutre
B20: 5 | C20: {=IFERROR(INDEX('DONNÉES BRUTES'!A$3:A$42,MATCH(_xlfn.AGGREGATE(14,6,'DONNÉES BRUTES'!AB$3:AB$42*1000+(40-ROW('DONNÉES BRUTES'!AB$3:AB$42)+ROW('DONNÉES BRUTES'!AB$3)),5),'DONNÉES BRUTES'!AB$3:AB$42*1000+(40-ROW('DONNÉES BRUTES'!AB$3:AB$42)+ROW('DONNÉES BRUTES'!AB$3)),0)),"—")} -> SAN.PA | D20: {=IFERROR(LEFT(IFERROR(INDEX('DONNÉES BRUTES'!B$3:B$42,MATCH(_xlfn.AGGREGATE(14,6,'DONNÉES BRUTES'!AB$3:AB$42*1000+(40-ROW('DONNÉES BRUTES'!AB$3:AB$42)+ROW('DONNÉES BRUTES'!AB$3)),5),'DONNÉES BRUTES'!AB$3:AB$42*1000+(40-ROW('DONNÉES BRUTES'!AB$3:AB$42)+ROW('DONNÉES BRUTES'!AB$3)),0)),"—"),18),"—")} -> Sanofi | E20: {=IFERROR(INDEX('DONNÉES BRUTES'!C$3:C$42,MATCH(_xlfn.AGGREGATE(14,6,'DONNÉES BRUTES'!AB$3:AB$42*1000+(40-ROW('DONNÉES BRUTES'!AB$3:AB$42)+ROW('DONNÉES BRUTES'!AB$3)),5),'DONNÉES BRUTES'!AB$3:AB$42*1000+(40-ROW('DONNÉES BRUTES'!AB$3:AB$42)+ROW('DONNÉES BRUTES'!AB$3)),0)),"—")} -> Healthcare | F20: {=IFERROR(INT(_xlfn.AGGREGATE(14,6,'DONNÉES BRUTES'!AB$3:AB$42*1000+(40-ROW('DONNÉES BRUTES'!AB$3:AB$42)+ROW('DONNÉES BRUTES'!AB$3)),5)/1000)&"/100","—")} -> 72/100 | H20: {=IFERROR(INDEX('DONNÉES BRUTES'!Y$3:Y$42,MATCH(_xlfn.AGGREGATE(14,6,'DONNÉES BRUTES'!AB$3:AB$42*1000+(40-ROW('DONNÉES BRUTES'!AB$3:AB$42)+ROW('DONNÉES BRUTES'!AB$3)),5),'DONNÉES BRUTES'!AB$3:AB$42*1000+(40-ROW('DONNÉES BRUTES'!AB$3:AB$42)+ROW('DONNÉES BRUTES'!AB$3)),0)),"—")} -> 87 | I20: {=IFERROR(INDEX('DONNÉES BRUTES'!Z$3:Z$42,MATCH(_xlfn.AGGREGATE(14,6,'DONNÉES BRUTES'!AB$3:AB$42*1000+(40-ROW('DONNÉES BRUTES'!AB$3:AB$42)+ROW('DONNÉES BRUTES'!AB$3)),5),'DONNÉES BRUTES'!AB$3:AB$42*1000+(40-ROW('DONNÉES BRUTES'!AB$3:AB$42)+ROW('DONNÉES BRUTES'!AB$3)),0)),"—")} -> 97 | J20: {=IFERROR(INDEX('DONNÉES BRUTES'!AA$3:AA$42,MATCH(_xlfn.AGGREGATE(14,6,'DONNÉES BRUTES'!AB$3:AB$42*1000+(40-ROW('DONNÉES BRUTES'!AB$3:AB$42)+ROW('DONNÉES BRUTES'!AB$3)),5),'DONNÉES BRUTES'!AB$3:AB$42*1000+(40-ROW('DONNÉES BRUTES'!AB$3:AB$42)+ROW('DONNÉES BRUTES'!AB$3)),0)),"—")} -> 31 | K20: {=IFERROR(INDEX('DONNÉES BRUTES'!N$3:N$42,MATCH(_xlfn.AGGREGATE(14,6,'DONNÉES BRUTES'!AB$3:AB$42*1000+(40-ROW('DONNÉES BRUTES'!AB$3:AB$42)+ROW('DONNÉES BRUTES'!AB$3)),5),'DONNÉES BRUTES'!AB$3:AB$42*1000+(40-ROW('DONNÉES BRUTES'!AB$3:AB$42)+ROW('DONNÉES BRUTES'!AB$3)),0)),"—")} -> 26.7% | L20: {=IFERROR(INDEX('DONNÉES BRUTES'!P$3:P$42,MATCH(_xlfn.AGGREGATE(14,6,'DONNÉES BRUTES'!AB$3:AB$42*1000+(40-ROW('DONNÉES BRUTES'!AB$3:AB$42)+ROW('DONNÉES BRUTES'!AB$3)),5),'DONNÉES BRUTES'!AB$3:AB$42*1000+(40-ROW('DONNÉES BRUTES'!AB$3:AB$42)+ROW('DONNÉES BRUTES'!AB$3)),0)),"—")} -> +5.5% | N20: {=IFERROR(INDEX('DONNÉES BRUTES'!AC$3:AC$42,MATCH(_xlfn.AGGREGATE(14,6,'DONNÉES BRUTES'!AB$3:AB$42*1000+(40-ROW('DONNÉES BRUTES'!AB$3:AB$42)+ROW('DONNÉES BRUTES'!AB$3)),5),'DONNÉES BRUTES'!AB$3:AB$42*1000+(40-ROW('DONNÉES BRUTES'!AB$3:AB$42)+ROW('DONNÉES BRUTES'!AB$3)),0)),"—")} -> 2026-04-23 | R20: {=IFERROR(INDEX('DONNÉES BRUTES'!AD$3:AD$42,MATCH(_xlfn.AGGREGATE(14,6,'DONNÉES BRUTES'!AB$3:AB$42*1000+(40-ROW('DONNÉES BRUTES'!AB$3:AB$42)+ROW('DONNÉES BRUTES'!AB$3)),5),'DONNÉES BRUTES'!AB$3:AB$42*1000+(40-ROW('DONNÉES BRUTES'!AB$3:AB$42)+ROW('DONNÉES BRUTES'!AB$3)),0)),"—")} -> Neutre
B21: 6 | C21: {=IFERROR(INDEX('DONNÉES BRUTES'!A$3:A$42,MATCH(_xlfn.AGGREGATE(14,6,'DONNÉES BRUTES'!AB$3:AB$42*1000+(40-ROW('DONNÉES BRUTES'!AB$3:AB$42)+ROW('DONNÉES BRUTES'!AB$3)),6),'DONNÉES BRUTES'!AB$3:AB$42*1000+(40-ROW('DONNÉES BRUTES'!AB$3:AB$42)+ROW('DONNÉES BRUTES'!AB$3)),0)),"—")} -> ALO.PA | D21: {=IFERROR(LEFT(IFERROR(INDEX('DONNÉES BRUTES'!B$3:B$42,MATCH(_xlfn.AGGREGATE(14,6,'DONNÉES BRUTES'!AB$3:AB$42*1000+(40-ROW('DONNÉES BRUTES'!AB$3:AB$42)+ROW('DONNÉES BRUTES'!AB$3)),6),'DONNÉES BRUTES'!AB$3:AB$42*1000+(40-ROW('DONNÉES BRUTES'!AB$3:AB$42)+ROW('DONNÉES BRUTES'!AB$3)),0)),"—"),18),"—")} -> Alstom SA | E21: {=IFERROR(INDEX('DONNÉES BRUTES'!C$3:C$42,MATCH(_xlfn.AGGREGATE(14,6,'DONNÉES BRUTES'!AB$3:AB$42*1000+(40-ROW('DONNÉES BRUTES'!AB$3:AB$42)+ROW('DONNÉES BRUTES'!AB$3)),6),'DONNÉES BRUTES'!AB$3:AB$42*1000+(40-ROW('DONNÉES BRUTES'!AB$3:AB$42)+ROW('DONNÉES BRUTES'!AB$3)),0)),"—")} -> Industrials | F21: {=IFERROR(INT(_xlfn.AGGREGATE(14,6,'DONNÉES BRUTES'!AB$3:AB$42*1000+(40-ROW('DONNÉES BRUTES'!AB$3:AB$42)+ROW('DONNÉES BRUTES'!AB$3)),6)/1000)&"/100","—")} -> 70/100 | H21: {=IFERROR(INDEX('DONNÉES BRUTES'!Y$3:Y$42,MATCH(_xlfn.AGGREGATE(14,6,'DONNÉES BRUTES'!AB$3:AB$42*1000+(40-ROW('DONNÉES BRUTES'!AB$3:AB$42)+ROW('DONNÉES BRUTES'!AB$3)),6),'DONNÉES BRUTES'!AB$3:AB$42*1000+(40-ROW('DONNÉES BRUTES'!AB$3:AB$42)+ROW('DONNÉES BRUTES'!AB$3)),0)),"—")} -> 95 | I21: {=IFERROR(INDEX('DONNÉES BRUTES'!Z$3:Z$42,MATCH(_xlfn.AGGREGATE(14,6,'DONNÉES BRUTES'!AB$3:AB$42*1000+(40-ROW('DONNÉES BRUTES'!AB$3:AB$42)+ROW('DONNÉES BRUTES'!AB$3)),6),'DONNÉES BRUTES'!AB$3:AB$42*1000+(40-ROW('DONNÉES BRUTES'!AB$3:AB$42)+ROW('DONNÉES BRUTES'!AB$3)),0)),"—")} -> 15 | J21: {=IFERROR(INDEX('DONNÉES BRUTES'!AA$3:AA$42,MATCH(_xlfn.AGGREGATE(14,6,'DONNÉES BRUTES'!AB$3:AB$42*1000+(40-ROW('DONNÉES BRUTES'!AB$3:AB$42)+ROW('DONNÉES BRUTES'!AB$3)),6),'DONNÉES BRUTES'!AB$3:AB$42*1000+(40-ROW('DONNÉES BRUTES'!AB$3:AB$42)+ROW('DONNÉES BRUTES'!AB$3)),0)),"—")} -> 100 | K21: {=IFERROR(INDEX('DONNÉES BRUTES'!N$3:N$42,MATCH(_xlfn.AGGREGATE(14,6,'DONNÉES BRUTES'!AB$3:AB$42*1000+(40-ROW('DONNÉES BRUTES'!AB$3:AB$42)+ROW('DONNÉES BRUTES'!AB$3)),6),'DONNÉES BRUTES'!AB$3:AB$42*1000+(40-ROW('DONNÉES BRUTES'!AB$3:AB$42)+ROW('DONNÉES BRUTES'!AB$3)),0)),"—")} -> 6.8% | L21: {=IFERROR(INDEX('DONNÉES BRUTES'!P$3:P$42,MATCH(_xlfn.AGGREGATE(14,6,'DONNÉES BRUTES'!AB$3:AB$42*1000+(40-ROW('DONNÉES BRUTES'!AB$3:AB$42)+ROW('DONNÉES BRUTES'!AB$3)),6),'DONNÉES BRUTES'!AB$3:AB$42*1000+(40-ROW('DONNÉES BRUTES'!AB$3:AB$42)+ROW('DONNÉES BRUTES'!AB$3)),0)),"—")} -> +4.9% | N21: {=IFERROR(INDEX('DONNÉES BRUTES'!AC$3:AC$42,MATCH(_xlfn.AGGREGATE(14,6,'DONNÉES BRUTES'!AB$3:AB$42*1000+(40-ROW('DONNÉES BRUTES'!AB$3:AB$42)+ROW('DONNÉES BRUTES'!AB$3)),6),'DONNÉES BRUTES'!AB$3:AB$42*1000+(40-ROW('DONNÉES BRUTES'!AB$3:AB$42)+ROW('DONNÉES BRUTES'!AB$3)),0)),"—")} -> 2026-05-13 | R21: {=IFERROR(INDEX('DONNÉES BRUTES'!AD$3:AD$42,MATCH(_xlfn.AGGREGATE(14,6,'DONNÉES BRUTES'!AB$3:AB$42*1000+(40-ROW('DONNÉES BRUTES'!AB$3:AB$42)+ROW('DONNÉES BRUTES'!AB$3)),6),'DONNÉES BRUTES'!AB$3:AB$42*1000+(40-ROW('DONNÉES BRUTES'!AB$3:AB$42)+ROW('DONNÉES BRUTES'!AB$3)),0)),"—")} -> Neutre
B22: 7 | C22: {=IFERROR(INDEX('DONNÉES BRUTES'!A$3:A$42,MATCH(_xlfn.AGGREGATE(14,6,'DONNÉES BRUTES'!AB$3:AB$42*1000+(40-ROW('DONNÉES BRUTES'!AB$3:AB$42)+ROW('DONNÉES BRUTES'!AB$3)),7),'DONNÉES BRUTES'!AB$3:AB$42*1000+(40-ROW('DONNÉES BRUTES'!AB$3:AB$42)+ROW('DONNÉES BRUTES'!AB$3)),0)),"—")} -> URW.PA | D22: {=IFERROR(LEFT(IFERROR(INDEX('DONNÉES BRUTES'!B$3:B$42,MATCH(_xlfn.AGGREGATE(14,6,'DONNÉES BRUTES'!AB$3:AB$42*1000+(40-ROW('DONNÉES BRUTES'!AB$3:AB$42)+ROW('DONNÉES BRUTES'!AB$3)),7),'DONNÉES BRUTES'!AB$3:AB$42*1000+(40-ROW('DONNÉES BRUTES'!AB$3:AB$42)+ROW('DONNÉES BRUTES'!AB$3)),0)),"—"),18),"—")} -> Unibail-Rodamco-We | E22: {=IFERROR(INDEX('DONNÉES BRUTES'!C$3:C$42,MATCH(_xlfn.AGGREGATE(14,6,'DONNÉES BRUTES'!AB$3:AB$42*1000+(40-ROW('DONNÉES BRUTES'!AB$3:AB$42)+ROW('DONNÉES BRUTES'!AB$3)),7),'DONNÉES BRUTES'!AB$3:AB$42*1000+(40-ROW('DONNÉES BRUTES'!AB$3:AB$42)+ROW('DONNÉES BRUTES'!AB$3)),0)),"—")} -> Real Estate | F22: {=IFERROR(INT(_xlfn.AGGREGATE(14,6,'DONNÉES BRUTES'!AB$3:AB$42*1000+(40-ROW('DONNÉES BRUTES'!AB$3:AB$42)+ROW('DONNÉES BRUTES'!AB$3)),7)/1000)&"/100","—")} -> 69/100 | H22: {=IFERROR(INDEX('DONNÉES BRUTES'!Y$3:Y$42,MATCH(_xlfn.AGGREGATE(14,6,'DONNÉES BRUTES'!AB$3:AB$42*1000+(40-ROW('DONNÉES BRUTES'!AB$3:AB$42)+ROW('DONNÉES BRUTES'!AB$3)),7),'DONNÉES BRUTES'!AB$3:AB$42*1000+(40-ROW('DONNÉES BRUTES'!AB$3:AB$42)+ROW('DONNÉES BRUTES'!AB$3)),0)),"—")} -> 92 | I22: {=IFERROR(INDEX('DONNÉES BRUTES'!Z$3:Z$42,MATCH(_xlfn.AGGREGATE(14,6,'DONNÉES BRUTES'!AB$3:AB$42*1000+(40-ROW('DONNÉES BRUTES'!AB$3:AB$42)+ROW('DONNÉES BRUTES'!AB$3)),7),'DONNÉES BRUTES'!AB$3:AB$42*1000+(40-ROW('DONNÉES BRUTES'!AB$3:AB$42)+ROW('DONNÉES BRUTES'!AB$3)),0)),"—")} -> 95 | J22: {=IFERROR(INDEX('DONNÉES BRUTES'!AA$3:AA$42,MATCH(_xlfn.AGGREGATE(14,6,'DONNÉES BRUTES'!AB$3:AB$42*1000+(40-ROW('DONNÉES BRUTES'!AB$3:AB$42)+ROW('DONNÉES BRUTES'!AB$3)),7),'DONNÉES BRUTES'!AB$3:AB$42*1000+(40-ROW('DONNÉES BRUTES'!AB$3:AB$42)+ROW('DONNÉES BRUTES'!AB$3)),0)),"—")} -> 21 | K22: {=IFERROR(INDEX('DONNÉES BRUTES'!N$3:N$42,MATCH(_xlfn.AGGREGATE(14,6,'DONNÉES BRUTES'!AB$3:AB$42*1000+(40-ROW('DONNÉES BRUTES'!AB$3:AB$42)+ROW('DONNÉES BRUTES'!AB$3)),7),'DONNÉES BRUTES'!AB$3:AB$42*1000+(40-ROW('DONNÉES BRUTES'!AB$3:AB$42)+ROW('DONNÉES BRUTES'!AB$3)),0)),"—")} -> 89.1% | L22: {=IFERROR(INDEX('DONNÉES BRUTES'!P$3:P$42,MATCH(_xlfn.AGGREGATE(14,6,'DONNÉES BRUTES'!AB$3:AB$42*1000+(40-ROW('DONNÉES BRUTES'!AB$3:AB$42)+ROW('DONNÉES BRUTES'!AB$3)),7),'DONNÉES BRUTES'!AB$3:AB$42*1000+(40-ROW('DONNÉES BRUTES'!AB$3:AB$42)+ROW('DONNÉES BRUTES'!AB$3)),0)),"—")} -> -6.1% | N22: {=IFERROR(INDEX('DONNÉES BRUTES'!AC$3:AC$42,MATCH(_xlfn.AGGREGATE(14,6,'DONNÉES BRUTES'!AB$3:AB$42*1000+(40-ROW('DONNÉES BRUTES'!AB$3:AB$42)+ROW('DONNÉES BRUTES'!AB$3)),7),'DONNÉES BRUTES'!AB$3:AB$42*1000+(40-ROW('DONNÉES BRUTES'!AB$3:AB$42)+ROW('DONNÉES BRUTES'!AB$3)),0)),"—")} -> — | R22: {=IFERROR(INDEX('DONNÉES BRUTES'!AD$3:AD$42,MATCH(_xlfn.AGGREGATE(14,6,'DONNÉES BRUTES'!AB$3:AB$42*1000+(40-ROW('DONNÉES BRUTES'!AB$3:AB$42)+ROW('DONNÉES BRUTES'!AB$3)),7),'DONNÉES BRUTES'!AB$3:AB$42*1000+(40-ROW('DONNÉES BRUTES'!AB$3:AB$42)+ROW('DONNÉES BRUTES'!AB$3)),0)),"—")} -> Neutre
B23: 8 | C23: {=IFERROR(INDEX('DONNÉES BRUTES'!A$3:A$42,MATCH(_xlfn.AGGREGATE(14,6,'DONNÉES BRUTES'!AB$3:AB$42*1000+(40-ROW('DONNÉES BRUTES'!AB$3:AB$42)+ROW('DONNÉES BRUTES'!AB$3)),8),'DONNÉES BRUTES'!AB$3:AB$42*1000+(40-ROW('DONNÉES BRUTES'!AB$3:AB$42)+ROW('DONNÉES BRUTES'!AB$3)),0)),"—")} -> AIR.PA | D23: {=IFERROR(LEFT(IFERROR(INDEX('DONNÉES BRUTES'!B$3:B$42,MATCH(_xlfn.AGGREGATE(14,6,'DONNÉES BRUTES'!AB$3:AB$42*1000+(40-ROW('DONNÉES BRUTES'!AB$3:AB$42)+ROW('DONNÉES BRUTES'!AB$3)),8),'DONNÉES BRUTES'!AB$3:AB$42*1000+(40-ROW('DONNÉES BRUTES'!AB$3:AB$42)+ROW('DONNÉES BRUTES'!AB$3)),0)),"—"),18),"—")} -> Airbus SE | E23: {=IFERROR(INDEX('DONNÉES BRUTES'!C$3:C$42,MATCH(_xlfn.AGGREGATE(14,6,'DONNÉES BRUTES'!AB$3:AB$42*1000+(40-ROW('DONNÉES BRUTES'!AB$3:AB$42)+ROW('DONNÉES BRUTES'!AB$3)),8),'DONNÉES BRUTES'!AB$3:AB$42*1000+(40-ROW('DONNÉES BRUTES'!AB$3:AB$42)+ROW('DONNÉES BRUTES'!AB$3)),0)),"—")} -> Industrials | F23: {=IFERROR(INT(_xlfn.AGGREGATE(14,6,'DONNÉES BRUTES'!AB$3:AB$42*1000+(40-ROW('DONNÉES BRUTES'!AB$3:AB$42)+ROW('DONNÉES BRUTES'!AB$3)),8)/1000)&"/100","—")} -> 68/100 | H23: {=IFERROR(INDEX('DONNÉES BRUTES'!Y$3:Y$42,MATCH(_xlfn.AGGREGATE(14,6,'DONNÉES BRUTES'!AB$3:AB$42*1000+(40-ROW('DONNÉES BRUTES'!AB$3:AB$42)+ROW('DONNÉES BRUTES'!AB$3)),8),'DONNÉES BRUTES'!AB$3:AB$42*1000+(40-ROW('DONNÉES BRUTES'!AB$3:AB$42)+ROW('DONNÉES BRUTES'!AB$3)),0)),"—")} -> 84 | I23: {=IFERROR(INDEX('DONNÉES BRUTES'!Z$3:Z$42,MATCH(_xlfn.AGGREGATE(14,6,'DONNÉES BRUTES'!AB$3:AB$42*1000+(40-ROW('DONNÉES BRUTES'!AB$3:AB$42)+ROW('DONNÉES BRUTES'!AB$3)),8),'DONNÉES BRUTES'!AB$3:AB$42*1000+(40-ROW('DONNÉES BRUTES'!AB$3:AB$42)+ROW('DONNÉES BRUTES'!AB$3)),0)),"—")} -> 23 | J23: {=IFERROR(INDEX('DONNÉES BRUTES'!AA$3:AA$42,MATCH(_xlfn.AGGREGATE(14,6,'DONNÉES BRUTES'!AB$3:AB$42*1000+(40-ROW('DONNÉES BRUTES'!AB$3:AB$42)+ROW('DONNÉES BRUTES'!AB$3)),8),'DONNÉES BRUTES'!AB$3:AB$42*1000+(40-ROW('DONNÉES BRUTES'!AB$3:AB$42)+ROW('DONNÉES BRUTES'!AB$3)),0)),"—")} -> 97 | K23: {=IFERROR(INDEX('DONNÉES BRUTES'!N$3:N$42,MATCH(_xlfn.AGGREGATE(14,6,'DONNÉES BRUTES'!AB$3:AB$42*1000+(40-ROW('DONNÉES BRUTES'!AB$3:AB$42)+ROW('DONNÉES BRUTES'!AB$3)),8),'DONNÉES BRUTES'!AB$3:AB$42*1000+(40-ROW('DONNÉES BRUTES'!AB$3:AB$42)+ROW('DONNÉES BRUTES'!AB$3)),0)),"—")} -> 14.0% | L23: {=IFERROR(INDEX('DONNÉES BRUTES'!P$3:P$42,MATCH(_xlfn.AGGREGATE(14,6,'DONNÉES BRUTES'!AB$3:AB$42*1000+(40-ROW('DONNÉES BRUTES'!AB$3:AB$42)+ROW('DONNÉES BRUTES'!AB$3)),8),'DONNÉES BRUTES'!AB$3:AB$42*1000+(40-ROW('DONNÉES BRUTES'!AB$3:AB$42)+ROW('DONNÉES BRUTES'!AB$3)),0)),"—")} -> +6.1% | N23: {=IFERROR(INDEX('DONNÉES BRUTES'!AC$3:AC$42,MATCH(_xlfn.AGGREGATE(14,6,'DONNÉES BRUTES'!AB$3:AB$42*1000+(40-ROW('DONNÉES BRUTES'!AB$3:AB$42)+ROW('DONNÉES BRUTES'!AB$3)),8),'DONNÉES BRUTES'!AB$3:AB$42*1000+(40-ROW('DONNÉES BRUTES'!AB$3:AB$42)+ROW('DONNÉES BRUTES'!AB$3)),0)),"—")} -> 2026-04-28 | R23: {=IFERROR(INDEX('DONNÉES BRUTES'!AD$3:AD$42,MATCH(_xlfn.AGGREGATE(14,6,'DONNÉES BRUTES'!AB$3:AB$42*1000+(40-ROW('DONNÉES BRUTES'!AB$3:AB$42)+ROW('DONNÉES BRUTES'!AB$3)),8),'DONNÉES BRUTES'!AB$3:AB$42*1000+(40-ROW('DONNÉES BRUTES'!AB$3:AB$42)+ROW('DONNÉES BRUTES'!AB$3)),0)),"—")} -> Neutre
B24: 9 | C24: {=IFERROR(INDEX('DONNÉES BRUTES'!A$3:A$42,MATCH(_xlfn.AGGREGATE(14,6,'DONNÉES BRUTES'!AB$3:AB$42*1000+(40-ROW('DONNÉES BRUTES'!AB$3:AB$42)+ROW('DONNÉES BRUTES'!AB$3)),9),'DONNÉES BRUTES'!AB$3:AB$42*1000+(40-ROW('DONNÉES BRUTES'!AB$3:AB$42)+ROW('DONNÉES BRUTES'!AB$3)),0)),"—")} -> SAF.PA | D24: {=IFERROR(LEFT(IFERROR(INDEX('DONNÉES BRUTES'!B$3:B$42,MATCH(_xlfn.AGGREGATE(14,6,'DONNÉES BRUTES'!AB$3:AB$42*1000+(40-ROW('DONNÉES BRUTES'!AB$3:AB$42)+ROW('DONNÉES BRUTES'!AB$3)),9),'DONNÉES BRUTES'!AB$3:AB$42*1000+(40-ROW('DONNÉES BRUTES'!AB$3:AB$42)+ROW('DONNÉES BRUTES'!AB$3)),0)),"—"),18),"—")} -> Safran SA | E24: {=IFERROR(INDEX('DONNÉES BRUTES'!C$3:C$42,MATCH(_xlfn.AGGREGATE(14,6,'DONNÉES BRUTES'!AB$3:AB$42*1000+(40-ROW('DONNÉES BRUTES'!AB$3:AB$42)+ROW('DONNÉES BRUTES'!AB$3)),9),'DONNÉES BRUTES'!AB$3:AB$42*1000+(40-ROW('DONNÉES BRUTES'!AB$3:AB$42)+ROW('DONNÉES BRUTES'!AB$3)),0)),"—")} -> Industrials | F24: {=IFERROR(INT(_xlfn.AGGREGATE(14,6,'DONNÉES BRUTES'!AB$3:AB$42*1000+(40-ROW('DONNÉES BRUTES'!AB$3:AB$42)+ROW('DONNÉES BRUTES'!AB$3)),9)/1000)&"/100","—")} -> 68/100 | H24: {=IFERROR(INDEX('DONNÉES BRUTES'!Y$3:Y$42,MATCH(_xlfn.AGGREGATE(14,6,'DONNÉES BRUTES'!AB$3:AB$42*1000+(40-ROW('DONNÉES BRUTES'!AB$3:AB$42)+ROW('DONNÉES BRUTES'!AB$3)),9),'DONNÉES BRUTES'!AB$3:AB$42*1000+(40-ROW('DONNÉES BRUTES'!AB$3:AB$42)+ROW('DONNÉES BRUTES'!AB$3)),0)),"—")} -> 100 | I24: {=IFERROR(INDEX('DONNÉES BRUTES'!Z$3:Z$42,MATCH(_xlfn.AGGREGATE(14,6,'DONNÉES BRUTES'!AB$3:AB$42*1000+(40-ROW('DONNÉES BRUTES'!AB$3:AB$42)+ROW('DONNÉES BRUTES'!AB$3)),9),'DONNÉES BRUTES'!AB$3:AB$42*1000+(40-ROW('DONNÉES BRUTES'!AB$3:AB$42)+ROW('DONNÉES BRUTES'!AB$3)),0)),"—")} -> 67 | J24: {=IFERROR(INDEX('DONNÉES BRUTES'!AA$3:AA$42,MATCH(_xlfn.AGGREGATE(14,6,'DONNÉES BRUTES'!AB$3:AB$42*1000+(40-ROW('DONNÉES BRUTES'!AB$3:AB$42)+ROW('DONNÉES BRUTES'!AB$3)),9),'DONNÉES BRUTES'!AB$3:AB$42*1000+(40-ROW('DONNÉES BRUTES'!AB$3:AB$42)+ROW('DONNÉES BRUTES'!AB$3)),0)),"—")} -> 38 | K24: {=IFERROR(INDEX('DONNÉES BRUTES'!N$3:N$42,MATCH(_xlfn.AGGREGATE(14,6,'DONNÉES BRUTES'!AB$3:AB$42*1000+(40-ROW('DONNÉES BRUTES'!AB$3:AB$42)+ROW('DONNÉES BRUTES'!AB$3)),9),'DONNÉES BRUTES'!AB$3:AB$42*1000+(40-ROW('DONNÉES BRUTES'!AB$3:AB$42)+ROW('DONNÉES BRUTES'!AB$3)),0)),"—")} -> 39.2% | L24: {=IFERROR(INDEX('DONNÉES BRUTES'!P$3:P$42,MATCH(_xlfn.AGGREGATE(14,6,'DONNÉES BRUTES'!AB$3:AB$42*1000+(40-ROW('DONNÉES BRUTES'!AB$3:AB$42)+ROW('DONNÉES BRUTES'!AB$3)),9),'DONNÉES BRUTES'!AB$3:AB$42*1000+(40-ROW('DONNÉES BRUTES'!AB$3:AB$42)+ROW('DONNÉES BRUTES'!AB$3)),0)),"—")} -> +12.5% | N24: {=IFERROR(INDEX('DONNÉES BRUTES'!AC$3:AC$42,MATCH(_xlfn.AGGREGATE(14,6,'DONNÉES BRUTES'!AB$3:AB$42*1000+(40-ROW('DONNÉES BRUTES'!AB$3:AB$42)+ROW('DONNÉES BRUTES'!AB$3)),9),'DONNÉES BRUTES'!AB$3:AB$42*1000+(40-ROW('DONNÉES BRUTES'!AB$3:AB$42)+ROW('DONNÉES BRUTES'!AB$3)),0)),"—")} -> — | R24: {=IFERROR(INDEX('DONNÉES BRUTES'!AD$3:AD$42,MATCH(_xlfn.AGGREGATE(14,6,'DONNÉES BRUTES'!AB$3:AB$42*1000+(40-ROW('DONNÉES BRUTES'!AB$3:AB$42)+ROW('DONNÉES BRUTES'!AB$3)),9),'DONNÉES BRUTES'!AB$3:AB$42*1000+(40-ROW('DONNÉES BRUTES'!AB$3:AB$42)+ROW('DONNÉES BRUTES'!AB$3)),0)),"—")} -> Neutre
B25: 10 | C25: {=IFERROR(INDEX('DONNÉES BRUTES'!A$3:A$42,MATCH(_xlfn.AGGREGATE(14,6,'DONNÉES BRUTES'!AB$3:AB$42*1000+(40-ROW('DONNÉES BRUTES'!AB$3:AB$42)+ROW('DONNÉES BRUTES'!AB$3)),10),'DONNÉES BRUTES'!AB$3:AB$42*1000+(40-ROW('DONNÉES BRUTES'!AB$3:AB$42)+ROW('DONNÉES BRUTES'!AB$3)),0)),"—")} -> ACA.PA | D25: {=IFERROR(LEFT(IFERROR(INDEX('DONNÉES BRUTES'!B$3:B$42,MATCH(_xlfn.AGGREGATE(14,6,'DONNÉES BRUTES'!AB$3:AB$42*1000+(40-ROW('DONNÉES BRUTES'!AB$3:AB$42)+ROW('DONNÉES BRUTES'!AB$3)),10),'DONNÉES BRUTES'!AB$3:AB$42*1000+(40-ROW('DONNÉES BRUTES'!AB$3:AB$42)+ROW('DONNÉES BRUTES'!AB$3)),0)),"—"),18),"—")} -> Crédit Agricole S. | E25: {=IFERROR(INDEX('DONNÉES BRUTES'!C$3:C$42,MATCH(_xlfn.AGGREGATE(14,6,'DONNÉES BRUTES'!AB$3:AB$42*1000+(40-ROW('DONNÉES BRUTES'!AB$3:AB$42)+ROW('DONNÉES BRUTES'!AB$3)),10),'DONNÉES BRUTES'!AB$3:AB$42*1000+(40-ROW('DONNÉES BRUTES'!AB$3:AB$42)+ROW('DONNÉES BRUTES'!AB$3)),0)),"—")} -> Financials | F25: {=IFERROR(INT(_xlfn.AGGREGATE(14,6,'DONNÉES BRUTES'!AB$3:AB$42*1000+(40-ROW('DONNÉES BRUTES'!AB$3:AB$42)+ROW('DONNÉES BRUTES'!AB$3)),10)/1000)&"/100","—")} -> 65/100 | H25: {=IFERROR(INDEX('DONNÉES BRUTES'!Y$3:Y$42,MATCH(_xlfn.AGGREGATE(14,6,'DONNÉES BRUTES'!AB$3:AB$42*1000+(40-ROW('DONNÉES BRUTES'!AB$3:AB$42)+ROW('DONNÉES BRUTES'!AB$3)),10),'DONNÉES BRUTES'!AB$3:AB$42*1000+(40-ROW('DONNÉES BRUTES'!AB$3:AB$42)+ROW('DONNÉES BRUTES'!AB$3)),0)),"—")} -> 21 | I25: {=IFERROR(INDEX('DONNÉES BRUTES'!Z$3:Z$42,MATCH(_xlfn.AGGREGATE(14,6,'DONNÉES BRUTES'!AB$3:AB$42*1000+(40-ROW('DONNÉES BRUTES'!AB$3:AB$42)+ROW('DONNÉES BRUTES'!AB$3)),10),'DONNÉES BRUTES'!AB$3:AB$42*1000+(40-ROW('DONNÉES BRUTES'!AB$3:AB$42)+ROW('DONNÉES BRUTES'!AB$3)),0)),"—")} -> 92 | J25: {=IFERROR(INDEX('DONNÉES BRUTES'!AA$3:AA$42,MATCH(_xlfn.AGGREGATE(14,6,'DONNÉES BRUTES'!AB$3:AB$42*1000+(40-ROW('DONNÉES BRUTES'!AB$3:AB$42)+ROW('DONNÉES BRUTES'!AB$3)),10),'DONNÉES BRUTES'!AB$3:AB$42*1000+(40-ROW('DONNÉES BRUTES'!AB$3:AB$42)+ROW('DONNÉES BRUTES'!AB$3)),0)),"—")} -> 82 | K25: {=IFERROR(INDEX('DONNÉES BRUTES'!N$3:N$42,MATCH(_xlfn.AGGREGATE(14,6,'DONNÉES BRUTES'!AB$3:AB$42*1000+(40-ROW('DONNÉES BRUTES'!AB$3:AB$42)+ROW('DONNÉES BRUTES'!AB$3)),10),'DONNÉES BRUTES'!AB$3:AB$42*1000+(40-ROW('DONNÉES BRUTES'!AB$3:AB$42)+ROW('DONNÉES BRUTES'!AB$3)),0)),"—")} -> 192.6% | L25: {=IFERROR(INDEX('DONNÉES BRUTES'!P$3:P$42,MATCH(_xlfn.AGGREGATE(14,6,'DONNÉES BRUTES'!AB$3:AB$42*1000+(40-ROW('DONNÉES BRUTES'!AB$3:AB$42)+ROW('DONNÉES BRUTES'!AB$3)),10),'DONNÉES BRUTES'!AB$3:AB$42*1000+(40-ROW('DONNÉES BRUTES'!AB$3:AB$42)+ROW('DONNÉES BRUTES'!AB$3)),0)),"—")} -> +3.7% | N25: {=IFERROR(INDEX('DONNÉES BRUTES'!AC$3:AC$42,MATCH(_xlfn.AGGREGATE(14,6,'DONNÉES BRUTES'!AB$3:AB$42*1000+(40-ROW('DONNÉES BRUTES'!AB$3:AB$42)+ROW('DONNÉES BRUTES'!AB$3)),10),'DONNÉES BRUTES'!AB$3:AB$42*1000+(40-ROW('DONNÉES BRUTES'!AB$3:AB$42)+ROW('DONNÉES BRUTES'!AB$3)),0)),"—")} -> 2026-04-30 | R25: {=IFERROR(INDEX('DONNÉES BRUTES'!AD$3:AD$42,MATCH(_xlfn.AGGREGATE(14,6,'DONNÉES BRUTES'!AB$3:AB$42*1000+(40-ROW('DONNÉES BRUTES'!AB$3:AB$42)+ROW('DONNÉES BRUTES'!AB$3)),10),'DONNÉES BRUTES'!AB$3:AB$42*1000+(40-ROW('DONNÉES BRUTES'!AB$3:AB$42)+ROW('DONNÉES BRUTES'!AB$3)),0)),"—")} -> Neutre
B26: FinSight IA · Données issues de Supabase/Python · Scores calculés sur métriques Value, Growth, Quality, Momentum · Usage confidentiel

Sheet VALUE
A1: FinSight IA · Analyse VALUE · CAC 40 · 22/03/2026 | O1: Société | P1: Score Global | Q1: Signal
A2: Usage confidentiel · Calculs Python/NumPy depuis cache Supabase | O2: =IF(B4<>"—",LEFT(C4,20),"—") -> Hermès International | P2: =IF(E4<>"—",VALUE(LEFT(E4,FIND("/",E4)-1)),"") -> 75
A3: Rang | B3: Ticker | C3: Société | D3: Secteur | E3: Score | F3: EV/EBITDA | G3: EV/Revenue | H3: P/E | I3: Marge Brute | J3: Marge EBITDA | K3: Altman Z | L3: FCF Yield | M3: Décote DCF estimée | O3: =IF(B5<>"—",LEFT(C5,20),"—") -> L'Air Liquide S.A. | P3: =IF(E5<>"—",VALUE(LEFT(E5,FIND("/",E5)-1)),"") -> 74
A4: 1 | B4: {=IFERROR(INDEX('DONNÉES BRUTES'!A$3:A$42,MATCH(_xlfn.AGGREGATE(14,6,'DONNÉES BRUTES'!AB$3:AB$42+ROW('DONNÉES BRUTES'!AB$3:AB$42)/1000,1),'DONNÉES BRUTES'!AB$3:AB$42+ROW('DONNÉES BRUTES'!AB$3:AB$42)/1000,0)),"—")} -> RMS.PA | C4: {=IFERROR(INDEX('DONNÉES BRUTES'!B$3:B$42,MATCH(_xlfn.AGGREGATE(14,6,'DONNÉES BRUTES'!AB$3:AB$42+ROW('DONNÉES BRUTES'!AB$3:AB$42)/1000,1),'DONNÉES BRUTES'!AB$3:AB$42+ROW('DONNÉES BRUTES'!AB$3:AB$42)/1000,0)),"—")} -> Hermès International Société en commandite par actions | D4: {=IFERROR(INDEX('DONNÉES BRUTES'!C$3:C$42,MATCH(_xlfn.AGGREGATE(14,6,'DONNÉES BRUTES'!AB$3:AB$42+ROW('DONNÉES BRUTES'!AB$3:AB$42)/1000,1),'DONNÉES BRUTES'!AB$3:AB$42+ROW('DONNÉES BRUTES'!AB$3:AB$42)/1000,0)),"—")} -> Consumer Disc. | E4: {=IFERROR(INDEX('DONNÉES BRUTES'!AB$3:AB$42,MATCH(_xlfn.AGGREGATE(14,6,'DONNÉES BRUTES'!AB$3:AB$42+ROW('DONNÉES BRUTES'!AB$3:AB$42)/1000,1),'DONNÉES BRUTES'!AB$3:AB$42+ROW('DONNÉES BRUTES'!AB$3:AB$42)/1000,0))&"/100","—")} -> 75/100 | F4: {=IFERROR(INDEX('DONNÉES BRUTES'!I$3:I$42,MATCH(_xlfn.AGGREGATE(14,6,'DONNÉES BRUTES'!AB$3:AB$42+ROW('DONNÉES BRUTES'!AB$3:AB$42)/1000,1),'DONNÉES BRUTES'!AB$3:AB$42+ROW('DONNÉES BRUTES'!AB$3:AB$42)/1000,0)),"—")} -> — | G4: {=IFERROR(INDEX('DONNÉES BRUTES'!J$3:J$42,MATCH(_xlfn.AGGREGATE(14,6,'DONNÉES BRUTES'!AB$3:AB$42+ROW('DONNÉES BRUTES'!AB$3:AB$42)/1000,1),'DONNÉES BRUTES'!AB$3:AB$42+ROW('DONNÉES BRUTES'!AB$3:AB$42)/1000,0)),"—")} -> — | H4: {=IFERROR(INDEX('DONNÉES BRUTES'!K$3:K$42,MATCH(_xlfn.AGGREGATE(14,6,'DONNÉES BRUTES'!AB$3:AB$42+ROW('DONNÉES BRUTES'!AB$3:AB$42)/1000,1),'DONNÉES BRUTES'!AB$3:AB$42+ROW('DONNÉES BRUTES'!AB$3:AB$42)/1000,0)),"—")} -> — | I4: {=IFERROR(INDEX('DONNÉES BRUTES'!M$3:M$42,MATCH(_xlfn.AGGREGATE(14,6,'DONNÉES BRUTES'!AB$3:AB$42+ROW('DONNÉES BRUTES'!AB$3:AB$42)/1000,1),'DONNÉES BRUTES'!AB$3:AB$42+ROW('DONNÉES BRUTES'!AB$3:AB$42)/1000,0)),"—")} -> 71.1% | J4: {=IFERROR(INDEX('DONNÉES BRUTES'!N$3:N$42,MATCH(_xlfn.AGGREGATE(14,6,'DONNÉES BRUTES'!AB$3:AB$42+ROW('DONNÉES BRUTES'!AB$3:AB$42)/1000,1),'DONNÉES BRUTES'!AB$3:AB$42+ROW('DONNÉES BRUTES'!AB$3:AB$42)/1000,0)),"—")} -> 46.8% | K4: {=IFERROR(INDEX('DONNÉES BRUTES'!U$3:U$42,MATCH(_xlfn.AGGREGATE(14,6,'DONNÉES BRUTES'!AB$3:AB$42+ROW('DONNÉES BRUTES'!AB$3:AB$42)/1000,1),'DONNÉES BRUTES'!AB$3:AB$42+ROW('DONNÉES BRUTES'!AB$3:AB$42)/1000,0)),"—")} -> 9.47 | L4: — | M4: {=IFERROR(INDEX('DONNÉES BRUTES'!AD$3:AD$42,MATCH(_xlfn.AGGREGATE(14,6,'DONNÉES BRUTES'!AB$3:AB$42+ROW('DONNÉES BRUTES'!AB$3:AB$42)/1000,1),'DONNÉES BRUTES'!AB$3:AB$42+ROW('DONNÉES BRUTES'!AB$3:AB$42)/1000,0)),"—")} -> Surpondérer | O4: =IF(B6<>"—",LEFT(C6,20),"—") -> Sanofi | P4: =IF(E6<>"—",VALUE(LEFT(E6,FIND("/",E6)-1)),"") -> 72
A5: 2 | B5: {=IFERROR(INDEX('DONNÉES BRUTES'!A$3:A$42,MATCH(_xlfn.AGGREGATE(14,6,'DONNÉES BRUTES'!AB$3:AB$42+ROW('DONNÉES BRUTES'!AB$3:AB$42)/1000,2),'DONNÉES BRUTES'!AB$3:AB$42+ROW('DONNÉES BRUTES'!AB$3:AB$42)/1000,0)),"—")} -> AI.PA | C5: {=IFERROR(INDEX('DONNÉES BRUTES'!B$3:B$42,MATCH(_xlfn.AGGREGATE(14,6,'DONNÉES BRUTES'!AB$3:AB$42+ROW('DONNÉES BRUTES'!AB$3:AB$42)/1000,2),'DONNÉES BRUTES'!AB$3:AB$42+ROW('DONNÉES BRUTES'!AB$3:AB$42)/1000,0)),"—")} -> L'Air Liquide S.A. | D5: {=IFERROR(INDEX('DONNÉES BRUTES'!C$3:C$42,MATCH(_xlfn.AGGREGATE(14,6,'DONNÉES BRUTES'!AB$3:AB$42+ROW('DONNÉES BRUTES'!AB$3:AB$42)/1000,2),'DONNÉES BRUTES'!AB$3:AB$42+ROW('DONNÉES BRUTES'!AB$3:AB$42)/1000,0)),"—")} -> Materials | E5: {=IFERROR(INDEX('DONNÉES BRUTES'!AB$3:AB$42,MATCH(_xlfn.AGGREGATE(14,6,'DONNÉES BRUTES'!AB$3:AB$42+ROW('DONNÉES BRUTES'!AB$3:AB$42)/1000,2),'DONNÉES BRUTES'!AB$3:AB$42+ROW('DONNÉES BRUTES'!AB$3:AB$42)/1000,0))&"/100","—")} -> 74/100 | F5: {=IFERROR(INDEX('DONNÉES BRUTES'!I$3:I$42,MATCH(_xlfn.AGGREGATE(14,6,'DONNÉES BRUTES'!AB$3:AB$42+ROW('DONNÉES BRUTES'!AB$3:AB$42)/1000,2),'DONNÉES BRUTES'!AB$3:AB$42+ROW('DONNÉES BRUTES'!AB$3:AB$42)/1000,0)),"—")} -> — | G5: {=IFERROR(INDEX('DONNÉES BRUTES'!J$3:J$42,MATCH(_xlfn.AGGREGATE(14,6,'DONNÉES BRUTES'!AB$3:AB$42+ROW('DONNÉES BRUTES'!AB$3:AB$42)/1000,2),'DONNÉES BRUTES'!AB$3:AB$42+ROW('DONNÉES BRUTES'!AB$3:AB$42)/1000,0)),"—")} -> — | H5: {=IFERROR(INDEX('DONNÉES BRUTES'!K$3:K$42,MATCH(_xlfn.AGGREGATE(14,6,'DONNÉES BRUTES'!AB$3:AB$42+ROW('DONNÉES BRUTES'!AB$3:AB$42)/1000,2),'DONNÉES BRUTES'!AB$3:AB$42+ROW('DONNÉES BRUTES'!AB$3:AB$42)/1000,0)),"—")} -> — | I5: {=IFERROR(INDEX('DONNÉES BRUTES'!M$3:M$42,MATCH(_xlfn.AGGREGATE(14,6,'DONNÉES BRUTES'!AB$3:AB$42+ROW('DONNÉES BRUTES'!AB$3:AB$42)/1000,2),'DONNÉES BRUTES'!AB$3:AB$42+ROW('DONNÉES BRUTES'!AB$3:AB$42)/1000,0)),"—")} -> 64.2% | J5: {=IFERROR(INDEX('DONNÉES BRUTES'!N$3:N$42,MATCH(_xlfn.AGGREGATE(14,6,'DONNÉES BRUTES'!AB$3:AB$42+ROW('DONNÉES BRUTES'!AB$3:AB$42)/1000,2),'DONNÉES BRUTES'!AB$3:AB$42+ROW('DONNÉES BRUTES'!AB$3:AB$42)/1000,0)),"—")} -> 27.9% | K5: {=IFERROR(INDEX('DONNÉES BRUTES'!U$3:U$42,MATCH(_xlfn.AGGREGATE(14,6,'DONNÉES BRUTES'!AB$3:AB$42+ROW('DONNÉES BRUTES'!AB$3:AB$42)/1000,2),'DONNÉES BRUTES'!AB$3:AB$42+ROW('DONNÉES BRUTES'!AB$3:AB$42)/1000,0)),"—")} -> 3.26 | L5: — | M5: {=IFERROR(INDEX('DONNÉES BRUTES'!AD$3:AD$42,MATCH(_xlfn.AGGREGATE(14,6,'DONNÉES BRUTES'!AB$3:AB$42+ROW('DONNÉES BRUTES'!AB$3:AB$42)/1000,2),'DONNÉES BRUTES'!AB$3:AB$42+ROW('DONNÉES BRUTES'!AB$3:AB$42)/1000,0)),"—")} -> Neutre | O5: =IF(B7<>"—",LEFT(C7,20),"—") -> Eurofins Scientific | P5: =IF(E7<>"—",VALUE(LEFT(E7,FIND("/",E7)-1)),"") -> 72
