Workbook

Sheet DASHBOARD
B1: FinSight IA · Énergie Screening — Tableau de Bord
C3: =COUNTA('DONNÉES BRUTES'!A$3:A$90) -> 88 | H3: =ROUND(AVERAGE('DONNÉES BRUTES'!AB$3:AB$90),0)&"/100" -> 53/100 | L3: =IFERROR(_xlfn.XLOOKUP(MAX('DONNÉES BRUTES'!AB$3:AB$90),'DONNÉES BRUTES'!AB$3:AB$90,'DONNÉES BRUTES'!A$3:A$90)&" — "&MAX('DONNÉES BRUTES'!AB$3:AB$90)&"/100","—") -> ENI.MI — 79/100 | Q3: 16/04/2026
C4: SOCIÉTÉS ANALYSÉES | H4: SCORE MOYEN SECTEUR | L4: MEILLEUR SCORE GLOBAL | Q4: DATE D'ANALYSE
B6: TOP 5 · Classements par Facteur · Growth | H6: Quality | N6: Momentum
B7: # | C7: Ticker | D7: Société | E7: Score | F7: Croiss. Rev | H7: # | I7: Ticker | J7: Société | K7: Score | L7: Altman Z | N7: # | O7: Ticker | P7: Société | Q7: Score | R7: Mom 52W
B8: 1 | C8: =IFERROR(INDEX('DONNÉES BRUTES'!A$3:A$90,MATCH(LARGE('DONNÉES BRUTES'!Y$3:Y$90,1),'DONNÉES BRUTES'!Y$3:Y$90,0)),"—") -> EXE | D8: =IFERROR(_xlfn.XLOOKUP(C8,'DONNÉES BRUTES'!A$3:A$90,'DONNÉES BRUTES'!B$3:B$90),"—") -> Expand Energy Corporation | E8: =IFERROR(_xlfn.XLOOKUP(C8,'DONNÉES BRUTES'!A$3:A$90,'DONNÉES BRUTES'!Y$3:Y$90)&"/100","—") -> 100/100 | F8: =IFERROR(_xlfn.XLOOKUP(C8,'DONNÉES BRUTES'!A$3:A$90,'DONNÉES BRUTES'!P$3:P$90),"—") -> 1.888 | H8: 1 | I8: =IFERROR(INDEX('DONNÉES BRUTES'!A$3:A$90,MATCH(LARGE('DONNÉES BRUTES'!Z$3:Z$90,1),'DONNÉES BRUTES'!Z$3:Z$90,0)),"—") -> TPL | J8: =IFERROR(_xlfn.XLOOKUP(I8,'DONNÉES BRUTES'!A$3:A$90,'DONNÉES BRUTES'!B$3:B$90),"—") -> Texas Pacific Land Corporation | K8: =IFERROR(_xlfn.XLOOKUP(I8,'DONNÉES BRUTES'!A$3:A$90,'DONNÉES BRUTES'!Z$3:Z$90)&"/100","—") -> 91/100 | L8: =IFERROR(_xlfn.XLOOKUP(I8,'DONNÉES BRUTES'!A$3:A$90,'DONNÉES BRUTES'!U$3:U$90),"—") -> 16.05 | N8: 1 | O8: =IFERROR(_xlfn.XLOOKUP(LARGE('DONNÉES BRUTES'!AA$3:AA$90,1),'DONNÉES BRUTES'!AA$3:AA$90,'DONNÉES BRUTES'!A$3:A$90),"—") -> APA | P8: =IFERROR(_xlfn.XLOOKUP(O8,'DONNÉES BRUTES'!A$3:A$90,'DONNÉES BRUTES'!B$3:B$90),"—") -> APA Corporation | Q8: =IFERROR(_xlfn.XLOOKUP(O8,'DONNÉES BRUTES'!A$3:A$90,'DONNÉES BRUTES'!AA$3:AA$90)&"/100","—") -> 100/100 | R8: =IFERROR(_xlfn.XLOOKUP(O8,'DONNÉES BRUTES'!A$3:A$90,'DONNÉES BRUTES'!W$3:W$90),"—") -> +129.6%
B9: 2 | C9: {=IFERROR(INDEX('DONNÉES BRUTES'!A$3:A$90,MATCH(1,('DONNÉES BRUTES'!Y$3:Y$90=LARGE('DONNÉES BRUTES'!Y$3:Y$90,2))*(COUNTIF(C$8:C8,'DONNÉES BRUTES'!A$3:A$90)=0)*('DONNÉES BRUTES'!A$3:A$90<>""),0)),"—")} -> EQT | D9: =IFERROR(_xlfn.XLOOKUP(C9,'DONNÉES BRUTES'!A$3:A$90,'DONNÉES BRUTES'!B$3:B$90),"—") -> EQT Corporation | E9: =IFERROR(_xlfn.XLOOKUP(C9,'DONNÉES BRUTES'!A$3:A$90,'DONNÉES BRUTES'!Y$3:Y$90)&"/100","—") -> 96/100 | F9: =IFERROR(_xlfn.XLOOKUP(C9,'DONNÉES BRUTES'!A$3:A$90,'DONNÉES BRUTES'!P$3:P$90),"—") -> 0.6 | H9: 2 | I9: {=IFERROR(INDEX('DONNÉES BRUTES'!A$3:A$90,MATCH(1,('DONNÉES BRUTES'!Z$3:Z$90=LARGE('DONNÉES BRUTES'!Z$3:Z$90,2))*(COUNTIF(I$8:I8,'DONNÉES BRUTES'!A$3:A$90)=0)*('DONNÉES BRUTES'!A$3:A$90<>""),0)),"—")} -> AMAT | J9: =IFERROR(_xlfn.XLOOKUP(I9,'DONNÉES BRUTES'!A$3:A$90,'DONNÉES BRUTES'!B$3:B$90),"—") -> Applied Materials, Inc. | K9: =IFERROR(_xlfn.XLOOKUP(I9,'DONNÉES BRUTES'!A$3:A$90,'DONNÉES BRUTES'!Z$3:Z$90)&"/100","—") -> 91/100 | L9: =IFERROR(_xlfn.XLOOKUP(I9,'DONNÉES BRUTES'!A$3:A$90,'DONNÉES BRUTES'!U$3:U$90),"—") -> 10.40 | N9: 2 | O9: =IFERROR(_xlfn.XLOOKUP(LARGE('DONNÉES BRUTES'!AA$3:AA$90,2),'DONNÉES BRUTES'!AA$3:AA$90,'DONNÉES BRUTES'!A$3:A$90),"—") -> APA | P9: =IFERROR(_xlfn.XLOOKUP(O9,'DONNÉES BRUTES'!A$3:A$90,'DONNÉES BRUTES'!B$3:B$90),"—") -> APA Corporation | Q9: =IFERROR(_xlfn.XLOOKUP(O9,'DONNÉES BRUTES'!A$3:A$90,'DONNÉES BRUTES'!AA$3:AA$90)&"/100","—") -> 100/100 | R9: =IFERROR(_xlfn.XLOOKUP(O9,'DONNÉES BRUTES'!A$3:A$90,'DONNÉES BRUTES'!W$3:W$90),"—") -> +129.6%
B10: 3 | C10: {=IFERROR(INDEX('DONNÉES BRUTES'!A$3:A$90,MATCH(1,('DONNÉES BRUTES'!Y$3:Y$90>=LARGE('DONNÉES BRUTES'!Y$3:Y$90,3))*(COUNTIF(C$8:C9,'DONNÉES BRUTES'!A$3:A$90)=0)*('DONNÉES BRUTES'!A$3:A$90<>""),0)),"—")} -> ENI.MI | D10: =IFERROR(_xlfn.XLOOKUP(C10,'DONNÉES BRUTES'!A$3:A$90,'DONNÉES BRUTES'!B$3:B$90),"—") -> Eni S.p.A. | E10: =IFERROR(_xlfn.XLOOKUP(C10,'DONNÉES BRUTES'!A$3:A$90,'DONNÉES BRUTES'!Y$3:Y$90)&"/100","—") -> —/100 | F10: =IFERROR(_xlfn.XLOOKUP(C10,'DONNÉES BRUTES'!A$3:A$90,'DONNÉES BRUTES'!P$3:P$90),"—") -> — | H10: 3 | I10: {=IFERROR(INDEX('DONNÉES BRUTES'!A$3:A$90,MATCH(1,('DONNÉES BRUTES'!Z$3:Z$90>=LARGE('DONNÉES BRUTES'!Z$3:Z$90,3))*(COUNTIF(I$8:I9,'DONNÉES BRUTES'!A$3:A$90)=0)*('DONNÉES BRUTES'!A$3:A$90<>""),0)),"—")} -> FTNT | J10: =IFERROR(_xlfn.XLOOKUP(I10,'DONNÉES BRUTES'!A$3:A$90,'DONNÉES BRUTES'!B$3:B$90),"—") -> Fortinet, Inc. | K10: =IFERROR(_xlfn.XLOOKUP(I10,'DONNÉES BRUTES'!A$3:A$90,'DONNÉES BRUTES'!Z$3:Z$90)&"/100","—") -> 91/100 | L10: =IFERROR(_xlfn.XLOOKUP(I10,'DONNÉES BRUTES'!A$3:A$90,'DONNÉES BRUTES'!U$3:U$90),"—") -> 2.02 | N10: 3 | O10: =IFERROR(_xlfn.XLOOKUP(LARGE('DONNÉES BRUTES'!AA$3:AA$90,3),'DONNÉES BRUTES'!AA$3:AA$90,'DONNÉES BRUTES'!A$3:A$90),"—") -> CIEN | P10: =IFERROR(_xlfn.XLOOKUP(O10,'DONNÉES BRUTES'!A$3:A$90,'DONNÉES BRUTES'!B$3:B$90),"—") -> Ciena Corporation | Q10: =IFERROR(_xlfn.XLOOKUP(O10,'DONNÉES BRUTES'!A$3:A$90,'DONNÉES BRUTES'!AA$3:AA$90)&"/100","—") -> 98/100 | R10: =IFERROR(_xlfn.XLOOKUP(O10,'DONNÉES BRUTES'!A$3:A$90,'DONNÉES BRUTES'!W$3:W$90),"—") -> +454.6%
B11: 4 | C11: {=IFERROR(INDEX('DONNÉES BRUTES'!A$3:A$90,MATCH(1,('DONNÉES BRUTES'!Y$3:Y$90>=LARGE('DONNÉES BRUTES'!Y$3:Y$90,4))*(COUNTIF(C$8:C10,'DONNÉES BRUTES'!A$3:A$90)=0)*('DONNÉES BRUTES'!A$3:A$90<>""),0)),"—")} -> CTRA | D11: =IFERROR(_xlfn.XLOOKUP(C11,'DONNÉES BRUTES'!A$3:A$90,'DONNÉES BRUTES'!B$3:B$90),"—") -> Coterra Energy Inc. | E11: =IFERROR(_xlfn.XLOOKUP(C11,'DONNÉES BRUTES'!A$3:A$90,'DONNÉES BRUTES'!Y$3:Y$90)&"/100","—") -> 92/100 | F11: =IFERROR(_xlfn.XLOOKUP(C11,'DONNÉES BRUTES'!A$3:A$90,'DONNÉES BRUTES'!P$3:P$90),"—") -> 0.401 | H11: 4 | I11: {=IFERROR(INDEX('DONNÉES BRUTES'!A$3:A$90,MATCH(1,('DONNÉES BRUTES'!Z$3:Z$90>=LARGE('DONNÉES BRUTES'!Z$3:Z$90,4))*(COUNTIF(I$8:I10,'DONNÉES BRUTES'!A$3:A$90)=0)*('DONNÉES BRUTES'!A$3:A$90<>""),0)),"—")} -> ADBE | J11: =IFERROR(_xlfn.XLOOKUP(I11,'DONNÉES BRUTES'!A$3:A$90,'DONNÉES BRUTES'!B$3:B$90),"—") -> Adobe Inc. | K11: =IFERROR(_xlfn.XLOOKUP(I11,'DONNÉES BRUTES'!A$3:A$90,'DONNÉES BRUTES'!Z$3:Z$90)&"/100","—") -> 91/100 | L11: =IFERROR(_xlfn.XLOOKUP(I11,'DONNÉES BRUTES'!A$3:A$90,'DONNÉES BRUTES'!U$3:U$90),"—") -> 7.74 | N11: 4 | O11: =IFERROR(_xlfn.XLOOKUP(LARGE('DONNÉES BRUTES'!AA$3:AA$90,4),'DONNÉES BRUTES'!AA$3:AA$90,'DONNÉES BRUTES'!A$3:A$90),"—") -> HAL | P11: =IFERROR(_xlfn.XLOOKUP(O11,'DONNÉES BRUTES'!A$3:A$90,'DONNÉES BRUTES'!B$3:B$90),"—") -> Halliburton Company | Q11: =IFERROR(_xlfn.XLOOKUP(O11,'DONNÉES BRUTES'!A$3:A$90,'DONNÉES BRUTES'!AA$3:AA$90)&"/100","—") -> 96/100 | R11: =IFERROR(_xlfn.XLOOKUP(O11,'DONNÉES BRUTES'!A$3:A$90,'DONNÉES BRUTES'!W$3:W$90),"—") -> +99.5%
B12: 5 | C12: {=IFERROR(INDEX('DONNÉES BRUTES'!A$3:A$90,MATCH(1,('DONNÉES BRUTES'!Y$3:Y$90>=LARGE('DONNÉES BRUTES'!Y$3:Y$90,5))*(COUNTIF(C$8:C11,'DONNÉES BRUTES'!A$3:A$90)=0)*('DONNÉES BRUTES'!A$3:A$90<>""),0)),"—")} -> OKE | D12: =IFERROR(_xlfn.XLOOKUP(C12,'DONNÉES BRUTES'!A$3:A$90,'DONNÉES BRUTES'!B$3:B$90),"—") -> ONEOK, Inc. | E12: =IFERROR(_xlfn.XLOOKUP(C12,'DONNÉES BRUTES'!A$3:A$90,'DONNÉES BRUTES'!Y$3:Y$90)&"/100","—") -> 88/100 | F12: =IFERROR(_xlfn.XLOOKUP(C12,'DONNÉES BRUTES'!A$3:A$90,'DONNÉES BRUTES'!P$3:P$90),"—") -> 0.55 | H12: 5 | I12: {=IFERROR(INDEX('DONNÉES BRUTES'!A$3:A$90,MATCH(1,('DONNÉES BRUTES'!Z$3:Z$90>=LARGE('DONNÉES BRUTES'!Z$3:Z$90,5))*(COUNTIF(I$8:I11,'DONNÉES BRUTES'!A$3:A$90)=0)*('DONNÉES BRUTES'!A$3:A$90<>""),0)),"—")} -> CRM | J12: =IFERROR(_xlfn.XLOOKUP(I12,'DONNÉES BRUTES'!A$3:A$90,'DONNÉES BRUTES'!B$3:B$90),"—") -> Salesforce, Inc. | K12: =IFERROR(_xlfn.XLOOKUP(I12,'DONNÉES BRUTES'!A$3:A$90,'DONNÉES BRUTES'!Z$3:Z$90)&"/100","—") -> 88/100 | L12: =IFERROR(_xlfn.XLOOKUP(I12,'DONNÉES BRUTES'!A$3:A$90,'DONNÉES BRUTES'!U$3:U$90),"—") -> — | N12: 5 | O12: =IFERROR(_xlfn.XLOOKUP(LARGE('DONNÉES BRUTES'!AA$3:AA$90,5),'DONNÉES BRUTES'!AA$3:AA$90,'DONNÉES BRUTES'!A$3:A$90),"—") -> VLO | P12: =IFERROR(_xlfn.XLOOKUP(O12,'DONNÉES BRUTES'!A$3:A$90,'DONNÉES BRUTES'!B$3:B$90),"—") -> Valero Energy Corporation | Q12: =IFERROR(_xlfn.XLOOKUP(O12,'DONNÉES BRUTES'!A$3:A$90,'DONNÉES BRUTES'!AA$3:AA$90)&"/100","—") -> 92/100 | R12: =IFERROR(_xlfn.XLOOKUP(O12,'DONNÉES BRUTES'!A$3:A$90,'DONNÉES BRUTES'!W$3:W$90),"—") -> +92.9%
B14: TOP 10 GLOBAL · Score Composite · Growth / Quality / Momentum
B15: # | C15: Ticker | D15: Société | E15: Score | G15: Revenue | H15: Rev Gr YoY | I15: EBITDA | K15: Mg EBITDA | L15: Mg Nette | N15: ROE | O15: EV/EBITDA
B16: 1 | C16: =IFERROR(_xlfn.XLOOKUP(LARGE('DONNÉES BRUTES'!AB$3:AB$90,1),'DONNÉES BRUTES'!AB$3:AB$90,'DONNÉES BRUTES'!A$3:A$90),"—") -> ENI.MI | D16: =IFERROR(_xlfn.XLOOKUP(C16,'DONNÉES BRUTES'!A$3:A$90,'DONNÉES BRUTES'!B$3:B$90),"—") -> Eni S.p.A. | E16: =IFERROR(_xlfn.XLOOKUP(C16,'DONNÉES BRUTES'!A$3:A$90,'DONNÉES BRUTES'!AB$3:AB$90)&"/100","—") -> 79/100 | G16: =IFERROR(_xlfn.XLOOKUP(C16,'DONNÉES BRUTES'!A$3:A$90,'DONNÉES BRUTES'!G$3:G$90),"—") -> — | H16: =IFERROR(_xlfn.XLOOKUP(C16,'DONNÉES BRUTES'!A$3:A$90,'DONNÉES BRUTES'!P$3:P$90),"—") -> — | I16: =IFERROR(_xlfn.XLOOKUP(C16,'DONNÉES BRUTES'!A$3:A$90,'DONNÉES BRUTES'!H$3:H$90),"—") -> — | K16: =IFERROR(_xlfn.XLOOKUP(C16,'DONNÉES BRUTES'!A$3:A$90,'DONNÉES BRUTES'!N$3:N$90),"—") -> — | L16: =IFERROR(_xlfn.XLOOKUP(C16,'DONNÉES BRUTES'!A$3:A$90,'DONNÉES BRUTES'!O$3:O$90),"—") -> — | N16: =IFERROR(_xlfn.XLOOKUP(C16,'DONNÉES BRUTES'!A$3:A$90,'DONNÉES BRUTES'!Q$3:Q$90),"—") -> — | O16: =IFERROR(_xlfn.XLOOKUP(C16,'DONNÉES BRUTES'!A$3:A$90,'DONNÉES BRUTES'!I$3:I$90),"—") -> —
B17: 2 | C17: {=IFERROR(INDEX('DONNÉES BRUTES'!A$3:A$90,MATCH(1,('DONNÉES BRUTES'!AB$3:AB$90=LARGE('DONNÉES BRUTES'!AB$3:AB$90,2))*(COUNTIF(C$16:C16,'DONNÉES BRUTES'!A$3:A$90)=0)*('DONNÉES BRUTES'!A$3:A$90<>""),0)),"—")} -> APA | D17: =IFERROR(_xlfn.XLOOKUP(C17,'DONNÉES BRUTES'!A$3:A$90,'DONNÉES BRUTES'!B$3:B$90),"—") -> APA Corporation | E17: =IFERROR(_xlfn.XLOOKUP(C17,'DONNÉES BRUTES'!A$3:A$90,'DONNÉES BRUTES'!AB$3:AB$90)&"/100","—") -> 77/100 | G17: =IFERROR(_xlfn.XLOOKUP(C17,'DONNÉES BRUTES'!A$3:A$90,'DONNÉES BRUTES'!G$3:G$90),"—") -> $8.9 | H17: =IFERROR(_xlfn.XLOOKUP(C17,'DONNÉES BRUTES'!A$3:A$90,'DONNÉES BRUTES'!P$3:P$90),"—") -> -0.084 | I17: =IFERROR(_xlfn.XLOOKUP(C17,'DONNÉES BRUTES'!A$3:A$90,'DONNÉES BRUTES'!H$3:H$90),"—") -> $5.4 | K17: =IFERROR(_xlfn.XLOOKUP(C17,'DONNÉES BRUTES'!A$3:A$90,'DONNÉES BRUTES'!N$3:N$90),"—") -> 0.602 | L17: =IFERROR(_xlfn.XLOOKUP(C17,'DONNÉES BRUTES'!A$3:A$90,'DONNÉES BRUTES'!O$3:O$90),"—") -> 0.161 | N17: =IFERROR(_xlfn.XLOOKUP(C17,'DONNÉES BRUTES'!A$3:A$90,'DONNÉES BRUTES'!Q$3:Q$90),"—") -> 0.235 | O17: =IFERROR(_xlfn.XLOOKUP(C17,'DONNÉES BRUTES'!A$3:A$90,'DONNÉES BRUTES'!I$3:I$90),"—") -> 3.2x
B18: 3 | C18: {=IFERROR(INDEX('DONNÉES BRUTES'!A$3:A$90,MATCH(1,('DONNÉES BRUTES'!AB$3:AB$90>=LARGE('DONNÉES BRUTES'!AB$3:AB$90,3))*(COUNTIF(C$16:C17,'DONNÉES BRUTES'!A$3:A$90)=0)*('DONNÉES BRUTES'!A$3:A$90<>""),0)),"—")} -> TTE.PA | D18: =IFERROR(_xlfn.XLOOKUP(C18,'DONNÉES BRUTES'!A$3:A$90,'DONNÉES BRUTES'!B$3:B$90),"—") -> TotalEnergies SE | E18: =IFERROR(_xlfn.XLOOKUP(C18,'DONNÉES BRUTES'!A$3:A$90,'DONNÉES BRUTES'!AB$3:AB$90)&"/100","—") -> 77/100 | G18: =IFERROR(_xlfn.XLOOKUP(C18,'DONNÉES BRUTES'!A$3:A$90,'DONNÉES BRUTES'!G$3:G$90),"—") -> — | H18: =IFERROR(_xlfn.XLOOKUP(C18,'DONNÉES BRUTES'!A$3:A$90,'DONNÉES BRUTES'!P$3:P$90),"—") -> — | I18: =IFERROR(_xlfn.XLOOKUP(C18,'DONNÉES BRUTES'!A$3:A$90,'DONNÉES BRUTES'!H$3:H$90),"—") -> — | K18: =IFERROR(_xlfn.XLOOKUP(C18,'DONNÉES BRUTES'!A$3:A$90,'DONNÉES BRUTES'!N$3:N$90),"—") -> — | L18: =IFERROR(_xlfn.XLOOKUP(C18,'DONNÉES BRUTES'!A$3:A$90,'DONNÉES BRUTES'!O$3:O$90),"—") -> — | N18: =IFERROR(_xlfn.XLOOKUP(C18,'DONNÉES BRUTES'!A$3:A$90,'DONNÉES BRUTES'!Q$3:Q$90),"—") -> — | O18: =IFERROR(_xlfn.XLOOKUP(C18,'DONNÉES BRUTES'!A$3:A$90,'DONNÉES BRUTES'!I$3:I$90),"—") -> —
B19: 4 | C19: {=IFERROR(INDEX('DONNÉES BRUTES'!A$3:A$90,MATCH(1,('DONNÉES BRUTES'!AB$3:AB$90>=LARGE('DONNÉES BRUTES'!AB$3:AB$90,4))*(COUNTIF(C$16:C18,'DONNÉES BRUTES'!A$3:A$90)=0)*('DONNÉES BRUTES'!A$3:A$90<>""),0)),"—")} -> AMAT | D19: =IFERROR(_xlfn.XLOOKUP(C19,'DONNÉES BRUTES'!A$3:A$90,'DONNÉES BRUTES'!B$3:B$90),"—") -> Applied Materials, Inc. | E19: =IFERROR(_xlfn.XLOOKUP(C19,'DONNÉES BRUTES'!A$3:A$90,'DONNÉES BRUTES'!AB$3:AB$90)&"/100","—") -> 77/100 | G19: =IFERROR(_xlfn.XLOOKUP(C19,'DONNÉES BRUTES'!A$3:A$90,'DONNÉES BRUTES'!G$3:G$90),"—") -> $28.4 | H19: =IFERROR(_xlfn.XLOOKUP(C19,'DONNÉES BRUTES'!A$3:A$90,'DONNÉES BRUTES'!P$3:P$90),"—") -> 0.044 | I19: =IFERROR(_xlfn.XLOOKUP(C19,'DONNÉES BRUTES'!A$3:A$90,'DONNÉES BRUTES'!H$3:H$90),"—") -> $10.0 | K19: =IFERROR(_xlfn.XLOOKUP(C19,'DONNÉES BRUTES'!A$3:A$90,'DONNÉES BRUTES'!N$3:N$90),"—") -> 0.352 | L19: =IFERROR(_xlfn.XLOOKUP(C19,'DONNÉES BRUTES'!A$3:A$90,'DONNÉES BRUTES'!O$3:O$90),"—") -> 0.247 | N19: =IFERROR(_xlfn.XLOOKUP(C19,'DONNÉES BRUTES'!A$3:A$90,'DONNÉES BRUTES'!Q$3:Q$90),"—") -> 0.343 | O19: =IFERROR(_xlfn.XLOOKUP(C19,'DONNÉES BRUTES'!A$3:A$90,'DONNÉES BRUTES'!I$3:I$90),"—") -> —
B20: 5 | C20: {=IFERROR(INDEX('DONNÉES BRUTES'!A$3:A$90,MATCH(1,('DONNÉES BRUTES'!AB$3:AB$90>=LARGE('DONNÉES BRUTES'!AB$3:AB$90,5))*(COUNTIF(C$16:C19,'DONNÉES BRUTES'!A$3:A$90)=0)*('DONNÉES BRUTES'!A$3:A$90<>""),0)),"—")} -> MSI | D20: =IFERROR(_xlfn.XLOOKUP(C20,'DONNÉES BRUTES'!A$3:A$90,'DONNÉES BRUTES'!B$3:B$90),"—") -> Motorola Solutions, Inc. | E20: =IFERROR(_xlfn.XLOOKUP(C20,'DONNÉES BRUTES'!A$3:A$90,'DONNÉES BRUTES'!AB$3:AB$90)&"/100","—") -> 77/100 | G20: =IFERROR(_xlfn.XLOOKUP(C20,'DONNÉES BRUTES'!A$3:A$90,'DONNÉES BRUTES'!G$3:G$90),"—") -> $11.7 | H20: =IFERROR(_xlfn.XLOOKUP(C20,'DONNÉES BRUTES'!A$3:A$90,'DONNÉES BRUTES'!P$3:P$90),"—") -> 0.08 | I20: =IFERROR(_xlfn.XLOOKUP(C20,'DONNÉES BRUTES'!A$3:A$90,'DONNÉES BRUTES'!H$3:H$90),"—") -> $3.6 | K20: =IFERROR(_xlfn.XLOOKUP(C20,'DONNÉES BRUTES'!A$3:A$90,'DONNÉES BRUTES'!N$3:N$90),"—") -> 0.308 | L20: =IFERROR(_xlfn.XLOOKUP(C20,'DONNÉES BRUTES'!A$3:A$90,'DONNÉES BRUTES'!O$3:O$90),"—") -> 0.184 | N20: =IFERROR(_xlfn.XLOOKUP(C20,'DONNÉES BRUTES'!A$3:A$90,'DONNÉES BRUTES'!Q$3:Q$90),"—") -> 0.894 | O20: =IFERROR(_xlfn.XLOOKUP(C20,'DONNÉES BRUTES'!A$3:A$90,'DONNÉES BRUTES'!I$3:I$90),"—") -> —
B21: 6 | C21: {=IFERROR(INDEX('DONNÉES BRUTES'!A$3:A$90,MATCH(1,('DONNÉES BRUTES'!AB$3:AB$90>=LARGE('DONNÉES BRUTES'!AB$3:AB$90,6))*(COUNTIF(C$16:C20,'DONNÉES BRUTES'!A$3:A$90)=0)*('DONNÉES BRUTES'!A$3:A$90<>""),0)),"—")} -> SAP.DE | D21: =IFERROR(_xlfn.XLOOKUP(C21,'DONNÉES BRUTES'!A$3:A$90,'DONNÉES BRUTES'!B$3:B$90),"—") -> SAP SE | E21: =IFERROR(_xlfn.XLOOKUP(C21,'DONNÉES BRUTES'!A$3:A$90,'DONNÉES BRUTES'!AB$3:AB$90)&"/100","—") -> 74/100 | G21: =IFERROR(_xlfn.XLOOKUP(C21,'DONNÉES BRUTES'!A$3:A$90,'DONNÉES BRUTES'!G$3:G$90),"—") -> €36.8 | H21: =IFERROR(_xlfn.XLOOKUP(C21,'DONNÉES BRUTES'!A$3:A$90,'DONNÉES BRUTES'!P$3:P$90),"—") -> 0.077 | I21: =IFERROR(_xlfn.XLOOKUP(C21,'DONNÉES BRUTES'!A$3:A$90,'DONNÉES BRUTES'!H$3:H$90),"—") -> €12.1 | K21: =IFERROR(_xlfn.XLOOKUP(C21,'DONNÉES BRUTES'!A$3:A$90,'DONNÉES BRUTES'!N$3:N$90),"—") -> 0.328 | L21: =IFERROR(_xlfn.XLOOKUP(C21,'DONNÉES BRUTES'!A$3:A$90,'DONNÉES BRUTES'!O$3:O$90),"—") -> 0.195 | N21: =IFERROR(_xlfn.XLOOKUP(C21,'DONNÉES BRUTES'!A$3:A$90,'DONNÉES BRUTES'!Q$3:Q$90),"—") -> 0.161 | O21: =IFERROR(_xlfn.XLOOKUP(C21,'DONNÉES BRUTES'!A$3:A$90,'DONNÉES BRUTES'!I$3:I$90),"—") -> —
B22: 7 | C22: {=IFERROR(INDEX('DONNÉES BRUTES'!A$3:A$90,MATCH(1,('DONNÉES BRUTES'!AB$3:AB$90>=LARGE('DONNÉES BRUTES'!AB$3:AB$90,7))*(COUNTIF(C$16:C21,'DONNÉES BRUTES'!A$3:A$90)=0)*('DONNÉES BRUTES'!A$3:A$90<>""),0)),"—")} -> CIEN | D22: =IFERROR(_xlfn.XLOOKUP(C22,'DONNÉES BRUTES'!A$3:A$90,'DONNÉES BRUTES'!B$3:B$90),"—") -> Ciena Corporation | E22: =IFERROR(_xlfn.XLOOKUP(C22,'DONNÉES BRUTES'!A$3:A$90,'DONNÉES BRUTES'!AB$3:AB$90)&"/100","—") -> 73/100 | G22: =IFERROR(_xlfn.XLOOKUP(C22,'DONNÉES BRUTES'!A$3:A$90,'DONNÉES BRUTES'!G$3:G$90),"—") -> $4.8 | H22: =IFERROR(_xlfn.XLOOKUP(C22,'DONNÉES BRUTES'!A$3:A$90,'DONNÉES BRUTES'!P$3:P$90),"—") -> 0.188 | I22: =IFERROR(_xlfn.XLOOKUP(C22,'DONNÉES BRUTES'!A$3:A$90,'DONNÉES BRUTES'!H$3:H$90),"—") -> $0.4 | K22: =IFERROR(_xlfn.XLOOKUP(C22,'DONNÉES BRUTES'!A$3:A$90,'DONNÉES BRUTES'!N$3:N$90),"—") -> 0.081 | L22: =IFERROR(_xlfn.XLOOKUP(C22,'DONNÉES BRUTES'!A$3:A$90,'DONNÉES BRUTES'!O$3:O$90),"—") -> 0.026 | N22: =IFERROR(_xlfn.XLOOKUP(C22,'DONNÉES BRUTES'!A$3:A$90,'DONNÉES BRUTES'!Q$3:Q$90),"—") -> 0.045 | O22: =IFERROR(_xlfn.XLOOKUP(C22,'DONNÉES BRUTES'!A$3:A$90,'DONNÉES BRUTES'!I$3:I$90),"—") -> —
B23: 8 | C23: {=IFERROR(INDEX('DONNÉES BRUTES'!A$3:A$90,MATCH(1,('DONNÉES BRUTES'!AB$3:AB$90>=LARGE('DONNÉES BRUTES'!AB$3:AB$90,8))*(COUNTIF(C$16:C22,'DONNÉES BRUTES'!A$3:A$90)=0)*('DONNÉES BRUTES'!A$3:A$90<>""),0)),"—")} -> PSX | D23: =IFERROR(_xlfn.XLOOKUP(C23,'DONNÉES BRUTES'!A$3:A$90,'DONNÉES BRUTES'!B$3:B$90),"—") -> Phillips 66 | E23: =IFERROR(_xlfn.XLOOKUP(C23,'DONNÉES BRUTES'!A$3:A$90,'DONNÉES BRUTES'!AB$3:AB$90)&"/100","—") -> 71/100 | G23: =IFERROR(_xlfn.XLOOKUP(C23,'DONNÉES BRUTES'!A$3:A$90,'DONNÉES BRUTES'!G$3:G$90),"—") -> $132.4 | H23: =IFERROR(_xlfn.XLOOKUP(C23,'DONNÉES BRUTES'!A$3:A$90,'DONNÉES BRUTES'!P$3:P$90),"—") -> -0.075 | I23: =IFERROR(_xlfn.XLOOKUP(C23,'DONNÉES BRUTES'!A$3:A$90,'DONNÉES BRUTES'!H$3:H$90),"—") -> $9.8 | K23: =IFERROR(_xlfn.XLOOKUP(C23,'DONNÉES BRUTES'!A$3:A$90,'DONNÉES BRUTES'!N$3:N$90),"—") -> 0.074 | L23: =IFERROR(_xlfn.XLOOKUP(C23,'DONNÉES BRUTES'!A$3:A$90,'DONNÉES BRUTES'!O$3:O$90),"—") -> 0.033 | N23: =IFERROR(_xlfn.XLOOKUP(C23,'DONNÉES BRUTES'!A$3:A$90,'DONNÉES BRUTES'!Q$3:Q$90),"—") -> 0.151 | O23: =IFERROR(_xlfn.XLOOKUP(C23,'DONNÉES BRUTES'!A$3:A$90,'DONNÉES BRUTES'!I$3:I$90),"—") -> 8.6x
B24: 9 | C24: {=IFERROR(INDEX('DONNÉES BRUTES'!A$3:A$90,MATCH(1,('DONNÉES BRUTES'!AB$3:AB$90>=LARGE('DONNÉES BRUTES'!AB$3:AB$90,9))*(COUNTIF(C$16:C23,'DONNÉES BRUTES'!A$3:A$90)=0)*('DONNÉES BRUTES'!A$3:A$90<>""),0)),"—")} -> FTNT | D24: =IFERROR(_xlfn.XLOOKUP(C24,'DONNÉES BRUTES'!A$3:A$90,'DONNÉES BRUTES'!B$3:B$90),"—") -> Fortinet, Inc. | E24: =IFERROR(_xlfn.XLOOKUP(C24,'DONNÉES BRUTES'!A$3:A$90,'DONNÉES BRUTES'!AB$3:AB$90)&"/100","—") -> 70/100 | G24: =IFERROR(_xlfn.XLOOKUP(C24,'DONNÉES BRUTES'!A$3:A$90,'DONNÉES BRUTES'!G$3:G$90),"—") -> $6.8 | H24: =IFERROR(_xlfn.XLOOKUP(C24,'DONNÉES BRUTES'!A$3:A$90,'DONNÉES BRUTES'!P$3:P$90),"—") -> 0.142 | I24: =IFERROR(_xlfn.XLOOKUP(C24,'DONNÉES BRUTES'!A$3:A$90,'DONNÉES BRUTES'!H$3:H$90),"—") -> $2.5 | K24: =IFERROR(_xlfn.XLOOKUP(C24,'DONNÉES BRUTES'!A$3:A$90,'DONNÉES BRUTES'!N$3:N$90),"—") -> 0.361 | L24: =IFERROR(_xlfn.XLOOKUP(C24,'DONNÉES BRUTES'!A$3:A$90,'DONNÉES BRUTES'!O$3:O$90),"—") -> 0.273 | N24: =IFERROR(_xlfn.XLOOKUP(C24,'DONNÉES BRUTES'!A$3:A$90,'DONNÉES BRUTES'!Q$3:Q$90),"—") -> 1.498 | O24: =IFERROR(_xlfn.XLOOKUP(C24,'DONNÉES BRUTES'!A$3:A$90,'DONNÉES BRUTES'!I$3:I$90),"—") -> —
B25: 10 | C25: {=IFERROR(INDEX('DONNÉES BRUTES'!A$3:A$90,MATCH(1,('DONNÉES BRUTES'!AB$3:AB$90>=LARGE('DONNÉES BRUTES'!AB$3:AB$90,10))*(COUNTIF(C$16:C24,'DONNÉES BRUTES'!A$3:A$90)=0)*('DONNÉES BRUTES'!A$3:A$90<>""),0)),"—")} -> XYZ | D25: =IFERROR(_xlfn.XLOOKUP(C25,'DONNÉES BRUTES'!A$3:A$90,'DONNÉES BRUTES'!B$3:B$90),"—") -> Block, Inc. | E25: =IFERROR(_xlfn.XLOOKUP(C25,'DONNÉES BRUTES'!A$3:A$90,'DONNÉES BRUTES'!AB$3:AB$90)&"/100","—") -> 70/100 | G25: =IFERROR(_xlfn.XLOOKUP(C25,'DONNÉES BRUTES'!A$3:A$90,'DONNÉES BRUTES'!G$3:G$90),"—") -> $24.2 | H25: =IFERROR(_xlfn.XLOOKUP(C25,'DONNÉES BRUTES'!A$3:A$90,'DONNÉES BRUTES'!P$3:P$90),"—") -> 0.003 | I25: =IFERROR(_xlfn.XLOOKUP(C25,'DONNÉES BRUTES'!A$3:A$90,'DONNÉES BRUTES'!H$3:H$90),"—") -> $3.4 | K25: =IFERROR(_xlfn.XLOOKUP(C25,'DONNÉES BRUTES'!A$3:A$90,'DONNÉES BRUTES'!N$3:N$90),"—") -> 0.141 | L25: =IFERROR(_xlfn.XLOOKUP(C25,'DONNÉES BRUTES'!A$3:A$90,'DONNÉES BRUTES'!O$3:O$90),"—") -> 0.054 | N25: =IFERROR(_xlfn.XLOOKUP(C25,'DONNÉES BRUTES'!A$3:A$90,'DONNÉES BRUTES'!Q$3:Q$90),"—") -> 0.059 | O25: =IFERROR(_xlfn.XLOOKUP(C25,'DONNÉES BRUTES'!A$3:A$90,'DONNÉES BRUTES'!I$3:I$90),"—") -> —
B27: FinSight IA · Screening Énergie · Scores calculés sur métriques Growth, Quality, Momentum · Ne constitue pas un conseil en investissement

Sheet VALUE
B1: FinSight IA · Analyse VALUE · Énergie Screening (ScoreVal N/A → classé par Score Global) | P1: Ticker | Q1: Score | S1: Ticker | T1: Mg% | V1: Ticker | W1: Altman Z | Y1: Signal | Z1: Nb
B2: Usage confidentiel · Calculs FinSight IA · Screening Énergie | P2: NVDA | Q2: 88 | S2: NVDA | T2: 66.9 | V2: NVDA | W2: 13.22 | Y2: Surpondérer | Z2: 8
C3: =COUNTA('DONNÉES BRUTES'!A$3:A$90) -> 88 | H3: =IFERROR(_xlfn.XLOOKUP(LARGE('DONNÉES BRUTES'!AB$3:AB$90,1),'DONNÉES BRUTES'!AB$3:AB$90,'DONNÉES BRUTES'!A$3:A$90),"—") -> ENI.MI | M3: =IFERROR(ROUND(AVERAGE('DONNÉES BRUTES'!AB$3:AB$90),0)&"/100","—") -> 53/100 | P3: KLAC | Q3: 84 | S3: KLAC | T3: 43.9 | V3: KLAC | W3: 5.64 | Y3: Neutre | Z3: 29
C4: Sociétés | H4: #1 Score Global | M4: Moy. Score Score Global | P4: ANET | Q4: 83 | S4: ANET | T4: 43.6 | V4: ANET | W4: 8.46 | Y4: Sous-pondérer | Z4: 51
B5: ANALYSE DÉTAILLÉE · ÉNERGIE · TOP 20 par Score Global · Triée par Score Score Global | P5: AVGO | Q5: 81 | S5: AVGO | T5: 54.3 | V5: AVGO | W5: 2.66
B6: # | C6: Ticker | D6: Société | F6: Score | G6: EV/EBITDA | H6: EV/Rev | I6: P/E | J6: Mg Brute | K6: Mg EBITDA | L6: Altman Z | M6: FCF Yield | N6: Signal | P6: MU | Q6: 78 | S6: MU | T6: 49.4 | V6: MU | W6: 6.1
B7: 1 | C7: APA | D7: APA Corporation | F7: 100/100 | G7: 3.2x | H7: 1.9x | I7: 9.3x | J7: 40.6% | K7: 60.2% | L7: 1.46 | M7: 13.3% | N7: Surpondérer | P7: MPWR | Q7: 78 | S7: MPWR | T7: 28 | V7: MPWR | W7: 11.63
B8: 2 | C8: DVN | D8: Devon Energy Corporation | F8: 96/100 | G8: 4.7x | H8: 2.1x | I8: 10.8x | J8: 25.5% | K8: 44.0% | L8: 2.89 | M8: 9.8% | N8: Surpondérer | P8: LRCX | Q8: 77 | S8: LRCX | T8: 35.4 | V8: LRCX | W8: 9.7
B9: 3 | C9: EXE | D9: Expand Energy Corporation | F9: 92/100 | G9: 5.1x | H9: 2.3x | I9: 12.8x | J9: 50.8% | K9: 45.1% | L9: 3.17 | M9: 7.0% | N9: Surpondérer | P9: WDC | Q9: 77 | S9: WDC | T9: 20.4 | V9: WDC | W9: 1.76
B10: 4 | C10: CTRA | D10: Coterra Energy Inc. | F10: 88/100 | G10: 5.8x | H10: 3.7x | I10: 14.2x | J10: 41.5% | K10: 63.5% | L10: 3.35 | M10: 6.7% | N10: Surpondérer | P10: PTC | Q10: 74 | S10: PTC | T10: 41.3 | V10: PTC | W10: 3.62
B11: 5 | C11: PSX | D11: Phillips 66 | F11: 83/100 | G11: 8.6x | H11: 0.6x | I11: 14.9x | J11: 9.8% | K11: 7.4% | L11: 3.12 | M11: 4.2% | N11: Neutre | P11: AMD | Q11: 73 | S11: AMD | T11: 21 | V11: AMD | W11: 6.9
B12: 6 | C12: EOG | D12: EOG Resources, Inc. | F12: 79/100 | G12: 6.9x | H12: 3.4x | I12: 14.4x | J12: 63.4% | K12: 49.0% | L12: 4.53 | M12: 4.8% | N12: Neutre | P12: ASML | Q12: 72 | S12: ASML | T12: 38.4 | V12: ASML.AS | W12: 4.15
B13: 7 | C13: MPC | D13: Marathon Petroleum Corporation | F13: 75/100 | G13: 8.2x | H13: 0.7x | I13: 16.5x | J13: 7.5% | K13: 8.8% | L13: 2.92 | M13: 7.1% | N13: Neutre | P13: ADI | Q13: 71 | S13: ADI | T13: 45.6 | V13: ADI | W13: 4.17
B14: 8 | C14: COP | D14: ConocoPhillips | F14: 71/100 | G14: 6.4x | H14: 2.8x | I14: 18.6x | J14: 25.1% | K14: 43.4% | L14: 3.98 | M14: 4.9% | N14: Neutre | P14: GLW | Q14: 68 | S14: GLW | T14: 23.9 | V14: GLW | W14: 3.62
B15: 9 | C15: OKE | D15: ONEOK, Inc. | F15: 67/100 | G15: 11.1x | H15: 2.6x | I15: 15.8x | J15: 26.0% | K15: 23.2% | L15: 1.10 | M15: 4.6% | N15: Neutre | P15: INTC | Q15: 67 | S15: INTC | T15: 27.2 | V15: INTC | W15: 3.25
B16: 10 | C16: EQT | D16: EQT Corporation | F16: 62/100 | G16: 7.3x | H16: 5.3x | I16: 17.8x | J16: 43.2% | K16: 72.0% | L16: 2.52 | M16: 7.8% | N16: Neutre | P16: KEYS | Q16: 67 | S16: KEYS | T16: 27.1 | V16: KEYS | W16: 5.33
B17: 11 | C17: XOM | D17: Exxon Mobil Corporation | F17: 58/100 | G17: 9.7x | H17: 2.0x | I17: 21.9x | J17: 22.0% | K17: 21.0% | L17: 5.79 | M17: 3.7% | N17: Sous-pondérer | P17: APH | Q17: 66 | S17: APH | T17: 29.8 | V17: APH | W17: 5.05
B18: 12 | C18: OXY | D18: Occidental Petroleum Corporation | F18: 54/100 | G18: 6.5x | H18: 3.5x | I18: 24.2x | J18: 34.9% | K18: 54.0% | L18: 1.74 | M18: 7.3% | N18: Neutre | P18: CDNS | Q18: 66 | S18: CDNS | T18: 35.4 | V18: CDNS | W18: 6.55
... B21: 15 | C21: BKR | D21: Baker Hughes Company | F21: 42/100 | G21: 14.6x | H21: 2.3x | I21: 23.2x | J21: 23.6% | K21: 15.5% | L21: 1.95 | M21: 4.2% | N21: Neutre | P21: ADSK | Q21: 65 | S21: ADSK | T21: 27.6 | V21: ADSK | W21: 0.48
B22: 16 | C22: CVX | D22: Chevron Corporation | F22: 38/100 | G22: 9.8x | H22: 2.2x | I22: 30.4x | J22: 30.4% | K22: 22.5% | L22: 4.09 | M22: 4.4% | N22: Sous-pondérer
B23: 17 | C23: VLO | D23: Valero Energy Corporation | F23: 33/100 | G23: 11.6x | H23: 0.6x | I23: 30.8x | J23: 4.4% | K23: 5.5% | L23: 4.93 | M23: 7.0% | N23: Sous-pondérer
B24: 18 | C24: KMI | D24: Kinder Morgan, Inc. | F24: 29/100 | G24: 14.3x | H24: 6.0x | I24: 23.2x | J24: 52.9% | K24: 42.4% | L24: 0.65 | M24: 4.1% | N24: Neutre
B25: 19 | C25: TRGP | D25: Targa Resources Corp. | F25: 25/100 | G25: 14.1x | H25: 4.0x | I25: 26.8x | J25: 29.4% | K25: 28.5% | L25: 1.02 | M25: 1.1% | N25: Neutre
B26: 20 | C26: FANG | D26: Diamondback Energy, Inc. | F26: 21/100 | G26: 9.3x | H26: 4.5x | I26: 31.6x | J26: 35.0% | K26: 48.1% | L26: 1.55 | M26: -1.3% | N26: Neutre
B28: FinSight IA · Screening Énergie · Ne constitue pas un conseil en investissement

Sheet GROWTH
B1: FinSight IA · Analyse GROWTH · Énergie Screening | N1: Ticker | O1: Score | Q1: Ticker | R1: Rev% | T1: Ticker | U1: Mg EBITDA (%) | W1: Score Growth | X1: Score Global | Z1: Signal | AA1: Nb
B2: Usage confidentiel · Calculs FinSight IA · Screening Énergie | N2: INTC | O2: 100 | Q2: INTC | R2: -0.5 | T2: INTC | U2: 27.2 | W2: 100 | X2: 67 | Z2: Surpondérer | AA2: 8
C3: =COUNTA('DONNÉES BRUTES'!A$3:A$90) -> 88 | G3: =IFERROR(_xlfn.XLOOKUP(LARGE('DONNÉES BRUTES'!Y$3:Y$90,1),'DONNÉES BRUTES'!Y$3:Y$90,'DONNÉES BRUTES'!A$3:A$90),"—") -> EXE | L3: =IFERROR(ROUND(AVERAGE('DONNÉES BRUTES'!Y$3:Y$90),0)&"/100","—") -> 41/100 | N3: WDC | O3: 99 | Q3: WDC | R3: 50.7 | T3: WDC | U3: 20.4 | W3: 99 | X3: 77 | Z3: Neutre | AA3: 29
C4: Sociétés | G4: #1 Growth | L4: Moy. Score Growth | N4: MU | O4: 98 | Q4: MU | R4: 48.9 | T4: MU | U4: 49.4 | W4: 98 | X4: 78 | Z4: Sous-pondérer | AA4: 51
B5: ANALYSE DÉTAILLÉE · ÉNERGIE · TOP 20 par Growth · Triée par Score Growth | N5: STX | O5: 97 | Q5: STX | R5: 38.9 | T5: STX | U5: 22.9 | W5: 97 | X5: 73
B6: # | C6: Ticker | D6: Société | F6: Score | G6: Croiss. Rev | H6: Mg EBITDA | I6: Mg Nette | J6: ROE | K6: Score Global | L6: Next Earn. | M6: Signal | N6: NVDA | O6: 95 | Q6: NVDA | R6: 65.5 | T6: NVDA | U6: 66.9 | W6: 95 | X6: 88
B7: 1 | C7: =IFERROR(_xlfn.XLOOKUP(LARGE('DONNÉES BRUTES'!Y$3:Y$90,1),'DONNÉES BRUTES'!Y$3:Y$90,'DONNÉES BRUTES'!A$3:A$90),"—") -> EXE | D7: =IFERROR(_xlfn.XLOOKUP(C7,'DONNÉES BRUTES'!A$3:A$90,'DONNÉES BRUTES'!B$3:B$90),"—") -> Expand Energy Corporation | F7: =IFERROR(_xlfn.XLOOKUP(C7,'DONNÉES BRUTES'!A$3:A$90,'DONNÉES BRUTES'!Y$3:Y$90)&"/100","—") -> 100/100 | G7: =IFERROR(_xlfn.XLOOKUP(C7,'DONNÉES BRUTES'!A$3:A$90,'DONNÉES BRUTES'!P$3:P$90),"—") -> 1.888 | H7: =IFERROR(_xlfn.XLOOKUP(C7,'DONNÉES BRUTES'!A$3:A$90,'DONNÉES BRUTES'!N$3:N$90),"—") -> 0.451 | I7: =IFERROR(_xlfn.XLOOKUP(C7,'DONNÉES BRUTES'!A$3:A$90,'DONNÉES BRUTES'!O$3:O$90),"—") -> 0.149 | J7: =IFERROR(_xlfn.XLOOKUP(C7,'DONNÉES BRUTES'!A$3:A$90,'DONNÉES BRUTES'!Q$3:Q$90),"—") -> 0.098 | K7: =IFERROR(_xlfn.XLOOKUP(C7,'DONNÉES BRUTES'!A$3:A$90,'DONNÉES BRUTES'!AB$3:AB$90),"—") -> 63 | L7: =IFERROR(_xlfn.XLOOKUP(C7,'DONNÉES BRUTES'!A$3:A$90,'DONNÉES BRUTES'!AC$3:AC$90),"—") -> 2026-04-28 | M7: =IFERROR(_xlfn.XLOOKUP(C7,'DONNÉES BRUTES'!A$3:A$90,'DONNÉES BRUTES'!AD$3:AD$90),"—") -> Surpondérer | N7: APH | O7: 94 | Q7: APH | R7: 51.7 | T7: APH | U7: 29.8 | W7: 94 | X7: 66
B8: 2 | C8: =IFERROR(_xlfn.XLOOKUP(LARGE('DONNÉES BRUTES'!Y$3:Y$90,2),'DONNÉES BRUTES'!Y$3:Y$90,'DONNÉES BRUTES'!A$3:A$90),"—") -> EQT | D8: =IFERROR(_xlfn.XLOOKUP(C8,'DONNÉES BRUTES'!A$3:A$90,'DONNÉES BRUTES'!B$3:B$90),"—") -> EQT Corporation | F8: =IFERROR(_xlfn.XLOOKUP(C8,'DONNÉES BRUTES'!A$3:A$90,'DONNÉES BRUTES'!Y$3:Y$90)&"/100","—") -> 96/100 | G8: =IFERROR(_xlfn.XLOOKUP(C8,'DONNÉES BRUTES'!A$3:A$90,'DONNÉES BRUTES'!P$3:P$90),"—") -> 0.6 | H8: =IFERROR(_xlfn.XLOOKUP(C8,'DONNÉES BRUTES'!A$3:A$90,'DONNÉES BRUTES'!N$3:N$90),"—") -> 0.72 | I8: =IFERROR(_xlfn.XLOOKUP(C8,'DONNÉES BRUTES'!A$3:A$90,'DONNÉES BRUTES'!O$3:O$90),"—") -> 0.244 | J8: =IFERROR(_xlfn.XLOOKUP(C8,'DONNÉES BRUTES'!A$3:A$90,'DONNÉES BRUTES'!Q$3:Q$90),"—") -> 0.086 | K8: =IFERROR(_xlfn.XLOOKUP(C8,'DONNÉES BRUTES'!A$3:A$90,'DONNÉES BRUTES'!AB$3:AB$90),"—") -> 60 | L8: =IFERROR(_xlfn.XLOOKUP(C8,'DONNÉES BRUTES'!A$3:A$90,'DONNÉES BRUTES'!AC$3:AC$90),"—") -> 2026-04-21 | M8: =IFERROR(_xlfn.XLOOKUP(C8,'DONNÉES BRUTES'!A$3:A$90,'DONNÉES BRUTES'!AD$3:AD$90),"—") -> Neutre | N8: SAP.DE | O8: 93 | Q8: SAP.DE | R8: 7.7 | T8: SAP.DE | U8: 32.8 | W8: 93 | X8: 59
B9: 3 | C9: =IFERROR(_xlfn.XLOOKUP(LARGE('DONNÉES BRUTES'!Y$3:Y$90,3),'DONNÉES BRUTES'!Y$3:Y$90,'DONNÉES BRUTES'!A$3:A$90),"—") -> SAP.DE | D9: =IFERROR(_xlfn.XLOOKUP(C9,'DONNÉES BRUTES'!A$3:A$90,'DONNÉES BRUTES'!B$3:B$90),"—") -> SAP SE | F9: =IFERROR(_xlfn.XLOOKUP(C9,'DONNÉES BRUTES'!A$3:A$90,'DONNÉES BRUTES'!Y$3:Y$90)&"/100","—") -> 93/100 | G9: =IFERROR(_xlfn.XLOOKUP(C9,'DONNÉES BRUTES'!A$3:A$90,'DONNÉES BRUTES'!P$3:P$90),"—") -> 0.077 | H9: =IFERROR(_xlfn.XLOOKUP(C9,'DONNÉES BRUTES'!A$3:A$90,'DONNÉES BRUTES'!N$3:N$90),"—") -> 0.328 | I9: =IFERROR(_xlfn.XLOOKUP(C9,'DONNÉES BRUTES'!A$3:A$90,'DONNÉES BRUTES'!O$3:O$90),"—") -> 0.195 | J9: =IFERROR(_xlfn.XLOOKUP(C9,'DONNÉES BRUTES'!A$3:A$90,'DONNÉES BRUTES'!Q$3:Q$90),"—") -> 0.161 | K9: =IFERROR(_xlfn.XLOOKUP(C9,'DONNÉES BRUTES'!A$3:A$90,'DONNÉES BRUTES'!AB$3:AB$90),"—") -> 74 | L9: =IFERROR(_xlfn.XLOOKUP(C9,'DONNÉES BRUTES'!A$3:A$90,'DONNÉES BRUTES'!AC$3:AC$90),"—") -> 2026-04-23 | M9: =IFERROR(_xlfn.XLOOKUP(C9,'DONNÉES BRUTES'!A$3:A$90,'DONNÉES BRUTES'!AD$3:AD$90),"—") -> Neutre | N9: AMD | O9: 92 | Q9: AMD | R9: 34.3 | T9: AMD | U9: 21 | W9: 92 | X9: 73
B10: 4 | C10: =IFERROR(_xlfn.XLOOKUP(LARGE('DONNÉES BRUTES'!Y$3:Y$90,4),'DONNÉES BRUTES'!Y$3:Y$90,'DONNÉES BRUTES'!A$3:A$90),"—") -> CTRA | D10: =IFERROR(_xlfn.XLOOKUP(C10,'DONNÉES BRUTES'!A$3:A$90,'DONNÉES BRUTES'!B$3:B$90),"—") -> Coterra Energy Inc. | F10: =IFERROR(_xlfn.XLOOKUP(C10,'DONNÉES BRUTES'!A$3:A$90,'DONNÉES BRUTES'!Y$3:Y$90)&"/100","—") -> 92/100 | G10: =IFERROR(_xlfn.XLOOKUP(C10,'DONNÉES BRUTES'!A$3:A$90,'DONNÉES BRUTES'!P$3:P$90),"—") -> 0.401 | H10: =IFERROR(_xlfn.XLOOKUP(C10,'DONNÉES BRUTES'!A$3:A$90,'DONNÉES BRUTES'!N$3:N$90),"—") -> 0.635 | I10: =IFERROR(_xlfn.XLOOKUP(C10,'DONNÉES BRUTES'!A$3:A$90,'DONNÉES BRUTES'!O$3:O$90),"—") -> 0.225 | J10: =IFERROR(_xlfn.XLOOKUP(C10,'DONNÉES BRUTES'!A$3:A$90,'DONNÉES BRUTES'!Q$3:Q$90),"—") -> 0.116 | K10: =IFERROR(_xlfn.XLOOKUP(C10,'DONNÉES BRUTES'!A$3:A$90,'DONNÉES BRUTES'!AB$3:AB$90),"—") -> 69 | L10: =IFERROR(_xlfn.XLOOKUP(C10,'DONNÉES BRUTES'!A$3:A$90,'DONNÉES BRUTES'!AC$3:AC$90),"—") -> 2026-05-04 | M10: =IFERROR(_xlfn.XLOOKUP(C10,'DONNÉES BRUTES'!A$3:A$90,'DONNÉES BRUTES'!AD$3:AD$90),"—") -> Surpondérer | N10: PTC | O10: 91 | Q10: PTC | R10: 19.2 | T10: PTC | U10: 41.3 | W10: 91 | X10: 74
B11: 5 | C11: =IFERROR(_xlfn.XLOOKUP(LARGE('DONNÉES BRUTES'!Y$3:Y$90,5),'DONNÉES BRUTES'!Y$3:Y$90,'DONNÉES BRUTES'!A$3:A$90),"—") -> OKE | D11: =IFERROR(_xlfn.XLOOKUP(C11,'DONNÉES BRUTES'!A$3:A$90,'DONNÉES BRUTES'!B$3:B$90),"—") -> ONEOK, Inc. | F11: =IFERROR(_xlfn.XLOOKUP(C11,'DONNÉES BRUTES'!A$3:A$90,'DONNÉES BRUTES'!Y$3:Y$90)&"/100","—") -> 88/100 | G11: =IFERROR(_xlfn.XLOOKUP(C11,'DONNÉES BRUTES'!A$3:A$90,'DONNÉES BRUTES'!P$3:P$90),"—") -> 0.55 | H11: =IFERROR(_xlfn.XLOOKUP(C11,'DONNÉES BRUTES'!A$3:A$90,'DONNÉES BRUTES'!N$3:N$90),"—") -> 0.232 | I11: =IFERROR(_xlfn.XLOOKUP(C11,'DONNÉES BRUTES'!A$3:A$90,'DONNÉES BRUTES'!O$3:O$90),"—") -> 0.101 | J11: =IFERROR(_xlfn.XLOOKUP(C11,'DONNÉES BRUTES'!A$3:A$90,'DONNÉES BRUTES'!Q$3:Q$90),"—") -> 0.151 | K11: =IFERROR(_xlfn.XLOOKUP(C11,'DONNÉES BRUTES'!A$3:A$90,'DONNÉES BRUTES'!AB$3:AB$90),"—") -> 60 | L11: =IFERROR(_xlfn.XLOOKUP(C11,'DONNÉES BRUTES'!A$3:A$90,'DONNÉES BRUTES'!AC$3:AC$90),"—") -> 2026-04-28 | M11: =IFERROR(_xlfn.XLOOKUP(C11,'DONNÉES BRUTES'!A$3:A$90,'DONNÉES BRUTES'!AD$3:AD$90),"—") -> Neutre | N11: AVGO | O11: 90 | Q11: AVGO | R11: 23.9 | T11: AVGO | U11: 54.3 | W11: 90 | X11: 81
B12: 6 | C12: =IFERROR(_xlfn.XLOOKUP(LARGE('DONNÉES BRUTES'!Y$3:Y$90,6),'DONNÉES BRUTES'!Y$3:Y$90,'DONNÉES BRUTES'!A$3:A$90),"—") -> XYZ | D12: =IFERROR(_xlfn.XLOOKUP(C12,'DONNÉES BRUTES'!A$3:A$90,'DONNÉES BRUTES'!B$3:B$90),"—") -> Block, Inc. | F12: =IFERROR(_xlfn.XLOOKUP(C12,'DONNÉES BRUTES'!A$3:A$90,'DONNÉES BRUTES'!Y$3:Y$90)&"/100","—") -> 87/100 | G12: =IFERROR(_xlfn.XLOOKUP(C12,'DONNÉES BRUTES'!A$3:A$90,'DONNÉES BRUTES'!P$3:P$90),"—") -> 0.003 | H12: =IFERROR(_xlfn.XLOOKUP(C12,'DONNÉES BRUTES'!A$3:A$90,'DONNÉES BRUTES'!N$3:N$90),"—") -> 0.141 | I12: =IFERROR(_xlfn.XLOOKUP(C12,'DONNÉES BRUTES'!A$3:A$90,'DONNÉES BRUTES'!O$3:O$90),"—") -> 0.054 | J12: =IFERROR(_xlfn.XLOOKUP(C12,'DONNÉES BRUTES'!A$3:A$90,'DONNÉES BRUTES'!Q$3:Q$90),"—") -> 0.059 | K12: =IFERROR(_xlfn.XLOOKUP(C12,'DONNÉES BRUTES'!A$3:A$90,'DONNÉES BRUTES'!AB$3:AB$90),"—") -> 70 | L12: =IFERROR(_xlfn.XLOOKUP(C12,'DONNÉES BRUTES'!A$3:A$90,'DONNÉES BRUTES'!AC$3:AC$90),"—") -> 2026-04-30 | M12: =IFERROR(_xlfn.XLOOKUP(C12,'DONNÉES BRUTES'!A$3:A$90,'DONNÉES BRUTES'!AD$3:AD$90),"—") -> Sous-pondérer | N12: GLW | O12: 88 | Q12: GLW | R12: 19.1 | T12: GLW | U12: 23.9 | W12: 88 | X12: 68
B13: 7 | C13: =IFERROR(_xlfn.XLOOKUP(LARGE('DONNÉES BRUTES'!Y$3:Y$90,7),'DONNÉES BRUTES'!Y$3:Y$90,'DONNÉES BRUTES'!A$3:A$90),"—") -> PSX | D13: =IFERROR(_xlfn.XLOOKUP(C13,'DONNÉES BRUTES'!A$3:A$90,'DONNÉES BRUTES'!B$3:B$90),"—") -> Phillips 66 | F13: =IFERROR(_xlfn.XLOOKUP(C13,'DONNÉES BRUTES'!A$3:A$90,'DONNÉES BRUTES'!Y$3:Y$90)&"/100","—") -> 83/100 | G13: =IFERROR(_xlfn.XLOOKUP(C13,'DONNÉES BRUTES'!A$3:A$90,'DONNÉES BRUTES'!P$3:P$90),"—") -> -0.075 | H13: =IFERROR(_xlfn.XLOOKUP(C13,'DONNÉES BRUTES'!A$3:A$90,'DONNÉES BRUTES'!N$3:N$90),"—") -> 0.074 | I13: =IFERROR(_xlfn.XLOOKUP(C13,'DONNÉES BRUTES'!A$3:A$90,'DONNÉES BRUTES'!O$3:O$90),"—") -> 0.033 | J13: =IFERROR(_xlfn.XLOOKUP(C13,'DONNÉES BRUTES'!A$3:A$90,'DONNÉES BRUTES'!Q$3:Q$90),"—") -> 0.151 | K13: =IFERROR(_xlfn.XLOOKUP(C13,'DONNÉES BRUTES'!A$3:A$90,'DONNÉES BRUTES'!AB$3:AB$90),"—") -> 71 | L13: =IFERROR(_xlfn.XLOOKUP(C13,'DONNÉES BRUTES'!A$3:A$90,'DONNÉES BRUTES'!AC$3:AC$90),"—") -> 2026-04-24 | M13: =IFERROR(_xlfn.XLOOKUP(C13,'DONNÉES BRUTES'!A$3:A$90,'DONNÉES BRUTES'!AD$3:AD$90),"—") -> Neutre | N13: XYZ | O13: 87 | Q13: XYZ | R13: 0.3 | T13: XYZ | U13: 14.1 | W13: 87 | X13: 53
B14: 8 | C14: =IFERROR(_xlfn.XLOOKUP(LARGE('DONNÉES BRUTES'!Y$3:Y$90,8),'DONNÉES BRUTES'!Y$3:Y$90,'DONNÉES BRUTES'!A$3:A$90),"—") -> SMCI | D14: =IFERROR(_xlfn.XLOOKUP(C14,'DONNÉES BRUTES'!A$3:A$90,'DONNÉES BRUTES'!B$3:B$90),"—") -> Super Micro Computer, Inc. | F14: =IFERROR(_xlfn.XLOOKUP(C14,'DONNÉES BRUTES'!A$3:A$90,'DONNÉES BRUTES'!Y$3:Y$90)&"/100","—") -> 81/100 | G14: =IFERROR(_xlfn.XLOOKUP(C14,'DONNÉES BRUTES'!A$3:A$90,'DONNÉES BRUTES'!P$3:P$90),"—") -> 0.466 | H14: =IFERROR(_xlfn.XLOOKUP(C14,'DONNÉES BRUTES'!A$3:A$90,'DONNÉES BRUTES'!N$3:N$90),"—") -> 0.061 | I14: =IFERROR(_xlfn.XLOOKUP(C14,'DONNÉES BRUTES'!A$3:A$90,'DONNÉES BRUTES'!O$3:O$90),"—") -> — | J14: =IFERROR(_xlfn.XLOOKUP(C14,'DONNÉES BRUTES'!A$3:A$90,'DONNÉES BRUTES'!Q$3:Q$90),"—") -> — | K14: =IFERROR(_xlfn.XLOOKUP(C14,'DONNÉES BRUTES'!A$3:A$90,'DONNÉES BRUTES'!AB$3:AB$90),"—") -> 58 | L14: =IFERROR(_xlfn.XLOOKUP(C14,'DONNÉES BRUTES'!A$3:A$90,'DONNÉES BRUTES'!AC$3:AC$90),"—") -> — | M14: =IFERROR(_xlfn.XLOOKUP(C14,'DONNÉES BRUTES'!A$3:A$90,'DONNÉES BRUTES'!AD$3:AD$90),"—") -> Sous-pondérer | N14: MPWR | O14: 86 | Q14: MPWR | R14: 26.4 | T14: MPWR | U14: 28 | W14: 86 | X14: 78
B15: 9 | C15: =IFERROR(_xlfn.XLOOKUP(LARGE('DONNÉES BRUTES'!Y$3:Y$90,9),'DONNÉES BRUTES'!Y$3:Y$90,'DONNÉES BRUTES'!A$3:A$90),"—") -> NOW | D15: =IFERROR(_xlfn.XLOOKUP(C15,'DONNÉES BRUTES'!A$3:A$90,'DONNÉES BRUTES'!B$3:B$90),"—") -> ServiceNow, Inc. | F15: =IFERROR(_xlfn.XLOOKUP(C15,'DONNÉES BRUTES'!A$3:A$90,'DONNÉES BRUTES'!Y$3:Y$90)&"/100","—") -> 80/100 | G15: =IFERROR(_xlfn.XLOOKUP(C15,'DONNÉES BRUTES'!A$3:A$90,'DONNÉES BRUTES'!P$3:P$90),"—") -> 0.209 | H15: =IFERROR(_xlfn.XLOOKUP(C15,'DONNÉES BRUTES'!A$3:A$90,'DONNÉES BRUTES'!N$3:N$90),"—") -> 0.228 | I15: =IFERROR(_xlfn.XLOOKUP(C15,'DONNÉES BRUTES'!A$3:A$90,'DONNÉES BRUTES'!O$3:O$90),"—") -> 0.132 | J15: =IFERROR(_xlfn.XLOOKUP(C15,'DONNÉES BRUTES'!A$3:A$90,'DONNÉES BRUTES'!Q$3:Q$90),"—") -> 0.135 | K15: =IFERROR(_xlfn.XLOOKUP(C15,'DONNÉES BRUTES'!A$3:A$90,'DONNÉES BRUTES'!AB$3:AB$90),"—") -> 66 | L15: =IFERROR(_xlfn.XLOOKUP(C15,'DONNÉES BRUTES'!A$3:A$90,'DONNÉES BRUTES'!AC$3:AC$90),"—") -> 2026-04-22 | M15: =IFERROR(_xlfn.XLOOKUP(C15,'DONNÉES BRUTES'!A$3:A$90,'DONNÉES BRUTES'!AD$3:AD$90),"—") -> Sous-pondérer | N15: KLAC | O15: 85 | Q15: KLAC | R15: 23.9 | T15: KLAC | U15: 43.9 | W15: 85 | X15: 84
B16: 10 | C16: =IFERROR(_xlfn.XLOOKUP(LARGE('DONNÉES BRUTES'!Y$3:Y$90,10),'DONNÉES BRUTES'!Y$3:Y$90,'DONNÉES BRUTES'!A$3:A$90),"—") -> TPL | D16: =IFERROR(_xlfn.XLOOKUP(C16,'DONNÉES BRUTES'!A$3:A$90,'DONNÉES BRUTES'!B$3:B$90),"—") -> Texas Pacific Land Corporation | F16: =IFERROR(_xlfn.XLOOKUP(C16,'DONNÉES BRUTES'!A$3:A$90,'DONNÉES BRUTES'!Y$3:Y$90)&"/100","—") -> 79/100 | G16: =IFERROR(_xlfn.XLOOKUP(C16,'DONNÉES BRUTES'!A$3:A$90,'DONNÉES BRUTES'!P$3:P$90),"—") -> 0.131 | H16: =IFERROR(_xlfn.XLOOKUP(C16,'DONNÉES BRUTES'!A$3:A$90,'DONNÉES BRUTES'!N$3:N$90),"—") -> 0.844 | I16: =IFERROR(_xlfn.XLOOKUP(C16,'DONNÉES BRUTES'!A$3:A$90,'DONNÉES BRUTES'!O$3:O$90),"—") -> 0.603 | J16: =IFERROR(_xlfn.XLOOKUP(C16,'DONNÉES BRUTES'!A$3:A$90,'DONNÉES BRUTES'!Q$3:Q$90),"—") -> 0.33 | K16: =IFERROR(_xlfn.XLOOKUP(C16,'DONNÉES BRUTES'!A$3:A$90,'DONNÉES BRUTES'!AB$3:AB$90),"—") -> 59 | L16: =IFERROR(_xlfn.XLOOKUP(C16,'DONNÉES BRUTES'!A$3:A$90,'DONNÉES BRUTES'!AC$3:AC$90),"—") -> 2026-05-06 | M16: =IFERROR(_xlfn.XLOOKUP(C16,'DONNÉES BRUTES'!A$3:A$90,'DONNÉES BRUTES'!AD$3:AD$90),"—") -> Neutre | N16: ANET | O16: 84 | Q16: ANET | R16: 28.6 | T16: ANET | U16: 43.6 | W16: 84 | X16: 83
B17: 11 | C17: =IFERROR(_xlfn.XLOOKUP(LARGE('DONNÉES BRUTES'!Y$3:Y$90,11),'DONNÉES BRUTES'!Y$3:Y$90,'DONNÉES BRUTES'!A$3:A$90),"—") -> WDAY | D17: =IFERROR(_xlfn.XLOOKUP(C17,'DONNÉES BRUTES'!A$3:A$90,'DONNÉES BRUTES'!B$3:B$90),"—") -> Workday, Inc. | F17: =IFERROR(_xlfn.XLOOKUP(C17,'DONNÉES BRUTES'!A$3:A$90,'DONNÉES BRUTES'!Y$3:Y$90)&"/100","—") -> 77/100 | G17: =IFERROR(_xlfn.XLOOKUP(C17,'DONNÉES BRUTES'!A$3:A$90,'DONNÉES BRUTES'!P$3:P$90),"—") -> 0.131 | H17: =IFERROR(_xlfn.XLOOKUP(C17,'DONNÉES BRUTES'!A$3:A$90,'DONNÉES BRUTES'!N$3:N$90),"—") -> 0.154 | I17: =IFERROR(_xlfn.XLOOKUP(C17,'DONNÉES BRUTES'!A$3:A$90,'DONNÉES BRUTES'!O$3:O$90),"—") -> — | J17: =IFERROR(_xlfn.XLOOKUP(C17,'DONNÉES BRUTES'!A$3:A$90,'DONNÉES BRUTES'!Q$3:Q$90),"—") -> — | K17: =IFERROR(_xlfn.XLOOKUP(C17,'DONNÉES BRUTES'!A$3:A$90,'DONNÉES BRUTES'!AB$3:AB$90),"—") -> 63 | L17: =IFERROR(_xlfn.XLOOKUP(C17,'DONNÉES BRUTES'!A$3:A$90,'DONNÉES BRUTES'!AC$3:AC$90),"—") -> — | M17: =IFERROR(_xlfn.XLOOKUP(C17,'DONNÉES BRUTES'!A$3:A$90,'DONNÉES BRUTES'!AD$3:AD$90),"—") -> Sous-pondérer | N17: LRCX | O17: 83 | Q17: LRCX | R17: 23.7 | T17: LRCX | U17: 35.4 | W17: 83 | X17: 77
B18: 12 | C18: =IFERROR(_xlfn.XLOOKUP(LARGE('DONNÉES BRUTES'!Y$3:Y$90,12),'DONNÉES BRUTES'!Y$3:Y$90,'DONNÉES BRUTES'!A$3:A$90),"—") -> UBER | D18: =IFERROR(_xlfn.XLOOKUP(C18,'DONNÉES BRUTES'!A$3:A$90,'DONNÉES BRUTES'!B$3:B$90),"—") -> Uber Technologies, Inc. | F18: =IFERROR(_xlfn.XLOOKUP(C18,'DONNÉES BRUTES'!A$3:A$90,'DONNÉES BRUTES'!Y$3:Y$90)&"/100","—") -> 76/100 | G18: =IFERROR(_xlfn.XLOOKUP(C18,'DONNÉES BRUTES'!A$3:A$90,'DONNÉES BRUTES'!P$3:P$90),"—") -> 0.183 | H18: =IFERROR(_xlfn.XLOOKUP(C18,'DONNÉES BRUTES'!A$3:A$90,'DONNÉES BRUTES'!N$3:N$90),"—") -> 0.134 | I18: =IFERROR(_xlfn.XLOOKUP(C18,'DONNÉES BRUTES'!A$3:A$90,'DONNÉES BRUTES'!O$3:O$90),"—") -> — | J18: =IFERROR(_xlfn.XLOOKUP(C18,'DONNÉES BRUTES'!A$3:A$90,'DONNÉES BRUTES'!Q$3:Q$90),"—") -> — | K18: =IFERROR(_xlfn.XLOOKUP(C18,'DONNÉES BRUTES'!A$3:A$90,'DONNÉES BRUTES'!AB$3:AB$90),"—") -> 63 | L18: =IFERROR(_xlfn.XLOOKUP(C18,'DONNÉES BRUTES'!A$3:A$90,'DONNÉES BRUTES'!AC$3:AC$90),"—") -> — | M18: =IFERROR(_xlfn.XLOOKUP(C18,'DONNÉES BRUTES'!A$3:A$90,'DONNÉES BRUTES'!AD$3:AD$90),"—") -> Sous-pondérer | N18: SMCI | O18: 81 | Q18: SMCI | R18: 46.6 | T18: SMCI | U18: 6.1 | W18: 81 | X18: 32
B19: 13 | C19: =IFERROR(_xlfn.XLOOKUP(LARGE('DONNÉES BRUTES'!Y$3:Y$90,13),'DONNÉES BRUTES'!Y$3:Y$90,'DONNÉES BRUTES'!A$3:A$90),"—") -> FANG | D19: =IFERROR(_xlfn.XLOOKUP(C19,'DONNÉES BRUTES'!A$3:A$90,'DONNÉES BRUTES'!B$3:B$90),"—") -> Diamondback Energy, Inc. | F19: =IFERROR(_xlfn.XLOOKUP(C19,'DONNÉES BRUTES'!A$3:A$90,'DONNÉES BRUTES'!Y$3:Y$90)&"/100","—") -> 75/100 | G19: =IFERROR(_xlfn.XLOOKUP(C19,'DONNÉES BRUTES'!A$3:A$90,'DONNÉES BRUTES'!P$3:P$90),"—") -> 0.354 | H19: =IFERROR(_xlfn.XLOOKUP(C19,'DONNÉES BRUTES'!A$3:A$90,'DONNÉES BRUTES'!N$3:N$90),"—") -> 0.481 | I19: =IFERROR(_xlfn.XLOOKUP(C19,'DONNÉES BRUTES'!A$3:A$90,'DONNÉES BRUTES'!O$3:O$90),"—") -> 0.111 | J19: =IFERROR(_xlfn.XLOOKUP(C19,'DONNÉES BRUTES'!A$3:A$90,'DONNÉES BRUTES'!Q$3:Q$90),"—") -> 0.045 | K19: =IFERROR(_xlfn.XLOOKUP(C19,'DONNÉES BRUTES'!A$3:A$90,'DONNÉES BRUTES'!AB$3:AB$90),"—") -> 57 | L19: =IFERROR(_xlfn.XLOOKUP(C19,'DONNÉES BRUTES'!A$3:A$90,'DONNÉES BRUTES'!AC$3:AC$90),"—") -> 2026-05-04 | M19: =IFERROR(_xlfn.XLOOKUP(C19,'DONNÉES BRUTES'!A$3:A$90,'DONNÉES BRUTES'!AD$3:AD$90),"—") -> Neutre | N19: NOW | O19: 80 | Q19: NOW | R19: 20.9 | T19: NOW | U19: 22.8 | W19: 80 | X19: 53
B20: 14 | C20: =IFERROR(_xlfn.XLOOKUP(LARGE('DONNÉES BRUTES'!Y$3:Y$90,14),'DONNÉES BRUTES'!Y$3:Y$90,'DONNÉES BRUTES'!A$3:A$90),"—") -> MSI | D20: =IFERROR(_xlfn.XLOOKUP(C20,'DONNÉES BRUTES'!A$3:A$90,'DONNÉES BRUTES'!B$3:B$90),"—") -> Motorola Solutions, Inc. | F20: =IFERROR(_xlfn.XLOOKUP(C20,'DONNÉES BRUTES'!A$3:A$90,'DONNÉES BRUTES'!Y$3:Y$90)&"/100","—") -> 74/100 | G20: =IFERROR(_xlfn.XLOOKUP(C20,'DONNÉES BRUTES'!A$3:A$90,'DONNÉES BRUTES'!P$3:P$90),"—") -> 0.08 | H20: =IFERROR(_xlfn.XLOOKUP(C20,'DONNÉES BRUTES'!A$3:A$90,'DONNÉES BRUTES'!N$3:N$90),"—") -> 0.308 | I20: =IFERROR(_xlfn.XLOOKUP(C20,'DONNÉES BRUTES'!A$3:A$90,'DONNÉES BRUTES'!O$3:O$90),"—") -> 0.184 | J20: =IFERROR(_xlfn.XLOOKUP(C20,'DONNÉES BRUTES'!A$3:A$90,'DONNÉES BRUTES'!Q$3:Q$90),"—") -> 0.894 | K20: =IFERROR(_xlfn.XLOOKUP(C20,'DONNÉES BRUTES'!A$3:A$90,'DONNÉES BRUTES'!AB$3:AB$90),"—") -> 77 | L20: =IFERROR(_xlfn.XLOOKUP(C20,'DONNÉES BRUTES'!A$3:A$90,'DONNÉES BRUTES'!AC$3:AC$90),"—") -> 2026-04-30 | M20: =IFERROR(_xlfn.XLOOKUP(C20,'DONNÉES BRUTES'!A$3:A$90,'DONNÉES BRUTES'!AD$3:AD$90),"—") -> Neutre | N20: SNPS | O20: 79 | Q20: SNPS | R20: 15.1 | T20: SNPS | U20: 35.4 | W20: 79 | X20: 66
B21: 15 | C21: =IFERROR(_xlfn.XLOOKUP(LARGE('DONNÉES BRUTES'!Y$3:Y$90,15),'DONNÉES BRUTES'!Y$3:Y$90,'DONNÉES BRUTES'!A$3:A$90),"—") -> INTU | D21: =IFERROR(_xlfn.XLOOKUP(C21,'DONNÉES BRUTES'!A$3:A$90,'DONNÉES BRUTES'!B$3:B$90),"—") -> Intuit Inc. | F21: =IFERROR(_xlfn.XLOOKUP(C21,'DONNÉES BRUTES'!A$3:A$90,'DONNÉES BRUTES'!Y$3:Y$90)&"/100","—") -> 72/100 | G21: =IFERROR(_xlfn.XLOOKUP(C21,'DONNÉES BRUTES'!A$3:A$90,'DONNÉES BRUTES'!P$3:P$90),"—") -> 0.156 | H21: =IFERROR(_xlfn.XLOOKUP(C21,'DONNÉES BRUTES'!A$3:A$90,'DONNÉES BRUTES'!N$3:N$90),"—") -> 0.313 | I21: =IFERROR(_xlfn.XLOOKUP(C21,'DONNÉES BRUTES'!A$3:A$90,'DONNÉES BRUTES'!O$3:O$90),"—") -> 0.205 | J21: =IFERROR(_xlfn.XLOOKUP(C21,'DONNÉES BRUTES'!A$3:A$90,'DONNÉES BRUTES'!Q$3:Q$90),"—") -> 0.196 | K21: =IFERROR(_xlfn.XLOOKUP(C21,'DONNÉES BRUTES'!A$3:A$90,'DONNÉES BRUTES'!AB$3:AB$90),"—") -> 67 | L21: =IFERROR(_xlfn.XLOOKUP(C21,'DONNÉES BRUTES'!A$3:A$90,'DONNÉES BRUTES'!AC$3:AC$90),"—") -> 2026-05-21 | M21: =IFERROR(_xlfn.XLOOKUP(C21,'DONNÉES BRUTES'!A$3:A$90,'DONNÉES BRUTES'!AD$3:AD$90),"—") -> Neutre | N21: IBM | O21: 78 | Q21: IBM | R21: 7.6 | T21: IBM | U21: 25.6 | W21: 78 | X21: 60
B22: 16 | C22: =IFERROR(_xlfn.XLOOKUP(LARGE('DONNÉES BRUTES'!Y$3:Y$90,16),'DONNÉES BRUTES'!Y$3:Y$90,'DONNÉES BRUTES'!A$3:A$90),"—") -> WMB | D22: =IFERROR(_xlfn.XLOOKUP(C22,'DONNÉES BRUTES'!A$3:A$90,'DONNÉES BRUTES'!B$3:B$90),"—") -> The Williams Companies, Inc. | F22: =IFERROR(_xlfn.XLOOKUP(C22,'DONNÉES BRUTES'!A$3:A$90,'DONNÉES BRUTES'!Y$3:Y$90)&"/100","—") -> 71/100 | G22: =IFERROR(_xlfn.XLOOKUP(C22,'DONNÉES BRUTES'!A$3:A$90,'DONNÉES BRUTES'!P$3:P$90),"—") -> 0.138 | H22: =IFERROR(_xlfn.XLOOKUP(C22,'DONNÉES BRUTES'!A$3:A$90,'DONNÉES BRUTES'!N$3:N$90),"—") -> 0.62 | I22: =IFERROR(_xlfn.XLOOKUP(C22,'DONNÉES BRUTES'!A$3:A$90,'DONNÉES BRUTES'!O$3:O$90),"—") -> 0.219 | J22: =IFERROR(_xlfn.XLOOKUP(C22,'DONNÉES BRUTES'!A$3:A$90,'DONNÉES BRUTES'!Q$3:Q$90),"—") -> 0.205 | K22: =IFERROR(_xlfn.XLOOKUP(C22,'DONNÉES BRUTES'!A$3:A$90,'DONNÉES BRUTES'!AB$3:AB$90),"—") -> 53 | L22: =IFERROR(_xlfn.XLOOKUP(C22,'DONNÉES BRUTES'!A$3:A$90,'DONNÉES BRUTES'!AC$3:AC$90),"—") -> 2026-05-04 | M22: =IFERROR(_xlfn.XLOOKUP(C22,'DONNÉES BRUTES'!A$3:A$90,'DONNÉES BRUTES'!AD$3:AD$90),"—") -> Neutre
B23: 17 | C23: =IFERROR(_xlfn.XLOOKUP(LARGE('DONNÉES BRUTES'!Y$3:Y$90,17),'DONNÉES BRUTES'!Y$3:Y$90,'DONNÉES BRUTES'!A$3:A$90),"—") -> FSLR | D23: =IFERROR(_xlfn.XLOOKUP(C23,'DONNÉES BRUTES'!A$3:A$90,'DONNÉES BRUTES'!B$3:B$90),"—") -> First Solar, Inc. | F23: =IFERROR(_xlfn.XLOOKUP(C23,'DONNÉES BRUTES'!A$3:A$90,'DONNÉES BRUTES'!Y$3:Y$90)&"/100","—") -> 69/100 | G23: =IFERROR(_xlfn.XLOOKUP(C23,'DONNÉES BRUTES'!A$3:A$90,'DONNÉES BRUTES'!P$3:P$90),"—") -> 0.241 | H23: =IFERROR(_xlfn.XLOOKUP(C23,'DONNÉES BRUTES'!A$3:A$90,'DONNÉES BRUTES'!N$3:N$90),"—") -> 0.413 | I23: =IFERROR(_xlfn.XLOOKUP(D23,'DONNÉES BRUTES'!B$3:B$90,'DONNÉES BRUTES'!O$3:O$90),"—") -> 0.293 | J23: =IFERROR(_xlfn.XLOOKUP(E23,'DONNÉES BRUTES'!C$3:C$90,'DONNÉES BRUTES'!P$3:P$90),"—") -> — | K23: =IFERROR(_xlfn.XLOOKUP(C23,'DONNÉES BRUTES'!A$3:A$90,'DONNÉES BRUTES'!AB$3:AB$90),"—") -> 63 | L23: =IFERROR(_xlfn.XLOOKUP(C23,'DONNÉES BRUTES'!A$3:A$90,'DONNÉES BRUTES'!AC$3:AC$90),"—") -> 2026-04-28 | M23: =IFERROR(_xlfn.XLOOKUP(C23,'DONNÉES BRUTES'!A$3:A$90,'DONNÉES BRUTES'!AD$3:AD$90),"—") -> Neutre
B24: 18 | C24: =IFERROR(_xlfn.XLOOKUP(LARGE('DONNÉES BRUTES'!Y$3:Y$90,18),'DONNÉES BRUTES'!Y$3:Y$90,'DONNÉES BRUTES'!A$3:A$90),"—") -> TRGP | D24: =IFERROR(_xlfn.XLOOKUP(C24,'DONNÉES BRUTES'!A$3:A$90,'DONNÉES BRUTES'!B$3:B$90),"—") -> Targa Resources Corp. | F24: =IFERROR(_xlfn.XLOOKUP(C24,'DONNÉES BRUTES'!A$3:A$90,'DONNÉES BRUTES'!Y$3:Y$90)&"/100","—") -> 67/100 | G24: =IFERROR(_xlfn.XLOOKUP(C24,'DONNÉES BRUTES'!A$3:A$90,'DONNÉES BRUTES'!P$3:P$90),"—") -> 0.039 | H24: =IFERROR(_xlfn.XLOOKUP(C24,'DONNÉES BRUTES'!A$3:A$90,'DONNÉES BRUTES'!N$3:N$90),"—") -> 0.285 | I24: =IFERROR(_xlfn.XLOOKUP(C24,'DONNÉES BRUTES'!A$3:A$90,'DONNÉES BRUTES'!O$3:O$90),"—") -> 0.113 | J24: =IFERROR(_xlfn.XLOOKUP(C24,'DONNÉES BRUTES'!A$3:A$90,'DONNÉES BRUTES'!Q$3:Q$90),"—") -> 0.627 | K24: =IFERROR(_xlfn.XLOOKUP(C24,'DONNÉES BRUTES'!A$3:A$90,'DONNÉES BRUTES'!AB$3:AB$90),"—") -> 61 | L24: =IFERROR(_xlfn.XLOOKUP(C24,'DONNÉES BRUTES'!A$3:A$90,'DONNÉES BRUTES'!AC$3:AC$90),"—") -> 2026-04-30 | M24: =IFERROR(_xlfn.XLOOKUP(C24,'DONNÉES BRUTES'!A$3:A$90,'DONNÉES BRUTES'!AD$3:AD$90),"—") -> Neutre
B25: 19 | C25: =IFERROR(_xlfn.XLOOKUP(LARGE('DONNÉES BRUTES'!Y$3:Y$90,19),'DONNÉES BRUTES'!Y$3:Y$90,'DONNÉES BRUTES'!A$3:A$90),"—") -> ADBE | D25: =IFERROR(_xlfn.XLOOKUP(C25,'DONNÉES BRUTES'!A$3:A$90,'DONNÉES BRUTES'!B$3:B$90),"—") -> Adobe Inc. | F25: =IFERROR(_xlfn.XLOOKUP(C25,'DONNÉES BRUTES'!A$3:A$90,'DONNÉES BRUTES'!Y$3:Y$90)&"/100","—") -> 65/100 | G25: =IFERROR(_xlfn.XLOOKUP(C25,'DONNÉES BRUTES'!A$3:A$90,'DONNÉES BRUTES'!P$3:P$90),"—") -> 0.105 | H25: =IFERROR(_xlfn.XLOOKUP(C25,'DONNÉES BRUTES'!A$3:A$90,'DONNÉES BRUTES'!N$3:N$90),"—") -> 0.413 | I25: =IFERROR(_xlfn.XLOOKUP(C25,'DONNÉES BRUTES'!A$3:A$90,'DONNÉES BRUTES'!O$3:O$90),"—") -> 0.3 | J25: =IFERROR(_xlfn.XLOOKUP(C25,'DONNÉES BRUTES'!A$3:A$90,'DONNÉES BRUTES'!Q$3:Q$90),"—") -> 0.613 | K25: =IFERROR(_xlfn.XLOOKUP(C25,'DONNÉES BRUTES'!A$3:A$90,'DONNÉES BRUTES'!AB$3:AB$90),"—") -> 69 | L25: =IFERROR(_xlfn.XLOOKUP(C25,'DONNÉES BRUTES'!A$3:A$90,'DONNÉES BRUTES'!AC$3:AC$90),"—") -> 2026-06-11 | M25: =IFERROR(_xlfn.XLOOKUP(C25,'DONNÉES BRUTES'!A$3:A$90,'DONNÉES BRUTES'!AD$3:AD$90),"—") -> Neutre
B26: 20 | C26: =IFERROR(_xlfn.XLOOKUP(LARGE('DONNÉES BRUTES'!Y$3:Y$90,20),'DONNÉES BRUTES'!Y$3:Y$90,'DONNÉES BRUTES'!A$3:A$90),"—") -> QCOM | D26: =IFERROR(_xlfn.XLOOKUP(C26,'DONNÉES BRUTES'!A$3:A$90,'DONNÉES BRUTES'!B$3:B$90),"—") -> QUALCOMM Incorporated | F26: =IFERROR(_xlfn.XLOOKUP(C26,'DONNÉES BRUTES'!A$3:A$90,'DONNÉES BRUTES'!Y$3:Y$90)&"/100","—") -> 63/100 | G26: =IFERROR(_xlfn.XLOOKUP(C26,'DONNÉES BRUTES'!A$3:A$90,'DONNÉES BRUTES'!P$3:P$90),"—") -> 0.137 | H26: =IFERROR(_xlfn.XLOOKUP(C26,'DONNÉES BRUTES'!A$3:A$90,'DONNÉES BRUTES'!N$3:N$90),"—") -> 0.337 | I26: =IFERROR(_xlfn.XLOOKUP(C26,'DONNÉES BRUTES'!A$3:A$90,'DONNÉES BRUTES'!O$3:O$90),"—") -> — | J26: =IFERROR(_xlfn.XLOOKUP(C26,'DONNÉES BRUTES'!A$3:A$90,'DONNÉES BRUTES'!Q$3:Q$90),"—") -> — | K26: =IFERROR(_xlfn.XLOOKUP(C26,'DONNÉES BRUTES'!A$3:A$90,'DONNÉES BRUTES'!AB$3:AB$90),"—") -> 63 | L26: =IFERROR(_xlfn.XLOOKUP(C26,'DONNÉES BRUTES'!A$3:A$90,'DONNÉES BRUTES'!AC$3:AC$90),"—") -> — | M26: =IFERROR(_xlfn.XLOOKUP(C26,'DONNÉES BRUTES'!A$3:A$90,'DONNÉES BRUTES'!AD$3:AD$90),"—") -> Sous-pondérer
B28: FinSight IA · Screening Énergie · Ne constitue pas un conseil en investissement

Sheet QUALITY
B1: FinSight IA · Analyse QUALITY · Énergie Screening | N1: Ticker | O1: Score | Q1: Ticker | R1: AltZ | T1: Ticker | U1: Beneish M | W1: Ticker | X1: Mg EBITDA (%)
B2: Usage confidentiel · Calculs FinSight IA · Screening Énergie | N2: DSY.PA | O2: 100 | Q2: DSY.PA | R2: 0 | T2: DSY.PA | W2: DSY.PA | X2: 30.4
C3: =COUNTA('DONNÉES BRUTES'!A$3:A$90) -> 88 | F3: =IFERROR(_xlfn.XLOOKUP(LARGE('DONNÉES BRUTES'!Z$3:Z$90,1),'DONNÉES BRUTES'!Z$3:Z$90,'DONNÉES BRUTES'!A$3:A$90),"—") -> TPL | J3: =IFERROR(ROUND(AVERAGE('DONNÉES BRUTES'!Z$3:Z$90),0)&"/100","—") -> 68/100 | M3: VRSN | O3: 99 | Q3: VRSN | R3: 0 | T3: VRSN | U3: -2.84 | W3: VRSN | X3: 71
C4: Sociétés | F4: #1 Quality | J4: Moy. Score Quality | M4: NVDA | O4: 98 | Q4: NVDA | R4: 13.22 | T4: NVDA | U4: -2.19 | W4: NVDA | X4: 66.9
B5: ANALYSE DÉTAILLÉE · ÉNERGIE · TOP 20 par Quality · Triée par Score Quality | N5: ADBE | O5: 97 | Q5: ADBE | R5: 7.74 | T5: ADBE | U5: -2.97 | W5: ADBE | X5: 41.3
B6: # | C6: Ticker | D6: Société | F6: Score | G6: Altman Z | H6: Beneish M | I6: Mg EBITDA | J6: ROE | K6: Current R. | L6: ND/EBITDA | M6: Score Global | N6: FICO | O6: 95 | Q6: FICO | R6: 10.3 | T6: FICO | U6: -2.94 | W6: FICO | X6: 47.8
B7: 1 | C7: {=IFERROR(INDEX('DONNÉES BRUTES'!A$3:A$90,MATCH(1,('DONNÉES BRUTES'!Z$3:Z$90=LARGE('DONNÉES BRUTES'!Z$3:Z$90,1))*(COUNTIF(C$6:C6,'DONNÉES BRUTES'!A$3:A$90)=0)*('DONNÉES BRUTES'!A$3:A$90<>""),0)),"—")} -> TPL | D7: =IFERROR(_xlfn.XLOOKUP(C7,'DONNÉES BRUTES'!A$3:A$90,'DONNÉES BRUTES'!B$3:B$90),"—") -> Texas Pacific Land Corporation | F7: =IFERROR(_xlfn.XLOOKUP(C7,'DONNÉES BRUTES'!A$3:A$90,'DONNÉES BRUTES'!Z$3:Z$90)&"/100","—") -> 91/100 | G7: =IFERROR(_xlfn.XLOOKUP(C7,'DONNÉES BRUTES'!A$3:A$90,'DONNÉES BRUTES'!U$3:U$90),"—") -> 16.05 | H7: =IFERROR(_xlfn.XLOOKUP(C7,'DONNÉES BRUTES'!A$3:A$90,'DONNÉES BRUTES'!V$3:V$90),"—") -> -2.72 | I7: =IFERROR(_xlfn.XLOOKUP(C7,'DONNÉES BRUTES'!A$3:A$90,'DONNÉES BRUTES'!N$3:N$90),"—") -> 0.844 | J7: =IFERROR(_xlfn.XLOOKUP(C7,'DONNÉES BRUTES'!A$3:A$90,'DONNÉES BRUTES'!Q$3:Q$90),"—") -> 0.33 | K7: =IFERROR(_xlfn.XLOOKUP(C7,'DONNÉES BRUTES'!A$3:A$90,'DONNÉES BRUTES'!S$3:S$90),"—") -> 4.34 | L7: =IFERROR(_xlfn.XLOOKUP(C7,'DONNÉES BRUTES'!A$3:A$90,'DONNÉES BRUTES'!T$3:T$90),"—") -> -0.2x | M7: =IFERROR(_xlfn.XLOOKUP(C7,'DONNÉES BRUTES'!A$3:A$90,'DONNÉES BRUTES'!AB$3:AB$90),"—") -> 59 | N7: PTC | O7: 94 | Q7: PTC | R7: 3.62 | T7: PTC | U7: -2.99 | W7: PTC | X7: 41.3
B8: 2 | C8: {=IFERROR(INDEX('DONNÉES BRUTES'!A$3:A$90,MATCH(1,('DONNÉES BRUTES'!Z$3:Z$90>=LARGE('DONNÉES BRUTES'!Z$3:Z$90,2))*(COUNTIF(C$6:C7,'DONNÉES BRUTES'!A$3:A$90)=0)*('DONNÉES BRUTES'!A$3:A$90<>""),0)),"—")} -> AMAT | D8: =IFERROR(_xlfn.XLOOKUP(C8,'DONNÉES BRUTES'!A$3:A$90,'DONNÉES BRUTES'!B$3:B$90),"—") -> Applied Materials, Inc. | F8: =IFERROR(_xlfn.XLOOKUP(C8,'DONNÉES BRUTES'!A$3:A$90,'DONNÉES BRUTES'!Z$3:Z$90)&"/100","—") -> 91/100 | G8: =IFERROR(_xlfn.XLOOKUP(C8,'DONNÉES BRUTES'!A$3:A$90,'DONNÉES BRUTES'!U$3:U$90),"—") -> 10.40 | H8: =IFERROR(_xlfn.XLOOKUP(C8,'DONNÉES BRUTES'!A$3:A$90,'DONNÉES BRUTES'!V$3:V$90),"—") -> -3.07 | I8: =IFERROR(_xlfn.XLOOKUP(C8,'DONNÉES BRUTES'!A$3:A$90,'DONNÉES BRUTES'!N$3:N$90),"—") -> 0.352 | J8: =IFERROR(_xlfn.XLOOKUP(C8,'DONNÉES BRUTES'!A$3:A$90,'DONNÉES BRUTES'!Q$3:Q$90),"—") -> 0.343 | K8: =IFERROR(_xlfn.XLOOKUP(C8,'DONNÉES BRUTES'!A$3:A$90,'DONNÉES BRUTES'!S$3:S$90),"—") -> 2.61 | L8: =IFERROR(_xlfn.XLOOKUP(C8,'DONNÉES BRUTES'!A$3:A$90,'DONNÉES BRUTES'!T$3:T$90),"—") -> -0.1x | M8: =IFERROR(_xlfn.XLOOKUP(C8,'DONNÉES BRUTES'!A$3:A$90,'DONNÉES BRUTES'!AB$3:AB$90),"—") -> 77 | N8: CDNS | O8: 93 | Q8: CDNS | R8: 6.55 | T8: CDNS | U8: -2.92 | W8: CDNS | X8: 35.4
B9: 3 | C9: {=IFERROR(INDEX('DONNÉES BRUTES'!A$3:A$90,MATCH(1,('DONNÉES BRUTES'!Z$3:Z$90>=LARGE('DONNÉES BRUTES'!Z$3:Z$90,3))*(COUNTIF(C$6:C8,'DONNÉES BRUTES'!A$3:A$90)=0)*('DONNÉES BRUTES'!A$3:A$90<>""),0)),"—")} -> FTNT | D9: =IFERROR(_xlfn.XLOOKUP(C9,'DONNÉES BRUTES'!A$3:A$90,'DONNÉES BRUTES'!B$3:B$90),"—") -> Fortinet, Inc. | F9: =IFERROR(_xlfn.XLOOKUP(C9,'DONNÉES BRUTES'!A$3:A$90,'DONNÉES BRUTES'!Z$3:Z$90)&"/100","—") -> 91/100 | G9: =IFERROR(_xlfn.XLOOKUP(C9,'DONNÉES BRUTES'!A$3:A$90,'DONNÉES BRUTES'!U$3:U$90),"—") -> 2.02 | H9: =IFERROR(_xlfn.XLOOKUP(C9,'DONNÉES BRUTES'!A$3:A$90,'DONNÉES BRUTES'!V$3:V$90),"—") -> -2.92 | I9: =IFERROR(_xlfn.XLOOKUP(C9,'DONNÉES BRUTES'!A$3:A$90,'DONNÉES BRUTES'!N$3:N$90),"—") -> 0.361 | J9: =IFERROR(_xlfn.XLOOKUP(C9,'DONNÉES BRUTES'!A$3:A$90,'DONNÉES BRUTES'!Q$3:Q$90),"—") -> 1.498 | K9: =IFERROR(_xlfn.XLOOKUP(C9,'DONNÉES BRUTES'!A$3:A$90,'DONNÉES BRUTES'!S$3:S$90),"—") -> 1.17 | L9: =IFERROR(_xlfn.XLOOKUP(C9,'DONNÉES BRUTES'!A$3:A$90,'DONNÉES BRUTES'!T$3:T$90),"—") -> -0.6x | M9: =IFERROR(_xlfn.XLOOKUP(C9,'DONNÉES BRUTES'!A$3:A$90,'DONNÉES BRUTES'!AB$3:AB$90),"—") -> 70 | N9: FTNT | O9: 92 | Q9: FTNT | R9: 2.02 | T9: FTNT | U9: -2.92 | W9: FTNT | X9: 36.1
B10: 4 | C10: {=IFERROR(INDEX('DONNÉES BRUTES'!A$3:A$90,MATCH(1,('DONNÉES BRUTES'!Z$3:Z$90>=LARGE('DONNÉES BRUTES'!Z$3:Z$90,4))*(COUNTIF(C$6:C9,'DONNÉES BRUTES'!A$3:A$90)=0)*('DONNÉES BRUTES'!A$3:A$90<>""),0)),"—")} -> ADBE | D10: =IFERROR(_xlfn.XLOOKUP(C10,'DONNÉES BRUTES'!A$3:A$90,'DONNÉES BRUTES'!B$3:B$90),"—") -> Adobe Inc. | F10: =IFERROR(_xlfn.XLOOKUP(C10,'DONNÉES BRUTES'!A$3:A$90,'DONNÉES BRUTES'!Z$3:Z$90)&"/100","—") -> 91/100 | G10: =IFERROR(_xlfn.XLOOKUP(C10,'DONNÉES BRUTES'!A$3:A$90,'DONNÉES BRUTES'!U$3:U$90),"—") -> 7.74 | H10: =IFERROR(_xlfn.XLOOKUP(C10,'DONNÉES BRUTES'!A$3:A$90,'DONNÉES BRUTES'!V$3:V$90),"—") -> -2.97 | I10: =IFERROR(_xlfn.XLOOKUP(C10,'DONNÉES BRUTES'!A$3:A$90,'DONNÉES BRUTES'!N$3:N$90),"—") -> 0.413 | J10: =IFERROR(_xlfn.XLOOKUP(C10,'DONNÉES BRUTES'!A$3:A$90,'DONNÉES BRUTES'!Q$3:Q$90),"—") -> 0.613 | K10: =IFERROR(_xlfn.XLOOKUP(C10,'DONNÉES BRUTES'!A$3:A$90,'DONNÉES BRUTES'!S$3:S$90),"—") -> 1.00 | L10: =IFERROR(_xlfn.XLOOKUP(C10,'DONNÉES BRUTES'!A$3:A$90,'DONNÉES BRUTES'!T$3:T$90),"—") -> 0.1x | M10: =IFERROR(_xlfn.XLOOKUP(C10,'DONNÉES BRUTES'!A$3:A$90,'DONNÉES BRUTES'!AB$3:AB$90),"—") -> 69 | N10: SGE.L | O10: 91 | Q10: SGE.L | R10: 0 | T10: SGE.L | W10: SGE.L | X10: 25
B11: 5 | C11: {=IFERROR(INDEX('DONNÉES BRUTES'!A$3:A$90,MATCH(1,('DONNÉES BRUTES'!Z$3:Z$90>=LARGE('DONNÉES BRUTES'!Z$3:Z$90,5))*(COUNTIF(C$6:C10,'DONNÉES BRUTES'!A$3:A$90)=0)*('DONNÉES BRUTES'!A$3:A$90<>""),0)),"—")} -> CRM | D11: =IFERROR(_xlfn.XLOOKUP(C11,'DONNÉES BRUTES'!A$3:A$90,'DONNÉES BRUTES'!B$3:B$90),"—") -> Salesforce, Inc. | F11: =IFERROR(_xlfn.XLOOKUP(C11,'DONNÉES BRUTES'!A$3:A$90,'DONNÉES BRUTES'!Z$3:Z$90)&"/100","—") -> 88/100 | G11: =IFERROR(_xlfn.XLOOKUP(C11,'DONNÉES BRUTES'!A$3:A$90,'DONNÉES BRUTES'!U$3:U$90),"—") -> — | H11: =IFERROR(_xlfn.XLOOKUP(C11,'DONNÉES BRUTES'!A$3:A$90,'DONNÉES BRUTES'!V$3:V$90),"—") -> — | I11: =IFERROR(_xlfn.XLOOKUP(C11,'DONNÉES BRUTES'!A$3:A$90,'DONNÉES BRUTES'!N$3:N$90),"—") -> 0.302 | J11: =IFERROR(_xlfn.XLOOKUP(C11,'DONNÉES BRUTES'!A$3:A$90,'DONNÉES BRUTES'!Q$3:Q$90),"—") -> — | K11: =IFERROR(_xlfn.XLOOKUP(C11,'DONNÉES BRUTES'!A$3:A$90,'DONNÉES BRUTES'!S$3:S$90),"—") -> — | L11: =IFERROR(_xlfn.XLOOKUP(C11,'DONNÉES BRUTES'!A$3:A$90,'DONNÉES BRUTES'!T$3:T$90),"—") -> — | M11: =IFERROR(_xlfn.XLOOKUP(C11,'DONNÉES BRUTES'!A$3:A$90,'DONNÉES BRUTES'!AB$3:AB$90),"—") -> 58 | N11: ADSK | O11: 90 | Q11: ADSK | R11: 0.48 | T11: ADSK | U11: -2.86 | W11: ADSK | X11: 27.6
B12: 6 | C12: {=IFERROR(INDEX('DONNÉES BRUTES'!A$3:A$90,MATCH(1,('DONNÉES BRUTES'!Z$3:Z$90>=LARGE('DONNÉES BRUTES'!Z$3:Z$90,6))*(COUNTIF(C$6:C11,'DONNÉES BRUTES'!A$3:A$90)=0)*('DONNÉES BRUTES'!A$3:A$90<>""),0)),"—")} -> WDAY | D12: =IFERROR(_xlfn.XLOOKUP(C12,'DONNÉES BRUTES'!A$3:A$90,'DONNÉES BRUTES'!B$3:B$90),"—") -> Workday, Inc. | F12: =IFERROR(_xlfn.XLOOKUP(C12,'DONNÉES BRUTES'!A$3:A$90,'DONNÉES BRUTES'!Z$3:Z$90)&"/100","—") -> 88/100 | G12: =IFERROR(_xlfn.XLOOKUP(C12,'DONNÉES BRUTES'!A$3:A$90,'DONNÉES BRUTES'!U$3:U$90),"—") -> — | H12: =IFERROR(_xlfn.XLOOKUP(C12,'DONNÉES BRUTES'!A$3:A$90,'DONNÉES BRUTES'!V$3:V$90),"—") -> — | I12: =IFERROR(_xlfn.XLOOKUP(C12,'DONNÉES BRUTES'!A$3:A$90,'DONNÉES BRUTES'!N$3:N$90),"—") -> 0.154 | J12: =IFERROR(_xlfn.XLOOKUP(C12,'DONNÉES BRUTES'!A$3:A$90,'DONNÉES BRUTES'!Q$3:Q$90),"—") -> — | K12: =IFERROR(_xlfn.XLOOKUP(C12,'DONNÉES BRUTES'!A$3:A$90,'DONNÉES BRUTES'!S$3:S$90),"—") -> — | L12: =IFERROR(_xlfn.XLOOKUP(C12,'DONNÉES BRUTES'!A$3:A$90,'DONNÉES BRUTES'!T$3:T$90),"—") -> — | M12: =IFERROR(_xlfn.XLOOKUP(C12,'DONNÉES BRUTES'!A$3:A$90,'DONNÉES BRUTES'!AB$3:AB$90),"—") -> 63 | N12: ANET | O12: 89 | Q12: ANET | R12: 8.46 | T12: ANET | U12: -2.58 | W12: ANET | X12: 43.6
B13: 7 | C13: {=IFERROR(INDEX('DONNÉES BRUTES'!A$3:A$90,MATCH(1,('DONNÉES BRUTES'!Z$3:Z$90>=LARGE('DONNÉES BRUTES'!Z$3:Z$90,7))*(COUNTIF(C$6:C12,'DONNÉES BRUTES'!A$3:A$90)=0)*('DONNÉES BRUTES'!A$3:A$90<>""),0)),"—")} -> FSLR | D13: =IFERROR(_xlfn.XLOOKUP(C13,'DONNÉES BRUTES'!A$3:A$90,'DONNÉES BRUTES'!B$3:B$90),"—") -> First Solar, Inc. | F13: =IFERROR(_xlfn.XLOOKUP(C13,'DONNÉES BRUTES'!A$3:A$90,'DONNÉES BRUTES'!Z$3:Z$90)&"/100","—") -> 84/100 | G13: =IFERROR(_xlfn.XLOOKUP(C13,'DONNÉES BRUTES'!A$3:A$90,'DONNÉES BRUTES'!U$3:U$90),"—") -> 6.99 | H13: =IFERROR(_xlfn.XLOOKUP(C13,'DONNÉES BRUTES'!A$3:A$90,'DONNÉES BRUTES'!V$3:V$90),"—") -> -3.05 | I13: =IFERROR(_xlfn.XLOOKUP(C13,'DONNÉES BRUTES'!A$3:A$90,'DONNÉES BRUTES'!N$3:N$90),"—") -> 0.413 | J13: =IFERROR(_xlfn.XLOOKUP(C13,'DONNÉES BRUTES'!A$3:A$90,'DONNÉES BRUTES'!Q$3:Q$90),"—") -> 0.16 | K13: =IFERROR(_xlfn.XLOOKUP(C13,'DONNÉES BRUTES'!A$3:A$90,'DONNÉES BRUTES'!S$3:S$90),"—") -> 2.67 | L13: =IFERROR(_xlfn.XLOOKUP(C13,'DONNÉES BRUTES'!A$3:A$90,'DONNÉES BRUTES'!T$3:T$90),"—") -> -1.1x | M13: =IFERROR(_xlfn.XLOOKUP(C13,'DONNÉES BRUTES'!A$3:A$90,'DONNÉES BRUTES'!AB$3:AB$90),"—") -> 63 | N13: MSFT | O13: 87 | Q13: MSFT | R13: 4.46 | T13: MSFT | U13: -3 | W13: MSFT | X13: 56.9
